{
  "voxels": [
    {
      "id": 0,
      "x": -12,
      "y": -12,
      "z": -10,
      "c": "#9e9e9e"
    },
    {
      "id": 1,
      "x": -12,
      "y": -12,
      "z": -9,
      "c": "#9e9e9e"
    },
    {
      "id": 2,
      "x": -12,
      "y": -12,
      "z": -8,
      "c": "#9e9e9e"
    },
    {
      "id": 3,
      "x": -12,
      "y": -12,
      "z": -7,
      "c": "#9e9e9e"
    },
    {
      "id": 4,
      "x": -12,
      "y": -12,
      "z": -6,
      "c": "#9e9e9e"
    },
    {
      "id": 5,
      "x": -12,
      "y": -12,
      "z": -5,
      "c": "#9e9e9e"
    },
    {
      "id": 6,
      "x": -12,
      "y": -12,
      "z": -4,
      "c": "#9e9e9e"
    },
    {
      "id": 7,
      "x": -12,
      "y": -12,
      "z": -3,
      "c": "#9e9e9e"
    },
    {
      "id": 8,
      "x": -12,
      "y": -12,
      "z": -2,
      "c": "#9e9e9e"
    },
    {
      "id": 9,
      "x": -12,
      "y": -12,
      "z": -1,
      "c": "#9e9e9e"
    },
    {
      "id": 10,
      "x": -12,
      "y": -12,
      "z": 0,
      "c": "#9e9e9e"
    },
    {
      "id": 11,
      "x": -12,
      "y": -12,
      "z": 1,
      "c": "#9e9e9e"
    },
    {
      "id": 12,
      "x": -12,
      "y": -12,
      "z": 2,
      "c": "#9e9e9e"
    },
    {
      "id": 13,
      "x": -12,
      "y": -12,
      "z": 3,
      "c": "#9e9e9e"
    },
    {
      "id": 14,
      "x": -12,
      "y": -12,
      "z": 4,
      "c": "#9e9e9e"
    },
    {
      "id": 15,
      "x": -12,
      "y": -12,
      "z": 5,
      "c": "#9e9e9e"
    },
    {
      "id": 16,
      "x": -12,
      "y": -12,
      "z": 6,
      "c": "#9e9e9e"
    },
    {
      "id": 17,
      "x": -12,
      "y": -12,
      "z": 7,
      "c": "#9e9e9e"
    },
    {
      "id": 18,
      "x": -12,
      "y": -12,
      "z": 8,
      "c": "#9e9e9e"
    },
    {
      "id": 19,
      "x": -12,
      "y": -12,
      "z": 9,
      "c": "#9e9e9e"
    },
    {
      "id": 20,
      "x": -12,
      "y": -12,
      "z": 10,
      "c": "#9e9e9e"
    },
    {
      "id": 21,
      "x": -11,
      "y": -12,
      "z": -10,
      "c": "#9e9e9e"
    },
    {
      "id": 22,
      "x": -11,
      "y": -12,
      "z": -9,
      "c": "#9e9e9e"
    },
    {
      "id": 23,
      "x": -11,
      "y": -12,
      "z": -8,
      "c": "#9e9e9e"
    },
    {
      "id": 24,
      "x": -11,
      "y": -12,
      "z": -7,
      "c": "#9e9e9e"
    },
    {
      "id": 25,
      "x": -11,
      "y": -12,
      "z": -6,
      "c": "#9e9e9e"
    },
    {
      "id": 26,
      "x": -11,
      "y": -12,
      "z": -5,
      "c": "#9e9e9e"
    },
    {
      "id": 27,
      "x": -11,
      "y": -12,
      "z": -4,
      "c": "#9e9e9e"
    },
    {
      "id": 28,
      "x": -11,
      "y": -12,
      "z": -3,
      "c": "#9e9e9e"
    },
    {
      "id": 29,
      "x": -11,
      "y": -12,
      "z": -2,
      "c": "#9e9e9e"
    },
    {
      "id": 30,
      "x": -11,
      "y": -12,
      "z": -1,
      "c": "#9e9e9e"
    },
    {
      "id": 31,
      "x": -11,
      "y": -12,
      "z": 0,
      "c": "#9e9e9e"
    },
    {
      "id": 32,
      "x": -11,
      "y": -12,
      "z": 1,
      "c": "#9e9e9e"
    },
    {
      "id": 33,
      "x": -11,
      "y": -12,
      "z": 2,
      "c": "#9e9e9e"
    },
    {
      "id": 34,
      "x": -11,
      "y": -12,
      "z": 3,
      "c": "#9e9e9e"
    },
    {
      "id": 35,
      "x": -11,
      "y": -12,
      "z": 4,
      "c": "#9e9e9e"
    },
    {
      "id": 36,
      "x": -11,
      "y": -12,
      "z": 5,
      "c": "#9e9e9e"
    },
    {
      "id": 37,
      "x": -11,
      "y": -12,
      "z": 6,
      "c": "#9e9e9e"
    },
    {
      "id": 38,
      "x": -11,
      "y": -12,
      "z": 7,
      "c": "#9e9e9e"
    },
    {
      "id": 39,
      "x": -11,
      "y": -12,
      "z": 8,
      "c": "#9e9e9e"
    },
    {
      "id": 40,
      "x": -11,
      "y": -12,
      "z": 9,
      "c": "#9e9e9e"
    },
    {
      "id": 41,
      "x": -11,
      "y": -12,
      "z": 10,
      "c": "#9e9e9e"
    },
    {
      "id": 42,
      "x": -10,
      "y": -12,
      "z": -10,
      "c": "#9e9e9e"
    },
    {
      "id": 43,
      "x": -10,
      "y": -12,
      "z": -9,
      "c": "#9e9e9e"
    },
    {
      "id": 44,
      "x": -10,
      "y": -12,
      "z": -8,
      "c": "#9e9e9e"
    },
    {
      "id": 45,
      "x": -10,
      "y": -12,
      "z": -7,
      "c": "#9e9e9e"
    },
    {
      "id": 46,
      "x": -10,
      "y": -12,
      "z": -6,
      "c": "#9e9e9e"
    },
    {
      "id": 47,
      "x": -10,
      "y": -12,
      "z": -5,
      "c": "#9e9e9e"
    },
    {
      "id": 48,
      "x": -10,
      "y": -12,
      "z": -4,
      "c": "#9e9e9e"
    },
    {
      "id": 49,
      "x": -10,
      "y": -12,
      "z": -3,
      "c": "#9e9e9e"
    },
    {
      "id": 50,
      "x": -10,
      "y": -12,
      "z": -2,
      "c": "#9e9e9e"
    },
    {
      "id": 51,
      "x": -10,
      "y": -12,
      "z": -1,
      "c": "#9e9e9e"
    },
    {
      "id": 52,
      "x": -10,
      "y": -12,
      "z": 0,
      "c": "#9e9e9e"
    },
    {
      "id": 53,
      "x": -10,
      "y": -12,
      "z": 1,
      "c": "#9e9e9e"
    },
    {
      "id": 54,
      "x": -10,
      "y": -12,
      "z": 2,
      "c": "#9e9e9e"
    },
    {
      "id": 55,
      "x": -10,
      "y": -12,
      "z": 3,
      "c": "#9e9e9e"
    },
    {
      "id": 56,
      "x": -10,
      "y": -12,
      "z": 4,
      "c": "#9e9e9e"
    },
    {
      "id": 57,
      "x": -10,
      "y": -12,
      "z": 5,
      "c": "#9e9e9e"
    },
    {
      "id": 58,
      "x": -10,
      "y": -12,
      "z": 6,
      "c": "#9e9e9e"
    },
    {
      "id": 59,
      "x": -10,
      "y": -12,
      "z": 7,
      "c": "#9e9e9e"
    },
    {
      "id": 60,
      "x": -10,
      "y": -12,
      "z": 8,
      "c": "#9e9e9e"
    },
    {
      "id": 61,
      "x": -10,
      "y": -12,
      "z": 9,
      "c": "#9e9e9e"
    },
    {
      "id": 62,
      "x": -10,
      "y": -12,
      "z": 10,
      "c": "#9e9e9e"
    },
    {
      "id": 63,
      "x": -9,
      "y": -12,
      "z": -10,
      "c": "#9e9e9e"
    },
    {
      "id": 64,
      "x": -9,
      "y": -12,
      "z": -9,
      "c": "#9e9e9e"
    },
    {
      "id": 65,
      "x": -9,
      "y": -12,
      "z": -8,
      "c": "#9e9e9e"
    },
    {
      "id": 66,
      "x": -9,
      "y": -12,
      "z": -7,
      "c": "#9e9e9e"
    },
    {
      "id": 67,
      "x": -9,
      "y": -12,
      "z": -6,
      "c": "#9e9e9e"
    },
    {
      "id": 68,
      "x": -9,
      "y": -12,
      "z": -5,
      "c": "#9e9e9e"
    },
    {
      "id": 69,
      "x": -9,
      "y": -12,
      "z": -4,
      "c": "#9e9e9e"
    },
    {
      "id": 70,
      "x": -9,
      "y": -12,
      "z": -3,
      "c": "#9e9e9e"
    },
    {
      "id": 71,
      "x": -9,
      "y": -12,
      "z": -2,
      "c": "#9e9e9e"
    },
    {
      "id": 72,
      "x": -9,
      "y": -12,
      "z": -1,
      "c": "#9e9e9e"
    },
    {
      "id": 73,
      "x": -9,
      "y": -12,
      "z": 0,
      "c": "#9e9e9e"
    },
    {
      "id": 74,
      "x": -9,
      "y": -12,
      "z": 1,
      "c": "#9e9e9e"
    },
    {
      "id": 75,
      "x": -9,
      "y": -12,
      "z": 2,
      "c": "#9e9e9e"
    },
    {
      "id": 76,
      "x": -9,
      "y": -12,
      "z": 3,
      "c": "#9e9e9e"
    },
    {
      "id": 77,
      "x": -9,
      "y": -12,
      "z": 4,
      "c": "#9e9e9e"
    },
    {
      "id": 78,
      "x": -9,
      "y": -12,
      "z": 5,
      "c": "#9e9e9e"
    },
    {
      "id": 79,
      "x": -9,
      "y": -12,
      "z": 6,
      "c": "#9e9e9e"
    },
    {
      "id": 80,
      "x": -9,
      "y": -12,
      "z": 7,
      "c": "#9e9e9e"
    },
    {
      "id": 81,
      "x": -9,
      "y": -12,
      "z": 8,
      "c": "#9e9e9e"
    },
    {
      "id": 82,
      "x": -9,
      "y": -12,
      "z": 9,
      "c": "#9e9e9e"
    },
    {
      "id": 83,
      "x": -9,
      "y": -12,
      "z": 10,
      "c": "#9e9e9e"
    },
    {
      "id": 84,
      "x": -8,
      "y": -12,
      "z": -10,
      "c": "#9e9e9e"
    },
    {
      "id": 85,
      "x": -8,
      "y": -12,
      "z": -9,
      "c": "#9e9e9e"
    },
    {
      "id": 86,
      "x": -8,
      "y": -12,
      "z": -8,
      "c": "#9e9e9e"
    },
    {
      "id": 87,
      "x": -8,
      "y": -12,
      "z": -7,
      "c": "#9e9e9e"
    },
    {
      "id": 88,
      "x": -8,
      "y": -12,
      "z": -6,
      "c": "#9e9e9e"
    },
    {
      "id": 89,
      "x": -8,
      "y": -12,
      "z": -5,
      "c": "#9e9e9e"
    },
    {
      "id": 90,
      "x": -8,
      "y": -12,
      "z": -4,
      "c": "#9e9e9e"
    },
    {
      "id": 91,
      "x": -8,
      "y": -12,
      "z": -3,
      "c": "#9e9e9e"
    },
    {
      "id": 92,
      "x": -8,
      "y": -12,
      "z": -2,
      "c": "#9e9e9e"
    },
    {
      "id": 93,
      "x": -8,
      "y": -12,
      "z": -1,
      "c": "#9e9e9e"
    },
    {
      "id": 94,
      "x": -8,
      "y": -12,
      "z": 0,
      "c": "#9e9e9e"
    },
    {
      "id": 95,
      "x": -8,
      "y": -12,
      "z": 1,
      "c": "#9e9e9e"
    },
    {
      "id": 96,
      "x": -8,
      "y": -12,
      "z": 2,
      "c": "#9e9e9e"
    },
    {
      "id": 97,
      "x": -8,
      "y": -12,
      "z": 3,
      "c": "#9e9e9e"
    },
    {
      "id": 98,
      "x": -8,
      "y": -12,
      "z": 4,
      "c": "#9e9e9e"
    },
    {
      "id": 99,
      "x": -8,
      "y": -12,
      "z": 5,
      "c": "#9e9e9e"
    },
    {
      "id": 100,
      "x": -8,
      "y": -12,
      "z": 6,
      "c": "#9e9e9e"
    },
    {
      "id": 101,
      "x": -8,
      "y": -12,
      "z": 7,
      "c": "#9e9e9e"
    },
    {
      "id": 102,
      "x": -8,
      "y": -12,
      "z": 8,
      "c": "#9e9e9e"
    },
    {
      "id": 103,
      "x": -8,
      "y": -12,
      "z": 9,
      "c": "#9e9e9e"
    },
    {
      "id": 104,
      "x": -8,
      "y": -12,
      "z": 10,
      "c": "#9e9e9e"
    },
    {
      "id": 105,
      "x": -7,
      "y": -12,
      "z": -10,
      "c": "#9e9e9e"
    },
    {
      "id": 106,
      "x": -7,
      "y": -12,
      "z": -9,
      "c": "#9e9e9e"
    },
    {
      "id": 107,
      "x": -7,
      "y": -12,
      "z": -8,
      "c": "#9e9e9e"
    },
    {
      "id": 108,
      "x": -7,
      "y": -12,
      "z": -7,
      "c": "#9e9e9e"
    },
    {
      "id": 109,
      "x": -7,
      "y": -12,
      "z": -6,
      "c": "#9e9e9e"
    },
    {
      "id": 110,
      "x": -7,
      "y": -12,
      "z": -5,
      "c": "#9e9e9e"
    },
    {
      "id": 111,
      "x": -7,
      "y": -12,
      "z": -4,
      "c": "#9e9e9e"
    },
    {
      "id": 112,
      "x": -7,
      "y": -12,
      "z": -3,
      "c": "#9e9e9e"
    },
    {
      "id": 113,
      "x": -7,
      "y": -12,
      "z": -2,
      "c": "#9e9e9e"
    },
    {
      "id": 114,
      "x": -7,
      "y": -12,
      "z": -1,
      "c": "#9e9e9e"
    },
    {
      "id": 115,
      "x": -7,
      "y": -12,
      "z": 0,
      "c": "#9e9e9e"
    },
    {
      "id": 116,
      "x": -7,
      "y": -12,
      "z": 1,
      "c": "#9e9e9e"
    },
    {
      "id": 117,
      "x": -7,
      "y": -12,
      "z": 2,
      "c": "#9e9e9e"
    },
    {
      "id": 118,
      "x": -7,
      "y": -12,
      "z": 3,
      "c": "#9e9e9e"
    },
    {
      "id": 119,
      "x": -7,
      "y": -12,
      "z": 4,
      "c": "#9e9e9e"
    },
    {
      "id": 120,
      "x": -7,
      "y": -12,
      "z": 5,
      "c": "#9e9e9e"
    },
    {
      "id": 121,
      "x": -7,
      "y": -12,
      "z": 6,
      "c": "#9e9e9e"
    },
    {
      "id": 122,
      "x": -7,
      "y": -12,
      "z": 7,
      "c": "#9e9e9e"
    },
    {
      "id": 123,
      "x": -7,
      "y": -12,
      "z": 8,
      "c": "#9e9e9e"
    },
    {
      "id": 124,
      "x": -7,
      "y": -12,
      "z": 9,
      "c": "#9e9e9e"
    },
    {
      "id": 125,
      "x": -7,
      "y": -12,
      "z": 10,
      "c": "#9e9e9e"
    },
    {
      "id": 126,
      "x": -6,
      "y": -12,
      "z": -10,
      "c": "#9e9e9e"
    },
    {
      "id": 127,
      "x": -6,
      "y": -12,
      "z": -9,
      "c": "#9e9e9e"
    },
    {
      "id": 128,
      "x": -6,
      "y": -12,
      "z": -8,
      "c": "#9e9e9e"
    },
    {
      "id": 129,
      "x": -6,
      "y": -12,
      "z": -7,
      "c": "#9e9e9e"
    },
    {
      "id": 130,
      "x": -6,
      "y": -12,
      "z": -6,
      "c": "#9e9e9e"
    },
    {
      "id": 131,
      "x": -6,
      "y": -12,
      "z": -5,
      "c": "#9e9e9e"
    },
    {
      "id": 132,
      "x": -6,
      "y": -12,
      "z": -4,
      "c": "#9e9e9e"
    },
    {
      "id": 133,
      "x": -6,
      "y": -12,
      "z": -3,
      "c": "#9e9e9e"
    },
    {
      "id": 134,
      "x": -6,
      "y": -12,
      "z": -2,
      "c": "#9e9e9e"
    },
    {
      "id": 135,
      "x": -6,
      "y": -12,
      "z": -1,
      "c": "#9e9e9e"
    },
    {
      "id": 136,
      "x": -6,
      "y": -12,
      "z": 0,
      "c": "#9e9e9e"
    },
    {
      "id": 137,
      "x": -6,
      "y": -12,
      "z": 1,
      "c": "#9e9e9e"
    },
    {
      "id": 138,
      "x": -6,
      "y": -12,
      "z": 2,
      "c": "#9e9e9e"
    },
    {
      "id": 139,
      "x": -6,
      "y": -12,
      "z": 3,
      "c": "#9e9e9e"
    },
    {
      "id": 140,
      "x": -6,
      "y": -12,
      "z": 4,
      "c": "#9e9e9e"
    },
    {
      "id": 141,
      "x": -6,
      "y": -12,
      "z": 5,
      "c": "#9e9e9e"
    },
    {
      "id": 142,
      "x": -6,
      "y": -12,
      "z": 6,
      "c": "#9e9e9e"
    },
    {
      "id": 143,
      "x": -6,
      "y": -12,
      "z": 7,
      "c": "#9e9e9e"
    },
    {
      "id": 144,
      "x": -6,
      "y": -12,
      "z": 8,
      "c": "#9e9e9e"
    },
    {
      "id": 145,
      "x": -6,
      "y": -12,
      "z": 9,
      "c": "#9e9e9e"
    },
    {
      "id": 146,
      "x": -6,
      "y": -12,
      "z": 10,
      "c": "#9e9e9e"
    },
    {
      "id": 147,
      "x": -5,
      "y": -12,
      "z": -10,
      "c": "#9e9e9e"
    },
    {
      "id": 148,
      "x": -5,
      "y": -12,
      "z": -9,
      "c": "#9e9e9e"
    },
    {
      "id": 149,
      "x": -5,
      "y": -12,
      "z": -8,
      "c": "#9e9e9e"
    },
    {
      "id": 150,
      "x": -5,
      "y": -12,
      "z": -7,
      "c": "#9e9e9e"
    },
    {
      "id": 151,
      "x": -5,
      "y": -12,
      "z": -6,
      "c": "#9e9e9e"
    },
    {
      "id": 152,
      "x": -5,
      "y": -12,
      "z": -5,
      "c": "#9e9e9e"
    },
    {
      "id": 153,
      "x": -5,
      "y": -12,
      "z": -4,
      "c": "#9e9e9e"
    },
    {
      "id": 154,
      "x": -5,
      "y": -12,
      "z": -3,
      "c": "#9e9e9e"
    },
    {
      "id": 155,
      "x": -5,
      "y": -12,
      "z": -2,
      "c": "#9e9e9e"
    },
    {
      "id": 156,
      "x": -5,
      "y": -12,
      "z": -1,
      "c": "#9e9e9e"
    },
    {
      "id": 157,
      "x": -5,
      "y": -12,
      "z": 0,
      "c": "#9e9e9e"
    },
    {
      "id": 158,
      "x": -5,
      "y": -12,
      "z": 1,
      "c": "#9e9e9e"
    },
    {
      "id": 159,
      "x": -5,
      "y": -12,
      "z": 2,
      "c": "#9e9e9e"
    },
    {
      "id": 160,
      "x": -5,
      "y": -12,
      "z": 3,
      "c": "#9e9e9e"
    },
    {
      "id": 161,
      "x": -5,
      "y": -12,
      "z": 4,
      "c": "#9e9e9e"
    },
    {
      "id": 162,
      "x": -5,
      "y": -12,
      "z": 5,
      "c": "#9e9e9e"
    },
    {
      "id": 163,
      "x": -5,
      "y": -12,
      "z": 6,
      "c": "#9e9e9e"
    },
    {
      "id": 164,
      "x": -5,
      "y": -12,
      "z": 7,
      "c": "#9e9e9e"
    },
    {
      "id": 165,
      "x": -5,
      "y": -12,
      "z": 8,
      "c": "#9e9e9e"
    },
    {
      "id": 166,
      "x": -5,
      "y": -12,
      "z": 9,
      "c": "#9e9e9e"
    },
    {
      "id": 167,
      "x": -5,
      "y": -12,
      "z": 10,
      "c": "#9e9e9e"
    },
    {
      "id": 168,
      "x": -4,
      "y": -12,
      "z": -10,
      "c": "#9e9e9e"
    },
    {
      "id": 169,
      "x": -4,
      "y": -12,
      "z": -9,
      "c": "#9e9e9e"
    },
    {
      "id": 170,
      "x": -4,
      "y": -12,
      "z": -8,
      "c": "#9e9e9e"
    },
    {
      "id": 171,
      "x": -4,
      "y": -12,
      "z": -7,
      "c": "#9e9e9e"
    },
    {
      "id": 172,
      "x": -4,
      "y": -12,
      "z": -6,
      "c": "#9e9e9e"
    },
    {
      "id": 173,
      "x": -4,
      "y": -12,
      "z": -5,
      "c": "#9e9e9e"
    },
    {
      "id": 174,
      "x": -4,
      "y": -12,
      "z": -4,
      "c": "#9e9e9e"
    },
    {
      "id": 175,
      "x": -4,
      "y": -12,
      "z": -3,
      "c": "#9e9e9e"
    },
    {
      "id": 176,
      "x": -4,
      "y": -12,
      "z": -2,
      "c": "#9e9e9e"
    },
    {
      "id": 177,
      "x": -4,
      "y": -12,
      "z": -1,
      "c": "#9e9e9e"
    },
    {
      "id": 178,
      "x": -4,
      "y": -12,
      "z": 0,
      "c": "#9e9e9e"
    },
    {
      "id": 179,
      "x": -4,
      "y": -12,
      "z": 1,
      "c": "#9e9e9e"
    },
    {
      "id": 180,
      "x": -4,
      "y": -12,
      "z": 2,
      "c": "#9e9e9e"
    },
    {
      "id": 181,
      "x": -4,
      "y": -12,
      "z": 3,
      "c": "#9e9e9e"
    },
    {
      "id": 182,
      "x": -4,
      "y": -12,
      "z": 4,
      "c": "#9e9e9e"
    },
    {
      "id": 183,
      "x": -4,
      "y": -12,
      "z": 5,
      "c": "#9e9e9e"
    },
    {
      "id": 184,
      "x": -4,
      "y": -12,
      "z": 6,
      "c": "#9e9e9e"
    },
    {
      "id": 185,
      "x": -4,
      "y": -12,
      "z": 7,
      "c": "#9e9e9e"
    },
    {
      "id": 186,
      "x": -4,
      "y": -12,
      "z": 8,
      "c": "#9e9e9e"
    },
    {
      "id": 187,
      "x": -4,
      "y": -12,
      "z": 9,
      "c": "#9e9e9e"
    },
    {
      "id": 188,
      "x": -4,
      "y": -12,
      "z": 10,
      "c": "#9e9e9e"
    },
    {
      "id": 189,
      "x": -3,
      "y": -12,
      "z": -10,
      "c": "#9e9e9e"
    },
    {
      "id": 190,
      "x": -3,
      "y": -12,
      "z": -9,
      "c": "#9e9e9e"
    },
    {
      "id": 191,
      "x": -3,
      "y": -12,
      "z": -8,
      "c": "#9e9e9e"
    },
    {
      "id": 192,
      "x": -3,
      "y": -12,
      "z": -7,
      "c": "#9e9e9e"
    },
    {
      "id": 193,
      "x": -3,
      "y": -12,
      "z": -6,
      "c": "#9e9e9e"
    },
    {
      "id": 194,
      "x": -3,
      "y": -12,
      "z": -5,
      "c": "#9e9e9e"
    },
    {
      "id": 195,
      "x": -3,
      "y": -12,
      "z": -4,
      "c": "#9e9e9e"
    },
    {
      "id": 196,
      "x": -3,
      "y": -12,
      "z": -3,
      "c": "#9e9e9e"
    },
    {
      "id": 197,
      "x": -3,
      "y": -12,
      "z": -2,
      "c": "#9e9e9e"
    },
    {
      "id": 198,
      "x": -3,
      "y": -12,
      "z": -1,
      "c": "#9e9e9e"
    },
    {
      "id": 199,
      "x": -3,
      "y": -12,
      "z": 0,
      "c": "#9e9e9e"
    },
    {
      "id": 200,
      "x": -3,
      "y": -12,
      "z": 1,
      "c": "#9e9e9e"
    },
    {
      "id": 201,
      "x": -3,
      "y": -12,
      "z": 2,
      "c": "#9e9e9e"
    },
    {
      "id": 202,
      "x": -3,
      "y": -12,
      "z": 3,
      "c": "#9e9e9e"
    },
    {
      "id": 203,
      "x": -3,
      "y": -12,
      "z": 4,
      "c": "#9e9e9e"
    },
    {
      "id": 204,
      "x": -3,
      "y": -12,
      "z": 5,
      "c": "#9e9e9e"
    },
    {
      "id": 205,
      "x": -3,
      "y": -12,
      "z": 6,
      "c": "#9e9e9e"
    },
    {
      "id": 206,
      "x": -3,
      "y": -12,
      "z": 7,
      "c": "#9e9e9e"
    },
    {
      "id": 207,
      "x": -3,
      "y": -12,
      "z": 8,
      "c": "#9e9e9e"
    },
    {
      "id": 208,
      "x": -3,
      "y": -12,
      "z": 9,
      "c": "#9e9e9e"
    },
    {
      "id": 209,
      "x": -3,
      "y": -12,
      "z": 10,
      "c": "#9e9e9e"
    },
    {
      "id": 210,
      "x": -2,
      "y": -12,
      "z": -10,
      "c": "#9e9e9e"
    },
    {
      "id": 211,
      "x": -2,
      "y": -12,
      "z": -9,
      "c": "#9e9e9e"
    },
    {
      "id": 212,
      "x": -2,
      "y": -12,
      "z": -8,
      "c": "#9e9e9e"
    },
    {
      "id": 213,
      "x": -2,
      "y": -12,
      "z": -7,
      "c": "#9e9e9e"
    },
    {
      "id": 214,
      "x": -2,
      "y": -12,
      "z": -6,
      "c": "#9e9e9e"
    },
    {
      "id": 215,
      "x": -2,
      "y": -12,
      "z": -5,
      "c": "#9e9e9e"
    },
    {
      "id": 216,
      "x": -2,
      "y": -12,
      "z": -4,
      "c": "#9e9e9e"
    },
    {
      "id": 217,
      "x": -2,
      "y": -12,
      "z": -3,
      "c": "#9e9e9e"
    },
    {
      "id": 218,
      "x": -2,
      "y": -12,
      "z": -2,
      "c": "#9e9e9e"
    },
    {
      "id": 219,
      "x": -2,
      "y": -12,
      "z": -1,
      "c": "#9e9e9e"
    },
    {
      "id": 220,
      "x": -2,
      "y": -12,
      "z": 0,
      "c": "#9e9e9e"
    },
    {
      "id": 221,
      "x": -2,
      "y": -12,
      "z": 1,
      "c": "#9e9e9e"
    },
    {
      "id": 222,
      "x": -2,
      "y": -12,
      "z": 2,
      "c": "#9e9e9e"
    },
    {
      "id": 223,
      "x": -2,
      "y": -12,
      "z": 3,
      "c": "#9e9e9e"
    },
    {
      "id": 224,
      "x": -2,
      "y": -12,
      "z": 4,
      "c": "#9e9e9e"
    },
    {
      "id": 225,
      "x": -2,
      "y": -12,
      "z": 5,
      "c": "#9e9e9e"
    },
    {
      "id": 226,
      "x": -2,
      "y": -12,
      "z": 6,
      "c": "#9e9e9e"
    },
    {
      "id": 227,
      "x": -2,
      "y": -12,
      "z": 7,
      "c": "#9e9e9e"
    },
    {
      "id": 228,
      "x": -2,
      "y": -12,
      "z": 8,
      "c": "#9e9e9e"
    },
    {
      "id": 229,
      "x": -2,
      "y": -12,
      "z": 9,
      "c": "#9e9e9e"
    },
    {
      "id": 230,
      "x": -2,
      "y": -12,
      "z": 10,
      "c": "#9e9e9e"
    },
    {
      "id": 231,
      "x": -1,
      "y": -12,
      "z": -10,
      "c": "#9e9e9e"
    },
    {
      "id": 232,
      "x": -1,
      "y": -12,
      "z": -9,
      "c": "#9e9e9e"
    },
    {
      "id": 233,
      "x": -1,
      "y": -12,
      "z": -8,
      "c": "#9e9e9e"
    },
    {
      "id": 234,
      "x": -1,
      "y": -12,
      "z": -7,
      "c": "#9e9e9e"
    },
    {
      "id": 235,
      "x": -1,
      "y": -12,
      "z": -6,
      "c": "#9e9e9e"
    },
    {
      "id": 236,
      "x": -1,
      "y": -12,
      "z": -5,
      "c": "#9e9e9e"
    },
    {
      "id": 237,
      "x": -1,
      "y": -12,
      "z": -4,
      "c": "#9e9e9e"
    },
    {
      "id": 238,
      "x": -1,
      "y": -12,
      "z": -3,
      "c": "#9e9e9e"
    },
    {
      "id": 239,
      "x": -1,
      "y": -12,
      "z": -2,
      "c": "#9e9e9e"
    },
    {
      "id": 240,
      "x": -1,
      "y": -12,
      "z": -1,
      "c": "#9e9e9e"
    },
    {
      "id": 241,
      "x": -1,
      "y": -12,
      "z": 0,
      "c": "#9e9e9e"
    },
    {
      "id": 242,
      "x": -1,
      "y": -12,
      "z": 1,
      "c": "#9e9e9e"
    },
    {
      "id": 243,
      "x": -1,
      "y": -12,
      "z": 2,
      "c": "#9e9e9e"
    },
    {
      "id": 244,
      "x": -1,
      "y": -12,
      "z": 3,
      "c": "#9e9e9e"
    },
    {
      "id": 245,
      "x": -1,
      "y": -12,
      "z": 4,
      "c": "#9e9e9e"
    },
    {
      "id": 246,
      "x": -1,
      "y": -12,
      "z": 5,
      "c": "#9e9e9e"
    },
    {
      "id": 247,
      "x": -1,
      "y": -12,
      "z": 6,
      "c": "#9e9e9e"
    },
    {
      "id": 248,
      "x": -1,
      "y": -12,
      "z": 7,
      "c": "#9e9e9e"
    },
    {
      "id": 249,
      "x": -1,
      "y": -12,
      "z": 8,
      "c": "#9e9e9e"
    },
    {
      "id": 250,
      "x": -1,
      "y": -12,
      "z": 9,
      "c": "#9e9e9e"
    },
    {
      "id": 251,
      "x": -1,
      "y": -12,
      "z": 10,
      "c": "#9e9e9e"
    },
    {
      "id": 252,
      "x": 0,
      "y": -12,
      "z": -10,
      "c": "#9e9e9e"
    },
    {
      "id": 253,
      "x": 0,
      "y": -12,
      "z": -9,
      "c": "#9e9e9e"
    },
    {
      "id": 254,
      "x": 0,
      "y": -12,
      "z": -8,
      "c": "#9e9e9e"
    },
    {
      "id": 255,
      "x": 0,
      "y": -12,
      "z": -7,
      "c": "#9e9e9e"
    },
    {
      "id": 256,
      "x": 0,
      "y": -12,
      "z": -6,
      "c": "#9e9e9e"
    },
    {
      "id": 257,
      "x": 0,
      "y": -12,
      "z": -5,
      "c": "#9e9e9e"
    },
    {
      "id": 258,
      "x": 0,
      "y": -12,
      "z": -4,
      "c": "#9e9e9e"
    },
    {
      "id": 259,
      "x": 0,
      "y": -12,
      "z": -3,
      "c": "#9e9e9e"
    },
    {
      "id": 260,
      "x": 0,
      "y": -12,
      "z": -2,
      "c": "#9e9e9e"
    },
    {
      "id": 261,
      "x": 0,
      "y": -12,
      "z": -1,
      "c": "#9e9e9e"
    },
    {
      "id": 262,
      "x": 0,
      "y": -12,
      "z": 0,
      "c": "#9e9e9e"
    },
    {
      "id": 263,
      "x": 0,
      "y": -12,
      "z": 1,
      "c": "#9e9e9e"
    },
    {
      "id": 264,
      "x": 0,
      "y": -12,
      "z": 2,
      "c": "#9e9e9e"
    },
    {
      "id": 265,
      "x": 0,
      "y": -12,
      "z": 3,
      "c": "#9e9e9e"
    },
    {
      "id": 266,
      "x": 0,
      "y": -12,
      "z": 4,
      "c": "#9e9e9e"
    },
    {
      "id": 267,
      "x": 0,
      "y": -12,
      "z": 5,
      "c": "#9e9e9e"
    },
    {
      "id": 268,
      "x": 0,
      "y": -12,
      "z": 6,
      "c": "#9e9e9e"
    },
    {
      "id": 269,
      "x": 0,
      "y": -12,
      "z": 7,
      "c": "#9e9e9e"
    },
    {
      "id": 270,
      "x": 0,
      "y": -12,
      "z": 8,
      "c": "#9e9e9e"
    },
    {
      "id": 271,
      "x": 0,
      "y": -12,
      "z": 9,
      "c": "#9e9e9e"
    },
    {
      "id": 272,
      "x": 0,
      "y": -12,
      "z": 10,
      "c": "#9e9e9e"
    },
    {
      "id": 273,
      "x": 1,
      "y": -12,
      "z": -10,
      "c": "#228b22"
    },
    {
      "id": 274,
      "x": 1,
      "y": -12,
      "z": -9,
      "c": "#228b22"
    },
    {
      "id": 275,
      "x": 1,
      "y": -12,
      "z": -8,
      "c": "#228b22"
    },
    {
      "id": 276,
      "x": 1,
      "y": -12,
      "z": -7,
      "c": "#228b22"
    },
    {
      "id": 277,
      "x": 1,
      "y": -12,
      "z": -6,
      "c": "#228b22"
    },
    {
      "id": 278,
      "x": 1,
      "y": -12,
      "z": -5,
      "c": "#228b22"
    },
    {
      "id": 279,
      "x": 1,
      "y": -12,
      "z": -4,
      "c": "#228b22"
    },
    {
      "id": 280,
      "x": 1,
      "y": -12,
      "z": -3,
      "c": "#228b22"
    },
    {
      "id": 281,
      "x": 1,
      "y": -12,
      "z": -2,
      "c": "#9e9e9e"
    },
    {
      "id": 282,
      "x": 1,
      "y": -12,
      "z": -1,
      "c": "#9e9e9e"
    },
    {
      "id": 283,
      "x": 1,
      "y": -12,
      "z": 0,
      "c": "#9e9e9e"
    },
    {
      "id": 284,
      "x": 1,
      "y": -12,
      "z": 1,
      "c": "#9e9e9e"
    },
    {
      "id": 285,
      "x": 1,
      "y": -12,
      "z": 2,
      "c": "#9e9e9e"
    },
    {
      "id": 286,
      "x": 1,
      "y": -12,
      "z": 3,
      "c": "#9e9e9e"
    },
    {
      "id": 287,
      "x": 1,
      "y": -12,
      "z": 4,
      "c": "#9e9e9e"
    },
    {
      "id": 288,
      "x": 1,
      "y": -12,
      "z": 5,
      "c": "#9e9e9e"
    },
    {
      "id": 289,
      "x": 1,
      "y": -12,
      "z": 6,
      "c": "#9e9e9e"
    },
    {
      "id": 290,
      "x": 1,
      "y": -12,
      "z": 7,
      "c": "#9e9e9e"
    },
    {
      "id": 291,
      "x": 1,
      "y": -12,
      "z": 8,
      "c": "#9e9e9e"
    },
    {
      "id": 292,
      "x": 1,
      "y": -12,
      "z": 9,
      "c": "#9e9e9e"
    },
    {
      "id": 293,
      "x": 1,
      "y": -12,
      "z": 10,
      "c": "#9e9e9e"
    },
    {
      "id": 294,
      "x": 2,
      "y": -12,
      "z": -10,
      "c": "#228b22"
    },
    {
      "id": 295,
      "x": 2,
      "y": -12,
      "z": -9,
      "c": "#228b22"
    },
    {
      "id": 296,
      "x": 2,
      "y": -12,
      "z": -8,
      "c": "#228b22"
    },
    {
      "id": 297,
      "x": 2,
      "y": -12,
      "z": -7,
      "c": "#228b22"
    },
    {
      "id": 298,
      "x": 2,
      "y": -12,
      "z": -6,
      "c": "#228b22"
    },
    {
      "id": 299,
      "x": 2,
      "y": -12,
      "z": -5,
      "c": "#228b22"
    },
    {
      "id": 300,
      "x": 2,
      "y": -12,
      "z": -4,
      "c": "#228b22"
    },
    {
      "id": 301,
      "x": 2,
      "y": -12,
      "z": -3,
      "c": "#228b22"
    },
    {
      "id": 302,
      "x": 2,
      "y": -12,
      "z": -2,
      "c": "#9e9e9e"
    },
    {
      "id": 303,
      "x": 2,
      "y": -12,
      "z": -1,
      "c": "#9e9e9e"
    },
    {
      "id": 304,
      "x": 2,
      "y": -12,
      "z": 0,
      "c": "#9e9e9e"
    },
    {
      "id": 305,
      "x": 2,
      "y": -12,
      "z": 1,
      "c": "#9e9e9e"
    },
    {
      "id": 306,
      "x": 2,
      "y": -12,
      "z": 2,
      "c": "#9e9e9e"
    },
    {
      "id": 307,
      "x": 2,
      "y": -12,
      "z": 3,
      "c": "#9e9e9e"
    },
    {
      "id": 308,
      "x": 2,
      "y": -12,
      "z": 4,
      "c": "#9e9e9e"
    },
    {
      "id": 309,
      "x": 2,
      "y": -12,
      "z": 5,
      "c": "#9e9e9e"
    },
    {
      "id": 310,
      "x": 2,
      "y": -12,
      "z": 6,
      "c": "#9e9e9e"
    },
    {
      "id": 311,
      "x": 2,
      "y": -12,
      "z": 7,
      "c": "#9e9e9e"
    },
    {
      "id": 312,
      "x": 2,
      "y": -12,
      "z": 8,
      "c": "#9e9e9e"
    },
    {
      "id": 313,
      "x": 2,
      "y": -12,
      "z": 9,
      "c": "#9e9e9e"
    },
    {
      "id": 314,
      "x": 2,
      "y": -12,
      "z": 10,
      "c": "#9e9e9e"
    },
    {
      "id": 315,
      "x": 3,
      "y": -12,
      "z": -10,
      "c": "#228b22"
    },
    {
      "id": 316,
      "x": 3,
      "y": -12,
      "z": -9,
      "c": "#228b22"
    },
    {
      "id": 317,
      "x": 3,
      "y": -12,
      "z": -8,
      "c": "#228b22"
    },
    {
      "id": 318,
      "x": 3,
      "y": -12,
      "z": -7,
      "c": "#228b22"
    },
    {
      "id": 319,
      "x": 3,
      "y": -12,
      "z": -6,
      "c": "#228b22"
    },
    {
      "id": 320,
      "x": 3,
      "y": -12,
      "z": -5,
      "c": "#228b22"
    },
    {
      "id": 321,
      "x": 3,
      "y": -12,
      "z": -4,
      "c": "#228b22"
    },
    {
      "id": 322,
      "x": 3,
      "y": -12,
      "z": -3,
      "c": "#228b22"
    },
    {
      "id": 323,
      "x": 3,
      "y": -12,
      "z": -2,
      "c": "#9e9e9e"
    },
    {
      "id": 324,
      "x": 3,
      "y": -12,
      "z": -1,
      "c": "#9e9e9e"
    },
    {
      "id": 325,
      "x": 3,
      "y": -12,
      "z": 0,
      "c": "#9e9e9e"
    },
    {
      "id": 326,
      "x": 3,
      "y": -12,
      "z": 1,
      "c": "#9e9e9e"
    },
    {
      "id": 327,
      "x": 3,
      "y": -12,
      "z": 2,
      "c": "#9e9e9e"
    },
    {
      "id": 328,
      "x": 3,
      "y": -12,
      "z": 3,
      "c": "#424242"
    },
    {
      "id": 329,
      "x": 3,
      "y": -12,
      "z": 4,
      "c": "#424242"
    },
    {
      "id": 330,
      "x": 3,
      "y": -12,
      "z": 5,
      "c": "#424242"
    },
    {
      "id": 331,
      "x": 3,
      "y": -12,
      "z": 6,
      "c": "#424242"
    },
    {
      "id": 332,
      "x": 3,
      "y": -12,
      "z": 7,
      "c": "#424242"
    },
    {
      "id": 333,
      "x": 3,
      "y": -12,
      "z": 8,
      "c": "#424242"
    },
    {
      "id": 334,
      "x": 3,
      "y": -12,
      "z": 9,
      "c": "#424242"
    },
    {
      "id": 335,
      "x": 3,
      "y": -12,
      "z": 10,
      "c": "#424242"
    },
    {
      "id": 336,
      "x": 4,
      "y": -12,
      "z": -10,
      "c": "#228b22"
    },
    {
      "id": 337,
      "x": 4,
      "y": -12,
      "z": -9,
      "c": "#228b22"
    },
    {
      "id": 338,
      "x": 4,
      "y": -12,
      "z": -8,
      "c": "#228b22"
    },
    {
      "id": 339,
      "x": 4,
      "y": -12,
      "z": -7,
      "c": "#228b22"
    },
    {
      "id": 340,
      "x": 4,
      "y": -12,
      "z": -6,
      "c": "#228b22"
    },
    {
      "id": 341,
      "x": 4,
      "y": -12,
      "z": -5,
      "c": "#228b22"
    },
    {
      "id": 342,
      "x": 4,
      "y": -12,
      "z": -4,
      "c": "#228b22"
    },
    {
      "id": 343,
      "x": 4,
      "y": -12,
      "z": -3,
      "c": "#228b22"
    },
    {
      "id": 344,
      "x": 4,
      "y": -12,
      "z": -2,
      "c": "#9e9e9e"
    },
    {
      "id": 345,
      "x": 4,
      "y": -12,
      "z": -1,
      "c": "#9e9e9e"
    },
    {
      "id": 346,
      "x": 4,
      "y": -12,
      "z": 0,
      "c": "#9e9e9e"
    },
    {
      "id": 347,
      "x": 4,
      "y": -12,
      "z": 1,
      "c": "#9e9e9e"
    },
    {
      "id": 348,
      "x": 4,
      "y": -12,
      "z": 2,
      "c": "#9e9e9e"
    },
    {
      "id": 349,
      "x": 4,
      "y": -12,
      "z": 3,
      "c": "#424242"
    },
    {
      "id": 350,
      "x": 4,
      "y": -12,
      "z": 4,
      "c": "#424242"
    },
    {
      "id": 351,
      "x": 4,
      "y": -12,
      "z": 5,
      "c": "#424242"
    },
    {
      "id": 352,
      "x": 4,
      "y": -12,
      "z": 6,
      "c": "#424242"
    },
    {
      "id": 353,
      "x": 4,
      "y": -12,
      "z": 7,
      "c": "#424242"
    },
    {
      "id": 354,
      "x": 4,
      "y": -12,
      "z": 8,
      "c": "#424242"
    },
    {
      "id": 355,
      "x": 4,
      "y": -12,
      "z": 9,
      "c": "#424242"
    },
    {
      "id": 356,
      "x": 4,
      "y": -12,
      "z": 10,
      "c": "#424242"
    },
    {
      "id": 357,
      "x": 5,
      "y": -12,
      "z": -10,
      "c": "#228b22"
    },
    {
      "id": 358,
      "x": 5,
      "y": -12,
      "z": -9,
      "c": "#228b22"
    },
    {
      "id": 359,
      "x": 5,
      "y": -12,
      "z": -8,
      "c": "#228b22"
    },
    {
      "id": 360,
      "x": 5,
      "y": -12,
      "z": -7,
      "c": "#228b22"
    },
    {
      "id": 361,
      "x": 5,
      "y": -12,
      "z": -6,
      "c": "#228b22"
    },
    {
      "id": 362,
      "x": 5,
      "y": -12,
      "z": -5,
      "c": "#228b22"
    },
    {
      "id": 363,
      "x": 5,
      "y": -12,
      "z": -4,
      "c": "#228b22"
    },
    {
      "id": 364,
      "x": 5,
      "y": -12,
      "z": -3,
      "c": "#228b22"
    },
    {
      "id": 365,
      "x": 5,
      "y": -12,
      "z": -2,
      "c": "#9e9e9e"
    },
    {
      "id": 366,
      "x": 5,
      "y": -12,
      "z": -1,
      "c": "#9e9e9e"
    },
    {
      "id": 367,
      "x": 5,
      "y": -12,
      "z": 0,
      "c": "#9e9e9e"
    },
    {
      "id": 368,
      "x": 5,
      "y": -12,
      "z": 1,
      "c": "#9e9e9e"
    },
    {
      "id": 369,
      "x": 5,
      "y": -12,
      "z": 2,
      "c": "#9e9e9e"
    },
    {
      "id": 370,
      "x": 5,
      "y": -12,
      "z": 3,
      "c": "#424242"
    },
    {
      "id": 371,
      "x": 5,
      "y": -12,
      "z": 4,
      "c": "#424242"
    },
    {
      "id": 372,
      "x": 5,
      "y": -12,
      "z": 5,
      "c": "#424242"
    },
    {
      "id": 373,
      "x": 5,
      "y": -12,
      "z": 6,
      "c": "#424242"
    },
    {
      "id": 374,
      "x": 5,
      "y": -12,
      "z": 7,
      "c": "#424242"
    },
    {
      "id": 375,
      "x": 5,
      "y": -12,
      "z": 8,
      "c": "#424242"
    },
    {
      "id": 376,
      "x": 5,
      "y": -12,
      "z": 9,
      "c": "#424242"
    },
    {
      "id": 377,
      "x": 5,
      "y": -12,
      "z": 10,
      "c": "#424242"
    },
    {
      "id": 378,
      "x": 6,
      "y": -12,
      "z": -10,
      "c": "#228b22"
    },
    {
      "id": 379,
      "x": 6,
      "y": -12,
      "z": -9,
      "c": "#228b22"
    },
    {
      "id": 380,
      "x": 6,
      "y": -12,
      "z": -8,
      "c": "#228b22"
    },
    {
      "id": 381,
      "x": 6,
      "y": -12,
      "z": -7,
      "c": "#228b22"
    },
    {
      "id": 382,
      "x": 6,
      "y": -12,
      "z": -6,
      "c": "#228b22"
    },
    {
      "id": 383,
      "x": 6,
      "y": -12,
      "z": -5,
      "c": "#228b22"
    },
    {
      "id": 384,
      "x": 6,
      "y": -12,
      "z": -4,
      "c": "#228b22"
    },
    {
      "id": 385,
      "x": 6,
      "y": -12,
      "z": -3,
      "c": "#228b22"
    },
    {
      "id": 386,
      "x": 6,
      "y": -12,
      "z": -2,
      "c": "#9e9e9e"
    },
    {
      "id": 387,
      "x": 6,
      "y": -12,
      "z": -1,
      "c": "#9e9e9e"
    },
    {
      "id": 388,
      "x": 6,
      "y": -12,
      "z": 0,
      "c": "#9e9e9e"
    },
    {
      "id": 389,
      "x": 6,
      "y": -12,
      "z": 1,
      "c": "#9e9e9e"
    },
    {
      "id": 390,
      "x": 6,
      "y": -12,
      "z": 2,
      "c": "#9e9e9e"
    },
    {
      "id": 391,
      "x": 6,
      "y": -12,
      "z": 3,
      "c": "#424242"
    },
    {
      "id": 392,
      "x": 6,
      "y": -12,
      "z": 4,
      "c": "#424242"
    },
    {
      "id": 393,
      "x": 6,
      "y": -12,
      "z": 5,
      "c": "#424242"
    },
    {
      "id": 394,
      "x": 6,
      "y": -12,
      "z": 6,
      "c": "#424242"
    },
    {
      "id": 395,
      "x": 6,
      "y": -12,
      "z": 7,
      "c": "#424242"
    },
    {
      "id": 396,
      "x": 6,
      "y": -12,
      "z": 8,
      "c": "#424242"
    },
    {
      "id": 397,
      "x": 6,
      "y": -12,
      "z": 9,
      "c": "#424242"
    },
    {
      "id": 398,
      "x": 6,
      "y": -12,
      "z": 10,
      "c": "#424242"
    },
    {
      "id": 399,
      "x": 7,
      "y": -12,
      "z": -10,
      "c": "#228b22"
    },
    {
      "id": 400,
      "x": 7,
      "y": -12,
      "z": -9,
      "c": "#228b22"
    },
    {
      "id": 401,
      "x": 7,
      "y": -12,
      "z": -8,
      "c": "#228b22"
    },
    {
      "id": 402,
      "x": 7,
      "y": -12,
      "z": -7,
      "c": "#228b22"
    },
    {
      "id": 403,
      "x": 7,
      "y": -12,
      "z": -6,
      "c": "#228b22"
    },
    {
      "id": 404,
      "x": 7,
      "y": -12,
      "z": -5,
      "c": "#228b22"
    },
    {
      "id": 405,
      "x": 7,
      "y": -12,
      "z": -4,
      "c": "#228b22"
    },
    {
      "id": 406,
      "x": 7,
      "y": -12,
      "z": -3,
      "c": "#228b22"
    },
    {
      "id": 407,
      "x": 7,
      "y": -12,
      "z": -2,
      "c": "#9e9e9e"
    },
    {
      "id": 408,
      "x": 7,
      "y": -12,
      "z": -1,
      "c": "#9e9e9e"
    },
    {
      "id": 409,
      "x": 7,
      "y": -12,
      "z": 0,
      "c": "#9e9e9e"
    },
    {
      "id": 410,
      "x": 7,
      "y": -12,
      "z": 1,
      "c": "#9e9e9e"
    },
    {
      "id": 411,
      "x": 7,
      "y": -12,
      "z": 2,
      "c": "#9e9e9e"
    },
    {
      "id": 412,
      "x": 7,
      "y": -12,
      "z": 3,
      "c": "#424242"
    },
    {
      "id": 413,
      "x": 7,
      "y": -12,
      "z": 4,
      "c": "#424242"
    },
    {
      "id": 414,
      "x": 7,
      "y": -12,
      "z": 5,
      "c": "#424242"
    },
    {
      "id": 415,
      "x": 7,
      "y": -12,
      "z": 6,
      "c": "#424242"
    },
    {
      "id": 416,
      "x": 7,
      "y": -12,
      "z": 7,
      "c": "#424242"
    },
    {
      "id": 417,
      "x": 7,
      "y": -12,
      "z": 8,
      "c": "#424242"
    },
    {
      "id": 418,
      "x": 7,
      "y": -12,
      "z": 9,
      "c": "#424242"
    },
    {
      "id": 419,
      "x": 7,
      "y": -12,
      "z": 10,
      "c": "#424242"
    },
    {
      "id": 420,
      "x": 8,
      "y": -12,
      "z": -10,
      "c": "#228b22"
    },
    {
      "id": 421,
      "x": 8,
      "y": -12,
      "z": -9,
      "c": "#228b22"
    },
    {
      "id": 422,
      "x": 8,
      "y": -12,
      "z": -8,
      "c": "#228b22"
    },
    {
      "id": 423,
      "x": 8,
      "y": -12,
      "z": -7,
      "c": "#228b22"
    },
    {
      "id": 424,
      "x": 8,
      "y": -12,
      "z": -6,
      "c": "#228b22"
    },
    {
      "id": 425,
      "x": 8,
      "y": -12,
      "z": -5,
      "c": "#228b22"
    },
    {
      "id": 426,
      "x": 8,
      "y": -12,
      "z": -4,
      "c": "#228b22"
    },
    {
      "id": 427,
      "x": 8,
      "y": -12,
      "z": -3,
      "c": "#228b22"
    },
    {
      "id": 428,
      "x": 8,
      "y": -12,
      "z": -2,
      "c": "#9e9e9e"
    },
    {
      "id": 429,
      "x": 8,
      "y": -12,
      "z": -1,
      "c": "#9e9e9e"
    },
    {
      "id": 430,
      "x": 8,
      "y": -12,
      "z": 0,
      "c": "#9e9e9e"
    },
    {
      "id": 431,
      "x": 8,
      "y": -12,
      "z": 1,
      "c": "#9e9e9e"
    },
    {
      "id": 432,
      "x": 8,
      "y": -12,
      "z": 2,
      "c": "#9e9e9e"
    },
    {
      "id": 433,
      "x": 8,
      "y": -12,
      "z": 3,
      "c": "#424242"
    },
    {
      "id": 434,
      "x": 8,
      "y": -12,
      "z": 4,
      "c": "#424242"
    },
    {
      "id": 435,
      "x": 8,
      "y": -12,
      "z": 5,
      "c": "#424242"
    },
    {
      "id": 436,
      "x": 8,
      "y": -12,
      "z": 6,
      "c": "#424242"
    },
    {
      "id": 437,
      "x": 8,
      "y": -12,
      "z": 7,
      "c": "#424242"
    },
    {
      "id": 438,
      "x": 8,
      "y": -12,
      "z": 8,
      "c": "#424242"
    },
    {
      "id": 439,
      "x": 8,
      "y": -12,
      "z": 9,
      "c": "#424242"
    },
    {
      "id": 440,
      "x": 8,
      "y": -12,
      "z": 10,
      "c": "#424242"
    },
    {
      "id": 441,
      "x": 9,
      "y": -12,
      "z": -10,
      "c": "#228b22"
    },
    {
      "id": 442,
      "x": 9,
      "y": -12,
      "z": -9,
      "c": "#228b22"
    },
    {
      "id": 443,
      "x": 9,
      "y": -12,
      "z": -8,
      "c": "#228b22"
    },
    {
      "id": 444,
      "x": 9,
      "y": -12,
      "z": -7,
      "c": "#228b22"
    },
    {
      "id": 445,
      "x": 9,
      "y": -12,
      "z": -6,
      "c": "#228b22"
    },
    {
      "id": 446,
      "x": 9,
      "y": -12,
      "z": -5,
      "c": "#228b22"
    },
    {
      "id": 447,
      "x": 9,
      "y": -12,
      "z": -4,
      "c": "#228b22"
    },
    {
      "id": 448,
      "x": 9,
      "y": -12,
      "z": -3,
      "c": "#228b22"
    },
    {
      "id": 449,
      "x": 9,
      "y": -12,
      "z": -2,
      "c": "#9e9e9e"
    },
    {
      "id": 450,
      "x": 9,
      "y": -12,
      "z": -1,
      "c": "#9e9e9e"
    },
    {
      "id": 451,
      "x": 9,
      "y": -12,
      "z": 0,
      "c": "#9e9e9e"
    },
    {
      "id": 452,
      "x": 9,
      "y": -12,
      "z": 1,
      "c": "#9e9e9e"
    },
    {
      "id": 453,
      "x": 9,
      "y": -12,
      "z": 2,
      "c": "#9e9e9e"
    },
    {
      "id": 454,
      "x": 9,
      "y": -12,
      "z": 3,
      "c": "#424242"
    },
    {
      "id": 455,
      "x": 9,
      "y": -12,
      "z": 4,
      "c": "#424242"
    },
    {
      "id": 456,
      "x": 9,
      "y": -12,
      "z": 5,
      "c": "#424242"
    },
    {
      "id": 457,
      "x": 9,
      "y": -12,
      "z": 6,
      "c": "#424242"
    },
    {
      "id": 458,
      "x": 9,
      "y": -12,
      "z": 7,
      "c": "#424242"
    },
    {
      "id": 459,
      "x": 9,
      "y": -12,
      "z": 8,
      "c": "#424242"
    },
    {
      "id": 460,
      "x": 9,
      "y": -12,
      "z": 9,
      "c": "#424242"
    },
    {
      "id": 461,
      "x": 9,
      "y": -12,
      "z": 10,
      "c": "#424242"
    },
    {
      "id": 462,
      "x": 10,
      "y": -12,
      "z": -10,
      "c": "#228b22"
    },
    {
      "id": 463,
      "x": 10,
      "y": -12,
      "z": -9,
      "c": "#228b22"
    },
    {
      "id": 464,
      "x": 10,
      "y": -12,
      "z": -8,
      "c": "#228b22"
    },
    {
      "id": 465,
      "x": 10,
      "y": -12,
      "z": -7,
      "c": "#228b22"
    },
    {
      "id": 466,
      "x": 10,
      "y": -12,
      "z": -6,
      "c": "#228b22"
    },
    {
      "id": 467,
      "x": 10,
      "y": -12,
      "z": -5,
      "c": "#228b22"
    },
    {
      "id": 468,
      "x": 10,
      "y": -12,
      "z": -4,
      "c": "#228b22"
    },
    {
      "id": 469,
      "x": 10,
      "y": -12,
      "z": -3,
      "c": "#228b22"
    },
    {
      "id": 470,
      "x": 10,
      "y": -12,
      "z": -2,
      "c": "#9e9e9e"
    },
    {
      "id": 471,
      "x": 10,
      "y": -12,
      "z": -1,
      "c": "#9e9e9e"
    },
    {
      "id": 472,
      "x": 10,
      "y": -12,
      "z": 0,
      "c": "#9e9e9e"
    },
    {
      "id": 473,
      "x": 10,
      "y": -12,
      "z": 1,
      "c": "#9e9e9e"
    },
    {
      "id": 474,
      "x": 10,
      "y": -12,
      "z": 2,
      "c": "#9e9e9e"
    },
    {
      "id": 475,
      "x": 10,
      "y": -12,
      "z": 3,
      "c": "#424242"
    },
    {
      "id": 476,
      "x": 10,
      "y": -12,
      "z": 4,
      "c": "#424242"
    },
    {
      "id": 477,
      "x": 10,
      "y": -12,
      "z": 5,
      "c": "#424242"
    },
    {
      "id": 478,
      "x": 10,
      "y": -12,
      "z": 6,
      "c": "#424242"
    },
    {
      "id": 479,
      "x": 10,
      "y": -12,
      "z": 7,
      "c": "#424242"
    },
    {
      "id": 480,
      "x": 10,
      "y": -12,
      "z": 8,
      "c": "#424242"
    },
    {
      "id": 481,
      "x": 10,
      "y": -12,
      "z": 9,
      "c": "#424242"
    },
    {
      "id": 482,
      "x": 10,
      "y": -12,
      "z": 10,
      "c": "#424242"
    },
    {
      "id": 483,
      "x": 11,
      "y": -12,
      "z": -10,
      "c": "#228b22"
    },
    {
      "id": 484,
      "x": 11,
      "y": -12,
      "z": -9,
      "c": "#228b22"
    },
    {
      "id": 485,
      "x": 11,
      "y": -12,
      "z": -8,
      "c": "#228b22"
    },
    {
      "id": 486,
      "x": 11,
      "y": -12,
      "z": -7,
      "c": "#228b22"
    },
    {
      "id": 487,
      "x": 11,
      "y": -12,
      "z": -6,
      "c": "#228b22"
    },
    {
      "id": 488,
      "x": 11,
      "y": -12,
      "z": -5,
      "c": "#228b22"
    },
    {
      "id": 489,
      "x": 11,
      "y": -12,
      "z": -4,
      "c": "#228b22"
    },
    {
      "id": 490,
      "x": 11,
      "y": -12,
      "z": -3,
      "c": "#228b22"
    },
    {
      "id": 491,
      "x": 11,
      "y": -12,
      "z": -2,
      "c": "#9e9e9e"
    },
    {
      "id": 492,
      "x": 11,
      "y": -12,
      "z": -1,
      "c": "#9e9e9e"
    },
    {
      "id": 493,
      "x": 11,
      "y": -12,
      "z": 0,
      "c": "#9e9e9e"
    },
    {
      "id": 494,
      "x": 11,
      "y": -12,
      "z": 1,
      "c": "#9e9e9e"
    },
    {
      "id": 495,
      "x": 11,
      "y": -12,
      "z": 2,
      "c": "#9e9e9e"
    },
    {
      "id": 496,
      "x": 11,
      "y": -12,
      "z": 3,
      "c": "#424242"
    },
    {
      "id": 497,
      "x": 11,
      "y": -12,
      "z": 4,
      "c": "#424242"
    },
    {
      "id": 498,
      "x": 11,
      "y": -12,
      "z": 5,
      "c": "#424242"
    },
    {
      "id": 499,
      "x": 11,
      "y": -12,
      "z": 6,
      "c": "#424242"
    },
    {
      "id": 500,
      "x": 11,
      "y": -12,
      "z": 7,
      "c": "#424242"
    },
    {
      "id": 501,
      "x": 11,
      "y": -12,
      "z": 8,
      "c": "#424242"
    },
    {
      "id": 502,
      "x": 11,
      "y": -12,
      "z": 9,
      "c": "#424242"
    },
    {
      "id": 503,
      "x": 11,
      "y": -12,
      "z": 10,
      "c": "#424242"
    },
    {
      "id": 504,
      "x": 12,
      "y": -12,
      "z": -10,
      "c": "#228b22"
    },
    {
      "id": 505,
      "x": 12,
      "y": -12,
      "z": -9,
      "c": "#228b22"
    },
    {
      "id": 506,
      "x": 12,
      "y": -12,
      "z": -8,
      "c": "#228b22"
    },
    {
      "id": 507,
      "x": 12,
      "y": -12,
      "z": -7,
      "c": "#228b22"
    },
    {
      "id": 508,
      "x": 12,
      "y": -12,
      "z": -6,
      "c": "#228b22"
    },
    {
      "id": 509,
      "x": 12,
      "y": -12,
      "z": -5,
      "c": "#228b22"
    },
    {
      "id": 510,
      "x": 12,
      "y": -12,
      "z": -4,
      "c": "#228b22"
    },
    {
      "id": 511,
      "x": 12,
      "y": -12,
      "z": -3,
      "c": "#228b22"
    },
    {
      "id": 512,
      "x": 12,
      "y": -12,
      "z": -2,
      "c": "#9e9e9e"
    },
    {
      "id": 513,
      "x": 12,
      "y": -12,
      "z": -1,
      "c": "#9e9e9e"
    },
    {
      "id": 514,
      "x": 12,
      "y": -12,
      "z": 0,
      "c": "#9e9e9e"
    },
    {
      "id": 515,
      "x": 12,
      "y": -12,
      "z": 1,
      "c": "#9e9e9e"
    },
    {
      "id": 516,
      "x": 12,
      "y": -12,
      "z": 2,
      "c": "#9e9e9e"
    },
    {
      "id": 517,
      "x": 12,
      "y": -12,
      "z": 3,
      "c": "#424242"
    },
    {
      "id": 518,
      "x": 12,
      "y": -12,
      "z": 4,
      "c": "#424242"
    },
    {
      "id": 519,
      "x": 12,
      "y": -12,
      "z": 5,
      "c": "#424242"
    },
    {
      "id": 520,
      "x": 12,
      "y": -12,
      "z": 6,
      "c": "#424242"
    },
    {
      "id": 521,
      "x": 12,
      "y": -12,
      "z": 7,
      "c": "#424242"
    },
    {
      "id": 522,
      "x": 12,
      "y": -12,
      "z": 8,
      "c": "#424242"
    },
    {
      "id": 523,
      "x": 12,
      "y": -12,
      "z": 9,
      "c": "#424242"
    },
    {
      "id": 524,
      "x": 12,
      "y": -12,
      "z": 10,
      "c": "#424242"
    },
    {
      "id": 525,
      "x": 4,
      "y": -11,
      "z": 4,
      "c": "#f0f0f0"
    },
    {
      "id": 526,
      "x": 4,
      "y": -11,
      "z": 8,
      "c": "#f0f0f0"
    },
    {
      "id": 527,
      "x": 5,
      "y": -11,
      "z": 4,
      "c": "#f0f0f0"
    },
    {
      "id": 528,
      "x": 5,
      "y": -11,
      "z": 8,
      "c": "#f0f0f0"
    },
    {
      "id": 529,
      "x": 6,
      "y": -11,
      "z": 4,
      "c": "#f0f0f0"
    },
    {
      "id": 530,
      "x": 6,
      "y": -11,
      "z": 8,
      "c": "#f0f0f0"
    },
    {
      "id": 531,
      "x": 7,
      "y": -11,
      "z": 4,
      "c": "#f0f0f0"
    },
    {
      "id": 532,
      "x": 7,
      "y": -11,
      "z": 8,
      "c": "#f0f0f0"
    },
    {
      "id": 533,
      "x": 8,
      "y": -11,
      "z": 4,
      "c": "#f0f0f0"
    },
    {
      "id": 534,
      "x": 8,
      "y": -11,
      "z": 8,
      "c": "#f0f0f0"
    },
    {
      "id": 535,
      "x": 9,
      "y": -11,
      "z": 4,
      "c": "#f0f0f0"
    },
    {
      "id": 536,
      "x": 9,
      "y": -11,
      "z": 8,
      "c": "#f0f0f0"
    },
    {
      "id": 537,
      "x": 10,
      "y": -11,
      "z": 4,
      "c": "#f0f0f0"
    },
    {
      "id": 538,
      "x": 10,
      "y": -11,
      "z": 8,
      "c": "#f0f0f0"
    },
    {
      "id": 539,
      "x": 4,
      "y": -11,
      "z": 5,
      "c": "#f0f0f0"
    },
    {
      "id": 540,
      "x": 10,
      "y": -11,
      "z": 5,
      "c": "#f0f0f0"
    },
    {
      "id": 541,
      "x": 7,
      "y": -11,
      "z": 5,
      "c": "#f0f0f0"
    },
    {
      "id": 542,
      "x": 4,
      "y": -11,
      "z": 6,
      "c": "#9e9e9e"
    },
    {
      "id": 543,
      "x": 10,
      "y": -11,
      "z": 6,
      "c": "#9e9e9e"
    },
    {
      "id": 544,
      "x": 7,
      "y": -11,
      "z": 6,
      "c": "#f0f0f0"
    },
    {
      "id": 545,
      "x": 4,
      "y": -11,
      "z": 7,
      "c": "#f0f0f0"
    },
    {
      "id": 546,
      "x": 10,
      "y": -11,
      "z": 7,
      "c": "#f0f0f0"
    },
    {
      "id": 547,
      "x": 7,
      "y": -11,
      "z": 7,
      "c": "#f0f0f0"
    },
    {
      "id": 548,
      "x": 4,
      "y": -10,
      "z": 6,
      "c": "#9e9e9e"
    },
    {
      "id": 549,
      "x": 10,
      "y": -10,
      "z": 6,
      "c": "#9e9e9e"
    },
    {
      "id": 550,
      "x": 4,
      "y": -9,
      "z": 6,
      "c": "#f0f0f0"
    },
    {
      "id": 551,
      "x": 10,
      "y": -9,
      "z": 6,
      "c": "#f0f0f0"
    },
    {
      "id": 552,
      "x": 8,
      "y": -11,
      "z": -6,
      "c": "#3b2f2f"
    },
    {
      "id": 553,
      "x": 8,
      "y": -10,
      "z": -6,
      "c": "#3b2f2f"
    },
    {
      "id": 554,
      "x": 8,
      "y": -9,
      "z": -6,
      "c": "#3b2f2f"
    },
    {
      "id": 555,
      "x": 7,
      "y": -9,
      "z": -6,
      "c": "#f44336"
    },
    {
      "id": 556,
      "x": 6,
      "y": -10,
      "z": -6,
      "c": "#f44336"
    },
    {
      "id": 557,
      "x": 5,
      "y": -11,
      "z": -6,
      "c": "#f44336"
    },
    {
      "id": 558,
      "x": -2,
      "y": -11,
      "z": 4,
      "c": "#f0f0f0"
    },
    {
      "id": 559,
      "x": -2,
      "y": -10,
      "z": 4,
      "c": "#f0f0f0"
    },
    {
      "id": 560,
      "x": -2,
      "y": -9,
      "z": 4,
      "c": "#f0f0f0"
    },
    {
      "id": 561,
      "x": -2,
      "y": -8,
      "z": 4,
      "c": "#f0f0f0"
    },
    {
      "id": 562,
      "x": -2,
      "y": -7,
      "z": 4,
      "c": "#f0f0f0"
    },
    {
      "id": 563,
      "x": -2,
      "y": -6,
      "z": 4,
      "c": "#424242"
    },
    {
      "id": 564,
      "x": -1,
      "y": -7,
      "z": 4,
      "c": "#2196f3"
    },
    {
      "id": 565,
      "x": 0,
      "y": -7,
      "z": 4,
      "c": "#f44336"
    },
    {
      "id": 566,
      "x": 1,
      "y": -7,
      "z": 4,
      "c": "#f0f0f0"
    },
    {
      "id": 567,
      "x": -10,
      "y": -11,
      "z": -8,
      "c": "#f44336"
    },
    {
      "id": 568,
      "x": -10,
      "y": -11,
      "z": -7,
      "c": "#f44336"
    },
    {
      "id": 569,
      "x": -10,
      "y": -11,
      "z": -6,
      "c": "#f44336"
    },
    {
      "id": 570,
      "x": -10,
      "y": -11,
      "z": -5,
      "c": "#f44336"
    },
    {
      "id": 571,
      "x": -10,
      "y": -11,
      "z": -4,
      "c": "#f44336"
    },
    {
      "id": 572,
      "x": -10,
      "y": -11,
      "z": -3,
      "c": "#f44336"
    },
    {
      "id": 573,
      "x": -10,
      "y": -11,
      "z": -2,
      "c": "#f44336"
    },
    {
      "id": 574,
      "x": -10,
      "y": -11,
      "z": -1,
      "c": "#f44336"
    },
    {
      "id": 575,
      "x": -10,
      "y": -11,
      "z": 0,
      "c": "#f44336"
    },
    {
      "id": 576,
      "x": -10,
      "y": -11,
      "z": 1,
      "c": "#f44336"
    },
    {
      "id": 577,
      "x": -10,
      "y": -11,
      "z": 2,
      "c": "#f44336"
    },
    {
      "id": 578,
      "x": -10,
      "y": -11,
      "z": 3,
      "c": "#f44336"
    },
    {
      "id": 579,
      "x": -10,
      "y": -11,
      "z": 4,
      "c": "#f44336"
    },
    {
      "id": 580,
      "x": -10,
      "y": -11,
      "z": 5,
      "c": "#f44336"
    },
    {
      "id": 581,
      "x": -10,
      "y": -11,
      "z": 6,
      "c": "#f44336"
    },
    {
      "id": 582,
      "x": -10,
      "y": -11,
      "z": 7,
      "c": "#f44336"
    },
    {
      "id": 583,
      "x": -10,
      "y": -11,
      "z": 8,
      "c": "#f44336"
    },
    {
      "id": 584,
      "x": -9,
      "y": -11,
      "z": -8,
      "c": "#f44336"
    },
    {
      "id": 585,
      "x": -9,
      "y": -11,
      "z": 8,
      "c": "#f44336"
    },
    {
      "id": 586,
      "x": -8,
      "y": -11,
      "z": -8,
      "c": "#f44336"
    },
    {
      "id": 587,
      "x": -8,
      "y": -11,
      "z": 8,
      "c": "#f44336"
    },
    {
      "id": 588,
      "x": -7,
      "y": -11,
      "z": -8,
      "c": "#f44336"
    },
    {
      "id": 589,
      "x": -7,
      "y": -11,
      "z": 8,
      "c": "#f44336"
    },
    {
      "id": 590,
      "x": -6,
      "y": -11,
      "z": -8,
      "c": "#f44336"
    },
    {
      "id": 591,
      "x": -6,
      "y": -11,
      "z": 8,
      "c": "#f44336"
    },
    {
      "id": 592,
      "x": -5,
      "y": -11,
      "z": -8,
      "c": "#f44336"
    },
    {
      "id": 593,
      "x": -5,
      "y": -11,
      "z": 8,
      "c": "#f44336"
    },
    {
      "id": 594,
      "x": -4,
      "y": -11,
      "z": -8,
      "c": "#f44336"
    },
    {
      "id": 595,
      "x": -4,
      "y": -11,
      "z": 8,
      "c": "#f44336"
    },
    {
      "id": 596,
      "x": -3,
      "y": -11,
      "z": 8,
      "c": "#f44336"
    },
    {
      "id": 597,
      "x": -2,
      "y": -11,
      "z": 8,
      "c": "#aeeeee"
    },
    {
      "id": 598,
      "x": -1,
      "y": -11,
      "z": 8,
      "c": "#f44336"
    },
    {
      "id": 599,
      "x": 0,
      "y": -11,
      "z": 2,
      "c": "#f44336"
    },
    {
      "id": 600,
      "x": 0,
      "y": -11,
      "z": 3,
      "c": "#f44336"
    },
    {
      "id": 601,
      "x": 0,
      "y": -11,
      "z": 4,
      "c": "#f44336"
    },
    {
      "id": 602,
      "x": 0,
      "y": -11,
      "z": 5,
      "c": "#f44336"
    },
    {
      "id": 603,
      "x": 0,
      "y": -11,
      "z": 6,
      "c": "#f44336"
    },
    {
      "id": 604,
      "x": 0,
      "y": -11,
      "z": 7,
      "c": "#f44336"
    },
    {
      "id": 605,
      "x": 0,
      "y": -11,
      "z": 8,
      "c": "#f44336"
    },
    {
      "id": 606,
      "x": -10,
      "y": -10,
      "z": -8,
      "c": "#f44336"
    },
    {
      "id": 607,
      "x": -10,
      "y": -10,
      "z": -7,
      "c": "#f44336"
    },
    {
      "id": 608,
      "x": -10,
      "y": -10,
      "z": -6,
      "c": "#f44336"
    },
    {
      "id": 609,
      "x": -10,
      "y": -10,
      "z": -5,
      "c": "#f44336"
    },
    {
      "id": 610,
      "x": -10,
      "y": -10,
      "z": -4,
      "c": "#f44336"
    },
    {
      "id": 611,
      "x": -10,
      "y": -10,
      "z": -3,
      "c": "#f44336"
    },
    {
      "id": 612,
      "x": -10,
      "y": -10,
      "z": -2,
      "c": "#f44336"
    },
    {
      "id": 613,
      "x": -10,
      "y": -10,
      "z": -1,
      "c": "#f44336"
    },
    {
      "id": 614,
      "x": -10,
      "y": -10,
      "z": 0,
      "c": "#f44336"
    },
    {
      "id": 615,
      "x": -10,
      "y": -10,
      "z": 1,
      "c": "#f44336"
    },
    {
      "id": 616,
      "x": -10,
      "y": -10,
      "z": 2,
      "c": "#f44336"
    },
    {
      "id": 617,
      "x": -10,
      "y": -10,
      "z": 3,
      "c": "#f44336"
    },
    {
      "id": 618,
      "x": -10,
      "y": -10,
      "z": 4,
      "c": "#f44336"
    },
    {
      "id": 619,
      "x": -10,
      "y": -10,
      "z": 5,
      "c": "#f44336"
    },
    {
      "id": 620,
      "x": -10,
      "y": -10,
      "z": 6,
      "c": "#f44336"
    },
    {
      "id": 621,
      "x": -10,
      "y": -10,
      "z": 7,
      "c": "#f44336"
    },
    {
      "id": 622,
      "x": -10,
      "y": -10,
      "z": 8,
      "c": "#f44336"
    },
    {
      "id": 623,
      "x": -9,
      "y": -10,
      "z": -8,
      "c": "#aeeeee"
    },
    {
      "id": 624,
      "x": -9,
      "y": -10,
      "z": 8,
      "c": "#aeeeee"
    },
    {
      "id": 625,
      "x": -8,
      "y": -10,
      "z": -8,
      "c": "#f44336"
    },
    {
      "id": 626,
      "x": -8,
      "y": -10,
      "z": 8,
      "c": "#f44336"
    },
    {
      "id": 627,
      "x": -7,
      "y": -10,
      "z": -8,
      "c": "#f44336"
    },
    {
      "id": 628,
      "x": -7,
      "y": -10,
      "z": 8,
      "c": "#f44336"
    },
    {
      "id": 629,
      "x": -6,
      "y": -10,
      "z": -8,
      "c": "#aeeeee"
    },
    {
      "id": 630,
      "x": -6,
      "y": -10,
      "z": 8,
      "c": "#aeeeee"
    },
    {
      "id": 631,
      "x": -5,
      "y": -10,
      "z": -8,
      "c": "#f44336"
    },
    {
      "id": 632,
      "x": -5,
      "y": -10,
      "z": 8,
      "c": "#f44336"
    },
    {
      "id": 633,
      "x": -4,
      "y": -10,
      "z": -8,
      "c": "#f44336"
    },
    {
      "id": 634,
      "x": -4,
      "y": -10,
      "z": 8,
      "c": "#f44336"
    },
    {
      "id": 635,
      "x": -3,
      "y": -10,
      "z": 8,
      "c": "#aeeeee"
    },
    {
      "id": 636,
      "x": -2,
      "y": -10,
      "z": 8,
      "c": "#aeeeee"
    },
    {
      "id": 637,
      "x": -1,
      "y": -10,
      "z": 8,
      "c": "#f44336"
    },
    {
      "id": 638,
      "x": 0,
      "y": -10,
      "z": 2,
      "c": "#aeeeee"
    },
    {
      "id": 639,
      "x": 0,
      "y": -10,
      "z": 3,
      "c": "#aeeeee"
    },
    {
      "id": 640,
      "x": 0,
      "y": -10,
      "z": 4,
      "c": "#aeeeee"
    },
    {
      "id": 641,
      "x": 0,
      "y": -10,
      "z": 5,
      "c": "#aeeeee"
    },
    {
      "id": 642,
      "x": 0,
      "y": -10,
      "z": 6,
      "c": "#aeeeee"
    },
    {
      "id": 643,
      "x": 0,
      "y": -10,
      "z": 7,
      "c": "#aeeeee"
    },
    {
      "id": 644,
      "x": 0,
      "y": -10,
      "z": 8,
      "c": "#aeeeee"
    },
    {
      "id": 645,
      "x": -10,
      "y": -9,
      "z": -8,
      "c": "#f44336"
    },
    {
      "id": 646,
      "x": -10,
      "y": -9,
      "z": -7,
      "c": "#f44336"
    },
    {
      "id": 647,
      "x": -10,
      "y": -9,
      "z": -6,
      "c": "#f44336"
    },
    {
      "id": 648,
      "x": -10,
      "y": -9,
      "z": -5,
      "c": "#f44336"
    },
    {
      "id": 649,
      "x": -10,
      "y": -9,
      "z": -4,
      "c": "#f44336"
    },
    {
      "id": 650,
      "x": -10,
      "y": -9,
      "z": -3,
      "c": "#f44336"
    },
    {
      "id": 651,
      "x": -10,
      "y": -9,
      "z": -2,
      "c": "#f44336"
    },
    {
      "id": 652,
      "x": -10,
      "y": -9,
      "z": -1,
      "c": "#f44336"
    },
    {
      "id": 653,
      "x": -10,
      "y": -9,
      "z": 0,
      "c": "#f44336"
    },
    {
      "id": 654,
      "x": -10,
      "y": -9,
      "z": 1,
      "c": "#f44336"
    },
    {
      "id": 655,
      "x": -10,
      "y": -9,
      "z": 2,
      "c": "#f44336"
    },
    {
      "id": 656,
      "x": -10,
      "y": -9,
      "z": 3,
      "c": "#f44336"
    },
    {
      "id": 657,
      "x": -10,
      "y": -9,
      "z": 4,
      "c": "#f44336"
    },
    {
      "id": 658,
      "x": -10,
      "y": -9,
      "z": 5,
      "c": "#f44336"
    },
    {
      "id": 659,
      "x": -10,
      "y": -9,
      "z": 6,
      "c": "#f44336"
    },
    {
      "id": 660,
      "x": -10,
      "y": -9,
      "z": 7,
      "c": "#f44336"
    },
    {
      "id": 661,
      "x": -10,
      "y": -9,
      "z": 8,
      "c": "#f44336"
    },
    {
      "id": 662,
      "x": -9,
      "y": -9,
      "z": -8,
      "c": "#f44336"
    },
    {
      "id": 663,
      "x": -9,
      "y": -9,
      "z": 8,
      "c": "#f44336"
    },
    {
      "id": 664,
      "x": -8,
      "y": -9,
      "z": -8,
      "c": "#f44336"
    },
    {
      "id": 665,
      "x": -8,
      "y": -9,
      "z": 8,
      "c": "#f44336"
    },
    {
      "id": 666,
      "x": -7,
      "y": -9,
      "z": -8,
      "c": "#f44336"
    },
    {
      "id": 667,
      "x": -7,
      "y": -9,
      "z": 8,
      "c": "#f44336"
    },
    {
      "id": 668,
      "x": -6,
      "y": -9,
      "z": -8,
      "c": "#f44336"
    },
    {
      "id": 669,
      "x": -6,
      "y": -9,
      "z": 8,
      "c": "#f44336"
    },
    {
      "id": 670,
      "x": -5,
      "y": -9,
      "z": -8,
      "c": "#f44336"
    },
    {
      "id": 671,
      "x": -5,
      "y": -9,
      "z": 8,
      "c": "#f44336"
    },
    {
      "id": 672,
      "x": -4,
      "y": -9,
      "z": -8,
      "c": "#f44336"
    },
    {
      "id": 673,
      "x": -4,
      "y": -9,
      "z": 8,
      "c": "#f44336"
    },
    {
      "id": 674,
      "x": -3,
      "y": -9,
      "z": 8,
      "c": "#f44336"
    },
    {
      "id": 675,
      "x": -2,
      "y": -9,
      "z": 8,
      "c": "#aeeeee"
    },
    {
      "id": 676,
      "x": -1,
      "y": -9,
      "z": 8,
      "c": "#f44336"
    },
    {
      "id": 677,
      "x": 0,
      "y": -9,
      "z": 2,
      "c": "#f44336"
    },
    {
      "id": 678,
      "x": 0,
      "y": -9,
      "z": 3,
      "c": "#f44336"
    },
    {
      "id": 679,
      "x": 0,
      "y": -9,
      "z": 4,
      "c": "#f44336"
    },
    {
      "id": 680,
      "x": 0,
      "y": -9,
      "z": 5,
      "c": "#f44336"
    },
    {
      "id": 681,
      "x": 0,
      "y": -9,
      "z": 6,
      "c": "#f44336"
    },
    {
      "id": 682,
      "x": 0,
      "y": -9,
      "z": 7,
      "c": "#f44336"
    },
    {
      "id": 683,
      "x": 0,
      "y": -9,
      "z": 8,
      "c": "#f44336"
    },
    {
      "id": 684,
      "x": -10,
      "y": -8,
      "z": -8,
      "c": "#f44336"
    },
    {
      "id": 685,
      "x": -10,
      "y": -8,
      "z": -7,
      "c": "#f44336"
    },
    {
      "id": 686,
      "x": -10,
      "y": -8,
      "z": -6,
      "c": "#aeeeee"
    },
    {
      "id": 687,
      "x": -10,
      "y": -8,
      "z": -5,
      "c": "#f44336"
    },
    {
      "id": 688,
      "x": -10,
      "y": -8,
      "z": -4,
      "c": "#f44336"
    },
    {
      "id": 689,
      "x": -10,
      "y": -8,
      "z": -3,
      "c": "#aeeeee"
    },
    {
      "id": 690,
      "x": -10,
      "y": -8,
      "z": -2,
      "c": "#f44336"
    },
    {
      "id": 691,
      "x": -10,
      "y": -8,
      "z": -1,
      "c": "#f44336"
    },
    {
      "id": 692,
      "x": -10,
      "y": -8,
      "z": 0,
      "c": "#aeeeee"
    },
    {
      "id": 693,
      "x": -10,
      "y": -8,
      "z": 1,
      "c": "#f44336"
    },
    {
      "id": 694,
      "x": -10,
      "y": -8,
      "z": 2,
      "c": "#f44336"
    },
    {
      "id": 695,
      "x": -10,
      "y": -8,
      "z": 3,
      "c": "#aeeeee"
    },
    {
      "id": 696,
      "x": -10,
      "y": -8,
      "z": 4,
      "c": "#f44336"
    },
    {
      "id": 697,
      "x": -10,
      "y": -8,
      "z": 5,
      "c": "#f44336"
    },
    {
      "id": 698,
      "x": -10,
      "y": -8,
      "z": 6,
      "c": "#aeeeee"
    },
    {
      "id": 699,
      "x": -10,
      "y": -8,
      "z": 7,
      "c": "#f44336"
    },
    {
      "id": 700,
      "x": -10,
      "y": -8,
      "z": 8,
      "c": "#f44336"
    },
    {
      "id": 701,
      "x": -9,
      "y": -8,
      "z": -8,
      "c": "#f44336"
    },
    {
      "id": 702,
      "x": -9,
      "y": -8,
      "z": 8,
      "c": "#f44336"
    },
    {
      "id": 703,
      "x": -8,
      "y": -8,
      "z": -8,
      "c": "#f44336"
    },
    {
      "id": 704,
      "x": -8,
      "y": -8,
      "z": 8,
      "c": "#f44336"
    },
    {
      "id": 705,
      "x": -7,
      "y": -8,
      "z": -8,
      "c": "#f44336"
    },
    {
      "id": 706,
      "x": -7,
      "y": -8,
      "z": 8,
      "c": "#f44336"
    },
    {
      "id": 707,
      "x": -6,
      "y": -8,
      "z": -8,
      "c": "#f44336"
    },
    {
      "id": 708,
      "x": -6,
      "y": -8,
      "z": 8,
      "c": "#f44336"
    },
    {
      "id": 709,
      "x": -5,
      "y": -8,
      "z": -8,
      "c": "#f44336"
    },
    {
      "id": 710,
      "x": -5,
      "y": -8,
      "z": 8,
      "c": "#f44336"
    },
    {
      "id": 711,
      "x": -4,
      "y": -8,
      "z": -8,
      "c": "#f44336"
    },
    {
      "id": 712,
      "x": -4,
      "y": -8,
      "z": 8,
      "c": "#f44336"
    },
    {
      "id": 713,
      "x": -3,
      "y": -8,
      "z": 8,
      "c": "#f44336"
    },
    {
      "id": 714,
      "x": -2,
      "y": -8,
      "z": 8,
      "c": "#f44336"
    },
    {
      "id": 715,
      "x": -1,
      "y": -8,
      "z": 8,
      "c": "#f44336"
    },
    {
      "id": 716,
      "x": 0,
      "y": -8,
      "z": 2,
      "c": "#f44336"
    },
    {
      "id": 717,
      "x": 0,
      "y": -8,
      "z": 3,
      "c": "#aeeeee"
    },
    {
      "id": 718,
      "x": 0,
      "y": -8,
      "z": 4,
      "c": "#f44336"
    },
    {
      "id": 719,
      "x": 0,
      "y": -8,
      "z": 5,
      "c": "#f44336"
    },
    {
      "id": 720,
      "x": 0,
      "y": -8,
      "z": 6,
      "c": "#aeeeee"
    },
    {
      "id": 721,
      "x": 0,
      "y": -8,
      "z": 7,
      "c": "#f44336"
    },
    {
      "id": 722,
      "x": 0,
      "y": -8,
      "z": 8,
      "c": "#f44336"
    },
    {
      "id": 723,
      "x": -10,
      "y": -7,
      "z": -8,
      "c": "#f44336"
    },
    {
      "id": 724,
      "x": -10,
      "y": -7,
      "z": -7,
      "c": "#f44336"
    },
    {
      "id": 725,
      "x": -10,
      "y": -7,
      "z": -6,
      "c": "#f44336"
    },
    {
      "id": 726,
      "x": -10,
      "y": -7,
      "z": -5,
      "c": "#f44336"
    },
    {
      "id": 727,
      "x": -10,
      "y": -7,
      "z": -4,
      "c": "#f44336"
    },
    {
      "id": 728,
      "x": -10,
      "y": -7,
      "z": -3,
      "c": "#f44336"
    },
    {
      "id": 729,
      "x": -10,
      "y": -7,
      "z": -2,
      "c": "#f44336"
    },
    {
      "id": 730,
      "x": -10,
      "y": -7,
      "z": -1,
      "c": "#f44336"
    },
    {
      "id": 731,
      "x": -10,
      "y": -7,
      "z": 0,
      "c": "#f44336"
    },
    {
      "id": 732,
      "x": -10,
      "y": -7,
      "z": 1,
      "c": "#f44336"
    },
    {
      "id": 733,
      "x": -10,
      "y": -7,
      "z": 2,
      "c": "#f44336"
    },
    {
      "id": 734,
      "x": -10,
      "y": -7,
      "z": 3,
      "c": "#f44336"
    },
    {
      "id": 735,
      "x": -10,
      "y": -7,
      "z": 4,
      "c": "#f44336"
    },
    {
      "id": 736,
      "x": -10,
      "y": -7,
      "z": 5,
      "c": "#f44336"
    },
    {
      "id": 737,
      "x": -10,
      "y": -7,
      "z": 6,
      "c": "#f44336"
    },
    {
      "id": 738,
      "x": -10,
      "y": -7,
      "z": 7,
      "c": "#f44336"
    },
    {
      "id": 739,
      "x": -10,
      "y": -7,
      "z": 8,
      "c": "#f44336"
    },
    {
      "id": 740,
      "x": -9,
      "y": -7,
      "z": -8,
      "c": "#f44336"
    },
    {
      "id": 741,
      "x": -9,
      "y": -7,
      "z": 8,
      "c": "#f44336"
    },
    {
      "id": 742,
      "x": -8,
      "y": -7,
      "z": -8,
      "c": "#f44336"
    },
    {
      "id": 743,
      "x": -8,
      "y": -7,
      "z": 8,
      "c": "#f44336"
    },
    {
      "id": 744,
      "x": -7,
      "y": -7,
      "z": -8,
      "c": "#f44336"
    },
    {
      "id": 745,
      "x": -7,
      "y": -7,
      "z": 8,
      "c": "#f44336"
    },
    {
      "id": 746,
      "x": -6,
      "y": -7,
      "z": -8,
      "c": "#f44336"
    },
    {
      "id": 747,
      "x": -6,
      "y": -7,
      "z": 8,
      "c": "#f44336"
    },
    {
      "id": 748,
      "x": -5,
      "y": -7,
      "z": -8,
      "c": "#f44336"
    },
    {
      "id": 749,
      "x": -5,
      "y": -7,
      "z": 8,
      "c": "#f44336"
    },
    {
      "id": 750,
      "x": -4,
      "y": -7,
      "z": -8,
      "c": "#f44336"
    },
    {
      "id": 751,
      "x": -4,
      "y": -7,
      "z": 8,
      "c": "#f44336"
    },
    {
      "id": 752,
      "x": -3,
      "y": -7,
      "z": 8,
      "c": "#f44336"
    },
    {
      "id": 753,
      "x": -2,
      "y": -7,
      "z": 8,
      "c": "#f44336"
    },
    {
      "id": 754,
      "x": -1,
      "y": -7,
      "z": 8,
      "c": "#f44336"
    },
    {
      "id": 755,
      "x": 0,
      "y": -7,
      "z": 2,
      "c": "#f44336"
    },
    {
      "id": 756,
      "x": 0,
      "y": -7,
      "z": 3,
      "c": "#f44336"
    },
    {
      "id": 757,
      "x": 0,
      "y": -7,
      "z": 5,
      "c": "#f44336"
    },
    {
      "id": 758,
      "x": 0,
      "y": -7,
      "z": 6,
      "c": "#f44336"
    },
    {
      "id": 759,
      "x": 0,
      "y": -7,
      "z": 7,
      "c": "#f44336"
    },
    {
      "id": 760,
      "x": 0,
      "y": -7,
      "z": 8,
      "c": "#f44336"
    },
    {
      "id": 761,
      "x": -11,
      "y": -6,
      "z": -9,
      "c": "#424242"
    },
    {
      "id": 762,
      "x": -11,
      "y": -6,
      "z": -8,
      "c": "#424242"
    },
    {
      "id": 763,
      "x": -11,
      "y": -6,
      "z": -7,
      "c": "#424242"
    },
    {
      "id": 764,
      "x": -11,
      "y": -6,
      "z": -6,
      "c": "#424242"
    },
    {
      "id": 765,
      "x": -11,
      "y": -6,
      "z": -5,
      "c": "#424242"
    },
    {
      "id": 766,
      "x": -11,
      "y": -6,
      "z": -4,
      "c": "#424242"
    },
    {
      "id": 767,
      "x": -11,
      "y": -6,
      "z": -3,
      "c": "#424242"
    },
    {
      "id": 768,
      "x": -11,
      "y": -6,
      "z": -2,
      "c": "#424242"
    },
    {
      "id": 769,
      "x": -11,
      "y": -6,
      "z": -1,
      "c": "#424242"
    },
    {
      "id": 770,
      "x": -11,
      "y": -6,
      "z": 0,
      "c": "#424242"
    },
    {
      "id": 771,
      "x": -11,
      "y": -6,
      "z": 1,
      "c": "#424242"
    },
    {
      "id": 772,
      "x": -11,
      "y": -6,
      "z": 2,
      "c": "#424242"
    },
    {
      "id": 773,
      "x": -11,
      "y": -6,
      "z": 3,
      "c": "#424242"
    },
    {
      "id": 774,
      "x": -11,
      "y": -6,
      "z": 4,
      "c": "#424242"
    },
    {
      "id": 775,
      "x": -11,
      "y": -6,
      "z": 5,
      "c": "#424242"
    },
    {
      "id": 776,
      "x": -11,
      "y": -6,
      "z": 6,
      "c": "#424242"
    },
    {
      "id": 777,
      "x": -11,
      "y": -6,
      "z": 7,
      "c": "#424242"
    },
    {
      "id": 778,
      "x": -11,
      "y": -6,
      "z": 8,
      "c": "#424242"
    },
    {
      "id": 779,
      "x": -11,
      "y": -6,
      "z": 9,
      "c": "#424242"
    },
    {
      "id": 780,
      "x": -10,
      "y": -6,
      "z": -9,
      "c": "#424242"
    },
    {
      "id": 781,
      "x": -10,
      "y": -6,
      "z": -8,
      "c": "#424242"
    },
    {
      "id": 782,
      "x": -10,
      "y": -6,
      "z": -7,
      "c": "#424242"
    },
    {
      "id": 783,
      "x": -10,
      "y": -6,
      "z": -6,
      "c": "#424242"
    },
    {
      "id": 784,
      "x": -10,
      "y": -6,
      "z": -5,
      "c": "#424242"
    },
    {
      "id": 785,
      "x": -10,
      "y": -6,
      "z": -4,
      "c": "#424242"
    },
    {
      "id": 786,
      "x": -10,
      "y": -6,
      "z": -3,
      "c": "#424242"
    },
    {
      "id": 787,
      "x": -10,
      "y": -6,
      "z": -2,
      "c": "#424242"
    },
    {
      "id": 788,
      "x": -10,
      "y": -6,
      "z": -1,
      "c": "#424242"
    },
    {
      "id": 789,
      "x": -10,
      "y": -6,
      "z": 0,
      "c": "#424242"
    },
    {
      "id": 790,
      "x": -10,
      "y": -6,
      "z": 1,
      "c": "#424242"
    },
    {
      "id": 791,
      "x": -10,
      "y": -6,
      "z": 2,
      "c": "#424242"
    },
    {
      "id": 792,
      "x": -10,
      "y": -6,
      "z": 3,
      "c": "#424242"
    },
    {
      "id": 793,
      "x": -10,
      "y": -6,
      "z": 4,
      "c": "#424242"
    },
    {
      "id": 794,
      "x": -10,
      "y": -6,
      "z": 5,
      "c": "#424242"
    },
    {
      "id": 795,
      "x": -10,
      "y": -6,
      "z": 6,
      "c": "#424242"
    },
    {
      "id": 796,
      "x": -10,
      "y": -6,
      "z": 7,
      "c": "#424242"
    },
    {
      "id": 797,
      "x": -10,
      "y": -6,
      "z": 8,
      "c": "#424242"
    },
    {
      "id": 798,
      "x": -10,
      "y": -6,
      "z": 9,
      "c": "#424242"
    },
    {
      "id": 799,
      "x": -9,
      "y": -6,
      "z": -9,
      "c": "#424242"
    },
    {
      "id": 800,
      "x": -9,
      "y": -6,
      "z": -8,
      "c": "#424242"
    },
    {
      "id": 801,
      "x": -9,
      "y": -6,
      "z": -7,
      "c": "#424242"
    },
    {
      "id": 802,
      "x": -9,
      "y": -6,
      "z": -6,
      "c": "#424242"
    },
    {
      "id": 803,
      "x": -9,
      "y": -6,
      "z": -5,
      "c": "#424242"
    },
    {
      "id": 804,
      "x": -9,
      "y": -6,
      "z": -4,
      "c": "#424242"
    },
    {
      "id": 805,
      "x": -9,
      "y": -6,
      "z": -3,
      "c": "#424242"
    },
    {
      "id": 806,
      "x": -9,
      "y": -6,
      "z": -2,
      "c": "#424242"
    },
    {
      "id": 807,
      "x": -9,
      "y": -6,
      "z": -1,
      "c": "#424242"
    },
    {
      "id": 808,
      "x": -9,
      "y": -6,
      "z": 0,
      "c": "#424242"
    },
    {
      "id": 809,
      "x": -9,
      "y": -6,
      "z": 1,
      "c": "#424242"
    },
    {
      "id": 810,
      "x": -9,
      "y": -6,
      "z": 2,
      "c": "#424242"
    },
    {
      "id": 811,
      "x": -9,
      "y": -6,
      "z": 3,
      "c": "#424242"
    },
    {
      "id": 812,
      "x": -9,
      "y": -6,
      "z": 4,
      "c": "#424242"
    },
    {
      "id": 813,
      "x": -9,
      "y": -6,
      "z": 5,
      "c": "#424242"
    },
    {
      "id": 814,
      "x": -9,
      "y": -6,
      "z": 6,
      "c": "#424242"
    },
    {
      "id": 815,
      "x": -9,
      "y": -6,
      "z": 7,
      "c": "#424242"
    },
    {
      "id": 816,
      "x": -9,
      "y": -6,
      "z": 8,
      "c": "#424242"
    },
    {
      "id": 817,
      "x": -9,
      "y": -6,
      "z": 9,
      "c": "#424242"
    },
    {
      "id": 818,
      "x": -8,
      "y": -6,
      "z": -9,
      "c": "#424242"
    },
    {
      "id": 819,
      "x": -8,
      "y": -6,
      "z": -8,
      "c": "#424242"
    },
    {
      "id": 820,
      "x": -8,
      "y": -6,
      "z": -7,
      "c": "#424242"
    },
    {
      "id": 821,
      "x": -8,
      "y": -6,
      "z": -6,
      "c": "#424242"
    },
    {
      "id": 822,
      "x": -8,
      "y": -6,
      "z": -5,
      "c": "#424242"
    },
    {
      "id": 823,
      "x": -8,
      "y": -6,
      "z": -4,
      "c": "#424242"
    },
    {
      "id": 824,
      "x": -8,
      "y": -6,
      "z": -3,
      "c": "#424242"
    },
    {
      "id": 825,
      "x": -8,
      "y": -6,
      "z": -2,
      "c": "#424242"
    },
    {
      "id": 826,
      "x": -8,
      "y": -6,
      "z": -1,
      "c": "#424242"
    },
    {
      "id": 827,
      "x": -8,
      "y": -6,
      "z": 0,
      "c": "#424242"
    },
    {
      "id": 828,
      "x": -8,
      "y": -6,
      "z": 1,
      "c": "#424242"
    },
    {
      "id": 829,
      "x": -8,
      "y": -6,
      "z": 2,
      "c": "#424242"
    },
    {
      "id": 830,
      "x": -8,
      "y": -6,
      "z": 3,
      "c": "#424242"
    },
    {
      "id": 831,
      "x": -8,
      "y": -6,
      "z": 4,
      "c": "#424242"
    },
    {
      "id": 832,
      "x": -8,
      "y": -6,
      "z": 5,
      "c": "#424242"
    },
    {
      "id": 833,
      "x": -8,
      "y": -6,
      "z": 6,
      "c": "#424242"
    },
    {
      "id": 834,
      "x": -8,
      "y": -6,
      "z": 7,
      "c": "#424242"
    },
    {
      "id": 835,
      "x": -8,
      "y": -6,
      "z": 8,
      "c": "#424242"
    },
    {
      "id": 836,
      "x": -8,
      "y": -6,
      "z": 9,
      "c": "#424242"
    },
    {
      "id": 837,
      "x": -7,
      "y": -6,
      "z": -9,
      "c": "#424242"
    },
    {
      "id": 838,
      "x": -7,
      "y": -6,
      "z": -8,
      "c": "#424242"
    },
    {
      "id": 839,
      "x": -7,
      "y": -6,
      "z": -7,
      "c": "#424242"
    },
    {
      "id": 840,
      "x": -7,
      "y": -6,
      "z": -6,
      "c": "#424242"
    },
    {
      "id": 841,
      "x": -7,
      "y": -6,
      "z": -5,
      "c": "#424242"
    },
    {
      "id": 842,
      "x": -7,
      "y": -6,
      "z": -4,
      "c": "#424242"
    },
    {
      "id": 843,
      "x": -7,
      "y": -6,
      "z": -3,
      "c": "#424242"
    },
    {
      "id": 844,
      "x": -7,
      "y": -6,
      "z": -2,
      "c": "#424242"
    },
    {
      "id": 845,
      "x": -7,
      "y": -6,
      "z": -1,
      "c": "#424242"
    },
    {
      "id": 846,
      "x": -7,
      "y": -6,
      "z": 0,
      "c": "#424242"
    },
    {
      "id": 847,
      "x": -7,
      "y": -6,
      "z": 1,
      "c": "#424242"
    },
    {
      "id": 848,
      "x": -7,
      "y": -6,
      "z": 2,
      "c": "#424242"
    },
    {
      "id": 849,
      "x": -7,
      "y": -6,
      "z": 3,
      "c": "#424242"
    },
    {
      "id": 850,
      "x": -7,
      "y": -6,
      "z": 4,
      "c": "#424242"
    },
    {
      "id": 851,
      "x": -7,
      "y": -6,
      "z": 5,
      "c": "#424242"
    },
    {
      "id": 852,
      "x": -7,
      "y": -6,
      "z": 6,
      "c": "#424242"
    },
    {
      "id": 853,
      "x": -7,
      "y": -6,
      "z": 7,
      "c": "#424242"
    },
    {
      "id": 854,
      "x": -7,
      "y": -6,
      "z": 8,
      "c": "#424242"
    },
    {
      "id": 855,
      "x": -7,
      "y": -6,
      "z": 9,
      "c": "#424242"
    },
    {
      "id": 856,
      "x": -6,
      "y": -6,
      "z": -9,
      "c": "#424242"
    },
    {
      "id": 857,
      "x": -6,
      "y": -6,
      "z": -8,
      "c": "#424242"
    },
    {
      "id": 858,
      "x": -6,
      "y": -6,
      "z": -7,
      "c": "#424242"
    },
    {
      "id": 859,
      "x": -6,
      "y": -6,
      "z": -6,
      "c": "#424242"
    },
    {
      "id": 860,
      "x": -6,
      "y": -6,
      "z": -5,
      "c": "#424242"
    },
    {
      "id": 861,
      "x": -6,
      "y": -6,
      "z": -4,
      "c": "#424242"
    },
    {
      "id": 862,
      "x": -6,
      "y": -6,
      "z": -3,
      "c": "#424242"
    },
    {
      "id": 863,
      "x": -6,
      "y": -6,
      "z": -2,
      "c": "#424242"
    },
    {
      "id": 864,
      "x": -6,
      "y": -6,
      "z": -1,
      "c": "#424242"
    },
    {
      "id": 865,
      "x": -6,
      "y": -6,
      "z": 0,
      "c": "#424242"
    },
    {
      "id": 866,
      "x": -6,
      "y": -6,
      "z": 1,
      "c": "#424242"
    },
    {
      "id": 867,
      "x": -6,
      "y": -6,
      "z": 2,
      "c": "#424242"
    },
    {
      "id": 868,
      "x": -6,
      "y": -6,
      "z": 3,
      "c": "#424242"
    },
    {
      "id": 869,
      "x": -6,
      "y": -6,
      "z": 4,
      "c": "#424242"
    },
    {
      "id": 870,
      "x": -6,
      "y": -6,
      "z": 5,
      "c": "#424242"
    },
    {
      "id": 871,
      "x": -6,
      "y": -6,
      "z": 6,
      "c": "#424242"
    },
    {
      "id": 872,
      "x": -6,
      "y": -6,
      "z": 7,
      "c": "#424242"
    },
    {
      "id": 873,
      "x": -6,
      "y": -6,
      "z": 8,
      "c": "#424242"
    },
    {
      "id": 874,
      "x": -6,
      "y": -6,
      "z": 9,
      "c": "#424242"
    },
    {
      "id": 875,
      "x": -5,
      "y": -6,
      "z": -9,
      "c": "#424242"
    },
    {
      "id": 876,
      "x": -5,
      "y": -6,
      "z": -8,
      "c": "#424242"
    },
    {
      "id": 877,
      "x": -5,
      "y": -6,
      "z": -7,
      "c": "#424242"
    },
    {
      "id": 878,
      "x": -5,
      "y": -6,
      "z": -6,
      "c": "#424242"
    },
    {
      "id": 879,
      "x": -5,
      "y": -6,
      "z": -5,
      "c": "#424242"
    },
    {
      "id": 880,
      "x": -5,
      "y": -6,
      "z": -4,
      "c": "#424242"
    },
    {
      "id": 881,
      "x": -5,
      "y": -6,
      "z": -3,
      "c": "#424242"
    },
    {
      "id": 882,
      "x": -5,
      "y": -6,
      "z": -2,
      "c": "#424242"
    },
    {
      "id": 883,
      "x": -5,
      "y": -6,
      "z": -1,
      "c": "#424242"
    },
    {
      "id": 884,
      "x": -5,
      "y": -6,
      "z": 0,
      "c": "#424242"
    },
    {
      "id": 885,
      "x": -5,
      "y": -6,
      "z": 1,
      "c": "#424242"
    },
    {
      "id": 886,
      "x": -5,
      "y": -6,
      "z": 2,
      "c": "#424242"
    },
    {
      "id": 887,
      "x": -5,
      "y": -6,
      "z": 3,
      "c": "#424242"
    },
    {
      "id": 888,
      "x": -5,
      "y": -6,
      "z": 4,
      "c": "#424242"
    },
    {
      "id": 889,
      "x": -5,
      "y": -6,
      "z": 5,
      "c": "#424242"
    },
    {
      "id": 890,
      "x": -5,
      "y": -6,
      "z": 6,
      "c": "#424242"
    },
    {
      "id": 891,
      "x": -5,
      "y": -6,
      "z": 7,
      "c": "#424242"
    },
    {
      "id": 892,
      "x": -5,
      "y": -6,
      "z": 8,
      "c": "#424242"
    },
    {
      "id": 893,
      "x": -5,
      "y": -6,
      "z": 9,
      "c": "#424242"
    },
    {
      "id": 894,
      "x": -4,
      "y": -6,
      "z": -9,
      "c": "#424242"
    },
    {
      "id": 895,
      "x": -4,
      "y": -6,
      "z": -8,
      "c": "#424242"
    },
    {
      "id": 896,
      "x": -4,
      "y": -6,
      "z": -7,
      "c": "#424242"
    },
    {
      "id": 897,
      "x": -4,
      "y": -6,
      "z": -6,
      "c": "#424242"
    },
    {
      "id": 898,
      "x": -4,
      "y": -6,
      "z": -5,
      "c": "#424242"
    },
    {
      "id": 899,
      "x": -4,
      "y": -6,
      "z": -4,
      "c": "#424242"
    },
    {
      "id": 900,
      "x": -4,
      "y": -6,
      "z": -3,
      "c": "#424242"
    },
    {
      "id": 901,
      "x": -4,
      "y": -6,
      "z": -2,
      "c": "#424242"
    },
    {
      "id": 902,
      "x": -4,
      "y": -6,
      "z": -1,
      "c": "#424242"
    },
    {
      "id": 903,
      "x": -4,
      "y": -6,
      "z": 0,
      "c": "#424242"
    },
    {
      "id": 904,
      "x": -4,
      "y": -6,
      "z": 1,
      "c": "#424242"
    },
    {
      "id": 905,
      "x": -4,
      "y": -6,
      "z": 2,
      "c": "#424242"
    },
    {
      "id": 906,
      "x": -4,
      "y": -6,
      "z": 3,
      "c": "#424242"
    },
    {
      "id": 907,
      "x": -4,
      "y": -6,
      "z": 4,
      "c": "#424242"
    },
    {
      "id": 908,
      "x": -4,
      "y": -6,
      "z": 5,
      "c": "#424242"
    },
    {
      "id": 909,
      "x": -4,
      "y": -6,
      "z": 6,
      "c": "#424242"
    },
    {
      "id": 910,
      "x": -4,
      "y": -6,
      "z": 7,
      "c": "#424242"
    },
    {
      "id": 911,
      "x": -4,
      "y": -6,
      "z": 8,
      "c": "#424242"
    },
    {
      "id": 912,
      "x": -4,
      "y": -6,
      "z": 9,
      "c": "#424242"
    },
    {
      "id": 913,
      "x": -3,
      "y": -6,
      "z": -9,
      "c": "#424242"
    },
    {
      "id": 914,
      "x": -3,
      "y": -6,
      "z": -8,
      "c": "#424242"
    },
    {
      "id": 915,
      "x": -3,
      "y": -6,
      "z": -7,
      "c": "#424242"
    },
    {
      "id": 916,
      "x": -3,
      "y": -6,
      "z": -6,
      "c": "#424242"
    },
    {
      "id": 917,
      "x": -3,
      "y": -6,
      "z": -5,
      "c": "#424242"
    },
    {
      "id": 918,
      "x": -3,
      "y": -6,
      "z": -4,
      "c": "#424242"
    },
    {
      "id": 919,
      "x": -3,
      "y": -6,
      "z": -3,
      "c": "#424242"
    },
    {
      "id": 920,
      "x": -3,
      "y": -6,
      "z": -2,
      "c": "#424242"
    },
    {
      "id": 921,
      "x": -3,
      "y": -6,
      "z": -1,
      "c": "#424242"
    },
    {
      "id": 922,
      "x": -3,
      "y": -6,
      "z": 0,
      "c": "#424242"
    },
    {
      "id": 923,
      "x": -3,
      "y": -6,
      "z": 1,
      "c": "#424242"
    },
    {
      "id": 924,
      "x": -3,
      "y": -6,
      "z": 2,
      "c": "#424242"
    },
    {
      "id": 925,
      "x": -3,
      "y": -6,
      "z": 3,
      "c": "#424242"
    },
    {
      "id": 926,
      "x": -3,
      "y": -6,
      "z": 4,
      "c": "#424242"
    },
    {
      "id": 927,
      "x": -3,
      "y": -6,
      "z": 5,
      "c": "#424242"
    },
    {
      "id": 928,
      "x": -3,
      "y": -6,
      "z": 6,
      "c": "#424242"
    },
    {
      "id": 929,
      "x": -3,
      "y": -6,
      "z": 7,
      "c": "#424242"
    },
    {
      "id": 930,
      "x": -3,
      "y": -6,
      "z": 8,
      "c": "#424242"
    },
    {
      "id": 931,
      "x": -3,
      "y": -6,
      "z": 9,
      "c": "#424242"
    },
    {
      "id": 932,
      "x": -2,
      "y": -6,
      "z": 1,
      "c": "#424242"
    },
    {
      "id": 933,
      "x": -2,
      "y": -6,
      "z": 2,
      "c": "#424242"
    },
    {
      "id": 934,
      "x": -2,
      "y": -6,
      "z": 3,
      "c": "#424242"
    },
    {
      "id": 935,
      "x": -2,
      "y": -6,
      "z": 5,
      "c": "#424242"
    },
    {
      "id": 936,
      "x": -2,
      "y": -6,
      "z": 6,
      "c": "#424242"
    },
    {
      "id": 937,
      "x": -2,
      "y": -6,
      "z": 7,
      "c": "#424242"
    },
    {
      "id": 938,
      "x": -2,
      "y": -6,
      "z": 8,
      "c": "#424242"
    },
    {
      "id": 939,
      "x": -2,
      "y": -6,
      "z": 9,
      "c": "#424242"
    },
    {
      "id": 940,
      "x": -1,
      "y": -6,
      "z": 1,
      "c": "#424242"
    },
    {
      "id": 941,
      "x": -1,
      "y": -6,
      "z": 2,
      "c": "#424242"
    },
    {
      "id": 942,
      "x": -1,
      "y": -6,
      "z": 3,
      "c": "#424242"
    },
    {
      "id": 943,
      "x": -1,
      "y": -6,
      "z": 4,
      "c": "#424242"
    },
    {
      "id": 944,
      "x": -1,
      "y": -6,
      "z": 5,
      "c": "#424242"
    },
    {
      "id": 945,
      "x": -1,
      "y": -6,
      "z": 6,
      "c": "#424242"
    },
    {
      "id": 946,
      "x": -1,
      "y": -6,
      "z": 7,
      "c": "#424242"
    },
    {
      "id": 947,
      "x": -1,
      "y": -6,
      "z": 8,
      "c": "#424242"
    },
    {
      "id": 948,
      "x": -1,
      "y": -6,
      "z": 9,
      "c": "#424242"
    },
    {
      "id": 949,
      "x": 0,
      "y": -6,
      "z": 1,
      "c": "#424242"
    },
    {
      "id": 950,
      "x": 0,
      "y": -6,
      "z": 2,
      "c": "#424242"
    },
    {
      "id": 951,
      "x": 0,
      "y": -6,
      "z": 3,
      "c": "#424242"
    },
    {
      "id": 952,
      "x": 0,
      "y": -6,
      "z": 4,
      "c": "#424242"
    },
    {
      "id": 953,
      "x": 0,
      "y": -6,
      "z": 5,
      "c": "#424242"
    },
    {
      "id": 954,
      "x": 0,
      "y": -6,
      "z": 6,
      "c": "#424242"
    },
    {
      "id": 955,
      "x": 0,
      "y": -6,
      "z": 7,
      "c": "#424242"
    },
    {
      "id": 956,
      "x": 0,
      "y": -6,
      "z": 8,
      "c": "#424242"
    },
    {
      "id": 957,
      "x": 0,
      "y": -6,
      "z": 9,
      "c": "#424242"
    },
    {
      "id": 958,
      "x": 1,
      "y": -6,
      "z": 1,
      "c": "#424242"
    },
    {
      "id": 959,
      "x": 1,
      "y": -6,
      "z": 2,
      "c": "#424242"
    },
    {
      "id": 960,
      "x": 1,
      "y": -6,
      "z": 3,
      "c": "#424242"
    },
    {
      "id": 961,
      "x": 1,
      "y": -6,
      "z": 4,
      "c": "#424242"
    },
    {
      "id": 962,
      "x": 1,
      "y": -6,
      "z": 5,
      "c": "#424242"
    },
    {
      "id": 963,
      "x": 1,
      "y": -6,
      "z": 6,
      "c": "#424242"
    },
    {
      "id": 964,
      "x": 1,
      "y": -6,
      "z": 7,
      "c": "#424242"
    },
    {
      "id": 965,
      "x": 1,
      "y": -6,
      "z": 8,
      "c": "#424242"
    },
    {
      "id": 966,
      "x": 1,
      "y": -6,
      "z": 9,
      "c": "#424242"
    },
    {
      "id": 967,
      "x": -8,
      "y": -11,
      "z": -5,
      "c": "#111111"
    },
    {
      "id": 968,
      "x": -8,
      "y": -10,
      "z": -5,
      "c": "#ffd700"
    },
    {
      "id": 969,
      "x": -8,
      "y": -9,
      "z": -5,
      "c": "#aeeeee"
    },
    {
      "id": 970,
      "x": -8,
      "y": -8,
      "z": -5,
      "c": "#ffd700"
    },
    {
      "id": 971,
      "x": -8,
      "y": -11,
      "z": -4,
      "c": "#111111"
    },
    {
      "id": 972,
      "x": -8,
      "y": -10,
      "z": -4,
      "c": "#f0f0f0"
    },
    {
      "id": 973,
      "x": -8,
      "y": -9,
      "z": -4,
      "c": "#aeeeee"
    },
    {
      "id": 974,
      "x": -8,
      "y": -8,
      "z": -4,
      "c": "#ffd700"
    },
    {
      "id": 975,
      "x": -8,
      "y": -11,
      "z": -3,
      "c": "#111111"
    },
    {
      "id": 976,
      "x": -8,
      "y": -10,
      "z": -3,
      "c": "#ffd700"
    },
    {
      "id": 977,
      "x": -8,
      "y": -9,
      "z": -3,
      "c": "#aeeeee"
    },
    {
      "id": 978,
      "x": -8,
      "y": -8,
      "z": -3,
      "c": "#ffd700"
    },
    {
      "id": 979,
      "x": -7,
      "y": -11,
      "z": -5,
      "c": "#111111"
    },
    {
      "id": 980,
      "x": -7,
      "y": -10,
      "z": -5,
      "c": "#ffd700"
    },
    {
      "id": 981,
      "x": -7,
      "y": -9,
      "z": -5,
      "c": "#aeeeee"
    },
    {
      "id": 982,
      "x": -7,
      "y": -8,
      "z": -5,
      "c": "#ffd700"
    },
    {
      "id": 983,
      "x": -7,
      "y": -11,
      "z": -4,
      "c": "#111111"
    },
    {
      "id": 984,
      "x": -7,
      "y": -10,
      "z": -4,
      "c": "#ffd700"
    },
    {
      "id": 985,
      "x": -7,
      "y": -9,
      "z": -4,
      "c": "#ffd700"
    },
    {
      "id": 986,
      "x": -7,
      "y": -8,
      "z": -4,
      "c": "#ffd700"
    },
    {
      "id": 987,
      "x": -7,
      "y": -11,
      "z": -3,
      "c": "#111111"
    },
    {
      "id": 988,
      "x": -7,
      "y": -10,
      "z": -3,
      "c": "#ffd700"
    },
    {
      "id": 989,
      "x": -7,
      "y": -9,
      "z": -3,
      "c": "#aeeeee"
    },
    {
      "id": 990,
      "x": -7,
      "y": -8,
      "z": -3,
      "c": "#ffd700"
    },
    {
      "id": 991,
      "x": -6,
      "y": -11,
      "z": -5,
      "c": "#111111"
    },
    {
      "id": 992,
      "x": -6,
      "y": -10,
      "z": -5,
      "c": "#ffd700"
    },
    {
      "id": 993,
      "x": -6,
      "y": -9,
      "z": -5,
      "c": "#aeeeee"
    },
    {
      "id": 994,
      "x": -6,
      "y": -8,
      "z": -5,
      "c": "#ffd700"
    },
    {
      "id": 995,
      "x": -6,
      "y": -11,
      "z": -4,
      "c": "#111111"
    },
    {
      "id": 996,
      "x": -6,
      "y": -10,
      "z": -4,
      "c": "#ffd700"
    },
    {
      "id": 997,
      "x": -6,
      "y": -9,
      "z": -4,
      "c": "#ffd700"
    },
    {
      "id": 998,
      "x": -6,
      "y": -8,
      "z": -4,
      "c": "#ffd700"
    },
    {
      "id": 999,
      "x": -6,
      "y": -11,
      "z": -3,
      "c": "#111111"
    },
    {
      "id": 1000,
      "x": -6,
      "y": -10,
      "z": -3,
      "c": "#ffd700"
    },
    {
      "id": 1001,
      "x": -6,
      "y": -9,
      "z": -3,
      "c": "#aeeeee"
    },
    {
      "id": 1002,
      "x": -6,
      "y": -8,
      "z": -3,
      "c": "#ffd700"
    },
    {
      "id": 1003,
      "x": -5,
      "y": -11,
      "z": -5,
      "c": "#111111"
    },
    {
      "id": 1004,
      "x": -5,
      "y": -10,
      "z": -5,
      "c": "#ffd700"
    },
    {
      "id": 1005,
      "x": -5,
      "y": -9,
      "z": -5,
      "c": "#aeeeee"
    },
    {
      "id": 1006,
      "x": -5,
      "y": -8,
      "z": -5,
      "c": "#ffd700"
    },
    {
      "id": 1007,
      "x": -5,
      "y": -11,
      "z": -4,
      "c": "#111111"
    },
    {
      "id": 1008,
      "x": -5,
      "y": -10,
      "z": -4,
      "c": "#ffd700"
    },
    {
      "id": 1009,
      "x": -5,
      "y": -9,
      "z": -4,
      "c": "#ffd700"
    },
    {
      "id": 1010,
      "x": -5,
      "y": -8,
      "z": -4,
      "c": "#ffd700"
    },
    {
      "id": 1011,
      "x": -5,
      "y": -11,
      "z": -3,
      "c": "#111111"
    },
    {
      "id": 1012,
      "x": -5,
      "y": -10,
      "z": -3,
      "c": "#ffd700"
    },
    {
      "id": 1013,
      "x": -5,
      "y": -9,
      "z": -3,
      "c": "#aeeeee"
    },
    {
      "id": 1014,
      "x": -5,
      "y": -8,
      "z": -3,
      "c": "#ffd700"
    },
    {
      "id": 1015,
      "x": -4,
      "y": -11,
      "z": -5,
      "c": "#111111"
    },
    {
      "id": 1016,
      "x": -4,
      "y": -10,
      "z": -5,
      "c": "#ffd700"
    },
    {
      "id": 1017,
      "x": -4,
      "y": -9,
      "z": -5,
      "c": "#aeeeee"
    },
    {
      "id": 1018,
      "x": -4,
      "y": -8,
      "z": -5,
      "c": "#ffd700"
    },
    {
      "id": 1019,
      "x": -4,
      "y": -11,
      "z": -4,
      "c": "#111111"
    },
    {
      "id": 1020,
      "x": -4,
      "y": -10,
      "z": -4,
      "c": "#ffd700"
    },
    {
      "id": 1021,
      "x": -4,
      "y": -9,
      "z": -4,
      "c": "#ffd700"
    },
    {
      "id": 1022,
      "x": -4,
      "y": -8,
      "z": -4,
      "c": "#ffd700"
    },
    {
      "id": 1023,
      "x": -4,
      "y": -11,
      "z": -3,
      "c": "#111111"
    },
    {
      "id": 1024,
      "x": -4,
      "y": -10,
      "z": -3,
      "c": "#ffd700"
    },
    {
      "id": 1025,
      "x": -4,
      "y": -9,
      "z": -3,
      "c": "#aeeeee"
    },
    {
      "id": 1026,
      "x": -4,
      "y": -8,
      "z": -3,
      "c": "#ffd700"
    },
    {
      "id": 1027,
      "x": -3,
      "y": -11,
      "z": -5,
      "c": "#111111"
    },
    {
      "id": 1028,
      "x": -3,
      "y": -10,
      "z": -5,
      "c": "#ffd700"
    },
    {
      "id": 1029,
      "x": -3,
      "y": -9,
      "z": -5,
      "c": "#aeeeee"
    },
    {
      "id": 1030,
      "x": -3,
      "y": -8,
      "z": -5,
      "c": "#ffd700"
    },
    {
      "id": 1031,
      "x": -3,
      "y": -11,
      "z": -4,
      "c": "#111111"
    },
    {
      "id": 1032,
      "x": -3,
      "y": -10,
      "z": -4,
      "c": "#ffd700"
    },
    {
      "id": 1033,
      "x": -3,
      "y": -9,
      "z": -4,
      "c": "#ffd700"
    },
    {
      "id": 1034,
      "x": -3,
      "y": -8,
      "z": -4,
      "c": "#ffd700"
    },
    {
      "id": 1035,
      "x": -3,
      "y": -11,
      "z": -3,
      "c": "#111111"
    },
    {
      "id": 1036,
      "x": -3,
      "y": -10,
      "z": -3,
      "c": "#ffd700"
    },
    {
      "id": 1037,
      "x": -3,
      "y": -9,
      "z": -3,
      "c": "#aeeeee"
    },
    {
      "id": 1038,
      "x": -3,
      "y": -8,
      "z": -3,
      "c": "#ffd700"
    },
    {
      "id": 1039,
      "x": -2,
      "y": -11,
      "z": -5,
      "c": "#111111"
    },
    {
      "id": 1040,
      "x": -2,
      "y": -10,
      "z": -5,
      "c": "#ffd700"
    },
    {
      "id": 1041,
      "x": -2,
      "y": -9,
