{"voxels": [{"id": 0, "x": -12, "y": -12, "z": -8, "c": "#30363d"}, {"id": 1, "x": -12, "y": -12, "z": -7, "c": "#30363d"}, {"id": 2, "x": -12, "y": -12, "z": -6, "c": "#30363d"}, {"id": 3, "x": -12, "y": -12, "z": -5, "c": "#30363d"}, {"id": 4, "x": -12, "y": -12, "z": -4, "c": "#30363d"}, {"id": 5, "x": -12, "y": -12, "z": -3, "c": "#30363d"}, {"id": 6, "x": -12, "y": -12, "z": -2, "c": "#30363d"}, {"id": 7, "x": -12, "y": -12, "z": -1, "c": "#30363d"}, {"id": 8, "x": -12, "y": -12, "z": 0, "c": "#30363d"}, {"id": 9, "x": -12, "y": -12, "z": 1, "c": "#30363d"}, {"id": 10, "x": -12, "y": -12, "z": 2, "c": "#30363d"}, {"id": 11, "x": -12, "y": -12, "z": 3, "c": "#30363d"}, {"id": 12, "x": -12, "y": -12, "z": 4, "c": "#30363d"}, {"id": 13, "x": -12, "y": -12, "z": 5, "c": "#30363d"}, {"id": 14, "x": -12, "y": -12, "z": 6, "c": "#30363d"}, {"id": 15, "x": -12, "y": -12, "z": 7, "c": "#30363d"}, {"id": 16, "x": -12, "y": -12, "z": 8, "c": "#30363d"}, {"id": 17, "x": -12, "y": -12, "z": 9, "c": "#30363d"}, {"id": 18, "x": -12, "y": -12, "z": 10, "c": "#30363d"}, {"id": 19, "x": -11, "y": -12, "z": -8, "c": "#30363d"}, {"id": 20, "x": -11, "y": -12, "z": -7, "c": "#30363d"}, {"id": 21, "x": -11, "y": -12, "z": -6, "c": "#30363d"}, {"id": 22, "x": -11, "y": -12, "z": -5, "c": "#30363d"}, {"id": 23, "x": -11, "y": -12, "z": -4, "c": "#30363d"}, {"id": 24, "x": -11, "y": -12, "z": -3, "c": "#30363d"}, {"id": 25, "x": -11, "y": -12, "z": -2, "c": "#30363d"}, {"id": 26, "x": -11, "y": -12, "z": -1, "c": "#30363d"}, {"id": 27, "x": -11, "y": -12, "z": 0, "c": "#30363d"}, {"id": 28, "x": -11, "y": -12, "z": 1, "c": "#30363d"}, {"id": 29, "x": -11, "y": -12, "z": 2, "c": "#30363d"}, {"id": 30, "x": -11, "y": -12, "z": 3, "c": "#30363d"}, {"id": 31, "x": -11, "y": -12, "z": 4, "c": "#30363d"}, {"id": 32, "x": -11, "y": -12, "z": 5, "c": "#30363d"}, {"id": 33, "x": -11, "y": -12, "z": 6, "c": "#30363d"}, {"id": 34, "x": -11, "y": -12, "z": 7, "c": "#30363d"}, {"id": 35, "x": -11, "y": -12, "z": 8, "c": "#30363d"}, {"id": 36, "x": -11, "y": -12, "z": 9, "c": "#30363d"}, {"id": 37, "x": -11, "y": -12, "z": 10, "c": "#30363d"}, {"id": 38, "x": -10, "y": -12, "z": -8, "c": "#30363d"}, {"id": 39, "x": -10, "y": -12, "z": -7, "c": "#30363d"}, {"id": 40, "x": -10, "y": -12, "z": -6, "c": "#30363d"}, {"id": 41, "x": -10, "y": -12, "z": -5, "c": "#30363d"}, {"id": 42, "x": -10, "y": -12, "z": -4, "c": "#30363d"}, {"id": 43, "x": -10, "y": -12, "z": -3, "c": "#30363d"}, {"id": 44, "x": -10, "y": -12, "z": -2, "c": "#30363d"}, {"id": 45, "x": -10, "y": -12, "z": -1, "c": "#30363d"}, {"id": 46, "x": -10, "y": -12, "z": 0, "c": "#6f7378"}, {"id": 47, "x": -10, "y": -12, "z": 1, "c": "#30363d"}, {"id": 48, "x": -10, "y": -12, "z": 2, "c": "#30363d"}, {"id": 49, "x": -10, "y": -12, "z": 3, "c": "#30363d"}, {"id": 50, "x": -10, "y": -12, "z": 4, "c": "#30363d"}, {"id": 51, "x": -10, "y": -12, "z": 5, "c": "#30363d"}, {"id": 52, "x": -10, "y": -12, "z": 6, "c": "#30363d"}, {"id": 53, "x": -10, "y": -12, "z": 7, "c": "#30363d"}, {"id": 54, "x": -10, "y": -12, "z": 8, "c": "#30363d"}, {"id": 55, "x": -10, "y": -12, "z": 9, "c": "#30363d"}, {"id": 56, "x": -10, "y": -12, "z": 10, "c": "#30363d"}, {"id": 57, "x": -9, "y": -12, "z": -8, "c": "#30363d"}, {"id": 58, "x": -9, "y": -12, "z": -7, "c": "#30363d"}, {"id": 59, "x": -9, "y": -12, "z": -6, "c": "#30363d"}, {"id": 60, "x": -9, "y": -12, "z": -5, "c": "#30363d"}, {"id": 61, "x": -9, "y": -12, "z": -4, "c": "#30363d"}, {"id": 62, "x": -9, "y": -12, "z": -3, "c": "#30363d"}, {"id": 63, "x": -9, "y": -12, "z": -2, "c": "#30363d"}, {"id": 64, "x": -9, "y": -12, "z": -1, "c": "#6f7378"}, {"id": 65, "x": -9, "y": -12, "z": 0, "c": "#6f7378"}, {"id": 66, "x": -9, "y": -12, "z": 1, "c": "#6f7378"}, {"id": 67, "x": -9, "y": -12, "z": 2, "c": "#30363d"}, {"id": 68, "x": -9, "y": -12, "z": 3, "c": "#30363d"}, {"id": 69, "x": -9, "y": -12, "z": 4, "c": "#30363d"}, {"id": 70, "x": -9, "y": -12, "z": 5, "c": "#30363d"}, {"id": 71, "x": -9, "y": -12, "z": 6, "c": "#30363d"}, {"id": 72, "x": -9, "y": -12, "z": 7, "c": "#30363d"}, {"id": 73, "x": -9, "y": -12, "z": 8, "c": "#30363d"}, {"id": 74, "x": -9, "y": -12, "z": 9, "c": "#30363d"}, {"id": 75, "x": -9, "y": -12, "z": 10, "c": "#30363d"}, {"id": 76, "x": -8, "y": -12, "z": -8, "c": "#30363d"}, {"id": 77, "x": -8, "y": -12, "z": -7, "c": "#30363d"}, {"id": 78, "x": -8, "y": -12, "z": -6, "c": "#30363d"}, {"id": 79, "x": -8, "y": -12, "z": -5, "c": "#30363d"}, {"id": 80, "x": -8, "y": -12, "z": -4, "c": "#30363d"}, {"id": 81, "x": -8, "y": -12, "z": -3, "c": "#30363d"}, {"id": 82, "x": -8, "y": -12, "z": -2, "c": "#6f7378"}, {"id": 83, "x": -8, "y": -12, "z": -1, "c": "#6f7378"}, {"id": 84, "x": -8, "y": -12, "z": 0, "c": "#6f7378"}, {"id": 85, "x": -8, "y": -12, "z": 1, "c": "#6f7378"}, {"id": 86, "x": -8, "y": -12, "z": 2, "c": "#6f7378"}, {"id": 87, "x": -8, "y": -12, "z": 3, "c": "#30363d"}, {"id": 88, "x": -8, "y": -12, "z": 4, "c": "#30363d"}, {"id": 89, "x": -8, "y": -12, "z": 5, "c": "#30363d"}, {"id": 90, "x": -8, "y": -12, "z": 6, "c": "#30363d"}, {"id": 91, "x": -8, "y": -12, "z": 7, "c": "#30363d"}, {"id": 92, "x": -8, "y": -12, "z": 8, "c": "#30363d"}, {"id": 93, "x": -8, "y": -12, "z": 9, "c": "#30363d"}, {"id": 94, "x": -8, "y": -12, "z": 10, "c": "#30363d"}, {"id": 95, "x": -7, "y": -12, "z": -8, "c": "#30363d"}, {"id": 96, "x": -7, "y": -12, "z": -7, "c": "#30363d"}, {"id": 97, "x": -7, "y": -12, "z": -6, "c": "#30363d"}, {"id": 98, "x": -7, "y": -12, "z": -5, "c": "#30363d"}, {"id": 99, "x": -7, "y": -12, "z": -4, "c": "#30363d"}, {"id": 100, "x": -7, "y": -12, "z": -3, "c": "#6f7378"}, {"id": 101, "x": -7, "y": -12, "z": -2, "c": "#6f7378"}, {"id": 102, "x": -7, "y": -12, "z": -1, "c": "#6f7378"}, {"id": 103, "x": -7, "y": -12, "z": 0, "c": "#6f7378"}, {"id": 104, "x": -7, "y": -12, "z": 1, "c": "#6f7378"}, {"id": 105, "x": -7, "y": -12, "z": 2, "c": "#6f7378"}, {"id": 106, "x": -7, "y": -12, "z": 3, "c": "#6f7378"}, {"id": 107, "x": -7, "y": -12, "z": 4, "c": "#30363d"}, {"id": 108, "x": -7, "y": -12, "z": 5, "c": "#30363d"}, {"id": 109, "x": -7, "y": -12, "z": 6, "c": "#30363d"}, {"id": 110, "x": -7, "y": -12, "z": 7, "c": "#30363d"}, {"id": 111, "x": -7, "y": -12, "z": 8, "c": "#30363d"}, {"id": 112, "x": -7, "y": -12, "z": 9, "c": "#30363d"}, {"id": 113, "x": -7, "y": -12, "z": 10, "c": "#30363d"}, {"id": 114, "x": -6, "y": -12, "z": -8, "c": "#30363d"}, {"id": 115, "x": -6, "y": -12, "z": -7, "c": "#30363d"}, {"id": 116, "x": -6, "y": -12, "z": -6, "c": "#30363d"}, {"id": 117, "x": -6, "y": -12, "z": -5, "c": "#30363d"}, {"id": 118, "x": -6, "y": -12, "z": -4, "c": "#6f7378"}, {"id": 119, "x": -6, "y": -12, "z": -3, "c": "#6f7378"}, {"id": 120, "x": -6, "y": -12, "z": -2, "c": "#6f7378"}, {"id": 121, "x": -6, "y": -12, "z": -1, "c": "#6f7378"}, {"id": 122, "x": -6, "y": -12, "z": 0, "c": "#9ca2a6"}, {"id": 123, "x": -6, "y": -12, "z": 1, "c": "#6f7378"}, {"id": 124, "x": -6, "y": -12, "z": 2, "c": "#6f7378"}, {"id": 125, "x": -6, "y": -12, "z": 3, "c": "#6f7378"}, {"id": 126, "x": -6, "y": -12, "z": 4, "c": "#6f7378"}, {"id": 127, "x": -6, "y": -12, "z": 5, "c": "#30363d"}, {"id": 128, "x": -6, "y": -12, "z": 6, "c": "#30363d"}, {"id": 129, "x": -6, "y": -12, "z": 7, "c": "#30363d"}, {"id": 130, "x": -6, "y": -12, "z": 8, "c": "#30363d"}, {"id": 131, "x": -6, "y": -12, "z": 9, "c": "#30363d"}, {"id": 132, "x": -6, "y": -12, "z": 10, "c": "#30363d"}, {"id": 133, "x": -5, "y": -12, "z": -8, "c": "#30363d"}, {"id": 134, "x": -5, "y": -12, "z": -7, "c": "#30363d"}, {"id": 135, "x": -5, "y": -12, "z": -6, "c": "#30363d"}, {"id": 136, "x": -5, "y": -12, "z": -5, "c": "#6f7378"}, {"id": 137, "x": -5, "y": -12, "z": -4, "c": "#6f7378"}, {"id": 138, "x": -5, "y": -12, "z": -3, "c": "#6f7378"}, {"id": 139, "x": -5, "y": -12, "z": -2, "c": "#6f7378"}, {"id": 140, "x": -5, "y": -12, "z": -1, "c": "#9ca2a6"}, {"id": 141, "x": -5, "y": -12, "z": 0, "c": "#9ca2a6"}, {"id": 142, "x": -5, "y": -12, "z": 1, "c": "#9ca2a6"}, {"id": 143, "x": -5, "y": -12, "z": 2, "c": "#6f7378"}, {"id": 144, "x": -5, "y": -12, "z": 3, "c": "#6f7378"}, {"id": 145, "x": -5, "y": -12, "z": 4, "c": "#6f7378"}, {"id": 146, "x": -5, "y": -12, "z": 5, "c": "#6f7378"}, {"id": 147, "x": -5, "y": -12, "z": 6, "c": "#30363d"}, {"id": 148, "x": -5, "y": -12, "z": 7, "c": "#30363d"}, {"id": 149, "x": -5, "y": -12, "z": 8, "c": "#30363d"}, {"id": 150, "x": -5, "y": -12, "z": 9, "c": "#30363d"}, {"id": 151, "x": -5, "y": -12, "z": 10, "c": "#30363d"}, {"id": 152, "x": -4, "y": -12, "z": -8, "c": "#30363d"}, {"id": 153, "x": -4, "y": -12, "z": -7, "c": "#30363d"}, {"id": 154, "x": -4, "y": -12, "z": -6, "c": "#6f7378"}, {"id": 155, "x": -4, "y": -12, "z": -5, "c": "#6f7378"}, {"id": 156, "x": -4, "y": -12, "z": -4, "c": "#6f7378"}, {"id": 157, "x": -4, "y": -12, "z": -3, "c": "#6f7378"}, {"id": 158, "x": -4, "y": -12, "z": -2, "c": "#9ca2a6"}, {"id": 159, "x": -4, "y": -12, "z": -1, "c": "#9ca2a6"}, {"id": 160, "x": -4, "y": -12, "z": 0, "c": "#9ca2a6"}, {"id": 161, "x": -4, "y": -12, "z": 1, "c": "#9ca2a6"}, {"id": 162, "x": -4, "y": -12, "z": 2, "c": "#9ca2a6"}, {"id": 163, "x": -4, "y": -12, "z": 3, "c": "#6f7378"}, {"id": 164, "x": -4, "y": -12, "z": 4, "c": "#6f7378"}, {"id": 165, "x": -4, "y": -12, "z": 5, "c": "#6f7378"}, {"id": 166, "x": -4, "y": -12, "z": 6, "c": "#6f7378"}, {"id": 167, "x": -4, "y": -12, "z": 7, "c": "#30363d"}, {"id": 168, "x": -4, "y": -12, "z": 8, "c": "#30363d"}, {"id": 169, "x": -4, "y": -12, "z": 9, "c": "#30363d"}, {"id": 170, "x": -4, "y": -12, "z": 10, "c": "#30363d"}, {"id": 171, "x": -3, "y": -12, "z": -8, "c": "#30363d"}, {"id": 172, "x": -3, "y": -12, "z": -7, "c": "#6f7378"}, {"id": 173, "x": -3, "y": -12, "z": -6, "c": "#6f7378"}, {"id": 174, "x": -3, "y": -12, "z": -5, "c": "#6f7378"}, {"id": 175, "x": -3, "y": -12, "z": -4, "c": "#6f7378"}, {"id": 176, "x": -3, "y": -12, "z": -3, "c": "#9ca2a6"}, {"id": 177, "x": -3, "y": -12, "z": -2, "c": "#9ca2a6"}, {"id": 178, "x": -3, "y": -12, "z": -1, "c": "#9ca2a6"}, {"id": 179, "x": -3, "y": -12, "z": 0, "c": "#9ca2a6"}, {"id": 180, "x": -3, "y": -12, "z": 1, "c": "#9ca2a6"}, {"id": 181, "x": -3, "y": -12, "z": 2, "c": "#9ca2a6"}, {"id": 182, "x": -3, "y": -12, "z": 3, "c": "#9ca2a6"}, {"id": 183, "x": -3, "y": -12, "z": 4, "c": "#6f7378"}, {"id": 184, "x": -3, "y": -12, "z": 5, "c": "#6f7378"}, {"id": 185, "x": -3, "y": -12, "z": 6, "c": "#6f7378"}, {"id": 186, "x": -3, "y": -12, "z": 7, "c": "#6f7378"}, {"id": 187, "x": -3, "y": -12, "z": 8, "c": "#30363d"}, {"id": 188, "x": -3, "y": -12, "z": 9, "c": "#30363d"}, {"id": 189, "x": -3, "y": -12, "z": 10, "c": "#30363d"}, {"id": 190, "x": -2, "y": -12, "z": -8, "c": "#6f7378"}, {"id": 191, "x": -2, "y": -12, "z": -7, "c": "#6f7378"}, {"id": 192, "x": -2, "y": -12, "z": -6, "c": "#6f7378"}, {"id": 193, "x": -2, "y": -12, "z": -5, "c": "#6f7378"}, {"id": 194, "x": -2, "y": -12, "z": -4, "c": "#9ca2a6"}, {"id": 195, "x": -2, "y": -12, "z": -3, "c": "#9ca2a6"}, {"id": 196, "x": -2, "y": -12, "z": -2, "c": "#9ca2a6"}, {"id": 197, "x": -2, "y": -12, "z": -1, "c": "#9ca2a6"}, {"id": 198, "x": -2, "y": -12, "z": 0, "c": "#9ca2a6"}, {"id": 199, "x": -2, "y": -12, "z": 1, "c": "#9ca2a6"}, {"id": 200, "x": -2, "y": -12, "z": 2, "c": "#9ca2a6"}, {"id": 201, "x": -2, "y": -12, "z": 3, "c": "#9ca2a6"}, {"id": 202, "x": -2, "y": -12, "z": 4, "c": "#9ca2a6"}, {"id": 203, "x": -2, "y": -12, "z": 5, "c": "#6f7378"}, {"id": 204, "x": -2, "y": -12, "z": 6, "c": "#6f7378"}, {"id": 205, "x": -2, "y": -12, "z": 7, "c": "#6f7378"}, {"id": 206, "x": -2, "y": -12, "z": 8, "c": "#6f7378"}, {"id": 207, "x": -2, "y": -12, "z": 9, "c": "#30363d"}, {"id": 208, "x": -2, "y": -12, "z": 10, "c": "#30363d"}, {"id": 209, "x": -1, "y": -12, "z": -8, "c": "#6f7378"}, {"id": 210, "x": -1, "y": -12, "z": -7, "c": "#6f7378"}, {"id": 211, "x": -1, "y": -12, "z": -6, "c": "#6f7378"}, {"id": 212, "x": -1, "y": -12, "z": -5, "c": "#9ca2a6"}, {"id": 213, "x": -1, "y": -12, "z": -4, "c": "#9ca2a6"}, {"id": 214, "x": -1, "y": -12, "z": -3, "c": "#9ca2a6"}, {"id": 215, "x": -1, "y": -12, "z": -2, "c": "#9ca2a6"}, {"id": 216, "x": -1, "y": -12, "z": -1, "c": "#9ca2a6"}, {"id": 217, "x": -1, "y": -12, "z": 0, "c": "#9ca2a6"}, {"id": 218, "x": -1, "y": -12, "z": 1, "c": "#9ca2a6"}, {"id": 219, "x": -1, "y": -12, "z": 2, "c": "#9ca2a6"}, {"id": 220, "x": -1, "y": -12, "z": 3, "c": "#9ca2a6"}, {"id": 221, "x": -1, "y": -12, "z": 4, "c": "#9ca2a6"}, {"id": 222, "x": -1, "y": -12, "z": 5, "c": "#9ca2a6"}, {"id": 223, "x": -1, "y": -12, "z": 6, "c": "#6f7378"}, {"id": 224, "x": -1, "y": -12, "z": 7, "c": "#6f7378"}, {"id": 225, "x": -1, "y": -12, "z": 8, "c": "#6f7378"}, {"id": 226, "x": -1, "y": -12, "z": 9, "c": "#6f7378"}, {"id": 227, "x": -1, "y": -12, "z": 10, "c": "#30363d"}, {"id": 228, "x": 0, "y": -12, "z": -8, "c": "#6f7378"}, {"id": 229, "x": 0, "y": -12, "z": -7, "c": "#6f7378"}, {"id": 230, "x": 0, "y": -12, "z": -6, "c": "#9ca2a6"}, {"id": 231, "x": 0, "y": -12, "z": -5, "c": "#9ca2a6"}, {"id": 232, "x": 0, "y": -12, "z": -4, "c": "#9ca2a6"}, {"id": 233, "x": 0, "y": -12, "z": -3, "c": "#9ca2a6"}, {"id": 234, "x": 0, "y": -12, "z": -2, "c": "#9ca2a6"}, {"id": 235, "x": 0, "y": -12, "z": -1, "c": "#9ca2a6"}, {"id": 236, "x": 0, "y": -12, "z": 0, "c": "#9ca2a6"}, {"id": 237, "x": 0, "y": -12, "z": 1, "c": "#9ca2a6"}, {"id": 238, "x": 0, "y": -12, "z": 2, "c": "#9ca2a6"}, {"id": 239, "x": 0, "y": -12, "z": 3, "c": "#9ca2a6"}, {"id": 240, "x": 0, "y": -12, "z": 4, "c": "#9ca2a6"}, {"id": 241, "x": 0, "y": -12, "z": 5, "c": "#9ca2a6"}, {"id": 242, "x": 0, "y": -12, "z": 6, "c": "#9ca2a6"}, {"id": 243, "x": 0, "y": -12, "z": 7, "c": "#6f7378"}, {"id": 244, "x": 0, "y": -12, "z": 8, "c": "#6f7378"}, {"id": 245, "x": 0, "y": -12, "z": 9, "c": "#6f7378"}, {"id": 246, "x": 0, "y": -12, "z": 10, "c": "#6f7378"}, {"id": 247, "x": 1, "y": -12, "z": -8, "c": "#6f7378"}, {"id": 248, "x": 1, "y": -12, "z": -7, "c": "#6f7378"}, {"id": 249, "x": 1, "y": -12, "z": -6, "c": "#6f7378"}, {"id": 250, "x": 1, "y": -12, "z": -5, "c": "#9ca2a6"}, {"id": 251, "x": 1, "y": -12, "z": -4, "c": "#9ca2a6"}, {"id": 252, "x": 1, "y": -12, "z": -3, "c": "#9ca2a6"}, {"id": 253, "x": 1, "y": -12, "z": -2, "c": "#9ca2a6"}, {"id": 254, "x": 1, "y": -12, "z": -1, "c": "#9ca2a6"}, {"id": 255, "x": 1, "y": -12, "z": 0, "c": "#9ca2a6"}, {"id": 256, "x": 1, "y": -12, "z": 1, "c": "#9ca2a6"}, {"id": 257, "x": 1, "y": -12, "z": 2, "c": "#9ca2a6"}, {"id": 258, "x": 1, "y": -12, "z": 3, "c": "#9ca2a6"}, {"id": 259, "x": 1, "y": -12, "z": 4, "c": "#9ca2a6"}, {"id": 260, "x": 1, "y": -12, "z": 5, "c": "#9ca2a6"}, {"id": 261, "x": 1, "y": -12, "z": 6, "c": "#6f7378"}, {"id": 262, "x": 1, "y": -12, "z": 7, "c": "#6f7378"}, {"id": 263, "x": 1, "y": -12, "z": 8, "c": "#6f7378"}, {"id": 264, "x": 1, "y": -12, "z": 9, "c": "#6f7378"}, {"id": 265, "x": 1, "y": -12, "z": 10, "c": "#30363d"}, {"id": 266, "x": 2, "y": -12, "z": -8, "c": "#6f7378"}, {"id": 267, "x": 2, "y": -12, "z": -7, "c": "#6f7378"}, {"id": 268, "x": 2, "y": -12, "z": -6, "c": "#6f7378"}, {"id": 269, "x": 2, "y": -12, "z": -5, "c": "#6f7378"}, {"id": 270, "x": 2, "y": -12, "z": -4, "c": "#9ca2a6"}, {"id": 271, "x": 2, "y": -12, "z": -3, "c": "#9ca2a6"}, {"id": 272, "x": 2, "y": -12, "z": -2, "c": "#9ca2a6"}, {"id": 273, "x": 2, "y": -12, "z": -1, "c": "#9ca2a6"}, {"id": 274, "x": 2, "y": -12, "z": 0, "c": "#9ca2a6"}, {"id": 275, "x": 2, "y": -12, "z": 1, "c": "#9ca2a6"}, {"id": 276, "x": 2, "y": -12, "z": 2, "c": "#9ca2a6"}, {"id": 277, "x": 2, "y": -12, "z": 3, "c": "#9ca2a6"}, {"id": 278, "x": 2, "y": -12, "z": 4, "c": "#9ca2a6"}, {"id": 279, "x": 2, "y": -12, "z": 5, "c": "#6f7378"}, {"id": 280, "x": 2, "y": -12, "z": 6, "c": "#6f7378"}, {"id": 281, "x": 2, "y": -12, "z": 7, "c": "#6f7378"}, {"id": 282, "x": 2, "y": -12, "z": 8, "c": "#6f7378"}, {"id": 283, "x": 2, "y": -12, "z": 9, "c": "#30363d"}, {"id": 284, "x": 2, "y": -12, "z": 10, "c": "#30363d"}, {"id": 285, "x": 3, "y": -12, "z": -8, "c": "#30363d"}, {"id": 286, "x": 3, "y": -12, "z": -7, "c": "#6f7378"}, {"id": 287, "x": 3, "y": -12, "z": -6, "c": "#6f7378"}, {"id": 288, "x": 3, "y": -12, "z": -5, "c": "#6f7378"}, {"id": 289, "x": 3, "y": -12, "z": -4, "c": "#6f7378"}, {"id": 290, "x": 3, "y": -12, "z": -3, "c": "#9ca2a6"}, {"id": 291, "x": 3, "y": -12, "z": -2, "c": "#9ca2a6"}, {"id": 292, "x": 3, "y": -12, "z": -1, "c": "#9ca2a6"}, {"id": 293, "x": 3, "y": -12, "z": 0, "c": "#9ca2a6"}, {"id": 294, "x": 3, "y": -12, "z": 1, "c": "#9ca2a6"}, {"id": 295, "x": 3, "y": -12, "z": 2, "c": "#9ca2a6"}, {"id": 296, "x": 3, "y": -12, "z": 3, "c": "#9ca2a6"}, {"id": 297, "x": 3, "y": -12, "z": 4, "c": "#6f7378"}, {"id": 298, "x": 3, "y": -12, "z": 5, "c": "#6f7378"}, {"id": 299, "x": 3, "y": -12, "z": 6, "c": "#6f7378"}, {"id": 300, "x": 3, "y": -12, "z": 7, "c": "#6f7378"}, {"id": 301, "x": 3, "y": -12, "z": 8, "c": "#30363d"}, {"id": 302, "x": 3, "y": -12, "z": 9, "c": "#30363d"}, {"id": 303, "x": 3, "y": -12, "z": 10, "c": "#30363d"}, {"id": 304, "x": 4, "y": -12, "z": -8, "c": "#30363d"}, {"id": 305, "x": 4, "y": -12, "z": -7, "c": "#30363d"}, {"id": 306, "x": 4, "y": -12, "z": -6, "c": "#6f7378"}, {"id": 307, "x": 4, "y": -12, "z": -5, "c": "#6f7378"}, {"id": 308, "x": 4, "y": -12, "z": -4, "c": "#6f7378"}, {"id": 309, "x": 4, "y": -12, "z": -3, "c": "#6f7378"}, {"id": 310, "x": 4, "y": -12, "z": -2, "c": "#9ca2a6"}, {"id": 311, "x": 4, "y": -12, "z": -1, "c": "#9ca2a6"}, {"id": 312, "x": 4, "y": -12, "z": 0, "c": "#9ca2a6"}, {"id": 313, "x": 4, "y": -12, "z": 1, "c": "#9ca2a6"}, {"id": 314, "x": 4, "y": -12, "z": 2, "c": "#9ca2a6"}, {"id": 315, "x": 4, "y": -12, "z": 3, "c": "#6f7378"}, {"id": 316, "x": 4, "y": -12, "z": 4, "c": "#6f7378"}, {"id": 317, "x": 4, "y": -12, "z": 5, "c": "#6f7378"}, {"id": 318, "x": 4, "y": -12, "z": 6, "c": "#6f7378"}, {"id": 319, "x": 4, "y": -12, "z": 7, "c": "#30363d"}, {"id": 320, "x": 4, "y": -12, "z": 8, "c": "#30363d"}, {"id": 321, "x": 4, "y": -12, "z": 9, "c": "#30363d"}, {"id": 322, "x": 4, "y": -12, "z": 10, "c": "#30363d"}, {"id": 323, "x": 5, "y": -12, "z": -8, "c": "#30363d"}, {"id": 324, "x": 5, "y": -12, "z": -7, "c": "#30363d"}, {"id": 325, "x": 5, "y": -12, "z": -6, "c": "#30363d"}, {"id": 326, "x": 5, "y": -12, "z": -5, "c": "#6f7378"}, {"id": 327, "x": 5, "y": -12, "z": -4, "c": "#6f7378"}, {"id": 328, "x": 5, "y": -12, "z": -3, "c": "#6f7378"}, {"id": 329, "x": 5, "y": -12, "z": -2, "c": "#6f7378"}, {"id": 330, "x": 5, "y": -12, "z": -1, "c": "#9ca2a6"}, {"id": 331, "x": 5, "y": -12, "z": 0, "c": "#9ca2a6"}, {"id": 332, "x": 5, "y": -12, "z": 1, "c": "#9ca2a6"}, {"id": 333, "x": 5, "y": -12, "z": 2, "c": "#6f7378"}, {"id": 334, "x": 5, "y": -12, "z": 3, "c": "#6f7378"}, {"id": 335, "x": 5, "y": -12, "z": 4, "c": "#6f7378"}, {"id": 336, "x": 5, "y": -12, "z": 5, "c": "#6f7378"}, {"id": 337, "x": 5, "y": -12, "z": 6, "c": "#30363d"}, {"id": 338, "x": 5, "y": -12, "z": 7, "c": "#30363d"}, {"id": 339, "x": 5, "y": -12, "z": 8, "c": "#30363d"}, {"id": 340, "x": 5, "y": -12, "z": 9, "c": "#30363d"}, {"id": 341, "x": 5, "y": -12, "z": 10, "c": "#30363d"}, {"id": 342, "x": 6, "y": -12, "z": -8, "c": "#30363d"}, {"id": 343, "x": 6, "y": -12, "z": -7, "c": "#30363d"}, {"id": 344, "x": 6, "y": -12, "z": -6, "c": "#30363d"}, {"id": 345, "x": 6, "y": -12, "z": -5, "c": "#30363d"}, {"id": 346, "x": 6, "y": -12, "z": -4, "c": "#6f7378"}, {"id": 347, "x": 6, "y": -12, "z": -3, "c": "#6f7378"}, {"id": 348, "x": 6, "y": -12, "z": -2, "c": "#6f7378"}, {"id": 349, "x": 6, "y": -12, "z": -1, "c": "#6f7378"}, {"id": 350, "x": 6, "y": -12, "z": 0, "c": "#9ca2a6"}, {"id": 351, "x": 6, "y": -12, "z": 1, "c": "#6f7378"}, {"id": 352, "x": 6, "y": -12, "z": 2, "c": "#6f7378"}, {"id": 353, "x": 6, "y": -12, "z": 3, "c": "#6f7378"}, {"id": 354, "x": 6, "y": -12, "z": 4, "c": "#6f7378"}, {"id": 355, "x": 6, "y": -12, "z": 5, "c": "#30363d"}, {"id": 356, "x": 6, "y": -12, "z": 6, "c": "#30363d"}, {"id": 357, "x": 6, "y": -12, "z": 7, "c": "#30363d"}, {"id": 358, "x": 6, "y": -12, "z": 8, "c": "#30363d"}, {"id": 359, "x": 6, "y": -12, "z": 9, "c": "#30363d"}, {"id": 360, "x": 6, "y": -12, "z": 10, "c": "#30363d"}, {"id": 361, "x": 7, "y": -12, "z": -8, "c": "#30363d"}, {"id": 362, "x": 7, "y": -12, "z": -7, "c": "#30363d"}, {"id": 363, "x": 7, "y": -12, "z": -6, "c": "#30363d"}, {"id": 364, "x": 7, "y": -12, "z": -5, "c": "#30363d"}, {"id": 365, "x": 7, "y": -12, "z": -4, "c": "#30363d"}, {"id": 366, "x": 7, "y": -12, "z": -3, "c": "#6f7378"}, {"id": 367, "x": 7, "y": -12, "z": -2, "c": "#6f7378"}, {"id": 368, "x": 7, "y": -12, "z": -1, "c": "#6f7378"}, {"id": 369, "x": 7, "y": -12, "z": 0, "c": "#6f7378"}, {"id": 370, "x": 7, "y": -12, "z": 1, "c": "#6f7378"}, {"id": 371, "x": 7, "y": -12, "z": 2, "c": "#6f7378"}, {"id": 372, "x": 7, "y": -12, "z": 3, "c": "#6f7378"}, {"id": 373, "x": 7, "y": -12, "z": 4, "c": "#30363d"}, {"id": 374, "x": 7, "y": -12, "z": 5, "c": "#30363d"}, {"id": 375, "x": 7, "y": -12, "z": 6, "c": "#30363d"}, {"id": 376, "x": 7, "y": -12, "z": 7, "c": "#30363d"}, {"id": 377, "x": 7, "y": -12, "z": 8, "c": "#30363d"}, {"id": 378, "x": 7, "y": -12, "z": 9, "c": "#30363d"}, {"id": 379, "x": 7, "y": -12, "z": 10, "c": "#30363d"}, {"id": 380, "x": 8, "y": -12, "z": -8, "c": "#30363d"}, {"id": 381, "x": 8, "y": -12, "z": -7, "c": "#30363d"}, {"id": 382, "x": 8, "y": -12, "z": -6, "c": "#30363d"}, {"id": 383, "x": 8, "y": -12, "z": -5, "c": "#30363d"}, {"id": 384, "x": 8, "y": -12, "z": -4, "c": "#30363d"}, {"id": 385, "x": 8, "y": -12, "z": -3, "c": "#30363d"}, {"id": 386, "x": 8, "y": -12, "z": -2, "c": "#6f7378"}, {"id": 387, "x": 8, "y": -12, "z": -1, "c": "#6f7378"}, {"id": 388, "x": 8, "y": -12, "z": 0, "c": "#6f7378"}, {"id": 389, "x": 8, "y": -12, "z": 1, "c": "#6f7378"}, {"id": 390, "x": 8, "y": -12, "z": 2, "c": "#6f7378"}, {"id": 391, "x": 8, "y": -12, "z": 3, "c": "#30363d"}, {"id": 392, "x": 8, "y": -12, "z": 4, "c": "#30363d"}, {"id": 393, "x": 8, "y": -12, "z": 5, "c": "#30363d"}, {"id": 394, "x": 8, "y": -12, "z": 6, "c": "#30363d"}, {"id": 395, "x": 8, "y": -12, "z": 7, "c": "#30363d"}, {"id": 396, "x": 8, "y": -12, "z": 8, "c": "#30363d"}, {"id": 397, "x": 8, "y": -12, "z": 9, "c": "#30363d"}, {"id": 398, "x": 8, "y": -12, "z": 10, "c": "#30363d"}, {"id": 399, "x": 9, "y": -12, "z": -8, "c": "#30363d"}, {"id": 400, "x": 9, "y": -12, "z": -7, "c": "#30363d"}, {"id": 401, "x": 9, "y": -12, "z": -6, "c": "#30363d"}, {"id": 402, "x": 9, "y": -12, "z": -5, "c": "#30363d"}, {"id": 403, "x": 9, "y": -12, "z": -4, "c": "#30363d"}, {"id": 404, "x": 9, "y": -12, "z": -3, "c": "#30363d"}, {"id": 405, "x": 9, "y": -12, "z": -2, "c": "#30363d"}, {"id": 406, "x": 9, "y": -12, "z": -1, "c": "#6f7378"}, {"id": 407, "x": 9, "y": -12, "z": 0, "c": "#6f7378"}, {"id": 408, "x": 9, "y": -12, "z": 1, "c": "#6f7378"}, {"id": 409, "x": 9, "y": -12, "z": 2, "c": "#30363d"}, {"id": 410, "x": 9, "y": -12, "z": 3, "c": "#30363d"}, {"id": 411, "x": 9, "y": -12, "z": 4, "c": "#30363d"}, {"id": 412, "x": 9, "y": -12, "z": 5, "c": "#30363d"}, {"id": 413, "x": 9, "y": -12, "z": 6, "c": "#30363d"}, {"id": 414, "x": 9, "y": -12, "z": 7, "c": "#30363d"}, {"id": 415, "x": 9, "y": -12, "z": 8, "c": "#30363d"}, {"id": 416, "x": 9, "y": -12, "z": 9, "c": "#30363d"}, {"id": 417, "x": 9, "y": -12, "z": 10, "c": "#30363d"}, {"id": 418, "x": 10, "y": -12, "z": -8, "c": "#30363d"}, {"id": 419, "x": 10, "y": -12, "z": -7, "c": "#30363d"}, {"id": 420, "x": 10, "y": -12, "z": -6, "c": "#30363d"}, {"id": 421, "x": 10, "y": -12, "z": -5, "c": "#30363d"}, {"id": 422, "x": 10, "y": -12, "z": -4, "c": "#30363d"}, {"id": 423, "x": 10, "y": -12, "z": -3, "c": "#30363d"}, {"id": 424, "x": 10, "y": -12, "z": -2, "c": "#30363d"}, {"id": 425, "x": 10, "y": -12, "z": -1, "c": "#30363d"}, {"id": 426, "x": 10, "y": -12, "z": 0, "c": "#6f7378"}, {"id": 427, "x": 10, "y": -12, "z": 1, "c": "#30363d"}, {"id": 428, "x": 10, "y": -12, "z": 2, "c": "#30363d"}, {"id": 429, "x": 10, "y": -12, "z": 3, "c": "#30363d"}, {"id": 430, "x": 10, "y": -12, "z": 4, "c": "#30363d"}, {"id": 431, "x": 10, "y": -12, "z": 5, "c": "#30363d"}, {"id": 432, "x": 10, "y": -12, "z": 6, "c": "#30363d"}, {"id": 433, "x": 10, "y": -12, "z": 7, "c": "#30363d"}, {"id": 434, "x": 10, "y": -12, "z": 8, "c": "#30363d"}, {"id": 435, "x": 10, "y": -12, "z": 9, "c": "#30363d"}, {"id": 436, "x": 10, "y": -12, "z": 10, "c": "#30363d"}, {"id": 437, "x": 11, "y": -12, "z": -8, "c": "#30363d"}, {"id": 438, "x": 11, "y": -12, "z": -7, "c": "#30363d"}, {"id": 439, "x": 11, "y": -12, "z": -6, "c": "#30363d"}, {"id": 440, "x": 11, "y": -12, "z": -5, "c": "#30363d"}, {"id": 441, "x": 11, "y": -12, "z": -4, "c": "#30363d"}, {"id": 442, "x": 11, "y": -12, "z": -3, "c": "#30363d"}, {"id": 443, "x": 11, "y": -12, "z": -2, "c": "#30363d"}, {"id": 444, "x": 11, "y": -12, "z": -1, "c": "#30363d"}, {"id": 445, "x": 11, "y": -12, "z": 0, "c": "#30363d"}, {"id": 446, "x": 11, "y": -12, "z": 1, "c": "#30363d"}, {"id": 447, "x": 11, "y": -12, "z": 2, "c": "#30363d"}, {"id": 448, "x": 11, "y": -12, "z": 3, "c": "#30363d"}, {"id": 449, "x": 11, "y": -12, "z": 4, "c": "#30363d"}, {"id": 450, "x": 11, "y": -12, "z": 5, "c": "#30363d"}, {"id": 451, "x": 11, "y": -12, "z": 6, "c": "#30363d"}, {"id": 452, "x": 11, "y": -12, "z": 7, "c": "#30363d"}, {"id": 453, "x": 11, "y": -12, "z": 8, "c": "#30363d"}, {"id": 454, "x": 11, "y": -12, "z": 9, "c": "#30363d"}, {"id": 455, "x": 11, "y": -12, "z": 10, "c": "#30363d"}, {"id": 456, "x": 12, "y": -12, "z": -8, "c": "#30363d"}, {"id": 457, "x": 12, "y": -12, "z": -7, "c": "#30363d"}, {"id": 458, "x": 12, "y": -12, "z": -6, "c": "#30363d"}, {"id": 459, "x": 12, "y": -12, "z": -5, "c": "#30363d"}, {"id": 460, "x": 12, "y": -12, "z": -4, "c": "#30363d"}, {"id": 461, "x": 12, "y": -12, "z": -3, "c": "#30363d"}, {"id": 462, "x": 12, "y": -12, "z": -2, "c": "#30363d"}, {"id": 463, "x": 12, "y": -12, "z": -1, "c": "#30363d"}, {"id": 464, "x": 12, "y": -12, "z": 0, "c": "#30363d"}, {"id": 465, "x": 12, "y": -12, "z": 1, "c": "#30363d"}, {"id": 466, "x": 12, "y": -12, "z": 2, "c": "#30363d"}, {"id": 467, "x": 12, "y": -12, "z": 3, "c": "#30363d"}, {"id": 468, "x": 12, "y": -12, "z": 4, "c": "#30363d"}, {"id": 469, "x": 12, "y": -12, "z": 5, "c": "#30363d"}, {"id": 470, "x": 12, "y": -12, "z": 6, "c": "#30363d"}, {"id": 471, "x": 12, "y": -12, "z": 7, "c": "#30363d"}, {"id": 472, "x": 12, "y": -12, "z": 8, "c": "#30363d"}, {"id": 473, "x": 12, "y": -12, "z": 9, "c": "#30363d"}, {"id": 474, "x": 12, "y": -12, "z": 10, "c": "#30363d"}, {"id": 475, "x": -9, "y": -11, "z": 7, "c": "#b0a89c"}, {"id": 476, "x": -7, "y": -11, "z": 7, "c": "#b0a89c"}, {"id": 477, "x": -8, "y": -11, "z": 6, "c": "#b0a89c"}, {"id": 478, "x": -8, "y": -11, "z": 8, "c": "#b0a89c"}, {"id": 479, "x": -8, "y": -11, "z": 7, "c": "#b0a89c"}, {"id": 480, "x": -8, "y": -10, "z": 7, "c": "#4f6274"}, {"id": 481, "x": -9, "y": -11, "z": 8, "c": "#b0a89c"}, {"id": 482, "x": -7, "y": -11, "z": 8, "c": "#b0a89c"}, {"id": 483, "x": -8, "y": -11, "z": 9, "c": "#4f6274"}, {"id": 484, "x": -8, "y": -10, "z": 8, "c": "#4f6274"}, {"id": 485, "x": -9, "y": -11, "z": 9, "c": "#b0a89c"}, {"id": 486, "x": -7, "y": -11, "z": 9, "c": "#b0a89c"}, {"id": 487, "x": -8, "y": -11, "z": 10, "c": "#b0a89c"}, {"id": 488, "x": -8, "y": -10, "z": 9, "c": "#4f6274"}, {"id": 489, "x": 7, "y": -11, "z": 7, "c": "#b0a89c"}, {"id": 490, "x": 9, "y": -11, "z": 7, "c": "#b0a89c"}, {"id": 491, "x": 8, "y": -11, "z": 6, "c": "#b0a89c"}, {"id": 492, "x": 8, "y": -11, "z": 8, "c": "#b0a89c"}, {"id": 493, "x": 8, "y": -11, "z": 7, "c": "#b0a89c"}, {"id": 494, "x": 8, "y": -10, "z": 7, "c": "#4f6274"}, {"id": 495, "x": 7, "y": -11, "z": 8, "c": "#b0a89c"}, {"id": 496, "x": 9, "y": -11, "z": 8, "c": "#b0a89c"}, {"id": 497, "x": 8, "y": -11, "z": 9, "c": "#4f6274"}, {"id": 498, "x": 8, "y": -10, "z": 8, "c": "#4f6274"}, {"id": 499, "x": 7, "y": -11, "z": 9, "c": "#b0a89c"}, {"id": 500, "x": 9, "y": -11, "z": 9, "c": "#b0a89c"}, {"id": 501, "x": 8, "y": -11, "z": 10, "c": "#b0a89c"}, {"id": 502, "x": 8, "y": -10, "z": 9, "c": "#4f6274"}, {"id": 503, "x": -4, "y": -11, "z": 7, "c": "#30363d"}, {"id": 504, "x": -4, "y": -11, "z": 8, "c": "#30363d"}, {"id": 505, "x": -4, "y": -11, "z": 9, "c": "#30363d"}, {"id": 506, "x": -3, "y": -11, "z": 7, "c": "#6f7378"}, {"id": 507, "x": -3, "y": -11, "z": 8, "c": "#30363d"}, {"id": 508, "x": -3, "y": -11, "z": 9, "c": "#30363d"}, {"id": 509, "x": -2, "y": -11, "z": 7, "c": "#6f7378"}, {"id": 510, "x": -2, "y": -11, "z": 8, "c": "#6f7378"}, {"id": 511, "x": -2, "y": -11, "z": 9, "c": "#30363d"}, {"id": 512, "x": -1, "y": -11, "z": 7, "c": "#6f7378"}, {"id": 513, "x": -1, "y": -11, "z": 8, "c": "#6f7378"}, {"id": 514, "x": -1, "y": -11, "z": 9, "c": "#6f7378"}, {"id": 515, "x": 0, "y": -11, "z": 7, "c": "#6f7378"}, {"id": 516, "x": 0, "y": -11, "z": 8, "c": "#6f7378"}, {"id": 517, "x": 0, "y": -11, "z": 9, "c": "#6f7378"}, {"id": 518, "x": 1, "y": -11, "z": 7, "c": "#6f7378"}, {"id": 519, "x": 1, "y": -11, "z": 8, "c": "#6f7378"}, {"id": 520, "x": 1, "y": -11, "z": 9, "c": "#6f7378"}, {"id": 521, "x": 2, "y": -11, "z": 7, "c": "#6f7378"}, {"id": 522, "x": 2, "y": -11, "z": 8, "c": "#6f7378"}, {"id": 523, "x": 2, "y": -11, "z": 9, "c": "#30363d"}, {"id": 524, "x": 3, "y": -11, "z": 7, "c": "#6f7378"}, {"id": 525, "x": 3, "y": -11, "z": 8, "c": "#30363d"}, {"id": 526, "x": 3, "y": -11, "z": 9, "c": "#30363d"}, {"id": 527, "x": 4, "y": -11, "z": 7, "c": "#30363d"}, {"id": 528, "x": 4, "y": -11, "z": 8, "c": "#30363d"}, {"id": 529, "x": 4, "y": -11, "z": 9, "c": "#30363d"}, {"id": 530, "x": -4, "y": -10, "z": 8, "c": "#30363d"}, {"id": 531, "x": -4, "y": -10, "z": 9, "c": "#30363d"}, {"id": 532, "x": -3, "y": -10, "z": 8, "c": "#30363d"}, {"id": 533, "x": -3, "y": -10, "z": 9, "c": "#30363d"}, {"id": 534, "x": -2, "y": -10, "z": 8, "c": "#30363d"}, {"id": 535, "x": -2, "y": -10, "z": 9, "c": "#30363d"}, {"id": 536, "x": -1, "y": -10, "z": 8, "c": "#30363d"}, {"id": 537, "x": -1, "y": -10, "z": 9, "c": "#30363d"}, {"id": 538, "x": 0, "y": -10, "z": 8, "c": "#6f7378"}, {"id": 539, "x": 0, "y": -10, "z": 9, "c": "#30363d"}, {"id": 540, "x": 1, "y": -10, "z": 8, "c": "#30363d"}, {"id": 541, "x": 1, "y": -10, "z": 9, "c": "#30363d"}, {"id": 542, "x": 2, "y": -10, "z": 8, "c": "#30363d"}, {"id": 543, "x": 2, "y": -10, "z": 9, "c": "#30363d"}, {"id": 544, "x": 3, "y": -10, "z": 8, "c": "#30363d"}, {"id": 545, "x": 3, "y": -10, "z": 9, "c": "#30363d"}, {"id": 546, "x": 4, "y": -10, "z": 8, "c": "#30363d"}, {"id": 547, "x": 4, "y": -10, "z": 9, "c": "#30363d"}, {"id": 548, "x": -4, "y": -9, "z": 9, "c": "#9ca2a6"}, {"id": 549, "x": -3, "y": -9, "z": 9, "c": "#9ca2a6"}, {"id": 550, "x": -2, "y": -9, "z": 9, "c": "#9ca2a6"}, {"id": 551, "x": -1, "y": -9, "z": 9, "c": "#9ca2a6"}, {"id": 552, "x": 0, "y": -9, "z": 9, "c": "#9ca2a6"}, {"id": 553, "x": 1, "y": -9, "z": 9, "c": "#9ca2a6"}, {"id": 554, "x": 2, "y": -9, "z": 9, "c": "#9ca2a6"}, {"id": 555, "x": 3, "y": -9, "z": 9, "c": "#9ca2a6"}, {"id": 556, "x": 4, "y": -9, "z": 9, "c": "#9ca2a6"}, {"id": 557, "x": -10, "y": -11, "z": -6, "c": "#b0a89c"}, {"id": 558, "x": -10, "y": -11, "z": -5, "c": "#b0a89c"}, {"id": 559, "x": -10, "y": -11, "z": -4, "c": "#b0a89c"}, {"id": 560, "x": -10, "y": -11, "z": -3, "c": "#b0a89c"}, {"id": 561, "x": -10, "y": -11, "z": -2, "c": "#b0a89c"}, {"id": 562, "x": -10, "y": -11, "z": -1, "c": "#b0a89c"}, {"id": 563, "x": -10, "y": -11, "z": 0, "c": "#b0a89c"}, {"id": 564, "x": -10, "y": -11, "z": 1, "c": "#b0a89c"}, {"id": 565, "x": -10, "y": -11, "z": 2, "c": "#b0a89c"}, {"id": 566, "x": -10, "y": -11, "z": 3, "c": "#b0a89c"}, {"id": 567, "x": -10, "y": -11, "z": 4, "c": "#b0a89c"}, {"id": 568, "x": -10, "y": -11, "z": 5, "c": "#b0a89c"}, {"id": 569, "x": -10, "y": -11, "z": 6, "c": "#b0a89c"}, {"id": 570, "x": -9, "y": -11, "z": -6, "c": "#b0a89c"}, {"id": 571, "x": -9, "y": -11, "z": 6, "c": "#b0a89c"}, {"id": 572, "x": -8, "y": -11, "z": -6, "c": "#b0a89c"}, {"id": 573, "x": -7, "y": -11, "z": -6, "c": "#b0a89c"}, {"id": 574, "x": -7, "y": -11, "z": 6, "c": "#b0a89c"}, {"id": 575, "x": -6, "y": -11, "z": -6, "c": "#b0a89c"}, {"id": 576, "x": -6, "y": -11, "z": 6, "c": "#b0a89c"}, {"id": 577, "x": -5, "y": -11, "z": -6, "c": "#b0a89c"}, {"id": 578, "x": -5, "y": -11, "z": 6, "c": "#b0a89c"}, {"id": 579, "x": -4, "y": -11, "z": -6, "c": "#b0a89c"}, {"id": 580, "x": -4, "y": -11, "z": 6, "c": "#b0a89c"}, {"id": 581, "x": -3, "y": -11, "z": -6, "c": "#b0a89c"}, {"id": 582, "x": -3, "y": -11, "z": 6, "c": "#b0a89c"}, {"id": 583, "x": -2, "y": -11, "z": -6, "c": "#b0a89c"}, {"id": 584, "x": -2, "y": -11, "z": 6, "c": "#674f3c"}, {"id": 585, "x": -1, "y": -11, "z": -6, "c": "#b0a89c"}, {"id": 586, "x": -1, "y": -11, "z": 6, "c": "#674f3c"}, {"id": 587, "x": 0, "y": -11, "z": -6, "c": "#b0a89c"}, {"id": 588, "x": 0, "y": -11, "z": 6, "c": "#674f3c"}, {"id": 589, "x": 1, "y": -11, "z": -6, "c": "#b0a89c"}, {"id": 590, "x": 1, "y": -11, "z": 6, "c": "#674f3c"}, {"id": 591, "x": 2, "y": -11, "z": -6, "c": "#b0a89c"}, {"id": 592, "x": 2, "y": -11, "z": 6, "c": "#674f3c"}, {"id": 593, "x": 3, "y": -11, "z": -6, "c": "#b0a89c"}, {"id": 594, "x": 3, "y": -11, "z": 6, "c": "#b0a89c"}, {"id": 595, "x": 4, "y": -11, "z": -6, "c": "#b0a89c"}, {"id": 596, "x": 4, "y": -11, "z": 6, "c": "#b0a89c"}, {"id": 597, "x": 5, "y": -11, "z": -6, "c": "#b0a89c"}, {"id": 598, "x": 5, "y": -11, "z": 6, "c": "#b0a89c"}, {"id": 599, "x": 6, "y": -11, "z": -6, "c": "#b0a89c"}, {"id": 600, "x": 6, "y": -11, "z": 6, "c": "#b0a89c"}, {"id": 601, "x": 7, "y": -11, "z": -6, "c": "#b0a89c"}, {"id": 602, "x": 7, "y": -11, "z": 6, "c": "#b0a89c"}, {"id": 603, "x": 8, "y": -11, "z": -6, "c": "#b0a89c"}, {"id": 604, "x": 9, "y": -11, "z": -6, "c": "#b0a89c"}, {"id": 605, "x": 9, "y": -11, "z": 6, "c": "#b0a89c"}, {"id": 606, "x": 10, "y": -11, "z": -6, "c": "#b0a89c"}, {"id": 607, "x": 10, "y": -11, "z": -5, "c": "#b0a89c"}, {"id": 608, "x": 10, "y": -11, "z": -4, "c": "#b0a89c"}, {"id": 609, "x": 10, "y": -11, "z": -3, "c": "#b0a89c"}, {"id": 610, "x": 10, "y": -11, "z": -2, "c": "#b0a89c"}, {"id": 611, "x": 10, "y": -11, "z": -1, "c": "#b0a89c"}, {"id": 612, "x": 10, "y": -11, "z": 0, "c": "#b0a89c"}, {"id": 613, "x": 10, "y": -11, "z": 1, "c": "#b0a89c"}, {"id": 614, "x": 10, "y": -11, "z": 2, "c": "#b0a89c"}, {"id": 615, "x": 10, "y": -11, "z": 3, "c": "#b0a89c"}, {"id": 616, "x": 10, "y": -11, "z": 4, "c": "#b0a89c"}, {"id": 617, "x": 10, "y": -11, "z": 5, "c": "#b0a89c"}, {"id": 618, "x": 10, "y": -11, "z": 6, "c": "#b0a89c"}, {"id": 619, "x": -10, "y": -10, "z": -6, "c": "#b0a89c"}, {"id": 620, "x": -10, "y": -10, "z": -5, "c": "#b0a89c"}, {"id": 621, "x": -10, "y": -10, "z": -4, "c": "#b0a89c"}, {"id": 622, "x": -10, "y": -10, "z": -3, "c": "#b0a89c"}, {"id": 623, "x": -10, "y": -10, "z": -2, "c": "#b0a89c"}, {"id": 624, "x": -10, "y": -10, "z": -1, "c": "#b0a89c"}, {"id": 625, "x": -10, "y": -10, "z": 0, "c": "#b0a89c"}, {"id": 626, "x": -10, "y": -10, "z": 1, "c": "#b0a89c"}, {"id": 627, "x": -10, "y": -10, "z": 2, "c": "#b0a89c"}, {"id": 628, "x": -10, "y": -10, "z": 3, "c": "#b0a89c"}, {"id": 629, "x": -10, "y": -10, "z": 4, "c": "#b0a89c"}, {"id": 630, "x": -10, "y": -10, "z": 5, "c": "#b0a89c"}, {"id": 631, "x": -10, "y": -10, "z": 6, "c": "#b0a89c"}, {"id": 632, "x": -9, "y": -10, "z": -6, "c": "#b0a89c"}, {"id": 633, "x": -9, "y": -10, "z": 6, "c": "#b0a89c"}, {"id": 634, "x": -8, "y": -10, "z": -6, "c": "#b0a89c"}, {"id": 635, "x": -8, "y": -10, "z": 6, "c": "#b0a89c"}, {"id": 636, "x": -7, "y": -10, "z": -6, "c": "#b0a89c"}, {"id": 637, "x": -7, "y": -10, "z": 6, "c": "#b0a89c"}, {"id": 638, "x": -6, "y": -10, "z": -6, "c": "#b0a89c"}, {"id": 639, "x": -6, "y": -10, "z": 6, "c": "#b0a89c"}, {"id": 640, "x": -5, "y": -10, "z": -6, "c": "#b0a89c"}, {"id": 641, "x": -5, "y": -10, "z": 6, "c": "#b0a89c"}, {"id": 642, "x": -4, "y": -10, "z": -6, "c": "#b0a89c"}, {"id": 643, "x": -4, "y": -10, "z": 6, "c": "#b0a89c"}, {"id": 644, "x": -3, "y": -10, "z": -6, "c": "#b0a89c"}, {"id": 645, "x": -3, "y": -10, "z": 6, "c": "#b0a89c"}, {"id": 646, "x": -2, "y": -10, "z": -6, "c": "#b0a89c"}, {"id": 647, "x": -2, "y": -10, "z": 6, "c": "#674f3c"}, {"id": 648, "x": -1, "y": -10, "z": -6, "c": "#b0a89c"}, {"id": 649, "x": -1, "y": -10, "z": 6, "c": "#674f3c"}, {"id": 650, "x": 0, "y": -10, "z": -6, "c": "#b0a89c"}, {"id": 651, "x": 0, "y": -10, "z": 6, "c": "#674f3c"}, {"id": 652, "x": 1, "y": -10, "z": -6, "c": "#b0a89c"}, {"id": 653, "x": 1, "y": -10, "z": 6, "c": "#674f3c"}, {"id": 654, "x": 2, "y": -10, "z": -6, "c": "#b0a89c"}, {"id": 655, "x": 2, "y": -10, "z": 6, "c": "#674f3c"}, {"id": 656, "x": 3, "y": -10, "z": -6, "c": "#b0a89c"}, {"id": 657, "x": 3, "y": -10, "z": 6, "c": "#b0a89c"}, {"id": 658, "x": 4, "y": -10, "z": -6, "c": "#b0a89c"}, {"id": 659, "x": 4, "y": -10, "z": 6, "c": "#b0a89c"}, {"id": 660, "x": 5, "y": -10, "z": -6, "c": "#b0a89c"}, {"id": 661, "x": 5, "y": -10, "z": 6, "c": "#b0a89c"}, {"id": 662, "x": 6, "y": -10, "z": -6, "c": "#b0a89c"}, {"id": 663, "x": 6, "y": -10, "z": 6, "c": "#b0a89c"}, {"id": 664, "x": 7, "y": -10, "z": -6, "c": "#b0a89c"}, {"id": 665, "x": 7, "y": -10, "z": 6, "c": "#b0a89c"}, {"id": 666, "x": 8, "y": -10, "z": -6, "c": "#b0a89c"}, {"id": 667, "x": 8, "y": -10, "z": 6, "c": "#b0a89c"}, {"id": 668, "x": 9, "y": -10, "z": -6, "c": "#b0a89c"}, {"id": 669, "x": 9, "y": -10, "z": 6, "c": "#b0a89c"}, {"id": 670, "x": 10, "y": -10, "z": -6, "c": "#b0a89c"}, {"id": 671, "x": 10, "y": -10, "z": -5, "c": "#b0a89c"}, {"id": 672, "x": 10, "y": -10, "z": -4, "c": "#b0a89c"}, {"id": 673, "x": 10, "y": -10, "z": -3, "c": "#b0a89c"}, {"id": 674, "x": 10, "y": -10, "z": -2, "c": "#b0a89c"}, {"id": 675, "x": 10, "y": -10, "z": -1, "c": "#b0a89c"}, {"id": 676, "x": 10, "y": -10, "z": 0, "c": "#b0a89c"}, {"id": 677, "x": 10, "y": -10, "z": 1, "c": "#b0a89c"}, {"id": 678, "x": 10, "y": -10, "z": 2, "c": "#b0a89c"}, {"id": 679, "x": 10, "y": -10, "z": 3, "c": "#b0a89c"}, {"id": 680, "x": 10, "y": -10, "z": 4, "c": "#b0a89c"}, {"id": 681, "x": 10, "y": -10, "z": 5, "c": "#b0a89c"}, {"id": 682, "x": 10, "y": -10, "z": 6, "c": "#b0a89c"}, {"id": 683, "x": -10, "y": -9, "z": -6, "c": "#b0a89c"}, {"id": 684, "x": -10, "y": -9, "z": -5, "c": "#b0a89c"}, {"id": 685, "x": -10, "y": -9, "z": -4, "c": "#b0a89c"}, {"id": 686, "x": -10, "y": -9, "z": -3, "c": "#b0a89c"}, {"id": 687, "x": -10, "y": -9, "z": -2, "c": "#b0a89c"}, {"id": 688, "x": -10, "y": -9, "z": -1, "c": "#b0a89c"}, {"id": 689, "x": -10, "y": -9, "z": 0, "c": "#b0a89c"}, {"id": 690, "x": -10, "y": -9, "z": 1, "c": "#b0a89c"}, {"id": 691, "x": -10, "y": -9, "z": 2, "c": "#b0a89c"}, {"id": 692, "x": -10, "y": -9, "z": 3, "c": "#b0a89c"}, {"id": 693, "x": -10, "y": -9, "z": 4, "c": "#b0a89c"}, {"id": 694, "x": -10, "y": -9, "z": 5, "c": "#b0a89c"}, {"id": 695, "x": -10, "y": -9, "z": 6, "c": "#b0a89c"}, {"id": 696, "x": -9, "y": -9, "z": -6, "c": "#60737e"}, {"id": 697, "x": -9, "y": -9, "z": 6, "c": "#60737e"}, {"id": 698, "x": -8, "y": -9, "z": -6, "c": "#b0a89c"}, {"id": 699, "x": -8, "y": -9, "z": 6, "c": "#b0a89c"}, {"id": 700, "x": -7, "y": -9, "z": -6, "c": "#60737e"}, {"id": 701, "x": -7, "y": -9, "z": 6, "c": "#60737e"}, {"id": 702, "x": -6, "y": -9, "z": -6, "c": "#b0a89c"}, {"id": 703, "x": -6, "y": -9, "z": 6, "c": "#b0a89c"}, {"id": 704, "x": -5, "y": -9, "z": -6, "c": "#60737e"}, {"id": 705, "x": -5, "y": -9, "z": 6, "c": "#60737e"}, {"id": 706, "x": -4, "y": -9, "z": -6, "c": "#b0a89c"}, {"id": 707, "x": -4, "y": -9, "z": 6, "c": "#b0a89c"}, {"id": 708, "x": -3, "y": -9, "z": -6, "c": "#60737e"}, {"id": 709, "x": -3, "y": -9, "z": 6, "c": "#60737e"}, {"id": 710, "x": -2, "y": -9, "z": -6, "c": "#b0a89c"}, {"id": 711, "x": -2, "y": -9, "z": 6, "c": "#674f3c"}, {"id": 712, "x": -1, "y": -9, "z": -6, "c": "#60737e"}, {"id": 713, "x": -1, "y": -9, "z": 6, "c": "#674f3c"}, {"id": 714, "x": 0, "y": -9, "z": -6, "c": "#b0a89c"}, {"id": 715, "x": 0, "y": -9, "z": 6, "c": "#674f3c"}, {"id": 716, "x": 1, "y": -9, "z": -6, "c": "#60737e"}, {"id": 717, "x": 1, "y": -9, "z": 6, "c": "#674f3c"}, {"id": 718, "x": 2, "y": -9, "z": -6, "c": "#b0a89c"}, {"id": 719, "x": 2, "y": -9, "z": 6, "c": "#674f3c"}, {"id": 720, "x": 3, "y": -9, "z": -6, "c": "#60737e"}, {"id": 721, "x": 3, "y": -9, "z": 6, "c": "#60737e"}, {"id": 722, "x": 4, "y": -9, "z": -6, "c": "#b0a89c"}, {"id": 723, "x": 4, "y": -9, "z": 6, "c": "#b0a89c"}, {"id": 724, "x": 5, "y": -9, "z": -6, "c": "#60737e"}, {"id": 725, "x": 5, "y": -9, "z": 6, "c": "#60737e"}, {"id": 726, "x": 6, "y": -9, "z": -6, "c": "#b0a89c"}, {"id": 727, "x": 6, "y": -9, "z": 6, "c": "#b0a89c"}, {"id": 728, "x": 7, "y": -9, "z": -6, "c": "#60737e"}, {"id": 729, "x": 7, "y": -9, "z": 6, "c": "#60737e"}, {"id": 730, "x": 8, "y": -9, "z": -6, "c": "#b0a89c"}, {"id": 731, "x": 8, "y": -9, "z": 6, "c": "#b0a89c"}, {"id": 732, "x": 9, "y": -9, "z": -6, "c": "#60737e"}, {"id": 733, "x": 9, "y": -9, "z": 6, "c": "#60737e"}, {"id": 734, "x": 10, "y": -9, "z": -6, "c": "#b0a89c"}, {"id": 735, "x": 10, "y": -9, "z": -5, "c": "#b0a89c"}, {"id": 736, "x": 10, "y": -9, "z": -4, "c": "#b0a89c"}, {"id": 737, "x": 10, "y": -9, "z": -3, "c": "#b0a89c"}, {"id": 738, "x": 10, "y": -9, "z": -2, "c": "#b0a89c"}, {"id": 739, "x": 10, "y": -9, "z": -1, "c": "#b0a89c"}, {"id": 740, "x": 10, "y": -9, "z": 0, "c": "#b0a89c"}, {"id": 741, "x": 10, "y": -9, "z": 1, "c": "#b0a89c"}, {"id": 742, "x": 10, "y": -9, "z": 2, "c": "#b0a89c"}, {"id": 743, "x": 10, "y": -9, "z": 3, "c": "#b0a89c"}, {"id": 744, "x": 10, "y": -9, "z": 4, "c": "#b0a89c"}, {"id": 745, "x": 10, "y": -9, "z": 5, "c": "#b0a89c"}, {"id": 746, "x": 10, "y": -9, "z": 6, "c": "#b0a89c"}, {"id": 747, "x": -10, "y": -8, "z": -6, "c": "#c6beb1"}, {"id": 748, "x": -10, "y": -8, "z": -5, "c": "#c6beb1"}, {"id": 749, "x": -10, "y": -8, "z": -4, "c": "#c6beb1"}, {"id": 750, "x": -10, "y": -8, "z": -3, "c": "#c6beb1"}, {"id": 751, "x": -10, "y": -8, "z": -2, "c": "#c6beb1"}, {"id": 752, "x": -10, "y": -8, "z": -1, "c": "#c6beb1"}, {"id": 753, "x": -10, "y": -8, "z": 0, "c": "#c6beb1"}, {"id": 754, "x": -10, "y": -8, "z": 1, "c": "#c6beb1"}, {"id": 755, "x": -10, "y": -8, "z": 2, "c": "#c6beb1"}, {"id": 756, "x": -10, "y": -8, "z": 3, "c": "#c6beb1"}, {"id": 757, "x": -10, "y": -8, "z": 4, "c": "#c6beb1"}, {"id": 758, "x": -10, "y": -8, "z": 5, "c": "#c6beb1"}, {"id": 759, "x": -10, "y": -8, "z": 6, "c": "#c6beb1"}, {"id": 760, "x": -9, "y": -8, "z": -6, "c": "#c6beb1"}, {"id": 761, "x": -9, "y": -8, "z": 6, "c": "#c6beb1"}, {"id": 762, "x": -8, "y": -8, "z": -6, "c": "#c6beb1"}, {"id": 763, "x": -8, "y": -8, "z": 6, "c": "#c6beb1"}, {"id": 764, "x": -7, "y": -8, "z": -6, "c": "#c6beb1"}, {"id": 765, "x": -7, "y": -8, "z": 6, "c": "#c6beb1"}, {"id": 766, "x": -6, "y": -8, "z": -6, "c": "#c6beb1"}, {"id": 767, "x": -6, "y": -8, "z": 6, "c": "#c6beb1"}, {"id": 768, "x": -5, "y": -8, "z": -6, "c": "#c6beb1"}, {"id": 769, "x": -5, "y": -8, "z": 6, "c": "#c6beb1"}, {"id": 770, "x": -4, "y": -8, "z": -6, "c": "#c6beb1"}, {"id": 771, "x": -4, "y": -8, "z": 6, "c": "#c6beb1"}, {"id": 772, "x": -3, "y": -8, "z": -6, "c": "#c6beb1"}, {"id": 773, "x": -3, "y": -8, "z": 6, "c": "#c6beb1"}, {"id": 774, "x": -2, "y": -8, "z": -6, "c": "#c6beb1"}, {"id": 775, "x": -2, "y": -8, "z": 6, "c": "#674f3c"}, {"id": 776, "x": -1, "y": -8, "z": -6, "c": "#c6beb1"}, {"id": 777, "x": -1, "y": -8, "z": 6, "c": "#674f3c"}, {"id": 778, "x": 0, "y": -8, "z": -6, "c": "#c6beb1"}, {"id": 779, "x": 0, "y": -8, "z": 6, "c": "#674f3c"}, {"id": 780, "x": 1, "y": -8, "z": -6, "c": "#c6beb1"}, {"id": 781, "x": 1, "y": -8, "z": 6, "c": "#674f3c"}, {"id": 782, "x": 2, "y": -8, "z": -6, "c": "#c6beb1"}, {"id": 783, "x": 2, "y": -8, "z": 6, "c": "#674f3c"}, {"id": 784, "x": 3, "y": -8, "z": -6, "c": "#c6beb1"}, {"id": 785, "x": 3, "y": -8, "z": 6, "c": "#c6beb1"}, {"id": 786, "x": 4, "y": -8, "z": -6, "c": "#c6beb1"}, {"id": 787, "x": 4, "y": -8, "z": 6, "c": "#c6beb1"}, {"id": 788, "x": 5, "y": -8, "z": -6, "c": "#c6beb1"}, {"id": 789, "x": 5, "y": -8, "z": 6, "c": "#c6beb1"}, {"id": 790, "x": 6, "y": -8, "z": -6, "c": "#c6beb1"}, {"id": 791, "x": 6, "y": -8, "z": 6, "c": "#c6beb1"}, {"id": 792, "x": 7, "y": -8, "z": -6, "c": "#c6beb1"}, {"id": 793, "x": 7, "y": -8, "z": 6, "c": "#c6beb1"}, {"id": 794, "x": 8, "y": -8, "z": -6, "c": "#c6beb1"}, {"id": 795, "x": 8, "y": -8, "z": 6, "c": "#c6beb1"}, {"id": 796, "x": 9, "y": -8, "z": -6, "c": "#c6beb1"}, {"id": 797, "x": 9, "y": -8, "z": 6, "c": "#c6beb1"}, {"id": 798, "x": 10, "y": -8, "z": -6, "c": "#c6beb1"}, {"id": 799, "x": 10, "y": -8, "z": -5, "c": "#c6beb1"}, {"id": 800, "x": 10, "y": -8, "z": -4, "c": "#c6beb1"}, {"id": 801, "x": 10, "y": -8, "z": -3, "c": "#c6beb1"}, {"id": 802, "x": 10, "y": -8, "z": -2, "c": "#c6beb1"}, {"id": 803, "x": 10, "y": -8, "z": -1, "c": "#c6beb1"}, {"id": 804, "x": 10, "y": -8, "z": 0, "c": "#c6beb1"}, {"id": 805, "x": 10, "y": -8, "z": 1, "c": "#c6beb1"}, {"id": 806, "x": 10, "y": -8, "z": 2, "c": "#c6beb1"}, {"id": 807, "x": 10, "y": -8, "z": 3, "c": "#c6beb1"}, {"id": 808, "x": 10, "y": -8, "z": 4, "c": "#c6beb1"}, {"id": 809, "x": 10, "y": -8, "z": 5, "c": "#c6beb1"}, {"id": 810, "x": 10, "y": -8, "z": 6, "c": "#c6beb1"}, {"id": 811, "x": -10, "y": -7, "z": -6, "c": "#c6beb1"}, {"id": 812, "x": -10, "y": -7, "z": -5, "c": "#c6beb1"}, {"id": 813, "x": -10, "y": -7, "z": -4, "c": "#c6beb1"}, {"id": 814, "x": -10, "y": -7, "z": -3, "c": "#c6beb1"}, {"id": 815, "x": -10, "y": -7, "z": -2, "c": "#c6beb1"}, {"id": 816, "x": -10, "y": -7, "z": -1, "c": "#c6beb1"}, {"id": 817, "x": -10, "y": -7, "z": 0, "c": "#c6beb1"}, {"id": 818, "x": -10, "y": -7, "z": 1, "c": "#c6beb1"}, {"id": 819, "x": -10, "y": -7, "z": 2, "c": "#c6beb1"}, {"id": 820, "x": -10, "y": -7, "z": 3, "c": "#c6beb1"}, {"id": 821, "x": -10, "y": -7, "z": 4, "c": "#c6beb1"}, {"id": 822, "x": -10, "y": -7, "z": 5, "c": "#c6beb1"}, {"id": 823, "x": -10, "y": -7, "z": 6, "c": "#c6beb1"}, {"id": 824, "x": -9, "y": -7, "z": -6, "c": "#c6beb1"}, {"id": 825, "x": -9, "y": -7, "z": 6, "c": "#c6beb1"}, {"id": 826, "x": -8, "y": -7, "z": -6, "c": "#c6beb1"}, {"id": 827, "x": -8, "y": -7, "z": 6, "c": "#c6beb1"}, {"id": 828, "x": -7, "y": -7, "z": -6, "c": "#c6beb1"}, {"id": 829, "x": -7, "y": -7, "z": 6, "c": "#c6beb1"}, {"id": 830, "x": -6, "y": -7, "z": -6, "c": "#c6beb1"}, {"id": 831, "x": -6, "y": -7, "z": 6, "c": "#c6beb1"}, {"id": 832, "x": -5, "y": -7, "z": -6, "c": "#c6beb1"}, {"id": 833, "x": -5, "y": -7, "z": 6, "c": "#c6beb1"}, {"id": 834, "x": -4, "y": -7, "z": -6, "c": "#c6beb1"}, {"id": 835, "x": -4, "y": -7, "z": 6, "c": "#c6beb1"}, {"id": 836, "x": -3, "y": -7, "z": -6, "c": "#c6beb1"}, {"id": 837, "x": -3, "y": -7, "z": 6, "c": "#c6beb1"}, {"id": 838, "x": -2, "y": -7, "z": -6, "c": "#c6beb1"}, {"id": 839, "x": -2, "y": -7, "z": 6, "c": "#c6beb1"}, {"id": 840, "x": -1, "y": -7, "z": -6, "c": "#c6beb1"}, {"id": 841, "x": -1, "y": -7, "z": 6, "c": "#c6beb1"}, {"id": 842, "x": 0, "y": -7, "z": -6, "c": "#c6beb1"}, {"id": 843, "x": 0, "y": -7, "z": 6, "c": "#c6beb1"}, {"id": 844, "x": 1, "y": -7, "z": -6, "c": "#c6beb1"}, {"id": 845, "x": 1, "y": -7, "z": 6, "c": "#c6beb1"}, {"id": 846, "x": 2, "y": -7, "z": -6, "c": "#c6beb1"}, {"id": 847, "x": 2, "y": -7, "z": 6, "c": "#c6beb1"}, {"id": 848, "x": 3, "y": -7, "z": -6, "c": "#c6beb1"}, {"id": 849, "x": 3, "y": -7, "z": 6, "c": "#c6beb1"}, {"id": 850, "x": 4, "y": -7, "z": -6, "c": "#c6beb1"}, {"id": 851, "x": 4, "y": -7, "z": 6, "c": "#c6beb1"}, {"id": 852, "x": 5, "y": -7, "z": -6, "c": "#c6beb1"}, {"id": 853, "x": 5, "y": -7, "z": 6, "c": "#c6beb1"}, {"id": 854, "x": 6, "y": -7, "z": -6, "c": "#c6beb1"}, {"id": 855, "x": 6, "y": -7, "z": 6, "c": "#c6beb1"}, {"id": 856, "x": 7, "y": -7, "z": -6, "c": "#c6beb1"}, {"id": 857, "x": 7, "y": -7, "z": 6, "c": "#c6beb1"}, {"id": 858, "x": 8, "y": -7, "z": -6, "c": "#c6beb1"}, {"id": 859, "x": 8, "y": -7, "z": 6, "c": "#c6beb1"}, {"id": 860, "x": 9, "y": -7, "z": -6, "c": "#c6beb1"}, {"id": 861, "x": 9, "y": -7, "z": 6, "c": "#c6beb1"}, {"id": 862, "x": 10, "y": -7, "z": -6, "c": "#c6beb1"}, {"id": 863, "x": 10, "y": -7, "z": -5, "c": "#c6beb1"}, {"id": 864, "x": 10, "y": -7, "z": -4, "c": "#c6beb1"}, {"id": 865, "x": 10, "y": -7, "z": -3, "c": "#c6beb1"}, {"id": 866, "x": 10, "y": -7, "z": -2, "c": "#c6beb1"}, {"id": 867, "x": 10, "y": -7, "z": -1, "c": "#c6beb1"}, {"id": 868, "x": 10, "y": -7, "z": 0, "c": "#c6beb1"}, {"id": 869, "x": 10, "y": -7, "z": 1, "c": "#c6beb1"}, {"id": 870, "x": 10, "y": -7, "z": 2, "c": "#c6beb1"}, {"id": 871, "x": 10, "y": -7, "z": 3, "c": "#c6beb1"}, {"id": 872, "x": 10, "y": -7, "z": 4, "c": "#c6beb1"}, {"id": 873, "x": 10, "y": -7, "z": 5, "c": "#c6beb1"}, {"id": 874, "x": 10, "y": -7, "z": 6, "c": "#c6beb1"}, {"id": 875, "x": -10, "y": -6, "z": -6, "c": "#c6beb1"}, {"id": 876, "x": -10, "y": -6, "z": -5, "c": "#60737e"}, {"id": 877, "x": -10, "y": -6, "z": -4, "c": "#c6beb1"}, {"id": 878, "x": -10, "y": -6, "z": -3, "c": "#c6beb1"}, {"id": 879, "x": -10, "y": -6, "z": -2, "c": "#60737e"}, {"id": 880, "x": -10, "y": -6, "z": -1, "c": "#c6beb1"}, {"id": 881, "x": -10, "y": -6, "z": 0, "c": "#c6beb1"}, {"id": 882, "x": -10, "y": -6, "z": 1, "c": "#60737e"}, {"id": 883, "x": -10, "y": -6, "z": 2, "c": "#c6beb1"}, {"id": 884, "x": -10, "y": -6, "z": 3, "c": "#c6beb1"}, {"id": 885, "x": -10, "y": -6, "z": 4, "c": "#60737e"}, {"id": 886, "x": -10, "y": -6, "z": 5, "c": "#c6beb1"}, {"id": 887, "x": -10, "y": -6, "z": 6, "c": "#c6beb1"}, {"id": 888, "x": -9, "y": -6, "z": -6, "c": "#60737e"}, {"id": 889, "x": -9, "y": -6, "z": 6, "c": "#60737e"}, {"id": 890, "x": -8, "y": -6, "z": -6, "c": "#c6beb1"}, {"id": 891, "x": -8, "y": -6, "z": 6, "c": "#c6beb1"}, {"id": 892, "x": -7, "y": -6, "z": -6, "c": "#60737e"}, {"id": 893, "x": -7, "y": -6, "z": 6, "c": "#60737e"}, {"id": 894, "x": -6, "y": -6, "z": -6, "c": "#60737e"}, {"id": 895, "x": -6, "y": -6, "z": 6, "c": "#60737e"}, {"id": 896, "x": -5, "y": -6, "z": -6, "c": "#60737e"}, {"id": 897, "x": -5, "y": -6, "z": 6, "c": "#60737e"}, {"id": 898, "x": -4, "y": -6, "z": -6, "c": "#c6beb1"}, {"id": 899, "x": -4, "y": -6, "z": 6, "c": "#c6beb1"}, {"id": 900, "x": -3, "y": -6, "z": -6, "c": "#60737e"}, {"id": 901, "x": -3, "y": -6, "z": 6, "c": "#60737e"}, {"id": 902, "x": -2, "y": -6, "z": -6, "c": "#c6beb1"}, {"id": 903, "x": -2, "y": -6, "z": 6, "c": "#c6beb1"}, {"id": 904, "x": -1, "y": -6, "z": -6, "c": "#60737e"}, {"id": 905, "x": -1, "y": -6, "z": 6, "c": "#60737e"}, {"id": 906, "x": 0, "y": -6, "z": -6, "c": "#60737e"}, {"id": 907, "x": 0, "y": -6, "z": 6, "c": "#60737e"}, {"id": 908, "x": 1, "y": -6, "z": -6, "c": "#60737e"}, {"id": 909, "x": 1, "y": -6, "z": 6, "c": "#60737e"}, {"id": 910, "x": 2, "y": -6, "z": -6, "c": "#c6beb1"}, {"id": 911, "x": 2, "y": -6, "z": 6, "c": "#c6beb1"}, {"id": 912, "x": 3, "y": -6, "z": -6, "c": "#60737e"}, {"id": 913, "x": 3, "y": -6, "z": 6, "c": "#60737e"}, {"id": 914, "x": 4, "y": -6, "z": -6, "c": "#c6beb1"}, {"id": 915, "x": 4, "y": -6, "z": 6, "c": "#c6beb1"}, {"id": 916, "x": 5, "y": -6, "z": -6, "c": "#60737e"}, {"id": 917, "x": 5, "y": -6, "z": 6, "c": "#60737e"}, {"id": 918, "x": 6, "y": -6, "z": -6, "c": "#60737e"}, {"id": 919, "x": 6, "y": -6, "z": 6, "c": "#60737e"}, {"id": 920, "x": 7, "y": -6, "z": -6, "c": "#60737e"}, {"id": 921, "x": 7, "y": -6, "z": 6, "c": "#60737e"}, {"id": 922, "x": 8, "y": -6, "z": -6, "c": "#c6beb1"}, {"id": 923, "x": 8, "y": -6, "z": 6, "c": "#c6beb1"}, {"id": 924, "x": 9, "y": -6, "z": -6, "c": "#60737e"}, {"id": 925, "x": 9, "y": -6, "z": 6, "c": "#60737e"}, {"id": 926, "x": 10, "y": -6, "z": -6, "c": "#c6beb1"}, {"id": 927, "x": 10, "y": -6, "z": -5, "c": "#c6beb1"}, {"id": 928, "x": 10, "y": -6, "z": -4, "c": "#60737e"}, {"id": 929, "x": 10, "y": -6, "z": -3, "c": "#c6beb1"}, {"id": 930, "x": 10, "y": -6, "z": -2, "c": "#c6beb1"}, {"id": 931, "x": 10, "y": -6, "z": -1, "c": "#60737e"}, {"id": 932, "x": 10, "y": -6, "z": 0, "c": "#c6beb1"}, {"id": 933, "x": 10, "y": -6, "z": 1, "c": "#c6beb1"}, {"id": 934, "x": 10, "y": -6, "z": 2, "c": "#60737e"}, {"id": 935, "x": 10, "y": -6, "z": 3, "c": "#c6beb1"}, {"id": 936, "x": 10, "y": -6, "z": 4, "c": "#c6beb1"}, {"id": 937, "x": 10, "y": -6, "z": 5, "c": "#60737e"}, {"id": 938, "x": 10, "y": -6, "z": 6, "c": "#c6beb1"}, {"id": 939, "x": -10, "y": -5, "z": -6, "c": "#c6beb1"}, {"id": 940, "x": -10, "y": -5, "z": -5, "c": "#60737e"}, {"id": 941, "x": -10, "y": -5, "z": -4, "c": "#c6beb1"}, {"id": 942, "x": -10, "y": -5, "z": -3, "c": "#c6beb1"}, {"id": 943, "x": -10, "y": -5, "z": -2, "c": "#60737e"}, {"id": 944, "x": -10, "y": -5, "z": -1, "c": "#c6beb1"}, {"id": 945, "x": -10, "y": -5, "z": 0, "c": "#c6beb1"}, {"id": 946, "x": -10, "y": -5, "z": 1, "c": "#60737e"}, {"id": 947, "x": -10, "y": -5, "z": 2, "c": "#c6beb1"}, {"id": 948, "x": -10, "y": -5, "z": 3, "c": "#c6beb1"}, {"id": 949, "x": -10, "y": -5, "z": 4, "c": "#60737e"}, {"id": 950, "x": -10, "y": -5, "z": 5, "c": "#c6beb1"}, {"id": 951, "x": -10, "y": -5, "z": 6, "c": "#c6beb1"}, {"id": 952, "x": -9, "y": -5, "z": -6, "c": "#60737e"}, {"id": 953, "x": -9, "y": -5, "z": 6, "c": "#60737e"}, {"id": 954, "x": -8, "y": -5, "z": -6, "c": "#c6beb1"}, {"id": 955, "x": -8, "y": -5, "z": 6, "c": "#c6beb1"}, {"id": 956, "x": -7, "y": -5, "z": -6, "c": "#c6beb1"}, {"id": 957, "x": -7, "y": -5, "z": 6, "c": "#c6beb1"}, {"id": 958, "x": -6, "y": -5, "z": -6, "c": "#60737e"}, {"id": 959, "x": -6, "y": -5, "z": 6, "c": "#60737e"}, {"id": 960, "x": -5, "y": -5, "z": -6, "c": "#c6beb1"}, {"id": 961, "x": -5, "y": -5, "z": 6, "c": "#c6beb1"}, {"id": 962, "x": -4, "y": -5, "z": -6, "c": "#c6beb1"}, {"id": 963, "x": -4, "y": -5, "z": 6, "c": "#c6beb1"}, {"id": 964, "x": -3, "y": -5, "z": -6, "c": "#60737e"}, {"id": 965, "x": -3, "y": -5, "z": 6, "c": "#60737e"}, {"id": 966, "x": -2, "y": -5, "z": -6, "c": "#c6beb1"}, {"id": 967, "x": -2, "y": -5, "z": 6, "c": "#c6beb1"}, {"id": 968, "x": -1, "y": -5, "z": -6, "c": "#c6beb1"}, {"id": 969, "x": -1, "y": -5, "z": 6, "c": "#c6beb1"}, {"id": 970, "x": 0, "y": -5, "z": -6, "c": "#60737e"}, {"id": 971, "x": 0, "y": -5, "z": 6, "c": "#60737e"}, {"id": 972, "x": 1, "y": -5, "z": -6, "c": "#c6beb1"}, {"id": 973, "x": 1, "y": -5, "z": 6, "c": "#c6beb1"}, {"id": 974, "x": 2, "y": -5, "z": -6, "c": "#c6beb1"}, {"id": 975, "x": 2, "y": -5, "z": 6, "c": "#c6beb1"}, {"id": 976, "x": 3, "y": -5, "z": -6, "c": "#60737e"}, {"id": 977, "x": 3, "y": -5, "z": 6, "c": "#60737e"}, {"id": 978, "x": 4, "y": -5, "z": -6, "c": "#c6beb1"}, {"id": 979, "x": 4, "y": -5, "z": 6, "c": "#c6beb1"}, {"id": 980, "x": 5, "y": -5, "z": -6, "c": "#c6beb1"}, {"id": 981, "x": 5, "y": -5, "z": 6, "c": "#c6beb1"}, {"id": 982, "x": 6, "y": -5, "z": -6, "c": "#60737e"}, {"id": 983, "x": 6, "y": -5, "z": 6, "c": "#60737e"}, {"id": 984, "x": 7, "y": -5, "z": -6, "c": "#c6beb1"}, {"id": 985, "x": 7, "y": -5, "z": 6, "c": "#c6beb1"}, {"id": 986, "x": 8, "y": -5, "z": -6, "c": "#c6beb1"}, {"id": 987, "x": 8, "y": -5, "z": 6, "c": "#c6beb1"}, {"id": 988, "x": 9, "y": -5, "z": -6, "c": "#60737e"}, {"id": 989, "x": 9, "y": -5, "z": 6, "c": "#60737e"}, {"id": 990, "x": 10, "y": -5, "z": -6, "c": "#c6beb1"}, {"id": 991, "x": 10, "y": -5, "z": -5, "c": "#c6beb1"}, {"id": 992, "x": 10, "y": -5, "z": -4, "c": "#60737e"}, {"id": 993, "x": 10, "y": -5, "z": -3, "c": "#c6beb1"}, {"id": 994, "x": 10, "y": -5, "z": -2, "c": "#c6beb1"}, {"id": 995, "x": 10, "y": -5, "z": -1, "c": "#60737e"}, {"id": 996, "x": 10, "y": -5, "z": 0, "c": "#c6beb1"}, {"id": 997, "x": 10, "y": -5, "z": 1, "c": "#c6beb1"}, {"id": 998, "x": 10, "y": -5, "z": 2, "c": "#60737e"}, {"id": 999, "x": 10, "y": -5, "z": 3, "c": "#c6beb1"}, {"id": 1000, "x": 10, "y": -5, "z": 4, "c": "#c6beb1"}, {"id": 1001, "x": 10, "y": -5, "z": 5, "c": "#60737e"}, {"id": 1002, "x": 10, "y": -5, "z": 6, "c": "#c6beb1"}, {"id": 1003, "x": -10, "y": -4, "z": -6, "c": "#b18b57"}, {"id": 1004, "x": -10, "y": -4, "z": -5, "c": "#b18b57"}, {"id": 1005, "x": -10, "y": -4, "z": -4, "c": "#b18b57"}, {"id": 1006, "x": -10, "y": -4, "z": -3, "c": "#b18b57"}, {"id": 1007, "x": -10, "y": -4, "z": -2, "c": "#b18b57"}, {"id": 1008, "x": -10, "y": -4, "z": -1, "c": "#b18b57"}, {"id": 1009, "x": -10, "y": -4, "z": 0, "c": "#b18b57"}, {"id": 1010, "x": -10, "y": -4, "z": 1, "c": "#b18b57"}, {"id": 1011, "x": -10, "y": -4, "z": 2, "c": "#b18b57"}, {"id": 1012, "x": -10, "y": -4, "z": 3, "c": "#b18b57"}, {"id": 1013, "x": -10, "y": -4, "z": 4, "c": "#b18b57"}, {"id": 1014, "x": -10, "y": -4, "z": 5, "c": "#b18b57"}, {"id": 1015, "x": -10, "y": -4, "z": 6, "c": "#b18b57"}, {"id": 1016, "x": -9, "y": -4, "z": -6, "c": "#b18b57"}, {"id": 1017, "x": -9, "y": -4, "z": 6, "c": "#b18b57"}, {"id": 1018, "x": -8, "y": -4, "z": -6, "c": "#b18b57"}, {"id": 1019, "x": -8, "y": -4, "z": 6, "c": "#b18b57"}, {"id": 1020, "x": -7, "y": -4, "z": -6, "c": "#b18b57"}, {"id": 1021, "x": -7, "y": -4, "z": 6, "c": "#b18b57"}, {"id": 1022, "x": -6, "y": -4, "z": -6, "c": "#b18b57"}, {"id": 1023, "x": -6, "y": -4, "z": 6, "c": "#b18b57"}, {"id": 1024, "x": -5, "y": -4, "z": -6, "c": "#b18b57"}, {"id": 1025, "x": -5, "y": -4, "z": 6, "c": "#b18b57"}, {"id": 1026, "x": -4, "y": -4, "z": -6, "c": "#b18b57"}, {"id": 1027, "x": -4, "y": -4, "z": 6, "c": "#b18b57"}, {"id": 1028, "x": -3, "y": -4, "z": -6, "c": "#b18b57"}, {"id": 1029, "x": -3, "y": -4, "z": 6, "c": "#b18b57"}, {"id": 1030, "x": -2, "y": -4, "z": -6, "c": "#b18b57"}, {"id": 1031, "x": -2, "y": -4, "z": 6, "c": "#b18b57"}, {"id": 1032, "x": -1, "y": -4, "z": -6, "c": "#b18b57"}, {"id": 1033, "x": -1, "y": -4, "z": 6, "c": "#b18b57"}, {"id": 1034, "x": 0, "y": -4, "z": -6, "c": "#b18b57"}, {"id": 1035, "x": 0, "y": -4, "z": 6, "c": "#b18b57"}, {"id": 1036, "x": 1, "y": -4, "z": -6, "c": "#b18b57"}, {"id": 1037, "x": 1, "y": -4, "z": 6, "c": "#b18b57"}, {"id": 1038, "x": 2, "y": -4, "z": -6, "c": "#b18b57"}, {"id": 1039, "x": 2, "y": -4, "z": 6, "c": "#b18b57"}, {"id": 1040, "x": 3, "y": -4, "z": -6, "c": "#b18b57"}, {"id": 1041, "x": 3, "y": -4, "z": 6, "c": "#b18b57"}, {"id": 1042, "x": 4, "y": -4, "z": -6, "c": "#b18b57"}, {"id": 1043, "x": 4, "y": -4, "z": 6, "c": "#b18b57"}, {"id": 1044, "x": 5, "y": -4, "z": -6, "c": "#b18b57"}, {"id": 1045, "x": 5, "y": -4, "z": 6, "c": "#b18b57"}, {"id": 1046, "x": 6, "y": -4, "z": -6, "c": "#b18b57"}, {"id": 1047, "x": 6, "y": -4, "z": 6, "c": "#b18b57"}, {"id": 1048, "x": 7, "y": -4, "z": -6, "c": "#b18b57"}, {"id": 1049, "x": 7, "y": -4, "z": 6, "c": "#b18b57"}, {"id": 1050, "x": 8, "y": -4, "z": -6, "c": "#b18b57"}, {"id": 1051, "x": 8, "y": -4, "z": 6, "c": "#b18b57"}, {"id": 1052, "x": 9, "y": -4, "z": -6, "c": "#b18b57"}, {"id": 1053, "x": 9, "y": -4, "z": 6, "c": "#b18b57"}, {"id": 1054, "x": 10, "y": -4, "z": -6, "c": "#b18b57"}, {"id": 1055, "x": 10, "y": -4, "z": -5, "c": "#b18b57"}, {"id": 1056, "x": 10, "y": -4, "z": -4, "c": "#b18b57"}, {"id": 1057, "x": 10, "y": -4, "z": -3, "c": "#b18b57"}, {"id": 1058, "x": 10, "y": -4, "z": -2, "c": "#b18b57"}, {"id": 1059, "x": 10, "y": -4, "z": -1, "c": "#b18b57"}, {"id": 1060, "x": 10, "y": -4, "z": 0, "c": "#b18b57"}, {"id": 1061, "x": 10, "y": -4, "z": 1, "c": "#b18b57"}, {"id": 1062, "x": 10, "y": -4, "z": 2, "c": "#b18b57"}, {"id": 1063, "x": 10, "y": -4, "z": 3, "c": "#b18b57"}, {"id": 1064, "x": 10, "y": -4, "z": 4, "c": "#b18b57"}, {"id": 1065, "x": 10, "y": -4, "z": 5, "c": "#b18b57"}, {"id": 1066, "x": 10, "y": -4, "z": 6, "c": "#b18b57"}, {"id": 1067, "x": -4, "y": -8, "z": 7, "c": "#c6beb1"}, {"id": 1068, "x": -4, "y": -7, "z": 7, "c": "#c6beb1"}, {"id": 1069, "x": -4, "y": -6, "z": 7, "c": "#60737e"}, {"id": 1070, "x": -4, "y": -5, "z": 7, "c": "#60737e"}, {"id": 1071, "x": -4, "y": -4, "z": 7, "c": "#b18b57"}, {"id": 1072, "x": -2, "y": -8, "z": 7, "c": "#c6beb1"}, {"id": 1073, "x": -2, "y": -7, "z": 7, "c": "#c6beb1"}, {"id": 1074, "x": -2, "y": -6, "z": 7, "c": "#c6beb1"}, {"id": 1075, "x": -2, "y": -5, "z": 7, "c": "#c6beb1"}, {"id": 1076, "x": -2, "y": -4, "z": 7, "c": "#b18b57"}, {"id": 1077, "x": 0, "y": -8, "z": 7, "c": "#c6beb1"}, {"id": 1078, "x": 0, "y": -7, "z": 7, "c": "#c6beb1"}, {"id": 1079, "x": 0, "y": -6, "z": 7, "c": "#c6beb1"}, {"id": 1080, "x": 0, "y": -5, "z": 7, "c": "#c6beb1"}, {"id": 1081, "x": 0, "y": -4, "z": 7, "c": "#b18b57"}, {"id": 1082, "x": 2, "y": -8, "z": 7, "c": "#c6beb1"}, {"id": 1083, "x": 2, "y": -7, "z": 7, "c": "#c6beb1"}, {"id": 1084, "x": 2, "y": -6, "z": 7, "c": "#60737e"}, {"id": 1085, "x": 2, "y": -5, "z": 7, "c": "#60737e"}, {"id": 1086, "x": 2, "y": -4, "z": 7, "c": "#b18b57"}, {"id": 1087, "x": 4, "y": -8, "z": 7, "c": "#c6beb1"}, {"id": 1088, "x": 4, "y": -7, "z": 7, "c": "#c6beb1"}, {"id": 1089, "x": 4, "y": -6, "z": 7, "c": "#c6beb1"}, {"id": 1090, "x": 4, "y": -5, "z": 7, "c": "#c6beb1"}, {"id": 1091, "x": 4, "y": -4, "z": 7, "c": "#b18b57"}, {"id": 1092, "x": -5, "y": -3, "z": 6, "c": "#30363d"}, {"id": 1093, "x": -5, "y": -3, "z": 7, "c": "#30363d"}, {"id": 1094, "x": -5, "y": -3, "z": 8, "c": "#c6beb1"}, {"id": 1095, "x": -4, "y": -3, "z": 6, "c": "#30363d"}, {"id": 1096, "x": -4, "y": -3, "z": 7, "c": "#30363d"}, {"id": 1097, "x": -4, "y": -3, "z": 8, "c": "#c6beb1"}, {"id": 1098, "x": -3, "y": -3, "z": 6, "c": "#30363d"}, {"id": 1099, "x": -3, "y": -3, "z": 7, "c": "#30363d"}, {"id": 1100, "x": -3, "y": -3, "z": 8, "c": "#c6beb1"}, {"id": 1101, "x": -2, "y": -3, "z": 6, "c": "#30363d"}, {"id": 1102, "x": -2, "y": -3, "z": 7, "c": "#30363d"}, {"id": 1103, "x": -2, "y": -3, "z": 8, "c": "#c6beb1"}, {"id": 1104, "x": -1, "y": -3, "z": 6, "c": "#30363d"}, {"id": 1105, "x": -1, "y": -3, "z": 7, "c": "#30363d"}, {"id": 1106, "x": -1, "y": -3, "z": 8, "c": "#c6beb1"}, {"id": 1107, "x": 0, "y": -3, "z": 6, "c": "#30363d"}, {"id": 1108, "x": 0, "y": -3, "z": 7, "c": "#30363d"}, {"id": 1109, "x": 0, "y": -3, "z": 8, "c": "#c6beb1"}, {"id": 1110, "x": 1, "y": -3, "z": 6, "c": "#30363d"}, {"id": 1111, "x": 1, "y": -3, "z": 7, "c": "#30363d"}, {"id": 1112, "x": 1, "y": -3, "z": 8, "c": "#c6beb1"}, {"id": 1113, "x": 2, "y": -3, "z": 6, "c": "#30363d"}, {"id": 1114, "x": 2, "y": -3, "z": 7, "c": "#30363d"}, {"id": 1115, "x": 2, "y": -3, "z": 8, "c": "#c6beb1"}, {"id": 1116, "x": 3, "y": -3, "z": 6, "c": "#30363d"}, {"id": 1117, "x": 3, "y": -3, "z": 7, "c": "#30363d"}, {"id": 1118, "x": 3, "y": -3, "z": 8, "c": "#c6beb1"}, {"id": 1119, "x": 4, "y": -3, "z": 6, "c": "#30363d"}, {"id": 1120, "x": 4, "y": -3, "z": 7, "c": "#30363d"}, {"id": 1121, "x": 4, "y": -3, "z": 8, "c": "#c6beb1"}, {"id": 1122, "x": 5, "y": -3, "z": 6, "c": "#30363d"}, {"id": 1123, "x": 5, "y": -3, "z": 7, "c": "#30363d"}, {"id": 1124, "x": 5, "y": -3, "z": 8, "c": "#c6beb1"}, {"id": 1125, "x": -4, "y": -2, "z": 6, "c": "#c6beb1"}, {"id": 1126, "x": -4, "y": -2, "z": 7, "c": "#60737e"}, {"id": 1127, "x": -4, "y": -2, "z": 8, "c": "#c6beb1"}, {"id": 1128, "x": -3, "y": -2, "z": 6, "c": "#c6beb1"}, {"id": 1129, "x": -3, "y": -2, "z": 7, "c": "#c6beb1"}, {"id": 1130, "x": -3, "y": -2, "z": 8, "c": "#c6beb1"}, {"id": 1131, "x": -2, "y": -2, "z": 6, "c": "#c6beb1"}, {"id": 1132, "x": -2, "y": -2, "z": 7, "c": "#c6beb1"}, {"id": 1133, "x": -2, "y": -2, "z": 8, "c": "#60737e"}, {"id": 1134, "x": -1, "y": -2, "z": 6, "c": "#c6beb1"}, {"id": 1135, "x": -1, "y": -2, "z": 7, "c": "#c6beb1"}, {"id": 1136, "x": -1, "y": -2, "z": 8, "c": "#c6beb1"}, {"id": 1137, "x": 0, "y": -2, "z": 6, "c": "#c6beb1"}, {"id": 1138, "x": 0, "y": -2, "z": 7, "c": "#c6beb1"}, {"id": 1139, "x": 0, "y": -2, "z": 8, "c": "#23272c"}, {"id": 1140, "x": 1, "y": -2, "z": 6, "c": "#c6beb1"}, {"id": 1141, "x": 1, "y": -2, "z": 7, "c": "#c6beb1"}, {"id": 1142, "x": 1, "y": -2, "z": 8, "c": "#60737e"}, {"id": 1143, "x": 2, "y": -2, "z": 6, "c": "#c6beb1"}, {"id": 1144, "x": 2, "y": -2, "z": 7, "c": "#c6beb1"}, {"id": 1145, "x": 2, "y": -2, "z": 8, "c": "#c6beb1"}, {"id": 1146, "x": 3, "y": -2, "z": 6, "c": "#c6beb1"}, {"id": 1147, "x": 3, "y": -2, "z": 7, "c": "#c6beb1"}, {"id": 1148, "x": 3, "y": -2, "z": 8, "c": "#c6beb1"}, {"id": 1149, "x": 4, "y": -2, "z": 6, "c": "#c6beb1"}, {"id": 1150, "x": 4, "y": -2, "z": 7, "c": "#c6beb1"}, {"id": 1151, "x": 4, "y": -2, "z": 8, "c": "#60737e"}, {"id": 1152, "x": -3, "y": -1, "z": 6, "c": "#60737e"}, {"id": 1153, "x": -3, "y": -1, "z": 7, "c": "#c6beb1"}, {"id": 1154, "x": -3, "y": -1, "z": 8, "c": "#c6beb1"}, {"id": 1155, "x": -2, "y": -1, "z": 6, "c": "#c6beb1"}, {"id": 1156, "x": -2, "y": -1, "z": 7, "c": "#c6beb1"}, {"id": 1157, "x": -2, "y": -1, "z": 8, "c": "#60737e"}, {"id": 1158, "x": -1, "y": -1, "z": 6, "c": "#c6beb1"}, {"id": 1159, "x": -1, "y": -1, "z": 7, "c": "#c6beb1"}, {"id": 1160, "x": -1, "y": -1, "z": 8, "c": "#c6beb1"}, {"id": 1161, "x": 0, "y": -1, "z": 6, "c": "#60737e"}, {"id": 1162, "x": 0, "y": -1, "z": 7, "c": "#c6beb1"}, {"id": 1163, "x": 0, "y": -1, "z": 8, "c": "#c6beb1"}, {"id": 1164, "x": 1, "y": -1, "z": 6, "c": "#c6beb1"}, {"id": 1165, "x": 1, "y": -1, "z": 7, "c": "#c6beb1"}, {"id": 1166, "x": 1, "y": -1, "z": 8, "c": "#60737e"}, {"id": 1167, "x": 2, "y": -1, "z": 6, "c": "#c6beb1"}, {"id": 1168, "x": 2, "y": -1, "z": 7, "c": "#c6beb1"}, {"id": 1169, "x": 2, "y": -1, "z": 8, "c": "#c6beb1"}, {"id": 1170, "x": 3, "y": -1, "z": 6, "c": "#60737e"}, {"id": 1171, "x": 3, "y": -1, "z": 7, "c": "#c6beb1"}, {"id": 1172, "x": 3, "y": -1, "z": 8, "c": "#c6beb1"}, {"id": 1173, "x": -2, "y": 0, "z": 6, "c": "#c6beb1"}, {"id": 1174, "x": -2, "y": 0, "z": 7, "c": "#c6beb1"}, {"id": 1175, "x": -2, "y": 0, "z": 8, "c": "#c6beb1"}, {"id": 1176, "x": -1, "y": 0, "z": 6, "c": "#c6beb1"}, {"id": 1177, "x": -1, "y": 0, "z": 7, "c": "#c6beb1"}, {"id": 1178, "x": -1, "y": 0, "z": 8, "c": "#c6beb1"}, {"id": 1179, "x": 0, "y": 0, "z": 6, "c": "#c6beb1"}, {"id": 1180, "x": 0, "y": 0, "z": 7, "c": "#c6beb1"}, {"id": 1181, "x": 0, "y": 0, "z": 8, "c": "#c6beb1"}, {"id": 1182, "x": 1, "y": 0, "z": 6, "c": "#c6beb1"}, {"id": 1183, "x": 1, "y": 0, "z": 7, "c": "#c6beb1"}, {"id": 1184, "x": 1, "y": 0, "z": 8, "c": "#c6beb1"}, {"id": 1185, "x": 2, "y": 0, "z": 6, "c": "#c6beb1"}, {"id": 1186, "x": 2, "y": 0, "z": 7, "c": "#c6beb1"}, {"id": 1187, "x": 2, "y": 0, "z": 8, "c": "#c6beb1"}, {"id": 1188, "x": -1, "y": 1, "z": 6, "c": "#d4cec3"}, {"id": 1189, "x": -1, "y": 1, "z": 7, "c": "#d4cec3"}, {"id": 1190, "x": -1, "y": 1, "z": 8, "c": "#d4cec3"}, {"id": 1191, "x": 0, "y": 1, "z": 6, "c": "#b18b57"}, {"id": 1192, "x": 0, "y": 1, "z": 7, "c": "#d4cec3"}, {"id": 1193, "x": 0, "y": 1, "z": 8, "c": "#d4cec3"}, {"id": 1194, "x": 1, "y": 1, "z": 6, "c": "#d4cec3"}, {"id": 1195, "x": 1, "y": 1, "z": 7, "c": "#d4cec3"}, {"id": 1196, "x": 1, "y": 1, "z": 8, "c": "#d4cec3"}, {"id": 1197, "x": -11, "y": -3, "z": -7, "c": "#30363d"}, {"id": 1198, "x": -11, "y": -3, "z": -6, "c": "#30363d"}, {"id": 1199, "x": -11, "y": -3, "z": -5, "c": "#30363d"}, {"id": 1200, "x": -11, "y": -3, "z": -4, "c": "#30363d"}, {"id": 1201, "x": -11, "y": -3, "z": -3, "c": "#30363d"}, {"id": 1202, "x": -11, "y": -3, "z": -2, "c": "#30363d"}, {"id": 1203, "x": -11, "y": -3, "z": -1, "c": "#30363d"}, {"id": 1204, "x": -11, "y": -3, "z": 0, "c": "#30363d"}, {"id": 1205, "x": -11, "y": -3, "z": 1, "c": "#30363d"}, {"id": 1206, "x": -11, "y": -3, "z": 2, "c": "#30363d"}, {"id": 1207, "x": -11, "y": -3, "z": 3, "c": "#30363d"}, {"id": 1208, "x": -11, "y": -3, "z": 4, "c": "#30363d"}, {"id": 1209, "x": -11, "y": -3, "z": 5, "c": "#30363d"}, {"id": 1210, "x": -11, "y": -3, "z": 6, "c": "#30363d"}, {"id": 1211, "x": -11, "y": -3, "z": 7, "c": "#30363d"}, {"id": 1212, "x": -10, "y": -3, "z": -7, "c": "#30363d"}, {"id": 1213, "x": -10, "y": -3, "z": -6, "c": "#30363d"}, {"id": 1214, "x": -10, "y": -3, "z": -5, "c": "#30363d"}, {"id": 1215, "x": -10, "y": -3, "z": -4, "c": "#30363d"}, {"id": 1216, "x": -10, "y": -3, "z": -3, "c": "#30363d"}, {"id": 1217, "x": -10, "y": -3, "z": -2, "c": "#30363d"}, {"id": 1218, "x": -10, "y": -3, "z": -1, "c": "#30363d"}, {"id": 1219, "x": -10, "y": -3, "z": 0, "c": "#30363d"}, {"id": 1220, "x": -10, "y": -3, "z": 1, "c": "#30363d"}, {"id": 1221, "x": -10, "y": -3, "z": 2, "c": "#30363d"}, {"id": 1222, "x": -10, "y": -3, "z": 3, "c": "#30363d"}, {"id": 1223, "x": -10, "y": -3, "z": 4, "c": "#30363d"}, {"id": 1224, "x": -10, "y": -3, "z": 5, "c": "#30363d"}, {"id": 1225, "x": -10, "y": -3, "z": 6, "c": "#30363d"}, {"id": 1226, "x": -10, "y": -3, "z": 7, "c": "#30363d"}, {"id": 1227, "x": -9, "y": -3, "z": -7, "c": "#30363d"}, {"id": 1228, "x": -9, "y": -3, "z": -6, "c": "#30363d"}, {"id": 1229, "x": -9, "y": -3, "z": -5, "c": "#30363d"}, {"id": 1230, "x": -9, "y": -3, "z": -4, "c": "#30363d"}, {"id": 1231, "x": -9, "y": -3, "z": -3, "c": "#30363d"}, {"id": 1232, "x": -9, "y": -3, "z": -2, "c": "#30363d"}, {"id": 1233, "x": -9, "y": -3, "z": -1, "c": "#30363d"}, {"id": 1234, "x": -9, "y": -3, "z": 0, "c": "#30363d"}, {"id": 1235, "x": -9, "y": -3, "z": 1, "c": "#30363d"}, {"id": 1236, "x": -9, "y": -3, "z": 2, "c": "#30363d"}, {"id": 1237, "x": -9, "y": -3, "z": 3, "c": "#30363d"}, {"id": 1238, "x": -9, "y": -3, "z": 4, "c": "#30363d"}, {"id": 1239, "x": -9, "y": -3, "z": 5, "c": "#30363d"}, {"id": 1240, "x": -9, "y": -3, "z": 6, "c": "#30363d"}, {"id": 1241, "x": -9, "y": -3, "z": 7, "c": "#30363d"}, {"id": 1242, "x": -8, "y": -3, "z": -7, "c": "#30363d"}, {"id": 1243, "x": -8, "y": -3, "z": -6, "c": "#30363d"}, {"id": 1244, "x": -8, "y": -3, "z": -5, "c": "#30363d"}, {"id": 1245, "x": -8, "y": -3, "z": -4, "c": "#30363d"}, {"id": 1246, "x": -8, "y": -3, "z": -3, "c": "#30363d"}, {"id": 1247, "x": -8, "y": -3, "z": -2, "c": "#30363d"}, {"id": 1248, "x": -8, "y": -3, "z": -1, "c": "#30363d"}, {"id": 1249, "x": -8, "y": -3, "z": 0, "c": "#30363d"}, {"id": 1250, "x": -8, "y": -3, "z": 1, "c": "#30363d"}, {"id": 1251, "x": -8, "y": -3, "z": 2, "c": "#30363d"}, {"id": 1252, "x": -8, "y": -3, "z": 3, "c": "#30363d"}, {"id": 1253, "x": -8, "y": -3, "z": 4, "c": "#30363d"}, {"id": 1254, "x": -8, "y": -3, "z": 5, "c": "#30363d"}, {"id": 1255, "x": -8, "y": -3, "z": 6, "c": "#30363d"}, {"id": 1256, "x": -8, "y": -3, "z": 7, "c": "#30363d"}, {"id": 1257, "x": -7, "y": -3, "z": -7, "c": "#30363d"}, {"id": 1258, "x": -7, "y": -3, "z": -6, "c": "#30363d"}, {"id": 1259, "x": -7, "y": -3, "z": -5, "c": "#30363d"}, {"id": 1260, "x": -7, "y": -3, "z": -4, "c": "#30363d"}, {"id": 1261, "x": -7, "y": -3, "z": -3, "c": "#30363d"}, {"id": 1262, "x": -7, "y": -3, "z": -2, "c": "#30363d"}, {"id": 1263, "x": -7, "y": -3, "z": -1, "c": "#30363d"}, {"id": 1264, "x": -7, "y": -3, "z": 0, "c": "#30363d"}, {"id": 1265, "x": -7, "y": -3, "z": 1, "c": "#30363d"}, {"id": 1266, "x": -7, "y": -3, "z": 2, "c": "#30363d"}, {"id": 1267, "x": -7, "y": -3, "z": 3, "c": "#30363d"}, {"id": 1268, "x": -7, "y": -3, "z": 4, "c": "#30363d"}, {"id": 1269, "x": -7, "y": -3, "z": 5, "c": "#30363d"}, {"id": 1270, "x": -7, "y": -3, "z": 6, "c": "#30363d"}, {"id": 1271, "x": -7, "y": -3, "z": 7, "c": "#30363d"}, {"id": 1272, "x": -6, "y": -3, "z": -7, "c": "#30363d"}, {"id": 1273, "x": -6, "y": -3, "z": -6, "c": "#30363d"}, {"id": 1274, "x": -6, "y": -3, "z": -5, "c": "#30363d"}, {"id": 1275, "x": -6, "y": -3, "z": -4, "c": "#30363d"}, {"id": 1276, "x": -6, "y": -3, "z": -3, "c": "#30363d"}, {"id": 1277, "x": -6, "y": -3, "z": -2, "c": "#30363d"}, {"id": 1278, "x": -6, "y": -3, "z": -1, "c": "#30363d"}, {"id": 1279, "x": -6, "y": -3, "z": 0, "c": "#30363d"}, {"id": 1280, "x": -6, "y": -3, "z": 1, "c": "#30363d"}, {"id": 1281, "x": -6, "y": -3, "z": 2, "c": "#30363d"}, {"id": 1282, "x": -6, "y": -3, "z": 3, "c": "#30363d"}, {"id": 1283, "x": -6, "y": -3, "z": 4, "c": "#30363d"}, {"id": 1284, "x": -6, "y": -3, "z": 5, "c": "#30363d"}, {"id": 1285, "x": -6, "y": -3, "z": 6, "c": "#30363d"}, {"id": 1286, "x": -6, "y": -3, "z": 7, "c": "#30363d"}, {"id": 1287, "x": -5, "y": -3, "z": -7, "c": "#30363d"}, {"id": 1288, "x": -5, "y": -3, "z": -6, "c": "#30363d"}, {"id": 1289, "x": -5, "y": -3, "z": -5, "c": "#30363d"}, {"id": 1290, "x": -5, "y": -3, "z": -4, "c": "#30363d"}, {"id": 1291, "x": -5, "y": -3, "z": -3, "c": "#30363d"}, {"id": 1292, "x": -5, "y": -3, "z": -2, "c": "#30363d"}, {"id": 1293, "x": -5, "y": -3, "z": -1, "c": "#30363d"}, {"id": 1294, "x": -5, "y": -3, "z": 0, "c": "#30363d"}, {"id": 1295, "x": -5, "y": -3, "z": 1, "c": "#30363d"}, {"id": 1296, "x": -5, "y": -3, "z": 2, "c": "#30363d"}, {"id": 1297, "x": -5, "y": -3, "z": 3, "c": "#30363d"}, {"id": 1298, "x": -5, "y": -3, "z": 4, "c": "#30363d"}, {"id": 1299, "x": -5, "y": -3, "z": 5, "c": "#30363d"}, {"id": 1300, "x": -4, "y": -3, "z": -7, "c": "#30363d"}, {"id": 1301, "x": -4, "y": -3, "z": -6, "c": "#30363d"}, {"id": 1302, "x": -4, "y": -3, "z": -5, "c": "#30363d"}, {"id": 1303, "x": -4, "y": -3, "z": -4, "c": "#30363d"}, {"id": 1304, "x": -4, "y": -3, "z": -3, "c": "#30363d"}, {"id": 1305, "x": -4, "y": -3, "z": -2, "c": "#30363d"}, {"id": 1306, "x": -4, "y": -3, "z": -1, "c": "#30363d"}, {"id": 1307, "x": -4, "y": -3, "z": 0, "c": "#30363d"}, {"id": 1308, "x": -4, "y": -3, "z": 1, "c": "#30363d"}, {"id": 1309, "x": -4, "y": -3, "z": 2, "c": "#30363d"}, {"id": 1310, "x": -4, "y": -3, "z": 3, "c": "#30363d"}, {"id": 1311, "x": -4, "y": -3, "z": 4, "c": "#30363d"}, {"id": 1312, "x": -4, "y": -3, "z": 5, "c": "#30363d"}, {"id": 1313, "x": -3, "y": -3, "z": -7, "c": "#30363d"}, {"id": 1314, "x": -3, "y": -3, "z": -6, "c": "#30363d"}, {"id": 1315, "x": -3, "y": -3, "z": -5, "c": "#30363d"}, {"id": 1316, "x": -3, "y": -3, "z": -4, "c": "#30363d"}, {"id": 1317, "x": -3, "y": -3, "z": -3, "c": "#30363d"}, {"id": 1318, "x": -3, "y": -3, "z": -2, "c": "#30363d"}, {"id": 1319, "x": -3, "y": -3, "z": -1, "c": "#30363d"}, {"id": 1320, "x": -3, "y": -3, "z": 0, "c": "#30363d"}, {"id": 1321, "x": -3, "y": -3, "z": 1, "c": "#30363d"}, {"id": 1322, "x": -3, "y": -3, "z": 2, "c": "#30363d"}, {"id": 1323, "x": -3, "y": -3, "z": 3, "c": "#30363d"}, {"id": 1324, "x": -3, "y": -3, "z": 4, "c": "#30363d"}, {"id": 1325, "x": -3, "y": -3, "z": 5, "c": "#30363d"}, {"id": 1326, "x": -2, "y": -3, "z": -7, "c": "#30363d"}, {"id": 1327, "x": -2, "y": -3, "z": -6, "c": "#30363d"}, {"id": 1328, "x": -2, "y": -3, "z": -5, "c": "#30363d"}, {"id": 1329, "x": -2, "y": -3, "z": -4, "c": "#30363d"}, {"id": 1330, "x": -2, "y": -3, "z": -3, "c": "#30363d"}, {"id": 1331, "x": -2, "y": -3, "z": -2, "c": "#30363d"}, {"id": 1332, "x": -2, "y": -3, "z": -1, "c": "#30363d"}, {"id": 1333, "x": -2, "y": -3, "z": 0, "c": "#30363d"}, {"id": 1334, "x": -2, "y": -3, "z": 1, "c": "#30363d"}, {"id": 1335, "x": -2, "y": -3, "z": 2, "c": "#30363d"}, {"id": 1336, "x": -2, "y": -3, "z": 3, "c": "#30363d"}, {"id": 1337, "x": -2, "y": -3, "z": 4, "c": "#30363d"}, {"id": 1338, "x": -2, "y": -3, "z": 5, "c": "#30363d"}, {"id": 1339, "x": -1, "y": -3, "z": -7, "c": "#30363d"}, {"id": 1340, "x": -1, "y": -3, "z": -6, "c": "#30363d"}, {"id": 1341, "x": -1, "y": -3, "z": -5, "c": "#30363d"}, {"id": 1342, "x": -1, "y": -3, "z": -4, "c": "#30363d"}, {"id": 1343, "x": -1, "y": -3, "z": -3, "c": "#30363d"}, {"id": 1344, "x": -1, "y": -3, "z": -2, "c": "#30363d"}, {"id": 1345, "x": -1, "y": -3, "z": -1, "c": "#30363d"}, {"id": 1346, "x": -1, "y": -3, "z": 0, "c": "#30363d"}, {"id": 1347, "x": -1, "y": -3, "z": 1, "c": "#30363d"}, {"id": 1348, "x": -1, "y": -3, "z": 2, "c": "#30363d"}, {"id": 1349, "x": -1, "y": -3, "z": 3, "c": "#30363d"}, {"id": 1350, "x": -1, "y": -3, "z": 4, "c": "#30363d"}, {"id": 1351, "x": -1, "y": -3, "z": 5, "c": "#30363d"}, {"id": 1352, "x": 0, "y": -3, "z": -7, "c": "#30363d"}, {"id": 1353, "x": 0, "y": -3, "z": -6, "c": "#30363d"}, {"id": 1354, "x": 0, "y": -3, "z": -5, "c": "#30363d"}, {"id": 1355, "x": 0, "y": -3, "z": -4, "c": "#30363d"}, {"id": 1356, "x": 0, "y": -3, "z": -3, "c": "#30363d"}, {"id": 1357, "x": 0, "y": -3, "z": -2, "c": "#30363d"}, {"id": 1358, "x": 0, "y": -3, "z": -1, "c": "#30363d"}, {"id": 1359, "x": 0, "y": -3, "z": 0, "c": "#30363d"}, {"id": 1360, "x": 0, "y": -3, "z": 1, "c": "#30363d"}, {"id": 1361, "x": 0, "y": -3, "z": 2, "c": "#30363d"}, {"id": 1362, "x": 0, "y": -3, "z": 3, "c": "#30363d"}, {"id": 1363, "x": 0, "y": -3, "z": 4, "c": "#30363d"}, {"id": 1364, "x": 0, "y": -3, "z": 5, "c": "#30363d"}, {"id": 1365, "x": 1, "y": -3, "z": -7, "c": "#30363d"}, {"id": 1366, "x": 1, "y": -3, "z": -6, "c": "#30363d"}, {"id": 1367, "x": 1, "y": -3, "z": -5, "c": "#30363d"}, {"id": 1368, "x": 1, "y": -3, "z": -4, "c": "#30363d"}, {"id": 1369, "x": 1, "y": -3, "z": -3, "c": "#30363d"}, {"id": 1370, "x": 1, "y": -3, "z": -2, "c": "#30363d"}, {"id": 1371, "x": 1, "y": -3, "z": -1, "c": "#30363d"}, {"id": 1372, "x": 1, "y": -3, "z": 0, "c": "#30363d"}, {"id": 1373, "x": 1, "y": -3, "z": 1, "c": "#30363d"}, {"id": 1374, "x": 1, "y": -3, "z": 2, "c": "#30363d"}, {"id": 1375, "x": 1, "y": -3, "z": 3, "c": "#30363d"}, {"id": 1376, "x": 1, "y": -3, "z": 4, "c": "#30363d"}, {"id": 1377, "x": 1, "y": -3, "z": 5, "c": "#30363d"}, {"id": 1378, "x": 2, "y": -3, "z": -7, "c": "#30363d"}, {"id": 1379, "x": 2, "y": -3, "z": -6, "c": "#30363d"}, {"id": 1380, "x": 2, "y": -3, "z": -5, "c": "#30363d"}, {"id": 1381, "x": 2, "y": -3, "z": -4, "c": "#30363d"}, {"id": 1382, "x": 2, "y": -3, "z": -3, "c": "#30363d"}, {"id": 1383, "x": 2, "y": -3, "z": -2, "c": "#30363d"}, {"id": 1384, "x": 2, "y": -3, "z": -1, "c": "#30363d"}, {"id": 1385, "x": 2, "y": -3, "z": 0, "c": "#30363d"}, {"id": 1386, "x": 2, "y": -3, "z": 1, "c": "#30363d"}, {"id": 1387, "x": 2, "y": -3, "z": 2, "c": "#30363d"}, {"id": 1388, "x": 2, "y": -3, "z": 3, "c": "#30363d"}, {"id": 1389, "x": 2, "y": -3, "z": 4, "c": "#30363d"}, {"id": 1390, "x": 2, "y": -3, "z": 5, "c": "#30363d"}, {"id": 1391, "x": 3, "y": -3, "z": -7, "c": "#30363d"}, {"id": 1392, "x": 3, "y": -3, "z": -6, "c": "#30363d"}, {"id": 1393, "x": 3, "y": -3, "z": -5, "c": "#30363d"}, {"id": 1394, "x": 3, "y": -3, "z": -4, "c": "#30363d"}, {"id": 1395, "x": 3, "y": -3, "z": -3, "c": "#30363d"}, {"id": 1396, "x": 3, "y": -3, "z": -2, "c": "#30363d"}, {"id": 1397, "x": 3, "y": -3, "z": -1, "c": "#30363d"}, {"id": 1398, "x": 3, "y": -3, "z": 0, "c": "#30363d"}, {"id": 1399, "x": 3, "y": -3, "z": 1, "c": "#30363d"}, {"id": 1400, "x": 3, "y": -3, "z": 2, "c": "#30363d"}, {"id": 1401, "x": 3, "y": -3, "z": 3, "c": "#30363d"}, {"id": 1402, "x": 3, "y": -3, "z": 4, "c": "#30363d"}, {"id": 1403, "x": 3, "y": -3, "z": 5, "c": "#30363d"}, {"id": 1404, "x": 4, "y": -3, "z": -7, "c": "#30363d"}, {"id": 1405, "x": 4, "y": -3, "z": -6, "c": "#30363d"}, {"id": 1406, "x": 4, "y": -3, "z": -5, "c": "#30363d"}, {"id": 1407, "x": 4, "y": -3, "z": -4, "c": "#30363d"}, {"id": 1408, "x": 4, "y": -3, "z": -3, "c": "#30363d"}, {"id": 1409, "x": 4, "y": -3, "z": -2, "c": "#30363d"}, {"id": 1410, "x": 4, "y": -3, "z": -1, "c": "#30363d"}, {"id": 1411, "x": 4, "y": -3, "z": 0, "c": "#30363d"}, {"id": 1412, "x": 4, "y": -3, "z": 1, "c": "#30363d"}, {"id": 1413, "x": 4, "y": -3, "z": 2, "c": "#30363d"}, {"id": 1414, "x": 4, "y": -3, "z": 3, "c": "#30363d"}, {"id": 1415, "x": 4, "y": -3, "z": 4, "c": "#30363d"}, {"id": 1416, "x": 4, "y": -3, "z": 5, "c": "#30363d"}, {"id": 1417, "x": 5, "y": -3, "z": -7, "c": "#30363d"}, {"id": 1418, "x": 5, "y": -3, "z": -6, "c": "#30363d"}, {"id": 1419, "x": 5, "y": -3, "z": -5, "c": "#30363d"}, {"id": 1420, "x": 5, "y": -3, "z": -4, "c": "#30363d"}, {"id": 1421, "x": 5, "y": -3, "z": -3, "c": "#30363d"}, {"id": 1422, "x": 5, "y": -3, "z": -2, "c": "#30363d"}, {"id": 1423, "x": 5, "y": -3, "z": -1, "c": "#30363d"}, {"id": 1424, "x": 5, "y": -3, "z": 0, "c": "#30363d"}, {"id": 1425, "x": 5, "y": -3, "z": 1, "c": "#30363d"}, {"id": 1426, "x": 5, "y": -3, "z": 2, "c": "#30363d"}, {"id": 1427, "x": 5, "y": -3, "z": 3, "c": "#30363d"}, {"id": 1428, "x": 5, "y": -3, "z": 4, "c": "#30363d"}, {"id": 1429, "x": 5, "y": -3, "z": 5, "c": "#30363d"}, {"id": 1430, "x": 6, "y": -3, "z": -7, "c": "#30363d"}, {"id": 1431, "x": 6, "y": -3, "z": -6, "c": "#30363d"}, {"id": 1432, "x": 6, "y": -3, "z": -5, "c": "#30363d"}, {"id": 1433, "x": 6, "y": -3, "z": -4, "c": "#30363d"}, {"id": 1434, "x": 6, "y": -3, "z": -3, "c": "#30363d"}, {"id": 1435, "x": 6, "y": -3, "z": -2, "c": "#30363d"}, {"id": 1436, "x": 6, "y": -3, "z": -1, "c": "#30363d"}, {"id": 1437, "x": 6, "y": -3, "z": 0, "c": "#30363d"}, {"id": 1438, "x": 6, "y": -3, "z": 1, "c": "#30363d"}, {"id": 1439, "x": 6, "y": -3, "z": 2, "c": "#30363d"}, {"id": 1440, "x": 6, "y": -3, "z": 3, "c": "#30363d"}, {"id": 1441, "x": 6, "y": -3, "z": 4, "c": "#30363d"}, {"id": 1442, "x": 6, "y": -3, "z": 5, "c": "#30363d"}, {"id": 1443, "x": 6, "y": -3, "z": 6, "c": "#30363d"}, {"id": 1444, "x": 6, "y": -3, "z": 7, "c": "#30363d"}, {"id": 1445, "x": 7, "y": -3, "z": -7, "c": "#30363d"}, {"id": 1446, "x": 7, "y": -3, "z": -6, "c": "#30363d"}, {"id": 1447, "x": 7, "y": -3, "z": -5, "c": "#30363d"}, {"id": 1448, "x": 7, "y": -3, "z": -4, "c": "#30363d"}, {"id": 1449, "x": 7, "y": -3, "z": -3, "c": "#30363d"}, {"id": 1450, "x": 7, "y": -3, "z": -2, "c": "#30363d"}, {"id": 1451, "x": 7, "y": -3, "z": -1, "c": "#30363d"}, {"id": 1452, "x": 7, "y": -3, "z": 0, "c": "#30363d"}, {"id": 1453, "x": 7, "y": -3, "z": 1, "c": "#30363d"}, {"id": 1454, "x": 7, "y": -3, "z": 2, "c": "#30363d"}, {"id": 1455, "x": 7, "y": -3, "z": 3, "c": "#30363d"}, {"id": 1456, "x": 7, "y": -3, "z": 4, "c": "#30363d"}, {"id": 1457, "x": 7, "y": -3, "z": 5, "c": "#30363d"}, {"id": 1458, "x": 7, "y": -3, "z": 6, "c": "#30363d"}, {"id": 1459, "x": 7, "y": -3, "z": 7, "c": "#30363d"}, {"id": 1460, "x": 8, "y": -3, "z": -7, "c": "#30363d"}, {"id": 1461, "x": 8, "y": -3, "z": -6, "c": "#30363d"}, {"id": 1462, "x": 8, "y": -3, "z": -5, "c": "#30363d"}, {"id": 1463, "x": 8, "y": -3, "z": -4, "c": "#30363d"}, {"id": 1464, "x": 8, "y": -3, "z": -3, "c": "#30363d"}, {"id": 1465, "x": 8, "y": -3, "z": -2, "c": "#30363d"}, {"id": 1466, "x": 8, "y": -3, "z": -1, "c": "#30363d"}, {"id": 1467, "x": 8, "y": -3, "z": 0, "c": "#30363d"}, {"id": 1468, "x": 8, "y": -3, "z": 1, "c": "#30363d"}, {"id": 1469, "x": 8, "y": -3, "z": 2, "c": "#30363d"}, {"id": 1470, "x": 8, "y": -3, "z": 3, "c": "#30363d"}, {"id": 1471, "x": 8, "y": -3, "z": 4, "c": "#30363d"}, {"id": 1472, "x": 8, "y": -3, "z": 5, "c": "#30363d"}, {"id": 1473, "x": 8, "y": -3, "z": 6, "c": "#30363d"}, {"id": 1474, "x": 8, "y": -3, "z": 7, "c": "#30363d"}, {"id": 1475, "x": 9, "y": -3, "z": -7, "c": "#30363d"}, {"id": 1476, "x": 9, "y": -3, "z": -6, "c": "#30363d"}, {"id": 1477, "x": 9, "y": -3, "z": -5, "c": "#30363d"}, {"id": 1478, "x": 9, "y": -3, "z": -4, "c": "#30363d"}, {"id": 1479, "x": 9, "y": -3, "z": -3, "c": "#30363d"}, {"id": 1480, "x": 9, "y": -3, "z": -2, "c": "#30363d"}, {"id": 1481, "x": 9, "y": -3, "z": -1, "c": "#30363d"}, {"id": 1482, "x": 9, "y": -3, "z": 0, "c": "#30363d"}, {"id": 1483, "x": 9, "y": -3, "z": 1, "c": "#30363d"}, {"id": 1484, "x": 9, "y": -3, "z": 2, "c": "#30363d"}, {"id": 1485, "x": 9, "y": -3, "z": 3, "c": "#30363d"}, {"id": 1486, "x": 9, "y": -3, "z": 4, "c": "#30363d"}, {"id": 1487, "x": 9, "y": -3, "z": 5, "c": "#30363d"}, {"id": 1488, "x": 9, "y": -3, "z": 6, "c": "#30363d"}, {"id": 1489, "x": 9, "y": -3, "z": 7, "c": "#30363d"}, {"id": 1490, "x": 10, "y": -3, "z": -7, "c": "#30363d"}, {"id": 1491, "x": 10, "y": -3, "z": -6, "c": "#30363d"}, {"id": 1492, "x": 10, "y": -3, "z": -5, "c": "#30363d"}, {"id": 1493, "x": 10, "y": -3, "z": -4, "c": "#30363d"}, {"id": 1494, "x": 10, "y": -3, "z": -3, "c": "#30363d"}, {"id": 1495, "x": 10, "y": -3, "z": -2, "c": "#30363d"}, {"id": 1496, "x": 10, "y": -3, "z": -1, "c": "#30363d"}, {"id": 1497, "x": 10, "y": -3, "z": 0, "c": "#30363d"}, {"id": 1498, "x": 10, "y": -3, "z": 1, "c": "#30363d"}, {"id": 1499, "x": 10, "y": -3, "z": 2, "c": "#30363d"}, {"id": 1500, "x": 10, "y": -3, "z": 3, "c": "#30363d"}, {"id": 1501, "x": 10, "y": -3, "z": 4, "c": "#30363d"}, {"id": 1502, "x": 10, "y": -3, "z": 5, "c": "#30363d"}, {"id": 1503, "x": 10, "y": -3, "z": 6, "c": "#30363d"}, {"id": 1504, "x": 10, "y": -3, "z": 7, "c": "#30363d"}, {"id": 1505, "x": 11, "y": -3, "z": -7, "c": "#30363d"}, {"id": 1506, "x": 11, "y": -3, "z": -6, "c": "#30363d"}, {"id": 1507, "x": 11, "y": -3, "z": -5, "c": "#30363d"}, {"id": 1508, "x": 11, "y": -3, "z": -4, "c": "#30363d"}, {"id": 1509, "x": 11, "y": -3, "z": -3, "c": "#30363d"}, {"id": 1510, "x": 11, "y": -3, "z": -2, "c": "#30363d"}, {"id": 1511, "x": 11, "y": -3, "z": -1, "c": "#30363d"}, {"id": 1512, "x": 11, "y": -3, "z": 0, "c": "#30363d"}, {"id": 1513, "x": 11, "y": -3, "z": 1, "c": "#30363d"}, {"id": 1514, "x": 11, "y": -3, "z": 2, "c": "#30363d"}, {"id": 1515, "x": 11, "y": -3, "z": 3, "c": "#30363d"}, {"id": 1516, "x": 11, "y": -3, "z": 4, "c": "#30363d"}, {"id": 1517, "x": 11, "y": -3, "z": 5, "c": "#30363d"}, {"id": 1518, "x": 11, "y": -3, "z": 6, "c": "#30363d"}, {"id": 1519, "x": 11, "y": -3, "z": 7, "c": "#30363d"}, {"id": 1520, "x": -6, "y": -2, "z": 0, "c": "#60737e"}, {"id": 1521, "x": -5, "y": -2, "z": -3, "c": "#c6beb1"}, {"id": 1522, "x": -5, "y": -2, "z": -2, "c": "#c6beb1"}, {"id": 1523, "x": -5, "y": -2, "z": -1, "c": "#60737e"}, {"id": 1524, "x": -5, "y": -2, "z": 0, "c": "#c6beb1"}, {"id": 1525, "x": -5, "y": -2, "z": 1, "c": "#c6beb1"}, {"id": 1526, "x": -5, "y": -2, "z": 2, "c": "#60737e"}, {"id": 1527, "x": -5, "y": -2, "z": 3, "c": "#c6beb1"}, {"id": 1528, "x": -4, "y": -2, "z": -4, "c": "#c6beb1"}, {"id": 1529, "x": -4, "y": -2, "z": -3, "c": "#c6beb1"}, {"id": 1530, "x": -4, "y": -2, "z": -2, "c": "#c6beb1"}, {"id": 1531, "x": -4, "y": -2, "z": -1, "c": "#c6beb1"}, {"id": 1532, "x": -4, "y": -2, "z": 0, "c": "#c6beb1"}, {"id": 1533, "x": -4, "y": -2, "z": 1, "c": "#c6beb1"}, {"id": 1534, "x": -4, "y": -2, "z": 2, "c": "#c6beb1"}, {"id": 1535, "x": -4, "y": -2, "z": 3, "c": "#c6beb1"}, {"id": 1536, "x": -4, "y": -2, "z": 4, "c": "#60737e"}, {"id": 1537, "x": -3, "y": -2, "z": -5, "c": "#c6beb1"}, {"id": 1538, "x": -3, "y": -2, "z": -4, "c": "#c6beb1"}, {"id": 1539, "x": -3, "y": -2, "z": -3, "c": "#c6beb1"}, {"id": 1540, "x": -3, "y": -2, "z": -2, "c": "#c6beb1"}, {"id": 1541, "x": -3, "y": -2, "z": -1, "c": "#c6beb1"}, {"id": 1542, "x": -3, "y": -2, "z": 0, "c": "#c6beb1"}, {"id": 1543, "x": -3, "y": -2, "z": 1, "c": "#c6beb1"}, {"id": 1544, "x": -3, "y": -2, "z": 2, "c": "#c6beb1"}, {"id": 1545, "x": -3, "y": -2, "z": 3, "c": "#c6beb1"}, {"id": 1546, "x": -3, "y": -2, "z": 4, "c": "#c6beb1"}, {"id": 1547, "x": -3, "y": -2, "z": 5, "c": "#c6beb1"}, {"id": 1548, "x": -2, "y": -2, "z": -5, "c": "#c6beb1"}, {"id": 1549, "x": -2, "y": -2, "z": -4, "c": "#c6beb1"}, {"id": 1550, "x": -2, "y": -2, "z": -3, "c": "#c6beb1"}, {"id": 1551, "x": -2, "y": -2, "z": -2, "c": "#c6beb1"}, {"id": 1552, "x": -2, "y": -2, "z": -1, "c": "#c6beb1"}, {"id": 1553, "x": -2, "y": -2, "z": 0, "c": "#c6beb1"}, {"id": 1554, "x": -2, "y": -2, "z": 1, "c": "#c6beb1"}, {"id": 1555, "x": -2, "y": -2, "z": 2, "c": "#c6beb1"}, {"id": 1556, "x": -2, "y": -2, "z": 3, "c": "#c6beb1"}, {"id": 1557, "x": -2, "y": -2, "z": 4, "c": "#c6beb1"}, {"id": 1558, "x": -2, "y": -2, "z": 5, "c": "#c6beb1"}, {"id": 1559, "x": -1, "y": -2, "z": -5, "c": "#60737e"}, {"id": 1560, "x": -1, "y": -2, "z": -4, "c": "#c6beb1"}, {"id": 1561, "x": -1, "y": -2, "z": -3, "c": "#c6beb1"}, {"id": 1562, "x": -1, "y": -2, "z": -2, "c": "#c6beb1"}, {"id": 1563, "x": -1, "y": -2, "z": -1, "c": "#c6beb1"}, {"id": 1564, "x": -1, "y": -2, "z": 0, "c": "#c6beb1"}, {"id": 1565, "x": -1, "y": -2, "z": 1, "c": "#c6beb1"}, {"id": 1566, "x": -1, "y": -2, "z": 2, "c": "#c6beb1"}, {"id": 1567, "x": -1, "y": -2, "z": 3, "c": "#c6beb1"}, {"id": 1568, "x": -1, "y": -2, "z": 4, "c": "#c6beb1"}, {"id": 1569, "x": -1, "y": -2, "z": 5, "c": "#c6beb1"}, {"id": 1570, "x": 0, "y": -2, "z": -6, "c": "#60737e"}, {"id": 1571, "x": 0, "y": -2, "z": -5, "c": "#c6beb1"}, {"id": 1572, "x": 0, "y": -2, "z": -4, "c": "#c6beb1"}, {"id": 1573, "x": 0, "y": -2, "z": -3, "c": "#c6beb1"}, {"id": 1574, "x": 0, "y": -2, "z": -2, "c": "#c6beb1"}, {"id": 1575, "x": 0, "y": -2, "z": -1, "c": "#c6beb1"}, {"id": 1576, "x": 0, "y": -2, "z": 0, "c": "#c6beb1"}, {"id": 1577, "x": 0, "y": -2, "z": 1, "c": "#c6beb1"}, {"id": 1578, "x": 0, "y": -2, "z": 2, "c": "#c6beb1"}, {"id": 1579, "x": 0, "y": -2, "z": 3, "c": "#c6beb1"}, {"id": 1580, "x": 0, "y": -2, "z": 4, "c": "#c6beb1"}, {"id": 1581, "x": 0, "y": -2, "z": 5, "c": "#c6beb1"}, {"id": 1582, "x": 1, "y": -2, "z": -5, "c": "#c6beb1"}, {"id": 1583, "x": 1, "y": -2, "z": -4, "c": "#c6beb1"}, {"id": 1584, "x": 1, "y": -2, "z": -3, "c": "#c6beb1"}, {"id": 1585, "x": 1, "y": -2, "z": -2, "c": "#c6beb1"}, {"id": 1586, "x": 1, "y": -2, "z": -1, "c": "#c6beb1"}, {"id": 1587, "x": 1, "y": -2, "z": 0, "c": "#c6beb1"}, {"id": 1588, "x": 1, "y": -2, "z": 1, "c": "#c6beb1"}, {"id": 1589, "x": 1, "y": -2, "z": 2, "c": "#c6beb1"}, {"id": 1590, "x": 1, "y": -2, "z": 3, "c": "#c6beb1"}, {"id": 1591, "x": 1, "y": -2, "z": 4, "c": "#c6beb1"}, {"id": 1592, "x": 1, "y": -2, "z": 5, "c": "#c6beb1"}, {"id": 1593, "x": 2, "y": -2, "z": -5, "c": "#60737e"}, {"id": 1594, "x": 2, "y": -2, "z": -4, "c": "#c6beb1"}, {"id": 1595, "x": 2, "y": -2, "z": -3, "c": "#c6beb1"}, {"id": 1596, "x": 2, "y": -2, "z": -2, "c": "#c6beb1"}, {"id": 1597, "x": 2, "y": -2, "z": -1, "c": "#c6beb1"}, {"id": 1598, "x": 2, "y": -2, "z": 0, "c": "#c6beb1"}, {"id": 1599, "x": 2, "y": -2, "z": 1, "c": "#c6beb1"}, {"id": 1600, "x": 2, "y": -2, "z": 2, "c": "#c6beb1"}, {"id": 1601, "x": 2, "y": -2, "z": 3, "c": "#c6beb1"}, {"id": 1602, "x": 2, "y": -2, "z": 4, "c": "#c6beb1"}, {"id": 1603, "x": 2, "y": -2, "z": 5, "c": "#c6beb1"}, {"id": 1604, "x": 3, "y": -2, "z": -5, "c": "#c6beb1"}, {"id": 1605, "x": 3, "y": -2, "z": -4, "c": "#c6beb1"}, {"id": 1606, "x": 3, "y": -2, "z": -3, "c": "#c6beb1"}, {"id": 1607, "x": 3, "y": -2, "z": -2, "c": "#c6beb1"}, {"id": 1608, "x": 3, "y": -2, "z": -1, "c": "#c6beb1"}, {"id": 1609, "x": 3, "y": -2, "z": 0, "c": "#c6beb1"}, {"id": 1610, "x": 3, "y": -2, "z": 1, "c": "#c6beb1"}, {"id": 1611, "x": 3, "y": -2, "z": 2, "c": "#c6beb1"}, {"id": 1612, "x": 3, "y": -2, "z": 3, "c": "#c6beb1"}, {"id": 1613, "x": 3, "y": -2, "z": 4, "c": "#c6beb1"}, {"id": 1614, "x": 3, "y": -2, "z": 5, "c": "#c6beb1"}, {"id": 1615, "x": 4, "y": -2, "z": -4, "c": "#60737e"}, {"id": 1616, "x": 4, "y": -2, "z": -3, "c": "#c6beb1"}, {"id": 1617, "x": 4, "y": -2, "z": -2, "c": "#c6beb1"}, {"id": 1618, "x": 4, "y": -2, "z": -1, "c": "#c6beb1"}, {"id": 1619, "x": 4, "y": -2, "z": 0, "c": "#c6beb1"}, {"id": 1620, "x": 4, "y": -2, "z": 1, "c": "#c6beb1"}, {"id": 1621, "x": 4, "y": -2, "z": 2, "c": "#c6beb1"}, {"id": 1622, "x": 4, "y": -2, "z": 3, "c": "#c6beb1"}, {"id": 1623, "x": 4, "y": -2, "z": 4, "c": "#c6beb1"}, {"id": 1624, "x": 5, "y": -2, "z": -3, "c": "#c6beb1"}, {"id": 1625, "x": 5, "y": -2, "z": -2, "c": "#60737e"}, {"id": 1626, "x": 5, "y": -2, "z": -1, "c": "#c6beb1"}, {"id": 1627, "x": 5, "y": -2, "z": 0, "c": "#c6beb1"}, {"id": 1628, "x": 5, "y": -2, "z": 1, "c": "#60737e"}, {"id": 1629, "x": 5, "y": -2, "z": 2, "c": "#c6beb1"}, {"id": 1630, "x": 5, "y": -2, "z": 3, "c": "#c6beb1"}, {"id": 1631, "x": 6, "y": -2, "z": 0, "c": "#60737e"}, {"id": 1632, "x": -6, "y": -1, "z": 0, "c": "#60737e"}, {"id": 1633, "x": -5, "y": -1, "z": -3, "c": "#c6beb1"}, {"id": 1634, "x": -5, "y": -1, "z": -2, "c": "#c6beb1"}, {"id": 1635, "x": -5, "y": -1, "z": -1, "c": "#60737e"}, {"id": 1636, "x": -5, "y": -1, "z": 0, "c": "#c6beb1"}, {"id": 1637, "x": -5, "y": -1, "z": 1, "c": "#c6beb1"}, {"id": 1638, "x": -5, "y": -1, "z": 2, "c": "#60737e"}, {"id": 1639, "x": -5, "y": -1, "z": 3, "c": "#c6beb1"}, {"id": 1640, "x": -4, "y": -1, "z": -4, "c": "#60737e"}, {"id": 1641, "x": -4, "y": -1, "z": -3, "c": "#60737e"}, {"id": 1642, "x": -4, "y": -1, "z": -2, "c": "#60737e"}, {"id": 1643, "x": -4, "y": -1, "z": -1, "c": "#60737e"}, {"id": 1644, "x": -4, "y": -1, "z": 0, "c": "#60737e"}, {"id": 1645, "x": -4, "y": -1, "z": 1, "c": "#60737e"}, {"id": 1646, "x": -4, "y": -1, "z": 2, "c": "#60737e"}, {"id": 1647, "x": -4, "y": -1, "z": 3, "c": "#60737e"}, {"id": 1648, "x": -4, "y": -1, "z": 4, "c": "#60737e"}, {"id": 1649, "x": -3, "y": -1, "z": -5, "c": "#c6beb1"}, {"id": 1650, "x": -3, "y": -1, "z": -4, "c": "#c6beb1"}, {"id": 1651, "x": -3, "y": -1, "z": -3, "c": "#c6beb1"}, {"id": 1652, "x": -3, "y": -1, "z": -2, "c": "#c6beb1"}, {"id": 1653, "x": -3, "y": -1, "z": -1, "c": "#c6beb1"}, {"id": 1654, "x": -3, "y": -1, "z": 0, "c": "#c6beb1"}, {"id": 1655, "x": -3, "y": -1, "z": 1, "c": "#c6beb1"}, {"id": 1656, "x": -3, "y": -1, "z": 2, "c": "#c6beb1"}, {"id": 1657, "x": -3, "y": -1, "z": 3, "c": "#c6beb1"}, {"id": 1658, "x": -3, "y": -1, "z": 4, "c": "#c6beb1"}, {"id": 1659, "x": -3, "y": -1, "z": 5, "c": "#c6beb1"}, {"id": 1660, "x": -2, "y": -1, "z": -5, "c": "#60737e"}, {"id": 1661, "x": -2, "y": -1, "z": -4, "c": "#60737e"}, {"id": 1662, "x": -2, "y": -1, "z": -3, "c": "#60737e"}, {"id": 1663, "x": -2, "y": -1, "z": -2, "c": "#60737e"}, {"id": 1664, "x": -2, "y": -1, "z": -1, "c": "#60737e"}, {"id": 1665, "x": -2, "y": -1, "z": 0, "c": "#60737e"}, {"id": 1666, "x": -2, "y": -1, "z": 1, "c": "#60737e"}, {"id": 1667, "x": -2, "y": -1, "z": 2, "c": "#60737e"}, {"id": 1668, "x": -2, "y": -1, "z": 3, "c": "#60737e"}, {"id": 1669, "x": -2, "y": -1, "z": 4, "c": "#60737e"}, {"id": 1670, "x": -2, "y": -1, "z": 5, "c": "#60737e"}, {"id": 1671, "x": -1, "y": -1, "z": -5, "c": "#60737e"}, {"id": 1672, "x": -1, "y": -1, "z": -4, "c": "#c6beb1"}, {"id": 1673, "x": -1, "y": -1, "z": -3, "c": "#c6beb1"}, {"id": 1674, "x": -1, "y": -1, "z": -2, "c": "#c6beb1"}, {"id": 1675, "x": -1, "y": -1, "z": -1, "c": "#c6beb1"}, {"id": 1676, "x": -1, "y": -1, "z": 0, "c": "#c6beb1"}, {"id": 1677, "x": -1, "y": -1, "z": 1, "c": "#c6beb1"}, {"id": 1678, "x": -1, "y": -1, "z": 2, "c": "#c6beb1"}, {"id": 1679, "x": -1, "y": -1, "z": 3, "c": "#c6beb1"}, {"id": 1680, "x": -1, "y": -1, "z": 4, "c": "#c6beb1"}, {"id": 1681, "x": -1, "y": -1, "z": 5, "c": "#c6beb1"}, {"id": 1682, "x": 0, "y": -1, "z": -6, "c": "#60737e"}, {"id": 1683, "x": 0, "y": -1, "z": -5, "c": "#60737e"}, {"id": 1684, "x": 0, "y": -1, "z": -4, "c": "#60737e"}, {"id": 1685, "x": 0, "y": -1, "z": -3, "c": "#60737e"}, {"id": 1686, "x": 0, "y": -1, "z": -2, "c": "#60737e"}, {"id": 1687, "x": 0, "y": -1, "z": -1, "c": "#60737e"}, {"id": 1688, "x": 0, "y": -1, "z": 0, "c": "#60737e"}, {"id": 1689, "x": 0, "y": -1, "z": 1, "c": "#60737e"}, {"id": 1690, "x": 0, "y": -1, "z": 2, "c": "#60737e"}, {"id": 1691, "x": 0, "y": -1, "z": 3, "c": "#60737e"}, {"id": 1692, "x": 0, "y": -1, "z": 4, "c": "#60737e"}, {"id": 1693, "x": 0, "y": -1, "z": 5, "c": "#60737e"}, {"id": 1694, "x": 1, "y": -1, "z": -5, "c": "#c6beb1"}, {"id": 1695, "x": 1, "y": -1, "z": -4, "c": "#c6beb1"}, {"id": 1696, "x": 1, "y": -1, "z": -3, "c": "#c6beb1"}, {"id": 1697, "x": 1, "y": -1, "z": -2, "c": "#c6beb1"}, {"id": 1698, "x": 1, "y": -1, "z": -1, "c": "#c6beb1"}, {"id": 1699, "x": 1, "y": -1, "z": 0, "c": "#c6beb1"}, {"id": 1700, "x": 1, "y": -1, "z": 1, "c": "#c6beb1"}, {"id": 1701, "x": 1, "y": -1, "z": 2, "c": "#c6beb1"}, {"id": 1702, "x": 1, "y": -1, "z": 3, "c": "#c6beb1"}, {"id": 1703, "x": 1, "y": -1, "z": 4, "c": "#c6beb1"}, {"id": 1704, "x": 1, "y": -1, "z": 5, "c": "#c6beb1"}, {"id": 1705, "x": 2, "y": -1, "z": -5, "c": "#60737e"}, {"id": 1706, "x": 2, "y": -1, "z": -4, "c": "#60737e"}, {"id": 1707, "x": 2, "y": -1, "z": -3, "c": "#60737e"}, {"id": 1708, "x": 2, "y": -1, "z": -2, "c": "#60737e"}, {"id": 1709, "x": 2, "y": -1, "z": -1, "c": "#60737e"}, {"id": 1710, "x": 2, "y": -1, "z": 0, "c": "#60737e"}, {"id": 1711, "x": 2, "y": -1, "z": 1, "c": "#60737e"}, {"id": 1712, "x": 2, "y": -1, "z": 2, "c": "#60737e"}, {"id": 1713, "x": 2, "y": -1, "z": 3, "c": "#60737e"}, {"id": 1714, "x": 2, "y": -1, "z": 4, "c": "#60737e"}, {"id": 1715, "x": 2, "y": -1, "z": 5, "c": "#60737e"}, {"id": 1716, "x": 3, "y": -1, "z": -5, "c": "#c6beb1"}, {"id": 1717, "x": 3, "y": -1, "z": -4, "c": "#c6beb1"}, {"id": 1718, "x": 3, "y": -1, "z": -3, "c": "#c6beb1"}, {"id": 1719, "x": 3, "y": -1, "z": -2, "c": "#c6beb1"}, {"id": 1720, "x": 3, "y": -1, "z": -1, "c": "#c6beb1"}, {"id": 1721, "x": 3, "y": -1, "z": 0, "c": "#c6beb1"}, {"id": 1722, "x": 3, "y": -1, "z": 1, "c": "#c6beb1"}, {"id": 1723, "x": 3, "y": -1, "z": 2, "c": "#c6beb1"}, {"id": 1724, "x": 3, "y": -1, "z": 3, "c": "#c6beb1"}, {"id": 1725, "x": 3, "y": -1, "z": 4, "c": "#c6beb1"}, {"id": 1726, "x": 3, "y": -1, "z": 5, "c": "#c6beb1"}, {"id": 1727, "x": 4, "y": -1, "z": -4, "c": "#60737e"}, {"id": 1728, "x": 4, "y": -1, "z": -3, "c": "#60737e"}, {"id": 1729, "x": 4, "y": -1, "z": -2, "c": "#60737e"}, {"id": 1730, "x": 4, "y": -1, "z": -1, "c": "#60737e"}, {"id": 1731, "x": 4, "y": -1, "z": 0, "c": "#60737e"}, {"id": 1732, "x": 4, "y": -1, "z": 1, "c": "#60737e"}, {"id": 1733, "x": 4, "y": -1, "z": 2, "c": "#60737e"}, {"id": 1734, "x": 4, "y": -1, "z": 3, "c": "#60737e"}, {"id": 1735, "x": 4, "y": -1, "z": 4, "c": "#60737e"}, {"id": 1736, "x": 5, "y": -1, "z": -3, "c": "#c6beb1"}, {"id": 1737, "x": 5, "y": -1, "z": -2, "c": "#60737e"}, {"id": 1738, "x": 5, "y": -1, "z": -1, "c": "#c6beb1"}, {"id": 1739, "x": 5, "y": -1, "z": 0, "c": "#c6beb1"}, {"id": 1740, "x": 5, "y": -1, "z": 1, "c": "#60737e"}, {"id": 1741, "x": 5, "y": -1, "z": 2, "c": "#c6beb1"}, {"id": 1742, "x": 5, "y": -1, "z": 3, "c": "#c6beb1"}, {"id": 1743, "x": 6, "y": -1, "z": 0, "c": "#60737e"}, {"id": 1744, "x": -6, "y": 0, "z": 0, "c": "#c6beb1"}, {"id": 1745, "x": -5, "y": 0, "z": -3, "c": "#c6beb1"}, {"id": 1746, "x": -5, "y": 0, "z": -2, "c": "#c6beb1"}, {"id": 1747, "x": -5, "y": 0, "z": -1, "c": "#c6beb1"}, {"id": 1748, "x": -5, "y": 0, "z": 0, "c": "#c6beb1"}, {"id": 1749, "x": -5, "y": 0, "z": 1, "c": "#c6beb1"}, {"id": 1750, "x": -5, "y": 0, "z": 2, "c": "#c6beb1"}, {"id": 1751, "x": -5, "y": 0, "z": 3, "c": "#c6beb1"}, {"id": 1752, "x": -4, "y": 0, "z": -4, "c": "#c6beb1"}, {"id": 1753, "x": -4, "y": 0, "z": -3, "c": "#c6beb1"}, {"id": 1754, "x": -4, "y": 0, "z": -2, "c": "#c6beb1"}, {"id": 1755, "x": -4, "y": 0, "z": -1, "c": "#c6beb1"}, {"id": 1756, "x": -4, "y": 0, "z": 0, "c": "#c6beb1"}, {"id": 1757, "x": -4, "y": 0, "z": 1, "c": "#c6beb1"}, {"id": 1758, "x": -4, "y": 0, "z": 2, "c": "#c6beb1"}, {"id": 1759, "x": -4, "y": 0, "z": 3, "c": "#c6beb1"}, {"id": 1760, "x": -4, "y": 0, "z": 4, "c": "#c6beb1"}, {"id": 1761, "x": -3, "y": 0, "z": -5, "c": "#c6beb1"}, {"id": 1762, "x": -3, "y": 0, "z": -4, "c": "#c6beb1"}, {"id": 1763, "x": -3, "y": 0, "z": -3, "c": "#c6beb1"}, {"id": 1764, "x": -3, "y": 0, "z": -2, "c": "#c6beb1"}, {"id": 1765, "x": -3, "y": 0, "z": -1, "c": "#c6beb1"}, {"id": 1766, "x": -3, "y": 0, "z": 0, "c": "#c6beb1"}, {"id": 1767, "x": -3, "y": 0, "z": 1, "c": "#c6beb1"}, {"id": 1768, "x": -3, "y": 0, "z": 2, "c": "#c6beb1"}, {"id": 1769, "x": -3, "y": 0, "z": 3, "c": "#c6beb1"}, {"id": 1770, "x": -3, "y": 0, "z": 4, "c": "#c6beb1"}, {"id": 1771, "x": -3, "y": 0, "z": 5, "c": "#c6beb1"}, {"id": 1772, "x": -2, "y": 0, "z": -5, "c": "#c6beb1"}, {"id": 1773, "x": -2, "y": 0, "z": -4, "c": "#c6beb1"}, {"id": 1774, "x": -2, "y": 0, "z": -3, "c": "#c6beb1"}, {"id": 1775, "x": -2, "y": 0, "z": -2, "c": "#c6beb1"}, {"id": 1776, "x": -2, "y": 0, "z": -1, "c": "#c6beb1"}, {"id": 1777, "x": -2, "y": 0, "z": 0, "c": "#c6beb1"}, {"id": 1778, "x": -2, "y": 0, "z": 1, "c": "#c6beb1"}, {"id": 1779, "x": -2, "y": 0, "z": 2, "c": "#c6beb1"}, {"id": 1780, "x": -2, "y": 0, "z": 3, "c": "#c6beb1"}, {"id": 1781, "x": -2, "y": 0, "z": 4, "c": "#c6beb1"}, {"id": 1782, "x": -2, "y": 0, "z": 5, "c": "#c6beb1"}, {"id": 1783, "x": -1, "y": 0, "z": -5, "c": "#c6beb1"}, {"id": 1784, "x": -1, "y": 0, "z": -4, "c": "#c6beb1"}, {"id": 1785, "x": -1, "y": 0, "z": -3, "c": "#c6beb1"}, {"id": 1786, "x": -1, "y": 0, "z": -2, "c": "#c6beb1"}, {"id": 1787, "x": -1, "y": 0, "z": -1, "c": "#c6beb1"}, {"id": 1788, "x": -1, "y": 0, "z": 0, "c": "#c6beb1"}, {"id": 1789, "x": -1, "y": 0, "z": 1, "c": "#c6beb1"},