{"voxels": [{"id": 0, "x": -10, "y": -12, "z": -10, "c": "#3d434a"}, {"id": 1, "x": -10, "y": -12, "z": -9, "c": "#3d434a"}, {"id": 2, "x": -10, "y": -12, "z": -8, "c": "#3d434a"}, {"id": 3, "x": -10, "y": -12, "z": -7, "c": "#3d434a"}, {"id": 4, "x": -10, "y": -12, "z": -6, "c": "#3d434a"}, {"id": 5, "x": -10, "y": -12, "z": -5, "c": "#3d434a"}, {"id": 6, "x": -10, "y": -12, "z": -4, "c": "#3d434a"}, {"id": 7, "x": -10, "y": -12, "z": -3, "c": "#3d434a"}, {"id": 8, "x": -10, "y": -12, "z": -2, "c": "#3d434a"}, {"id": 9, "x": -10, "y": -12, "z": -1, "c": "#3d434a"}, {"id": 10, "x": -10, "y": -12, "z": 0, "c": "#3d434a"}, {"id": 11, "x": -10, "y": -12, "z": 1, "c": "#3d434a"}, {"id": 12, "x": -10, "y": -12, "z": 2, "c": "#3d434a"}, {"id": 13, "x": -10, "y": -12, "z": 3, "c": "#3d434a"}, {"id": 14, "x": -10, "y": -12, "z": 4, "c": "#3d434a"}, {"id": 15, "x": -10, "y": -12, "z": 5, "c": "#3d434a"}, {"id": 16, "x": -10, "y": -12, "z": 6, "c": "#3d434a"}, {"id": 17, "x": -10, "y": -12, "z": 7, "c": "#3d434a"}, {"id": 18, "x": -10, "y": -12, "z": 8, "c": "#3d434a"}, {"id": 19, "x": -10, "y": -12, "z": 9, "c": "#3d434a"}, {"id": 20, "x": -10, "y": -12, "z": 10, "c": "#3d434a"}, {"id": 21, "x": -9, "y": -12, "z": -10, "c": "#3d434a"}, {"id": 22, "x": -9, "y": -12, "z": -9, "c": "#3d434a"}, {"id": 23, "x": -9, "y": -12, "z": -8, "c": "#3d434a"}, {"id": 24, "x": -9, "y": -12, "z": -7, "c": "#3d434a"}, {"id": 25, "x": -9, "y": -12, "z": -6, "c": "#3d434a"}, {"id": 26, "x": -9, "y": -12, "z": -5, "c": "#3d434a"}, {"id": 27, "x": -9, "y": -12, "z": -4, "c": "#3d434a"}, {"id": 28, "x": -9, "y": -12, "z": -3, "c": "#3d434a"}, {"id": 29, "x": -9, "y": -12, "z": -2, "c": "#3d434a"}, {"id": 30, "x": -9, "y": -12, "z": -1, "c": "#3d434a"}, {"id": 31, "x": -9, "y": -12, "z": 0, "c": "#3d434a"}, {"id": 32, "x": -9, "y": -12, "z": 1, "c": "#3d434a"}, {"id": 33, "x": -9, "y": -12, "z": 2, "c": "#3d434a"}, {"id": 34, "x": -9, "y": -12, "z": 3, "c": "#3d434a"}, {"id": 35, "x": -9, "y": -12, "z": 4, "c": "#3d434a"}, {"id": 36, "x": -9, "y": -12, "z": 5, "c": "#3d434a"}, {"id": 37, "x": -9, "y": -12, "z": 6, "c": "#3d434a"}, {"id": 38, "x": -9, "y": -12, "z": 7, "c": "#3d434a"}, {"id": 39, "x": -9, "y": -12, "z": 8, "c": "#3d434a"}, {"id": 40, "x": -9, "y": -12, "z": 9, "c": "#3d434a"}, {"id": 41, "x": -9, "y": -12, "z": 10, "c": "#3d434a"}, {"id": 42, "x": -8, "y": -12, "z": -10, "c": "#3d434a"}, {"id": 43, "x": -8, "y": -12, "z": -9, "c": "#3d434a"}, {"id": 44, "x": -8, "y": -12, "z": -8, "c": "#3d434a"}, {"id": 45, "x": -8, "y": -12, "z": -7, "c": "#3d434a"}, {"id": 46, "x": -8, "y": -12, "z": -6, "c": "#3d434a"}, {"id": 47, "x": -8, "y": -12, "z": -5, "c": "#3d434a"}, {"id": 48, "x": -8, "y": -12, "z": -4, "c": "#3d434a"}, {"id": 49, "x": -8, "y": -12, "z": -3, "c": "#3d434a"}, {"id": 50, "x": -8, "y": -12, "z": -2, "c": "#3d434a"}, {"id": 51, "x": -8, "y": -12, "z": -1, "c": "#3d434a"}, {"id": 52, "x": -8, "y": -12, "z": 0, "c": "#3d434a"}, {"id": 53, "x": -8, "y": -12, "z": 1, "c": "#3d434a"}, {"id": 54, "x": -8, "y": -12, "z": 2, "c": "#3d434a"}, {"id": 55, "x": -8, "y": -12, "z": 3, "c": "#3d434a"}, {"id": 56, "x": -8, "y": -12, "z": 4, "c": "#3d434a"}, {"id": 57, "x": -8, "y": -12, "z": 5, "c": "#3d434a"}, {"id": 58, "x": -8, "y": -12, "z": 6, "c": "#3d434a"}, {"id": 59, "x": -8, "y": -12, "z": 7, "c": "#3d434a"}, {"id": 60, "x": -8, "y": -12, "z": 8, "c": "#3d434a"}, {"id": 61, "x": -8, "y": -12, "z": 9, "c": "#3d434a"}, {"id": 62, "x": -8, "y": -12, "z": 10, "c": "#3d434a"}, {"id": 63, "x": -7, "y": -12, "z": -10, "c": "#3d434a"}, {"id": 64, "x": -7, "y": -12, "z": -9, "c": "#3d434a"}, {"id": 65, "x": -7, "y": -12, "z": -8, "c": "#3d434a"}, {"id": 66, "x": -7, "y": -12, "z": -7, "c": "#3d434a"}, {"id": 67, "x": -7, "y": -12, "z": -6, "c": "#3d434a"}, {"id": 68, "x": -7, "y": -12, "z": -5, "c": "#3d434a"}, {"id": 69, "x": -7, "y": -12, "z": -4, "c": "#3d434a"}, {"id": 70, "x": -7, "y": -12, "z": -3, "c": "#3d434a"}, {"id": 71, "x": -7, "y": -12, "z": -2, "c": "#3d434a"}, {"id": 72, "x": -7, "y": -12, "z": -1, "c": "#3d434a"}, {"id": 73, "x": -7, "y": -12, "z": 0, "c": "#3d434a"}, {"id": 74, "x": -7, "y": -12, "z": 1, "c": "#3d434a"}, {"id": 75, "x": -7, "y": -12, "z": 2, "c": "#3d434a"}, {"id": 76, "x": -7, "y": -12, "z": 3, "c": "#3d434a"}, {"id": 77, "x": -7, "y": -12, "z": 4, "c": "#3d434a"}, {"id": 78, "x": -7, "y": -12, "z": 5, "c": "#3d434a"}, {"id": 79, "x": -7, "y": -12, "z": 6, "c": "#3d434a"}, {"id": 80, "x": -7, "y": -12, "z": 7, "c": "#3d434a"}, {"id": 81, "x": -7, "y": -12, "z": 8, "c": "#3d434a"}, {"id": 82, "x": -7, "y": -12, "z": 9, "c": "#3d434a"}, {"id": 83, "x": -7, "y": -12, "z": 10, "c": "#3d434a"}, {"id": 84, "x": -6, "y": -12, "z": -10, "c": "#3d434a"}, {"id": 85, "x": -6, "y": -12, "z": -9, "c": "#3d434a"}, {"id": 86, "x": -6, "y": -12, "z": -8, "c": "#3d434a"}, {"id": 87, "x": -6, "y": -12, "z": -7, "c": "#3d434a"}, {"id": 88, "x": -6, "y": -12, "z": -6, "c": "#3d434a"}, {"id": 89, "x": -6, "y": -12, "z": -5, "c": "#3d434a"}, {"id": 90, "x": -6, "y": -12, "z": -4, "c": "#3d434a"}, {"id": 91, "x": -6, "y": -12, "z": -3, "c": "#3d434a"}, {"id": 92, "x": -6, "y": -12, "z": -2, "c": "#3d434a"}, {"id": 93, "x": -6, "y": -12, "z": -1, "c": "#3d434a"}, {"id": 94, "x": -6, "y": -12, "z": 0, "c": "#3d434a"}, {"id": 95, "x": -6, "y": -12, "z": 1, "c": "#3d434a"}, {"id": 96, "x": -6, "y": -12, "z": 2, "c": "#3d434a"}, {"id": 97, "x": -6, "y": -12, "z": 3, "c": "#3d434a"}, {"id": 98, "x": -6, "y": -12, "z": 4, "c": "#3d434a"}, {"id": 99, "x": -6, "y": -12, "z": 5, "c": "#3d434a"}, {"id": 100, "x": -6, "y": -12, "z": 6, "c": "#3d434a"}, {"id": 101, "x": -6, "y": -12, "z": 7, "c": "#3d434a"}, {"id": 102, "x": -6, "y": -12, "z": 8, "c": "#3d434a"}, {"id": 103, "x": -6, "y": -12, "z": 9, "c": "#3d434a"}, {"id": 104, "x": -6, "y": -12, "z": 10, "c": "#3d434a"}, {"id": 105, "x": -5, "y": -12, "z": -10, "c": "#3d434a"}, {"id": 106, "x": -5, "y": -12, "z": -9, "c": "#3d434a"}, {"id": 107, "x": -5, "y": -12, "z": -8, "c": "#3d434a"}, {"id": 108, "x": -5, "y": -12, "z": -7, "c": "#3d434a"}, {"id": 109, "x": -5, "y": -12, "z": -6, "c": "#3d434a"}, {"id": 110, "x": -5, "y": -12, "z": -5, "c": "#3d434a"}, {"id": 111, "x": -5, "y": -12, "z": -4, "c": "#3d434a"}, {"id": 112, "x": -5, "y": -12, "z": -3, "c": "#3d434a"}, {"id": 113, "x": -5, "y": -12, "z": -2, "c": "#3d434a"}, {"id": 114, "x": -5, "y": -12, "z": -1, "c": "#3d434a"}, {"id": 115, "x": -5, "y": -12, "z": 0, "c": "#3d434a"}, {"id": 116, "x": -5, "y": -12, "z": 1, "c": "#3d434a"}, {"id": 117, "x": -5, "y": -12, "z": 2, "c": "#3d434a"}, {"id": 118, "x": -5, "y": -12, "z": 3, "c": "#3d434a"}, {"id": 119, "x": -5, "y": -12, "z": 4, "c": "#3d434a"}, {"id": 120, "x": -5, "y": -12, "z": 5, "c": "#3d434a"}, {"id": 121, "x": -5, "y": -12, "z": 6, "c": "#3d434a"}, {"id": 122, "x": -5, "y": -12, "z": 7, "c": "#3d434a"}, {"id": 123, "x": -5, "y": -12, "z": 8, "c": "#3d434a"}, {"id": 124, "x": -5, "y": -12, "z": 9, "c": "#3d434a"}, {"id": 125, "x": -5, "y": -12, "z": 10, "c": "#3d434a"}, {"id": 126, "x": -4, "y": -12, "z": -10, "c": "#3d434a"}, {"id": 127, "x": -4, "y": -12, "z": -9, "c": "#3d434a"}, {"id": 128, "x": -4, "y": -12, "z": -8, "c": "#3d434a"}, {"id": 129, "x": -4, "y": -12, "z": -7, "c": "#3d434a"}, {"id": 130, "x": -4, "y": -12, "z": -6, "c": "#3d434a"}, {"id": 131, "x": -4, "y": -12, "z": -5, "c": "#3d434a"}, {"id": 132, "x": -4, "y": -12, "z": -4, "c": "#3d434a"}, {"id": 133, "x": -4, "y": -12, "z": -3, "c": "#3d434a"}, {"id": 134, "x": -4, "y": -12, "z": -2, "c": "#3d434a"}, {"id": 135, "x": -4, "y": -12, "z": -1, "c": "#3d434a"}, {"id": 136, "x": -4, "y": -12, "z": 0, "c": "#3d434a"}, {"id": 137, "x": -4, "y": -12, "z": 1, "c": "#3d434a"}, {"id": 138, "x": -4, "y": -12, "z": 2, "c": "#3d434a"}, {"id": 139, "x": -4, "y": -12, "z": 3, "c": "#3d434a"}, {"id": 140, "x": -4, "y": -12, "z": 4, "c": "#3d434a"}, {"id": 141, "x": -4, "y": -12, "z": 5, "c": "#3d434a"}, {"id": 142, "x": -4, "y": -12, "z": 6, "c": "#3d434a"}, {"id": 143, "x": -4, "y": -12, "z": 7, "c": "#3d434a"}, {"id": 144, "x": -4, "y": -12, "z": 8, "c": "#3d434a"}, {"id": 145, "x": -4, "y": -12, "z": 9, "c": "#3d434a"}, {"id": 146, "x": -4, "y": -12, "z": 10, "c": "#3d434a"}, {"id": 147, "x": -3, "y": -12, "z": -10, "c": "#3d434a"}, {"id": 148, "x": -3, "y": -12, "z": -9, "c": "#3d434a"}, {"id": 149, "x": -3, "y": -12, "z": -8, "c": "#3d434a"}, {"id": 150, "x": -3, "y": -12, "z": -7, "c": "#3d434a"}, {"id": 151, "x": -3, "y": -12, "z": -6, "c": "#3d434a"}, {"id": 152, "x": -3, "y": -12, "z": -5, "c": "#3d434a"}, {"id": 153, "x": -3, "y": -12, "z": -4, "c": "#3d434a"}, {"id": 154, "x": -3, "y": -12, "z": -3, "c": "#3d434a"}, {"id": 155, "x": -3, "y": -12, "z": -2, "c": "#3d434a"}, {"id": 156, "x": -3, "y": -12, "z": -1, "c": "#3d434a"}, {"id": 157, "x": -3, "y": -12, "z": 0, "c": "#3d434a"}, {"id": 158, "x": -3, "y": -12, "z": 1, "c": "#3d434a"}, {"id": 159, "x": -3, "y": -12, "z": 2, "c": "#3d434a"}, {"id": 160, "x": -3, "y": -12, "z": 3, "c": "#3d434a"}, {"id": 161, "x": -3, "y": -12, "z": 4, "c": "#3d434a"}, {"id": 162, "x": -3, "y": -12, "z": 5, "c": "#3d434a"}, {"id": 163, "x": -3, "y": -12, "z": 6, "c": "#3d434a"}, {"id": 164, "x": -3, "y": -12, "z": 7, "c": "#3d434a"}, {"id": 165, "x": -3, "y": -12, "z": 8, "c": "#3d434a"}, {"id": 166, "x": -3, "y": -12, "z": 9, "c": "#3d434a"}, {"id": 167, "x": -3, "y": -12, "z": 10, "c": "#3d434a"}, {"id": 168, "x": -2, "y": -12, "z": -10, "c": "#3d434a"}, {"id": 169, "x": -2, "y": -12, "z": -9, "c": "#3d434a"}, {"id": 170, "x": -2, "y": -12, "z": -8, "c": "#3d434a"}, {"id": 171, "x": -2, "y": -12, "z": -7, "c": "#3d434a"}, {"id": 172, "x": -2, "y": -12, "z": -6, "c": "#3d434a"}, {"id": 173, "x": -2, "y": -12, "z": -5, "c": "#3d434a"}, {"id": 174, "x": -2, "y": -12, "z": -4, "c": "#3d434a"}, {"id": 175, "x": -2, "y": -12, "z": -3, "c": "#3d434a"}, {"id": 176, "x": -2, "y": -12, "z": -2, "c": "#3d434a"}, {"id": 177, "x": -2, "y": -12, "z": -1, "c": "#3d434a"}, {"id": 178, "x": -2, "y": -12, "z": 0, "c": "#3d434a"}, {"id": 179, "x": -2, "y": -12, "z": 1, "c": "#3d434a"}, {"id": 180, "x": -2, "y": -12, "z": 2, "c": "#3d434a"}, {"id": 181, "x": -2, "y": -12, "z": 3, "c": "#3d434a"}, {"id": 182, "x": -2, "y": -12, "z": 4, "c": "#3d434a"}, {"id": 183, "x": -2, "y": -12, "z": 5, "c": "#3d434a"}, {"id": 184, "x": -2, "y": -12, "z": 6, "c": "#3d434a"}, {"id": 185, "x": -2, "y": -12, "z": 7, "c": "#3d434a"}, {"id": 186, "x": -2, "y": -12, "z": 8, "c": "#3d434a"}, {"id": 187, "x": -2, "y": -12, "z": 9, "c": "#3d434a"}, {"id": 188, "x": -2, "y": -12, "z": 10, "c": "#3d434a"}, {"id": 189, "x": -1, "y": -12, "z": -10, "c": "#3d434a"}, {"id": 190, "x": -1, "y": -12, "z": -9, "c": "#3d434a"}, {"id": 191, "x": -1, "y": -12, "z": -8, "c": "#3d434a"}, {"id": 192, "x": -1, "y": -12, "z": -7, "c": "#3d434a"}, {"id": 193, "x": -1, "y": -12, "z": -6, "c": "#3d434a"}, {"id": 194, "x": -1, "y": -12, "z": -5, "c": "#3d434a"}, {"id": 195, "x": -1, "y": -12, "z": -4, "c": "#3d434a"}, {"id": 196, "x": -1, "y": -12, "z": -3, "c": "#3d434a"}, {"id": 197, "x": -1, "y": -12, "z": -2, "c": "#3d434a"}, {"id": 198, "x": -1, "y": -12, "z": -1, "c": "#3d434a"}, {"id": 199, "x": -1, "y": -12, "z": 0, "c": "#3d434a"}, {"id": 200, "x": -1, "y": -12, "z": 1, "c": "#3d434a"}, {"id": 201, "x": -1, "y": -12, "z": 2, "c": "#3d434a"}, {"id": 202, "x": -1, "y": -12, "z": 3, "c": "#3d434a"}, {"id": 203, "x": -1, "y": -12, "z": 4, "c": "#3d434a"}, {"id": 204, "x": -1, "y": -12, "z": 5, "c": "#3d434a"}, {"id": 205, "x": -1, "y": -12, "z": 6, "c": "#3d434a"}, {"id": 206, "x": -1, "y": -12, "z": 7, "c": "#3d434a"}, {"id": 207, "x": -1, "y": -12, "z": 8, "c": "#3d434a"}, {"id": 208, "x": -1, "y": -12, "z": 9, "c": "#3d434a"}, {"id": 209, "x": -1, "y": -12, "z": 10, "c": "#3d434a"}, {"id": 210, "x": 0, "y": -12, "z": -10, "c": "#3d434a"}, {"id": 211, "x": 0, "y": -12, "z": -9, "c": "#3d434a"}, {"id": 212, "x": 0, "y": -12, "z": -8, "c": "#3d434a"}, {"id": 213, "x": 0, "y": -12, "z": -7, "c": "#3d434a"}, {"id": 214, "x": 0, "y": -12, "z": -6, "c": "#3d434a"}, {"id": 215, "x": 0, "y": -12, "z": -5, "c": "#3d434a"}, {"id": 216, "x": 0, "y": -12, "z": -4, "c": "#3d434a"}, {"id": 217, "x": 0, "y": -12, "z": -3, "c": "#3d434a"}, {"id": 218, "x": 0, "y": -12, "z": -2, "c": "#3d434a"}, {"id": 219, "x": 0, "y": -12, "z": -1, "c": "#3d434a"}, {"id": 220, "x": 0, "y": -12, "z": 0, "c": "#3d434a"}, {"id": 221, "x": 0, "y": -12, "z": 1, "c": "#3d434a"}, {"id": 222, "x": 0, "y": -12, "z": 2, "c": "#3d434a"}, {"id": 223, "x": 0, "y": -12, "z": 3, "c": "#3d434a"}, {"id": 224, "x": 0, "y": -12, "z": 4, "c": "#3d434a"}, {"id": 225, "x": 0, "y": -12, "z": 5, "c": "#3d434a"}, {"id": 226, "x": 0, "y": -12, "z": 6, "c": "#3d434a"}, {"id": 227, "x": 0, "y": -12, "z": 7, "c": "#3d434a"}, {"id": 228, "x": 0, "y": -12, "z": 8, "c": "#3d434a"}, {"id": 229, "x": 0, "y": -12, "z": 9, "c": "#3d434a"}, {"id": 230, "x": 0, "y": -12, "z": 10, "c": "#3d434a"}, {"id": 231, "x": 1, "y": -12, "z": -10, "c": "#3d434a"}, {"id": 232, "x": 1, "y": -12, "z": -9, "c": "#3d434a"}, {"id": 233, "x": 1, "y": -12, "z": -8, "c": "#3d434a"}, {"id": 234, "x": 1, "y": -12, "z": -7, "c": "#3d434a"}, {"id": 235, "x": 1, "y": -12, "z": -6, "c": "#3d434a"}, {"id": 236, "x": 1, "y": -12, "z": -5, "c": "#3d434a"}, {"id": 237, "x": 1, "y": -12, "z": -4, "c": "#3d434a"}, {"id": 238, "x": 1, "y": -12, "z": -3, "c": "#3d434a"}, {"id": 239, "x": 1, "y": -12, "z": -2, "c": "#3d434a"}, {"id": 240, "x": 1, "y": -12, "z": -1, "c": "#3d434a"}, {"id": 241, "x": 1, "y": -12, "z": 0, "c": "#3d434a"}, {"id": 242, "x": 1, "y": -12, "z": 1, "c": "#3d434a"}, {"id": 243, "x": 1, "y": -12, "z": 2, "c": "#3d434a"}, {"id": 244, "x": 1, "y": -12, "z": 3, "c": "#3d434a"}, {"id": 245, "x": 1, "y": -12, "z": 4, "c": "#3d434a"}, {"id": 246, "x": 1, "y": -12, "z": 5, "c": "#3d434a"}, {"id": 247, "x": 1, "y": -12, "z": 6, "c": "#3d434a"}, {"id": 248, "x": 1, "y": -12, "z": 7, "c": "#3d434a"}, {"id": 249, "x": 1, "y": -12, "z": 8, "c": "#3d434a"}, {"id": 250, "x": 1, "y": -12, "z": 9, "c": "#3d434a"}, {"id": 251, "x": 1, "y": -12, "z": 10, "c": "#3d434a"}, {"id": 252, "x": 2, "y": -12, "z": -10, "c": "#3d434a"}, {"id": 253, "x": 2, "y": -12, "z": -9, "c": "#3d434a"}, {"id": 254, "x": 2, "y": -12, "z": -8, "c": "#3d434a"}, {"id": 255, "x": 2, "y": -12, "z": -7, "c": "#3d434a"}, {"id": 256, "x": 2, "y": -12, "z": -6, "c": "#3d434a"}, {"id": 257, "x": 2, "y": -12, "z": -5, "c": "#3d434a"}, {"id": 258, "x": 2, "y": -12, "z": -4, "c": "#3d434a"}, {"id": 259, "x": 2, "y": -12, "z": -3, "c": "#3d434a"}, {"id": 260, "x": 2, "y": -12, "z": -2, "c": "#3d434a"}, {"id": 261, "x": 2, "y": -12, "z": -1, "c": "#3d434a"}, {"id": 262, "x": 2, "y": -12, "z": 0, "c": "#3d434a"}, {"id": 263, "x": 2, "y": -12, "z": 1, "c": "#3d434a"}, {"id": 264, "x": 2, "y": -12, "z": 2, "c": "#3d434a"}, {"id": 265, "x": 2, "y": -12, "z": 3, "c": "#3d434a"}, {"id": 266, "x": 2, "y": -12, "z": 4, "c": "#3d434a"}, {"id": 267, "x": 2, "y": -12, "z": 5, "c": "#3d434a"}, {"id": 268, "x": 2, "y": -12, "z": 6, "c": "#3d434a"}, {"id": 269, "x": 2, "y": -12, "z": 7, "c": "#3d434a"}, {"id": 270, "x": 2, "y": -12, "z": 8, "c": "#3d434a"}, {"id": 271, "x": 2, "y": -12, "z": 9, "c": "#3d434a"}, {"id": 272, "x": 2, "y": -12, "z": 10, "c": "#3d434a"}, {"id": 273, "x": 3, "y": -12, "z": -10, "c": "#3d434a"}, {"id": 274, "x": 3, "y": -12, "z": -9, "c": "#3d434a"}, {"id": 275, "x": 3, "y": -12, "z": -8, "c": "#3d434a"}, {"id": 276, "x": 3, "y": -12, "z": -7, "c": "#3d434a"}, {"id": 277, "x": 3, "y": -12, "z": -6, "c": "#3d434a"}, {"id": 278, "x": 3, "y": -12, "z": -5, "c": "#3d434a"}, {"id": 279, "x": 3, "y": -12, "z": -4, "c": "#3d434a"}, {"id": 280, "x": 3, "y": -12, "z": -3, "c": "#3d434a"}, {"id": 281, "x": 3, "y": -12, "z": -2, "c": "#3d434a"}, {"id": 282, "x": 3, "y": -12, "z": -1, "c": "#3d434a"}, {"id": 283, "x": 3, "y": -12, "z": 0, "c": "#3d434a"}, {"id": 284, "x": 3, "y": -12, "z": 1, "c": "#3d434a"}, {"id": 285, "x": 3, "y": -12, "z": 2, "c": "#3d434a"}, {"id": 286, "x": 3, "y": -12, "z": 3, "c": "#3d434a"}, {"id": 287, "x": 3, "y": -12, "z": 4, "c": "#3d434a"}, {"id": 288, "x": 3, "y": -12, "z": 5, "c": "#3d434a"}, {"id": 289, "x": 3, "y": -12, "z": 6, "c": "#3d434a"}, {"id": 290, "x": 3, "y": -12, "z": 7, "c": "#3d434a"}, {"id": 291, "x": 3, "y": -12, "z": 8, "c": "#3d434a"}, {"id": 292, "x": 3, "y": -12, "z": 9, "c": "#3d434a"}, {"id": 293, "x": 3, "y": -12, "z": 10, "c": "#3d434a"}, {"id": 294, "x": 4, "y": -12, "z": -10, "c": "#3d434a"}, {"id": 295, "x": 4, "y": -12, "z": -9, "c": "#3d434a"}, {"id": 296, "x": 4, "y": -12, "z": -8, "c": "#3d434a"}, {"id": 297, "x": 4, "y": -12, "z": -7, "c": "#3d434a"}, {"id": 298, "x": 4, "y": -12, "z": -6, "c": "#3d434a"}, {"id": 299, "x": 4, "y": -12, "z": -5, "c": "#3d434a"}, {"id": 300, "x": 4, "y": -12, "z": -4, "c": "#3d434a"}, {"id": 301, "x": 4, "y": -12, "z": -3, "c": "#3d434a"}, {"id": 302, "x": 4, "y": -12, "z": -2, "c": "#3d434a"}, {"id": 303, "x": 4, "y": -12, "z": -1, "c": "#3d434a"}, {"id": 304, "x": 4, "y": -12, "z": 0, "c": "#3d434a"}, {"id": 305, "x": 4, "y": -12, "z": 1, "c": "#3d434a"}, {"id": 306, "x": 4, "y": -12, "z": 2, "c": "#3d434a"}, {"id": 307, "x": 4, "y": -12, "z": 3, "c": "#3d434a"}, {"id": 308, "x": 4, "y": -12, "z": 4, "c": "#3d434a"}, {"id": 309, "x": 4, "y": -12, "z": 5, "c": "#3d434a"}, {"id": 310, "x": 4, "y": -12, "z": 6, "c": "#3d434a"}, {"id": 311, "x": 4, "y": -12, "z": 7, "c": "#3d434a"}, {"id": 312, "x": 4, "y": -12, "z": 8, "c": "#3d434a"}, {"id": 313, "x": 4, "y": -12, "z": 9, "c": "#3d434a"}, {"id": 314, "x": 4, "y": -12, "z": 10, "c": "#3d434a"}, {"id": 315, "x": 5, "y": -12, "z": -10, "c": "#3d434a"}, {"id": 316, "x": 5, "y": -12, "z": -9, "c": "#3d434a"}, {"id": 317, "x": 5, "y": -12, "z": -8, "c": "#3d434a"}, {"id": 318, "x": 5, "y": -12, "z": -7, "c": "#3d434a"}, {"id": 319, "x": 5, "y": -12, "z": -6, "c": "#3d434a"}, {"id": 320, "x": 5, "y": -12, "z": -5, "c": "#3d434a"}, {"id": 321, "x": 5, "y": -12, "z": -4, "c": "#3d434a"}, {"id": 322, "x": 5, "y": -12, "z": -3, "c": "#3d434a"}, {"id": 323, "x": 5, "y": -12, "z": -2, "c": "#3d434a"}, {"id": 324, "x": 5, "y": -12, "z": -1, "c": "#3d434a"}, {"id": 325, "x": 5, "y": -12, "z": 0, "c": "#3d434a"}, {"id": 326, "x": 5, "y": -12, "z": 1, "c": "#3d434a"}, {"id": 327, "x": 5, "y": -12, "z": 2, "c": "#3d434a"}, {"id": 328, "x": 5, "y": -12, "z": 3, "c": "#3d434a"}, {"id": 329, "x": 5, "y": -12, "z": 4, "c": "#3d434a"}, {"id": 330, "x": 5, "y": -12, "z": 5, "c": "#3d434a"}, {"id": 331, "x": 5, "y": -12, "z": 6, "c": "#3d434a"}, {"id": 332, "x": 5, "y": -12, "z": 7, "c": "#3d434a"}, {"id": 333, "x": 5, "y": -12, "z": 8, "c": "#3d434a"}, {"id": 334, "x": 5, "y": -12, "z": 9, "c": "#3d434a"}, {"id": 335, "x": 5, "y": -12, "z": 10, "c": "#3d434a"}, {"id": 336, "x": 6, "y": -12, "z": -10, "c": "#3d434a"}, {"id": 337, "x": 6, "y": -12, "z": -9, "c": "#3d434a"}, {"id": 338, "x": 6, "y": -12, "z": -8, "c": "#3d434a"}, {"id": 339, "x": 6, "y": -12, "z": -7, "c": "#3d434a"}, {"id": 340, "x": 6, "y": -12, "z": -6, "c": "#3d434a"}, {"id": 341, "x": 6, "y": -12, "z": -5, "c": "#3d434a"}, {"id": 342, "x": 6, "y": -12, "z": -4, "c": "#3d434a"}, {"id": 343, "x": 6, "y": -12, "z": -3, "c": "#3d434a"}, {"id": 344, "x": 6, "y": -12, "z": -2, "c": "#3d434a"}, {"id": 345, "x": 6, "y": -12, "z": -1, "c": "#3d434a"}, {"id": 346, "x": 6, "y": -12, "z": 0, "c": "#3d434a"}, {"id": 347, "x": 6, "y": -12, "z": 1, "c": "#3d434a"}, {"id": 348, "x": 6, "y": -12, "z": 2, "c": "#3d434a"}, {"id": 349, "x": 6, "y": -12, "z": 3, "c": "#3d434a"}, {"id": 350, "x": 6, "y": -12, "z": 4, "c": "#3d434a"}, {"id": 351, "x": 6, "y": -12, "z": 5, "c": "#3d434a"}, {"id": 352, "x": 6, "y": -12, "z": 6, "c": "#3d434a"}, {"id": 353, "x": 6, "y": -12, "z": 7, "c": "#3d434a"}, {"id": 354, "x": 6, "y": -12, "z": 8, "c": "#3d434a"}, {"id": 355, "x": 6, "y": -12, "z": 9, "c": "#3d434a"}, {"id": 356, "x": 6, "y": -12, "z": 10, "c": "#3d434a"}, {"id": 357, "x": 7, "y": -12, "z": -10, "c": "#3d434a"}, {"id": 358, "x": 7, "y": -12, "z": -9, "c": "#3d434a"}, {"id": 359, "x": 7, "y": -12, "z": -8, "c": "#3d434a"}, {"id": 360, "x": 7, "y": -12, "z": -7, "c": "#3d434a"}, {"id": 361, "x": 7, "y": -12, "z": -6, "c": "#3d434a"}, {"id": 362, "x": 7, "y": -12, "z": -5, "c": "#3d434a"}, {"id": 363, "x": 7, "y": -12, "z": -4, "c": "#3d434a"}, {"id": 364, "x": 7, "y": -12, "z": -3, "c": "#3d434a"}, {"id": 365, "x": 7, "y": -12, "z": -2, "c": "#3d434a"}, {"id": 366, "x": 7, "y": -12, "z": -1, "c": "#3d434a"}, {"id": 367, "x": 7, "y": -12, "z": 0, "c": "#3d434a"}, {"id": 368, "x": 7, "y": -12, "z": 1, "c": "#3d434a"}, {"id": 369, "x": 7, "y": -12, "z": 2, "c": "#3d434a"}, {"id": 370, "x": 7, "y": -12, "z": 3, "c": "#3d434a"}, {"id": 371, "x": 7, "y": -12, "z": 4, "c": "#3d434a"}, {"id": 372, "x": 7, "y": -12, "z": 5, "c": "#3d434a"}, {"id": 373, "x": 7, "y": -12, "z": 6, "c": "#3d434a"}, {"id": 374, "x": 7, "y": -12, "z": 7, "c": "#3d434a"}, {"id": 375, "x": 7, "y": -12, "z": 8, "c": "#3d434a"}, {"id": 376, "x": 7, "y": -12, "z": 9, "c": "#3d434a"}, {"id": 377, "x": 7, "y": -12, "z": 10, "c": "#3d434a"}, {"id": 378, "x": 8, "y": -12, "z": -10, "c": "#3d434a"}, {"id": 379, "x": 8, "y": -12, "z": -9, "c": "#3d434a"}, {"id": 380, "x": 8, "y": -12, "z": -8, "c": "#3d434a"}, {"id": 381, "x": 8, "y": -12, "z": -7, "c": "#3d434a"}, {"id": 382, "x": 8, "y": -12, "z": -6, "c": "#3d434a"}, {"id": 383, "x": 8, "y": -12, "z": -5, "c": "#3d434a"}, {"id": 384, "x": 8, "y": -12, "z": -4, "c": "#3d434a"}, {"id": 385, "x": 8, "y": -12, "z": -3, "c": "#3d434a"}, {"id": 386, "x": 8, "y": -12, "z": -2, "c": "#3d434a"}, {"id": 387, "x": 8, "y": -12, "z": -1, "c": "#3d434a"}, {"id": 388, "x": 8, "y": -12, "z": 0, "c": "#3d434a"}, {"id": 389, "x": 8, "y": -12, "z": 1, "c": "#3d434a"}, {"id": 390, "x": 8, "y": -12, "z": 2, "c": "#3d434a"}, {"id": 391, "x": 8, "y": -12, "z": 3, "c": "#3d434a"}, {"id": 392, "x": 8, "y": -12, "z": 4, "c": "#3d434a"}, {"id": 393, "x": 8, "y": -12, "z": 5, "c": "#3d434a"}, {"id": 394, "x": 8, "y": -12, "z": 6, "c": "#3d434a"}, {"id": 395, "x": 8, "y": -12, "z": 7, "c": "#3d434a"}, {"id": 396, "x": 8, "y": -12, "z": 8, "c": "#3d434a"}, {"id": 397, "x": 8, "y": -12, "z": 9, "c": "#3d434a"}, {"id": 398, "x": 8, "y": -12, "z": 10, "c": "#3d434a"}, {"id": 399, "x": 9, "y": -12, "z": -10, "c": "#3d434a"}, {"id": 400, "x": 9, "y": -12, "z": -9, "c": "#3d434a"}, {"id": 401, "x": 9, "y": -12, "z": -8, "c": "#3d434a"}, {"id": 402, "x": 9, "y": -12, "z": -7, "c": "#3d434a"}, {"id": 403, "x": 9, "y": -12, "z": -6, "c": "#3d434a"}, {"id": 404, "x": 9, "y": -12, "z": -5, "c": "#3d434a"}, {"id": 405, "x": 9, "y": -12, "z": -4, "c": "#3d434a"}, {"id": 406, "x": 9, "y": -12, "z": -3, "c": "#3d434a"}, {"id": 407, "x": 9, "y": -12, "z": -2, "c": "#3d434a"}, {"id": 408, "x": 9, "y": -12, "z": -1, "c": "#3d434a"}, {"id": 409, "x": 9, "y": -12, "z": 0, "c": "#3d434a"}, {"id": 410, "x": 9, "y": -12, "z": 1, "c": "#3d434a"}, {"id": 411, "x": 9, "y": -12, "z": 2, "c": "#3d434a"}, {"id": 412, "x": 9, "y": -12, "z": 3, "c": "#3d434a"}, {"id": 413, "x": 9, "y": -12, "z": 4, "c": "#3d434a"}, {"id": 414, "x": 9, "y": -12, "z": 5, "c": "#3d434a"}, {"id": 415, "x": 9, "y": -12, "z": 6, "c": "#3d434a"}, {"id": 416, "x": 9, "y": -12, "z": 7, "c": "#3d434a"}, {"id": 417, "x": 9, "y": -12, "z": 8, "c": "#3d434a"}, {"id": 418, "x": 9, "y": -12, "z": 9, "c": "#3d434a"}, {"id": 419, "x": 9, "y": -12, "z": 10, "c": "#3d434a"}, {"id": 420, "x": 10, "y": -12, "z": -10, "c": "#3d434a"}, {"id": 421, "x": 10, "y": -12, "z": -9, "c": "#3d434a"}, {"id": 422, "x": 10, "y": -12, "z": -8, "c": "#3d434a"}, {"id": 423, "x": 10, "y": -12, "z": -7, "c": "#3d434a"}, {"id": 424, "x": 10, "y": -12, "z": -6, "c": "#3d434a"}, {"id": 425, "x": 10, "y": -12, "z": -5, "c": "#3d434a"}, {"id": 426, "x": 10, "y": -12, "z": -4, "c": "#3d434a"}, {"id": 427, "x": 10, "y": -12, "z": -3, "c": "#3d434a"}, {"id": 428, "x": 10, "y": -12, "z": -2, "c": "#3d434a"}, {"id": 429, "x": 10, "y": -12, "z": -1, "c": "#3d434a"}, {"id": 430, "x": 10, "y": -12, "z": 0, "c": "#3d434a"}, {"id": 431, "x": 10, "y": -12, "z": 1, "c": "#3d434a"}, {"id": 432, "x": 10, "y": -12, "z": 2, "c": "#3d434a"}, {"id": 433, "x": 10, "y": -12, "z": 3, "c": "#3d434a"}, {"id": 434, "x": 10, "y": -12, "z": 4, "c": "#3d434a"}, {"id": 435, "x": 10, "y": -12, "z": 5, "c": "#3d434a"}, {"id": 436, "x": 10, "y": -12, "z": 6, "c": "#3d434a"}, {"id": 437, "x": 10, "y": -12, "z": 7, "c": "#3d434a"}, {"id": 438, "x": 10, "y": -12, "z": 8, "c": "#3d434a"}, {"id": 439, "x": 10, "y": -12, "z": 9, "c": "#3d434a"}, {"id": 440, "x": 10, "y": -12, "z": 10, "c": "#3d434a"}, {"id": 441, "x": -3, "y": -11, "z": 8, "c": "#5a4231"}, {"id": 442, "x": -3, "y": -11, "z": 9, "c": "#d4cec3"}, {"id": 443, "x": -3, "y": -11, "z": 10, "c": "#d4cec3"}, {"id": 444, "x": -2, "y": -11, "z": 8, "c": "#8fa3ad"}, {"id": 445, "x": -2, "y": -11, "z": 9, "c": "#d4cec3"}, {"id": 446, "x": -2, "y": -11, "z": 10, "c": "#d4cec3"}, {"id": 447, "x": -1, "y": -11, "z": 8, "c": "#8fa3ad"}, {"id": 448, "x": -1, "y": -11, "z": 9, "c": "#d4cec3"}, {"id": 449, "x": -1, "y": -11, "z": 10, "c": "#d4cec3"}, {"id": 450, "x": 0, "y": -11, "z": 8, "c": "#8fa3ad"}, {"id": 451, "x": 0, "y": -11, "z": 9, "c": "#d4cec3"}, {"id": 452, "x": 0, "y": -11, "z": 10, "c": "#d4cec3"}, {"id": 453, "x": 1, "y": -11, "z": 8, "c": "#8fa3ad"}, {"id": 454, "x": 1, "y": -11, "z": 9, "c": "#d4cec3"}, {"id": 455, "x": 1, "y": -11, "z": 10, "c": "#d4cec3"}, {"id": 456, "x": 2, "y": -11, "z": 8, "c": "#8fa3ad"}, {"id": 457, "x": 2, "y": -11, "z": 9, "c": "#d4cec3"}, {"id": 458, "x": 2, "y": -11, "z": 10, "c": "#d4cec3"}, {"id": 459, "x": 3, "y": -11, "z": 8, "c": "#5a4231"}, {"id": 460, "x": 3, "y": -11, "z": 9, "c": "#d4cec3"}, {"id": 461, "x": 3, "y": -11, "z": 10, "c": "#d4cec3"}, {"id": 462, "x": -3, "y": -10, "z": 9, "c": "#d4cec3"}, {"id": 463, "x": -3, "y": -10, "z": 10, "c": "#d4cec3"}, {"id": 464, "x": -2, "y": -10, "z": 9, "c": "#d4cec3"}, {"id": 465, "x": -2, "y": -10, "z": 10, "c": "#d4cec3"}, {"id": 466, "x": -1, "y": -10, "z": 9, "c": "#d4cec3"}, {"id": 467, "x": -1, "y": -10, "z": 10, "c": "#d4cec3"}, {"id": 468, "x": 0, "y": -10, "z": 9, "c": "#d4cec3"}, {"id": 469, "x": 0, "y": -10, "z": 10, "c": "#d4cec3"}, {"id": 470, "x": 1, "y": -10, "z": 9, "c": "#d4cec3"}, {"id": 471, "x": 1, "y": -10, "z": 10, "c": "#d4cec3"}, {"id": 472, "x": 2, "y": -10, "z": 9, "c": "#d4cec3"}, {"id": 473, "x": 2, "y": -10, "z": 10, "c": "#d4cec3"}, {"id": 474, "x": 3, "y": -10, "z": 9, "c": "#d4cec3"}, {"id": 475, "x": 3, "y": -10, "z": 10, "c": "#d4cec3"}, {"id": 476, "x": -3, "y": -9, "z": 10, "c": "#d4cec3"}, {"id": 477, "x": -2, "y": -9, "z": 10, "c": "#d4cec3"}, {"id": 478, "x": -1, "y": -9, "z": 10, "c": "#d4cec3"}, {"id": 479, "x": 0, "y": -9, "z": 10, "c": "#d4cec3"}, {"id": 480, "x": 1, "y": -9, "z": 10, "c": "#d4cec3"}, {"id": 481, "x": 2, "y": -9, "z": 10, "c": "#d4cec3"}, {"id": 482, "x": 3, "y": -9, "z": 10, "c": "#d4cec3"}, {"id": 483, "x": -6, "y": -11, "z": 8, "c": "#5a4231"}, {"id": 484, "x": -6, "y": -10, "z": 8, "c": "#674f3c"}, {"id": 485, "x": -6, "y": -11, "z": 9, "c": "#6f7378"}, {"id": 486, "x": -6, "y": -10, "z": 9, "c": "#586a4b"}, {"id": 487, "x": 6, "y": -11, "z": 8, "c": "#5a4231"}, {"id": 488, "x": 6, "y": -10, "z": 8, "c": "#674f3c"}, {"id": 489, "x": 6, "y": -11, "z": 9, "c": "#6f7378"}, {"id": 490, "x": 6, "y": -10, "z": 9, "c": "#586a4b"}, {"id": 491, "x": -8, "y": -11, "z": -8, "c": "#5a4231"}, {"id": 492, "x": -8, "y": -11, "z": -7, "c": "#5a4231"}, {"id": 493, "x": -8, "y": -11, "z": -6, "c": "#5a4231"}, {"id": 494, "x": -8, "y": -11, "z": -5, "c": "#5a4231"}, {"id": 495, "x": -8, "y": -11, "z": -4, "c": "#5a4231"}, {"id": 496, "x": -8, "y": -11, "z": -3, "c": "#5a4231"}, {"id": 497, "x": -8, "y": -11, "z": -2, "c": "#5a4231"}, {"id": 498, "x": -8, "y": -11, "z": -1, "c": "#5a4231"}, {"id": 499, "x": -8, "y": -11, "z": 0, "c": "#5a4231"}, {"id": 500, "x": -8, "y": -11, "z": 1, "c": "#5a4231"}, {"id": 501, "x": -8, "y": -11, "z": 2, "c": "#5a4231"}, {"id": 502, "x": -8, "y": -11, "z": 3, "c": "#5a4231"}, {"id": 503, "x": -8, "y": -11, "z": 4, "c": "#5a4231"}, {"id": 504, "x": -8, "y": -11, "z": 5, "c": "#5a4231"}, {"id": 505, "x": -8, "y": -11, "z": 6, "c": "#5a4231"}, {"id": 506, "x": -8, "y": -11, "z": 7, "c": "#5a4231"}, {"id": 507, "x": -8, "y": -11, "z": 8, "c": "#5a4231"}, {"id": 508, "x": -7, "y": -11, "z": -8, "c": "#5a4231"}, {"id": 509, "x": -7, "y": -11, "z": 8, "c": "#5a4231"}, {"id": 510, "x": -6, "y": -11, "z": -8, "c": "#5a4231"}, {"id": 511, "x": -5, "y": -11, "z": -8, "c": "#5a4231"}, {"id": 512, "x": -5, "y": -11, "z": 8, "c": "#5a4231"}, {"id": 513, "x": -4, "y": -11, "z": -8, "c": "#5a4231"}, {"id": 514, "x": -4, "y": -11, "z": 8, "c": "#5a4231"}, {"id": 515, "x": -3, "y": -11, "z": -8, "c": "#5a4231"}, {"id": 516, "x": -2, "y": -11, "z": -8, "c": "#5a4231"}, {"id": 517, "x": -1, "y": -11, "z": -8, "c": "#5a4231"}, {"id": 518, "x": 0, "y": -11, "z": -8, "c": "#5a4231"}, {"id": 519, "x": 1, "y": -11, "z": -8, "c": "#5a4231"}, {"id": 520, "x": 2, "y": -11, "z": -8, "c": "#5a4231"}, {"id": 521, "x": 3, "y": -11, "z": -8, "c": "#5a4231"}, {"id": 522, "x": 4, "y": -11, "z": -8, "c": "#5a4231"}, {"id": 523, "x": 4, "y": -11, "z": 8, "c": "#5a4231"}, {"id": 524, "x": 5, "y": -11, "z": -8, "c": "#5a4231"}, {"id": 525, "x": 5, "y": -11, "z": 8, "c": "#5a4231"}, {"id": 526, "x": 6, "y": -11, "z": -8, "c": "#5a4231"}, {"id": 527, "x": 7, "y": -11, "z": -8, "c": "#5a4231"}, {"id": 528, "x": 7, "y": -11, "z": 8, "c": "#5a4231"}, {"id": 529, "x": 8, "y": -11, "z": -8, "c": "#5a4231"}, {"id": 530, "x": 8, "y": -11, "z": -7, "c": "#5a4231"}, {"id": 531, "x": 8, "y": -11, "z": -6, "c": "#5a4231"}, {"id": 532, "x": 8, "y": -11, "z": -5, "c": "#5a4231"}, {"id": 533, "x": 8, "y": -11, "z": -4, "c": "#5a4231"}, {"id": 534, "x": 8, "y": -11, "z": -3, "c": "#5a4231"}, {"id": 535, "x": 8, "y": -11, "z": -2, "c": "#5a4231"}, {"id": 536, "x": 8, "y": -11, "z": -1, "c": "#5a4231"}, {"id": 537, "x": 8, "y": -11, "z": 0, "c": "#5a4231"}, {"id": 538, "x": 8, "y": -11, "z": 1, "c": "#5a4231"}, {"id": 539, "x": 8, "y": -11, "z": 2, "c": "#5a4231"}, {"id": 540, "x": 8, "y": -11, "z": 3, "c": "#5a4231"}, {"id": 541, "x": 8, "y": -11, "z": 4, "c": "#5a4231"}, {"id": 542, "x": 8, "y": -11, "z": 5, "c": "#5a4231"}, {"id": 543, "x": 8, "y": -11, "z": 6, "c": "#5a4231"}, {"id": 544, "x": 8, "y": -11, "z": 7, "c": "#5a4231"}, {"id": 545, "x": 8, "y": -11, "z": 8, "c": "#5a4231"}, {"id": 546, "x": -8, "y": -10, "z": -8, "c": "#8fa3ad"}, {"id": 547, "x": -8, "y": -10, "z": -7, "c": "#674f3c"}, {"id": 548, "x": -8, "y": -10, "z": -6, "c": "#674f3c"}, {"id": 549, "x": -8, "y": -10, "z": -5, "c": "#674f3c"}, {"id": 550, "x": -8, "y": -10, "z": -4, "c": "#8fa3ad"}, {"id": 551, "x": -8, "y": -10, "z": -3, "c": "#674f3c"}, {"id": 552, "x": -8, "y": -10, "z": -2, "c": "#674f3c"}, {"id": 553, "x": -8, "y": -10, "z": -1, "c": "#674f3c"}, {"id": 554, "x": -8, "y": -10, "z": 0, "c": "#8fa3ad"}, {"id": 555, "x": -8, "y": -10, "z": 1, "c": "#674f3c"}, {"id": 556, "x": -8, "y": -10, "z": 2, "c": "#674f3c"}, {"id": 557, "x": -8, "y": -10, "z": 3, "c": "#674f3c"}, {"id": 558, "x": -8, "y": -10, "z": 4, "c": "#8fa3ad"}, {"id": 559, "x": -8, "y": -10, "z": 5, "c": "#674f3c"}, {"id": 560, "x": -8, "y": -10, "z": 6, "c": "#674f3c"}, {"id": 561, "x": -8, "y": -10, "z": 7, "c": "#674f3c"}, {"id": 562, "x": -8, "y": -10, "z": 8, "c": "#8fa3ad"}, {"id": 563, "x": -7, "y": -10, "z": -8, "c": "#674f3c"}, {"id": 564, "x": -7, "y": -10, "z": 8, "c": "#674f3c"}, {"id": 565, "x": -6, "y": -10, "z": -8, "c": "#674f3c"}, {"id": 566, "x": -5, "y": -10, "z": -8, "c": "#674f3c"}, {"id": 567, "x": -5, "y": -10, "z": 8, "c": "#674f3c"}, {"id": 568, "x": -4, "y": -10, "z": -8, "c": "#8fa3ad"}, {"id": 569, "x": -4, "y": -10, "z": 8, "c": "#8fa3ad"}, {"id": 570, "x": -3, "y": -10, "z": -8, "c": "#674f3c"}, {"id": 571, "x": -3, "y": -10, "z": 8, "c": "#674f3c"}, {"id": 572, "x": -2, "y": -10, "z": -8, "c": "#674f3c"}, {"id": 573, "x": -2, "y": -10, "z": 8, "c": "#8fa3ad"}, {"id": 574, "x": -1, "y": -10, "z": -8, "c": "#674f3c"}, {"id": 575, "x": -1, "y": -10, "z": 8, "c": "#8fa3ad"}, {"id": 576, "x": 0, "y": -10, "z": -8, "c": "#8fa3ad"}, {"id": 577, "x": 0, "y": -10, "z": 8, "c": "#8fa3ad"}, {"id": 578, "x": 1, "y": -10, "z": -8, "c": "#674f3c"}, {"id": 579, "x": 1, "y": -10, "z": 8, "c": "#8fa3ad"}, {"id": 580, "x": 2, "y": -10, "z": -8, "c": "#674f3c"}, {"id": 581, "x": 2, "y": -10, "z": 8, "c": "#8fa3ad"}, {"id": 582, "x": 3, "y": -10, "z": -8, "c": "#674f3c"}, {"id": 583, "x": 3, "y": -10, "z": 8, "c": "#674f3c"}, {"id": 584, "x": 4, "y": -10, "z": -8, "c": "#8fa3ad"}, {"id": 585, "x": 4, "y": -10, "z": 8, "c": "#8fa3ad"}, {"id": 586, "x": 5, "y": -10, "z": -8, "c": "#674f3c"}, {"id": 587, "x": 5, "y": -10, "z": 8, "c": "#674f3c"}, {"id": 588, "x": 6, "y": -10, "z": -8, "c": "#674f3c"}, {"id": 589, "x": 7, "y": -10, "z": -8, "c": "#674f3c"}, {"id": 590, "x": 7, "y": -10, "z": 8, "c": "#674f3c"}, {"id": 591, "x": 8, "y": -10, "z": -8, "c": "#8fa3ad"}, {"id": 592, "x": 8, "y": -10, "z": -7, "c": "#674f3c"}, {"id": 593, "x": 8, "y": -10, "z": -6, "c": "#674f3c"}, {"id": 594, "x": 8, "y": -10, "z": -5, "c": "#674f3c"}, {"id": 595, "x": 8, "y": -10, "z": -4, "c": "#8fa3ad"}, {"id": 596, "x": 8, "y": -10, "z": -3, "c": "#674f3c"}, {"id": 597, "x": 8, "y": -10, "z": -2, "c": "#674f3c"}, {"id": 598, "x": 8, "y": -10, "z": -1, "c": "#674f3c"}, {"id": 599, "x": 8, "y": -10, "z": 0, "c": "#8fa3ad"}, {"id": 600, "x": 8, "y": -10, "z": 1, "c": "#674f3c"}, {"id": 601, "x": 8, "y": -10, "z": 2, "c": "#674f3c"}, {"id": 602, "x": 8, "y": -10, "z": 3, "c": "#674f3c"}, {"id": 603, "x": 8, "y": -10, "z": 4, "c": "#8fa3ad"}, {"id": 604, "x": 8, "y": -10, "z": 5, "c": "#674f3c"}, {"id": 605, "x": 8, "y": -10, "z": 6, "c": "#674f3c"}, {"id": 606, "x": 8, "y": -10, "z": 7, "c": "#674f3c"}, {"id": 607, "x": 8, "y": -10, "z": 8, "c": "#8fa3ad"}, {"id": 608, "x": -8, "y": -9, "z": -8, "c": "#8fa3ad"}, {"id": 609, "x": -8, "y": -9, "z": -7, "c": "#674f3c"}, {"id": 610, "x": -8, "y": -9, "z": -6, "c": "#8fa3ad"}, {"id": 611, "x": -8, "y": -9, "z": -5, "c": "#674f3c"}, {"id": 612, "x": -8, "y": -9, "z": -4, "c": "#8fa3ad"}, {"id": 613, "x": -8, "y": -9, "z": -3, "c": "#8fa3ad"}, {"id": 614, "x": -8, "y": -9, "z": -2, "c": "#674f3c"}, {"id": 615, "x": -8, "y": -9, "z": -1, "c": "#674f3c"}, {"id": 616, "x": -8, "y": -9, "z": 0, "c": "#8fa3ad"}, {"id": 617, "x": -8, "y": -9, "z": 1, "c": "#674f3c"}, {"id": 618, "x": -8, "y": -9, "z": 2, "c": "#674f3c"}, {"id": 619, "x": -8, "y": -9, "z": 3, "c": "#8fa3ad"}, {"id": 620, "x": -8, "y": -9, "z": 4, "c": "#8fa3ad"}, {"id": 621, "x": -8, "y": -9, "z": 5, "c": "#674f3c"}, {"id": 622, "x": -8, "y": -9, "z": 6, "c": "#8fa3ad"}, {"id": 623, "x": -8, "y": -9, "z": 7, "c": "#674f3c"}, {"id": 624, "x": -8, "y": -9, "z": 8, "c": "#8fa3ad"}, {"id": 625, "x": -7, "y": -9, "z": -8, "c": "#674f3c"}, {"id": 626, "x": -7, "y": -9, "z": 8, "c": "#674f3c"}, {"id": 627, "x": -6, "y": -9, "z": -8, "c": "#8fa3ad"}, {"id": 628, "x": -6, "y": -9, "z": 8, "c": "#8fa3ad"}, {"id": 629, "x": -5, "y": -9, "z": -8, "c": "#674f3c"}, {"id": 630, "x": -5, "y": -9, "z": 8, "c": "#674f3c"}, {"id": 631, "x": -4, "y": -9, "z": -8, "c": "#8fa3ad"}, {"id": 632, "x": -4, "y": -9, "z": 8, "c": "#8fa3ad"}, {"id": 633, "x": -3, "y": -9, "z": -8, "c": "#8fa3ad"}, {"id": 634, "x": -3, "y": -9, "z": 8, "c": "#8fa3ad"}, {"id": 635, "x": -2, "y": -9, "z": -8, "c": "#674f3c"}, {"id": 636, "x": -2, "y": -9, "z": 8, "c": "#8fa3ad"}, {"id": 637, "x": -1, "y": -9, "z": -8, "c": "#674f3c"}, {"id": 638, "x": -1, "y": -9, "z": 8, "c": "#8fa3ad"}, {"id": 639, "x": 0, "y": -9, "z": -8, "c": "#8fa3ad"}, {"id": 640, "x": 0, "y": -9, "z": 8, "c": "#8fa3ad"}, {"id": 641, "x": 1, "y": -9, "z": -8, "c": "#674f3c"}, {"id": 642, "x": 1, "y": -9, "z": 8, "c": "#8fa3ad"}, {"id": 643, "x": 2, "y": -9, "z": -8, "c": "#674f3c"}, {"id": 644, "x": 2, "y": -9, "z": 8, "c": "#8fa3ad"}, {"id": 645, "x": 3, "y": -9, "z": -8, "c": "#8fa3ad"}, {"id": 646, "x": 3, "y": -9, "z": 8, "c": "#8fa3ad"}, {"id": 647, "x": 4, "y": -9, "z": -8, "c": "#8fa3ad"}, {"id": 648, "x": 4, "y": -9, "z": 8, "c": "#8fa3ad"}, {"id": 649, "x": 5, "y": -9, "z": -8, "c": "#674f3c"}, {"id": 650, "x": 5, "y": -9, "z": 8, "c": "#674f3c"}, {"id": 651, "x": 6, "y": -9, "z": -8, "c": "#8fa3ad"}, {"id": 652, "x": 6, "y": -9, "z": 8, "c": "#8fa3ad"}, {"id": 653, "x": 7, "y": -9, "z": -8, "c": "#674f3c"}, {"id": 654, "x": 7, "y": -9, "z": 8, "c": "#674f3c"}, {"id": 655, "x": 8, "y": -9, "z": -8, "c": "#8fa3ad"}, {"id": 656, "x": 8, "y": -9, "z": -7, "c": "#674f3c"}, {"id": 657, "x": 8, "y": -9, "z": -6, "c": "#8fa3ad"}, {"id": 658, "x": 8, "y": -9, "z": -5, "c": "#674f3c"}, {"id": 659, "x": 8, "y": -9, "z": -4, "c": "#8fa3ad"}, {"id": 660, "x": 8, "y": -9, "z": -3, "c": "#8fa3ad"}, {"id": 661, "x": 8, "y": -9, "z": -2, "c": "#674f3c"}, {"id": 662, "x": 8, "y": -9, "z": -1, "c": "#674f3c"}, {"id": 663, "x": 8, "y": -9, "z": 0, "c": "#8fa3ad"}, {"id": 664, "x": 8, "y": -9, "z": 1, "c": "#674f3c"}, {"id": 665, "x": 8, "y": -9, "z": 2, "c": "#674f3c"}, {"id": 666, "x": 8, "y": -9, "z": 3, "c": "#8fa3ad"}, {"id": 667, "x": 8, "y": -9, "z": 4, "c": "#8fa3ad"}, {"id": 668, "x": 8, "y": -9, "z": 5, "c": "#674f3c"}, {"id": 669, "x": 8, "y": -9, "z": 6, "c": "#8fa3ad"}, {"id": 670, "x": 8, "y": -9, "z": 7, "c": "#674f3c"}, {"id": 671, "x": 8, "y": -9, "z": 8, "c": "#8fa3ad"}, {"id": 672, "x": -8, "y": -8, "z": -8, "c": "#8fa3ad"}, {"id": 673, "x": -8, "y": -8, "z": -7, "c": "#674f3c"}, {"id": 674, "x": -8, "y": -8, "z": -6, "c": "#8fa3ad"}, {"id": 675, "x": -8, "y": -8, "z": -5, "c": "#674f3c"}, {"id": 676, "x": -8, "y": -8, "z": -4, "c": "#8fa3ad"}, {"id": 677, "x": -8, "y": -8, "z": -3, "c": "#8fa3ad"}, {"id": 678, "x": -8, "y": -8, "z": -2, "c": "#674f3c"}, {"id": 679, "x": -8, "y": -8, "z": -1, "c": "#674f3c"}, {"id": 680, "x": -8, "y": -8, "z": 0, "c": "#8fa3ad"}, {"id": 681, "x": -8, "y": -8, "z": 1, "c": "#674f3c"}, {"id": 682, "x": -8, "y": -8, "z": 2, "c": "#674f3c"}, {"id": 683, "x": -8, "y": -8, "z": 3, "c": "#8fa3ad"}, {"id": 684, "x": -8, "y": -8, "z": 4, "c": "#8fa3ad"}, {"id": 685, "x": -8, "y": -8, "z": 5, "c": "#674f3c"}, {"id": 686, "x": -8, "y": -8, "z": 6, "c": "#8fa3ad"}, {"id": 687, "x": -8, "y": -8, "z": 7, "c": "#674f3c"}, {"id": 688, "x": -8, "y": -8, "z": 8, "c": "#8fa3ad"}, {"id": 689, "x": -7, "y": -8, "z": -8, "c": "#674f3c"}, {"id": 690, "x": -7, "y": -8, "z": 8, "c": "#674f3c"}, {"id": 691, "x": -6, "y": -8, "z": -8, "c": "#8fa3ad"}, {"id": 692, "x": -6, "y": -8, "z": 8, "c": "#8fa3ad"}, {"id": 693, "x": -5, "y": -8, "z": -8, "c": "#674f3c"}, {"id": 694, "x": -5, "y": -8, "z": 8, "c": "#674f3c"}, {"id": 695, "x": -4, "y": -8, "z": -8, "c": "#8fa3ad"}, {"id": 696, "x": -4, "y": -8, "z": 8, "c": "#8fa3ad"}, {"id": 697, "x": -3, "y": -8, "z": -8, "c": "#8fa3ad"}, {"id": 698, "x": -3, "y": -8, "z": 8, "c": "#8fa3ad"}, {"id": 699, "x": -2, "y": -8, "z": -8, "c": "#674f3c"}, {"id": 700, "x": -2, "y": -8, "z": 8, "c": "#8fa3ad"}, {"id": 701, "x": -1, "y": -8, "z": -8, "c": "#674f3c"}, {"id": 702, "x": -1, "y": -8, "z": 8, "c": "#8fa3ad"}, {"id": 703, "x": 0, "y": -8, "z": -8, "c": "#8fa3ad"}, {"id": 704, "x": 0, "y": -8, "z": 8, "c": "#8fa3ad"}, {"id": 705, "x": 1, "y": -8, "z": -8, "c": "#674f3c"}, {"id": 706, "x": 1, "y": -8, "z": 8, "c": "#8fa3ad"}, {"id": 707, "x": 2, "y": -8, "z": -8, "c": "#674f3c"}, {"id": 708, "x": 2, "y": -8, "z": 8, "c": "#8fa3ad"}, {"id": 709, "x": 3, "y": -8, "z": -8, "c": "#8fa3ad"}, {"id": 710, "x": 3, "y": -8, "z": 8, "c": "#8fa3ad"}, {"id": 711, "x": 4, "y": -8, "z": -8, "c": "#8fa3ad"}, {"id": 712, "x": 4, "y": -8, "z": 8, "c": "#8fa3ad"}, {"id": 713, "x": 5, "y": -8, "z": -8, "c": "#674f3c"}, {"id": 714, "x": 5, "y": -8, "z": 8, "c": "#674f3c"}, {"id": 715, "x": 6, "y": -8, "z": -8, "c": "#8fa3ad"}, {"id": 716, "x": 6, "y": -8, "z": 8, "c": "#8fa3ad"}, {"id": 717, "x": 7, "y": -8, "z": -8, "c": "#674f3c"}, {"id": 718, "x": 7, "y": -8, "z": 8, "c": "#674f3c"}, {"id": 719, "x": 8, "y": -8, "z": -8, "c": "#8fa3ad"}, {"id": 720, "x": 8, "y": -8, "z": -7, "c": "#674f3c"}, {"id": 721, "x": 8, "y": -8, "z": -6, "c": "#8fa3ad"}, {"id": 722, "x": 8, "y": -8, "z": -5, "c": "#674f3c"}, {"id": 723, "x": 8, "y": -8, "z": -4, "c": "#8fa3ad"}, {"id": 724, "x": 8, "y": -8, "z": -3, "c": "#8fa3ad"}, {"id": 725, "x": 8, "y": -8, "z": -2, "c": "#674f3c"}, {"id": 726, "x": 8, "y": -8, "z": -1, "c": "#674f3c"}, {"id": 727, "x": 8, "y": -8, "z": 0, "c": "#8fa3ad"}, {"id": 728, "x": 8, "y": -8, "z": 1, "c": "#674f3c"}, {"id": 729, "x": 8, "y": -8, "z": 2, "c": "#674f3c"}, {"id": 730, "x": 8, "y": -8, "z": 3, "c": "#8fa3ad"}, {"id": 731, "x": 8, "y": -8, "z": 4, "c": "#8fa3ad"}, {"id": 732, "x": 8, "y": -8, "z": 5, "c": "#674f3c"}, {"id": 733, "x": 8, "y": -8, "z": 6, "c": "#8fa3ad"}, {"id": 734, "x": 8, "y": -8, "z": 7, "c": "#674f3c"}, {"id": 735, "x": 8, "y": -8, "z": 8, "c": "#8fa3ad"}, {"id": 736, "x": -8, "y": -7, "z": -8, "c": "#8fa3ad"}, {"id": 737, "x": -8, "y": -7, "z": -7, "c": "#674f3c"}, {"id": 738, "x": -8, "y": -7, "z": -6, "c": "#8fa3ad"}, {"id": 739, "x": -8, "y": -7, "z": -5, "c": "#674f3c"}, {"id": 740, "x": -8, "y": -7, "z": -4, "c": "#8fa3ad"}, {"id": 741, "x": -8, "y": -7, "z": -3, "c": "#8fa3ad"}, {"id": 742, "x": -8, "y": -7, "z": -2, "c": "#674f3c"}, {"id": 743, "x": -8, "y": -7, "z": -1, "c": "#674f3c"}, {"id": 744, "x": -8, "y": -7, "z": 0, "c": "#8fa3ad"}, {"id": 745, "x": -8, "y": -7, "z": 1, "c": "#674f3c"}, {"id": 746, "x": -8, "y": -7, "z": 2, "c": "#674f3c"}, {"id": 747, "x": -8, "y": -7, "z": 3, "c": "#8fa3ad"}, {"id": 748, "x": -8, "y": -7, "z": 4, "c": "#8fa3ad"}, {"id": 749, "x": -8, "y": -7, "z": 5, "c": "#674f3c"}, {"id": 750, "x": -8, "y": -7, "z": 6, "c": "#8fa3ad"}, {"id": 751, "x": -8, "y": -7, "z": 7, "c": "#674f3c"}, {"id": 752, "x": -8, "y": -7, "z": 8, "c": "#8fa3ad"}, {"id": 753, "x": -7, "y": -7, "z": -8, "c": "#674f3c"}, {"id": 754, "x": -7, "y": -7, "z": 8, "c": "#674f3c"}, {"id": 755, "x": -6, "y": -7, "z": -8, "c": "#8fa3ad"}, {"id": 756, "x": -6, "y": -7, "z": 8, "c": "#8fa3ad"}, {"id": 757, "x": -5, "y": -7, "z": -8, "c": "#674f3c"}, {"id": 758, "x": -5, "y": -7, "z": 8, "c": "#674f3c"}, {"id": 759, "x": -4, "y": -7, "z": -8, "c": "#8fa3ad"}, {"id": 760, "x": -4, "y": -7, "z": 8, "c": "#8fa3ad"}, {"id": 761, "x": -3, "y": -7, "z": -8, "c": "#8fa3ad"}, {"id": 762, "x": -3, "y": -7, "z": 8, "c": "#8fa3ad"}, {"id": 763, "x": -2, "y": -7, "z": -8, "c": "#674f3c"}, {"id": 764, "x": -2, "y": -7, "z": 8, "c": "#674f3c"}, {"id": 765, "x": -1, "y": -7, "z": -8, "c": "#674f3c"}, {"id": 766, "x": -1, "y": -7, "z": 8, "c": "#674f3c"}, {"id": 767, "x": 0, "y": -7, "z": -8, "c": "#8fa3ad"}, {"id": 768, "x": 0, "y": -7, "z": 8, "c": "#8fa3ad"}, {"id": 769, "x": 1, "y": -7, "z": -8, "c": "#674f3c"}, {"id": 770, "x": 1, "y": -7, "z": 8, "c": "#674f3c"}, {"id": 771, "x": 2, "y": -7, "z": -8, "c": "#674f3c"}, {"id": 772, "x": 2, "y": -7, "z": 8, "c": "#674f3c"}, {"id": 773, "x": 3, "y": -7, "z": -8, "c": "#8fa3ad"}, {"id": 774, "x": 3, "y": -7, "z": 8, "c": "#8fa3ad"}, {"id": 775, "x": 4, "y": -7, "z": -8, "c": "#8fa3ad"}, {"id": 776, "x": 4, "y": -7, "z": 8, "c": "#8fa3ad"}, {"id": 777, "x": 5, "y": -7, "z": -8, "c": "#674f3c"}, {"id": 778, "x": 5, "y": -7, "z": 8, "c": "#674f3c"}, {"id": 779, "x": 6, "y": -7, "z": -8, "c": "#8fa3ad"}, {"id": 780, "x": 6, "y": -7, "z": 8, "c": "#8fa3ad"}, {"id": 781, "x": 7, "y": -7, "z": -8, "c": "#674f3c"}, {"id": 782, "x": 7, "y": -7, "z": 8, "c": "#674f3c"}, {"id": 783, "x": 8, "y": -7, "z": -8, "c": "#8fa3ad"}, {"id": 784, "x": 8, "y": -7, "z": -7, "c": "#674f3c"}, {"id": 785, "x": 8, "y": -7, "z": -6, "c": "#8fa3ad"}, {"id": 786, "x": 8, "y": -7, "z": -5, "c": "#674f3c"}, {"id": 787, "x": 8, "y": -7, "z": -4, "c": "#8fa3ad"}, {"id": 788, "x": 8, "y": -7, "z": -3, "c": "#8fa3ad"}, {"id": 789, "x": 8, "y": -7, "z": -2, "c": "#674f3c"}, {"id": 790, "x": 8, "y": -7, "z": -1, "c": "#674f3c"}, {"id": 791, "x": 8, "y": -7, "z": 0, "c": "#8fa3ad"}, {"id": 792, "x": 8, "y": -7, "z": 1, "c": "#674f3c"}, {"id": 793, "x": 8, "y": -7, "z": 2, "c": "#674f3c"}, {"id": 794, "x": 8, "y": -7, "z": 3, "c": "#8fa3ad"}, {"id": 795, "x": 8, "y": -7, "z": 4, "c": "#8fa3ad"}, {"id": 796, "x": 8, "y": -7, "z": 5, "c": "#674f3c"}, {"id": 797, "x": 8, "y": -7, "z": 6, "c": "#8fa3ad"}, {"id": 798, "x": 8, "y": -7, "z": 7, "c": "#674f3c"}, {"id": 799, "x": 8, "y": -7, "z": 8, "c": "#8fa3ad"}, {"id": 800, "x": -8, "y": -6, "z": -8, "c": "#8fa3ad"}, {"id": 801, "x": -8, "y": -6, "z": -7, "c": "#674f3c"}, {"id": 802, "x": -8, "y": -6, "z": -6, "c": "#8fa3ad"}, {"id": 803, "x": -8, "y": -6, "z": -5, "c": "#674f3c"}, {"id": 804, "x": -8, "y": -6, "z": -4, "c": "#8fa3ad"}, {"id": 805, "x": -8, "y": -6, "z": -3, "c": "#8fa3ad"}, {"id": 806, "x": -8, "y": -6, "z": -2, "c": "#674f3c"}, {"id": 807, "x": -8, "y": -6, "z": -1, "c": "#674f3c"}, {"id": 808, "x": -8, "y": -6, "z": 0, "c": "#8fa3ad"}, {"id": 809, "x": -8, "y": -6, "z": 1, "c": "#674f3c"}, {"id": 810, "x": -8, "y": -6, "z": 2, "c": "#674f3c"}, {"id": 811, "x": -8, "y": -6, "z": 3, "c": "#8fa3ad"}, {"id": 812, "x": -8, "y": -6, "z": 4, "c": "#8fa3ad"}, {"id": 813, "x": -8, "y": -6, "z": 5, "c": "#674f3c"}, {"id": 814, "x": -8, "y": -6, "z": 6, "c": "#8fa3ad"}, {"id": 815, "x": -8, "y": -6, "z": 7, "c": "#674f3c"}, {"id": 816, "x": -8, "y": -6, "z": 8, "c": "#8fa3ad"}, {"id": 817, "x": -7, "y": -6, "z": -8, "c": "#674f3c"}, {"id": 818, "x": -7, "y": -6, "z": 8, "c": "#674f3c"}, {"id": 819, "x": -6, "y": -6, "z": -8, "c": "#8fa3ad"}, {"id": 820, "x": -6, "y": -6, "z": 8, "c": "#8fa3ad"}, {"id": 821, "x": -5, "y": -6, "z": -8, "c": "#674f3c"}, {"id": 822, "x": -5, "y": -6, "z": 8, "c": "#674f3c"}, {"id": 823, "x": -4, "y": -6, "z": -8, "c": "#8fa3ad"}, {"id": 824, "x": -4, "y": -6, "z": 8, "c": "#8fa3ad"}, {"id": 825, "x": -3, "y": -6, "z": -8, "c": "#8fa3ad"}, {"id": 826, "x": -3, "y": -6, "z": 8, "c": "#8fa3ad"}, {"id": 827, "x": -2, "y": -6, "z": -8, "c": "#674f3c"}, {"id": 828, "x": -2, "y": -6, "z": 8, "c": "#674f3c"}, {"id": 829, "x": -1, "y": -6, "z": -8, "c": "#674f3c"}, {"id": 830, "x": -1, "y": -6, "z": 8, "c": "#674f3c"}, {"id": 831, "x": 0, "y": -6, "z": -8, "c": "#8fa3ad"}, {"id": 832, "x": 0, "y": -6, "z": 8, "c": "#8fa3ad"}, {"id": 833, "x": 1, "y": -6, "z": -8, "c": "#674f3c"}, {"id": 834, "x": 1, "y": -6, "z": 8, "c": "#674f3c"}, {"id": 835, "x": 2, "y": -6, "z": -8, "c": "#674f3c"}, {"id": 836, "x": 2, "y": -6, "z": 8, "c": "#674f3c"}, {"id": 837, "x": 3, "y": -6, "z": -8, "c": "#8fa3ad"}, {"id": 838, "x": 3, "y": -6, "z": 8, "c": "#8fa3ad"}, {"id": 839, "x": 4, "y": -6, "z": -8, "c": "#8fa3ad"}, {"id": 840, "x": 4, "y": -6, "z": 8, "c": "#8fa3ad"}, {"id": 841, "x": 5, "y": -6, "z": -8, "c": "#674f3c"}, {"id": 842, "x": 5, "y": -6, "z": 8, "c": "#674f3c"}, {"id": 843, "x": 6, "y": -6, "z": -8, "c": "#8fa3ad"}, {"id": 844, "x": 6, "y": -6, "z": 8, "c": "#8fa3ad"}, {"id": 845, "x": 7, "y": -6, "z": -8, "c": "#674f3c"}, {"id": 846, "x": 7, "y": -6, "z": 8, "c": "#674f3c"}, {"id": 847, "x": 8, "y": -6, "z": -8, "c": "#8fa3ad"}, {"id": 848, "x": 8, "y": -6, "z": -7, "c": "#674f3c"}, {"id": 849, "x": 8, "y": -6, "z": -6, "c": "#8fa3ad"}, {"id": 850, "x": 8, "y": -6, "z": -5, "c": "#674f3c"}, {"id": 851, "x": 8, "y": -6, "z": -4, "c": "#8fa3ad"}, {"id": 852, "x": 8, "y": -6, "z": -3, "c": "#8fa3ad"}, {"id": 853, "x": 8, "y": -6, "z": -2, "c": "#674f3c"}, {"id": 854, "x": 8, "y": -6, "z": -1, "c": "#674f3c"}, {"id": 855, "x": 8, "y": -6, "z": 0, "c": "#8fa3ad"}, {"id": 856, "x": 8, "y": -6, "z": 1, "c": "#674f3c"}, {"id": 857, "x": 8, "y": -6, "z": 2, "c": "#674f3c"}, {"id": 858, "x": 8, "y": -6, "z": 3, "c": "#8fa3ad"}, {"id": 859, "x": 8, "y": -6, "z": 4, "c": "#8fa3ad"}, {"id": 860, "x": 8, "y": -6, "z": 5, "c": "#674f3c"}, {"id": 861, "x": 8, "y": -6, "z": 6, "c": "#8fa3ad"}, {"id": 862, "x": 8, "y": -6, "z": 7, "c": "#674f3c"}, {"id": 863, "x": 8, "y": -6, "z": 8, "c": "#8fa3ad"}, {"id": 864, "x": -8, "y": -5, "z": -8, "c": "#8fa3ad"}, {"id": 865, "x": -8, "y": -5, "z": -7, "c": "#b69b74"}, {"id": 866, "x": -8, "y": -5, "z": -6, "c": "#b69b74"}, {"id": 867, "x": -8, "y": -5, "z": -5, "c": "#b69b74"}, {"id": 868, "x": -8, "y": -5, "z": -4, "c": "#8fa3ad"}, {"id": 869, "x": -8, "y": -5, "z": -3, "c": "#b69b74"}, {"id": 870, "x": -8, "y": -5, "z": -2, "c": "#b69b74"}, {"id": 871, "x": -8, "y": -5, "z": -1, "c": "#b69b74"}, {"id": 872, "x": -8, "y": -5, "z": 0, "c": "#8fa3ad"}, {"id": 873, "x": -8, "y": -5, "z": 1, "c": "#b69b74"}, {"id": 874, "x": -8, "y": -5, "z": 2, "c": "#b69b74"}, {"id": 875, "x": -8, "y": -5, "z": 3, "c": "#b69b74"}, {"id": 876, "x": -8, "y": -5, "z": 4, "c": "#8fa3ad"}, {"id": 877, "x": -8, "y": -5, "z": 5, "c": "#b69b74"}, {"id": 878, "x": -8, "y": -5, "z": 6, "c": "#b69b74"}, {"id": 879, "x": -8, "y": -5, "z": 7, "c": "#b69b74"}, {"id": 880, "x": -8, "y": -5, "z": 8, "c": "#8fa3ad"}, {"id": 881, "x": -7, "y": -5, "z": -8, "c": "#b69b74"}, {"id": 882, "x": -7, "y": -5, "z": 8, "c": "#b69b74"}, {"id": 883, "x": -6, "y": -5, "z": -8, "c": "#b69b74"}, {"id": 884, "x": -6, "y": -5, "z": 8, "c": "#b69b74"}, {"id": 885, "x": -5, "y": -5, "z": -8, "c": "#b69b74"}, {"id": 886, "x": -5, "y": -5, "z": 8, "c": "#b69b74"}, {"id": 887, "x": -4, "y": -5, "z": -8, "c": "#8fa3ad"}, {"id": 888, "x": -4, "y": -5, "z": 8, "c": "#8fa3ad"}, {"id": 889, "x": -3, "y": -5, "z": -8, "c": "#b69b74"}, {"id": 890, "x": -3, "y": -5, "z": 8, "c": "#b69b74"}, {"id": 891, "x": -2, "y": -5, "z": -8, "c": "#b69b74"}, {"id": 892, "x": -2, "y": -5, "z": 8, "c": "#b69b74"}, {"id": 893, "x": -1, "y": -5, "z": -8, "c": "#b69b74"}, {"id": 894, "x": -1, "y": -5, "z": 8, "c": "#b69b74"}, {"id": 895, "x": 0, "y": -5, "z": -8, "c": "#8fa3ad"}, {"id": 896, "x": 0, "y": -5, "z": 8, "c": "#8fa3ad"}, {"id": 897, "x": 1, "y": -5, "z": -8, "c": "#b69b74"}, {"id": 898, "x": 1, "y": -5, "z": 8, "c": "#b69b74"}, {"id": 899, "x": 2, "y": -5, "z": -8, "c": "#b69b74"}, {"id": 900, "x": 2, "y": -5, "z": 8, "c": "#b69b74"}, {"id": 901, "x": 3, "y": -5, "z": -8, "c": "#b69b74"}, {"id": 902, "x": 3, "y": -5, "z": 8, "c": "#b69b74"}, {"id": 903, "x": 4, "y": -5, "z": -8, "c": "#8fa3ad"}, {"id": 904, "x": 4, "y": -5, "z": 8, "c": "#8fa3ad"}, {"id": 905, "x": 5, "y": -5, "z": -8, "c": "#b69b74"}, {"id": 906, "x": 5, "y": -5, "z": 8, "c": "#b69b74"}, {"id": 907, "x": 6, "y": -5, "z": -8, "c": "#b69b74"}, {"id": 908, "x": 6, "y": -5, "z": 8, "c": "#b69b74"}, {"id": 909, "x": 7, "y": -5, "z": -8, "c": "#b69b74"}, {"id": 910, "x": 7, "y": -5, "z": 8, "c": "#b69b74"}, {"id": 911, "x": 8, "y": -5, "z": -8, "c": "#8fa3ad"}, {"id": 912, "x": 8, "y": -5, "z": -7, "c": "#b69b74"}, {"id": 913, "x": 8, "y": -5, "z": -6, "c": "#b69b74"}, {"id": 914, "x": 8, "y": -5, "z": -5, "c": "#b69b74"}, {"id": 915, "x": 8, "y": -5, "z": -4, "c": "#8fa3ad"}, {"id": 916, "x": 8, "y": -5, "z": -3, "c": "#b69b74"}, {"id": 917, "x": 8, "y": -5, "z": -2, "c": "#b69b74"}, {"id": 918, "x": 8, "y": -5, "z": -1, "c": "#b69b74"}, {"id": 919, "x": 8, "y": -5, "z": 0, "c": "#8fa3ad"}, {"id": 920, "x": 8, "y": -5, "z": 1, "c": "#b69b74"}, {"id": 921, "x": 8, "y": -5, "z": 2, "c": "#b69b74"}, {"id": 922, "x": 8, "y": -5, "z": 3, "c": "#b69b74"}, {"id": 923, "x": 8, "y": -5, "z": 4, "c": "#8fa3ad"}, {"id": 924, "x": 8, "y": -5, "z": 5, "c": "#b69b74"}, {"id": 925, "x": 8, "y": -5, "z": 6, "c": "#b69b74"}, {"id": 926, "x": 8, "y": -5, "z": 7, "c": "#b69b74"}, {"id": 927, "x": 8, "y": -5, "z": 8, "c": "#8fa3ad"}, {"id": 928, "x": -8, "y": -4, "z": -8, "c": "#b18b57"}, {"id": 929, "x": -8, "y": -4, "z": -7, "c": "#b18b57"}, {"id": 930, "x": -8, "y": -4, "z": -6, "c": "#b18b57"}, {"id": 931, "x": -8, "y": -4, "z": -5, "c": "#b18b57"}, {"id": 932, "x": -8, "y": -4, "z": -4, "c": "#b18b57"}, {"id": 933, "x": -8, "y": -4, "z": -3, "c": "#b18b57"}, {"id": 934, "x": -8, "y": -4, "z": -2, "c": "#b18b57"}, {"id": 935, "x": -8, "y": -4, "z": -1, "c": "#b18b57"}, {"id": 936, "x": -8, "y": -4, "z": 0, "c": "#b18b57"}, {"id": 937, "x": -8, "y": -4, "z": 1, "c": "#b18b57"}, {"id": 938, "x": -8, "y": -4, "z": 2, "c": "#b18b57"}, {"id": 939, "x": -8, "y": -4, "z": 3, "c": "#b18b57"}, {"id": 940, "x": -8, "y": -4, "z": 4, "c": "#b18b57"}, {"id": 941, "x": -8, "y": -4, "z": 5, "c": "#b18b57"}, {"id": 942, "x": -8, "y": -4, "z": 6, "c": "#b18b57"}, {"id": 943, "x": -8, "y": -4, "z": 7, "c": "#b18b57"}, {"id": 944, "x": -8, "y": -4, "z": 8, "c": "#b18b57"}, {"id": 945, "x": -7, "y": -4, "z": -8, "c": "#b18b57"}, {"id": 946, "x": -7, "y": -4, "z": 8, "c": "#b18b57"}, {"id": 947, "x": -6, "y": -4, "z": -8, "c": "#b18b57"}, {"id": 948, "x": -6, "y": -4, "z": 8, "c": "#b18b57"}, {"id": 949, "x": -5, "y": -4, "z": -8, "c": "#b18b57"}, {"id": 950, "x": -5, "y": -4, "z": 8, "c": "#b18b57"}, {"id": 951, "x": -4, "y": -4, "z": -8, "c": "#b18b57"}, {"id": 952, "x": -4, "y": -4, "z": 8, "c": "#b18b57"}, {"id": 953, "x": -3, "y": -4, "z": -8, "c": "#b18b57"}, {"id": 954, "x": -3, "y": -4, "z": 8, "c": "#b18b57"}, {"id": 955, "x": -2, "y": -4, "z": -8, "c": "#b18b57"}, {"id": 956, "x": -2, "y": -4, "z": 8, "c": "#b18b57"}, {"id": 957, "x": -1, "y": -4, "z": -8, "c": "#b18b57"}, {"id": 958, "x": -1, "y": -4, "z": 8, "c": "#b18b57"}, {"id": 959, "x": 0, "y": -4, "z": -8, "c": "#b18b57"}, {"id": 960, "x": 0, "y": -4, "z": 8, "c": "#b18b57"}, {"id": 961, "x": 1, "y": -4, "z": -8, "c": "#b18b57"}, {"id": 962, "x": 1, "y": -4, "z": 8, "c": "#b18b57"}, {"id": 963, "x": 2, "y": -4, "z": -8, "c": "#b18b57"}, {"id": 964, "x": 2, "y": -4, "z": 8, "c": "#b18b57"}, {"id": 965, "x": 3, "y": -4, "z": -8, "c": "#b18b57"}, {"id": 966, "x": 3, "y": -4, "z": 8, "c": "#b18b57"}, {"id": 967, "x": 4, "y": -4, "z": -8, "c": "#b18b57"}, {"id": 968, "x": 4, "y": -4, "z": 8, "c": "#b18b57"}, {"id": 969, "x": 5, "y": -4, "z": -8, "c": "#b18b57"}, {"id": 970, "x": 5, "y": -4, "z": 8, "c": "#b18b57"}, {"id": 971, "x": 6, "y": -4, "z": -8, "c": "#b18b57"}, {"id": 972, "x": 6, "y": -4, "z": 8, "c": "#b18b57"}, {"id": 973, "x": 7, "y": -4, "z": -8, "c": "#b18b57"}, {"id": 974, "x": 7, "y": -4, "z": 8, "c": "#b18b57"}, {"id": 975, "x": 8, "y": -4, "z": -8, "c": "#b18b57"}, {"id": 976, "x": 8, "y": -4, "z": -7, "c": "#b18b57"}, {"id": 977, "x": 8, "y": -4, "z": -6, "c": "#b18b57"}, {"id": 978, "x": 8, "y": -4, "z": -5, "c": "#b18b57"}, {"id": 979, "x": 8, "y": -4, "z": -4, "c": "#b18b57"}, {"id": 980, "x": 8, "y": -4, "z": -3, "c": "#b18b57"}, {"id": 981, "x": 8, "y": -4, "z": -2, "c": "#b18b57"}, {"id": 982, "x": 8, "y": -4, "z": -1, "c": "#b18b57"}, {"id": 983, "x": 8, "y": -4, "z": 0, "c": "#b18b57"}, {"id": 984, "x": 8, "y": -4, "z": 1, "c": "#b18b57"}, {"id": 985, "x": 8, "y": -4, "z": 2, "c": "#b18b57"}, {"id": 986, "x": 8, "y": -4, "z": 3, "c": "#b18b57"}, {"id": 987, "x": 8, "y": -4, "z": 4, "c": "#b18b57"}, {"id": 988, "x": 8, "y": -4, "z": 5, "c": "#b18b57"}, {"id": 989, "x": 8, "y": -4, "z": 6, "c": "#b18b57"}, {"id": 990, "x": 8, "y": -4, "z": 7, "c": "#b18b57"}, {"id": 991, "x": 8, "y": -4, "z": 8, "c": "#b18b57"}, {"id": 992, "x": -9, "y": -3, "z": -9, "c": "#6f7378"}, {"id": 993, "x": -9, "y": -3, "z": -8, "c": "#6f7378"}, {"id": 994, "x": -9, "y": -3, "z": -7, "c": "#6f7378"}, {"id": 995, "x": -9, "y": -3, "z": -6, "c": "#6f7378"}, {"id": 996, "x": -9, "y": -3, "z": -5, "c": "#6f7378"}, {"id": 997, "x": -9, "y": -3, "z": -4, "c": "#6f7378"}, {"id": 998, "x": -9, "y": -3, "z": -3, "c": "#6f7378"}, {"id": 999, "x": -9, "y": -3, "z": -2, "c": "#6f7378"}, {"id": 1000, "x": -9, "y": -3, "z": -1, "c": "#6f7378"}, {"id": 1001, "x": -9, "y": -3, "z": 0, "c": "#6f7378"}, {"id": 1002, "x": -9, "y": -3, "z": 1, "c": "#6f7378"}, {"id": 1003, "x": -9, "y": -3, "z": 2, "c": "#6f7378"}, {"id": 1004, "x": -9, "y": -3, "z": 3, "c": "#6f7378"}, {"id": 1005, "x": -9, "y": -3, "z": 4, "c": "#6f7378"}, {"id": 1006, "x": -9, "y": -3, "z": 5, "c": "#6f7378"}, {"id": 1007, "x": -9, "y": -3, "z": 6, "c": "#6f7378"}, {"id": 1008, "x": -9, "y": -3, "z": 7, "c": "#6f7378"}, {"id": 1009, "x": -9, "y": -3, "z": 8, "c": "#6f7378"}, {"id": 1010, "x": -9, "y": -3, "z": 9, "c": "#6f7378"}, {"id": 1011, "x": -8, "y": -3, "z": -9, "c": "#6f7378"}, {"id": 1012, "x": -8, "y": -3, "z": -8, "c": "#6f7378"}, {"id": 1013, "x": -8, "y": -3, "z": -7, "c": "#6f7378"}, {"id": 1014, "x": -8, "y": -3, "z": -6, "c": "#6f7378"}, {"id": 1015, "x": -8, "y": -3, "z": -5, "c": "#6f7378"}, {"id": 1016, "x": -8, "y": -3, "z": -4, "c": "#6f7378"}, {"id": 1017, "x": -8, "y": -3, "z": -3, "c": "#6f7378"}, {"id": 1018, "x": -8, "y": -3, "z": -2, "c": "#6f7378"}, {"id": 1019, "x": -8, "y": -3, "z": -1, "c": "#6f7378"}, {"id": 1020, "x": -8, "y": -3, "z": 0, "c": "#6f7378"}, {"id": 1021, "x": -8, "y": -3, "z": 1, "c": "#6f7378"}, {"id": 1022, "x": -8, "y": -3, "z": 2, "c": "#6f7378"}, {"id": 1023, "x": -8, "y": -3, "z": 3, "c": "#6f7378"}, {"id": 1024, "x": -8, "y": -3, "z": 4, "c": "#6f7378"}, {"id": 1025, "x": -8, "y": -3, "z": 5, "c": "#6f7378"}, {"id": 1026, "x": -8, "y": -3, "z": 6, "c": "#6f7378"}, {"id": 1027, "x": -8, "y": -3, "z": 7, "c": "#6f7378"}, {"id": 1028, "x": -8, "y": -3, "z": 8, "c": "#6f7378"}, {"id": 1029, "x": -8, "y": -3, "z": 9, "c": "#6f7378"}, {"id": 1030, "x": -7, "y": -3, "z": -9, "c": "#6f7378"}, {"id": 1031, "x": -7, "y": -3, "z": -8, "c": "#6f7378"}, {"id": 1032, "x": -7, "y": -3, "z": -7, "c": "#6f7378"}, {"id": 1033, "x": -7, "y": -3, "z": -6, "c": "#6f7378"}, {"id": 1034, "x": -7, "y": -3, "z": -5, "c": "#6f7378"}, {"id": 1035, "x": -7, "y": -3, "z": -4, "c": "#6f7378"}, {"id": 1036, "x": -7, "y": -3, "z": -3, "c": "#6f7378"}, {"id": 1037, "x": -7, "y": -3, "z": -2, "c": "#6f7378"}, {"id": 1038, "x": -7, "y": -3, "z": -1, "c": "#6f7378"}, {"id": 1039, "x": -7, "y": -3, "z": 0, "c": "#6f7378"}, {"id": 1040, "x": -7, "y": -3, "z": 1, "c": "#6f7378"}, {"id": 1041, "x": -7, "y": -3, "z": 2, "c": "#6f7378"}, {"id": 1042, "x": -7, "y": -3, "z": 3, "c": "#6f7378"}, {"id": 1043, "x": -7, "y": -3, "z": 4, "c": "#6f7378"}, {"id": 1044, "x": -7, "y": -3, "z": 5, "c": "#6f7378"}, {"id": 1045, "x": -7, "y": -3, "z": 6, "c": "#6f7378"}, {"id": 1046, "x": -7, "y": -3, "z": 7, "c": "#6f7378"}, {"id": 1047, "x": -7, "y": -3, "z": 8, "c": "#6f7378"}, {"id": 1048, "x": -7, "y": -3, "z": 9, "c": "#6f7378"}, {"id": 1049, "x": -6, "y": -3, "z": -9, "c": "#6f7378"}, {"id": 1050, "x": -6, "y": -3, "z": -8, "c": "#6f7378"}, {"id": 1051, "x": -6, "y": -3, "z": -7, "c": "#6f7378"}, {"id": 1052, "x": -6, "y": -3, "z": -6, "c": "#6f7378"}, {"id": 1053, "x": -6, "y": -3, "z": -5, "c": "#6f7378"}, {"id": 1054, "x": -6, "y": -3, "z": -4, "c": "#6f7378"}, {"id": 1055, "x": -6, "y": -3, "z": -3, "c": "#6f7378"}, {"id": 1056, "x": -6, "y": -3, "z": -2, "c": "#6f7378"}, {"id": 1057, "x": -6, "y": -3, "z": -1, "c": "#6f7378"}, {"id": 1058, "x": -6, "y": -3, "z": 0, "c": "#6f7378"}, {"id": 1059, "x": -6, "y": -3, "z": 1, "c": "#6f7378"}, {"id": 1060, "x": -6, "y": -3, "z": 2, "c": "#6f7378"}, {"id": 1061, "x": -6, "y": -3, "z": 3, "c": "#6f7378"}, {"id": 1062, "x": -6, "y": -3, "z": 4, "c": "#6f7378"}, {"id": 1063, "x": -6, "y": -3, "z": 5, "c": "#6f7378"}, {"id": 1064, "x": -6, "y": -3, "z": 6, "c": "#6f7378"}, {"id": 1065, "x": -6, "y": -3, "z": 7, "c": "#6f7378"}, {"id": 1066, "x": -6, "y": -3, "z": 8, "c": "#6f7378"}, {"id": 1067, "x": -6, "y": -3, "z": 9, "c": "#6f7378"}, {"id": 1068, "x": -5, "y": -3, "z": -9, "c": "#6f7378"}, {"id": 1069, "x": -5, "y": -3, "z": -8, "c": "#6f7378"}, {"id": 1070, "x": -5, "y": -3, "z": -7, "c": "#6f7378"}, {"id": 1071, "x": -5, "y": -3, "z": -6, "c": "#6f7378"}, {"id": 1072, "x": -5, "y": -3, "z": -5, "c": "#6f7378"}, {"id": 1073, "x": -5, "y": -3, "z": -4, "c": "#6f7378"}, {"id": 1074, "x": -5, "y": -3, "z": -3, "c": "#6f7378"}, {"id": 1075, "x": -5, "y": -3, "z": -2, "c": "#6f7378"}, {"id": 1076, "x": -5, "y": -3, "z": -1, "c": "#6f7378"}, {"id": 1077, "x": -5, "y": -3, "z": 0, "c": "#6f7378"}, {"id": 1078, "x": -5, "y": -3, "z": 1, "c": "#6f7378"}, {"id": 1079, "x": -5, "y": -3, "z": 2, "c": "#6f7378"}, {"id": 1080, "x": -5, "y": -3, "z": 3, "c": "#6f7378"}, {"id": 1081, "x": -5, "y": -3, "z": 4, "c": "#6f7378"}, {"id": 1082, "x": -5, "y": -3, "z": 5, "c": "#6f7378"}, {"id": 1083, "x": -5, "y": -3, "z": 6, "c": "#6f7378"}, {"id": 1084, "x": -5, "y": -3, "z": 7, "c": "#6f7378"}, {"id": 1085, "x": -5, "y": -3, "z": 8, "c": "#6f7378"}, {"id": 1086, "x": -5, "y": -3, "z": 9, "c": "#6f7378"}, {"id": 1087, "x": -4, "y": -3, "z": -9, "c": "#6f7378"}, {"id": 1088, "x": -4, "y": -3, "z": -8, "c": "#6f7378"}, {"id": 1089, "x": -4, "y": -3, "z": -7, "c": "#6f7378"}, {"id": 1090, "x": -4, "y": -3, "z": -6, "c": "#6f7378"}, {"id": 1091, "x": -4, "y": -3, "z": -5, "c": "#6f7378"}, {"id": 1092, "x": -4, "y": -3, "z": -4, "c": "#8fa3ad"}, {"id": 1093, "x": -4, "y": -3, "z": -3, "c": "#8fa3ad"}, {"id": 1094, "x": -4, "y": -3, "z": -2, "c": "#8fa3ad"}, {"id": 1095, "x": -4, "y": -3, "z": -1, "c": "#8fa3ad"}, {"id": 1096, "x": -4, "y": -3, "z": 0, "c": "#8fa3ad"}, {"id": 1097, "x": -4, "y": -3, "z": 1, "c": "#8fa3ad"}, {"id": 1098, "x": -4, "y": -3, "z": 2, "c": "#8fa3ad"}, {"id": 1099, "x": -4, "y": -3, "z": 3, "c": "#8fa3ad"}, {"id": 1100, "x": -4, "y": -3, "z": 4, "c": "#8fa3ad"}, {"id": 1101, "x": -4, "y": -3, "z": 5, "c": "#6f7378"}, {"id": 1102, "x": -4, "y": -3, "z": 6, "c": "#6f7378"}, {"id": 1103, "x": -4, "y": -3, "z": 7, "c": "#6f7378"}, {"id": 1104, "x": -4, "y": -3, "z": 8, "c": "#6f7378"}, {"id": 1105, "x": -4, "y": -3, "z": 9, "c": "#6f7378"}, {"id": 1106, "x": -3, "y": -3, "z": -9, "c": "#6f7378"}, {"id": 1107, "x": -3, "y": -3, "z": -8, "c": "#6f7378"}, {"id": 1108, "x": -3, "y": -3, "z": -7, "c": "#6f7378"}, {"id": 1109, "x": -3, "y": -3, "z": -6, "c": "#6f7378"}, {"id": 1110, "x": -3, "y": -3, "z": -5, "c": "#6f7378"}, {"id": 1111, "x": -3, "y": -3, "z": -4, "c": "#8fa3ad"}, {"id": 1112, "x": -3, "y": -3, "z": -3, "c": "#8fa3ad"}, {"id": 1113, "x": -3, "y": -3, "z": -2, "c": "#8fa3ad"}, {"id": 1114, "x": -3, "y": -3, "z": -1, "c": "#8fa3ad"}, {"id": 1115, "x": -3, "y": -3, "z": 0, "c": "#8fa3ad"}, {"id": 1116, "x": -3, "y": -3, "z": 1, "c": "#8fa3ad"}, {"id": 1117, "x": -3, "y": -3, "z": 2, "c": "#8fa3ad"}, {"id": 1118, "x": -3, "y": -3, "z": 3, "c": "#8fa3ad"}, {"id": 1119, "x": -3, "y": -3, "z": 4, "c": "#8fa3ad"}, {"id": 1120, "x": -3, "y": -3, "z": 5, "c": "#6f7378"}, {"id": 1121, "x": -3, "y": -3, "z": 6, "c": "#6f7378"}, {"id": 1122, "x": -3, "y": -3, "z": 7, "c": "#6f7378"}, {"id": 1123, "x": -3, "y": -3, "z": 8, "c": "#6f7378"}, {"id": 1124, "x": -3, "y": -3, "z": 9, "c": "#6f7378"}, {"id": 1125, "x": -2, "y": -3, "z": -9, "c": "#6f7378"}, {"id": 1126, "x": -2, "y": -3, "z": -8, "c": "#6f7378"}, {"id": 1127, "x": -2, "y": -3, "z": -7, "c": "#6f7378"}, {"id": 1128, "x": -2, "y": -3, "z": -6, "c": "#6f7378"}, {"id": 1129, "x": -2, "y": -3, "z": -5, "c": "#6f7378"}, {"id": 1130, "x": -2, "y": -3, "z": -4, "c": "#8fa3ad"}, {"id": 1131, "x": -2, "y": -3, "z": -3, "c": "#8fa3ad"}, {"id": 1132, "x": -2, "y": -3, "z": -2, "c": "#8fa3ad"}, {"id": 1133, "x": -2, "y": -3, "z": -1, "c": "#8fa3ad"}, {"id": 1134, "x": -2, "y": -3, "z": 0, "c": "#8fa3ad"}, {"id": 1135, "x": -2, "y": -3, "z": 1, "c": "#8fa3ad"}, {"id": 1136, "x": -2, "y": -3, "z": 2, "c": "#8fa3ad"}, {"id": 1137, "x": -2, "y": -3, "z": 3, "c": "#8fa3ad"}, {"id": 1138, "x": -2, "y": -3, "z": 4, "c": "#8fa3ad"}, {"id": 1139, "x": -2, "y": -3, "z": 5, "c": "#6f7378"}, {"id": 1140, "x": -2, "y": -3, "z": 6, "c": "#6f7378"}, {"id": 1141, "x": -2, "y": -3, "z": 7, "c": "#6f7378"}, {"id": 1142, "x": -2, "y": -3, "z": 8, "c": "#6f7378"}, {"id": 1143, "x": -2, "y": -3, "z": 9, "c": "#6f7378"}, {"id": 1144, "x": -1, "y": -3, "z": -9, "c": "#6f7378"}, {"id": 1145, "x": -1, "y": -3, "z": -8, "c": "#6f7378"}, {"id": 1146, "x": -1, "y": -3, "z": -7, "c": "#6f7378"}, {"id": 1147, "x": -1, "y": -3, "z": -6, "c": "#6f7378"}, {"id": 1148, "x": -1, "y": -3, "z": -5, "c": "#6f7378"}, {"id": 1149, "x": -1, "y": -3, "z": -4, "c": "#8fa3ad"}, {"id": 1150, "x": -1, "y": -3, "z": -3, "c": "#8fa3ad"}, {"id": 1151, "x": -1, "y": -3, "z": -2, "c": "#8fa3ad"}, {"id": 1152, "x": -1, "y": -3, "z": -1, "c": "#8fa3ad"}, {"id": 1153, "x": -1, "y": -3, "z": 0, "c": "#8fa3ad"}, {"id": 1154, "x": -1, "y": -3, "z": 1, "c": "#8fa3ad"}, {"id": 1155, "x": -1, "y": -3, "z": 2, "c": "#8fa3ad"}, {"id": 1156, "x": -1, "y": -3, "z": 3, "c": "#8fa3ad"}, {"id": 1157, "x": -1, "y": -3, "z": 4, "c": "#8fa3ad"}, {"id": 1158, "x": -1, "y": -3, "z": 5, "c": "#6f7378"}, {"id": 1159, "x": -1, "y": -3, "z": 6, "c": "#6f7378"}, {"id": 1160, "x": -1, "y": -3, "z": 7, "c": "#6f7378"}, {"id": 1161, "x": -1, "y": -3, "z": 8, "c": "#6f7378"}, {"id": 1162, "x": -1, "y": -3, "z": 9, "c": "#6f7378"}, {"id": 1163, "x": 0, "y": -3, "z": -9, "c": "#6f7378"}, {"id": 1164, "x": 0, "y": -3, "z": -8, "c": "#6f7378"}, {"id": 1165, "x": 0, "y": -3, "z": -7, "c": "#6f7378"}, {"id": 1166, "x": 0, "y": -3, "z": -6, "c": "#6f7378"}, {"id": 1167, "x": 0, "y": -3, "z": -5, "c": "#6f7378"}, {"id": 1168, "x": 0, "y": -3, "z": -4, "c": "#8fa3ad"}, {"id": 1169, "x": 0, "y": -3, "z": -3, "c": "#8fa3ad"}, {"id": 1170, "x": 0, "y": -3, "z": -2, "c": "#8fa3ad"}, {"id": 1171, "x": 0, "y": -3, "z": -1, "c": "#8fa3ad"}, {"id": 1172, "x": 0, "y": -3, "z": 0, "c": "#8fa3ad"}, {"id": 1173, "x": 0, "y": -3, "z": 1, "c": "#8fa3ad"}, {"id": 1174, "x": 0, "y": -3, "z": 2, "c": "#8fa3ad"}, {"id": 1175, "x": 0, "y": -3, "z": 3, "c": "#8fa3ad"}, {"id": 1176, "x": 0, "y": -3, "z": 4, "c": "#8fa3ad"}, {"id": 1177, "x": 0, "y": -3, "z": 5, "c": "#6f7378"}, {"id": 1178, "x": 0, "y": -3, "z": 6, "c": "#6f7378"}, {"id": 1179, "x": 0, "y": -3, "z": 7, "c": "#6f7378"}, {"id": 1180, "x": 0, "y": -3, "z": 8, "c": "#6f7378"}, {"id": 1181, "x": 0, "y": -3, "z": 9, "c": "#6f7378"}, {"id": 1182, "x": 1, "y": -3, "z": -9, "c": "#6f7378"}, {"id": 1183, "x": 1, "y": -3, "z": -8, "c": "#6f7378"}, {"id": 1184, "x": 1, "y": -3, "z": -7, "c": "#6f7378"}, {"id": 1185, "x": 1, "y": -3, "z": -6, "c": "#6f7378"}, {"id": 1186, "x": 1, "y": -3, "z": -5, "c": "#6f7378"}, {"id": 1187, "x": 1, "y": -3, "z": -4, "c": "#8fa3ad"}, {"id": 1188, "x": 1, "y": -3, "z": -3, "c": "#8fa3ad"}, {"id": 1189, "x": 1, "y": -3, "z": -2, "c": "#8fa3ad"}, {"id": 1190, "x": 1, "y": -3, "z": -1, "c": "#8fa3ad"}, {"id": 1191, "x": 1, "y": -3, "z": 0, "c": "#8fa3ad"}, {"id": 1192, "x": 1, "y": -3, "z": 1, "c": "#8fa3ad"}, {"id": 1193, "x": 1, "y": -3, "z": 2, "c": "#8fa3ad"}, {"id": 1194, "x": 1, "y": -3, "z": 3, "c": "#8fa3ad"}, {"id": 1195, "x": 1, "y": -3, "z": 4, "c": "#8fa3ad"}, {"id": 1196, "x": 1, "y": -3, "z": 5, "c": "#6f7378"}, {"id": 1197, "x": 1, "y": -3, "z": 6, "c": "#6f7378"}, {"id": 1198, "x": 1, "y": -3, "z": 7, "c": "#6f7378"}, {"id": 1199, "x": 1, "y": -3, "z": 8, "c": "#6f7378"}, {"id": 1200, "x": 1, "y": -3, "z": 9, "c": "#6f7378"}, {"id": 1201, "x": 2, "y": -3, "z": -9, "c": "#6f7378"}, {"id": 1202, "x": 2, "y": -3, "z": -8, "c": "#6f7378"}, {"id": 1203, "x": 2, "y": -3, "z": -7, "c": "#6f7378"}, {"id": 1204, "x": 2, "y": -3, "z": -6, "c": "#6f7378"}, {"id": 1205, "x": 2, "y": -3, "z": -5, "c": "#6f7378"}, {"id": 1206, "x": 2, "y": -3, "z": -4, "c": "#8fa3ad"}, {"id": 1207, "x": 2, "y": -3, "z": -3, "c": "#8fa3ad"}, {"id": 1208, "x": 2, "y": -3, "z": -2, "c": "#8fa3ad"}, {"id": 1209, "x": 2, "y": -3, "z": -1, "c": "#8fa3ad"}, {"id": 1210, "x": 2, "y": -3, "z": 0, "c": "#8fa3ad"}, {"id": 1211, "x": 2, "y": -3, "z": 1, "c": "#8fa3ad"}, {"id": 1212, "x": 2, "y": -3, "z": 2, "c": "#8fa3ad"}, {"id": 1213, "x": 2, "y": -3, "z": 3, "c": "#8fa3ad"}, {"id": 1214, "x": 2, "y": -3, "z": 4, "c": "#8fa3ad"}, {"id": 1215, "x": 2, "y": -3, "z": 5, "c": "#6f7378"}, {"id": 1216, "x": 2, "y": -3, "z": 6, "c": "#6f7378"}, {"id": 1217, "x": 2, "y": -3, "z": 7, "c": "#6f7378"}, {"id": 1218, "x": 2, "y": -3, "z": 8, "c": "#6f7378"}, {"id": 1219, "x": 2, "y": -3, "z": 9, "c": "#6f7378"}, {"id": 1220, "x": 3, "y": -3, "z": -9, "c": "#6f7378"}, {"id": 1221, "x": 3, "y": -3, "z": -8, "c": "#6f7378"}, {"id": 1222, "x": 3, "y": -3, "z": -7, "c": "#6f7378"}, {"id": 1223, "x": 3, "y": -3, "z": -6, "c": "#6f7378"}, {"id": 1224, "x": 3, "y": -3, "z": -5, "c": "#6f7378"}, {"id": 1225, "x": 3, "y": -3, "z": -4, "c": "#8fa3ad"}, {"id": 1226, "x": 3, "y": -3, "z": -3, "c": "#8fa3ad"}, {"id": 1227, "x": 3, "y": -3, "z": -2, "c": "#8fa3ad"}, {"id": 1228, "x": 3, "y": -3, "z": -1, "c": "#8fa3ad"}, {"id": 1229, "x": 3, "y": -3, "z": 0, "c": "#8fa3ad"}, {"id": 1230, "x": 3, "y": -3, "z": 1, "c": "#8fa3ad"}, {"id": 1231, "x": 3, "y": -3, "z": 2, "c": "#8fa3ad"}, {"id": 1232, "x": 3, "y": -3, "z": 3, "c": "#8fa3ad"}, {"id": 1233, "x": 3, "y": -3, "z": 4, "c": "#8fa3ad"}, {"id": 1234, "x": 3, "y": -3, "z": 5, "c": "#6f7378"}, {"id": 1235, "x": 3, "y": -3, "z": 6, "c": "#6f7378"}, {"id": 1236, "x": 3, "y": -3, "z": 7, "c": "#6f7378"}, {"id": 1237, "x": 3, "y": -3, "z": 8, "c": "#6f7378"}, {"id": 1238, "x": 3, "y": -3, "z": 9, "c": "#6f7378"}, {"id": 1239, "x": 4, "y": -3, "z": -9, "c": "#6f7378"}, {"id": 1240, "x": 4, "y": -3, "z": -8, "c": "#6f7378"}, {"id": 1241, "x": 4, "y": -3, "z": -7, "c": "#6f7378"}, {"id": 1242, "x": 4, "y": -3, "z": -6, "c": "#6f7378"}, {"id": 1243, "x": 4, "y": -3, "z": -5, "c": "#6f7378"}, {"id": 1244, "x": 4, "y": -3, "z": -4, "c": "#8fa3ad"}, {"id": 1245, "x": 4, "y": -3, "z": -3, "c": "#8fa3ad"}, {"id": 1246, "x": 4, "y": -3, "z": -2, "c": "#8fa3ad"}, {"id": 1247, "x": 4, "y": -3, "z": -1, "c": "#8fa3ad"}, {"id": 1248, "x": 4, "y": -3, "z": 0, "c": "#8fa3ad"}, {"id": 1249, "x": 4, "y": -3, "z": 1, "c": "#8fa3ad"}, {"id": 1250, "x": 4, "y": -3, "z": 2, "c": "#8fa3ad"}, {"id": 1251, "x": 4, "y": -3, "z": 3, "c": "#8fa3ad"}, {"id": 1252, "x": 4, "y": -3, "z": 4, "c": "#8fa3ad"}, {"id": 1253, "x": 4, "y": -3, "z": 5, "c": "#6f7378"}, {"id": 1254, "x": 4, "y": -3, "z": 6, "c": "#6f7378"}, {"id": 1255, "x": 4, "y": -3, "z": 7, "c": "#6f7378"}, {"id": 1256, "x": 4, "y": -3, "z": 8, "c": "#6f7378"}, {"id": 1257, "x": 4, "y": -3, "z": 9, "c": "#6f7378"}, {"id": 1258, "x": 5, "y": -3, "z": -9, "c": "#6f7378"}, {"id": 1259, "x": 5, "y": -3, "z": -8, "c": "#6f7378"}, {"id": 1260, "x": 5, "y": -3, "z": -7, "c": "#6f7378"}, {"id": 1261, "x": 5, "y": -3, "z": -6, "c": "#6f7378"}, {"id": 1262, "x": 5, "y": -3, "z": -5, "c": "#6f7378"}, {"id": 1263, "x": 5, "y": -3, "z": -4, "c": "#6f7378"}, {"id": 1264, "x": 5, "y": -3, "z": -3, "c": "#6f7378"}, {"id": 1265, "x": 5, "y": -3, "z": -2, "c": "#6f7378"}, {"id": 1266, "x": 5, "y": -3, "z": -1, "c": "#6f7378"}, {"id": 1267, "x": 5, "y": -3, "z": 0, "c": "#6f7378"}, {"id": 1268, "x": 5, "y": -3, "z": 1, "c": "#6f7378"}, {"id": 1269, "x": 5, "y": -3, "z": 2, "c": "#6f7378"}, {"id": 1270, "x": 5, "y": -3, "z": 3, "c": "#6f7378"}, {"id": 1271, "x": 5, "y": -3, "z": 4, "c": "#6f7378"}, {"id": 1272, "x": 5, "y": -3, "z": 5, "c": "#6f7378"}, {"id": 1273, "x": 5, "y": -3, "z": 6, "c": "#6f7378"}, {"id": 1274, "x": 5, "y": -3, "z": 7, "c": "#6f7378"}, {"id": 1275, "x": 5, "y": -3, "z": 8, "c": "#6f7378"}, {"id": 1276, "x": 5, "y": -3, "z": 9, "c": "#6f7378"}, {"id": 1277, "x": 6, "y": -3, "z": -9, "c": "#6f7378"}, {"id": 1278, "x": 6, "y": -3, "z": -8, "c": "#6f7378"}, {"id": 1279, "x": 6, "y": -3, "z": -7, "c": "#6f7378"}, {"id": 1280, "x": 6, "y": -3, "z": -6, "c": "#6f7378"}, {"id": 1281, "x": 6, "y": -3, "z": -5, "c": "#6f7378"}, {"id": 1282, "x": 6, "y": -3, "z": -4, "c": "#6f7378"}, {"id": 1283, "x": 6, "y": -3, "z": -3, "c": "#6f7378"}, {"id": 1284, "x": 6, "y": -3, "z": -2, "c": "#6f7378"}, {"id": 1285, "x": 6, "y": -3, "z": -1, "c": "#6f7378"}, {"id": 1286, "x": 6, "y": -3, "z": 0, "c": "#6f7378"}, {"id": 1287, "x": 6, "y": -3, "z": 1, "c": "#6f7378"}, {"id": 1288, "x": 6, "y": -3, "z": 2, "c": "#6f7378"}, {"id": 1289, "x": 6, "y": -3, "z": 3, "c": "#6f7378"}, {"id": 1290, "x": 6, "y": -3, "z": 4, "c": "#6f7378"}, {"id": 1291, "x": 6, "y": -3, "z": 5, "c": "#6f7378"}, {"id": 1292, "x": 6, "y": -3, "z": 6, "c": "#6f7378"}, {"id": 1293, "x": 6, "y": -3, "z": 7, "c": "#6f7378"}, {"id": 1294, "x": 6, "y": -3, "z": 8, "c": "#6f7378"}, {"id": 1295, "x": 6, "y": -3, "z": 9, "c": "#6f7378"}, {"id": 1296, "x": 7, "y": -3, "z": -9, "c": "#6f7378"}, {"id": 1297, "x": 7, "y": -3, "z": -8, "c": "#6f7378"}, {"id": 1298, "x": 7, "y": -3, "z": -7, "c": "#6f7378"}, {"id": 1299, "x": 7, "y": -3, "z": -6, "c": "#6f7378"}, {"id": 1300, "x": 7, "y": -3, "z": -5, "c": "#6f7378"}, {"id": 1301, "x": 7, "y": -3, "z": -4, "c": "#6f7378"}, {"id": 1302, "x": 7, "y": -3, "z": -3, "c": "#6f7378"}, {"id": 1303, "x": 7, "y": -3, "z": -2, "c": "#6f7378"}, {"id": 1304, "x": 7, "y": -3, "z": -1, "c": "#6f7378"}, {"id": 1305, "x": 7, "y": -3, "z": 0, "c": "#6f7378"}, {"id": 1306, "x": 7, "y": -3, "z": 1, "c": "#6f7378"}, {"id": 1307, "x": 7, "y": -3, "z": 2, "c": "#6f7378"}, {"id": 1308, "x": 7, "y": -3, "z": 3, "c": "#6f7378"}, {"id": 1309, "x": 7, "y": -3, "z": 4, "c": "#6f7378"}, {"id": 1310, "x": 7, "y": -3, "z": 5, "c": "#6f7378"}, {"id": 1311, "x": 7, "y": -3, "z": 6, "c": "#6f7378"}, {"id": 1312, "x": 7, "y": -3, "z": 7, "c": "#6f7378"}, {"id": 1313, "x": 7, "y": -3, "z": 8, "c": "#6f7378"}, {"id": 1314, "x": 7, "y": -3, "z": 9, "c": "#6f7378"}, {"id": 1315, "x": 8, "y": -3, "z": -9, "c": "#6f7378"}, {"id": 1316, "x": 8, "y": -3, "z": -8, "c": "#6f7378"}, {"id": 1317, "x": 8, "y": -3, "z": -7, "c": "#6f7378"}, {"id": 1318, "x": 8, "y": -3, "z": -6, "c": "#6f7378"}, {"id": 1319, "x": 8, "y": -3, "z": -5, "c": "#6f7378"}, {"id": 1320, "x": 8, "y": -3, "z": -4, "c": "#6f7378"}, {"id": 1321, "x": 8, "y": -3, "z": -3, "c": "#6f7378"}, {"id": 1322, "x": 8, "y": -3, "z": -2, "c": "#6f7378"}, {"id": 1323, "x": 8, "y": -3, "z": -1, "c": "#6f7378"}, {"id": 1324, "x": 8, "y": -3, "z": 0, "c": "#6f7378"}, {"id": 1325, "x": 8, "y": -3, "z": 1, "c": "#6f7378"}, {"id": 1326, "x": 8, "y": -3, "z": 2, "c": "#6f7378"}, {"id": 1327, "x": 8, "y": -3, "z": 3, "c": "#6f7378"}, {"id": 1328, "x": 8, "y": -3, "z": 4, "c": "#6f7378"}, {"id": 1329, "x": 8, "y": -3, "z": 5, "c": "#6f7378"}, {"id": 1330, "x": 8, "y": -3, "z": 6, "c": "#6f7378"}, {"id": 1331, "x": 8, "y": -3, "z": 7, "c": "#6f7378"}, {"id": 1332, "x": 8, "y": -3, "z": 8, "c": "#6f7378"}, {"id": 1333, "x": 8, "y": -3, "z": 9, "c": "#6f7378"}, {"id": 1334, "x": 9, "y": -3, "z": -9, "c": "#6f7378"}, {"id": 1335, "x": 9, "y": -3, "z": -8, "c": "#6f7378"}, {"id": 1336, "x": 9, "y": -3, "z": -7, "c": "#6f7378"}, {"id": 1337, "x": 9, "y": -3, "z": -6, "c": "#6f7378"}, {"id": 1338, "x": 9, "y": -3, "z": -5, "c": "#6f7378"}, {"id": 1339, "x": 9, "y": -3, "z": -4, "c": "#6f7378"}, {"id": 1340, "x": 9, "y": -3, "z": -3, "c": "#6f7378"}, {"id": 1341, "x": 9, "y": -3, "z": -2, "c": "#6f7378"}, {"id": 1342, "x": 9, "y": -3, "z": -1, "c": "#6f7378"}, {"id": 1343, "x": 9, "y": -3, "z": 0, "c": "#6f7378"}, {"id": 1344, "x": 9, "y": -3, "z": 1, "c": "#6f7378"}, {"id": 1345, "x": 9, "y": -3, "z": 2, "c": "#6f7378"}, {"id": 1346, "x": 9, "y": -3, "z": 3, "c": "#6f7378"}, {"id": 1347, "x": 9, "y": -3, "z": 4, "c": "#6f7378"}, {"id": 1348, "x": 9, "y": -3, "z": 5, "c": "#6f7378"}, {"id": 1349, "x": 9, "y": -3, "z": 6, "c": "#6f7378"}, {"id": 1350, "x": 9, "y": -3, "z": 7, "c": "#6f7378"}, {"id": 1351, "x": 9, "y": -3, "z": 8, "c": "#6f7378"}, {"id": 1352, "x": 9, "y": -3, "z": 9, "c": "#6f7378"}, {"id": 1353, "x": -4, "y": -2, "z": -4, "c": "#8fa3ad"}, {"id": 1354, "x": -4, "y": -2, "z": -3, "c": "#8fa3ad"}, {"id": 1355, "x": -4, "y": -2, "z": -2, "c": "#8fa3ad"}, {"id": 1356, "x": -4, "y": -2, "z": -1, "c": "#8fa3ad"}, {"id": 1357, "x": -4, "y": -2, "z": 0, "c": "#8fa3ad"}, {"id": 1358, "x": -4, "y": -2, "z": 1, "c": "#8fa3ad"}, {"id": 1359, "x": -4, "y": -2, "z": 2, "c": "#8fa3ad"}, {"id": 1360, "x": -4, "y": -2, "z": 3, "c": "#8fa3ad"}, {"id": 1361, "x": -4, "y": -2, "z": 4, "c": "#8fa3ad"}, {"id": 1362, "x": -3, "y": -2, "z": -4, "c": "#8fa3ad"}, {"id": 1363, "x": -3, "y": -2, "z": -3, "c": "#8fa3ad"}, {"id": 1364, "x": -3, "y": -2, "z": -2, "c": "#8fa3ad"}, {"id": 1365, "x": -3, "y": -2, "z": -1, "c": "#8fa3ad"}, {"id": 1366, "x": -3, "y": -2, "z": 0, "c": "#8fa3ad"}, {"id": 1367, "x": -3, "y": -2, "z": 1, "c": "#8fa3ad"}, {"id": 1368, "x": -3, "y": -2, "z": 2, "c": "#8fa3ad"}, {"id": 1369, "x": -3, "y": -2, "z": 3, "c": "#8fa3ad"}, {"id": 1370, "x": -3, "y": -2, "z": 4, "c": "#8fa3ad"}, {"id": 1371, "x": -2, "y": -2, "z": -4, "c": "#8fa3ad"}, {"id": 1372, "x": -2, "y": -2, "z": -3, "c": "#8fa3ad"}, {"id": 1373, "x": -2, "y": -2, "z": -2, "c": "#8fa3ad"}, {"id": 1374, "x": -2, "y": -2, "z": -1, "c": "#8fa3ad"}, {"id": 1375, "x": -2, "y": -2, "z": 0, "c": "#8fa3ad"}, {"id": 1376, "x": -2, "y": -2, "z": 1, "c": "#8fa3ad"}, {"id": 1377, "x": -2, "y": -2, "z": 2, "c": "#8fa3ad"}, {"id": 1378, "x": -2, "y": -2, "z": 3, "c": "#8fa3ad"}, {"id": 1379, "x": -2, "y": -2, "z": 4, "c": "#8fa3ad"}, {"id": 1380, "x": -1, "y": -2, "z": -4, "c": "#8fa3ad"}, {"id": 1381, "x": -1, "y": -2, "z": -3, "c": "#8fa3ad"}, {"id": 1382, "x": -1, "y": -2, "z": -2, "c": "#8fa3ad"}, {"id": 1383, "x": -1, "y": -2, "z": -1, "c": "#8fa3ad"}, {"id": 1384, "x": -1, "y": -2, "z": 0, "c": "#8fa3ad"}, {"id": 1385, "x": -1, "y": -2, "z": 1, "c": "#8fa3ad"}, {"id": 1386, "x": -1, "y": -2, "z": 2, "c": "#8fa3ad"}, {"id": 1387, "x": -1, "y": -2, "z": 3, "c": "#8fa3ad"}, {"id": 1388, "x": -1, "y": -2, "z": 4, "c": "#8fa3ad"}, {"id": 1389, "x": 0, "y": -2, "z": -4, "c": "#8fa3ad"}, {"id": 1390, "x": 0, "y": -2, "z": -3, "c": "#8fa3ad"}, {"id": 1391, "x": 0, "y": -2, "z": -2, "c": "#8fa3ad"}, {"id": 1392, "x": 0, "y": -2, "z": -1, "c": "#8fa3ad"}, {"id": 1393, "x": 0, "y": -2, "z": 0, "c": "#8fa3ad"}, {"id": 1394, "x": 0, "y": -2, "z": 1, "c": "#8fa3ad"}, {"id": 1395, "x": 0, "y": -2, "z": 2, "c": "#8fa3ad"}, {"id": 1396, "x": 0, "y": -2, "z": 3, "c": "#8fa3ad"}, {"id": 1397, "x": 0, "y": -2, "z": 4, "c": "#8fa3ad"}, {"id": 1398, "x": 1, "y": -2, "z": -4, "c": "#8fa3ad"}, {"id": 1399, "x": 1, "y": -2, "z": -3, "c": "#8fa3ad"}, {"id": 1400, "x": 1, "y": -2, "z": -2, "c": "#8fa3ad"}, {"id": 1401, "x": 1, "y": -2, "z": -1, "c": "#8fa3ad"}, {"id": 1402, "x": 1, "y": -2, "z": 0, "c": "#8fa3ad"}, {"id": 1403, "x": 1, "y": -2, "z": 1, "c": "#8fa3ad"}, {"id": 1404, "x": 1, "y": -2, "z": 2, "c": "#8fa3ad"}, {"id": 1405, "x": 1, "y": -2, "z": 3, "c": "#8fa3ad"}, {"id": 1406, "x": 1, "y": -2, "z": 4, "c": "#8fa3ad"}, {"id": 1407, "x": 2, "y": -2, "z": -4, "c": "#8fa3ad"}, {"id": 1408, "x": 2, "y": -2, "z": -3, "c": "#8fa3ad"}, {"id": 1409, "x": 2, "y": -2, "z": -2, "c": "#8fa3ad"}, {"id": 1410, "x": 2, "y": -2, "z": -1, "c": "#8fa3ad"}, {"id": 1411, "x": 2, "y": -2, "z": 0, "c": "#8fa3ad"}, {"id": 1412, "x": 2, "y": -2, "z": 1, "c": "#8fa3ad"}, {"id": 1413, "x": 2, "y": -2, "z": 2, "c": "#8fa3ad"}, {"id": 1414, "x": 2, "y": -2, "z": 3, "c": "#8fa3ad"}, {"id": 1415, "x": 2, "y": -2, "z": 4, "c": "#8fa3ad"}, {"id": 1416, "x": 3, "y": -2, "z": -4, "c": "#8fa3ad"}, {"id": 1417, "x": 3, "y": -2, "z": -3, "c": "#8fa3ad"}, {"id": 1418, "x": 3, "y": -2, "z": -2, "c": "#8fa3ad"}, {"id": 1419, "x": 3, "y": -2, "z": -1, "c": "#8fa3ad"}, {"id": 1420, "x": 3, "y": -2, "z": 0, "c": "#8fa3ad"}, {"id": 1421, "x": 3, "y": -2, "z": 1, "c": "#8fa3ad"}, {"id": 1422, "x": 3, "y": -2, "z": 2, "c": "#8fa3ad"}, {"id": 1423, "x": 3, "y": -2, "z": 3, "c": "#8fa3ad"}, {"id": 1424, "x": 3, "y": -2, "z": 4, "c": "#8fa3ad"}, {"id": 1425, "x": 4, "y": -2, "z": -4, "c": "#8fa3ad"}, {"id": 1426, "x": 4, "y": -2, "z": -3, "c": "#8fa3ad"}, {"id": 1427, "x": 4, "y": -2, "z": -2, "c": "#8fa3ad"}, {"id": 1428, "x": 4, "y": -2, "z": -1, "c": "#8fa3ad"}, {"id": 1429, "x": 4, "y": -2, "z": 0, "c": "#8fa3ad"}, {"id": 1430, "x": 4, "y": -2, "z": 1, "c": "#8fa3ad"}, {"id": 1431, "x": 4, "y": -2, "z": 2, "c": "#8fa3ad"}, {"id": 1432, "x": 4, "y": -2, "z": 3, "c": "#8fa3ad"}, {"id": 1433, "x": 4, "y": -2, "z": 4, "c": "#8fa3ad"}, {"id": 1434, "x": -6, "y": -11, "z": -6, "c": "#5a4231"}, {"id": 1435, "x": -6, "y": -11, "z": -6.5, "c": "#4f6274"}, {"id": 1436, "x": -6, "y": -10, "z": -6, "c": "#8fa3ad"}, {"id": 1437, "x": -6, "y": -10, "z": -5.5, "c": "#86483f"}, {"id": 1438, "x": -6, "y": -9, "z": -6, "c": "#8fa3ad"}, {"id": 1439, "x": -6, "y": -9, "z": -6.5, "c": "#4f6274"}, {"id": 1440, "x": -6, "y": -8, "z": -6, "c": "#8fa3ad"}, {"id": 1441, "x": -6, "y": -8, "z": -5.5, "c": "#86483f"}, {"id": 1442, "x": -6, "y": -7, "z": -6, "c": "#8fa3ad"}, {"id": 1443, "x": -6, "y": -7, "z": -6.5, "c": "#4f6274"}, {"id": 1444, "x": -6, "y": -11, "z": -5, "c": "#5a4231"}, {"id": 1445, "x": -6, "y": -11, "z": -5.5, "c": "#4f6274"}, {"id": 1446, "x": -6, "y": -10, "z": -5, "c": "#674f3c"}, {"id": 1447, "x": -6, "y": -10, "z": -4.5, "c": "#86483f"}, {"id": 1448, "x": -6, "y": -9, "z": -5, "c": "#674f3c"}, {"id": 1449, "x": -6, "y": -9, "z": -5.5, "c": "#4f6274"}, {"id": 1450, "x": -6, "y": -8, "z": -5, "c": "#674f3c"}, {"id": 1451, "x": -6, "y": -8, "z": -4.5, "c": "#86483f"}, {"id": 1452, "x": -6, "y": -7, "z": -5, "c": "#674f3c"}, {"id": 1453, "x": -6, "y": -7, "z": -5.5, "c": "#4f6274"}, {"id": 1454, "x": -6, "y": -11, "z": -4, "c": "#5a4231"}, {"id": 1455, "x": -6, "y": -11, "z": -4.5, "c": "#4f6274"}, {"id": 1456, "x": -6, "y": -10, "z": -4, "c": "#674f3c"}, {"id": 1457, "x": -6, "y": -10, "z": -3.5, "c": "#86483f"}, {"id": 1458, "x": -6, "y": -9, "z": -4, "c": "#674f3c"}, {"id": 1459, "x": -6, "y": -9, "z": -4.5, "c": "#4f6274"}, {"id": 1460, "x": -6, "y": -8, "z": -4, "c": "#674f3c"}, {"id": 1461, "x": -6, "y": -8, "z": -3.5, "c": "#86483f"}, {"id": 1462, "x": -6, "y": -7, "z": -4, "c": "#674f3c"}, {"id": 1463, "x": -6, "y": -7, "z": -4.5, "c": "#4f6274"}, {"id": 1464, "x": -6, "y": -11, "z": -3, "c": "#5a4231"}, {"id": 1465, "x": -6, "y": -11, "z": -3.5, "c": "#4f6274"}, {"id": 1466, "x": -6, "y": -10, "z": -3, "c": "#674f3c"}, {"id": 1467, "x": -6, "y": -10, "z": -2.5, "c": "#86483f"}, {"id": 1468, "x": -6, "y": -9, "z": -3, "c": "#674f3c"}, {"id": 1469, "x": -6, "y": -9, "z": -3.5, "c": "#4f6274"}, {"id": 1470, "x": -6, "y": -8, "z": -3, "c": "#674f3c"}, {"id": 1471, "x": -6, "y": -8, "z": -2.5, "c": "#86483f"}, {"id": 1472, "x": -6, "y": -7, "z": -3, "c": "#674f3c"}, {"id": 1473, "x": -6, "y": -7, "z": -3.5, "c": "#4f6274"}, {"id": 1474, "x": -6, "y": -11, "z": -2, "c": "#5a4231"}, {"id": 1475, "x": -6, "y": -11, "z": -2.5, "c": "#4f6274"}, {"id": 1476, "x": -6, "y": -10, "z": -2, "c": "#8fa3ad"}, {"id": 1477, "x": -6, "y": -10, "z": -1.5, "c": "#86483f"}, {"id": 1478, "x": -6, "y": -9, "z": -2, "c": "#8fa3ad"}, {"id": 1479, "x": -6, "y": -9, "z": -2.5, "c": "#4f6274"}, {"id": 1480, "x": -6, "y": -8, "z": -2, "c": "#8fa3ad"}, {"id": 1481, "x": -6, "y": -8, "z": -1.5, "c": "#86483f"}, {"id": 1482, "x": -6, "y": -7, "z": -2, "c": "#8fa3ad"}, {"id": 1483, "x": -6, "y": -7, "z": -2.5, "c": "#4f6274"}, {"id": 1484, "x": -2, "y": -11, "z": -6, "c": "#5a4231"}, {"id": 1485, "x": -2, "y": -11, "z": -6.5, "c": "#4f6274"}, {"id": 1486, "x": -2, "y": -10, "z": -6, "c": "#8fa3ad"}, {"id": 1487, "x": -2, "y": -10, "z": -5.5, "c": "#86483f"}, {"id": 1488, "x": -2, "y": -9, "z": -6, "c": "#8fa3ad"}, {"id": 1489, "x": -2, "y": -9, "z": -6.5, "c": "#4f6274"}, {"id": 1490, "x": -2, "y": -8, "z": -6, "c": "#8fa3ad"}, {"id": 1491, "x": -2, "y": -8, "z": -5.5, "c": "#86483f"}, {"id": 1492, "x": -2, "y": -7, "z": -6, "c": "#8fa3ad"}, {"id": 1493, "x": -2, "y": -7, "z": -6.5, "c": "#4f6274"}, {"id": 1494, "x": -2, "y": -11, "z": -5, "c": "#5a4231"}, {"id": 1495, "x": -2, "y": -11, "z": -5.5, "c": "#4f6274"}, {"id": 1496, "x": -2, "y": -10, "z": -5, "c": "#674f3c"}, {"id": 1497, "x": -2, "y": -10, "z": -4.5, "c": "#86483f"}, {"id": 1498, "x": -2, "y": -9, "z": -5, "c": "#674f3c"}, {"id": 1499, "x": -2, "y": -9, "z": -5.5, "c": "#4f6274"}, {"id": 1500, "x": -2, "y": -8, "z": -5, "c": "#674f3c"}, {"id": 1501, "x": -2, "y": -8, "z": -4.5, "c": "#86483f"}, {"id": 1502, "x": -2, "y": -7, "z": -5, "c": "#674f3c"}, {"id": 1503, "x": -2, "y": -7, "z": -5.5, "c": "#4f6274"}, {"id": 1504, "x": -2, "y": -11, "z": -4, "c": "#5a4231"}, {"id": 1505, "x": -2, "y": -11, "z": -4.5, "c": "#4f6274"}, {"id": 1506, "x": -2, "y": -10, "z": -4, "c": "#674f3c"}, {"id": 1507, "x": -2, "y": -10, "z": -3.5, "c": "#86483f"}, {"id": 1508, "x": -2, "y": -9, "z": -4, "c": "#674f3c"}, {"id": 1509, "x": -2, "y": -9, "z": -4.5, "c": "#4f6274"}, {"id": 1510, "x": -2, "y": -8, "z": -4, "c": "#674f3c"}, {"id": 1511, "x": -2, "y": -8, "z": -3.5, "c": "#86483f"}, {"id": 1512, "x": -2, "y": -7, "z": -4, "c": "#674f3c"}, {"id": 1513, "x": -2, "y": -7, "z": -4.5, "c": "#4f6274"}, {"id": 1514, "x": -2, "y": -11, "z": -3, "c": "#5a4231"}, {"id": 1515, "x": -2, "y": -11, "z": -3.5, "c": "#4f6274"}, {"id": 1516, "x": -2, "y": -10, "z": -3, "c": "#674f3c"}, {"id": 1517, "x": -2, "y": -10, "z": -2.5, "c": "#86483f"}, {"id": 1518, "x": -2, "y": -9, "z": -3, "c": "#674f3c"}, {"id": 1519, "x": -2, "y": -9, "z": -3.5, "c": "#4f6274"}, {"id": 1520, "x": -2, "y": -8, "z": -3, "c": "#674f3c"}, {"id": 1521, "x": -2, "y": -8, "z": -2.5, "c": "#86483f"}, {"id": 1522, "x": -2, "y": -7, "z": -3, "c": "#674f3c"}, {"id": 1523, "x": -2, "y": -7, "z": -3.5, "c": "#4f6274"}, {"id": 1524, "x": -2, "y": -11, "z": -2, "c": "#5a4231"}, {"id": 1525, "x": -2, "y": -11, "z": -2.5, "c": "#4f6274"}, {"id": 1526, "x": -2, "y": -10, "z": -2, "c": "#8fa3ad"}, {"id": 1527, "x": -2, "y": -10, "z": -1.5, "c": "#86483f"}, {"id": 1528, "x": -2, "y": -9, "z": -2, "c": "#8fa3ad"}, {"id": 1529, "x": -2, "y": -9, "z": -2.5, "c": "#4f6274"}, {"id": 1530, "x": -2, "y": -8, "z": -2, "c": "#8fa3ad"}, {"id": 1531, "x": -2, "y": -8, "z": -1.5, "c": "#86483f"}, {"id": 1532, "x": -2, "y": -7, "z": -2, "c": "#8fa3ad"}, {"id": 1533, "x": -2, "y": -7, "z": -2.5, "c": "#4f6274"}, {"id": 1534, "x": 2, "y": -11, "z": -6, "c": "#5a4231"}, {"id": 1535, "x": 2, "y": -11, "z": -6.5, "c": "#4f6274"}, {"id": 1536, "x": 2, "y": -10, "z": -6, "c": "#8fa3ad"}, {"id": 1537, "x": 2, "y": -10, "z": -5.5, "c": "#86483f"}, {"id": 1538, "x": 2, "y": -9, "z": -6, "c": "#8fa3ad"}, {"id": 1539, "x": 2, "y": -9, "z": -6.5, "c": "#4f6274"}, {"id": 1540, "x": 2, "y": -8, "z": -6, "c": "#8fa3ad"}, {"id": 1541, "x": 2, "y": -8, "z": -5.5, "c": "#86483f"}, {"id": 1542, "x": 2, "y": -7, "z": -6, "c": "#8fa3ad"}, {"id": 1543, "x": 2, "y": -7, "z": -6.5, "c": "#4f6274"}, {"id": 1544, "x": 2, "y": -11, "z": -5, "c": "#5a4231"}, {"id": 1545, "x": 2, "y": -11, "z": -5.5, "c": "#4f6274"}, {"id": 1546, "x": 2, "y": -10, "z": -5, "c": "#674f3c"}, {"id": 1547, "x": 2, "y": -10, "z": -4.5, "c": "#86483f"}, {"id": 1548, "x": 2, "y": -9, "z": -5, "c": "#674f3c"}, {"id": 1549, "x": 2, "y": -9, "z": -5.5, "c": "#4f6274"}, {"id": 1550, "x": 2, "y": -8, "z": -5, "c": "#674f3c"}, {"id": 1551, "x": 2, "y": -8, "z": -4.5, "c": "#86483f"}, {"id": 1552, "x": 2, "y": -7, "z": -5, "c": "#674f3c"}, {"id": 1553, "x": 2, "y": -7, "z": -5.5, "c": "#4f6274"}, {"id": 1554, "x": 2, "y": -11, "z": -4, "c": "#5a4231"}, {"id": 1555, "x": 2, "y": -11, "z": -4.5, "c": "#4f6274"}, {"id": 1556, "x": 2, "y": -10, "z": -4, "c": "#674f3c"}, {"id": 1557, "x": 2, "y": -10, "z": -3.5, "c": "#86483f"}, {"id": 1558, "x": 2, "y": -9, "z": -4, "c": "#674f3c"}, {"id": 1559, "x": 2, "y": -9, "z": -4.5, "c": "#4f6274"}, {"id": 1560, "x": 2, "y": -8, "z": -4, "c": "#674f3c"}, {"id": 1561, "x": 2, "y": -8, "z": -3.5, "c": "#86483f"}, {"id": 1562, "x": 2, "y": -7, "z": -4, "c": "#674f3c"}, {"id": 1563, "x": 2, "y": -7, "z": -4.5, "c": "#4f6274"}, {"id": 1564, "x": 2, "y": -11, "z": -3, "c": "#5a4231"}, {"id": 1565, "x": 2, "y": -11, "z": -3.5, "c": "#4f6274"}, {"id": 1566, "x": 2, "y": -10, "z": -3, "c": "#674f3c"}, {"id": 1567, "x": 2, "y": -10, "z": -2.5, "c": "#86483f"}, {"id": 1568, "x": 2, "y": -9, "z": -3, "c": "#674f3c"}, {"id": 1569, "x": 2, "y": -9, "z": -3.5, "c": "#4f6274"}, {"id": 1570, "x": 2, "y": -8, "z": -3, "c": "#674f3c"}, {"id": 1571, "x": 2, "y": -8, "z": -2.5, "c": "#86483f"}, {"id": 1572, "x": 2, "y": -7, "z": -3, "c": "#674f3c"}, {"id": 1573, "x": 2, "y": -7, "z": -3.5, "c": "#4f6274"}, {"id": 1574, "x": 2, "y": -11, "z": -2, "c": "#5a4231"}, {"id": 1575, "x": 2, "y": -11, "z": -2.5, "c": "#4f6274"}, {"id": 1576, "x": 2, "y": -10, "z": -2, "c": "#8fa3ad"}, {"id": 1577, "x": 2, "y": -10, "z": -1.5, "c": "#86483f"}, {"id": 1578, "x": 2, "y": -9, "z": -2, "c": "#8fa3ad"}, {"id": 1579, "x": 2, "y": -9, "z": -2.5, "c": "#4f6274"}, {"id": 1580, "x": 2, "y": -8, "z": -2, "c": "#8fa3ad"}, {"id": 1581, "x": 2, "y": -8, "z": -1.5, "c": "#86483f"}, {"id": 1582, "x": 2, "y": -7, "z": -2, "c": "#8fa3ad"}, {"id": 1583, "x": 2, "y": -7, "z": -2.5, "c": "#4f6274"}, {"id": 1584, "x": 6, "y": -11, "z": -6, "c": "#5a4231"}, {"id": 1585, "x": 6, "y": -11, "z": -6.5, "c": "#4f6274"}, {"id": 1586, "x": 6, "y": -10, "z": -6, "c": "#8fa3ad"}, {"id": 1587, "x": 6, "y": -10, "z": -5.5, "c": "#86483f"}, {"id": 1588, "x": 6, "y": -9, "z": -6, "c": "#8fa3ad"}, {"id": 1589, "x": 6, "y": -9, "z": -6.5, "c": "#4f6274"}, {"id": 1590, "x": 6, "y": -8, "z": -6, "c": "#8fa3ad"}, {"id": 1591, "x": 6, "y": -8, "z": -5.5, "c": "#86483f"}, {"id": 1592, "x": 6, "y": -7, "z": -6, "c": "#8fa3ad"}, {"id": 1593, "x": 6, "y": -7, "z": -6.5, "c": "#4f6274"}, {"id": 1594, "x": 6, "y": -11, "z": -5, "c": "#5a4231"}, {"id": 1595, "x": 6, "y": -11, "z": -5.5, "c": "#4f6274"}, {"id": 1596, "x": 6, "y": -10, "z": -5, "c": "#674f3c"}, {"id": 1597, "x": 6, "y": -10, "z": -4.5, "c": "#86483f"}, {"id": 1598, "x": 6, "y": -9, "z": -5, "c": "#674f3c"}, {"id": 1599, "x": 6, "y": -9, "z": -5.5, "c": "#4f6274"}, {"id": 1600, "x": 6, "y": -8, "z": -5, "c": "#674f3c"}, {"id": 1601, "x": 6, "y": -8, "z": -4.5, "c": "#86483f"}, {"id": 1602, "x": 6, "y": -7, "z": -5, "c": "#674f3c"}, {"id": 1603, "x": 6, "y": -7, "z": -5.5, "c": "#4f6274"}, {"id": 1604, "x": 6, "y": -11, "z": -4, "c": "#5a4231"}, {"id": 1605, "x": 6, "y": -11, "z": -4.5, "c": "#4f6274"}, {"id": 1606, "x": 6, "y": -10, "z": -4, "c": "#674f3c"}, {"id": 1607, "x": 6, "y": -10, "z": -3.5, "c": "#86483f"}, {"id": 1608, "x": 6, "y": -9, "z": -4, "c": "#674f3c"}, {"id": 1609, "x": 6, "y": -9, "z": -4.5, "c": "#4f6274"}, {"id": 1610, "x": 6, "y": -8, "z": -4, "c": "#674f3c"}, {"id": 1611, "x": 6, "y": -8, "z": -3.5, "c": "#86483f"}, {"id": 1612, "x": 6, "y": -7, "z": -4, "c": "#674f3c"}, {"id": 1613, "x": 6, "y": -7, "z": -4.5, "c": "#4f6274"}, {"id": 1614, "x": 6, "y": -11, "z": -3, "c": "#5a4231"}, {"id": 1615, "x": 6, "y": -11, "z": -3.5, "c": "#4f6274"}, {"id": 1616, "x": 6, "y": -10, "z": -3, "c": "#674f3c"}, {"id": 1617, "x": 6, "y": -10, "z": -2.5, "c": "#86483f"}, {"id": 1618, "x": 6, "y": -9, "z": -3, "c": "#674f3c"}, {"id": 1619, "x": 6, "y": -9, "z": -3.5, "c": "#4f6274"}, {"id": 1620, "x": 6, "y": -8, "z": -3, "c": "#674f3c"}, {"id": 1621, "x": 6, "y": -8, "z": -2.5, "c": "#86483f"}, {"id": 1622, "x": 6, "y": -7, "z": -3, "c": "#674f3c"}, {"id": 1623, "x": 6, "y": -7, "z": -3.5, "c": "#4f6274"}, {"id": 1624, "x": 6, "y": -11, "z": -2, "c": "#5a4231"}, {"id": 1625, "x": 6, "y": -11, "z": -2.5, "c": "#4f6274"}, {"id": 1626, "x": 6, "y": -10, "z": -2, "c": "#8fa3ad"}, {"id": 1627, "x": 6, "y": -10, "z": -1.5, "c": "#86483f"}, {"id": 1628, "x": 6, "y": -9, "z": -2, "c": "#8fa3ad"}, {"id": 1629, "x": 6, "y": -9, "z": -2.5, "c": "#4f6274"}, {"id": 1630, "x": 6, "y": -8, "z": -2, "c": "#8fa3ad"}, {"id": 1631, "x": 6, "y": -8, "z": -1.5, "c": "#86483f"}, {"id": 1632, "x": 6, "y": -7, "z": -2, "c": "#8fa3ad"}, {"id": 1633, "x": 6, "y": -7, "z": -2.5, "c": "#4f6274"}, {"id": 1634, "x": -4, "y": -11, "z": 4, "c": "#5a4231"}, {"id": 1635, "x": -4, "y": -10, "z": 4, "c": "#8fa3ad"}, {"id": 1636, "x": -4, "y": -10, "z": 4.5, "c": "#b18b57"}, {"id": 1637, "x": 0, "y": -11, "z": 4, "c": "#5a4231"}, {"id": 1638, "x": 0, "y": -10, "z": 4, "c": "#8fa3ad"}, {"id": 1639, "x": 0, "y": -10, "z": 4.5, "c": "#b18b57"}, {"id": 1640, "x": 4, "y": -11, "z": 4, "c": "#5a4231"}, {"id": 1641, "x": 4, "y": -10, "z": 4, "c": "#8fa3ad"}, {"id": 1642, "x": 4, "y": -10, "z": 4.5, "c": "#b18b57"}, {"id": 1643, "x": -2, "y": -13, "z": 0, "c": "#c6beb1"}, {"id": 1644, "x": -1, "y": -13, "z": 0, "c": "#c6beb1"}, {"id": 1645, "x": 0, "y": -13, "z": 0, "c": "#c6beb1"}, {"id": 1646, "x": 1, "y": -13, "z": 0, "c": "#c6beb1"}, {"id": 1647, "x": 2, "y": -13, "z": 0, "c": "#c6beb1"}]}