{
  "voxels": [
    {
      "id": 0,
      "x": -12,
      "y": -12,
      "z": -10,
      "c": "#6f7378"
    },
    {
      "id": 1,
      "x": -12,
      "y": -12,
      "z": -9,
      "c": "#6f7378"
    },
    {
      "id": 2,
      "x": -12,
      "y": -12,
      "z": -8,
      "c": "#6f7378"
    },
    {
      "id": 3,
      "x": -12,
      "y": -12,
      "z": -7,
      "c": "#6f7378"
    },
    {
      "id": 4,
      "x": -12,
      "y": -12,
      "z": -6,
      "c": "#6f7378"
    },
    {
      "id": 5,
      "x": -12,
      "y": -12,
      "z": -5,
      "c": "#6f7378"
    },
    {
      "id": 6,
      "x": -12,
      "y": -12,
      "z": -4,
      "c": "#6f7378"
    },
    {
      "id": 7,
      "x": -12,
      "y": -12,
      "z": -3,
      "c": "#6f7378"
    },
    {
      "id": 8,
      "x": -12,
      "y": -12,
      "z": -2,
      "c": "#6f7378"
    },
    {
      "id": 9,
      "x": -12,
      "y": -12,
      "z": -1,
      "c": "#6f7378"
    },
    {
      "id": 10,
      "x": -12,
      "y": -12,
      "z": 0,
      "c": "#c6beb1"
    },
    {
      "id": 11,
      "x": -12,
      "y": -12,
      "z": 1,
      "c": "#6f7378"
    },
    {
      "id": 12,
      "x": -12,
      "y": -12,
      "z": 2,
      "c": "#6f7378"
    },
    {
      "id": 13,
      "x": -12,
      "y": -12,
      "z": 3,
      "c": "#6f7378"
    },
    {
      "id": 14,
      "x": -12,
      "y": -12,
      "z": 4,
      "c": "#6f7378"
    },
    {
      "id": 15,
      "x": -12,
      "y": -12,
      "z": 5,
      "c": "#6f7378"
    },
    {
      "id": 16,
      "x": -12,
      "y": -12,
      "z": 6,
      "c": "#6f7378"
    },
    {
      "id": 17,
      "x": -12,
      "y": -12,
      "z": 7,
      "c": "#6f7378"
    },
    {
      "id": 18,
      "x": -12,
      "y": -12,
      "z": 8,
      "c": "#6f7378"
    },
    {
      "id": 19,
      "x": -12,
      "y": -12,
      "z": 9,
      "c": "#6f7378"
    },
    {
      "id": 20,
      "x": -12,
      "y": -12,
      "z": 10,
      "c": "#6f7378"
    },
    {
      "id": 21,
      "x": -11,
      "y": -12,
      "z": -10,
      "c": "#6f7378"
    },
    {
      "id": 22,
      "x": -11,
      "y": -12,
      "z": -9,
      "c": "#6f7378"
    },
    {
      "id": 23,
      "x": -11,
      "y": -12,
      "z": -8,
      "c": "#6f7378"
    },
    {
      "id": 24,
      "x": -11,
      "y": -12,
      "z": -7,
      "c": "#6f7378"
    },
    {
      "id": 25,
      "x": -11,
      "y": -12,
      "z": -6,
      "c": "#6f7378"
    },
    {
      "id": 26,
      "x": -11,
      "y": -12,
      "z": -5,
      "c": "#6f7378"
    },
    {
      "id": 27,
      "x": -11,
      "y": -12,
      "z": -4,
      "c": "#6f7378"
    },
    {
      "id": 28,
      "x": -11,
      "y": -12,
      "z": -3,
      "c": "#6f7378"
    },
    {
      "id": 29,
      "x": -11,
      "y": -12,
      "z": -2,
      "c": "#6f7378"
    },
    {
      "id": 30,
      "x": -11,
      "y": -12,
      "z": -1,
      "c": "#c6beb1"
    },
    {
      "id": 31,
      "x": -11,
      "y": -12,
      "z": 0,
      "c": "#c6beb1"
    },
    {
      "id": 32,
      "x": -11,
      "y": -12,
      "z": 1,
      "c": "#c6beb1"
    },
    {
      "id": 33,
      "x": -11,
      "y": -12,
      "z": 2,
      "c": "#6f7378"
    },
    {
      "id": 34,
      "x": -11,
      "y": -12,
      "z": 3,
      "c": "#6f7378"
    },
    {
      "id": 35,
      "x": -11,
      "y": -12,
      "z": 4,
      "c": "#6f7378"
    },
    {
      "id": 36,
      "x": -11,
      "y": -12,
      "z": 5,
      "c": "#6f7378"
    },
    {
      "id": 37,
      "x": -11,
      "y": -12,
      "z": 6,
      "c": "#6f7378"
    },
    {
      "id": 38,
      "x": -11,
      "y": -12,
      "z": 7,
      "c": "#6f7378"
    },
    {
      "id": 39,
      "x": -11,
      "y": -12,
      "z": 8,
      "c": "#6f7378"
    },
    {
      "id": 40,
      "x": -11,
      "y": -12,
      "z": 9,
      "c": "#6f7378"
    },
    {
      "id": 41,
      "x": -11,
      "y": -12,
      "z": 10,
      "c": "#6f7378"
    },
    {
      "id": 42,
      "x": -10,
      "y": -12,
      "z": -10,
      "c": "#6f7378"
    },
    {
      "id": 43,
      "x": -10,
      "y": -12,
      "z": -9,
      "c": "#6f7378"
    },
    {
      "id": 44,
      "x": -10,
      "y": -12,
      "z": -8,
      "c": "#6f7378"
    },
    {
      "id": 45,
      "x": -10,
      "y": -12,
      "z": -7,
      "c": "#6f7378"
    },
    {
      "id": 46,
      "x": -10,
      "y": -12,
      "z": -6,
      "c": "#6f7378"
    },
    {
      "id": 47,
      "x": -10,
      "y": -12,
      "z": -5,
      "c": "#6f7378"
    },
    {
      "id": 48,
      "x": -10,
      "y": -12,
      "z": -4,
      "c": "#6f7378"
    },
    {
      "id": 49,
      "x": -10,
      "y": -12,
      "z": -3,
      "c": "#6f7378"
    },
    {
      "id": 50,
      "x": -10,
      "y": -12,
      "z": -2,
      "c": "#c6beb1"
    },
    {
      "id": 51,
      "x": -10,
      "y": -12,
      "z": -1,
      "c": "#c6beb1"
    },
    {
      "id": 52,
      "x": -10,
      "y": -12,
      "z": 0,
      "c": "#c6beb1"
    },
    {
      "id": 53,
      "x": -10,
      "y": -12,
      "z": 1,
      "c": "#c6beb1"
    },
    {
      "id": 54,
      "x": -10,
      "y": -12,
      "z": 2,
      "c": "#c6beb1"
    },
    {
      "id": 55,
      "x": -10,
      "y": -12,
      "z": 3,
      "c": "#6f7378"
    },
    {
      "id": 56,
      "x": -10,
      "y": -12,
      "z": 4,
      "c": "#6f7378"
    },
    {
      "id": 57,
      "x": -10,
      "y": -12,
      "z": 5,
      "c": "#6f7378"
    },
    {
      "id": 58,
      "x": -10,
      "y": -12,
      "z": 6,
      "c": "#6f7378"
    },
    {
      "id": 59,
      "x": -10,
      "y": -12,
      "z": 7,
      "c": "#6f7378"
    },
    {
      "id": 60,
      "x": -10,
      "y": -12,
      "z": 8,
      "c": "#6f7378"
    },
    {
      "id": 61,
      "x": -10,
      "y": -12,
      "z": 9,
      "c": "#6f7378"
    },
    {
      "id": 62,
      "x": -10,
      "y": -12,
      "z": 10,
      "c": "#6f7378"
    },
    {
      "id": 63,
      "x": -9,
      "y": -12,
      "z": -10,
      "c": "#6f7378"
    },
    {
      "id": 64,
      "x": -9,
      "y": -12,
      "z": -9,
      "c": "#6f7378"
    },
    {
      "id": 65,
      "x": -9,
      "y": -12,
      "z": -8,
      "c": "#6f7378"
    },
    {
      "id": 66,
      "x": -9,
      "y": -12,
      "z": -7,
      "c": "#6f7378"
    },
    {
      "id": 67,
      "x": -9,
      "y": -12,
      "z": -6,
      "c": "#6f7378"
    },
    {
      "id": 68,
      "x": -9,
      "y": -12,
      "z": -5,
      "c": "#6f7378"
    },
    {
      "id": 69,
      "x": -9,
      "y": -12,
      "z": -4,
      "c": "#6f7378"
    },
    {
      "id": 70,
      "x": -9,
      "y": -12,
      "z": -3,
      "c": "#c6beb1"
    },
    {
      "id": 71,
      "x": -9,
      "y": -12,
      "z": -2,
      "c": "#c6beb1"
    },
    {
      "id": 72,
      "x": -9,
      "y": -12,
      "z": -1,
      "c": "#c6beb1"
    },
    {
      "id": 73,
      "x": -9,
      "y": -12,
      "z": 0,
      "c": "#c6beb1"
    },
    {
      "id": 74,
      "x": -9,
      "y": -12,
      "z": 1,
      "c": "#c6beb1"
    },
    {
      "id": 75,
      "x": -9,
      "y": -12,
      "z": 2,
      "c": "#c6beb1"
    },
    {
      "id": 76,
      "x": -9,
      "y": -12,
      "z": 3,
      "c": "#c6beb1"
    },
    {
      "id": 77,
      "x": -9,
      "y": -12,
      "z": 4,
      "c": "#6f7378"
    },
    {
      "id": 78,
      "x": -9,
      "y": -12,
      "z": 5,
      "c": "#6f7378"
    },
    {
      "id": 79,
      "x": -9,
      "y": -12,
      "z": 6,
      "c": "#6f7378"
    },
    {
      "id": 80,
      "x": -9,
      "y": -12,
      "z": 7,
      "c": "#6f7378"
    },
    {
      "id": 81,
      "x": -9,
      "y": -12,
      "z": 8,
      "c": "#6f7378"
    },
    {
      "id": 82,
      "x": -9,
      "y": -12,
      "z": 9,
      "c": "#6f7378"
    },
    {
      "id": 83,
      "x": -9,
      "y": -12,
      "z": 10,
      "c": "#6f7378"
    },
    {
      "id": 84,
      "x": -8,
      "y": -12,
      "z": -10,
      "c": "#6f7378"
    },
    {
      "id": 85,
      "x": -8,
      "y": -12,
      "z": -9,
      "c": "#6f7378"
    },
    {
      "id": 86,
      "x": -8,
      "y": -12,
      "z": -8,
      "c": "#6f7378"
    },
    {
      "id": 87,
      "x": -8,
      "y": -12,
      "z": -7,
      "c": "#6f7378"
    },
    {
      "id": 88,
      "x": -8,
      "y": -12,
      "z": -6,
      "c": "#6f7378"
    },
    {
      "id": 89,
      "x": -8,
      "y": -12,
      "z": -5,
      "c": "#6f7378"
    },
    {
      "id": 90,
      "x": -8,
      "y": -12,
      "z": -4,
      "c": "#c6beb1"
    },
    {
      "id": 91,
      "x": -8,
      "y": -12,
      "z": -3,
      "c": "#c6beb1"
    },
    {
      "id": 92,
      "x": -8,
      "y": -12,
      "z": -2,
      "c": "#c6beb1"
    },
    {
      "id": 93,
      "x": -8,
      "y": -12,
      "z": -1,
      "c": "#c6beb1"
    },
    {
      "id": 94,
      "x": -8,
      "y": -12,
      "z": 0,
      "c": "#9ca2a6"
    },
    {
      "id": 95,
      "x": -8,
      "y": -12,
      "z": 1,
      "c": "#c6beb1"
    },
    {
      "id": 96,
      "x": -8,
      "y": -12,
      "z": 2,
      "c": "#c6beb1"
    },
    {
      "id": 97,
      "x": -8,
      "y": -12,
      "z": 3,
      "c": "#c6beb1"
    },
    {
      "id": 98,
      "x": -8,
      "y": -12,
      "z": 4,
      "c": "#c6beb1"
    },
    {
      "id": 99,
      "x": -8,
      "y": -12,
      "z": 5,
      "c": "#6f7378"
    },
    {
      "id": 100,
      "x": -8,
      "y": -12,
      "z": 6,
      "c": "#6f7378"
    },
    {
      "id": 101,
      "x": -8,
      "y": -12,
      "z": 7,
      "c": "#6f7378"
    },
    {
      "id": 102,
      "x": -8,
      "y": -12,
      "z": 8,
      "c": "#6f7378"
    },
    {
      "id": 103,
      "x": -8,
      "y": -12,
      "z": 9,
      "c": "#6f7378"
    },
    {
      "id": 104,
      "x": -8,
      "y": -12,
      "z": 10,
      "c": "#6f7378"
    },
    {
      "id": 105,
      "x": -7,
      "y": -12,
      "z": -10,
      "c": "#6f7378"
    },
    {
      "id": 106,
      "x": -7,
      "y": -12,
      "z": -9,
      "c": "#6f7378"
    },
    {
      "id": 107,
      "x": -7,
      "y": -12,
      "z": -8,
      "c": "#6f7378"
    },
    {
      "id": 108,
      "x": -7,
      "y": -12,
      "z": -7,
      "c": "#6f7378"
    },
    {
      "id": 109,
      "x": -7,
      "y": -12,
      "z": -6,
      "c": "#6f7378"
    },
    {
      "id": 110,
      "x": -7,
      "y": -12,
      "z": -5,
      "c": "#c6beb1"
    },
    {
      "id": 111,
      "x": -7,
      "y": -12,
      "z": -4,
      "c": "#c6beb1"
    },
    {
      "id": 112,
      "x": -7,
      "y": -12,
      "z": -3,
      "c": "#c6beb1"
    },
    {
      "id": 113,
      "x": -7,
      "y": -12,
      "z": -2,
      "c": "#c6beb1"
    },
    {
      "id": 114,
      "x": -7,
      "y": -12,
      "z": -1,
      "c": "#9ca2a6"
    },
    {
      "id": 115,
      "x": -7,
      "y": -12,
      "z": 0,
      "c": "#9ca2a6"
    },
    {
      "id": 116,
      "x": -7,
      "y": -12,
      "z": 1,
      "c": "#9ca2a6"
    },
    {
      "id": 117,
      "x": -7,
      "y": -12,
      "z": 2,
      "c": "#c6beb1"
    },
    {
      "id": 118,
      "x": -7,
      "y": -12,
      "z": 3,
      "c": "#c6beb1"
    },
    {
      "id": 119,
      "x": -7,
      "y": -12,
      "z": 4,
      "c": "#c6beb1"
    },
    {
      "id": 120,
      "x": -7,
      "y": -12,
      "z": 5,
      "c": "#c6beb1"
    },
    {
      "id": 121,
      "x": -7,
      "y": -12,
      "z": 6,
      "c": "#6f7378"
    },
    {
      "id": 122,
      "x": -7,
      "y": -12,
      "z": 7,
      "c": "#6f7378"
    },
    {
      "id": 123,
      "x": -7,
      "y": -12,
      "z": 8,
      "c": "#6f7378"
    },
    {
      "id": 124,
      "x": -7,
      "y": -12,
      "z": 9,
      "c": "#6f7378"
    },
    {
      "id": 125,
      "x": -7,
      "y": -12,
      "z": 10,
      "c": "#6f7378"
    },
    {
      "id": 126,
      "x": -6,
      "y": -12,
      "z": -10,
      "c": "#6f7378"
    },
    {
      "id": 127,
      "x": -6,
      "y": -12,
      "z": -9,
      "c": "#6f7378"
    },
    {
      "id": 128,
      "x": -6,
      "y": -12,
      "z": -8,
      "c": "#6f7378"
    },
    {
      "id": 129,
      "x": -6,
      "y": -12,
      "z": -7,
      "c": "#6f7378"
    },
    {
      "id": 130,
      "x": -6,
      "y": -12,
      "z": -6,
      "c": "#c6beb1"
    },
    {
      "id": 131,
      "x": -6,
      "y": -12,
      "z": -5,
      "c": "#c6beb1"
    },
    {
      "id": 132,
      "x": -6,
      "y": -12,
      "z": -4,
      "c": "#c6beb1"
    },
    {
      "id": 133,
      "x": -6,
      "y": -12,
      "z": -3,
      "c": "#c6beb1"
    },
    {
      "id": 134,
      "x": -6,
      "y": -12,
      "z": -2,
      "c": "#9ca2a6"
    },
    {
      "id": 135,
      "x": -6,
      "y": -12,
      "z": -1,
      "c": "#9ca2a6"
    },
    {
      "id": 136,
      "x": -6,
      "y": -12,
      "z": 0,
      "c": "#9ca2a6"
    },
    {
      "id": 137,
      "x": -6,
      "y": -12,
      "z": 1,
      "c": "#9ca2a6"
    },
    {
      "id": 138,
      "x": -6,
      "y": -12,
      "z": 2,
      "c": "#9ca2a6"
    },
    {
      "id": 139,
      "x": -6,
      "y": -12,
      "z": 3,
      "c": "#c6beb1"
    },
    {
      "id": 140,
      "x": -6,
      "y": -12,
      "z": 4,
      "c": "#c6beb1"
    },
    {
      "id": 141,
      "x": -6,
      "y": -12,
      "z": 5,
      "c": "#c6beb1"
    },
    {
      "id": 142,
      "x": -6,
      "y": -12,
      "z": 6,
      "c": "#c6beb1"
    },
    {
      "id": 143,
      "x": -6,
      "y": -12,
      "z": 7,
      "c": "#6f7378"
    },
    {
      "id": 144,
      "x": -6,
      "y": -12,
      "z": 8,
      "c": "#6f7378"
    },
    {
      "id": 145,
      "x": -6,
      "y": -12,
      "z": 9,
      "c": "#6f7378"
    },
    {
      "id": 146,
      "x": -6,
      "y": -12,
      "z": 10,
      "c": "#6f7378"
    },
    {
      "id": 147,
      "x": -5,
      "y": -12,
      "z": -10,
      "c": "#6f7378"
    },
    {
      "id": 148,
      "x": -5,
      "y": -12,
      "z": -9,
      "c": "#6f7378"
    },
    {
      "id": 149,
      "x": -5,
      "y": -12,
      "z": -8,
      "c": "#6f7378"
    },
    {
      "id": 150,
      "x": -5,
      "y": -12,
      "z": -7,
      "c": "#c6beb1"
    },
    {
      "id": 151,
      "x": -5,
      "y": -12,
      "z": -6,
      "c": "#c6beb1"
    },
    {
      "id": 152,
      "x": -5,
      "y": -12,
      "z": -5,
      "c": "#c6beb1"
    },
    {
      "id": 153,
      "x": -5,
      "y": -12,
      "z": -4,
      "c": "#c6beb1"
    },
    {
      "id": 154,
      "x": -5,
      "y": -12,
      "z": -3,
      "c": "#9ca2a6"
    },
    {
      "id": 155,
      "x": -5,
      "y": -12,
      "z": -2,
      "c": "#9ca2a6"
    },
    {
      "id": 156,
      "x": -5,
      "y": -12,
      "z": -1,
      "c": "#9ca2a6"
    },
    {
      "id": 157,
      "x": -5,
      "y": -12,
      "z": 0,
      "c": "#9ca2a6"
    },
    {
      "id": 158,
      "x": -5,
      "y": -12,
      "z": 1,
      "c": "#9ca2a6"
    },
    {
      "id": 159,
      "x": -5,
      "y": -12,
      "z": 2,
      "c": "#9ca2a6"
    },
    {
      "id": 160,
      "x": -5,
      "y": -12,
      "z": 3,
      "c": "#9ca2a6"
    },
    {
      "id": 161,
      "x": -5,
      "y": -12,
      "z": 4,
      "c": "#c6beb1"
    },
    {
      "id": 162,
      "x": -5,
      "y": -12,
      "z": 5,
      "c": "#c6beb1"
    },
    {
      "id": 163,
      "x": -5,
      "y": -12,
      "z": 6,
      "c": "#c6beb1"
    },
    {
      "id": 164,
      "x": -5,
      "y": -12,
      "z": 7,
      "c": "#c6beb1"
    },
    {
      "id": 165,
      "x": -5,
      "y": -12,
      "z": 8,
      "c": "#6f7378"
    },
    {
      "id": 166,
      "x": -5,
      "y": -12,
      "z": 9,
      "c": "#6f7378"
    },
    {
      "id": 167,
      "x": -5,
      "y": -12,
      "z": 10,
      "c": "#6f7378"
    },
    {
      "id": 168,
      "x": -4,
      "y": -12,
      "z": -10,
      "c": "#6f7378"
    },
    {
      "id": 169,
      "x": -4,
      "y": -12,
      "z": -9,
      "c": "#6f7378"
    },
    {
      "id": 170,
      "x": -4,
      "y": -12,
      "z": -8,
      "c": "#c6beb1"
    },
    {
      "id": 171,
      "x": -4,
      "y": -12,
      "z": -7,
      "c": "#c6beb1"
    },
    {
      "id": 172,
      "x": -4,
      "y": -12,
      "z": -6,
      "c": "#c6beb1"
    },
    {
      "id": 173,
      "x": -4,
      "y": -12,
      "z": -5,
      "c": "#c6beb1"
    },
    {
      "id": 174,
      "x": -4,
      "y": -12,
      "z": -4,
      "c": "#9ca2a6"
    },
    {
      "id": 175,
      "x": -4,
      "y": -12,
      "z": -3,
      "c": "#9ca2a6"
    },
    {
      "id": 176,
      "x": -4,
      "y": -12,
      "z": -2,
      "c": "#9ca2a6"
    },
    {
      "id": 177,
      "x": -4,
      "y": -12,
      "z": -1,
      "c": "#9ca2a6"
    },
    {
      "id": 178,
      "x": -4,
      "y": -12,
      "z": 0,
      "c": "#9ca2a6"
    },
    {
      "id": 179,
      "x": -4,
      "y": -12,
      "z": 1,
      "c": "#9ca2a6"
    },
    {
      "id": 180,
      "x": -4,
      "y": -12,
      "z": 2,
      "c": "#9ca2a6"
    },
    {
      "id": 181,
      "x": -4,
      "y": -12,
      "z": 3,
      "c": "#9ca2a6"
    },
    {
      "id": 182,
      "x": -4,
      "y": -12,
      "z": 4,
      "c": "#9ca2a6"
    },
    {
      "id": 183,
      "x": -4,
      "y": -12,
      "z": 5,
      "c": "#c6beb1"
    },
    {
      "id": 184,
      "x": -4,
      "y": -12,
      "z": 6,
      "c": "#c6beb1"
    },
    {
      "id": 185,
      "x": -4,
      "y": -12,
      "z": 7,
      "c": "#c6beb1"
    },
    {
      "id": 186,
      "x": -4,
      "y": -12,
      "z": 8,
      "c": "#c6beb1"
    },
    {
      "id": 187,
      "x": -4,
      "y": -12,
      "z": 9,
      "c": "#6f7378"
    },
    {
      "id": 188,
      "x": -4,
      "y": -12,
      "z": 10,
      "c": "#6f7378"
    },
    {
      "id": 189,
      "x": -3,
      "y": -12,
      "z": -10,
      "c": "#6f7378"
    },
    {
      "id": 190,
      "x": -3,
      "y": -12,
      "z": -9,
      "c": "#c6beb1"
    },
    {
      "id": 191,
      "x": -3,
      "y": -12,
      "z": -8,
      "c": "#c6beb1"
    },
    {
      "id": 192,
      "x": -3,
      "y": -12,
      "z": -7,
      "c": "#c6beb1"
    },
    {
      "id": 193,
      "x": -3,
      "y": -12,
      "z": -6,
      "c": "#c6beb1"
    },
    {
      "id": 194,
      "x": -3,
      "y": -12,
      "z": -5,
      "c": "#9ca2a6"
    },
    {
      "id": 195,
      "x": -3,
      "y": -12,
      "z": -4,
      "c": "#9ca2a6"
    },
    {
      "id": 196,
      "x": -3,
      "y": -12,
      "z": -3,
      "c": "#9ca2a6"
    },
    {
      "id": 197,
      "x": -3,
      "y": -12,
      "z": -2,
      "c": "#9ca2a6"
    },
    {
      "id": 198,
      "x": -3,
      "y": -12,
      "z": -1,
      "c": "#9ca2a6"
    },
    {
      "id": 199,
      "x": -3,
      "y": -12,
      "z": 0,
      "c": "#9ca2a6"
    },
    {
      "id": 200,
      "x": -3,
      "y": -12,
      "z": 1,
      "c": "#9ca2a6"
    },
    {
      "id": 201,
      "x": -3,
      "y": -12,
      "z": 2,
      "c": "#9ca2a6"
    },
    {
      "id": 202,
      "x": -3,
      "y": -12,
      "z": 3,
      "c": "#9ca2a6"
    },
    {
      "id": 203,
      "x": -3,
      "y": -12,
      "z": 4,
      "c": "#9ca2a6"
    },
    {
      "id": 204,
      "x": -3,
      "y": -12,
      "z": 5,
      "c": "#9ca2a6"
    },
    {
      "id": 205,
      "x": -3,
      "y": -12,
      "z": 6,
      "c": "#c6beb1"
    },
    {
      "id": 206,
      "x": -3,
      "y": -12,
      "z": 7,
      "c": "#c6beb1"
    },
    {
      "id": 207,
      "x": -3,
      "y": -12,
      "z": 8,
      "c": "#c6beb1"
    },
    {
      "id": 208,
      "x": -3,
      "y": -12,
      "z": 9,
      "c": "#c6beb1"
    },
    {
      "id": 209,
      "x": -3,
      "y": -12,
      "z": 10,
      "c": "#6f7378"
    },
    {
      "id": 210,
      "x": -2,
      "y": -12,
      "z": -10,
      "c": "#c6beb1"
    },
    {
      "id": 211,
      "x": -2,
      "y": -12,
      "z": -9,
      "c": "#c6beb1"
    },
    {
      "id": 212,
      "x": -2,
      "y": -12,
      "z": -8,
      "c": "#c6beb1"
    },
    {
      "id": 213,
      "x": -2,
      "y": -12,
      "z": -7,
      "c": "#c6beb1"
    },
    {
      "id": 214,
      "x": -2,
      "y": -12,
      "z": -6,
      "c": "#9ca2a6"
    },
    {
      "id": 215,
      "x": -2,
      "y": -12,
      "z": -5,
      "c": "#9ca2a6"
    },
    {
      "id": 216,
      "x": -2,
      "y": -12,
      "z": -4,
      "c": "#9ca2a6"
    },
    {
      "id": 217,
      "x": -2,
      "y": -12,
      "z": -3,
      "c": "#9ca2a6"
    },
    {
      "id": 218,
      "x": -2,
      "y": -12,
      "z": -2,
      "c": "#9ca2a6"
    },
    {
      "id": 219,
      "x": -2,
      "y": -12,
      "z": -1,
      "c": "#9ca2a6"
    },
    {
      "id": 220,
      "x": -2,
      "y": -12,
      "z": 0,
      "c": "#9ca2a6"
    },
    {
      "id": 221,
      "x": -2,
      "y": -12,
      "z": 1,
      "c": "#9ca2a6"
    },
    {
      "id": 222,
      "x": -2,
      "y": -12,
      "z": 2,
      "c": "#9ca2a6"
    },
    {
      "id": 223,
      "x": -2,
      "y": -12,
      "z": 3,
      "c": "#9ca2a6"
    },
    {
      "id": 224,
      "x": -2,
      "y": -12,
      "z": 4,
      "c": "#9ca2a6"
    },
    {
      "id": 225,
      "x": -2,
      "y": -12,
      "z": 5,
      "c": "#9ca2a6"
    },
    {
      "id": 226,
      "x": -2,
      "y": -12,
      "z": 6,
      "c": "#9ca2a6"
    },
    {
      "id": 227,
      "x": -2,
      "y": -12,
      "z": 7,
      "c": "#c6beb1"
    },
    {
      "id": 228,
      "x": -2,
      "y": -12,
      "z": 8,
      "c": "#c6beb1"
    },
    {
      "id": 229,
      "x": -2,
      "y": -12,
      "z": 9,
      "c": "#c6beb1"
    },
    {
      "id": 230,
      "x": -2,
      "y": -12,
      "z": 10,
      "c": "#c6beb1"
    },
    {
      "id": 231,
      "x": -1,
      "y": -12,
      "z": -10,
      "c": "#c6beb1"
    },
    {
      "id": 232,
      "x": -1,
      "y": -12,
      "z": -9,
      "c": "#c6beb1"
    },
    {
      "id": 233,
      "x": -1,
      "y": -12,
      "z": -8,
      "c": "#c6beb1"
    },
    {
      "id": 234,
      "x": -1,
      "y": -12,
      "z": -7,
      "c": "#9ca2a6"
    },
    {
      "id": 235,
      "x": -1,
      "y": -12,
      "z": -6,
      "c": "#9ca2a6"
    },
    {
      "id": 236,
      "x": -1,
      "y": -12,
      "z": -5,
      "c": "#9ca2a6"
    },
    {
      "id": 237,
      "x": -1,
      "y": -12,
      "z": -4,
      "c": "#9ca2a6"
    },
    {
      "id": 238,
      "x": -1,
      "y": -12,
      "z": -3,
      "c": "#9ca2a6"
    },
    {
      "id": 239,
      "x": -1,
      "y": -12,
      "z": -2,
      "c": "#9ca2a6"
    },
    {
      "id": 240,
      "x": -1,
      "y": -12,
      "z": -1,
      "c": "#9ca2a6"
    },
    {
      "id": 241,
      "x": -1,
      "y": -12,
      "z": 0,
      "c": "#9ca2a6"
    },
    {
      "id": 242,
      "x": -1,
      "y": -12,
      "z": 1,
      "c": "#9ca2a6"
    },
    {
      "id": 243,
      "x": -1,
      "y": -12,
      "z": 2,
      "c": "#9ca2a6"
    },
    {
      "id": 244,
      "x": -1,
      "y": -12,
      "z": 3,
      "c": "#9ca2a6"
    },
    {
      "id": 245,
      "x": -1,
      "y": -12,
      "z": 4,
      "c": "#9ca2a6"
    },
    {
      "id": 246,
      "x": -1,
      "y": -12,
      "z": 5,
      "c": "#9ca2a6"
    },
    {
      "id": 247,
      "x": -1,
      "y": -12,
      "z": 6,
      "c": "#9ca2a6"
    },
    {
      "id": 248,
      "x": -1,
      "y": -12,
      "z": 7,
      "c": "#9ca2a6"
    },
    {
      "id": 249,
      "x": -1,
      "y": -12,
      "z": 8,
      "c": "#c6beb1"
    },
    {
      "id": 250,
      "x": -1,
      "y": -12,
      "z": 9,
      "c": "#c6beb1"
    },
    {
      "id": 251,
      "x": -1,
      "y": -12,
      "z": 10,
      "c": "#c6beb1"
    },
    {
      "id": 252,
      "x": 0,
      "y": -12,
      "z": -10,
      "c": "#c6beb1"
    },
    {
      "id": 253,
      "x": 0,
      "y": -12,
      "z": -9,
      "c": "#c6beb1"
    },
    {
      "id": 254,
      "x": 0,
      "y": -12,
      "z": -8,
      "c": "#9ca2a6"
    },
    {
      "id": 255,
      "x": 0,
      "y": -12,
      "z": -7,
      "c": "#9ca2a6"
    },
    {
      "id": 256,
      "x": 0,
      "y": -12,
      "z": -6,
      "c": "#9ca2a6"
    },
    {
      "id": 257,
      "x": 0,
      "y": -12,
      "z": -5,
      "c": "#9ca2a6"
    },
    {
      "id": 258,
      "x": 0,
      "y": -12,
      "z": -4,
      "c": "#9ca2a6"
    },
    {
      "id": 259,
      "x": 0,
      "y": -12,
      "z": -3,
      "c": "#9ca2a6"
    },
    {
      "id": 260,
      "x": 0,
      "y": -12,
      "z": -2,
      "c": "#9ca2a6"
    },
    {
      "id": 261,
      "x": 0,
      "y": -12,
      "z": -1,
      "c": "#9ca2a6"
    },
    {
      "id": 262,
      "x": 0,
      "y": -12,
      "z": 0,
      "c": "#9ca2a6"
    },
    {
      "id": 263,
      "x": 0,
      "y": -12,
      "z": 1,
      "c": "#9ca2a6"
    },
    {
      "id": 264,
      "x": 0,
      "y": -12,
      "z": 2,
      "c": "#9ca2a6"
    },
    {
      "id": 265,
      "x": 0,
      "y": -12,
      "z": 3,
      "c": "#9ca2a6"
    },
    {
      "id": 266,
      "x": 0,
      "y": -12,
      "z": 4,
      "c": "#9ca2a6"
    },
    {
      "id": 267,
      "x": 0,
      "y": -12,
      "z": 5,
      "c": "#9ca2a6"
    },
    {
      "id": 268,
      "x": 0,
      "y": -12,
      "z": 6,
      "c": "#9ca2a6"
    },
    {
      "id": 269,
      "x": 0,
      "y": -12,
      "z": 7,
      "c": "#9ca2a6"
    },
    {
      "id": 270,
      "x": 0,
      "y": -12,
      "z": 8,
      "c": "#9ca2a6"
    },
    {
      "id": 271,
      "x": 0,
      "y": -12,
      "z": 9,
      "c": "#c6beb1"
    },
    {
      "id": 272,
      "x": 0,
      "y": -12,
      "z": 10,
      "c": "#c6beb1"
    },
    {
      "id": 273,
      "x": 1,
      "y": -12,
      "z": -10,
      "c": "#586a4b"
    },
    {
      "id": 274,
      "x": 1,
      "y": -12,
      "z": -9,
      "c": "#586a4b"
    },
    {
      "id": 275,
      "x": 1,
      "y": -12,
      "z": -8,
      "c": "#586a4b"
    },
    {
      "id": 276,
      "x": 1,
      "y": -12,
      "z": -7,
      "c": "#586a4b"
    },
    {
      "id": 277,
      "x": 1,
      "y": -12,
      "z": -6,
      "c": "#586a4b"
    },
    {
      "id": 278,
      "x": 1,
      "y": -12,
      "z": -5,
      "c": "#586a4b"
    },
    {
      "id": 279,
      "x": 1,
      "y": -12,
      "z": -4,
      "c": "#586a4b"
    },
    {
      "id": 280,
      "x": 1,
      "y": -12,
      "z": -3,
      "c": "#586a4b"
    },
    {
      "id": 281,
      "x": 1,
      "y": -12,
      "z": -2,
      "c": "#9ca2a6"
    },
    {
      "id": 282,
      "x": 1,
      "y": -12,
      "z": -1,
      "c": "#9ca2a6"
    },
    {
      "id": 283,
      "x": 1,
      "y": -12,
      "z": 0,
      "c": "#9ca2a6"
    },
    {
      "id": 284,
      "x": 1,
      "y": -12,
      "z": 1,
      "c": "#9ca2a6"
    },
    {
      "id": 285,
      "x": 1,
      "y": -12,
      "z": 2,
      "c": "#9ca2a6"
    },
    {
      "id": 286,
      "x": 1,
      "y": -12,
      "z": 3,
      "c": "#9ca2a6"
    },
    {
      "id": 287,
      "x": 1,
      "y": -12,
      "z": 4,
      "c": "#9ca2a6"
    },
    {
      "id": 288,
      "x": 1,
      "y": -12,
      "z": 5,
      "c": "#9ca2a6"
    },
    {
      "id": 289,
      "x": 1,
      "y": -12,
      "z": 6,
      "c": "#9ca2a6"
    },
    {
      "id": 290,
      "x": 1,
      "y": -12,
      "z": 7,
      "c": "#9ca2a6"
    },
    {
      "id": 291,
      "x": 1,
      "y": -12,
      "z": 8,
      "c": "#c6beb1"
    },
    {
      "id": 292,
      "x": 1,
      "y": -12,
      "z": 9,
      "c": "#c6beb1"
    },
    {
      "id": 293,
      "x": 1,
      "y": -12,
      "z": 10,
      "c": "#c6beb1"
    },
    {
      "id": 294,
      "x": 2,
      "y": -12,
      "z": -10,
      "c": "#586a4b"
    },
    {
      "id": 295,
      "x": 2,
      "y": -12,
      "z": -9,
      "c": "#586a4b"
    },
    {
      "id": 296,
      "x": 2,
      "y": -12,
      "z": -8,
      "c": "#586a4b"
    },
    {
      "id": 297,
      "x": 2,
      "y": -12,
      "z": -7,
      "c": "#586a4b"
    },
    {
      "id": 298,
      "x": 2,
      "y": -12,
      "z": -6,
      "c": "#586a4b"
    },
    {
      "id": 299,
      "x": 2,
      "y": -12,
      "z": -5,
      "c": "#586a4b"
    },
    {
      "id": 300,
      "x": 2,
      "y": -12,
      "z": -4,
      "c": "#586a4b"
    },
    {
      "id": 301,
      "x": 2,
      "y": -12,
      "z": -3,
      "c": "#586a4b"
    },
    {
      "id": 302,
      "x": 2,
      "y": -12,
      "z": -2,
      "c": "#9ca2a6"
    },
    {
      "id": 303,
      "x": 2,
      "y": -12,
      "z": -1,
      "c": "#9ca2a6"
    },
    {
      "id": 304,
      "x": 2,
      "y": -12,
      "z": 0,
      "c": "#9ca2a6"
    },
    {
      "id": 305,
      "x": 2,
      "y": -12,
      "z": 1,
      "c": "#9ca2a6"
    },
    {
      "id": 306,
      "x": 2,
      "y": -12,
      "z": 2,
      "c": "#9ca2a6"
    },
    {
      "id": 307,
      "x": 2,
      "y": -12,
      "z": 3,
      "c": "#9ca2a6"
    },
    {
      "id": 308,
      "x": 2,
      "y": -12,
      "z": 4,
      "c": "#9ca2a6"
    },
    {
      "id": 309,
      "x": 2,
      "y": -12,
      "z": 5,
      "c": "#9ca2a6"
    },
    {
      "id": 310,
      "x": 2,
      "y": -12,
      "z": 6,
      "c": "#9ca2a6"
    },
    {
      "id": 311,
      "x": 2,
      "y": -12,
      "z": 7,
      "c": "#c6beb1"
    },
    {
      "id": 312,
      "x": 2,
      "y": -12,
      "z": 8,
      "c": "#c6beb1"
    },
    {
      "id": 313,
      "x": 2,
      "y": -12,
      "z": 9,
      "c": "#c6beb1"
    },
    {
      "id": 314,
      "x": 2,
      "y": -12,
      "z": 10,
      "c": "#c6beb1"
    },
    {
      "id": 315,
      "x": 3,
      "y": -12,
      "z": -10,
      "c": "#586a4b"
    },
    {
      "id": 316,
      "x": 3,
      "y": -12,
      "z": -9,
      "c": "#586a4b"
    },
    {
      "id": 317,
      "x": 3,
      "y": -12,
      "z": -8,
      "c": "#586a4b"
    },
    {
      "id": 318,
      "x": 3,
      "y": -12,
      "z": -7,
      "c": "#586a4b"
    },
    {
      "id": 319,
      "x": 3,
      "y": -12,
      "z": -6,
      "c": "#586a4b"
    },
    {
      "id": 320,
      "x": 3,
      "y": -12,
      "z": -5,
      "c": "#586a4b"
    },
    {
      "id": 321,
      "x": 3,
      "y": -12,
      "z": -4,
      "c": "#586a4b"
    },
    {
      "id": 322,
      "x": 3,
      "y": -12,
      "z": -3,
      "c": "#586a4b"
    },
    {
      "id": 323,
      "x": 3,
      "y": -12,
      "z": -2,
      "c": "#9ca2a6"
    },
    {
      "id": 324,
      "x": 3,
      "y": -12,
      "z": -1,
      "c": "#9ca2a6"
    },
    {
      "id": 325,
      "x": 3,
      "y": -12,
      "z": 0,
      "c": "#9ca2a6"
    },
    {
      "id": 326,
      "x": 3,
      "y": -12,
      "z": 1,
      "c": "#9ca2a6"
    },
    {
      "id": 327,
      "x": 3,
      "y": -12,
      "z": 2,
      "c": "#9ca2a6"
    },
    {
      "id": 328,
      "x": 3,
      "y": -12,
      "z": 3,
      "c": "#30363d"
    },
    {
      "id": 329,
      "x": 3,
      "y": -12,
      "z": 4,
      "c": "#30363d"
    },
    {
      "id": 330,
      "x": 3,
      "y": -12,
      "z": 5,
      "c": "#30363d"
    },
    {
      "id": 331,
      "x": 3,
      "y": -12,
      "z": 6,
      "c": "#30363d"
    },
    {
      "id": 332,
      "x": 3,
      "y": -12,
      "z": 7,
      "c": "#30363d"
    },
    {
      "id": 333,
      "x": 3,
      "y": -12,
      "z": 8,
      "c": "#30363d"
    },
    {
      "id": 334,
      "x": 3,
      "y": -12,
      "z": 9,
      "c": "#30363d"
    },
    {
      "id": 335,
      "x": 3,
      "y": -12,
      "z": 10,
      "c": "#30363d"
    },
    {
      "id": 336,
      "x": 4,
      "y": -12,
      "z": -10,
      "c": "#586a4b"
    },
    {
      "id": 337,
      "x": 4,
      "y": -12,
      "z": -9,
      "c": "#586a4b"
    },
    {
      "id": 338,
      "x": 4,
      "y": -12,
      "z": -8,
      "c": "#586a4b"
    },
    {
      "id": 339,
      "x": 4,
      "y": -12,
      "z": -7,
      "c": "#586a4b"
    },
    {
      "id": 340,
      "x": 4,
      "y": -12,
      "z": -6,
      "c": "#586a4b"
    },
    {
      "id": 341,
      "x": 4,
      "y": -12,
      "z": -5,
      "c": "#586a4b"
    },
    {
      "id": 342,
      "x": 4,
      "y": -12,
      "z": -4,
      "c": "#586a4b"
    },
    {
      "id": 343,
      "x": 4,
      "y": -12,
      "z": -3,
      "c": "#586a4b"
    },
    {
      "id": 344,
      "x": 4,
      "y": -12,
      "z": -2,
      "c": "#9ca2a6"
    },
    {
      "id": 345,
      "x": 4,
      "y": -12,
      "z": -1,
      "c": "#9ca2a6"
    },
    {
      "id": 346,
      "x": 4,
      "y": -12,
      "z": 0,
      "c": "#9ca2a6"
    },
    {
      "id": 347,
      "x": 4,
      "y": -12,
      "z": 1,
      "c": "#9ca2a6"
    },
    {
      "id": 348,
      "x": 4,
      "y": -12,
      "z": 2,
      "c": "#9ca2a6"
    },
    {
      "id": 349,
      "x": 4,
      "y": -12,
      "z": 3,
      "c": "#30363d"
    },
    {
      "id": 350,
      "x": 4,
      "y": -12,
      "z": 4,
      "c": "#30363d"
    },
    {
      "id": 351,
      "x": 4,
      "y": -12,
      "z": 5,
      "c": "#30363d"
    },
    {
      "id": 352,
      "x": 4,
      "y": -12,
      "z": 6,
      "c": "#30363d"
    },
    {
      "id": 353,
      "x": 4,
      "y": -12,
      "z": 7,
      "c": "#30363d"
    },
    {
      "id": 354,
      "x": 4,
      "y": -12,
      "z": 8,
      "c": "#30363d"
    },
    {
      "id": 355,
      "x": 4,
      "y": -12,
      "z": 9,
      "c": "#30363d"
    },
    {
      "id": 356,
      "x": 4,
      "y": -12,
      "z": 10,
      "c": "#30363d"
    },
    {
      "id": 357,
      "x": 5,
      "y": -12,
      "z": -10,
      "c": "#586a4b"
    },
    {
      "id": 358,
      "x": 5,
      "y": -12,
      "z": -9,
      "c": "#586a4b"
    },
    {
      "id": 359,
      "x": 5,
      "y": -12,
      "z": -8,
      "c": "#586a4b"
    },
    {
      "id": 360,
      "x": 5,
      "y": -12,
      "z": -7,
      "c": "#586a4b"
    },
    {
      "id": 361,
      "x": 5,
      "y": -12,
      "z": -6,
      "c": "#586a4b"
    },
    {
      "id": 362,
      "x": 5,
      "y": -12,
      "z": -5,
      "c": "#586a4b"
    },
    {
      "id": 363,
      "x": 5,
      "y": -12,
      "z": -4,
      "c": "#586a4b"
    },
    {
      "id": 364,
      "x": 5,
      "y": -12,
      "z": -3,
      "c": "#586a4b"
    },
    {
      "id": 365,
      "x": 5,
      "y": -12,
      "z": -2,
      "c": "#9ca2a6"
    },
    {
      "id": 366,
      "x": 5,
      "y": -12,
      "z": -1,
      "c": "#9ca2a6"
    },
    {
      "id": 367,
      "x": 5,
      "y": -12,
      "z": 0,
      "c": "#9ca2a6"
    },
    {
      "id": 368,
      "x": 5,
      "y": -12,
      "z": 1,
      "c": "#9ca2a6"
    },
    {
      "id": 369,
      "x": 5,
      "y": -12,
      "z": 2,
      "c": "#9ca2a6"
    },
    {
      "id": 370,
      "x": 5,
      "y": -12,
      "z": 3,
      "c": "#30363d"
    },
    {
      "id": 371,
      "x": 5,
      "y": -12,
      "z": 4,
      "c": "#30363d"
    },
    {
      "id": 372,
      "x": 5,
      "y": -12,
      "z": 5,
      "c": "#30363d"
    },
    {
      "id": 373,
      "x": 5,
      "y": -12,
      "z": 6,
      "c": "#30363d"
    },
    {
      "id": 374,
      "x": 5,
      "y": -12,
      "z": 7,
      "c": "#30363d"
    },
    {
      "id": 375,
      "x": 5,
      "y": -12,
      "z": 8,
      "c": "#30363d"
    },
    {
      "id": 376,
      "x": 5,
      "y": -12,
      "z": 9,
      "c": "#30363d"
    },
    {
      "id": 377,
      "x": 5,
      "y": -12,
      "z": 10,
      "c": "#30363d"
    },
    {
      "id": 378,
      "x": 6,
      "y": -12,
      "z": -10,
      "c": "#586a4b"
    },
    {
      "id": 379,
      "x": 6,
      "y": -12,
      "z": -9,
      "c": "#586a4b"
    },
    {
      "id": 380,
      "x": 6,
      "y": -12,
      "z": -8,
      "c": "#586a4b"
    },
    {
      "id": 381,
      "x": 6,
      "y": -12,
      "z": -7,
      "c": "#586a4b"
    },
    {
      "id": 382,
      "x": 6,
      "y": -12,
      "z": -6,
      "c": "#586a4b"
    },
    {
      "id": 383,
      "x": 6,
      "y": -12,
      "z": -5,
      "c": "#586a4b"
    },
    {
      "id": 384,
      "x": 6,
      "y": -12,
      "z": -4,
      "c": "#586a4b"
    },
    {
      "id": 385,
      "x": 6,
      "y": -12,
      "z": -3,
      "c": "#586a4b"
    },
    {
      "id": 386,
      "x": 6,
      "y": -12,
      "z": -2,
      "c": "#9ca2a6"
    },
    {
      "id": 387,
      "x": 6,
      "y": -12,
      "z": -1,
      "c": "#9ca2a6"
    },
    {
      "id": 388,
      "x": 6,
      "y": -12,
      "z": 0,
      "c": "#9ca2a6"
    },
    {
      "id": 389,
      "x": 6,
      "y": -12,
      "z": 1,
      "c": "#9ca2a6"
    },
    {
      "id": 390,
      "x": 6,
      "y": -12,
      "z": 2,
      "c": "#9ca2a6"
    },
    {
      "id": 391,
      "x": 6,
      "y": -12,
      "z": 3,
      "c": "#30363d"
    },
    {
      "id": 392,
      "x": 6,
      "y": -12,
      "z": 4,
      "c": "#30363d"
    },
    {
      "id": 393,
      "x": 6,
      "y": -12,
      "z": 5,
      "c": "#30363d"
    },
    {
      "id": 394,
      "x": 6,
      "y": -12,
      "z": 6,
      "c": "#30363d"
    },
    {
      "id": 395,
      "x": 6,
      "y": -12,
      "z": 7,
      "c": "#30363d"
    },
    {
      "id": 396,
      "x": 6,
      "y": -12,
      "z": 8,
      "c": "#30363d"
    },
    {
      "id": 397,
      "x": 6,
      "y": -12,
      "z": 9,
      "c": "#30363d"
    },
    {
      "id": 398,
      "x": 6,
      "y": -12,
      "z": 10,
      "c": "#30363d"
    },
    {
      "id": 399,
      "x": 7,
      "y": -12,
      "z": -10,
      "c": "#586a4b"
    },
    {
      "id": 400,
      "x": 7,
      "y": -12,
      "z": -9,
      "c": "#586a4b"
    },
    {
      "id": 401,
      "x": 7,
      "y": -12,
      "z": -8,
      "c": "#586a4b"
    },
    {
      "id": 402,
      "x": 7,
      "y": -12,
      "z": -7,
      "c": "#586a4b"
    },
    {
      "id": 403,
      "x": 7,
      "y": -12,
      "z": -6,
      "c": "#586a4b"
    },
    {
      "id": 404,
      "x": 7,
      "y": -12,
      "z": -5,
      "c": "#586a4b"
    },
    {
      "id": 405,
      "x": 7,
      "y": -12,
      "z": -4,
      "c": "#586a4b"
    },
    {
      "id": 406,
      "x": 7,
      "y": -12,
      "z": -3,
      "c": "#586a4b"
    },
    {
      "id": 407,
      "x": 7,
      "y": -12,
      "z": -2,
      "c": "#c6beb1"
    },
    {
      "id": 408,
      "x": 7,
      "y": -12,
      "z": -1,
      "c": "#9ca2a6"
    },
    {
      "id": 409,
      "x": 7,
      "y": -12,
      "z": 0,
      "c": "#9ca2a6"
    },
    {
      "id": 410,
      "x": 7,
      "y": -12,
      "z": 1,
      "c": "#9ca2a6"
    },
    {
      "id": 411,
      "x": 7,
      "y": -12,
      "z": 2,
      "c": "#c6beb1"
    },
    {
      "id": 412,
      "x": 7,
      "y": -12,
      "z": 3,
      "c": "#30363d"
    },
    {
      "id": 413,
      "x": 7,
      "y": -12,
      "z": 4,
      "c": "#30363d"
    },
    {
      "id": 414,
      "x": 7,
      "y": -12,
      "z": 5,
      "c": "#30363d"
    },
    {
      "id": 415,
      "x": 7,
      "y": -12,
      "z": 6,
      "c": "#30363d"
    },
    {
      "id": 416,
      "x": 7,
      "y": -12,
      "z": 7,
      "c": "#30363d"
    },
    {
      "id": 417,
      "x": 7,
      "y": -12,
      "z": 8,
      "c": "#30363d"
    },
    {
      "id": 418,
      "x": 7,
      "y": -12,
      "z": 9,
      "c": "#30363d"
    },
    {
      "id": 419,
      "x": 7,
      "y": -12,
      "z": 10,
      "c": "#30363d"
    },
    {
      "id": 420,
      "x": 8,
      "y": -12,
      "z": -10,
      "c": "#586a4b"
    },
    {
      "id": 421,
      "x": 8,
      "y": -12,
      "z": -9,
      "c": "#586a4b"
    },
    {
      "id": 422,
      "x": 8,
      "y": -12,
      "z": -8,
      "c": "#586a4b"
    },
    {
      "id": 423,
      "x": 8,
      "y": -12,
      "z": -7,
      "c": "#586a4b"
    },
    {
      "id": 424,
      "x": 8,
      "y": -12,
      "z": -6,
      "c": "#586a4b"
    },
    {
      "id": 425,
      "x": 8,
      "y": -12,
      "z": -5,
      "c": "#586a4b"
    },
    {
      "id": 426,
      "x": 8,
      "y": -12,
      "z": -4,
      "c": "#586a4b"
    },
    {
      "id": 427,
      "x": 8,
      "y": -12,
      "z": -3,
      "c": "#586a4b"
    },
    {
      "id": 428,
      "x": 8,
      "y": -12,
      "z": -2,
      "c": "#c6beb1"
    },
    {
      "id": 429,
      "x": 8,
      "y": -12,
      "z": -1,
      "c": "#c6beb1"
    },
    {
      "id": 430,
      "x": 8,
      "y": -12,
      "z": 0,
      "c": "#9ca2a6"
    },
    {
      "id": 431,
      "x": 8,
      "y": -12,
      "z": 1,
      "c": "#c6beb1"
    },
    {
      "id": 432,
      "x": 8,
      "y": -12,
      "z": 2,
      "c": "#c6beb1"
    },
    {
      "id": 433,
      "x": 8,
      "y": -12,
      "z": 3,
      "c": "#30363d"
    },
    {
      "id": 434,
      "x": 8,
      "y": -12,
      "z": 4,
      "c": "#30363d"
    },
    {
      "id": 435,
      "x": 8,
      "y": -12,
      "z": 5,
      "c": "#30363d"
    },
    {
      "id": 436,
      "x": 8,
      "y": -12,
      "z": 6,
      "c": "#30363d"
    },
    {
      "id": 437,
      "x": 8,
      "y": -12,
      "z": 7,
      "c": "#30363d"
    },
    {
      "id": 438,
      "x": 8,
      "y": -12,
      "z": 8,
      "c": "#30363d"
    },
    {
      "id": 439,
      "x": 8,
      "y": -12,
      "z": 9,
      "c": "#30363d"
    },
    {
      "id": 440,
      "x": 8,
      "y": -12,
      "z": 10,
      "c": "#30363d"
    },
    {
      "id": 441,
      "x": 9,
      "y": -12,
      "z": -10,
      "c": "#586a4b"
    },
    {
      "id": 442,
      "x": 9,
      "y": -12,
      "z": -9,
      "c": "#586a4b"
    },
    {
      "id": 443,
      "x": 9,
      "y": -12,
      "z": -8,
      "c": "#586a4b"
    },
    {
      "id": 444,
      "x": 9,
      "y": -12,
      "z": -7,
      "c": "#586a4b"
    },
    {
      "id": 445,
      "x": 9,
      "y": -12,
      "z": -6,
      "c": "#586a4b"
    },
    {
      "id": 446,
      "x": 9,
      "y": -12,
      "z": -5,
      "c": "#586a4b"
    },
    {
      "id": 447,
      "x": 9,
      "y": -12,
      "z": -4,
      "c": "#586a4b"
    },
    {
      "id": 448,
      "x": 9,
      "y": -12,
      "z": -3,
      "c": "#586a4b"
    },
    {
      "id": 449,
      "x": 9,
      "y": -12,
      "z": -2,
      "c": "#c6beb1"
    },
    {
      "id": 450,
      "x": 9,
      "y": -12,
      "z": -1,
      "c": "#c6beb1"
    },
    {
      "id": 451,
      "x": 9,
      "y": -12,
      "z": 0,
      "c": "#c6beb1"
    },
    {
      "id": 452,
      "x": 9,
      "y": -12,
      "z": 1,
      "c": "#c6beb1"
    },
    {
      "id": 453,
      "x": 9,
      "y": -12,
      "z": 2,
      "c": "#c6beb1"
    },
    {
      "id": 454,
      "x": 9,
      "y": -12,
      "z": 3,
      "c": "#30363d"
    },
    {
      "id": 455,
      "x": 9,
      "y": -12,
      "z": 4,
      "c": "#30363d"
    },
    {
      "id": 456,
      "x": 9,
      "y": -12,
      "z": 5,
      "c": "#30363d"
    },
    {
      "id": 457,
      "x": 9,
      "y": -12,
      "z": 6,
      "c": "#30363d"
    },
    {
      "id": 458,
      "x": 9,
      "y": -12,
      "z": 7,
      "c": "#30363d"
    },
    {
      "id": 459,
      "x": 9,
      "y": -12,
      "z": 8,
      "c": "#30363d"
    },
    {
      "id": 460,
      "x": 9,
      "y": -12,
      "z": 9,
      "c": "#30363d"
    },
    {
      "id": 461,
      "x": 9,
      "y": -12,
      "z": 10,
      "c": "#30363d"
    },
    {
      "id": 462,
      "x": 10,
      "y": -12,
      "z": -10,
      "c": "#586a4b"
    },
    {
      "id": 463,
      "x": 10,
      "y": -12,
      "z": -9,
      "c": "#586a4b"
    },
    {
      "id": 464,
      "x": 10,
      "y": -12,
      "z": -8,
      "c": "#586a4b"
    },
    {
      "id": 465,
      "x": 10,
      "y": -12,
      "z": -7,
      "c": "#586a4b"
    },
    {
      "id": 466,
      "x": 10,
      "y": -12,
      "z": -6,
      "c": "#586a4b"
    },
    {
      "id": 467,
      "x": 10,
      "y": -12,
      "z": -5,
      "c": "#586a4b"
    },
    {
      "id": 468,
      "x": 10,
      "y": -12,
      "z": -4,
      "c": "#586a4b"
    },
    {
      "id": 469,
      "x": 10,
      "y": -12,
      "z": -3,
      "c": "#586a4b"
    },
    {
      "id": 470,
      "x": 10,
      "y": -12,
      "z": -2,
      "c": "#c6beb1"
    },
    {
      "id": 471,
      "x": 10,
      "y": -12,
      "z": -1,
      "c": "#c6beb1"
    },
    {
      "id": 472,
      "x": 10,
      "y": -12,
      "z": 0,
      "c": "#c6beb1"
    },
    {
      "id": 473,
      "x": 10,
      "y": -12,
      "z": 1,
      "c": "#c6beb1"
    },
    {
      "id": 474,
      "x": 10,
      "y": -12,
      "z": 2,
      "c": "#c6beb1"
    },
    {
      "id": 475,
      "x": 10,
      "y": -12,
      "z": 3,
      "c": "#30363d"
    },
    {
      "id": 476,
      "x": 10,
      "y": -12,
      "z": 4,
      "c": "#30363d"
    },
    {
      "id": 477,
      "x": 10,
      "y": -12,
      "z": 5,
      "c": "#30363d"
    },
    {
      "id": 478,
      "x": 10,
      "y": -12,
      "z": 6,
      "c": "#30363d"
    },
    {
      "id": 479,
      "x": 10,
      "y": -12,
      "z": 7,
      "c": "#30363d"
    },
    {
      "id": 480,
      "x": 10,
      "y": -12,
      "z": 8,
      "c": "#30363d"
    },
    {
      "id": 481,
      "x": 10,
      "y": -12,
      "z": 9,
      "c": "#30363d"
    },
    {
      "id": 482,
      "x": 10,
      "y": -12,
      "z": 10,
      "c": "#30363d"
    },
    {
      "id": 483,
      "x": 11,
      "y": -12,
      "z": -10,
      "c": "#586a4b"
    },
    {
      "id": 484,
      "x": 11,
      "y": -12,
      "z": -9,
      "c": "#586a4b"
    },
    {
      "id": 485,
      "x": 11,
      "y": -12,
      "z": -8,
      "c": "#586a4b"
    },
    {
      "id": 486,
      "x": 11,
      "y": -12,
      "z": -7,
      "c": "#586a4b"
    },
    {
      "id": 487,
      "x": 11,
      "y": -12,
      "z": -6,
      "c": "#586a4b"
    },
    {
      "id": 488,
      "x": 11,
      "y": -12,
      "z": -5,
      "c": "#586a4b"
    },
    {
      "id": 489,
      "x": 11,
      "y": -12,
      "z": -4,
      "c": "#586a4b"
    },
    {
      "id": 490,
      "x": 11,
      "y": -12,
      "z": -3,
      "c": "#586a4b"
    },
    {
      "id": 491,
      "x": 11,
      "y": -12,
      "z": -2,
      "c": "#6f7378"
    },
    {
      "id": 492,
      "x": 11,
      "y": -12,
      "z": -1,
      "c": "#c6beb1"
    },
    {
      "id": 493,
      "x": 11,
      "y": -12,
      "z": 0,
      "c": "#c6beb1"
    },
    {
      "id": 494,
      "x": 11,
      "y": -12,
      "z": 1,
      "c": "#c6beb1"
    },
    {
      "id": 495,
      "x": 11,
      "y": -12,
      "z": 2,
      "c": "#6f7378"
    },
    {
      "id": 496,
      "x": 11,
      "y": -12,
      "z": 3,
      "c": "#30363d"
    },
    {
      "id": 497,
      "x": 11,
      "y": -12,
      "z": 4,
      "c": "#30363d"
    },
    {
      "id": 498,
      "x": 11,
      "y": -12,
      "z": 5,
      "c": "#30363d"
    },
    {
      "id": 499,
      "x": 11,
      "y": -12,
      "z": 6,
      "c": "#30363d"
    },
    {
      "id": 500,
      "x": 11,
      "y": -12,
      "z": 7,
      "c": "#30363d"
    },
    {
      "id": 501,
      "x": 11,
      "y": -12,
      "z": 8,
      "c": "#30363d"
    },
    {
      "id": 502,
      "x": 11,
      "y": -12,
      "z": 9,
      "c": "#30363d"
    },
    {
      "id": 503,
      "x": 11,
      "y": -12,
      "z": 10,
      "c": "#30363d"
    },
    {
      "id": 504,
      "x": 12,
      "y": -12,
      "z": -10,
      "c": "#586a4b"
    },
    {
      "id": 505,
      "x": 12,
      "y": -12,
      "z": -9,
      "c": "#586a4b"
    },
    {
      "id": 506,
      "x": 12,
      "y": -12,
      "z": -8,
      "c": "#586a4b"
    },
    {
      "id": 507,
      "x": 12,
      "y": -12,
      "z": -7,
      "c": "#586a4b"
    },
    {
      "id": 508,
      "x": 12,
      "y": -12,
      "z": -6,
      "c": "#586a4b"
    },
    {
      "id": 509,
      "x": 12,
      "y": -12,
      "z": -5,
      "c": "#586a4b"
    },
    {
      "id": 510,
      "x": 12,
      "y": -12,
      "z": -4,
      "c": "#586a4b"
    },
    {
      "id": 511,
      "x": 12,
      "y": -12,
      "z": -3,
      "c": "#586a4b"
    },
    {
      "id": 512,
      "x": 12,
      "y": -12,
      "z": -2,
      "c": "#6f7378"
    },
    {
      "id": 513,
      "x": 12,
      "y": -12,
      "z": -1,
      "c": "#6f7378"
    },
    {
      "id": 514,
      "x": 12,
      "y": -12,
      "z": 0,
      "c": "#c6beb1"
    },
    {
      "id": 515,
      "x": 12,
      "y": -12,
      "z": 1,
      "c": "#6f7378"
    },
    {
      "id": 516,
      "x": 12,
      "y": -12,
      "z": 2,
      "c": "#6f7378"
    },
    {
      "id": 517,
      "x": 12,
      "y": -12,
      "z": 3,
      "c": "#30363d"
    },
    {
      "id": 518,
      "x": 12,
      "y": -12,
      "z": 4,
      "c": "#30363d"
    },
    {
      "id": 519,
      "x": 12,
      "y": -12,
      "z": 5,
      "c": "#30363d"
    },
    {
      "id": 520,
      "x": 12,
      "y": -12,
      "z": 6,
      "c": "#30363d"
    },
    {
      "id": 521,
      "x": 12,
      "y": -12,
      "z": 7,
      "c": "#30363d"
    },
    {
      "id": 522,
      "x": 12,
      "y": -12,
      "z": 8,
      "c": "#30363d"
    },
    {
      "id": 523,
      "x": 12,
      "y": -12,
      "z": 9,
      "c": "#30363d"
    },
    {
      "id": 524,
      "x": 12,
      "y": -12,
      "z": 10,
      "c": "#30363d"
    },
    {
      "id": 525,
      "x": 4,
      "y": -11,
      "z": 4,
      "c": "#d4cec3"
    },
    {
      "id": 526,
      "x": 4,
      "y": -11,
      "z": 8,
      "c": "#d4cec3"
    },
    {
      "id": 527,
      "x": 5,
      "y": -11,
      "z": 4,
      "c": "#d4cec3"
    },
    {
      "id": 528,
      "x": 5,
      "y": -11,
      "z": 8,
      "c": "#d4cec3"
    },
    {
      "id": 529,
      "x": 6,
      "y": -11,
      "z": 4,
      "c": "#d4cec3"
    },
    {
      "id": 530,
      "x": 6,
      "y": -11,
      "z": 8,
      "c": "#d4cec3"
    },
    {
      "id": 531,
      "x": 7,
      "y": -11,
      "z": 4,
      "c": "#d4cec3"
    },
    {
      "id": 532,
      "x": 7,
      "y": -11,
      "z": 8,
      "c": "#d4cec3"
    },
    {
      "id": 533,
      "x": 8,
      "y": -11,
      "z": 4,
      "c": "#d4cec3"
    },
    {
      "id": 534,
      "x": 8,
      "y": -11,
      "z": 8,
      "c": "#d4cec3"
    },
    {
      "id": 535,
      "x": 9,
      "y": -11,
      "z": 4,
      "c": "#d4cec3"
    },
    {
      "id": 536,
      "x": 9,
      "y": -11,
      "z": 8,
      "c": "#d4cec3"
    },
    {
      "id": 537,
      "x": 10,
      "y": -11,
      "z": 4,
      "c": "#d4cec3"
    },
    {
      "id": 538,
      "x": 10,
      "y": -11,
      "z": 8,
      "c": "#d4cec3"
    },
    {
      "id": 539,
      "x": 4,
      "y": -11,
      "z": 5,
      "c": "#d4cec3"
    },
    {
      "id": 540,
      "x": 10,
      "y": -11,
      "z": 5,
      "c": "#d4cec3"
    },
    {
      "id": 541,
      "x": 7,
      "y": -11,
      "z": 5,
      "c": "#d4cec3"
    },
    {
      "id": 542,
      "x": 4,
      "y": -11,
      "z": 6,
      "c": "#b69b74"
    },
    {
      "id": 543,
      "x": 10,
      "y": -11,
      "z": 6,
      "c": "#b69b74"
    },
    {
      "id": 544,
      "x": 7,
      "y": -11,
      "z": 6,
      "c": "#d4cec3"
    },
    {
      "id": 545,
      "x": 4,
      "y": -11,
      "z": 7,
      "c": "#d4cec3"
    },
    {
      "id": 546,
      "x": 10,
      "y": -11,
      "z": 7,
      "c": "#d4cec3"
    },
    {
      "id": 547,
      "x": 7,
      "y": -11,
      "z": 7,
      "c": "#d4cec3"
    },
    {
      "id": 548,
      "x": 4,
      "y": -10,
      "z": 6,
      "c": "#c6beb1"
    },
    {
      "id": 549,
      "x": 10,
      "y": -10,
      "z": 6,
      "c": "#6f7378"
    },
    {
      "id": 550,
      "x": 4,
      "y": -9,
      "z": 6,
      "c": "#d4cec3"
    },
    {
      "id": 551,
      "x": 10,
      "y": -9,
      "z": 6,
      "c": "#d4cec3"
    },
    {
      "id": 552,
      "x": 8,
      "y": -11,
      "z": -6,
      "c": "#674f3c"
    },
    {
      "id": 553,
      "x": 8,
      "y": -10,
      "z": -6,
      "c": "#674f3c"
    },
    {
      "id": 554,
      "x": 8,
      "y": -9,
      "z": -6,
      "c": "#674f3c"
    },
    {
      "id": 555,
      "x": 7,
      "y": -9,
      "z": -6,
      "c": "#7a5749"
    },
    {
      "id": 556,
      "x": 6,
      "y": -10,
      "z": -6,
      "c": "#d6bb71"
    },
    {
      "id": 557,
      "x": 5,
      "y": -11,
      "z": -6,
      "c": "#5a4231"
    },
    {
      "id": 558,
      "x": -2,
      "y": -11,
      "z": 4,
      "c": "#d4cec3"
    },
    {
      "id": 559,
      "x": -2,
      "y": -10,
      "z": 4,
      "c": "#d4cec3"
    },
    {
      "id": 560,
      "x": -2,
      "y": -9,
      "z": 4,
      "c": "#d4cec3"
    },
    {
      "id": 561,
      "x": -2,
      "y": -8,
      "z": 4,
      "c": "#d4cec3"
    },
    {
      "id": 562,
      "x": -2,
      "y": -7,
      "z": 4,
      "c": "#d4cec3"
    },
    {
      "id": 563,
      "x": -2,
      "y": -6,
      "z": 4,
      "c": "#30363d"
    },
    {
      "id": 564,
      "x": -1,
      "y": -7,
      "z": 4,
      "c": "#4f7a74"
    },
    {
      "id": 565,
      "x": 0,
      "y": -7,
      "z": 4,
      "c": "#86483f"
    },
    {
      "id": 566,
      "x": 1,
      "y": -7,
      "z": 4,
      "c": "#d4cec3"
    },
    {
      "id": 567,
      "x": -10,
      "y": -11,
      "z": -8,
      "c": "#5a4231"
    },
    {
      "id": 568,
      "x": -10,
      "y": -11,
      "z": -7,
      "c": "#5a4231"
    },
    {
      "id": 569,
      "x": -10,
      "y": -11,
      "z": -6,
      "c": "#5a4231"
    },
    {
      "id": 570,
      "x": -10,
      "y": -11,
      "z": -5,
      "c": "#5a4231"
    },
    {
      "id": 571,
      "x": -10,
      "y": -11,
      "z": -4,
      "c": "#5a4231"
    },
    {
      "id": 572,
      "x": -10,
      "y": -11,
      "z": -3,
      "c": "#5a4231"
    },
    {
      "id": 573,
      "x": -10,
      "y": -11,
      "z": -2,
      "c": "#5a4231"
    },
    {
      "id": 574,
      "x": -10,
      "y": -11,
      "z": -1,
      "c": "#5a4231"
    },
    {
      "id": 575,
      "x": -10,
      "y": -11,
      "z": 0,
      "c": "#5a4231"
    },
    {
      "id": 576,
      "x": -10,
      "y": -11,
      "z": 1,
      "c": "#5a4231"
    },
    {
      "id": 577,
      "x": -10,
      "y": -11,
      "z": 2,
      "c": "#5a4231"
    },
    {
      "id": 578,
      "x": -10,
      "y": -11,
      "z": 3,
      "c": "#5a4231"
    },
    {
      "id": 579,
      "x": -10,
      "y": -11,
      "z": 4,
      "c": "#5a4231"
    },
    {
      "id": 580,
      "x": -10,
      "y": -11,
      "z": 5,
      "c": "#5a4231"
    },
    {
      "id": 581,
      "x": -10,
      "y": -11,
      "z": 6,
      "c": "#5a4231"
    },
    {
      "id": 582,
      "x": -10,
      "y": -11,
      "z": 7,
      "c": "#5a4231"
    },
    {
      "id": 583,
      "x": -10,
      "y": -11,
      "z": 8,
      "c": "#5a4231"
    },
    {
      "id": 584,
      "x": -9,
      "y": -11,
      "z": -8,
      "c": "#5a4231"
    },
    {
      "id": 585,
      "x": -9,
      "y": -11,
      "z": 8,
      "c": "#5a4231"
    },
    {
      "id": 586,
      "x": -8,
      "y": -11,
      "z": -8,
      "c": "#5a4231"
    },
    {
      "id": 587,
      "x": -8,
      "y": -11,
      "z": 8,
      "c": "#5a4231"
    },
    {
      "id": 588,
      "x": -7,
      "y": -11,
      "z": -8,
      "c": "#5a4231"
    },
    {
      "id": 589,
      "x": -7,
      "y": -11,
      "z": 8,
      "c": "#5a4231"
    },
    {
      "id": 590,
      "x": -6,
      "y": -11,
      "z": -8,
      "c": "#5a4231"
    },
    {
      "id": 591,
      "x": -6,
      "y": -11,
      "z": 8,
      "c": "#5a4231"
    },
    {
      "id": 592,
      "x": -5,
      "y": -11,
      "z": -8,
      "c": "#5a4231"
    },
    {
      "id": 593,
      "x": -5,
      "y": -11,
      "z": 8,
      "c": "#5a4231"
    },
    {
      "id": 594,
      "x": -4,
      "y": -11,
      "z": -8,
      "c": "#5a4231"
    },
    {
      "id": 595,
      "x": -4,
      "y": -11,
      "z": 8,
      "c": "#5a4231"
    },
    {
      "id": 596,
      "x": -3,
      "y": -11,
      "z": 8,
      "c": "#5a4231"
    },
    {
      "id": 597,
      "x": -2,
      "y": -11,
      "z": 8,
      "c": "#8fa3ad"
    },
    {
      "id": 598,
      "x": -1,
      "y": -11,
      "z": 8,
      "c": "#5a4231"
    },
    {
      "id": 599,
      "x": 0,
      "y": -11,
      "z": 2,
      "c": "#5a4231"
    },
    {
      "id": 600,
      "x": 0,
      "y": -11,
      "z": 3,
      "c": "#5a4231"
    },
    {
      "id": 601,
      "x": 0,
      "y": -11,
      "z": 4,
      "c": "#5a4231"
    },
    {
      "id": 602,
      "x": 0,
      "y": -11,
      "z": 5,
      "c": "#5a4231"
    },
    {
      "id": 603,
      "x": 0,
      "y": -11,
      "z": 6,
      "c": "#5a4231"
    },
    {
      "id": 604,
      "x": 0,
      "y": -11,
      "z": 7,
      "c": "#5a4231"
    },
    {
      "id": 605,
      "x": 0,
      "y": -11,
      "z": 8,
      "c": "#5a4231"
    },
    {
      "id": 606,
      "x": -10,
      "y": -10,
      "z": -8,
      "c": "#d6bb71"
    },
    {
      "id": 607,
      "x": -10,
      "y": -10,
      "z": -7,
      "c": "#7a5749"
    },
    {
      "id": 608,
      "x": -10,
      "y": -10,
      "z": -6,
      "c": "#7a5749"
    },
    {
      "id": 609,
      "x": -10,
      "y": -10,
      "z": -5,
      "c": "#d6bb71"
    },
    {
      "id": 610,
      "x": -10,
      "y": -10,
      "z": -4,
      "c": "#7a5749"
    },
    {
      "id": 611,
      "x": -10,
      "y": -10,
      "z": -3,
      "c": "#7a5749"
    },
    {
      "id": 612,
      "x": -10,
      "y": -10,
      "z": -2,
      "c": "#d6bb71"
    },
    {
      "id": 613,
      "x": -10,
      "y": -10,
      "z": -1,
      "c": "#7a5749"
    },
    {
      "id": 614,
      "x": -10,
      "y": -10,
      "z": 0,
      "c": "#7a5749"
    },
    {
      "id": 615,
      "x": -10,
      "y": -10,
      "z": 1,
      "c": "#d6bb71"
    },
    {
      "id": 616,
      "x": -10,
      "y": -10,
      "z": 2,
      "c": "#7a5749"
    },
    {
      "id": 617,
      "x": -10,
      "y": -10,
      "z": 3,
      "c": "#7a5749"
    },
    {
      "id": 618,
      "x": -10,
      "y": -10,
      "z": 4,
      "c": "#d6bb71"
    },
    {
      "id": 619,
      "x": -10,
      "y": -10,
      "z": 5,
      "c": "#7a5749"
    },
    {
      "id": 620,
      "x": -10,
      "y": -10,
      "z": 6,
      "c": "#7a5749"
    },
    {
      "id": 621,
      "x": -10,
      "y": -10,
      "z": 7,
      "c": "#d6bb71"
    },
    {
      "id": 622,
      "x": -10,
      "y": -10,
      "z": 8,
      "c": "#7a5749"
    },
    {
      "id": 623,
      "x": -9,
      "y": -10,
      "z": -8,
      "c": "#d6bb71"
    },
    {
      "id": 624,
      "x": -9,
      "y": -10,
      "z": 8,
      "c": "#d6bb71"
    },
    {
      "id": 625,
      "x": -8,
      "y": -10,
      "z": -8,
      "c": "#7a5749"
    },
    {
      "id": 626,
      "x": -8,
      "y": -10,
      "z": 8,
      "c": "#d6bb71"
    },
    {
      "id": 627,
      "x": -7,
      "y": -10,
      "z": -8,
      "c": "#d6bb71"
    },
    {
      "id": 628,
      "x": -7,
      "y": -10,
      "z": 8,
      "c": "#7a5749"
    },
    {
      "id": 629,
      "x": -6,
      "y": -10,
      "z": -8,
      "c": "#d6bb71"
    },
    {
      "id": 630,
      "x": -6,
      "y": -10,
      "z": 8,
      "c": "#d6bb71"
    },
    {
      "id": 631,
      "x": -5,
      "y": -10,
      "z": -8,
      "c": "#7a5749"
    },
    {
      "id": 632,
      "x": -5,
      "y": -10,
      "z": 8,
      "c": "#d6bb71"
    },
    {
      "id": 633,
      "x": -4,
      "y": -10,
      "z": -8,
      "c": "#d6bb71"
    },
    {
      "id": 634,
      "x": -4,
      "y": -10,
      "z": 8,
      "c": "#7a5749"
    },
    {
      "id": 635,
      "x": -3,
      "y": -10,
      "z": 8,
      "c": "#d6bb71"
    },
    {
      "id": 636,
      "x": -2,
      "y": -10,
      "z": 8,
      "c": "#d6bb71"
    },
    {
      "id": 637,
      "x": -1,
      "y": -10,
      "z": 8,
      "c": "#7a5749"
    },
    {
      "id": 638,
      "x": 0,
      "y": -10,
      "z": 2,
      "c": "#d6bb71"
    },
    {
      "id": 639,
      "x": 0,
      "y": -10,
      "z": 3,
      "c": "#d6bb71"
    },
    {
      "id": 640,
      "x": 0,
      "y": -10,
      "z": 4,
      "c": "#d6bb71"
    },
    {
      "id": 641,
      "x": 0,
      "y": -10,
      "z": 5,
      "c": "#d6bb71"
    },
    {
      "id": 642,
      "x": 0,
      "y": -10,
      "z": 6,
      "c": "#d6bb71"
    },
    {
      "id": 643,
      "x": 0,
      "y": -10,
      "z": 7,
      "c": "#d6bb71"
    },
    {
      "id": 644,
      "x": 0,
      "y": -10,
      "z": 8,
      "c": "#d6bb71"
    },
    {
      "id": 645,
      "x": -10,
      "y": -9,
      "z": -8,
      "c": "#8fa3ad"
    },
    {
      "id": 646,
      "x": -10,
      "y": -9,
      "z": -7,
      "c": "#7a5749"
    },
    {
      "id": 647,
      "x": -10,
      "y": -9,
      "z": -6,
      "c": "#7a5749"
    },
    {
      "id": 648,
      "x": -10,
      "y": -9,
      "z": -5,
      "c": "#8fa3ad"
    },
    {
      "id": 649,
      "x": -10,
      "y": -9,
      "z": -4,
      "c": "#7a5749"
    },
    {
      "id": 650,
      "x": -10,
      "y": -9,
      "z": -3,
      "c": "#7a5749"
    },
    {
      "id": 651,
      "x": -10,
      "y": -9,
      "z": -2,
      "c": "#8fa3ad"
    },
    {
      "id": 652,
      "x": -10,
      "y": -9,
      "z": -1,
      "c": "#7a5749"
    },
    {
      "id": 653,
      "x": -10,
      "y": -9,
      "z": 0,
      "c": "#7a5749"
    },
    {
      "id": 654,
      "x": -10,
      "y": -9,
      "z": 1,
      "c": "#8fa3ad"
    },
    {
      "id": 655,
      "x": -10,
      "y": -9,
      "z": 2,
      "c": "#7a5749"
    },
    {
      "id": 656,
      "x": -10,
      "y": -9,
      "z": 3,
      "c": "#7a5749"
    },
    {
      "id": 657,
      "x": -10,
      "y": -9,
      "z": 4,
      "c": "#8fa3ad"
    },
    {
      "id": 658,
      "x": -10,
      "y": -9,
      "z": 5,
      "c": "#7a5749"
    },
    {
      "id": 659,
      "x": -10,
      "y": -9,
      "z": 6,
      "c": "#7a5749"
    },
    {
      "id": 660,
      "x": -10,
      "y": -9,
      "z": 7,
      "c": "#8fa3ad"
    },
    {
      "id": 661,
      "x": -10,
      "y": -9,
      "z": 8,
      "c": "#7a5749"
    },
    {
      "id": 662,
      "x": -9,
      "y": -9,
      "z": -8,
      "c": "#7a5749"
    },
    {
      "id": 663,
      "x": -9,
      "y": -9,
      "z": 8,
      "c": "#7a5749"
    },
    {
      "id": 664,
      "x": -8,
      "y": -9,
      "z": -8,
      "c": "#7a5749"
    },
    {
      "id": 665,
      "x": -8,
      "y": -9,
      "z": 8,
      "c": "#8fa3ad"
    },
    {
      "id": 666,
      "x": -7,
      "y": -9,
      "z": -8,
      "c": "#8fa3ad"
    },
    {
      "id": 667,
      "x": -7,
      "y": -9,
      "z": 8,
      "c": "#7a5749"
    },
    {
      "id": 668,
      "x": -6,
      "y": -9,
      "z": -8,
      "c": "#7a5749"
    },
    {
      "id": 669,
      "x": -6,
      "y": -9,
      "z": 8,
      "c": "#7a5749"
    },
    {
      "id": 670,
      "x": -5,
      "y": -9,
      "z": -8,
      "c": "#7a5749"
    },
    {
      "id": 671,
      "x": -5,
      "y": -9,
      "z": 8,
      "c": "#8fa3ad"
    },
    {
      "id": 672,
      "x": -4,
      "y": -9,
      "z": -8,
      "c": "#8fa3ad"
    },
    {
      "id": 673,
      "x": -4,
      "y": -9,
      "z": 8,
      "c": "#7a5749"
    },
    {
      "id": 674,
      "x": -3,
      "y": -9,
      "z": 8,
      "c": "#7a5749"
    },
    {
      "id": 675,
      "x": -2,
      "y": -9,
      "z": 8,
      "c": "#8fa3ad"
    },
    {
      "id": 676,
      "x": -1,
      "y": -9,
      "z": 8,
      "c": "#7a5749"
    },
    {
      "id": 677,
      "x": 0,
      "y": -9,
      "z": 2,
      "c": "#7a5749"
    },
    {
      "id": 678,
      "x": 0,
      "y": -9,
      "z": 3,
      "c": "#8fa3ad"
    },
    {
      "id": 679,
      "x": 0,
      "y": -9,
      "z": 4,
      "c": "#7a5749"
    },
    {
      "id": 680,
      "x": 0,
      "y": -9,
      "z": 5,
      "c": "#7a5749"
    },
    {
      "id": 681,
      "x": 0,
      "y": -9,
      "z": 6,
      "c": "#8fa3ad"
    },
    {
      "id": 682,
      "x": 0,
      "y": -9,
      "z": 7,
      "c": "#7a5749"
    },
    {
      "id": 683,
      "x": 0,
      "y": -9,
      "z": 8,
      "c": "#7a5749"
    },
    {
      "id": 684,
      "x": -10,
      "y": -8,
      "z": -8,
      "c": "#8fa3ad"
    },
    {
      "id": 685,
      "x": -10,
      "y": -8,
      "z": -7,
      "c": "#7a5749"
    },
    {
      "id": 686,
      "x": -10,
      "y": -8,
      "z": -6,
      "c": "#8fa3ad"
    },
    {
      "id": 687,
      "x": -10,
      "y": -8,
      "z": -5,
      "c": "#8fa3ad"
    },
    {
      "id": 688,
      "x": -10,
      "y": -8,
      "z": -4,
      "c": "#7a5749"
    },
    {
      "id": 689,
      "x": -10,
      "y": -8,
      "z": -3,
      "c": "#8fa3ad"
    },
    {
      "id": 690,
      "x": -10,
      "y": -8,
      "z": -2,
      "c": "#8fa3ad"
    },
    {
      "id": 691,
      "x": -10,
      "y": -8,
      "z": -1,
      "c": "#7a5749"
    },
    {
      "id": 692,
      "x": -10,
      "y": -8,
      "z": 0,
      "c": "#8fa3ad"
    },
    {
      "id": 693,
      "x": -10,
      "y": -8,
      "z": 1,
      "c": "#8fa3ad"
    },
    {
      "id": 694,
      "x": -10,
      "y": -8,
      "z": 2,
      "c": "#7a5749"
    },
    {
      "id": 695,
      "x": -10,
      "y": -8,
      "z": 3,
      "c": "#8fa3ad"
    },
    {
      "id": 696,
      "x": -10,
      "y": -8,
      "z": 4,
      "c": "#8fa3ad"
    },
    {
      "id": 697,
      "x": -10,
      "y": -8,
      "z": 5,
      "c": "#7a5749"
    },
    {
      "id": 698,
      "x": -10,
      "y": -8,
      "z": 6,
      "c": "#8fa3ad"
    },
    {
      "id": 699,
      "x": -10,
      "y": -8,
      "z": 7,
      "c": "#8fa3ad"
    },
    {
      "id": 700,
      "x": -10,
      "y": -8,
      "z": 8,
      "c": "#7a5749"
    },
    {
      "id": 701,
      "x": -9,
      "y": -8,
      "z": -8,
      "c": "#7a5749"
    },
    {
      "id": 702,
      "x": -9,
      "y": -8,
      "z": 8,
      "c": "#7a5749"
    },
    {
      "id": 703,
      "x": -8,
      "y": -8,
      "z": -8,
      "c": "#7a5749"
    },
    {
      "id": 704,
      "x": -8,
      "y": -8,
      "z": 8,
      "c": "#8fa3ad"
    },
    {
      "id": 705,
      "x": -7,
      "y": -8,
      "z": -8,
      "c": "#8fa3ad"
    },
    {
      "id": 706,
      "x": -7,
      "y": -8,
      "z": 8,
      "c": "#7a5749"
    },
    {
      "id": 707,
      "x": -6,
      "y": -8,
      "z": -8,
      "c": "#7a5749"
    },
    {
      "id": 708,
      "x": -6,
      "y": -8,
      "z": 8,
      "c": "#7a5749"
    },
    {
      "id": 709,
      "x": -5,
      "y": -8,
      "z": -8,
      "c": "#7a5749"
    },
    {
      "id": 710,
      "x": -5,
      "y": -8,
      "z": 8,
      "c": "#8fa3ad"
    },
    {
      "id": 711,
      "x": -4,
      "y": -8,
      "z": -8,
      "c": "#8fa3ad"
    },
    {
      "id": 712,
      "x": -4,
      "y": -8,
      "z": 8,
      "c": "#7a5749"
    },
    {
      "id": 713,
      "x": -3,
      "y": -8,
      "z": 8,
      "c": "#7a5749"
    },
    {
      "id": 714,
      "x": -2,
      "y": -8,
      "z": 8,
      "c": "#8fa3ad"
    },
    {
      "id": 715,
      "x": -1,
      "y": -8,
      "z": 8,
      "c": "#7a5749"
    },
    {
      "id": 716,
      "x": 0,
      "y": -8,
      "z": 2,
      "c": "#7a5749"
    },
    {
      "id": 717,
      "x": 0,
      "y": -8,
      "z": 3,
      "c": "#8fa3ad"
    },
    {
      "id": 718,
      "x": 0,
      "y": -8,
      "z": 4,
      "c": "#7a5749"
    },
    {
      "id": 719,
      "x": 0,
      "y": -8,
      "z": 5,
      "c": "#7a5749"
    },
    {
      "id": 720,
      "x": 0,
      "y": -8,
      "z": 6,
      "c": "#8fa3ad"
    },
    {
      "id": 721,
      "x": 0,
      "y": -8,
      "z": 7,
      "c": "#7a5749"
    },
    {
      "id": 722,
      "x": 0,
      "y": -8,
      "z": 8,
      "c": "#7a5749"
    },
    {
      "id": 723,
      "x": -10,
      "y": -7,
      "z": -8,
      "c": "#86483f"
    },
    {
      "id": 724,
      "x": -10,
      "y": -7,
      "z": -7,
      "c": "#86483f"
    },
    {
      "id": 725,
      "x": -10,
      "y": -7,
      "z": -6,
      "c": "#86483f"
    },
    {
      "id": 726,
      "x": -10,
      "y": -7,
      "z": -5,
      "c": "#86483f"
    },
    {
      "id": 727,
      "x": -10,
      "y": -7,
      "z": -4,
      "c": "#86483f"
    },
    {
      "id": 728,
      "x": -10,
      "y": -7,
      "z": -3,
      "c": "#86483f"
    },
    {
      "id": 729,
      "x": -10,
      "y": -7,
      "z": -2,
      "c": "#86483f"
    },
    {
      "id": 730,
      "x": -10,
      "y": -7,
      "z": -1,
      "c": "#86483f"
    },
    {
      "id": 731,
      "x": -10,
      "y": -7,
      "z": 0,
      "c": "#86483f"
    },
    {
      "id": 732,
      "x": -10,
      "y": -7,
      "z": 1,
      "c": "#86483f"
    },
    {
      "id": 733,
      "x": -10,
      "y": -7,
      "z": 2,
      "c": "#86483f"
    },
    {
      "id": 734,
      "x": -10,
      "y": -7,
      "z": 3,
      "c": "#86483f"
    },
    {
      "id": 735,
      "x": -10,
      "y": -7,
      "z": 4,
      "c": "#86483f"
    },
    {
      "id": 736,
      "x": -10,
      "y": -7,
      "z": 5,
      "c": "#86483f"
    },
    {
      "id": 737,
      "x": -10,
      "y": -7,
      "z": 6,
      "c": "#86483f"
    },
    {
      "id": 738,
      "x": -10,
      "y": -7,
      "z": 7,
      "c": "#86483f"
    },
    {
      "id": 739,
      "x": -10,
      "y": -7,
      "z": 8,
      "c": "#86483f"
    },
    {
      "id": 740,
      "x": -9,
      "y": -7,
      "z": -8,
      "c": "#86483f"
    },
    {
      "id": 741,
      "x": -9,
      "y": -7,
      "z": 8,
      "c": "#86483f"
    },
    {
      "id": 742,
      "x": -8,
      "y": -7,
      "z": -8,
      "c": "#86483f"
    },
    {
      "id": 743,
      "x": -8,
      "y": -7,
      "z": 8,
      "c": "#86483f"
    },
    {
      "id": 744,
      "x": -7,
      "y": -7,
      "z": -8,
      "c": "#86483f"
    },
    {
      "id": 745,
      "x": -7,
      "y": -7,
      "z": 8,
      "c": "#86483f"
    },
    {
      "id": 746,
      "x": -6,
      "y": -7,
      "z": -8,
      "c": "#86483f"
    },
    {
      "id": 747,
      "x": -6,
      "y": -7,
      "z": 8,
      "c": "#86483f"
    },
    {
      "id": 748,
      "x": -5,
      "y": -7,
      "z": -8,
      "c": "#86483f"
    },
    {
      "id": 749,
      "x": -5,
      "y": -7,
      "z": 8,
      "c": "#86483f"
    },
    {
      "id": 750,
      "x": -4,
      "y": -7,
      "z": -8,
      "c": "#86483f"
    },
    {
      "id": 751,
      "x": -4,
      "y": -7,
      "z": 8,
      "c": "#86483f"
    },
    {
      "id": 752,
      "x": -3,
      "y": -7,
      "z": 8,
      "c": "#86483f"
    },
    {
      "id": 753,
      "x": -2,
      "y": -7,
      "z": 8,
      "c": "#86483f"
    },
    {
      "id": 754,
      "x": -1,
      "y": -7,
      "z": 8,
      "c": "#86483f"
    },
    {
      "id": 755,
      "x": 0,
      "y": -7,
      "z": 2,
      "c": "#86483f"
    },
    {
      "id": 756,
      "x": 0,
      "y": -7,
      "z": 3,
      "c": "#86483f"
    },
    {
      "id": 757,
      "x": 0,
      "y": -7,
      "z": 5,
      "c": "#86483f"
    },
    {
      "id": 758,
      "x": 0,
      "y": -7,
      "z": 6,
      "c": "#86483f"
    },
    {
      "id": 759,
      "x": 0,
      "y": -7,
      "z": 7,
      "c": "#86483f"
    },
    {
      "id": 760,
      "x": 0,
      "y": -7,
      "z": 8,
      "c": "#86483f"
    },
    {
      "id": 761,
      "x": -11,
      "y": -6,
      "z": -9,
      "c": "#6f7378"
    },
    {
      "id": 762,
      "x": -11,
      "y": -6,
      "z": -8,
      "c": "#6f7378"
    },
    {
      "id": 763,
      "x": -11,
      "y": -6,
      "z": -7,
      "c": "#6f7378"
    },
    {
      "id": 764,
      "x": -11,
      "y": -6,
      "z": -6,
      "c": "#6f7378"
    },
    {
      "id": 765,
      "x": -11,
      "y": -6,
      "z": -5,
      "c": "#6f7378"
    },
    {
      "id": 766,
      "x": -11,
      "y": -6,
      "z": -4,
      "c": "#6f7378"
    },
    {
      "id": 767,
      "x": -11,
      "y": -6,
      "z": -3,
      "c": "#6f7378"
    },
    {
      "id": 768,
      "x": -11,
      "y": -6,
      "z": -2,
      "c": "#6f7378"
    },
    {
      "id": 769,
      "x": -11,
      "y": -6,
      "z": -1,
      "c": "#6f7378"
    },
    {
      "id": 770,
      "x": -11,
      "y": -6,
      "z": 0,
      "c": "#6f7378"
    },
    {
      "id": 771,
      "x": -11,
      "y": -6,
      "z": 1,
      "c": "#6f7378"
    },
    {
      "id": 772,
      "x": -11,
      "y": -6,
      "z": 2,
      "c": "#6f7378"
    },
    {
      "id": 773,
      "x": -11,
      "y": -6,
      "z": 3,
      "c": "#6f7378"
    },
    {
      "id": 774,
      "x": -11,
      "y": -6,
      "z": 4,
      "c": "#6f7378"
    },
    {
      "id": 775,
      "x": -11,
      "y": -6,
      "z": 5,
      "c": "#6f7378"
    },
    {
      "id": 776,
      "x": -11,
      "y": -6,
      "z": 6,
      "c": "#6f7378"
    },
    {
      "id": 777,
      "x": -11,
      "y": -6,
      "z": 7,
      "c": "#6f7378"
    },
    {
      "id": 778,
      "x": -11,
      "y": -6,
      "z": 8,
      "c": "#6f7378"
    },
    {
      "id": 779,
      "x": -11,
      "y": -6,
      "z": 9,
      "c": "#6f7378"
    },
    {
      "id": 780,
      "x": -10,
      "y": -6,
      "z": -9,
      "c": "#6f7378"
    },
    {
      "id": 781,
      "x": -10,
      "y": -6,
      "z": -8,
      "c": "#6f7378"
    },
    {
      "id": 782,
      "x": -10,
      "y": -6,
      "z": -7,
      "c": "#6f7378"
    },
    {
      "id": 783,
      "x": -10,
      "y": -6,
      "z": -6,
      "c": "#6f7378"
    },
    {
      "id": 784,
      "x": -10,
      "y": -6,
      "z": -5,
      "c": "#6f7378"
    },
    {
      "id": 785,
      "x": -10,
      "y": -6,
      "z": -4,
      "c": "#6f7378"
    },
    {
      "id": 786,
      "x": -10,
      "y": -6,
      "z": -3,
      "c": "#6f7378"
    },
    {
      "id": 787,
      "x": -10,
      "y": -6,
      "z": -2,
      "c": "#6f7378"
    },
    {
      "id": 788,
      "x": -10,
      "y": -6,
      "z": -1,
      "c": "#6f7378"
    },
    {
      "id": 789,
      "x": -10,
      "y": -6,
      "z": 0,
      "c": "#30363d"
    },
    {
      "id": 790,
      "x": -10,
      "y": -6,
      "z": 1,
      "c": "#6f7378"
    },
    {
      "id": 791,
      "x": -10,
      "y": -6,
      "z": 2,
      "c": "#6f7378"
    },
    {
      "id": 792,
      "x": -10,
      "y": -6,
      "z": 3,
      "c": "#6f7378"
    },
    {
      "id": 793,
      "x": -10,
      "y": -6,
      "z": 4,
      "c": "#6f7378"
    },
    {
      "id": 794,
      "x": -10,
      "y": -6,
      "z": 5,
      "c": "#6f7378"
    },
    {
      "id": 795,
      "x": -10,
      "y": -6,
      "z": 6,
      "c": "#6f7378"
    },
    {
      "id": 796,
      "x": -10,
      "y": -6,
      "z": 7,
      "c": "#6f7378"
    },
    {
      "id": 797,
      "x": -10,
      "y": -6,
      "z": 8,
      "c": "#6f7378"
    },
    {
      "id": 798,
      "x": -10,
      "y": -6,
      "z": 9,
      "c": "#6f7378"
    },
    {
      "id": 799,
      "x": -9,
      "y": -6,
      "z": -9,
      "c": "#6f7378"
    },
    {
      "id": 800,
      "x": -9,
      "y": -6,
      "z": -8,
      "c": "#6f7378"
    },
    {
      "id": 801,
      "x": -9,
      "y": -6,
      "z": -7,
      "c": "#6f7378"
    },
    {
      "id": 802,
      "x": -9,
      "y": -6,
      "z": -6,
      "c": "#6f7378"
    },
    {
      "id": 803,
      "x": -9,
      "y": -6,
      "z": -5,
      "c": "#6f7378"
    },
    {
      "id": 804,
      "x": -9,
      "y": -6,
      "z": -4,
      "c": "#6f7378"
    },
    {
      "id": 805,
      "x": -9,
      "y": -6,
      "z": -3,
      "c": "#6f7378"
    },
    {
      "id": 806,
      "x": -9,
      "y": -6,
      "z": -2,
      "c": "#6f7378"
    },
    {
      "id": 807,
      "x": -9,
      "y": -6,
      "z": -1,
      "c": "#30363d"
    },
    {
      "id": 808,
      "x": -9,
      "y": -6,
      "z": 0,
      "c": "#30363d"
    },
    {
      "id": 809,
      "x": -9,
      "y": -6,
      "z": 1,
      "c": "#30363d"
    },
    {
      "id": 810,
      "x": -9,
      "y": -6,
      "z": 2,
      "c": "#6f7378"
    },
    {
      "id": 811,
      "x": -9,
      "y": -6,
      "z": 3,
      "c": "#6f7378"
    },
    {
      "id": 812,
      "x": -9,
      "y": -6,
      "z": 4,
      "c": "#6f7378"
    },
    {
      "id": 813,
      "x": -9,
      "y": -6,
      "z": 5,
      "c": "#6f7378"
    },
    {
      "id": 814,
      "x": -9,
      "y": -6,
      "z": 6,
      "c": "#6f7378"
    },
    {
      "id": 815,
      "x": -9,
      "y": -6,
      "z": 7,
      "c": "#6f7378"
    },
    {
      "id": 816,
      "x": -9,
      "y": -6,
      "z": 8,
      "c": "#6f7378"
    },
    {
      "id": 817,
      "x": -9,
      "y": -6,
      "z": 9,
      "c": "#6f7378"
    },
    {
      "id": 818,
      "x": -8,
      "y": -6,
      "z": -9,
      "c": "#6f7378"
    },
    {
      "id": 819,
      "x": -8,
      "y": -6,
      "z": -8,
      "c": "#6f7378"
    },
    {
      "id": 820,
      "x": -8,
      "y": -6,
      "z": -7,
      "c": "#6f7378"
    },
    {
      "id": 821,
      "x": -8,
      "y": -6,
      "z": -6,
      "c": "#6f7378"
    },
    {
      "id": 822,
      "x": -8,
      "y": -6,
      "z": -5,
      "c": "#6f7378"
    },
    {
      "id": 823,
      "x": -8,
      "y": -6,
      "z": -4,
      "c": "#6f7378"
    },
    {
      "id": 824,
      "x": -8,
      "y": -6,
      "z": -3,
      "c": "#6f7378"
    },
    {
      "id": 825,
      "x": -8,
      "y": -6,
      "z": -2,
      "c": "#30363d"
    },
    {
      "id": 826,
      "x": -8,
      "y": -6,
      "z": -1,
      "c": "#30363d"
    },
    {
      "id": 827,
      "x": -8,
      "y": -6,
      "z": 0,
      "c": "#30363d"
    },
    {
      "id": 828,
      "x": -8,
      "y": -6,
      "z": 1,
      "c": "#30363d"
    },
    {
      "id": 829,
      "x": -8,
      "y": -6,
      "z": 2,
      "c": "#30363d"
    },
    {
      "id": 830,
      "x": -8,
      "y": -6,
      "z": 3,
      "c": "#6f7378"
    },
    {
      "id": 831,
      "x": -8,
      "y": -6,
      "z": 4,
      "c": "#6f7378"
    },
    {
      "id": 832,
      "x": -8,
      "y": -6,
      "z": 5,
      "c": "#6f7378"
    },
    {
      "id": 833,
      "x": -8,
      "y": -6,
      "z": 6,
      "c": "#6f7378"
    },
    {
      "id": 834,
      "x": -8,
      "y": -6,
      "z": 7,
      "c": "#6f7378"
    },
    {
      "id": 835,
      "x": -8,
      "y": -6,
      "z": 8,
      "c": "#6f7378"
    },
    {
      "id": 836,
      "x": -8,
      "y": -6,
      "z": 9,
      "c": "#6f7378"
    },
    {
      "id": 837,
      "x": -7,
      "y": -6,
      "z": -9,
      "c": "#6f7378"
    },
    {
      "id": 838,
      "x": -7,
      "y": -6,
      "z": -8,
      "c": "#6f7378"
    },
    {
      "id": 839,
      "x": -7,
      "y": -6,
      "z": -7,
      "c": "#6f7378"
    },
    {
      "id": 840,
      "x": -7,
      "y": -6,
      "z": -6,
      "c": "#6f7378"
    },
    {
      "id": 841,
      "x": -7,
      "y": -6,
      "z": -5,
      "c": "#6f7378"
    },
    {
      "id": 842,
      "x": -7,
      "y": -6,
      "z": -4,
      "c": "#6f7378"
    },
    {
      "id": 843,
      "x": -7,
      "y": -6,
      "z": -3,
      "c": "#30363d"
    },
    {
      "id": 844,
      "x": -7,
      "y": -6,
      "z": -2,
      "c": "#30363d"
    },
    {
      "id": 845,
      "x": -7,
      "y": -6,
      "z": -1,
      "c": "#30363d"
    },
    {
      "id": 846,
      "x": -7,
      "y": -6,
      "z": 0,
      "c": "#30363d"
    },
    {
      "id": 847,
      "x": -7,
      "y": -6,
      "z": 1,
      "c": "#30363d"
    },
    {
      "id": 848,
      "x": -7,
      "y": -6,
      "z": 2,
      "c": "#30363d"
    },
    {
      "id": 849,
      "x": -7,
      "y": -6,
      "z": 3,
      "c": "#30363d"
    },
    {
      "id": 850,
      "x": -7,
      "y": -6,
      "z": 4,
      "c": "#6f7378"
    },
    {
      "id": 851,
      "x": -7,
      "y": -6,
      "z": 5,
      "c": "#6f7378"
    },
    {
      "id": 852,
      "x": -7,
      "y": -6,
      "z": 6,
      "c": "#6f7378"
    },
    {
      "id": 853,
      "x": -7,
      "y": -6,
      "z": 7,
      "c": "#6f7378"
    },
    {
      "id": 854,
      "x": -7,
      "y": -6,
      "z": 8,
      "c": "#6f7378"
    },
    {
      "id": 855,
      "x": -7,
      "y": -6,
      "z": 9,
      "c": "#6f7378"
    },
    {
      "id": 856,
      "x": -6,
      "y": -6,
      "z": -9,
      "c": "#6f7378"
    },
    {
      "id": 857,
      "x": -6,
      "y": -6,
      "z": -8,
      "c": "#6f7378"
    },
    {
      "id": 858,
      "x": -6,
      "y": -6,
      "z": -7,
      "c": "#6f7378"
    },
    {
      "id": 859,
      "x": -6,
      "y": -6,
      "z": -6,
      "c": "#6f7378"
    },
    {
      "id": 860,
      "x": -6,
      "y": -6,
      "z": -5,
      "c": "#6f7378"
    },
    {
      "id": 861,
      "x": -6,
      "y": -6,
      "z": -4,
      "c": "#30363d"
    },
    {
      "id": 862,
      "x": -6,
      "y": -6,
      "z": -3,
      "c": "#30363d"
    },
    {
      "id": 863,
      "x": -6,
      "y": -6,
      "z": -2,
      "c": "#30363d"
    },
    {
      "id": 864,
      "x": -6,
      "y": -6,
      "z": -1,
      "c": "#30363d"
    },
    {
      "id": 865,
      "x": -6,
      "y": -6,
      "z": 0,
      "c": "#30363d"
    },
    {
      "id": 866,
      "x": -6,
      "y": -6,
      "z": 1,
      "c": "#30363d"
    },
    {
      "id": 867,
      "x": -6,
      "y": -6,
      "z": 2,
      "c": "#30363d"
    },
    {
      "id": 868,
      "x": -6,
      "y": -6,
      "z": 3,
      "c": "#30363d"
    },
    {
      "id": 869,
      "x": -6,
      "y": -6,
      "z": 4,
      "c": "#30363d"
    },
    {
      "id": 870,
      "x": -6,
      "y": -6,
      "z": 5,
      "c": "#6f7378"
    },
    {
      "id": 871,
      "x": -6,
      "y": -6,
      "z": 6,
      "c": "#6f7378"
    },
    {
      "id": 872,
      "x": -6,
      "y": -6,
      "z": 7,
      "c": "#6f7378"
    },
    {
      "id": 873,
      "x": -6,
      "y": -6,
      "z": 8,
      "c": "#6f7378"
    },
    {
      "id": 874,
      "x": -6,
      "y": -6,
      "z": 9,
      "c": "#6f7378"
    },
    {
      "id": 875,
      "x": -5,
      "y": -6,
      "z": -9,
      "c": "#6f7378"
    },
    {
      "id": 876,
      "x": -5,
      "y": -6,
      "z": -8,
      "c": "#6f7378"
    },
    {
      "id": 877,
      "x": -5,
      "y": -6,
      "z": -7,
      "c": "#6f7378"
    },
    {
      "id": 878,
      "x": -5,
      "y": -6,
      "z": -6,
      "c": "#6f7378"
    },
    {
      "id": 879,
      "x": -5,
      "y": -6,
      "z": -5,
      "c": "#30363d"
    },
    {
      "id": 880,
      "x": -5,
      "y": -6,
      "z": -4,
      "c": "#30363d"
    },
    {
      "id": 881,
      "x": -5,
      "y": -6,
      "z": -3,
      "c": "#30363d"
    },
    {
      "id": 882,
      "x": -5,
      "y": -6,
      "z": -2,
      "c": "#30363d"
    },
    {
      "id": 883,
      "x": -5,
      "y": -6,
      "z": -1,
      "c": "#30363d"
    },
    {
      "id": 884,
      "x": -5,
      "y": -6,
      "z": 0,
      "c": "#30363d"
    },
    {
      "id": 885,
      "x": -5,
      "y": -6,
      "z": 1,
      "c": "#30363d"
    },
    {
      "id": 886,
      "x": -5,
      "y": -6,
      "z": 2,
      "c": "#30363d"
    },
    {
      "id": 887,
      "x": -5,
      "y": -6,
      "z": 3,
      "c": "#30363d"
    },
    {
      "id": 888,
      "x": -5,
      "y": -6,
      "z": 4,
      "c": "#30363d"
    },
    {
      "id": 889,
      "x": -5,
      "y": -6,
      "z": 5,
      "c": "#30363d"
    },
    {
      "id": 890,
      "x": -5,
      "y": -6,
      "z": 6,
      "c": "#6f7378"
    },
    {
      "id": 891,
      "x": -5,
      "y": -6,
      "z": 7,
      "c": "#6f7378"
    },
    {
      "id": 892,
      "x": -5,
      "y": -6,
      "z": 8,
      "c": "#6f7378"
    },
    {
      "id": 893,
      "x": -5,
      "y": -6,
      "z": 9,
      "c": "#6f7378"
    },
    {
      "id": 894,
      "x": -4,
      "y": -6,
      "z": -9,
      "c": "#6f7378"
    },
    {
      "id": 895,
      "x": -4,
      "y": -6,
      "z": -8,
      "c": "#6f7378"
    },
    {
      "id": 896,
      "x": -4,
      "y": -6,
      "z": -7,
      "c": "#6f7378"
    },
    {
      "id": 897,
      "x": -4,
      "y": -6,
      "z": -6,
      "c": "#30363d"
    },
    {
      "id": 898,
      "x": -4,
      "y": -6,
      "z": -5,
      "c": "#30363d"
    },
    {
      "id": 899,
      "x": -4,
      "y": -6,
      "z": -4,
      "c": "#30363d"
    },
    {
      "id": 900,
      "x": -4,
      "y": -6,
      "z": -3,
      "c": "#30363d"
    },
    {
      "id": 901,
      "x": -4,
      "y": -6,
      "z": -2,
      "c": "#30363d"
    },
    {
      "id": 902,
      "x": -4,
      "y": -6,
      "z": -1,
      "c": "#30363d"
    },
    {
      "id": 903,
      "x": -4,
      "y": -6,
      "z": 0,
      "c": "#30363d"
    },
    {
      "id": 904,
      "x": -4,
      "y": -6,
      "z": 1,
      "c": "#30363d"
    },
    {
      "id": 905,
      "x": -4,
      "y": -6,
      "z": 2,
      "c": "#30363d"
    },
    {
      "id": 906,
      "x": -4,
      "y": -6,
      "z": 3,
      "c": "#30363d"
    },
    {
      "id": 907,
      "x": -4,
      "y": -6,
      "z": 4,
      "c": "#30363d"
    },
    {
      "id": 908,
      "x": -4,
      "y": -6,
      "z": 5,
      "c": "#30363d"
    },
    {
      "id": 909,
      "x": -4,
      "y": -6,
      "z": 6,
      "c": "#30363d"
    },
    {
      "id": 910,
      "x": -4,
      "y": -6,
      "z": 7,
      "c": "#6f7378"
    },
    {
      "id": 911,
      "x": -4,
      "y": -6,
      "z": 8,
      "c": "#6f7378"
    },
    {
      "id": 912,
      "x": -4,
      "y": -6,
      "z": 9,
      "c": "#6f7378"
    },
    {
      "id": 913,
      "x": -3,
      "y": -6,
      "z": -9,
      "c": "#6f7378"
    },
    {
      "id": 914,
      "x": -3,
      "y": -6,
      "z": -8,
      "c": "#6f7378"
    },
    {
      "id": 915,
      "x": -3,
      "y": -6,
      "z": -7,
      "c": "#30363d"
    },
    {
      "id": 916,
      "x": -3,
      "y": -6,
      "z": -6,
      "c": "#30363d"
    },
    {
      "id": 917,
      "x": -3,
      "y": -6,
      "z": -5,
      "c": "#30363d"
    },
    {
      "id": 918,
      "x": -3,
      "y": -6,
      "z": -4,
      "c": "#30363d"
    },
    {
      "id": 919,
      "x": -3,
      "y": -6,
      "z": -3,
      "c": "#30363d"
    },
    {
      "id": 920,
      "x": -3,
      "y": -6,
      "z": -2,
      "c": "#30363d"
    },
    {
      "id": 921,
      "x": -3,
      "y": -6,
      "z": -1,
      "c": "#30363d"
    },
    {
      "id": 922,
      "x": -3,
      "y": -6,
      "z": 0,
      "c": "#30363d"
    },
    {
      "id": 923,
      "x": -3,
      "y": -6,
      "z": 1,
      "c": "#30363d"
    },
    {
      "id": 924,
      "x": -3,
      "y": -6,
      "z": 2,
      "c": "#30363d"
    },
    {
      "id": 925,
      "x": -3,
      "y": -6,
      "z": 3,
      "c": "#30363d"
    },
    {
      "id": 926,
      "x": -3,
      "y": -6,
      "z": 4,
      "c": "#30363d"
    },
    {
      "id": 927,
      "x": -3,
      "y": -6,
      "z": 5,
      "c": "#30363d"
    },
    {
      "id": 928,
      "x": -3,
      "y": -6,
      "z": 6,
      "c": "#30363d"
    },
    {
      "id": 929,
      "x": -3,
      "y": -6,
      "z": 7,
      "c": "#30363d"
    },
    {
      "id": 930,
      "x": -3,
      "y": -6,
      "z": 8,
      "c": "#6f7378"
    },
    {
      "id": 931,
      "x": -3,
      "y": -6,
      "z": 9,
      "c": "#6f7378"
    },
    {
      "id": 932,
      "x": -2,
      "y": -6,
      "z": 1,
      "c": "#30363d"
    },
    {
      "id": 933,
      "x": -2,
      "y": -6,
      "z": 2,
      "c": "#30363d"
    },
    {
      "id": 934,
      "x": -2,
      "y": -6,
      "z": 3,
      "c": "#30363d"
    },
    {
      "id": 935,
      "x": -2,
      "y": -6,
      "z": 5,
      "c": "#30363d"
    },
    {
      "id": 936,
      "x": -2,
      "y": -6,
      "z": 6,
      "c": "#30363d"
    },
    {
      "id": 937,
      "x": -2,
      "y": -6,
      "z": 7,
      "c": "#30363d"
    },
    {
      "id": 938,
      "x": -2,
      "y": -6,
      "z": 8,
      "c": "#30363d"
    },
    {
      "id": 939,
      "x": -2,
      "y": -6,
      "z": 9,
      "c": "#6f7378"
    },
    {
      "id": 940,
      "x": -1,
      "y": -6,
      "z": 1,
      "c": "#505860"
    },
    {
      "id": 941,
      "x": -1,
      "y": -6,
      "z": 2,
      "c": "#30363d"
    },
    {
      "id": 942,
      "x": -1,
      "y": -6,
      "z": 3,
      "c": "#30363d"
    },
    {
      "id": 943,
      "x": -1,
      "y": -6,
      "z": 4,
      "c": "#30363d"
    },
    {
      "id": 944,
      "x": -1,
      "y": -6,
      "z": 5,
      "c": "#30363d"
    },
    {
      "id": 945,
      "x": -1,
      "y": -6,
      "z": 6,
      "c": "#30363d"
    },
    {
      "id": 946,
      "x": -1,
      "y": -6,
      "z": 7,
      "c": "#30363d"
    },
    {
      "id": 947,
      "x": -1,
      "y": -6,
      "z": 8,
      "c": "#30363d"
    },
    {
      "id": 948,
      "x": -1,
      "y": -6,
      "z": 9,
      "c": "#30363d"
    },
    {
      "id": 949,
      "x": 0,
      "y": -6,
      "z": 1,
      "c": "#505860"
    },
    {
      "id": 950,
      "x": 0,
      "y": -6,
      "z": 2,
      "c": "#505860"
    },
    {
      "id": 951,
      "x": 0,
      "y": -6,
      "z": 3,
      "c": "#30363d"
    },
    {
      "id": 952,
      "x": 0,
      "y": -6,
      "z": 4,
      "c": "#30363d"
    },
    {
      "id": 953,
      "x": 0,
      "y": -6,
      "z": 5,
      "c": "#30363d"
    },
    {
      "id": 954,
      "x": 0,
      "y": -6,
      "z": 6,
      "c": "#30363d"
    },
    {
      "id": 955,
      "x": 0,
      "y": -6,
      "z": 7,
      "c": "#30363d"
    },
    {
      "id": 956,
      "x": 0,
      "y": -6,
      "z": 8,
      "c": "#30363d"
    },
    {
      "id": 957,
      "x": 0,
      "y": -6,
      "z": 9,
      "c": "#30363d"
    },
    {
      "id": 958,
      "x": 1,
      "y": -6,
      "z": 1,
      "c": "#505860"
    },
    {
      "id": 959,
      "x": 1,
      "y": -6,
      "z": 2,
      "c": "#30363d"
    },
    {
      "id": 960,
      "x": 1,
      "y": -6,
      "z": 3,
      "c": "#30363d"
    },
    {
      "id": 961,
      "x": 1,
      "y": -6,
      "z": 4,
      "c": "#30363d"
    },
    {
      "id": 962,
      "x": 1,
      "y": -6,
      "z": 5,
      "c": "#30363d"
    },
    {
      "id": 963,
      "x": 1,
      "y": -6,
      "z": 6,
      "c": "#30363d"
    },
    {
      "id": 964,
      "x": 1,
      "y": -6,
      "z": 7,
      "c": "#30363d"
    },
    {
      "id": 965,
      "x": 1,
      "y": -6,
      "z": 8,
      "c": "#30363d"
    },
    {
      "id": 966,
      "x": 1,
      "y": -6,
      "z": 9,
      "c": "#30363d"
    },
    {
      "id": 967,
      "x": -8,
      "y": -11,
      "z": -5,
      "c": "#30363d"
    },
    {
      "id": 968,
      "x": -8,
      "y": -10,
      "z": -5,
      "c": "#d6bb71"
    },
    {
      "id": 969,
      "x": -8,
      "y": -9,
      "z": -5,
      "c": "#8fa3ad"
    },
    {
      "id": 970,
      "x": -8,
      "y": -8,
      "z": -5,
      "c": "#d6bb71"
    },
    {
      "id": 971,
      "x": -8,
      "y": -11,
      "z": -4,
      "c": "#30363d"
    },
    {
      "id": 972,
      "x": -8,
      "y": -10,
      "z": -4,
      "c": "#d4cec3"
    },
    {
      "id": 973,
      "x": -8,
      "y": -9,
      "z": -4,
      "c": "#8fa3ad"
    },
    {
      "id": 974,
      "x": -8,
      "y": -8,
      "z": -4,
      "c": "#d6bb71"
    },
    {
      "id": 975,
      "x": -8,
      "y": -11,
      "z": -3,
      "c": "#30363d"
    },
    {
      "id": 976,
      "x": -8,
      "y": -10,
      "z": -3,
      "c": "#d6bb71"
    },
    {
      "id": 977,
      "x": -8,
      "y": -9,
      "z": -3,
      "c": "#8fa3ad"
    },
    {
      "id": 978,
      "x": -8,
      "y": -8,
      "z": -3,
      "c": "#d6bb71"
    },
    {
      "id": 979,
      "x": -7,
      "y": -11,
      "z": -5,
      "c": "#30363d"
    },
    {
      "id": 980,
      "x": -7,
      "y": -10,
      "z": -5,
      "c": "#d6bb71"
    },
    {
      "id": 981,
      "x": -7,
      "y": -9,
      "z": -5,
      "c": "#8fa3ad"
    },
    {
      "id": 982,
      "x": -7,
      "y": -8,
      "z": -5,
      "c": "#d6bb71"
    },
    {
      "id": 983,
      "x": -7,
      "y": -11,
      "z": -4,
      "c": "#30363d"
    },
    {
      "id": 984,
      "x": -7,
      "y": -10,
      "z": -4,
      "c": "#d6bb71"
    },
    {
      "id": 985,
      "x": -7,
      "y": -9,
      "z": -4,
      "c": "#d6bb71"
    },
    {
      "id": 986,
      "x": -7,
      "y": -8,
      "z": -4,
      "c": "#d6bb71"
    },
    {
      "id": 987,
      "x": -7,
      "y": -11,
      "z": -3,
      "c": "#30363d"
    },
    {
      "id": 988,
      "x": -7,
      "y": -10,
      "z": -3,
      "c": "#d6bb71"
    },
    {
      "id": 989,
      "x": -7,
      "y": -9,
      "z": -3,
      "c": "#8fa3ad"
    },
    {
      "id": 990,
      "x": -7,
      "y": -8,
      "z": -3,
      "c": "#d6bb71"
    },
    {
      "id": 991,
      "x": -6,
      "y": -11,
      "z": -5,
      "c": "#30363d"
    },
    {
      "id": 992,
      "x": -6,
      "y": -10,
      "z": -5,
      "c": "#d6bb71"
    },
    {
      "id": 993,
      "x": -6,
      "y": -9,
      "z": -5,
      "c": "#8fa3ad"
    },
    {
      "id": 994,
      "x": -6,
      "y": -8,
      "z": -5,
      "c": "#d6bb71"
    },
    {
      "id": 995,
      "x": -6,
      "y": -11,
      "z": -4,
      "c": "#30363d"
    },
    {
      "id": 996,
      "x": -6,
      "y": -10,
      "z": -4,
      "c": "#d6bb71"
    },
    {
      "id": 997,
      "x": -6,
      "y": -9,
      "z": -4,
      "c": "#d6bb71"
    },
    {
      "id": 998,
      "x": -6,
      "y": -8,
      "z": -4,
      "c": "#d6bb71"
    },
    {
      "id": 999,
      "x": -6,
      "y": -11,
      "z": -3,
      "c": "#30363d"
    },
    {
      "id": 1000,
      "x": -6,
      "y": -10,
      "z": -3,
      "c": "#d6bb71"
    },
    {
      "id": 1001,
      "x": -6,
      "y": -9,
      "z": -3,
      "c": "#8fa3ad"
    },
    {
      "id": 1002,
      "x": -6,
      "y": -8,
      "z": -3,
      "c": "#d6bb71"
    },
    {
      "id": 1003,
      "x": -5,
      "y": -11,
      "z": -5,
      "c": "#30363d"
    },
    {
      "id": 1004,
      "x": -5,
      "y": -10,
      "z": -5,
      "c": "#d6bb71"
    },
    {
      "id": 1005,
      "x": -5,
      "y": -9,
      "z": -5,
      "c": "#8fa3ad"
    },
    {
      "id": 1006,
      "x": -5,
      "y": -8,
      "z": -5,
      "c": "#d6bb71"
    },
    {
      "id": 1007,
      "x": -5,
      "y": -11,
      "z": -4,
      "c": "#30363d"
    },
    {
      "id": 1008,
      "x": -5,
      "y": -10,
      "z": -4,
      "c": "#d6bb71"
    },
    {
      "id": 1009,
      "x": -5,
      "y": -9,
      "z": -4,
      "c": "#d6bb71"
    },
    {
      "id": 1010,
      "x": -5,
      "y": -8,
      "z": -4,
      "c": "#d6bb71"
    },
    {
      "id": 1011,
      "x": -5,
      "y": -11,
      "z": -3,
      "c": "#30363d"
    },
    {
      "id": 1012,
      "x": -5,
      "y": -10,
      "z": -3,
      "c": "#d6bb71"
    },
    {
      "id": 1013,
      "x": -5,
      "y": -9,
      "z": -3,
      "c": "#8fa3ad"
    },
    {
      "id": 1014,
      "x": -5,
      "y": -8,
      "z": -3,
      "c": "#d6bb71"
    },
    {
      "id": 1015,
      "x": -4,
      "y": -11,
      "z": -5,
      "c": "#30363d"
    },
    {
      "id": 1016,
      "x": -4,
      "y": -10,
      "z": -5,
      "c": "#d6bb71"
    },
    {
      "id": 1017,
      "x": -4,
      "y": -9,
      "z": -5,
      "c": "#8fa3ad"
    },
    {
      "id": 1018,
      "x": -4,
      "y": -8,
      "z": -5,
      "c": "#d6bb71"
    },
    {
      "id": 1019,
      "x": -4,
      "y": -11,
      "z": -4,
      "c": "#30363d"
    },
    {
      "id": 1020,
      "x": -4,
      "y": -10,
      "z": -4,
      "c": "#d6bb71"
    },
    {
      "id": 1021,
      "x": -4,
      "y": -9,
      "z": -4,
      "c": "#d6bb71"
    },
    {
      "id": 1022,
      "x": -4,
      "y": -8,
      "z": -4,
      "c": "#d6bb71"
    },
    {
      "id": 1023,
      "x": -4,
      "y": -11,
      "z": -3,
      "c": "#30363d"
    },
    {
      "id": 1024,
      "x": -4,
      "y": -10,
      "z": -3,
      "c": "#d6bb71"
    },
    {
      "id": 1025,
      "x": -4,
      "y": -9,
      "z": -3,
      "c": "#8fa3ad"
    },
    {
      "id": 1026,
      "x": -4,
      "y": -8,
      "z": -3,
      "c": "#d6bb71"
    },
    {
      "id": 1027,
      "x": -3,
      "y": -11,
      "z": -5,
      "c": "#30363d"
    },
    {
      "id": 1028,
      "x": -3,
      "y": -10,
      "z": -5,
      "c": "#d6bb71"
    },
    {
      "id": 1029,
      "x": -3,
      "y": -9,
      "z": -5,
      "c": "#8fa3ad"
    },
    {
      "id": 1030,
      "x": -3,
      "y": -8,
      "z": -5,
      "c": "#d6bb71"
    },
    {
      "id": 1031,
      "x": -3,
      "y": -11,
      "z": -4,
      "c": "#30363d"
    },
    {
      "id": 1032,
      "x": -3,
      "y": -10,
      "z": -4,
      "c": "#d6bb71"
    },
    {
      "id": 1033,
      "x": -3,
      "y": -9,
      "z": -4,
      "c": "#d6bb71"
    },
    {
      "id": 1034,
      "x": -3,
      "y": -8,
      "z": -4,
      "c": "#d6bb71"
    },
    {
      "id": 1035,
      "x": -3,
      "y": -11,
      "z": -3,
      "c": "#30363d"
    },
    {
      "id": 1036,
      "x": -3,
      "y": -10,
      "z": -3,
      "c": "#d6bb71"
    },
    {
      "id": 1037,
      "x": -3,
      "y": -9,
      "z": -3,
      "c": "#8fa3ad"
    },
    {
      "id": 1038,
      "x": -3,
      "y": -8,
      "z": -3,
      "c": "#d6bb71"
    },
    {
      "id": 1039,
      "x": -2,
      "y": -11,
      "z": -5,
      "c": "#30363d"
    },
    {
      "id": 1040,
      "x": -2,
      "y": -10,
      "z": -5,
      "c": "#d6bb71"
    },
    {
      "id": 1041,
      "x": -2,
      "y": -9,
