{"voxels": [{"id": 0, "x": -12, "y": -12, "z": -10, "c": "#9a8366"}, {"id": 1, "x": -12, "y": -12, "z": -9, "c": "#6f7378"}, {"id": 2, "x": -12, "y": -12, "z": -8, "c": "#9a8366"}, {"id": 3, "x": -12, "y": -12, "z": -7, "c": "#6f7378"}, {"id": 4, "x": -12, "y": -12, "z": -6, "c": "#6f7378"}, {"id": 5, "x": -12, "y": -12, "z": -5, "c": "#6f7378"}, {"id": 6, "x": -12, "y": -12, "z": -4, "c": "#6f7378"}, {"id": 7, "x": -12, "y": -12, "z": -3, "c": "#6f7378"}, {"id": 8, "x": -12, "y": -12, "z": -2, "c": "#6f7378"}, {"id": 9, "x": -12, "y": -12, "z": -1, "c": "#6f7378"}, {"id": 10, "x": -12, "y": -12, "z": 0, "c": "#9a8366"}, {"id": 11, "x": -12, "y": -12, "z": 1, "c": "#30363d"}, {"id": 12, "x": -12, "y": -12, "z": 2, "c": "#30363d"}, {"id": 13, "x": -12, "y": -12, "z": 3, "c": "#30363d"}, {"id": 14, "x": -12, "y": -12, "z": 4, "c": "#30363d"}, {"id": 15, "x": -12, "y": -12, "z": 5, "c": "#30363d"}, {"id": 16, "x": -12, "y": -12, "z": 6, "c": "#30363d"}, {"id": 17, "x": -12, "y": -12, "z": 7, "c": "#30363d"}, {"id": 18, "x": -12, "y": -12, "z": 8, "c": "#30363d"}, {"id": 19, "x": -12, "y": -12, "z": 9, "c": "#30363d"}, {"id": 20, "x": -12, "y": -12, "z": 10, "c": "#30363d"}, {"id": 21, "x": -11, "y": -12, "z": -10, "c": "#6f7378"}, {"id": 22, "x": -11, "y": -12, "z": -9, "c": "#9a8366"}, {"id": 23, "x": -11, "y": -12, "z": -8, "c": "#6f7378"}, {"id": 24, "x": -11, "y": -12, "z": -7, "c": "#9a8366"}, {"id": 25, "x": -11, "y": -12, "z": -6, "c": "#6f7378"}, {"id": 26, "x": -11, "y": -12, "z": -5, "c": "#6f7378"}, {"id": 27, "x": -11, "y": -12, "z": -4, "c": "#6f7378"}, {"id": 28, "x": -11, "y": -12, "z": -3, "c": "#6f7378"}, {"id": 29, "x": -11, "y": -12, "z": -2, "c": "#6f7378"}, {"id": 30, "x": -11, "y": -12, "z": -1, "c": "#6f7378"}, {"id": 31, "x": -11, "y": -12, "z": 0, "c": "#9a8366"}, {"id": 32, "x": -11, "y": -12, "z": 1, "c": "#30363d"}, {"id": 33, "x": -11, "y": -12, "z": 2, "c": "#30363d"}, {"id": 34, "x": -11, "y": -12, "z": 3, "c": "#30363d"}, {"id": 35, "x": -11, "y": -12, "z": 4, "c": "#30363d"}, {"id": 36, "x": -11, "y": -12, "z": 5, "c": "#30363d"}, {"id": 37, "x": -11, "y": -12, "z": 6, "c": "#30363d"}, {"id": 38, "x": -11, "y": -12, "z": 7, "c": "#30363d"}, {"id": 39, "x": -11, "y": -12, "z": 8, "c": "#30363d"}, {"id": 40, "x": -11, "y": -12, "z": 9, "c": "#30363d"}, {"id": 41, "x": -11, "y": -12, "z": 10, "c": "#30363d"}, {"id": 42, "x": -10, "y": -12, "z": -10, "c": "#9a8366"}, {"id": 43, "x": -10, "y": -12, "z": -9, "c": "#6f7378"}, {"id": 44, "x": -10, "y": -12, "z": -8, "c": "#9a8366"}, {"id": 45, "x": -10, "y": -12, "z": -7, "c": "#6f7378"}, {"id": 46, "x": -10, "y": -12, "z": -6, "c": "#6f7378"}, {"id": 47, "x": -10, "y": -12, "z": -5, "c": "#6f7378"}, {"id": 48, "x": -10, "y": -12, "z": -4, "c": "#6f7378"}, {"id": 49, "x": -10, "y": -12, "z": -3, "c": "#6f7378"}, {"id": 50, "x": -10, "y": -12, "z": -2, "c": "#6f7378"}, {"id": 51, "x": -10, "y": -12, "z": -1, "c": "#6f7378"}, {"id": 52, "x": -10, "y": -12, "z": 0, "c": "#9a8366"}, {"id": 53, "x": -10, "y": -12, "z": 1, "c": "#30363d"}, {"id": 54, "x": -10, "y": -12, "z": 2, "c": "#30363d"}, {"id": 55, "x": -10, "y": -12, "z": 3, "c": "#30363d"}, {"id": 56, "x": -10, "y": -12, "z": 4, "c": "#30363d"}, {"id": 57, "x": -10, "y": -12, "z": 5, "c": "#30363d"}, {"id": 58, "x": -10, "y": -12, "z": 6, "c": "#30363d"}, {"id": 59, "x": -10, "y": -12, "z": 7, "c": "#30363d"}, {"id": 60, "x": -10, "y": -12, "z": 8, "c": "#30363d"}, {"id": 61, "x": -10, "y": -12, "z": 9, "c": "#30363d"}, {"id": 62, "x": -10, "y": -12, "z": 10, "c": "#30363d"}, {"id": 63, "x": -9, "y": -12, "z": -10, "c": "#6f7378"}, {"id": 64, "x": -9, "y": -12, "z": -9, "c": "#9a8366"}, {"id": 65, "x": -9, "y": -12, "z": -8, "c": "#6f7378"}, {"id": 66, "x": -9, "y": -12, "z": -7, "c": "#9a8366"}, {"id": 67, "x": -9, "y": -12, "z": -6, "c": "#6f7378"}, {"id": 68, "x": -9, "y": -12, "z": -5, "c": "#6f7378"}, {"id": 69, "x": -9, "y": -12, "z": -4, "c": "#6f7378"}, {"id": 70, "x": -9, "y": -12, "z": -3, "c": "#6f7378"}, {"id": 71, "x": -9, "y": -12, "z": -2, "c": "#6f7378"}, {"id": 72, "x": -9, "y": -12, "z": -1, "c": "#6f7378"}, {"id": 73, "x": -9, "y": -12, "z": 0, "c": "#9a8366"}, {"id": 74, "x": -9, "y": -12, "z": 1, "c": "#30363d"}, {"id": 75, "x": -9, "y": -12, "z": 2, "c": "#30363d"}, {"id": 76, "x": -9, "y": -12, "z": 3, "c": "#30363d"}, {"id": 77, "x": -9, "y": -12, "z": 4, "c": "#30363d"}, {"id": 78, "x": -9, "y": -12, "z": 5, "c": "#30363d"}, {"id": 79, "x": -9, "y": -12, "z": 6, "c": "#30363d"}, {"id": 80, "x": -9, "y": -12, "z": 7, "c": "#30363d"}, {"id": 81, "x": -9, "y": -12, "z": 8, "c": "#30363d"}, {"id": 82, "x": -9, "y": -12, "z": 9, "c": "#30363d"}, {"id": 83, "x": -9, "y": -12, "z": 10, "c": "#30363d"}, {"id": 84, "x": -8, "y": -12, "z": -10, "c": "#9a8366"}, {"id": 85, "x": -8, "y": -12, "z": -9, "c": "#6f7378"}, {"id": 86, "x": -8, "y": -12, "z": -8, "c": "#9a8366"}, {"id": 87, "x": -8, "y": -12, "z": -7, "c": "#6f7378"}, {"id": 88, "x": -8, "y": -12, "z": -6, "c": "#6f7378"}, {"id": 89, "x": -8, "y": -12, "z": -5, "c": "#6f7378"}, {"id": 90, "x": -8, "y": -12, "z": -4, "c": "#6f7378"}, {"id": 91, "x": -8, "y": -12, "z": -3, "c": "#6f7378"}, {"id": 92, "x": -8, "y": -12, "z": -2, "c": "#6f7378"}, {"id": 93, "x": -8, "y": -12, "z": -1, "c": "#6f7378"}, {"id": 94, "x": -8, "y": -12, "z": 0, "c": "#6f7378"}, {"id": 95, "x": -8, "y": -12, "z": 1, "c": "#30363d"}, {"id": 96, "x": -8, "y": -12, "z": 2, "c": "#30363d"}, {"id": 97, "x": -8, "y": -12, "z": 3, "c": "#30363d"}, {"id": 98, "x": -8, "y": -12, "z": 4, "c": "#30363d"}, {"id": 99, "x": -8, "y": -12, "z": 5, "c": "#30363d"}, {"id": 100, "x": -8, "y": -12, "z": 6, "c": "#30363d"}, {"id": 101, "x": -8, "y": -12, "z": 7, "c": "#30363d"}, {"id": 102, "x": -8, "y": -12, "z": 8, "c": "#30363d"}, {"id": 103, "x": -8, "y": -12, "z": 9, "c": "#30363d"}, {"id": 104, "x": -8, "y": -12, "z": 10, "c": "#30363d"}, {"id": 105, "x": -7, "y": -12, "z": -10, "c": "#6f7378"}, {"id": 106, "x": -7, "y": -12, "z": -9, "c": "#9a8366"}, {"id": 107, "x": -7, "y": -12, "z": -8, "c": "#6f7378"}, {"id": 108, "x": -7, "y": -12, "z": -7, "c": "#9a8366"}, {"id": 109, "x": -7, "y": -12, "z": -6, "c": "#6f7378"}, {"id": 110, "x": -7, "y": -12, "z": -5, "c": "#6f7378"}, {"id": 111, "x": -7, "y": -12, "z": -4, "c": "#6f7378"}, {"id": 112, "x": -7, "y": -12, "z": -3, "c": "#6f7378"}, {"id": 113, "x": -7, "y": -12, "z": -2, "c": "#6f7378"}, {"id": 114, "x": -7, "y": -12, "z": -1, "c": "#6f7378"}, {"id": 115, "x": -7, "y": -12, "z": 0, "c": "#6f7378"}, {"id": 116, "x": -7, "y": -12, "z": 1, "c": "#30363d"}, {"id": 117, "x": -7, "y": -12, "z": 2, "c": "#30363d"}, {"id": 118, "x": -7, "y": -12, "z": 3, "c": "#30363d"}, {"id": 119, "x": -7, "y": -12, "z": 4, "c": "#30363d"}, {"id": 120, "x": -7, "y": -12, "z": 5, "c": "#30363d"}, {"id": 121, "x": -7, "y": -12, "z": 6, "c": "#30363d"}, {"id": 122, "x": -7, "y": -12, "z": 7, "c": "#30363d"}, {"id": 123, "x": -7, "y": -12, "z": 8, "c": "#30363d"}, {"id": 124, "x": -7, "y": -12, "z": 9, "c": "#30363d"}, {"id": 125, "x": -7, "y": -12, "z": 10, "c": "#30363d"}, {"id": 126, "x": -6, "y": -12, "z": -10, "c": "#9a8366"}, {"id": 127, "x": -6, "y": -12, "z": -9, "c": "#6f7378"}, {"id": 128, "x": -6, "y": -12, "z": -8, "c": "#9a8366"}, {"id": 129, "x": -6, "y": -12, "z": -7, "c": "#6f7378"}, {"id": 130, "x": -6, "y": -12, "z": -6, "c": "#6f7378"}, {"id": 131, "x": -6, "y": -12, "z": -5, "c": "#6f7378"}, {"id": 132, "x": -6, "y": -12, "z": -4, "c": "#6f7378"}, {"id": 133, "x": -6, "y": -12, "z": -3, "c": "#6f7378"}, {"id": 134, "x": -6, "y": -12, "z": -2, "c": "#6f7378"}, {"id": 135, "x": -6, "y": -12, "z": -1, "c": "#6f7378"}, {"id": 136, "x": -6, "y": -12, "z": 0, "c": "#6f7378"}, {"id": 137, "x": -6, "y": -12, "z": 1, "c": "#6f7378"}, {"id": 138, "x": -6, "y": -12, "z": 2, "c": "#6f7378"}, {"id": 139, "x": -6, "y": -12, "z": 3, "c": "#6f7378"}, {"id": 140, "x": -6, "y": -12, "z": 4, "c": "#6f7378"}, {"id": 141, "x": -6, "y": -12, "z": 5, "c": "#6f7378"}, {"id": 142, "x": -6, "y": -12, "z": 6, "c": "#6f7378"}, {"id": 143, "x": -6, "y": -12, "z": 7, "c": "#6f7378"}, {"id": 144, "x": -6, "y": -12, "z": 8, "c": "#9a8366"}, {"id": 145, "x": -6, "y": -12, "z": 9, "c": "#6f7378"}, {"id": 146, "x": -6, "y": -12, "z": 10, "c": "#9a8366"}, {"id": 147, "x": -5, "y": -12, "z": -10, "c": "#6f7378"}, {"id": 148, "x": -5, "y": -12, "z": -9, "c": "#9a8366"}, {"id": 149, "x": -5, "y": -12, "z": -8, "c": "#6f7378"}, {"id": 150, "x": -5, "y": -12, "z": -7, "c": "#9a8366"}, {"id": 151, "x": -5, "y": -12, "z": -6, "c": "#6f7378"}, {"id": 152, "x": -5, "y": -12, "z": -5, "c": "#6f7378"}, {"id": 153, "x": -5, "y": -12, "z": -4, "c": "#6f7378"}, {"id": 154, "x": -5, "y": -12, "z": -3, "c": "#6f7378"}, {"id": 155, "x": -5, "y": -12, "z": -2, "c": "#6f7378"}, {"id": 156, "x": -5, "y": -12, "z": -1, "c": "#6f7378"}, {"id": 157, "x": -5, "y": -12, "z": 0, "c": "#6f7378"}, {"id": 158, "x": -5, "y": -12, "z": 1, "c": "#6f7378"}, {"id": 159, "x": -5, "y": -12, "z": 2, "c": "#6f7378"}, {"id": 160, "x": -5, "y": -12, "z": 3, "c": "#6f7378"}, {"id": 161, "x": -5, "y": -12, "z": 4, "c": "#6f7378"}, {"id": 162, "x": -5, "y": -12, "z": 5, "c": "#6f7378"}, {"id": 163, "x": -5, "y": -12, "z": 6, "c": "#6f7378"}, {"id": 164, "x": -5, "y": -12, "z": 7, "c": "#9a8366"}, {"id": 165, "x": -5, "y": -12, "z": 8, "c": "#6f7378"}, {"id": 166, "x": -5, "y": -12, "z": 9, "c": "#9a8366"}, {"id": 167, "x": -5, "y": -12, "z": 10, "c": "#6f7378"}, {"id": 168, "x": -4, "y": -12, "z": -10, "c": "#9a8366"}, {"id": 169, "x": -4, "y": -12, "z": -9, "c": "#6f7378"}, {"id": 170, "x": -4, "y": -12, "z": -8, "c": "#9a8366"}, {"id": 171, "x": -4, "y": -12, "z": -7, "c": "#6f7378"}, {"id": 172, "x": -4, "y": -12, "z": -6, "c": "#6f7378"}, {"id": 173, "x": -4, "y": -12, "z": -5, "c": "#6f7378"}, {"id": 174, "x": -4, "y": -12, "z": -4, "c": "#6f7378"}, {"id": 175, "x": -4, "y": -12, "z": -3, "c": "#6f7378"}, {"id": 176, "x": -4, "y": -12, "z": -2, "c": "#6f7378"}, {"id": 177, "x": -4, "y": -12, "z": -1, "c": "#6f7378"}, {"id": 178, "x": -4, "y": -12, "z": 0, "c": "#6f7378"}, {"id": 179, "x": -4, "y": -12, "z": 1, "c": "#6f7378"}, {"id": 180, "x": -4, "y": -12, "z": 2, "c": "#6f7378"}, {"id": 181, "x": -4, "y": -12, "z": 3, "c": "#6f7378"}, {"id": 182, "x": -4, "y": -12, "z": 4, "c": "#6f7378"}, {"id": 183, "x": -4, "y": -12, "z": 5, "c": "#6f7378"}, {"id": 184, "x": -4, "y": -12, "z": 6, "c": "#6f7378"}, {"id": 185, "x": -4, "y": -12, "z": 7, "c": "#6f7378"}, {"id": 186, "x": -4, "y": -12, "z": 8, "c": "#9a8366"}, {"id": 187, "x": -4, "y": -12, "z": 9, "c": "#6f7378"}, {"id": 188, "x": -4, "y": -12, "z": 10, "c": "#9a8366"}, {"id": 189, "x": -3, "y": -12, "z": -10, "c": "#6f7378"}, {"id": 190, "x": -3, "y": -12, "z": -9, "c": "#9a8366"}, {"id": 191, "x": -3, "y": -12, "z": -8, "c": "#6f7378"}, {"id": 192, "x": -3, "y": -12, "z": -7, "c": "#9a8366"}, {"id": 193, "x": -3, "y": -12, "z": -6, "c": "#6f7378"}, {"id": 194, "x": -3, "y": -12, "z": -5, "c": "#6f7378"}, {"id": 195, "x": -3, "y": -12, "z": -4, "c": "#6f7378"}, {"id": 196, "x": -3, "y": -12, "z": -3, "c": "#6f7378"}, {"id": 197, "x": -3, "y": -12, "z": -2, "c": "#6f7378"}, {"id": 198, "x": -3, "y": -12, "z": -1, "c": "#6f7378"}, {"id": 199, "x": -3, "y": -12, "z": 0, "c": "#6f7378"}, {"id": 200, "x": -3, "y": -12, "z": 1, "c": "#6f7378"}, {"id": 201, "x": -3, "y": -12, "z": 2, "c": "#6f7378"}, {"id": 202, "x": -3, "y": -12, "z": 3, "c": "#6f7378"}, {"id": 203, "x": -3, "y": -12, "z": 4, "c": "#6f7378"}, {"id": 204, "x": -3, "y": -12, "z": 5, "c": "#6f7378"}, {"id": 205, "x": -3, "y": -12, "z": 6, "c": "#6f7378"}, {"id": 206, "x": -3, "y": -12, "z": 7, "c": "#9a8366"}, {"id": 207, "x": -3, "y": -12, "z": 8, "c": "#6f7378"}, {"id": 208, "x": -3, "y": -12, "z": 9, "c": "#9a8366"}, {"id": 209, "x": -3, "y": -12, "z": 10, "c": "#6f7378"}, {"id": 210, "x": -2, "y": -12, "z": -10, "c": "#9a8366"}, {"id": 211, "x": -2, "y": -12, "z": -9, "c": "#6f7378"}, {"id": 212, "x": -2, "y": -12, "z": -8, "c": "#9a8366"}, {"id": 213, "x": -2, "y": -12, "z": -7, "c": "#6f7378"}, {"id": 214, "x": -2, "y": -12, "z": -6, "c": "#6f7378"}, {"id": 215, "x": -2, "y": -12, "z": -5, "c": "#6f7378"}, {"id": 216, "x": -2, "y": -12, "z": -4, "c": "#6f7378"}, {"id": 217, "x": -2, "y": -12, "z": -3, "c": "#6f7378"}, {"id": 218, "x": -2, "y": -12, "z": -2, "c": "#6f7378"}, {"id": 219, "x": -2, "y": -12, "z": -1, "c": "#6f7378"}, {"id": 220, "x": -2, "y": -12, "z": 0, "c": "#6f7378"}, {"id": 221, "x": -2, "y": -12, "z": 1, "c": "#6f7378"}, {"id": 222, "x": -2, "y": -12, "z": 2, "c": "#6f7378"}, {"id": 223, "x": -2, "y": -12, "z": 3, "c": "#6f7378"}, {"id": 224, "x": -2, "y": -12, "z": 4, "c": "#6f7378"}, {"id": 225, "x": -2, "y": -12, "z": 5, "c": "#6f7378"}, {"id": 226, "x": -2, "y": -12, "z": 6, "c": "#6f7378"}, {"id": 227, "x": -2, "y": -12, "z": 7, "c": "#6f7378"}, {"id": 228, "x": -2, "y": -12, "z": 8, "c": "#9a8366"}, {"id": 229, "x": -2, "y": -12, "z": 9, "c": "#6f7378"}, {"id": 230, "x": -2, "y": -12, "z": 10, "c": "#9a8366"}, {"id": 231, "x": -1, "y": -12, "z": -10, "c": "#6f7378"}, {"id": 232, "x": -1, "y": -12, "z": -9, "c": "#9a8366"}, {"id": 233, "x": -1, "y": -12, "z": -8, "c": "#6f7378"}, {"id": 234, "x": -1, "y": -12, "z": -7, "c": "#9a8366"}, {"id": 235, "x": -1, "y": -12, "z": -6, "c": "#6f7378"}, {"id": 236, "x": -1, "y": -12, "z": -5, "c": "#6f7378"}, {"id": 237, "x": -1, "y": -12, "z": -4, "c": "#6f7378"}, {"id": 238, "x": -1, "y": -12, "z": -3, "c": "#6f7378"}, {"id": 239, "x": -1, "y": -12, "z": -2, "c": "#6f7378"}, {"id": 240, "x": -1, "y": -12, "z": -1, "c": "#6f7378"}, {"id": 241, "x": -1, "y": -12, "z": 0, "c": "#6f7378"}, {"id": 242, "x": -1, "y": -12, "z": 1, "c": "#6f7378"}, {"id": 243, "x": -1, "y": -12, "z": 2, "c": "#6f7378"}, {"id": 244, "x": -1, "y": -12, "z": 3, "c": "#6f7378"}, {"id": 245, "x": -1, "y": -12, "z": 4, "c": "#6f7378"}, {"id": 246, "x": -1, "y": -12, "z": 5, "c": "#6f7378"}, {"id": 247, "x": -1, "y": -12, "z": 6, "c": "#6f7378"}, {"id": 248, "x": -1, "y": -12, "z": 7, "c": "#9a8366"}, {"id": 249, "x": -1, "y": -12, "z": 8, "c": "#6f7378"}, {"id": 250, "x": -1, "y": -12, "z": 9, "c": "#9a8366"}, {"id": 251, "x": -1, "y": -12, "z": 10, "c": "#6f7378"}, {"id": 252, "x": 0, "y": -12, "z": -10, "c": "#9a8366"}, {"id": 253, "x": 0, "y": -12, "z": -9, "c": "#6f7378"}, {"id": 254, "x": 0, "y": -12, "z": -8, "c": "#9a8366"}, {"id": 255, "x": 0, "y": -12, "z": -7, "c": "#6f7378"}, {"id": 256, "x": 0, "y": -12, "z": -6, "c": "#6f7378"}, {"id": 257, "x": 0, "y": -12, "z": -5, "c": "#6f7378"}, {"id": 258, "x": 0, "y": -12, "z": -4, "c": "#6f7378"}, {"id": 259, "x": 0, "y": -12, "z": -3, "c": "#6f7378"}, {"id": 260, "x": 0, "y": -12, "z": -2, "c": "#6f7378"}, {"id": 261, "x": 0, "y": -12, "z": -1, "c": "#6f7378"}, {"id": 262, "x": 0, "y": -12, "z": 0, "c": "#6f7378"}, {"id": 263, "x": 0, "y": -12, "z": 1, "c": "#6f7378"}, {"id": 264, "x": 0, "y": -12, "z": 2, "c": "#6f7378"}, {"id": 265, "x": 0, "y": -12, "z": 3, "c": "#6f7378"}, {"id": 266, "x": 0, "y": -12, "z": 4, "c": "#6f7378"}, {"id": 267, "x": 0, "y": -12, "z": 5, "c": "#6f7378"}, {"id": 268, "x": 0, "y": -12, "z": 6, "c": "#6f7378"}, {"id": 269, "x": 0, "y": -12, "z": 7, "c": "#6f7378"}, {"id": 270, "x": 0, "y": -12, "z": 8, "c": "#9a8366"}, {"id": 271, "x": 0, "y": -12, "z": 9, "c": "#6f7378"}, {"id": 272, "x": 0, "y": -12, "z": 10, "c": "#9a8366"}, {"id": 273, "x": 1, "y": -12, "z": -10, "c": "#6f7378"}, {"id": 274, "x": 1, "y": -12, "z": -9, "c": "#9a8366"}, {"id": 275, "x": 1, "y": -12, "z": -8, "c": "#6f7378"}, {"id": 276, "x": 1, "y": -12, "z": -7, "c": "#9a8366"}, {"id": 277, "x": 1, "y": -12, "z": -6, "c": "#6f7378"}, {"id": 278, "x": 1, "y": -12, "z": -5, "c": "#6f7378"}, {"id": 279, "x": 1, "y": -12, "z": -4, "c": "#6f7378"}, {"id": 280, "x": 1, "y": -12, "z": -3, "c": "#6f7378"}, {"id": 281, "x": 1, "y": -12, "z": -2, "c": "#6f7378"}, {"id": 282, "x": 1, "y": -12, "z": -1, "c": "#6f7378"}, {"id": 283, "x": 1, "y": -12, "z": 0, "c": "#6f7378"}, {"id": 284, "x": 1, "y": -12, "z": 1, "c": "#6f7378"}, {"id": 285, "x": 1, "y": -12, "z": 2, "c": "#6f7378"}, {"id": 286, "x": 1, "y": -12, "z": 3, "c": "#6f7378"}, {"id": 287, "x": 1, "y": -12, "z": 4, "c": "#6f7378"}, {"id": 288, "x": 1, "y": -12, "z": 5, "c": "#6f7378"}, {"id": 289, "x": 1, "y": -12, "z": 6, "c": "#6f7378"}, {"id": 290, "x": 1, "y": -12, "z": 7, "c": "#9a8366"}, {"id": 291, "x": 1, "y": -12, "z": 8, "c": "#6f7378"}, {"id": 292, "x": 1, "y": -12, "z": 9, "c": "#9a8366"}, {"id": 293, "x": 1, "y": -12, "z": 10, "c": "#6f7378"}, {"id": 294, "x": 2, "y": -12, "z": -10, "c": "#9a8366"}, {"id": 295, "x": 2, "y": -12, "z": -9, "c": "#6f7378"}, {"id": 296, "x": 2, "y": -12, "z": -8, "c": "#9a8366"}, {"id": 297, "x": 2, "y": -12, "z": -7, "c": "#6f7378"}, {"id": 298, "x": 2, "y": -12, "z": -6, "c": "#6f7378"}, {"id": 299, "x": 2, "y": -12, "z": -5, "c": "#6f7378"}, {"id": 300, "x": 2, "y": -12, "z": -4, "c": "#6f7378"}, {"id": 301, "x": 2, "y": -12, "z": -3, "c": "#6f7378"}, {"id": 302, "x": 2, "y": -12, "z": -2, "c": "#6f7378"}, {"id": 303, "x": 2, "y": -12, "z": -1, "c": "#6f7378"}, {"id": 304, "x": 2, "y": -12, "z": 0, "c": "#6f7378"}, {"id": 305, "x": 2, "y": -12, "z": 1, "c": "#6f7378"}, {"id": 306, "x": 2, "y": -12, "z": 2, "c": "#6f7378"}, {"id": 307, "x": 2, "y": -12, "z": 3, "c": "#6f7378"}, {"id": 308, "x": 2, "y": -12, "z": 4, "c": "#6f7378"}, {"id": 309, "x": 2, "y": -12, "z": 5, "c": "#6f7378"}, {"id": 310, "x": 2, "y": -12, "z": 6, "c": "#6f7378"}, {"id": 311, "x": 2, "y": -12, "z": 7, "c": "#6f7378"}, {"id": 312, "x": 2, "y": -12, "z": 8, "c": "#9a8366"}, {"id": 313, "x": 2, "y": -12, "z": 9, "c": "#6f7378"}, {"id": 314, "x": 2, "y": -12, "z": 10, "c": "#9a8366"}, {"id": 315, "x": 3, "y": -12, "z": -10, "c": "#6f7378"}, {"id": 316, "x": 3, "y": -12, "z": -9, "c": "#9a8366"}, {"id": 317, "x": 3, "y": -12, "z": -8, "c": "#6f7378"}, {"id": 318, "x": 3, "y": -12, "z": -7, "c": "#9a8366"}, {"id": 319, "x": 3, "y": -12, "z": -6, "c": "#6f7378"}, {"id": 320, "x": 3, "y": -12, "z": -5, "c": "#6f7378"}, {"id": 321, "x": 3, "y": -12, "z": -4, "c": "#6f7378"}, {"id": 322, "x": 3, "y": -12, "z": -3, "c": "#6f7378"}, {"id": 323, "x": 3, "y": -12, "z": -2, "c": "#6f7378"}, {"id": 324, "x": 3, "y": -12, "z": -1, "c": "#6f7378"}, {"id": 325, "x": 3, "y": -12, "z": 0, "c": "#6f7378"}, {"id": 326, "x": 3, "y": -12, "z": 1, "c": "#6f7378"}, {"id": 327, "x": 3, "y": -12, "z": 2, "c": "#6f7378"}, {"id": 328, "x": 3, "y": -12, "z": 3, "c": "#6f7378"}, {"id": 329, "x": 3, "y": -12, "z": 4, "c": "#6f7378"}, {"id": 330, "x": 3, "y": -12, "z": 5, "c": "#6f7378"}, {"id": 331, "x": 3, "y": -12, "z": 6, "c": "#6f7378"}, {"id": 332, "x": 3, "y": -12, "z": 7, "c": "#9a8366"}, {"id": 333, "x": 3, "y": -12, "z": 8, "c": "#6f7378"}, {"id": 334, "x": 3, "y": -12, "z": 9, "c": "#9a8366"}, {"id": 335, "x": 3, "y": -12, "z": 10, "c": "#6f7378"}, {"id": 336, "x": 4, "y": -12, "z": -10, "c": "#9a8366"}, {"id": 337, "x": 4, "y": -12, "z": -9, "c": "#6f7378"}, {"id": 338, "x": 4, "y": -12, "z": -8, "c": "#9a8366"}, {"id": 339, "x": 4, "y": -12, "z": -7, "c": "#6f7378"}, {"id": 340, "x": 4, "y": -12, "z": -6, "c": "#6f7378"}, {"id": 341, "x": 4, "y": -12, "z": -5, "c": "#6f7378"}, {"id": 342, "x": 4, "y": -12, "z": -4, "c": "#6f7378"}, {"id": 343, "x": 4, "y": -12, "z": -3, "c": "#6f7378"}, {"id": 344, "x": 4, "y": -12, "z": -2, "c": "#6f7378"}, {"id": 345, "x": 4, "y": -12, "z": -1, "c": "#6f7378"}, {"id": 346, "x": 4, "y": -12, "z": 0, "c": "#6f7378"}, {"id": 347, "x": 4, "y": -12, "z": 1, "c": "#6f7378"}, {"id": 348, "x": 4, "y": -12, "z": 2, "c": "#6f7378"}, {"id": 349, "x": 4, "y": -12, "z": 3, "c": "#6f7378"}, {"id": 350, "x": 4, "y": -12, "z": 4, "c": "#6f7378"}, {"id": 351, "x": 4, "y": -12, "z": 5, "c": "#6f7378"}, {"id": 352, "x": 4, "y": -12, "z": 6, "c": "#6f7378"}, {"id": 353, "x": 4, "y": -12, "z": 7, "c": "#6f7378"}, {"id": 354, "x": 4, "y": -12, "z": 8, "c": "#9a8366"}, {"id": 355, "x": 4, "y": -12, "z": 9, "c": "#6f7378"}, {"id": 356, "x": 4, "y": -12, "z": 10, "c": "#9a8366"}, {"id": 357, "x": 5, "y": -12, "z": -10, "c": "#6f7378"}, {"id": 358, "x": 5, "y": -12, "z": -9, "c": "#9a8366"}, {"id": 359, "x": 5, "y": -12, "z": -8, "c": "#6f7378"}, {"id": 360, "x": 5, "y": -12, "z": -7, "c": "#9a8366"}, {"id": 361, "x": 5, "y": -12, "z": -6, "c": "#6f7378"}, {"id": 362, "x": 5, "y": -12, "z": -5, "c": "#6f7378"}, {"id": 363, "x": 5, "y": -12, "z": -4, "c": "#6f7378"}, {"id": 364, "x": 5, "y": -12, "z": -3, "c": "#6f7378"}, {"id": 365, "x": 5, "y": -12, "z": -2, "c": "#6f7378"}, {"id": 366, "x": 5, "y": -12, "z": -1, "c": "#6f7378"}, {"id": 367, "x": 5, "y": -12, "z": 0, "c": "#6f7378"}, {"id": 368, "x": 5, "y": -12, "z": 1, "c": "#6f7378"}, {"id": 369, "x": 5, "y": -12, "z": 2, "c": "#6f7378"}, {"id": 370, "x": 5, "y": -12, "z": 3, "c": "#6f7378"}, {"id": 371, "x": 5, "y": -12, "z": 4, "c": "#6f7378"}, {"id": 372, "x": 5, "y": -12, "z": 5, "c": "#6f7378"}, {"id": 373, "x": 5, "y": -12, "z": 6, "c": "#6f7378"}, {"id": 374, "x": 5, "y": -12, "z": 7, "c": "#9a8366"}, {"id": 375, "x": 5, "y": -12, "z": 8, "c": "#6f7378"}, {"id": 376, "x": 5, "y": -12, "z": 9, "c": "#9a8366"}, {"id": 377, "x": 5, "y": -12, "z": 10, "c": "#6f7378"}, {"id": 378, "x": 6, "y": -12, "z": -10, "c": "#9a8366"}, {"id": 379, "x": 6, "y": -12, "z": -9, "c": "#6f7378"}, {"id": 380, "x": 6, "y": -12, "z": -8, "c": "#9a8366"}, {"id": 381, "x": 6, "y": -12, "z": -7, "c": "#6f7378"}, {"id": 382, "x": 6, "y": -12, "z": -6, "c": "#6f7378"}, {"id": 383, "x": 6, "y": -12, "z": -5, "c": "#6f7378"}, {"id": 384, "x": 6, "y": -12, "z": -4, "c": "#6f7378"}, {"id": 385, "x": 6, "y": -12, "z": -3, "c": "#6f7378"}, {"id": 386, "x": 6, "y": -12, "z": -2, "c": "#6f7378"}, {"id": 387, "x": 6, "y": -12, "z": -1, "c": "#6f7378"}, {"id": 388, "x": 6, "y": -12, "z": 0, "c": "#6f7378"}, {"id": 389, "x": 6, "y": -12, "z": 1, "c": "#6f7378"}, {"id": 390, "x": 6, "y": -12, "z": 2, "c": "#6f7378"}, {"id": 391, "x": 6, "y": -12, "z": 3, "c": "#6f7378"}, {"id": 392, "x": 6, "y": -12, "z": 4, "c": "#6f7378"}, {"id": 393, "x": 6, "y": -12, "z": 5, "c": "#6f7378"}, {"id": 394, "x": 6, "y": -12, "z": 6, "c": "#6f7378"}, {"id": 395, "x": 6, "y": -12, "z": 7, "c": "#6f7378"}, {"id": 396, "x": 6, "y": -12, "z": 8, "c": "#9a8366"}, {"id": 397, "x": 6, "y": -12, "z": 9, "c": "#6f7378"}, {"id": 398, "x": 6, "y": -12, "z": 10, "c": "#9a8366"}, {"id": 399, "x": 7, "y": -12, "z": -10, "c": "#6f7378"}, {"id": 400, "x": 7, "y": -12, "z": -9, "c": "#9a8366"}, {"id": 401, "x": 7, "y": -12, "z": -8, "c": "#6f7378"}, {"id": 402, "x": 7, "y": -12, "z": -7, "c": "#9a8366"}, {"id": 403, "x": 7, "y": -12, "z": -6, "c": "#6f7378"}, {"id": 404, "x": 7, "y": -12, "z": -5, "c": "#6f7378"}, {"id": 405, "x": 7, "y": -12, "z": -4, "c": "#6f7378"}, {"id": 406, "x": 7, "y": -12, "z": -3, "c": "#6f7378"}, {"id": 407, "x": 7, "y": -12, "z": -2, "c": "#6f7378"}, {"id": 408, "x": 7, "y": -12, "z": -1, "c": "#6f7378"}, {"id": 409, "x": 7, "y": -12, "z": 0, "c": "#6f7378"}, {"id": 410, "x": 7, "y": -12, "z": 1, "c": "#6f7378"}, {"id": 411, "x": 7, "y": -12, "z": 2, "c": "#6f7378"}, {"id": 412, "x": 7, "y": -12, "z": 3, "c": "#6f7378"}, {"id": 413, "x": 7, "y": -12, "z": 4, "c": "#6f7378"}, {"id": 414, "x": 7, "y": -12, "z": 5, "c": "#6f7378"}, {"id": 415, "x": 7, "y": -12, "z": 6, "c": "#6f7378"}, {"id": 416, "x": 7, "y": -12, "z": 7, "c": "#9a8366"}, {"id": 417, "x": 7, "y": -12, "z": 8, "c": "#6f7378"}, {"id": 418, "x": 7, "y": -12, "z": 9, "c": "#9a8366"}, {"id": 419, "x": 7, "y": -12, "z": 10, "c": "#6f7378"}, {"id": 420, "x": 8, "y": -12, "z": -10, "c": "#9a8366"}, {"id": 421, "x": 8, "y": -12, "z": -9, "c": "#6f7378"}, {"id": 422, "x": 8, "y": -12, "z": -8, "c": "#9a8366"}, {"id": 423, "x": 8, "y": -12, "z": -7, "c": "#6f7378"}, {"id": 424, "x": 8, "y": -12, "z": -6, "c": "#6f7378"}, {"id": 425, "x": 8, "y": -12, "z": -5, "c": "#6f7378"}, {"id": 426, "x": 8, "y": -12, "z": -4, "c": "#6f7378"}, {"id": 427, "x": 8, "y": -12, "z": -3, "c": "#6f7378"}, {"id": 428, "x": 8, "y": -12, "z": -2, "c": "#6f7378"}, {"id": 429, "x": 8, "y": -12, "z": -1, "c": "#6f7378"}, {"id": 430, "x": 8, "y": -12, "z": 0, "c": "#6f7378"}, {"id": 431, "x": 8, "y": -12, "z": 1, "c": "#6f7378"}, {"id": 432, "x": 8, "y": -12, "z": 2, "c": "#6f7378"}, {"id": 433, "x": 8, "y": -12, "z": 3, "c": "#6f7378"}, {"id": 434, "x": 8, "y": -12, "z": 4, "c": "#6f7378"}, {"id": 435, "x": 8, "y": -12, "z": 5, "c": "#6f7378"}, {"id": 436, "x": 8, "y": -12, "z": 6, "c": "#6f7378"}, {"id": 437, "x": 8, "y": -12, "z": 7, "c": "#6f7378"}, {"id": 438, "x": 8, "y": -12, "z": 8, "c": "#9a8366"}, {"id": 439, "x": 8, "y": -12, "z": 9, "c": "#6f7378"}, {"id": 440, "x": 8, "y": -12, "z": 10, "c": "#9a8366"}, {"id": 441, "x": 9, "y": -12, "z": -10, "c": "#6f7378"}, {"id": 442, "x": 9, "y": -12, "z": -9, "c": "#9a8366"}, {"id": 443, "x": 9, "y": -12, "z": -8, "c": "#6f7378"}, {"id": 444, "x": 9, "y": -12, "z": -7, "c": "#9a8366"}, {"id": 445, "x": 9, "y": -12, "z": -6, "c": "#6f7378"}, {"id": 446, "x": 9, "y": -12, "z": -5, "c": "#6f7378"}, {"id": 447, "x": 9, "y": -12, "z": -4, "c": "#6f7378"}, {"id": 448, "x": 9, "y": -12, "z": -3, "c": "#6f7378"}, {"id": 449, "x": 9, "y": -12, "z": -2, "c": "#6f7378"}, {"id": 450, "x": 9, "y": -12, "z": -1, "c": "#6f7378"}, {"id": 451, "x": 9, "y": -12, "z": 0, "c": "#9a8366"}, {"id": 452, "x": 9, "y": -12, "z": 1, "c": "#9a8366"}, {"id": 453, "x": 9, "y": -12, "z": 2, "c": "#6f7378"}, {"id": 454, "x": 9, "y": -12, "z": 3, "c": "#6f7378"}, {"id": 455, "x": 9, "y": -12, "z": 4, "c": "#6f7378"}, {"id": 456, "x": 9, "y": -12, "z": 5, "c": "#6f7378"}, {"id": 457, "x": 9, "y": -12, "z": 6, "c": "#6f7378"}, {"id": 458, "x": 9, "y": -12, "z": 7, "c": "#9a8366"}, {"id": 459, "x": 9, "y": -12, "z": 8, "c": "#6f7378"}, {"id": 460, "x": 9, "y": -12, "z": 9, "c": "#9a8366"}, {"id": 461, "x": 9, "y": -12, "z": 10, "c": "#6f7378"}, {"id": 462, "x": 10, "y": -12, "z": -10, "c": "#9a8366"}, {"id": 463, "x": 10, "y": -12, "z": -9, "c": "#6f7378"}, {"id": 464, "x": 10, "y": -12, "z": -8, "c": "#9a8366"}, {"id": 465, "x": 10, "y": -12, "z": -7, "c": "#6f7378"}, {"id": 466, "x": 10, "y": -12, "z": -6, "c": "#6f7378"}, {"id": 467, "x": 10, "y": -12, "z": -5, "c": "#6f7378"}, {"id": 468, "x": 10, "y": -12, "z": -4, "c": "#6f7378"}, {"id": 469, "x": 10, "y": -12, "z": -3, "c": "#6f7378"}, {"id": 470, "x": 10, "y": -12, "z": -2, "c": "#6f7378"}, {"id": 471, "x": 10, "y": -12, "z": -1, "c": "#6f7378"}, {"id": 472, "x": 10, "y": -12, "z": 0, "c": "#9a8366"}, {"id": 473, "x": 10, "y": -12, "z": 1, "c": "#9a8366"}, {"id": 474, "x": 10, "y": -12, "z": 2, "c": "#6f7378"}, {"id": 475, "x": 10, "y": -12, "z": 3, "c": "#6f7378"}, {"id": 476, "x": 10, "y": -12, "z": 4, "c": "#6f7378"}, {"id": 477, "x": 10, "y": -12, "z": 5, "c": "#6f7378"}, {"id": 478, "x": 10, "y": -12, "z": 6, "c": "#6f7378"}, {"id": 479, "x": 10, "y": -12, "z": 7, "c": "#6f7378"}, {"id": 480, "x": 10, "y": -12, "z": 8, "c": "#9a8366"}, {"id": 481, "x": 10, "y": -12, "z": 9, "c": "#6f7378"}, {"id": 482, "x": 10, "y": -12, "z": 10, "c": "#9a8366"}, {"id": 483, "x": 11, "y": -12, "z": -10, "c": "#6f7378"}, {"id": 484, "x": 11, "y": -12, "z": -9, "c": "#9a8366"}, {"id": 485, "x": 11, "y": -12, "z": -8, "c": "#6f7378"}, {"id": 486, "x": 11, "y": -12, "z": -7, "c": "#9a8366"}, {"id": 487, "x": 11, "y": -12, "z": -6, "c": "#6f7378"}, {"id": 488, "x": 11, "y": -12, "z": -5, "c": "#6f7378"}, {"id": 489, "x": 11, "y": -12, "z": -4, "c": "#6f7378"}, {"id": 490, "x": 11, "y": -12, "z": -3, "c": "#6f7378"}, {"id": 491, "x": 11, "y": -12, "z": -2, "c": "#6f7378"}, {"id": 492, "x": 11, "y": -12, "z": -1, "c": "#6f7378"}, {"id": 493, "x": 11, "y": -12, "z": 0, "c": "#9a8366"}, {"id": 494, "x": 11, "y": -12, "z": 1, "c": "#9a8366"}, {"id": 495, "x": 11, "y": -12, "z": 2, "c": "#6f7378"}, {"id": 496, "x": 11, "y": -12, "z": 3, "c": "#6f7378"}, {"id": 497, "x": 11, "y": -12, "z": 4, "c": "#6f7378"}, {"id": 498, "x": 11, "y": -12, "z": 5, "c": "#6f7378"}, {"id": 499, "x": 11, "y": -12, "z": 6, "c": "#6f7378"}, {"id": 500, "x": 11, "y": -12, "z": 7, "c": "#9a8366"}, {"id": 501, "x": 11, "y": -12, "z": 8, "c": "#6f7378"}, {"id": 502, "x": 11, "y": -12, "z": 9, "c": "#9a8366"}, {"id": 503, "x": 11, "y": -12, "z": 10, "c": "#6f7378"}, {"id": 504, "x": 12, "y": -12, "z": -10, "c": "#9a8366"}, {"id": 505, "x": 12, "y": -12, "z": -9, "c": "#6f7378"}, {"id": 506, "x": 12, "y": -12, "z": -8, "c": "#9a8366"}, {"id": 507, "x": 12, "y": -12, "z": -7, "c": "#6f7378"}, {"id": 508, "x": 12, "y": -12, "z": -6, "c": "#6f7378"}, {"id": 509, "x": 12, "y": -12, "z": -5, "c": "#6f7378"}, {"id": 510, "x": 12, "y": -12, "z": -4, "c": "#6f7378"}, {"id": 511, "x": 12, "y": -12, "z": -3, "c": "#6f7378"}, {"id": 512, "x": 12, "y": -12, "z": -2, "c": "#6f7378"}, {"id": 513, "x": 12, "y": -12, "z": -1, "c": "#6f7378"}, {"id": 514, "x": 12, "y": -12, "z": 0, "c": "#9a8366"}, {"id": 515, "x": 12, "y": -12, "z": 1, "c": "#9a8366"}, {"id": 516, "x": 12, "y": -12, "z": 2, "c": "#6f7378"}, {"id": 517, "x": 12, "y": -12, "z": 3, "c": "#6f7378"}, {"id": 518, "x": 12, "y": -12, "z": 4, "c": "#6f7378"}, {"id": 519, "x": 12, "y": -12, "z": 5, "c": "#6f7378"}, {"id": 520, "x": 12, "y": -12, "z": 6, "c": "#6f7378"}, {"id": 521, "x": 12, "y": -12, "z": 7, "c": "#6f7378"}, {"id": 522, "x": 12, "y": -12, "z": 8, "c": "#9a8366"}, {"id": 523, "x": 12, "y": -12, "z": 9, "c": "#6f7378"}, {"id": 524, "x": 12, "y": -12, "z": 10, "c": "#9a8366"}, {"id": 525, "x": -12, "y": -11, "z": 10, "c": "#30363d"}, {"id": 526, "x": -12, "y": -10, "z": 10, "c": "#30363d"}, {"id": 527, "x": -11, "y": -11, "z": 10, "c": "#30363d"}, {"id": 528, "x": -11, "y": -10, "z": 10, "c": "#30363d"}, {"id": 529, "x": -10, "y": -11, "z": 10, "c": "#30363d"}, {"id": 530, "x": -10, "y": -10, "z": 10, "c": "#30363d"}, {"id": 531, "x": -9, "y": -11, "z": 10, "c": "#30363d"}, {"id": 532, "x": -9, "y": -10, "z": 10, "c": "#30363d"}, {"id": 533, "x": -8, "y": -11, "z": 10, "c": "#30363d"}, {"id": 534, "x": -8, "y": -10, "z": 10, "c": "#30363d"}, {"id": 535, "x": -7, "y": -11, "z": 10, "c": "#30363d"}, {"id": 536, "x": -7, "y": -10, "z": 10, "c": "#30363d"}, {"id": 537, "x": -6, "y": -11, "z": 10, "c": "#30363d"}, {"id": 538, "x": -6, "y": -10, "z": 10, "c": "#30363d"}, {"id": 539, "x": -12, "y": -11, "z": 0, "c": "#30363d"}, {"id": 540, "x": -12, "y": -10, "z": 0, "c": "#30363d"}, {"id": 541, "x": -12, "y": -11, "z": 1, "c": "#30363d"}, {"id": 542, "x": -12, "y": -10, "z": 1, "c": "#30363d"}, {"id": 543, "x": -12, "y": -11, "z": 2, "c": "#30363d"}, {"id": 544, "x": -12, "y": -10, "z": 2, "c": "#30363d"}, {"id": 545, "x": -12, "y": -11, "z": 3, "c": "#30363d"}, {"id": 546, "x": -12, "y": -10, "z": 3, "c": "#30363d"}, {"id": 547, "x": -12, "y": -11, "z": 4, "c": "#30363d"}, {"id": 548, "x": -12, "y": -10, "z": 4, "c": "#30363d"}, {"id": 549, "x": -12, "y": -11, "z": 5, "c": "#30363d"}, {"id": 550, "x": -12, "y": -10, "z": 5, "c": "#30363d"}, {"id": 551, "x": -12, "y": -11, "z": 6, "c": "#30363d"}, {"id": 552, "x": -12, "y": -10, "z": 6, "c": "#30363d"}, {"id": 553, "x": -12, "y": -11, "z": 7, "c": "#30363d"}, {"id": 554, "x": -12, "y": -10, "z": 7, "c": "#30363d"}, {"id": 555, "x": -12, "y": -11, "z": 8, "c": "#30363d"}, {"id": 556, "x": -12, "y": -10, "z": 8, "c": "#30363d"}, {"id": 557, "x": -12, "y": -11, "z": 9, "c": "#30363d"}, {"id": 558, "x": -12, "y": -10, "z": 9, "c": "#30363d"}, {"id": 559, "x": -8, "y": -11, "z": -6, "c": "#b0a89c"}, {"id": 560, "x": -8, "y": -11, "z": -5, "c": "#b0a89c"}, {"id": 561, "x": -8, "y": -11, "z": -4, "c": "#b0a89c"}, {"id": 562, "x": -8, "y": -11, "z": -3, "c": "#b0a89c"}, {"id": 563, "x": -8, "y": -11, "z": -2, "c": "#b0a89c"}, {"id": 564, "x": -8, "y": -11, "z": -1, "c": "#b0a89c"}, {"id": 565, "x": -8, "y": -11, "z": 0, "c": "#b0a89c"}, {"id": 566, "x": -8, "y": -11, "z": 1, "c": "#b0a89c"}, {"id": 567, "x": -8, "y": -11, "z": 2, "c": "#b0a89c"}, {"id": 568, "x": -8, "y": -11, "z": 3, "c": "#23272c"}, {"id": 569, "x": -8, "y": -11, "z": 4, "c": "#23272c"}, {"id": 570, "x": -8, "y": -11, "z": 5, "c": "#23272c"}, {"id": 571, "x": -8, "y": -11, "z": 6, "c": "#23272c"}, {"id": 572, "x": -7, "y": -11, "z": -6, "c": "#b0a89c"}, {"id": 573, "x": -7, "y": -11, "z": 6, "c": "#b0a89c"}, {"id": 574, "x": -6, "y": -11, "z": -6, "c": "#b0a89c"}, {"id": 575, "x": -6, "y": -11, "z": 6, "c": "#b0a89c"}, {"id": 576, "x": -5, "y": -11, "z": -6, "c": "#b0a89c"}, {"id": 577, "x": -5, "y": -11, "z": 6, "c": "#b0a89c"}, {"id": 578, "x": -4, "y": -11, "z": -6, "c": "#b0a89c"}, {"id": 579, "x": -4, "y": -11, "z": 6, "c": "#b0a89c"}, {"id": 580, "x": -3, "y": -11, "z": -6, "c": "#b0a89c"}, {"id": 581, "x": -3, "y": -11, "z": 6, "c": "#b0a89c"}, {"id": 582, "x": -2, "y": -11, "z": -6, "c": "#b0a89c"}, {"id": 583, "x": -2, "y": -11, "z": 6, "c": "#b0a89c"}, {"id": 584, "x": -1, "y": -11, "z": -6, "c": "#b0a89c"}, {"id": 585, "x": -1, "y": -11, "z": 6, "c": "#60737e"}, {"id": 586, "x": 0, "y": -11, "z": -6, "c": "#b0a89c"}, {"id": 587, "x": 0, "y": -11, "z": 6, "c": "#60737e"}, {"id": 588, "x": 1, "y": -11, "z": -6, "c": "#b0a89c"}, {"id": 589, "x": 1, "y": -11, "z": 6, "c": "#60737e"}, {"id": 590, "x": 2, "y": -11, "z": -6, "c": "#b0a89c"}, {"id": 591, "x": 2, "y": -11, "z": 6, "c": "#b0a89c"}, {"id": 592, "x": 3, "y": -11, "z": -6, "c": "#b0a89c"}, {"id": 593, "x": 3, "y": -11, "z": 6, "c": "#b0a89c"}, {"id": 594, "x": 4, "y": -11, "z": -6, "c": "#b0a89c"}, {"id": 595, "x": 4, "y": -11, "z": 6, "c": "#b0a89c"}, {"id": 596, "x": 5, "y": -11, "z": -6, "c": "#b0a89c"}, {"id": 597, "x": 5, "y": -11, "z": 6, "c": "#b0a89c"}, {"id": 598, "x": 6, "y": -11, "z": -6, "c": "#b0a89c"}, {"id": 599, "x": 6, "y": -11, "z": 6, "c": "#b0a89c"}, {"id": 600, "x": 7, "y": -11, "z": -6, "c": "#b0a89c"}, {"id": 601, "x": 7, "y": -11, "z": 6, "c": "#b0a89c"}, {"id": 602, "x": 8, "y": -11, "z": -6, "c": "#b0a89c"}, {"id": 603, "x": 8, "y": -11, "z": -5, "c": "#b0a89c"}, {"id": 604, "x": 8, "y": -11, "z": -4, "c": "#b0a89c"}, {"id": 605, "x": 8, "y": -11, "z": -3, "c": "#b0a89c"}, {"id": 606, "x": 8, "y": -11, "z": -2, "c": "#b0a89c"}, {"id": 607, "x": 8, "y": -11, "z": -1, "c": "#b0a89c"}, {"id": 608, "x": 8, "y": -11, "z": 0, "c": "#b0a89c"}, {"id": 609, "x": 8, "y": -11, "z": 1, "c": "#b0a89c"}, {"id": 610, "x": 8, "y": -11, "z": 2, "c": "#b0a89c"}, {"id": 611, "x": 8, "y": -11, "z": 3, "c": "#b0a89c"}, {"id": 612, "x": 8, "y": -11, "z": 4, "c": "#b0a89c"}, {"id": 613, "x": 8, "y": -11, "z": 5, "c": "#b0a89c"}, {"id": 614, "x": 8, "y": -11, "z": 6, "c": "#b0a89c"}, {"id": 615, "x": -8, "y": -10, "z": -6, "c": "#b0a89c"}, {"id": 616, "x": -8, "y": -10, "z": -5, "c": "#b0a89c"}, {"id": 617, "x": -8, "y": -10, "z": -4, "c": "#b0a89c"}, {"id": 618, "x": -8, "y": -10, "z": -3, "c": "#b0a89c"}, {"id": 619, "x": -8, "y": -10, "z": -2, "c": "#b0a89c"}, {"id": 620, "x": -8, "y": -10, "z": -1, "c": "#b0a89c"}, {"id": 621, "x": -8, "y": -10, "z": 0, "c": "#b0a89c"}, {"id": 622, "x": -8, "y": -10, "z": 1, "c": "#b0a89c"}, {"id": 623, "x": -8, "y": -10, "z": 2, "c": "#b0a89c"}, {"id": 624, "x": -8, "y": -10, "z": 3, "c": "#23272c"}, {"id": 625, "x": -8, "y": -10, "z": 4, "c": "#b0a89c"}, {"id": 626, "x": -8, "y": -10, "z": 5, "c": "#23272c"}, {"id": 627, "x": -8, "y": -10, "z": 6, "c": "#b0a89c"}, {"id": 628, "x": -7, "y": -10, "z": -6, "c": "#b0a89c"}, {"id": 629, "x": -7, "y": -10, "z": 6, "c": "#b0a89c"}, {"id": 630, "x": -6, "y": -10, "z": -6, "c": "#60737e"}, {"id": 631, "x": -6, "y": -10, "z": 6, "c": "#60737e"}, {"id": 632, "x": -5, "y": -10, "z": -6, "c": "#b0a89c"}, {"id": 633, "x": -5, "y": -10, "z": 6, "c": "#b0a89c"}, {"id": 634, "x": -4, "y": -10, "z": -6, "c": "#b0a89c"}, {"id": 635, "x": -4, "y": -10, "z": 6, "c": "#b0a89c"}, {"id": 636, "x": -3, "y": -10, "z": -6, "c": "#60737e"}, {"id": 637, "x": -3, "y": -10, "z": 6, "c": "#60737e"}, {"id": 638, "x": -2, "y": -10, "z": -6, "c": "#b0a89c"}, {"id": 639, "x": -2, "y": -10, "z": 6, "c": "#b0a89c"}, {"id": 640, "x": -1, "y": -10, "z": -6, "c": "#b0a89c"}, {"id": 641, "x": -1, "y": -10, "z": 6, "c": "#60737e"}, {"id": 642, "x": 0, "y": -10, "z": -6, "c": "#60737e"}, {"id": 643, "x": 0, "y": -10, "z": 6, "c": "#60737e"}, {"id": 644, "x": 1, "y": -10, "z": -6, "c": "#b0a89c"}, {"id": 645, "x": 1, "y": -10, "z": 6, "c": "#60737e"}, {"id": 646, "x": 2, "y": -10, "z": -6, "c": "#b0a89c"}, {"id": 647, "x": 2, "y": -10, "z": 6, "c": "#b0a89c"}, {"id": 648, "x": 3, "y": -10, "z": -6, "c": "#60737e"}, {"id": 649, "x": 3, "y": -10, "z": 6, "c": "#60737e"}, {"id": 650, "x": 4, "y": -10, "z": -6, "c": "#b0a89c"}, {"id": 651, "x": 4, "y": -10, "z": 6, "c": "#b0a89c"}, {"id": 652, "x": 5, "y": -10, "z": -6, "c": "#b0a89c"}, {"id": 653, "x": 5, "y": -10, "z": 6, "c": "#b0a89c"}, {"id": 654, "x": 6, "y": -10, "z": -6, "c": "#60737e"}, {"id": 655, "x": 6, "y": -10, "z": 6, "c": "#60737e"}, {"id": 656, "x": 7, "y": -10, "z": -6, "c": "#b0a89c"}, {"id": 657, "x": 7, "y": -10, "z": 6, "c": "#b0a89c"}, {"id": 658, "x": 8, "y": -10, "z": -6, "c": "#b0a89c"}, {"id": 659, "x": 8, "y": -10, "z": -5, "c": "#b0a89c"}, {"id": 660, "x": 8, "y": -10, "z": -4, "c": "#b0a89c"}, {"id": 661, "x": 8, "y": -10, "z": -3, "c": "#b0a89c"}, {"id": 662, "x": 8, "y": -10, "z": -2, "c": "#b0a89c"}, {"id": 663, "x": 8, "y": -10, "z": -1, "c": "#b0a89c"}, {"id": 664, "x": 8, "y": -10, "z": 0, "c": "#b0a89c"}, {"id": 665, "x": 8, "y": -10, "z": 1, "c": "#b0a89c"}, {"id": 666, "x": 8, "y": -10, "z": 2, "c": "#b0a89c"}, {"id": 667, "x": 8, "y": -10, "z": 3, "c": "#b0a89c"}, {"id": 668, "x": 8, "y": -10, "z": 4, "c": "#b0a89c"}, {"id": 669, "x": 8, "y": -10, "z": 5, "c": "#b0a89c"}, {"id": 670, "x": 8, "y": -10, "z": 6, "c": "#b0a89c"}, {"id": 671, "x": -8, "y": -9, "z": -6, "c": "#b0a89c"}, {"id": 672, "x": -8, "y": -9, "z": -5, "c": "#b0a89c"}, {"id": 673, "x": -8, "y": -9, "z": -4, "c": "#b0a89c"}, {"id": 674, "x": -8, "y": -9, "z": -3, "c": "#b0a89c"}, {"id": 675, "x": -8, "y": -9, "z": -2, "c": "#b0a89c"}, {"id": 676, "x": -8, "y": -9, "z": -1, "c": "#b0a89c"}, {"id": 677, "x": -8, "y": -9, "z": 0, "c": "#b0a89c"}, {"id": 678, "x": -8, "y": -9, "z": 1, "c": "#b0a89c"}, {"id": 679, "x": -8, "y": -9, "z": 2, "c": "#b0a89c"}, {"id": 680, "x": -8, "y": -9, "z": 3, "c": "#23272c"}, {"id": 681, "x": -8, "y": -9, "z": 4, "c": "#60737e"}, {"id": 682, "x": -8, "y": -9, "z": 5, "c": "#23272c"}, {"id": 683, "x": -8, "y": -9, "z": 6, "c": "#60737e"}, {"id": 684, "x": -7, "y": -9, "z": -6, "c": "#b0a89c"}, {"id": 685, "x": -7, "y": -9, "z": 6, "c": "#b0a89c"}, {"id": 686, "x": -6, "y": -9, "z": -6, "c": "#b0a89c"}, {"id": 687, "x": -6, "y": -9, "z": 6, "c": "#b0a89c"}, {"id": 688, "x": -5, "y": -9, "z": -6, "c": "#b0a89c"}, {"id": 689, "x": -5, "y": -9, "z": 6, "c": "#b0a89c"}, {"id": 690, "x": -4, "y": -9, "z": -6, "c": "#b0a89c"}, {"id": 691, "x": -4, "y": -9, "z": 6, "c": "#b0a89c"}, {"id": 692, "x": -3, "y": -9, "z": -6, "c": "#b0a89c"}, {"id": 693, "x": -3, "y": -9, "z": 6, "c": "#b0a89c"}, {"id": 694, "x": -2, "y": -9, "z": -6, "c": "#b0a89c"}, {"id": 695, "x": -2, "y": -9, "z": 6, "c": "#b0a89c"}, {"id": 696, "x": -1, "y": -9, "z": -6, "c": "#b0a89c"}, {"id": 697, "x": -1, "y": -9, "z": 6, "c": "#60737e"}, {"id": 698, "x": 0, "y": -9, "z": -6, "c": "#b0a89c"}, {"id": 699, "x": 0, "y": -9, "z": 6, "c": "#60737e"}, {"id": 700, "x": 1, "y": -9, "z": -6, "c": "#b0a89c"}, {"id": 701, "x": 1, "y": -9, "z": 6, "c": "#60737e"}, {"id": 702, "x": 2, "y": -9, "z": -6, "c": "#b0a89c"}, {"id": 703, "x": 2, "y": -9, "z": 6, "c": "#b0a89c"}, {"id": 704, "x": 3, "y": -9, "z": -6, "c": "#b0a89c"}, {"id": 705, "x": 3, "y": -9, "z": 6, "c": "#b0a89c"}, {"id": 706, "x": 4, "y": -9, "z": -6, "c": "#b0a89c"}, {"id": 707, "x": 4, "y": -9, "z": 6, "c": "#b0a89c"}, {"id": 708, "x": 5, "y": -9, "z": -6, "c": "#b0a89c"}, {"id": 709, "x": 5, "y": -9, "z": 6, "c": "#b0a89c"}, {"id": 710, "x": 6, "y": -9, "z": -6, "c": "#b0a89c"}, {"id": 711, "x": 6, "y": -9, "z": 6, "c": "#b0a89c"}, {"id": 712, "x": 7, "y": -9, "z": -6, "c": "#b0a89c"}, {"id": 713, "x": 7, "y": -9, "z": 6, "c": "#b0a89c"}, {"id": 714, "x": 8, "y": -9, "z": -6, "c": "#b0a89c"}, {"id": 715, "x": 8, "y": -9, "z": -5, "c": "#b0a89c"}, {"id": 716, "x": 8, "y": -9, "z": -4, "c": "#b0a89c"}, {"id": 717, "x": 8, "y": -9, "z": -3, "c": "#b0a89c"}, {"id": 718, "x": 8, "y": -9, "z": -2, "c": "#b0a89c"}, {"id": 719, "x": 8, "y": -9, "z": -1, "c": "#b0a89c"}, {"id": 720, "x": 8, "y": -9, "z": 0, "c": "#b0a89c"}, {"id": 721, "x": 8, "y": -9, "z": 1, "c": "#b0a89c"}, {"id": 722, "x": 8, "y": -9, "z": 2, "c": "#b0a89c"}, {"id": 723, "x": 8, "y": -9, "z": 3, "c": "#b0a89c"}, {"id": 724, "x": 8, "y": -9, "z": 4, "c": "#b0a89c"}, {"id": 725, "x": 8, "y": -9, "z": 5, "c": "#b0a89c"}, {"id": 726, "x": 8, "y": -9, "z": 6, "c": "#b0a89c"}, {"id": 727, "x": -8, "y": -8, "z": -6, "c": "#c6beb1"}, {"id": 728, "x": -8, "y": -8, "z": -5, "c": "#c6beb1"}, {"id": 729, "x": -8, "y": -8, "z": -4, "c": "#c6beb1"}, {"id": 730, "x": -8, "y": -8, "z": -3, "c": "#c6beb1"}, {"id": 731, "x": -8, "y": -8, "z": -2, "c": "#c6beb1"}, {"id": 732, "x": -8, "y": -8, "z": -1, "c": "#c6beb1"}, {"id": 733, "x": -8, "y": -8, "z": 0, "c": "#c6beb1"}, {"id": 734, "x": -8, "y": -8, "z": 1, "c": "#c6beb1"}, {"id": 735, "x": -8, "y": -8, "z": 2, "c": "#c6beb1"}, {"id": 736, "x": -8, "y": -8, "z": 3, "c": "#c6beb1"}, {"id": 737, "x": -8, "y": -8, "z": 4, "c": "#c6beb1"}, {"id": 738, "x": -8, "y": -8, "z": 5, "c": "#c6beb1"}, {"id": 739, "x": -8, "y": -8, "z": 6, "c": "#c6beb1"}, {"id": 740, "x": -7, "y": -8, "z": -6, "c": "#c6beb1"}, {"id": 741, "x": -7, "y": -8, "z": 6, "c": "#c6beb1"}, {"id": 742, "x": -6, "y": -8, "z": -6, "c": "#60737e"}, {"id": 743, "x": -6, "y": -8, "z": 6, "c": "#60737e"}, {"id": 744, "x": -5, "y": -8, "z": -6, "c": "#c6beb1"}, {"id": 745, "x": -5, "y": -8, "z": 6, "c": "#c6beb1"}, {"id": 746, "x": -4, "y": -8, "z": -6, "c": "#c6beb1"}, {"id": 747, "x": -4, "y": -8, "z": 6, "c": "#c6beb1"}, {"id": 748, "x": -3, "y": -8, "z": -6, "c": "#60737e"}, {"id": 749, "x": -3, "y": -8, "z": 6, "c": "#60737e"}, {"id": 750, "x": -2, "y": -8, "z": -6, "c": "#c6beb1"}, {"id": 751, "x": -2, "y": -8, "z": 6, "c": "#c6beb1"}, {"id": 752, "x": -1, "y": -8, "z": -6, "c": "#c6beb1"}, {"id": 753, "x": -1, "y": -8, "z": 6, "c": "#c6beb1"}, {"id": 754, "x": 0, "y": -8, "z": -6, "c": "#60737e"}, {"id": 755, "x": 0, "y": -8, "z": 6, "c": "#60737e"}, {"id": 756, "x": 1, "y": -8, "z": -6, "c": "#c6beb1"}, {"id": 757, "x": 1, "y": -8, "z": 6, "c": "#c6beb1"}, {"id": 758, "x": 2, "y": -8, "z": -6, "c": "#c6beb1"}, {"id": 759, "x": 2, "y": -8, "z": 6, "c": "#c6beb1"}, {"id": 760, "x": 3, "y": -8, "z": -6, "c": "#60737e"}, {"id": 761, "x": 3, "y": -8, "z": 6, "c": "#60737e"}, {"id": 762, "x": 4, "y": -8, "z": -6, "c": "#c6beb1"}, {"id": 763, "x": 4, "y": -8, "z": 6, "c": "#c6beb1"}, {"id": 764, "x": 5, "y": -8, "z": -6, "c": "#c6beb1"}, {"id": 765, "x": 5, "y": -8, "z": 6, "c": "#c6beb1"}, {"id": 766, "x": 6, "y": -8, "z": -6, "c": "#60737e"}, {"id": 767, "x": 6, "y": -8, "z": 6, "c": "#60737e"}, {"id": 768, "x": 7, "y": -8, "z": -6, "c": "#c6beb1"}, {"id": 769, "x": 7, "y": -8, "z": 6, "c": "#c6beb1"}, {"id": 770, "x": 8, "y": -8, "z": -6, "c": "#c6beb1"}, {"id": 771, "x": 8, "y": -8, "z": -5, "c": "#c6beb1"}, {"id": 772, "x": 8, "y": -8, "z": -4, "c": "#c6beb1"}, {"id": 773, "x": 8, "y": -8, "z": -3, "c": "#c6beb1"}, {"id": 774, "x": 8, "y": -8, "z": -2, "c": "#c6beb1"}, {"id": 775, "x": 8, "y": -8, "z": -1, "c": "#c6beb1"}, {"id": 776, "x": 8, "y": -8, "z": 0, "c": "#c6beb1"}, {"id": 777, "x": 8, "y": -8, "z": 1, "c": "#c6beb1"}, {"id": 778, "x": 8, "y": -8, "z": 2, "c": "#c6beb1"}, {"id": 779, "x": 8, "y": -8, "z": 3, "c": "#c6beb1"}, {"id": 780, "x": 8, "y": -8, "z": 4, "c": "#c6beb1"}, {"id": 781, "x": 8, "y": -8, "z": 5, "c": "#c6beb1"}, {"id": 782, "x": 8, "y": -8, "z": 6, "c": "#c6beb1"}, {"id": 783, "x": -8, "y": -7, "z": -6, "c": "#4f7a74"}, {"id": 784, "x": -8, "y": -7, "z": -5, "c": "#4f7a74"}, {"id": 785, "x": -8, "y": -7, "z": -4, "c": "#4f7a74"}, {"id": 786, "x": -8, "y": -7, "z": -3, "c": "#4f7a74"}, {"id": 787, "x": -8, "y": -7, "z": -2, "c": "#4f7a74"}, {"id": 788, "x": -8, "y": -7, "z": -1, "c": "#4f7a74"}, {"id": 789, "x": -8, "y": -7, "z": 0, "c": "#4f7a74"}, {"id": 790, "x": -8, "y": -7, "z": 1, "c": "#4f7a74"}, {"id": 791, "x": -8, "y": -7, "z": 2, "c": "#4f7a74"}, {"id": 792, "x": -8, "y": -7, "z": 3, "c": "#4f7a74"}, {"id": 793, "x": -8, "y": -7, "z": 4, "c": "#4f7a74"}, {"id": 794, "x": -8, "y": -7, "z": 5, "c": "#4f7a74"}, {"id": 795, "x": -8, "y": -7, "z": 6, "c": "#4f7a74"}, {"id": 796, "x": -7, "y": -7, "z": -6, "c": "#4f7a74"}, {"id": 797, "x": -7, "y": -7, "z": 6, "c": "#4f7a74"}, {"id": 798, "x": -6, "y": -7, "z": -6, "c": "#4f7a74"}, {"id": 799, "x": -6, "y": -7, "z": 6, "c": "#4f7a74"}, {"id": 800, "x": -5, "y": -7, "z": -6, "c": "#4f7a74"}, {"id": 801, "x": -5, "y": -7, "z": 6, "c": "#4f7a74"}, {"id": 802, "x": -4, "y": -7, "z": -6, "c": "#4f7a74"}, {"id": 803, "x": -4, "y": -7, "z": 6, "c": "#4f7a74"}, {"id": 804, "x": -3, "y": -7, "z": -6, "c": "#4f7a74"}, {"id": 805, "x": -3, "y": -7, "z": 6, "c": "#4f7a74"}, {"id": 806, "x": -2, "y": -7, "z": -6, "c": "#4f7a74"}, {"id": 807, "x": -2, "y": -7, "z": 6, "c": "#4f7a74"}, {"id": 808, "x": -1, "y": -7, "z": -6, "c": "#4f7a74"}, {"id": 809, "x": -1, "y": -7, "z": 6, "c": "#4f7a74"}, {"id": 810, "x": 0, "y": -7, "z": -6, "c": "#4f7a74"}, {"id": 811, "x": 0, "y": -7, "z": 6, "c": "#4f7a74"}, {"id": 812, "x": 1, "y": -7, "z": -6, "c": "#4f7a74"}, {"id": 813, "x": 1, "y": -7, "z": 6, "c": "#4f7a74"}, {"id": 814, "x": 2, "y": -7, "z": -6, "c": "#4f7a74"}, {"id": 815, "x": 2, "y": -7, "z": 6, "c": "#4f7a74"}, {"id": 816, "x": 3, "y": -7, "z": -6, "c": "#4f7a74"}, {"id": 817, "x": 3, "y": -7, "z": 6, "c": "#4f7a74"}, {"id": 818, "x": 4, "y": -7, "z": -6, "c": "#4f7a74"}, {"id": 819, "x": 4, "y": -7, "z": 6, "c": "#4f7a74"}, {"id": 820, "x": 5, "y": -7, "z": -6, "c": "#4f7a74"}, {"id": 821, "x": 5, "y": -7, "z": 6, "c": "#4f7a74"}, {"id": 822, "x": 6, "y": -7, "z": -6, "c": "#4f7a74"}, {"id": 823, "x": 6, "y": -7, "z": 6, "c": "#4f7a74"}, {"id": 824, "x": 7, "y": -7, "z": -6, "c": "#4f7a74"}, {"id": 825, "x": 7, "y": -7, "z": 6, "c": "#4f7a74"}, {"id": 826, "x": 8, "y": -7, "z": -6, "c": "#4f7a74"}, {"id": 827, "x": 8, "y": -7, "z": -5, "c": "#4f7a74"}, {"id": 828, "x": 8, "y": -7, "z": -4, "c": "#4f7a74"}, {"id": 829, "x": 8, "y": -7, "z": -3, "c": "#4f7a74"}, {"id": 830, "x": 8, "y": -7, "z": -2, "c": "#4f7a74"}, {"id": 831, "x": 8, "y": -7, "z": -1, "c": "#4f7a74"}, {"id": 832, "x": 8, "y": -7, "z": 0, "c": "#4f7a74"}, {"id": 833, "x": 8, "y": -7, "z": 1, "c": "#4f7a74"}, {"id": 834, "x": 8, "y": -7, "z": 2, "c": "#4f7a74"}, {"id": 835, "x": 8, "y": -7, "z": 3, "c": "#4f7a74"}, {"id": 836, "x": 8, "y": -7, "z": 4, "c": "#4f7a74"}, {"id": 837, "x": 8, "y": -7, "z": 5, "c": "#4f7a74"}, {"id": 838, "x": 8, "y": -7, "z": 6, "c": "#4f7a74"}, {"id": 839, "x": -8, "y": -6, "z": -6, "c": "#c6beb1"}, {"id": 840, "x": -8, "y": -6, "z": -5, "c": "#c6beb1"}, {"id": 841, "x": -8, "y": -6, "z": -4, "c": "#c6beb1"}, {"id": 842, "x": -8, "y": -6, "z": -3, "c": "#c6beb1"}, {"id": 843, "x": -8, "y": -6, "z": -2, "c": "#60737e"}, {"id": 844, "x": -8, "y": -6, "z": -1, "c": "#c6beb1"}, {"id": 845, "x": -8, "y": -6, "z": 0, "c": "#c6beb1"}, {"id": 846, "x": -8, "y": -6, "z": 1, "c": "#c6beb1"}, {"id": 847, "x": -8, "y": -6, "z": 2, "c": "#c6beb1"}, {"id": 848, "x": -8, "y": -6, "z": 3, "c": "#60737e"}, {"id": 849, "x": -8, "y": -6, "z": 4, "c": "#c6beb1"}, {"id": 850, "x": -8, "y": -6, "z": 5, "c": "#c6beb1"}, {"id": 851, "x": -8, "y": -6, "z": 6, "c": "#c6beb1"}, {"id": 852, "x": -7, "y": -6, "z": -6, "c": "#c6beb1"}, {"id": 853, "x": -7, "y": -6, "z": 6, "c": "#c6beb1"}, {"id": 854, "x": -6, "y": -6, "z": -6, "c": "#60737e"}, {"id": 855, "x": -6, "y": -6, "z": 6, "c": "#60737e"}, {"id": 856, "x": -5, "y": -6, "z": -6, "c": "#c6beb1"}, {"id": 857, "x": -5, "y": -6, "z": 6, "c": "#c6beb1"}, {"id": 858, "x": -4, "y": -6, "z": -6, "c": "#60737e"}, {"id": 859, "x": -4, "y": -6, "z": 6, "c": "#c6beb1"}, {"id": 860, "x": -3, "y": -6, "z": -6, "c": "#60737e"}, {"id": 861, "x": -3, "y": -6, "z": 6, "c": "#60737e"}, {"id": 862, "x": -2, "y": -6, "z": -6, "c": "#c6beb1"}, {"id": 863, "x": -2, "y": -6, "z": 6, "c": "#c6beb1"}, {"id": 864, "x": -1, "y": -6, "z": -6, "c": "#c6beb1"}, {"id": 865, "x": -1, "y": -6, "z": 6, "c": "#60737e"}, {"id": 866, "x": 0, "y": -6, "z": -6, "c": "#60737e"}, {"id": 867, "x": 0, "y": -6, "z": 6, "c": "#60737e"}, {"id": 868, "x": 1, "y": -6, "z": -6, "c": "#60737e"}, {"id": 869, "x": 1, "y": -6, "z": 6, "c": "#c6beb1"}, {"id": 870, "x": 2, "y": -6, "z": -6, "c": "#c6beb1"}, {"id": 871, "x": 2, "y": -6, "z": 6, "c": "#c6beb1"}, {"id": 872, "x": 3, "y": -6, "z": -6, "c": "#60737e"}, {"id": 873, "x": 3, "y": -6, "z": 6, "c": "#60737e"}, {"id": 874, "x": 4, "y": -6, "z": -6, "c": "#c6beb1"}, {"id": 875, "x": 4, "y": -6, "z": 6, "c": "#60737e"}, {"id": 876, "x": 5, "y": -6, "z": -6, "c": "#c6beb1"}, {"id": 877, "x": 5, "y": -6, "z": 6, "c": "#c6beb1"}, {"id": 878, "x": 6, "y": -6, "z": -6, "c": "#60737e"}, {"id": 879, "x": 6, "y": -6, "z": 6, "c": "#60737e"}, {"id": 880, "x": 7, "y": -6, "z": -6, "c": "#c6beb1"}, {"id": 881, "x": 7, "y": -6, "z": 6, "c": "#c6beb1"}, {"id": 882, "x": 8, "y": -6, "z": -6, "c": "#c6beb1"}, {"id": 883, "x": 8, "y": -6, "z": -5, "c": "#c6beb1"}, {"id": 884, "x": 8, "y": -6, "z": -4, "c": "#c6beb1"}, {"id": 885, "x": 8, "y": -6, "z": -3, "c": "#60737e"}, {"id": 886, "x": 8, "y": -6, "z": -2, "c": "#c6beb1"}, {"id": 887, "x": 8, "y": -6, "z": -1, "c": "#c6beb1"}, {"id": 888, "x": 8, "y": -6, "z": 0, "c": "#c6beb1"}, {"id": 889, "x": 8, "y": -6, "z": 1, "c": "#c6beb1"}, {"id": 890, "x": 8, "y": -6, "z": 2, "c": "#60737e"}, {"id": 891, "x": 8, "y": -6, "z": 3, "c": "#c6beb1"}, {"id": 892, "x": 8, "y": -6, "z": 4, "c": "#c6beb1"}, {"id": 893, "x": 8, "y": -6, "z": 5, "c": "#c6beb1"}, {"id": 894, "x": 8, "y": -6, "z": 6, "c": "#c6beb1"}, {"id": 895, "x": -8, "y": -5, "z": -6, "c": "#c6beb1"}, {"id": 896, "x": -8, "y": -5, "z": -5, "c": "#c6beb1"}, {"id": 897, "x": -8, "y": -5, "z": -4, "c": "#c6beb1"}, {"id": 898, "x": -8, "y": -5, "z": -3, "c": "#c6beb1"}, {"id": 899, "x": -8, "y": -5, "z": -2, "c": "#60737e"}, {"id": 900, "x": -8, "y": -5, "z": -1, "c": "#c6beb1"}, {"id": 901, "x": -8, "y": -5, "z": 0, "c": "#c6beb1"}, {"id": 902, "x": -8, "y": -5, "z": 1, "c": "#c6beb1"}, {"id": 903, "x": -8, "y": -5, "z": 2, "c": "#c6beb1"}, {"id": 904, "x": -8, "y": -5, "z": 3, "c": "#60737e"}, {"id": 905, "x": -8, "y": -5, "z": 4, "c": "#c6beb1"}, {"id": 906, "x": -8, "y": -5, "z": 5, "c": "#c6beb1"}, {"id": 907, "x": -8, "y": -5, "z": 6, "c": "#c6beb1"}, {"id": 908, "x": -7, "y": -5, "z": -6, "c": "#c6beb1"}, {"id": 909, "x": -7, "y": -5, "z": 6, "c": "#c6beb1"}, {"id": 910, "x": -6, "y": -5, "z": -6, "c": "#c6beb1"}, {"id": 911, "x": -6, "y": -5, "z": 6, "c": "#60737e"}, {"id": 912, "x": -5, "y": -5, "z": -6, "c": "#c6beb1"}, {"id": 913, "x": -5, "y": -5, "z": 6, "c": "#c6beb1"}, {"id": 914, "x": -4, "y": -5, "z": -6, "c": "#60737e"}, {"id": 915, "x": -4, "y": -5, "z": 6, "c": "#c6beb1"}, {"id": 916, "x": -3, "y": -5, "z": -6, "c": "#c6beb1"}, {"id": 917, "x": -3, "y": -5, "z": 6, "c": "#c6beb1"}, {"id": 918, "x": -2, "y": -5, "z": -6, "c": "#c6beb1"}, {"id": 919, "x": -2, "y": -5, "z": 6, "c": "#c6beb1"}, {"id": 920, "x": -1, "y": -5, "z": -6, "c": "#c6beb1"}, {"id": 921, "x": -1, "y": -5, "z": 6, "c": "#60737e"}, {"id": 922, "x": 0, "y": -5, "z": -6, "c": "#c6beb1"}, {"id": 923, "x": 0, "y": -5, "z": 6, "c": "#c6beb1"}, {"id": 924, "x": 1, "y": -5, "z": -6, "c": "#60737e"}, {"id": 925, "x": 1, "y": -5, "z": 6, "c": "#c6beb1"}, {"id": 926, "x": 2, "y": -5, "z": -6, "c": "#c6beb1"}, {"id": 927, "x": 2, "y": -5, "z": 6, "c": "#c6beb1"}, {"id": 928, "x": 3, "y": -5, "z": -6, "c": "#c6beb1"}, {"id": 929, "x": 3, "y": -5, "z": 6, "c": "#c6beb1"}, {"id": 930, "x": 4, "y": -5, "z": -6, "c": "#c6beb1"}, {"id": 931, "x": 4, "y": -5, "z": 6, "c": "#60737e"}, {"id": 932, "x": 5, "y": -5, "z": -6, "c": "#c6beb1"}, {"id": 933, "x": 5, "y": -5, "z": 6, "c": "#c6beb1"}, {"id": 934, "x": 6, "y": -5, "z": -6, "c": "#60737e"}, {"id": 935, "x": 6, "y": -5, "z": 6, "c": "#c6beb1"}, {"id": 936, "x": 7, "y": -5, "z": -6, "c": "#c6beb1"}, {"id": 937, "x": 7, "y": -5, "z": 6, "c": "#c6beb1"}, {"id": 938, "x": 8, "y": -5, "z": -6, "c": "#c6beb1"}, {"id": 939, "x": 8, "y": -5, "z": -5, "c": "#c6beb1"}, {"id": 940, "x": 8, "y": -5, "z": -4, "c": "#c6beb1"}, {"id": 941, "x": 8, "y": -5, "z": -3, "c": "#60737e"}, {"id": 942, "x": 8, "y": -5, "z": -2, "c": "#c6beb1"}, {"id": 943, "x": 8, "y": -5, "z": -1, "c": "#c6beb1"}, {"id": 944, "x": 8, "y": -5, "z": 0, "c": "#c6beb1"}, {"id": 945, "x": 8, "y": -5, "z": 1, "c": "#c6beb1"}, {"id": 946, "x": 8, "y": -5, "z": 2, "c": "#60737e"}, {"id": 947, "x": 8, "y": -5, "z": 3, "c": "#c6beb1"}, {"id": 948, "x": 8, "y": -5, "z": 4, "c": "#c6beb1"}, {"id": 949, "x": 8, "y": -5, "z": 5, "c": "#c6beb1"}, {"id": 950, "x": 8, "y": -5, "z": 6, "c": "#c6beb1"}, {"id": 951, "x": -8, "y": -4, "z": -6, "c": "#c6beb1"}, {"id": 952, "x": -8, "y": -4, "z": -5, "c": "#c6beb1"}, {"id": 953, "x": -8, "y": -4, "z": -4, "c": "#c6beb1"}, {"id": 954, "x": -8, "y": -4, "z": -3, "c": "#c6beb1"}, {"id": 955, "x": -8, "y": -4, "z": -2, "c": "#60737e"}, {"id": 956, "x": -8, "y": -4, "z": -1, "c": "#c6beb1"}, {"id": 957, "x": -8, "y": -4, "z": 0, "c": "#c6beb1"}, {"id": 958, "x": -8, "y": -4, "z": 1, "c": "#c6beb1"}, {"id": 959, "x": -8, "y": -4, "z": 2, "c": "#c6beb1"}, {"id": 960, "x": -8, "y": -4, "z": 3, "c": "#60737e"}, {"id": 961, "x": -8, "y": -4, "z": 4, "c": "#c6beb1"}, {"id": 962, "x": -8, "y": -4, "z": 5, "c": "#c6beb1"}, {"id": 963, "x": -8, "y": -4, "z": 6, "c": "#c6beb1"}, {"id": 964, "x": -7, "y": -4, "z": -6, "c": "#c6beb1"}, {"id": 965, "x": -7, "y": -4, "z": 6, "c": "#c6beb1"}, {"id": 966, "x": -6, "y": -4, "z": -6, "c": "#60737e"}, {"id": 967, "x": -6, "y": -4, "z": 6, "c": "#60737e"}, {"id": 968, "x": -5, "y": -4, "z": -6, "c": "#c6beb1"}, {"id": 969, "x": -5, "y": -4, "z": 6, "c": "#c6beb1"}, {"id": 970, "x": -4, "y": -4, "z": -6, "c": "#60737e"}, {"id": 971, "x": -4, "y": -4, "z": 6, "c": "#c6beb1"}, {"id": 972, "x": -3, "y": -4, "z": -6, "c": "#60737e"}, {"id": 973, "x": -3, "y": -4, "z": 6, "c": "#60737e"}, {"id": 974, "x": -2, "y": -4, "z": -6, "c": "#c6beb1"}, {"id": 975, "x": -2, "y": -4, "z": 6, "c": "#c6beb1"}, {"id": 976, "x": -1, "y": -4, "z": -6, "c": "#c6beb1"}, {"id": 977, "x": -1, "y": -4, "z": 6, "c": "#60737e"}, {"id": 978, "x": 0, "y": -4, "z": -6, "c": "#60737e"}, {"id": 979, "x": 0, "y": -4, "z": 6, "c": "#60737e"}, {"id": 980, "x": 1, "y": -4, "z": -6, "c": "#60737e"}, {"id": 981, "x": 1, "y": -4, "z": 6, "c": "#c6beb1"}, {"id": 982, "x": 2, "y": -4, "z": -6, "c": "#c6beb1"}, {"id": 983, "x": 2, "y": -4, "z": 6, "c": "#c6beb1"}, {"id": 984, "x": 3, "y": -4, "z": -6, "c": "#60737e"}, {"id": 985, "x": 3, "y": -4, "z": 6, "c": "#60737e"}, {"id": 986, "x": 4, "y": -4, "z": -6, "c": "#c6beb1"}, {"id": 987, "x": 4, "y": -4, "z": 6, "c": "#60737e"}, {"id": 988, "x": 5, "y": -4, "z": -6, "c": "#c6beb1"}, {"id": 989, "x": 5, "y": -4, "z": 6, "c": "#c6beb1"}, {"id": 990, "x": 6, "y": -4, "z": -6, "c": "#60737e"}, {"id": 991, "x": 6, "y": -4, "z": 6, "c": "#60737e"}, {"id": 992, "x": 7, "y": -4, "z": -6, "c": "#c6beb1"}, {"id": 993, "x": 7, "y": -4, "z": 6, "c": "#c6beb1"}, {"id": 994, "x": 8, "y": -4, "z": -6, "c": "#c6beb1"}, {"id": 995, "x": 8, "y": -4, "z": -5, "c": "#c6beb1"}, {"id": 996, "x": 8, "y": -4, "z": -4, "c": "#c6beb1"}, {"id": 997, "x": 8, "y": -4, "z": -3, "c": "#60737e"}, {"id": 998, "x": 8, "y": -4, "z": -2, "c": "#c6beb1"}, {"id": 999, "x": 8, "y": -4, "z": -1, "c": "#c6beb1"}, {"id": 1000, "x": 8, "y": -4, "z": 0, "c": "#c6beb1"}, {"id": 1001, "x": 8, "y": -4, "z": 1, "c": "#c6beb1"}, {"id": 1002, "x": 8, "y": -4, "z": 2, "c": "#60737e"}, {"id": 1003, "x": 8, "y": -4, "z": 3, "c": "#c6beb1"}, {"id": 1004, "x": 8, "y": -4, "z": 4, "c": "#c6beb1"}, {"id": 1005, "x": 8, "y": -4, "z": 5, "c": "#c6beb1"}, {"id": 1006, "x": 8, "y": -4, "z": 6, "c": "#c6beb1"}, {"id": 1007, "x": -8, "y": -3, "z": -6, "c": "#4f7a74"}, {"id": 1008, "x": -8, "y": -3, "z": -5, "c": "#4f7a74"}, {"id": 1009, "x": -8, "y": -3, "z": -4, "c": "#4f7a74"}, {"id": 1010, "x": -8, "y": -3, "z": -3, "c": "#4f7a74"}, {"id": 1011, "x": -8, "y": -3, "z": -2, "c": "#4f7a74"}, {"id": 1012, "x": -8, "y": -3, "z": -1, "c": "#4f7a74"}, {"id": 1013, "x": -8, "y": -3, "z": 0, "c": "#4f7a74"}, {"id": 1014, "x": -8, "y": -3, "z": 1, "c": "#4f7a74"}, {"id": 1015, "x": -8, "y": -3, "z": 2, "c": "#4f7a74"}, {"id": 1016, "x": -8, "y": -3, "z": 3, "c": "#4f7a74"}, {"id": 1017, "x": -8, "y": -3, "z": 4, "c": "#4f7a74"}, {"id": 1018, "x": -8, "y": -3, "z": 5, "c": "#4f7a74"}, {"id": 1019, "x": -8, "y": -3, "z": 6, "c": "#4f7a74"}, {"id": 1020, "x": -7, "y": -3, "z": -6, "c": "#4f7a74"}, {"id": 1021, "x": -7, "y": -3, "z": 6, "c": "#4f7a74"}, {"id": 1022, "x": -6, "y": -3, "z": -6, "c": "#4f7a74"}, {"id": 1023, "x": -6, "y": -3, "z": 6, "c": "#4f7a74"}, {"id": 1024, "x": -5, "y": -3, "z": -6, "c": "#4f7a74"}, {"id": 1025, "x": -5, "y": -3, "z": 6, "c": "#4f7a74"}, {"id": 1026, "x": -4, "y": -3, "z": -6, "c": "#4f7a74"}, {"id": 1027, "x": -4, "y": -3, "z": 6, "c": "#4f7a74"}, {"id": 1028, "x": -3, "y": -3, "z": -6, "c": "#4f7a74"}, {"id": 1029, "x": -3, "y": -3, "z": 6, "c": "#4f7a74"}, {"id": 1030, "x": -2, "y": -3, "z": -6, "c": "#4f7a74"}, {"id": 1031, "x": -2, "y": -3, "z": 6, "c": "#4f7a74"}, {"id": 1032, "x": -1, "y": -3, "z": -6, "c": "#4f7a74"}, {"id": 1033, "x": -1, "y": -3, "z": 6, "c": "#4f7a74"}, {"id": 1034, "x": 0, "y": -3, "z": -6, "c": "#4f7a74"}, {"id": 1035, "x": 0, "y": -3, "z": 6, "c": "#4f7a74"}, {"id": 1036, "x": 1, "y": -3, "z": -6, "c": "#4f7a74"}, {"id": 1037, "x": 1, "y": -3, "z": 6, "c": "#4f7a74"}, {"id": 1038, "x": 2, "y": -3, "z": -6, "c": "#4f7a74"}, {"id": 1039, "x": 2, "y": -3, "z": 6, "c": "#4f7a74"}, {"id": 1040, "x": 3, "y": -3, "z": -6, "c": "#4f7a74"}, {"id": 1041, "x": 3, "y": -3, "z": 6, "c": "#4f7a74"}, {"id": 1042, "x": 4, "y": -3, "z": -6, "c": "#4f7a74"}, {"id": 1043, "x": 4, "y": -3, "z": 6, "c": "#4f7a74"}, {"id": 1044, "x": 5, "y": -3, "z": -6, "c": "#4f7a74"}, {"id": 1045, "x": 5, "y": -3, "z": 6, "c": "#4f7a74"}, {"id": 1046, "x": 6, "y": -3, "z": -6, "c": "#4f7a74"}, {"id": 1047, "x": 6, "y": -3, "z": 6, "c": "#4f7a74"}, {"id": 1048, "x": 7, "y": -3, "z": -6, "c": "#4f7a74"}, {"id": 1049, "x": 7, "y": -3, "z": 6, "c": "#4f7a74"}, {"id": 1050, "x": 8, "y": -3, "z": -6, "c": "#4f7a74"}, {"id": 1051, "x": 8, "y": -3, "z": -5, "c": "#4f7a74"}, {"id": 1052, "x": 8, "y": -3, "z": -4, "c": "#4f7a74"}, {"id": 1053, "x": 8, "y": -3, "z": -3, "c": "#4f7a74"}, {"id": 1054, "x": 8, "y": -3, "z": -2, "c": "#4f7a74"}, {"id": 1055, "x": 8, "y": -3, "z": -1, "c": "#4f7a74"}, {"id": 1056, "x": 8, "y": -3, "z": 0, "c": "#4f7a74"}, {"id": 1057, "x": 8, "y": -3, "z": 1, "c": "#4f7a74"}, {"id": 1058, "x": 8, "y": -3, "z": 2, "c": "#4f7a74"}, {"id": 1059, "x": 8, "y": -3, "z": 3, "c": "#4f7a74"}, {"id": 1060, "x": 8, "y": -3, "z": 4, "c": "#4f7a74"}, {"id": 1061, "x": 8, "y": -3, "z": 5, "c": "#4f7a74"}, {"id": 1062, "x": 8, "y": -3, "z": 6, "c": "#4f7a74"}, {"id": 1063, "x": -8, "y": -2, "z": -6, "c": "#c6beb1"}, {"id": 1064, "x": -8, "y": -2, "z": -5, "c": "#c6beb1"}, {"id": 1065, "x": -8, "y": -2, "z": -4, "c": "#c6beb1"}, {"id": 1066, "x": -8, "y": -2, "z": -3, "c": "#c6beb1"}, {"id": 1067, "x": -8, "y": -2, "z": -2, "c": "#60737e"}, {"id": 1068, "x": -8, "y": -2, "z": -1, "c": "#c6beb1"}, {"id": 1069, "x": -8, "y": -2, "z": 0, "c": "#c6beb1"}, {"id": 1070, "x": -8, "y": -2, "z": 1, "c": "#c6beb1"}, {"id": 1071, "x": -8, "y": -2, "z": 2, "c": "#c6beb1"}, {"id": 1072, "x": -8, "y": -2, "z": 3, "c": "#60737e"}, {"id": 1073, "x": -8, "y": -2, "z": 4, "c": "#c6beb1"}, {"id": 1074, "x": -8, "y": -2, "z": 5, "c": "#c6beb1"}, {"id": 1075, "x": -8, "y": -2, "z": 6, "c": "#c6beb1"}, {"id": 1076, "x": -7, "y": -2, "z": -6, "c": "#c6beb1"}, {"id": 1077, "x": -7, "y": -2, "z": 6, "c": "#c6beb1"}, {"id": 1078, "x": -6, "y": -2, "z": -6, "c": "#c6beb1"}, {"id": 1079, "x": -6, "y": -2, "z": 6, "c": "#60737e"}, {"id": 1080, "x": -5, "y": -2, "z": -6, "c": "#c6beb1"}, {"id": 1081, "x": -5, "y": -2, "z": 6, "c": "#c6beb1"}, {"id": 1082, "x": -4, "y": -2, "z": -6, "c": "#60737e"}, {"id": 1083, "x": -4, "y": -2, "z": 6, "c": "#c6beb1"}, {"id": 1084, "x": -3, "y": -2, "z": -6, "c": "#c6beb1"}, {"id": 1085, "x": -3, "y": -2, "z": 6, "c": "#c6beb1"}, {"id": 1086, "x": -2, "y": -2, "z": -6, "c": "#c6beb1"}, {"id": 1087, "x": -2, "y": -2, "z": 6, "c": "#c6beb1"}, {"id": 1088, "x": -1, "y": -2, "z": -6, "c": "#c6beb1"}, {"id": 1089, "x": -1, "y": -2, "z": 6, "c": "#60737e"}, {"id": 1090, "x": 0, "y": -2, "z": -6, "c": "#c6beb1"}, {"id": 1091, "x": 0, "y": -2, "z": 6, "c": "#c6beb1"}, {"id": 1092, "x": 1, "y": -2, "z": -6, "c": "#60737e"}, {"id": 1093, "x": 1, "y": -2, "z": 6, "c": "#c6beb1"}, {"id": 1094, "x": 2, "y": -2, "z": -6, "c": "#c6beb1"}, {"id": 1095, "x": 2, "y": -2, "z": 6, "c": "#c6beb1"}, {"id": 1096, "x": 3, "y": -2, "z": -6, "c": "#c6beb1"}, {"id": 1097, "x": 3, "y": -2, "z": 6, "c": "#c6beb1"}, {"id": 1098, "x": 4, "y": -2, "z": -6, "c": "#c6beb1"}, {"id": 1099, "x": 4, "y": -2, "z": 6, "c": "#60737e"}, {"id": 1100, "x": 5, "y": -2, "z": -6, "c": "#c6beb1"}, {"id": 1101, "x": 5, "y": -2, "z": 6, "c": "#c6beb1"}, {"id": 1102, "x": 6, "y": -2, "z": -6, "c": "#60737e"}, {"id": 1103, "x": 6, "y": -2, "z": 6, "c": "#c6beb1"}, {"id": 1104, "x": 7, "y": -2, "z": -6, "c": "#c6beb1"}, {"id": 1105, "x": 7, "y": -2, "z": 6, "c": "#c6beb1"}, {"id": 1106, "x": 8, "y": -2, "z": -6, "c": "#c6beb1"}, {"id": 1107, "x": 8, "y": -2, "z": -5, "c": "#c6beb1"}, {"id": 1108, "x": 8, "y": -2, "z": -4, "c": "#c6beb1"}, {"id": 1109, "x": 8, "y": -2, "z": -3, "c": "#60737e"}, {"id": 1110, "x": 8, "y": -2, "z": -2, "c": "#c6beb1"}, {"id": 1111, "x": 8, "y": -2, "z": -1, "c": "#c6beb1"}, {"id": 1112, "x": 8, "y": -2, "z": 0, "c": "#c6beb1"}, {"id": 1113, "x": 8, "y": -2, "z": 1, "c": "#c6beb1"}, {"id": 1114, "x": 8, "y": -2, "z": 2, "c": "#60737e"}, {"id": 1115, "x": 8, "y": -2, "z": 3, "c": "#c6beb1"}, {"id": 1116, "x": 8, "y": -2, "z": 4, "c": "#c6beb1"}, {"id": 1117, "x": 8, "y": -2, "z": 5, "c": "#c6beb1"}, {"id": 1118, "x": 8, "y": -2, "z": 6, "c": "#c6beb1"}, {"id": 1119, "x": -9, "y": -1, "z": -7, "c": "#505860"}, {"id": 1120, "x": -9, "y": -1, "z": -6, "c": "#505860"}, {"id": 1121, "x": -9, "y": -1, "z": -5, "c": "#505860"}, {"id": 1122, "x": -9, "y": -1, "z": -4, "c": "#505860"}, {"id": 1123, "x": -9, "y": -1, "z": -3, "c": "#505860"}, {"id": 1124, "x": -9, "y": -1, "z": -2, "c": "#505860"}, {"id": 1125, "x": -9, "y": -1, "z": -1, "c": "#505860"}, {"id": 1126, "x": -9, "y": -1, "z": 0, "c": "#505860"}, {"id": 1127, "x": -9, "y": -1, "z": 1, "c": "#505860"}, {"id": 1128, "x": -9, "y": -1, "z": 2, "c": "#505860"}, {"id": 1129, "x": -9, "y": -1, "z": 3, "c": "#505860"}, {"id": 1130, "x": -9, "y": -1, "z": 4, "c": "#505860"}, {"id": 1131, "x": -9, "y": -1, "z": 5, "c": "#505860"}, {"id": 1132, "x": -9, "y": -1, "z": 6, "c": "#505860"}, {"id": 1133, "x": -9, "y": -1, "z": 7, "c": "#505860"}, {"id": 1134, "x": -8, "y": -1, "z": -7, "c": "#505860"}, {"id": 1135, "x": -8, "y": -1, "z": -6, "c": "#505860"}, {"id": 1136, "x": -8, "y": -1, "z": -5, "c": "#505860"}, {"id": 1137, "x": -8, "y": -1, "z": -4, "c": "#505860"}, {"id": 1138, "x": -8, "y": -1, "z": -3, "c": "#505860"}, {"id": 1139, "x": -8, "y": -1, "z": -2, "c": "#505860"}, {"id": 1140, "x": -8, "y": -1, "z": -1, "c": "#505860"}, {"id": 1141, "x": -8, "y": -1, "z": 0, "c": "#505860"}, {"id": 1142, "x": -8, "y": -1, "z": 1, "c": "#505860"}, {"id": 1143, "x": -8, "y": -1, "z": 2, "c": "#505860"}, {"id": 1144, "x": -8, "y": -1, "z": 3, "c": "#505860"}, {"id": 1145, "x": -8, "y": -1, "z": 4, "c": "#505860"}, {"id": 1146, "x": -8, "y": -1, "z": 5, "c": "#505860"}, {"id": 1147, "x": -8, "y": -1, "z": 6, "c": "#505860"}, {"id": 1148, "x": -8, "y": -1, "z": 7, "c": "#505860"}, {"id": 1149, "x": -7, "y": -1, "z": -7, "c": "#505860"}, {"id": 1150, "x": -7, "y": -1, "z": -6, "c": "#505860"}, {"id": 1151, "x": -7, "y": -1, "z": -5, "c": "#505860"}, {"id": 1152, "x": -7, "y": -1, "z": -4, "c": "#505860"}, {"id": 1153, "x": -7, "y": -1, "z": -3, "c": "#505860"}, {"id": 1154, "x": -7, "y": -1, "z": -2, "c": "#505860"}, {"id": 1155, "x": -7, "y": -1, "z": -1, "c": "#505860"}, {"id": 1156, "x": -7, "y": -1, "z": 0, "c": "#505860"}, {"id": 1157, "x": -7, "y": -1, "z": 1, "c": "#505860"}, {"id": 1158, "x": -7, "y": -1, "z": 2, "c": "#505860"}, {"id": 1159, "x": -7, "y": -1, "z": 3, "c": "#505860"}, {"id": 1160, "x": -7, "y": -1, "z": 4, "c": "#505860"}, {"id": 1161, "x": -7, "y": -1, "z": 5, "c": "#505860"}, {"id": 1162, "x": -7, "y": -1, "z": 6, "c": "#505860"}, {"id": 1163, "x": -7, "y": -1, "z": 7, "c": "#505860"}, {"id": 1164, "x": -6, "y": -1, "z": -7, "c": "#505860"}, {"id": 1165, "x": -6, "y": -1, "z": -6, "c": "#505860"}, {"id": 1166, "x": -6, "y": -1, "z": -5, "c": "#505860"}, {"id": 1167, "x": -6, "y": -1, "z": -4, "c": "#505860"}, {"id": 1168, "x": -6, "y": -1, "z": -3, "c": "#505860"}, {"id": 1169, "x": -6, "y": -1, "z": -2, "c": "#505860"}, {"id": 1170, "x": -6, "y": -1, "z": -1, "c": "#505860"}, {"id": 1171, "x": -6, "y": -1, "z": 0, "c": "#505860"}, {"id": 1172, "x": -6, "y": -1, "z": 1, "c": "#505860"}, {"id": 1173, "x": -6, "y": -1, "z": 2, "c": "#505860"}, {"id": 1174, "x": -6, "y": -1, "z": 3, "c": "#505860"}, {"id": 1175, "x": -6, "y": -1, "z": 4, "c": "#505860"}, {"id": 1176, "x": -6, "y": -1, "z": 5, "c": "#505860"}, {"id": 1177, "x": -6, "y": -1, "z": 6, "c": "#505860"}, {"id": 1178, "x": -6, "y": -1, "z": 7, "c": "#505860"}, {"id": 1179, "x": -5, "y": -1, "z": -7, "c": "#505860"}, {"id": 1180, "x": -5, "y": -1, "z": -6, "c": "#505860"}, {"id": 1181, "x": -5, "y": -1, "z": -5, "c": "#505860"}, {"id": 1182, "x": -5, "y": -1, "z": -4, "c": "#505860"}, {"id": 1183, "x": -5, "y": -1, "z": -3, "c": "#505860"}, {"id": 1184, "x": -5, "y": -1, "z": -2, "c": "#505860"}, {"id": 1185, "x": -5, "y": -1, "z": -1, "c": "#505860"}, {"id": 1186, "x": -5, "y": -1, "z": 0, "c": "#505860"}, {"id": 1187, "x": -5, "y": -1, "z": 1, "c": "#505860"}, {"id": 1188, "x": -5, "y": -1, "z": 2, "c": "#505860"}, {"id": 1189, "x": -5, "y": -1, "z": 3, "c": "#505860"}, {"id": 1190, "x": -5, "y": -1, "z": 4, "c": "#505860"}, {"id": 1191, "x": -5, "y": -1, "z": 5, "c": "#505860"}, {"id": 1192, "x": -5, "y": -1, "z": 6, "c": "#505860"}, {"id": 1193, "x": -5, "y": -1, "z": 7, "c": "#505860"}, {"id": 1194, "x": -4, "y": -1, "z": -7, "c": "#505860"}, {"id": 1195, "x": -4, "y": -1, "z": -6, "c": "#505860"}, {"id": 1196, "x": -4, "y": -1, "z": -5, "c": "#505860"}, {"id": 1197, "x": -4, "y": -1, "z": -4, "c": "#505860"}, {"id": 1198, "x": -4, "y": -1, "z": -3, "c": "#505860"}, {"id": 1199, "x": -4, "y": -1, "z": -2, "c": "#505860"}, {"id": 1200, "x": -4, "y": -1, "z": -1, "c": "#505860"}, {"id": 1201, "x": -4, "y": -1, "z": 0, "c": "#505860"}, {"id": 1202, "x": -4, "y": -1, "z": 1, "c": "#505860"}, {"id": 1203, "x": -4, "y": -1, "z": 2, "c": "#505860"}, {"id": 1204, "x": -4, "y": -1, "z": 3, "c": "#505860"}, {"id": 1205, "x": -4, "y": -1, "z": 4, "c": "#505860"}, {"id": 1206, "x": -4, "y": -1, "z": 5, "c": "#505860"}, {"id": 1207, "x": -4, "y": -1, "z": 6, "c": "#505860"}, {"id": 1208, "x": -4, "y": -1, "z": 7, "c": "#505860"}, {"id": 1209, "x": -3, "y": -1, "z": -7, "c": "#505860"}, {"id": 1210, "x": -3, "y": -1, "z": -6, "c": "#505860"}, {"id": 1211, "x": -3, "y": -1, "z": -5, "c": "#505860"}, {"id": 1212, "x": -3, "y": -1, "z": -4, "c": "#505860"}, {"id": 1213, "x": -3, "y": -1, "z": -3, "c": "#505860"}, {"id": 1214, "x": -3, "y": -1, "z": -2, "c": "#505860"}, {"id": 1215, "x": -3, "y": -1, "z": -1, "c": "#505860"}, {"id": 1216, "x": -3, "y": -1, "z": 0, "c": "#505860"}, {"id": 1217, "x": -3, "y": -1, "z": 1, "c": "#505860"}, {"id": 1218, "x": -3, "y": -1, "z": 2, "c": "#505860"}, {"id": 1219, "x": -3, "y": -1, "z": 3, "c": "#505860"}, {"id": 1220, "x": -3, "y": -1, "z": 4, "c": "#505860"}, {"id": 1221, "x": -3, "y": -1, "z": 5, "c": "#505860"}, {"id": 1222, "x": -3, "y": -1, "z": 6, "c": "#505860"}, {"id": 1223, "x": -3, "y": -1, "z": 7, "c": "#505860"}, {"id": 1224, "x": -2, "y": -1, "z": -7, "c": "#505860"}, {"id": 1225, "x": -2, "y": -1, "z": -6, "c": "#505860"}, {"id": 1226, "x": -2, "y": -1, "z": -5, "c": "#505860"}, {"id": 1227, "x": -2, "y": -1, "z": -4, "c": "#505860"}, {"id": 1228, "x": -2, "y": -1, "z": -3, "c": "#505860"}, {"id": 1229, "x": -2, "y": -1, "z": -2, "c": "#505860"}, {"id": 1230, "x": -2, "y": -1, "z": -1, "c": "#505860"}, {"id": 1231, "x": -2, "y": -1, "z": 0, "c": "#505860"}, {"id": 1232, "x": -2, "y": -1, "z": 1, "c": "#505860"}, {"id": 1233, "x": -2, "y": -1, "z": 2, "c": "#505860"}, {"id": 1234, "x": -2, "y": -1, "z": 3, "c": "#505860"}, {"id": 1235, "x": -2, "y": -1, "z": 4, "c": "#505860"}, {"id": 1236, "x": -2, "y": -1, "z": 5, "c": "#505860"}, {"id": 1237, "x": -2, "y": -1, "z": 6, "c": "#505860"}, {"id": 1238, "x": -2, "y": -1, "z": 7, "c": "#505860"}, {"id": 1239, "x": -1, "y": -1, "z": -7, "c": "#505860"}, {"id": 1240, "x": -1, "y": -1, "z": -6, "c": "#505860"}, {"id": 1241, "x": -1, "y": -1, "z": -5, "c": "#505860"}, {"id": 1242, "x": -1, "y": -1, "z": -4, "c": "#505860"}, {"id": 1243, "x": -1, "y": -1, "z": -3, "c": "#505860"}, {"id": 1244, "x": -1, "y": -1, "z": -2, "c": "#505860"}, {"id": 1245, "x": -1, "y": -1, "z": -1, "c": "#505860"}, {"id": 1246, "x": -1, "y": -1, "z": 0, "c": "#505860"}, {"id": 1247, "x": -1, "y": -1, "z": 1, "c": "#505860"}, {"id": 1248, "x": -1, "y": -1, "z": 2, "c": "#505860"}, {"id": 1249, "x": -1, "y": -1, "z": 3, "c": "#505860"}, {"id": 1250, "x": -1, "y": -1, "z": 4, "c": "#505860"}, {"id": 1251, "x": -1, "y": -1, "z": 5, "c": "#505860"}, {"id": 1252, "x": -1, "y": -1, "z": 6, "c": "#505860"}, {"id": 1253, "x": -1, "y": -1, "z": 7, "c": "#505860"}, {"id": 1254, "x": 0, "y": -1, "z": -7, "c": "#505860"}, {"id": 1255, "x": 0, "y": -1, "z": -6, "c": "#505860"}, {"id": 1256, "x": 0, "y": -1, "z": -5, "c": "#505860"}, {"id": 1257, "x": 0, "y": -1, "z": -4, "c": "#505860"}, {"id": 1258, "x": 0, "y": -1, "z": -3, "c": "#505860"}, {"id": 1259, "x": 0, "y": -1, "z": -2, "c": "#505860"}, {"id": 1260, "x": 0, "y": -1, "z": -1, "c": "#505860"}, {"id": 1261, "x": 0, "y": -1, "z": 0, "c": "#505860"}, {"id": 1262, "x": 0, "y": -1, "z": 1, "c": "#505860"}, {"id": 1263, "x": 0, "y": -1, "z": 2, "c": "#505860"}, {"id": 1264, "x": 0, "y": -1, "z": 3, "c": "#505860"}, {"id": 1265, "x": 0, "y": -1, "z": 4, "c": "#505860"}, {"id": 1266, "x": 0, "y": -1, "z": 5, "c": "#505860"}, {"id": 1267, "x": 0, "y": -1, "z": 6, "c": "#505860"}, {"id": 1268, "x": 0, "y": -1, "z": 7, "c": "#505860"}, {"id": 1269, "x": 1, "y": -1, "z": -7, "c": "#505860"}, {"id": 1270, "x": 1, "y": -1, "z": -6, "c": "#505860"}, {"id": 1271, "x": 1, "y": -1, "z": -5, "c": "#505860"}, {"id": 1272, "x": 1, "y": -1, "z": -4, "c": "#505860"}, {"id": 1273, "x": 1, "y": -1, "z": -3, "c": "#505860"}, {"id": 1274, "x": 1, "y": -1, "z": -2, "c": "#505860"}, {"id": 1275, "x": 1, "y": -1, "z": -1, "c": "#505860"}, {"id": 1276, "x": 1, "y": -1, "z": 0, "c": "#505860"}, {"id": 1277, "x": 1, "y": -1, "z": 1, "c": "#505860"}, {"id": 1278, "x": 1, "y": -1, "z": 2, "c": "#505860"}, {"id": 1279, "x": 1, "y": -1, "z": 3, "c": "#505860"}, {"id": 1280, "x": 1, "y": -1, "z": 4, "c": "#505860"}, {"id": 1281, "x": 1, "y": -1, "z": 5, "c": "#505860"}, {"id": 1282, "x": 1, "y": -1, "z": 6, "c": "#505860"}, {"id": 1283, "x": 1, "y": -1, "z": 7, "c": "#505860"}, {"id": 1284, "x": 2, "y": -1, "z": -7, "c": "#505860"}, {"id": 1285, "x": 2, "y": -1, "z": -6, "c": "#505860"}, {"id": 1286, "x": 2, "y": -1, "z": -5, "c": "#505860"}, {"id": 1287, "x": 2, "y": -1, "z": -4, "c": "#505860"}, {"id": 1288, "x": 2, "y": -1, "z": -3, "c": "#505860"}, {"id": 1289, "x": 2, "y": -1, "z": -2, "c": "#505860"}, {"id": 1290, "x": 2, "y": -1, "z": -1, "c": "#505860"}, {"id": 1291, "x": 2, "y": -1, "z": 0, "c": "#505860"}, {"id": 1292, "x": 2, "y": -1, "z": 1, "c": "#505860"}, {"id": 1293, "x": 2, "y": -1, "z": 2, "c": "#505860"}, {"id": 1294, "x": 2, "y": -1, "z": 3, "c": "#505860"}, {"id": 1295, "x": 2, "y": -1, "z": 4, "c": "#505860"}, {"id": 1296, "x": 2, "y": -1, "z": 5, "c": "#505860"}, {"id": 1297, "x": 2, "y": -1, "z": 6, "c": "#505860"}, {"id": 1298, "x": 2, "y": -1, "z": 7, "c": "#505860"}, {"id": 1299, "x": 3, "y": -1, "z": -7, "c": "#505860"}, {"id": 1300, "x": 3, "y": -1, "z": -6, "c": "#505860"}, {"id": 1301, "x": 3, "y": -1, "z": -5, "c": "#505860"}, {"id": 1302, "x": 3, "y": -1, "z": -4, "c": "#505860"}, {"id": 1303, "x": 3, "y": -1, "z": -3, "c": "#505860"}, {"id": 1304, "x": 3, "y": -1, "z": -2, "c": "#505860"}, {"id": 1305, "x": 3, "y": -1, "z": -1, "c": "#505860"}, {"id": 1306, "x": 3, "y": -1, "z": 0, "c": "#505860"}, {"id": 1307, "x": 3, "y": -1, "z": 1, "c": "#505860"}, {"id": 1308, "x": 3, "y": -1, "z": 2, "c": "#505860"}, {"id": 1309, "x": 3, "y": -1, "z": 3, "c": "#505860"}, {"id": 1310, "x": 3, "y": -1, "z": 4, "c": "#505860"}, {"id": 1311, "x": 3, "y": -1, "z": 5, "c": "#505860"}, {"id": 1312, "x": 3, "y": -1, "z": 6, "c": "#505860"}, {"id": 1313, "x": 3, "y": -1, "z": 7, "c": "#505860"}, {"id": 1314, "x": 4, "y": -1, "z": -7, "c": "#505860"}, {"id": 1315, "x": 4, "y": -1, "z": -6, "c": "#505860"}, {"id": 1316, "x": 4, "y": -1, "z": -5, "c": "#505860"}, {"id": 1317, "x": 4, "y": -1, "z": -4, "c": "#505860"}, {"id": 1318, "x": 4, "y": -1, "z": -3, "c": "#505860"}, {"id": 1319, "x": 4, "y": -1, "z": -2, "c": "#505860"}, {"id": 1320, "x": 4, "y": -1, "z": -1, "c": "#505860"}, {"id": 1321, "x": 4, "y": -1, "z": 0, "c": "#505860"}, {"id": 1322, "x": 4, "y": -1, "z": 1, "c": "#505860"}, {"id": 1323, "x": 4, "y": -1, "z": 2, "c": "#505860"}, {"id": 1324, "x": 4, "y": -1, "z": 3, "c": "#505860"}, {"id": 1325, "x": 4, "y": -1, "z": 4, "c": "#505860"}, {"id": 1326, "x": 4, "y": -1, "z": 5, "c": "#505860"}, {"id": 1327, "x": 4, "y": -1, "z": 6, "c": "#505860"}, {"id": 1328, "x": 4, "y": -1, "z": 7, "c": "#505860"}, {"id": 1329, "x": 5, "y": -1, "z": -7, "c": "#505860"}, {"id": 1330, "x": 5, "y": -1, "z": -6, "c": "#505860"}, {"id": 1331, "x": 5, "y": -1, "z": -5, "c": "#505860"}, {"id": 1332, "x": 5, "y": -1, "z": -4, "c": "#505860"}, {"id": 1333, "x": 5, "y": -1, "z": -3, "c": "#505860"}, {"id": 1334, "x": 5, "y": -1, "z": -2, "c": "#505860"}, {"id": 1335, "x": 5, "y": -1, "z": -1, "c": "#505860"}, {"id": 1336, "x": 5, "y": -1, "z": 0, "c": "#505860"}, {"id": 1337, "x": 5, "y": -1, "z": 1, "c": "#505860"}, {"id": 1338, "x": 5, "y": -1, "z": 2, "c": "#505860"}, {"id": 1339, "x": 5, "y": -1, "z": 3, "c": "#505860"}, {"id": 1340, "x": 5, "y": -1, "z": 4, "c": "#505860"}, {"id": 1341, "x": 5, "y": -1, "z": 5, "c": "#505860"}, {"id": 1342, "x": 5, "y": -1, "z": 6, "c": "#505860"}, {"id": 1343, "x": 5, "y": -1, "z": 7, "c": "#505860"}, {"id": 1344, "x": 6, "y": -1, "z": -7, "c": "#505860"}, {"id": 1345, "x": 6, "y": -1, "z": -6, "c": "#505860"}, {"id": 1346, "x": 6, "y": -1, "z": -5, "c": "#505860"}, {"id": 1347, "x": 6, "y": -1, "z": -4, "c": "#505860"}, {"id": 1348, "x": 6, "y": -1, "z": -3, "c": "#505860"}, {"id": 1349, "x": 6, "y": -1, "z": -2, "c": "#505860"}, {"id": 1350, "x": 6, "y": -1, "z": -1, "c": "#505860"}, {"id": 1351, "x": 6, "y": -1, "z": 0, "c": "#505860"}, {"id": 1352, "x": 6, "y": -1, "z": 1, "c": "#505860"}, {"id": 1353, "x": 6, "y": -1, "z": 2, "c": "#505860"}, {"id": 1354, "x": 6, "y": -1, "z": 3, "c": "#505860"}, {"id": 1355, "x": 6, "y": -1, "z": 4, "c": "#505860"}, {"id": 1356, "x": 6, "y": -1, "z": 5, "c": "#505860"}, {"id": 1357, "x": 6, "y": -1, "z": 6, "c": "#505860"}, {"id": 1358, "x": 6, "y": -1, "z": 7, "c": "#505860"}, {"id": 1359, "x": 7, "y": -1, "z": -7, "c": "#505860"}, {"id": 1360, "x": 7, "y": -1, "z": -6, "c": "#505860"}, {"id": 1361, "x": 7, "y": -1, "z": -5, "c": "#505860"}, {"id": 1362, "x": 7, "y": -1, "z": -4, "c": "#505860"}, {"id": 1363, "x": 7, "y": -1, "z": -3, "c": "#505860"}, {"id": 1364, "x": 7, "y": -1, "z": -2, "c": "#505860"}, {"id": 1365, "x": 7, "y": -1, "z": -1, "c": "#505860"}, {"id": 1366, "x": 7, "y": -1, "z": 0, "c": "#505860"}, {"id": 1367, "x": 7, "y": -1, "z": 1, "c": "#505860"}, {"id": 1368, "x": 7, "y": -1, "z": 2, "c": "#505860"}, {"id": 1369, "x": 7, "y": -1, "z": 3, "c": "#505860"}, {"id": 1370, "x": 7, "y": -1, "z": 4, "c": "#505860"}, {"id": 1371, "x": 7, "y": -1, "z": 5, "c": "#505860"}, {"id": 1372, "x": 7, "y": -1, "z": 6, "c": "#505860"}, {"id": 1373, "x": 7, "y": -1, "z": 7, "c": "#505860"}, {"id": 1374, "x": 8, "y": -1, "z": -7, "c": "#505860"}, {"id": 1375, "x": 8, "y": -1, "z": -6, "c": "#505860"}, {"id": 1376, "x": 8, "y": -1, "z": -5, "c": "#505860"}, {"id": 1377, "x": 8, "y": -1, "z": -4, "c": "#505860"}, {"id": 1378, "x": 8, "y": -1, "z": -3, "c": "#505860"}, {"id": 1379, "x": 8, "y": -1, "z": -2, "c": "#505860"}, {"id": 1380, "x": 8, "y": -1, "z": -1, "c": "#505860"}, {"id": 1381, "x": 8, "y": -1, "z": 0, "c": "#505860"}, {"id": 1382, "x": 8, "y": -1, "z": 1, "c": "#505860"}, {"id": 1383, "x": 8, "y": -1, "z": 2, "c": "#505860"}, {"id": 1384, "x": 8, "y": -1, "z": 3, "c": "#505860"}, {"id": 1385, "x": 8, "y": -1, "z": 4, "c": "#505860"}, {"id": 1386, "x": 8, "y": -1, "z": 5, "c": "#505860"}, {"id": 1387, "x": 8, "y": -1, "z": 6, "c": "#505860"}, {"id": 1388, "x": 8, "y": -1, "z": 7, "c": "#505860"}, {"id": 1389, "x": 9, "y": -1, "z": -7, "c": "#505860"}, {"id": 1390, "x": 9, "y": -1, "z": -6, "c": "#505860"}, {"id": 1391, "x": 9, "y": -1, "z": -5, "c": "#505860"}, {"id": 1392, "x": 9, "y": -1, "z": -4, "c": "#505860"}, {"id": 1393, "x": 9, "y": -1, "z": -3, "c": "#505860"}, {"id": 1394, "x": 9, "y": -1, "z": -2, "c": "#505860"}, {"id": 1395, "x": 9, "y": -1, "z": -1, "c": "#505860"}, {"id": 1396, "x": 9, "y": -1, "z": 0, "c": "#505860"}, {"id": 1397, "x": 9, "y": -1, "z": 1, "c": "#505860"}, {"id": 1398, "x": 9, "y": -1, "z": 2, "c": "#505860"}, {"id": 1399, "x": 9, "y": -1, "z": 3, "c": "#505860"}, {"id": 1400, "x": 9, "y": -1, "z": 4, "c": "#505860"}, {"id": 1401, "x": 9, "y": -1, "z": 5, "c": "#505860"}, {"id": 1402, "x": 9, "y": -1, "z": 6, "c": "#505860"}, {"id": 1403, "x": 9, "y": -1, "z": 7, "c": "#505860"}, {"id": 1404, "x": -4, "y": 0, "z": -4, "c": "#9ca2a6"}, {"id": 1405, "x": -4, "y": 0, "z": -3, "c": "#9ca2a6"}, {"id": 1406, "x": -4, "y": 0, "z": -2, "c": "#9ca2a6"}, {"id": 1407, "x": -4, "y": 0, "z": -1, "c": "#9ca2a6"}, {"id": 1408, "x": -4, "y": 0, "z": 0, "c": "#9ca2a6"}, {"id": 1409, "x": -4, "y": 0, "z": 1, "c": "#9ca2a6"}, {"id": 1410, "x": -4, "y": 0, "z": 2, "c": "#9ca2a6"}, {"id": 1411, "x": -4, "y": 0, "z": 3, "c": "#9ca2a6"}, {"id": 1412, "x": -4, "y": 0, "z": 4, "c": "#9ca2a6"}, {"id": 1413, "x": -3, "y": 0, "z": -4, "c": "#9ca2a6"}, {"id": 1414, "x": -3, "y": 0, "z": -3, "c": "#9ca2a6"}, {"id": 1415, "x": -3, "y": 0, "z": -2, "c": "#9ca2a6"}, {"id": 1416, "x": -3, "y": 0, "z": -1, "c": "#9ca2a6"}, {"id": 1417, "x": -3, "y": 0, "z": 0, "c": "#9ca2a6"}, {"id": 1418, "x": -3, "y": 0, "z": 1, "c": "#9ca2a6"}, {"id": 1419, "x": -3, "y": 0, "z": 2, "c": "#9ca2a6"}, {"id": 1420, "x": -3, "y": 0, "z": 3, "c": "#9ca2a6"}, {"id": 1421, "x": -3, "y": 0, "z": 4, "c": "#9ca2a6"}, {"id": 1422, "x": -2, "y": 0, "z": -4, "c": "#9ca2a6"}, {"id": 1423, "x": -2, "y": 0, "z": -3, "c": "#9ca2a6"}, {"id": 1424, "x": -2, "y": 0, "z": -2, "c": "#c6beb1"}, {"id": 1425, "x": -2, "y": 0, "z": -1, "c": "#c6beb1"}, {"id": 1426, "x": -2, "y": 0, "z": 0, "c": "#c6beb1"}, {"id": 1427, "x": -2, "y": 0, "z": 1, "c": "#c6beb1"}, {"id": 1428, "x": -2, "y": 0, "z": 2, "c": "#c6beb1"}, {"id": 1429, "x": -2, "y": 0, "z": 3, "c": "#9ca2a6"}, {"id": 1430, "x": -2, "y": 0, "z": 4, "c": "#9ca2a6"}, {"id": 1431, "x": -1, "y": 0, "z": -4, "c": "#9ca2a6"}, {"id": 1432, "x": -1, "y": 0, "z": -3, "c": "#9ca2a6"}, {"id": 1433, "x": -1, "y": 0, "z": -2, "c": "#9ca2a6"}, {"id": 1434, "x": -1, "y": 0, "z": -1, "c": "#9ca2a6"}, {"id": 1435, "x": -1, "y": 0, "z": 0, "c": "#c6beb1"}, {"id": 1436, "x": -1, "y": 0, "z": 1, "c": "#9ca2a6"}, {"id": 1437, "x": -1, "y": 0, "z": 2, "c": "#9ca2a6"}, {"id": 1438, "x": -1, "y": 0, "z": 3, "c": "#9ca2a6"}, {"id": 1439, "x": -1, "y": 0, "z": 4, "c": "#9ca2a6"}, {"id": 1440, "x": 0, "y": 0, "z": -4, "c": "#9ca2a6"}, {"id": 1441, "x": 0, "y": 0, "z": -3, "c": "#9ca2a6"}, {"id": 1442, "x": 0, "y": 0, "z": -2, "c": "#9ca2a6"}, {"id": 1443, "x": 0, "y": 0, "z": -1, "c": "#9ca2a6"}, {"id": 1444, "x": 0, "y": 0, "z": 0, "c": "#c6beb1"}, {"id": 1445, "x": 0, "y": 0, "z": 1, "c": "#9ca2a6"}, {"id": 1446, "x": 0, "y": 0, "z": 2, "c": "#9ca2a6"}, {"id": 1447, "x": 0, "y": 0, "z": 3, "c": "#9ca2a6"}, {"id": 1448, "x": 0, "y": 0, "z": 4, "c": "#9ca2a6"}, {"id": 1449, "x": 1, "y": 0, "z": -4, "c": "#9ca2a6"}, {"id": 1450, "x": 1, "y": 0, "z": -3, "c": "#9ca2a6"}, {"id": 1451, "x": 1, "y": 0, "z": -2, "c": "#9ca2a6"}, {"id": 1452, "x": 1, "y": 0, "z": -1, "c": "#9ca2a6"}, {"id": 1453, "x": 1, "y": 0, "z": 0, "c": "#c6beb1"}, {"id": 1454, "x": 1, "y": 0, "z": 1, "c": "#9ca2a6"}, {"id": 1455, "x": 1, "y": 0, "z": 2, "c": "#9ca2a6"}, {"id": 1456, "x": 1, "y": 0, "z": 3, "c": "#9ca2a6"}, {"id": 1457, "x": 1, "y": 0, "z": 4, "c": "#9ca2a6"}, {"id": 1458, "x": 2, "y": 0, "z": -4, "c": "#9ca2a6"}, {"id": 1459, "x": 2, "y": 0, "z": -3, "c": "#9ca2a6"}, {"id": 1460, "x": 2, "y": 0, "z": -2, "c": "#c6beb1"}, {"id": 1461, "x": 2, "y": 0, "z": -1, "c": "#c6beb1"}, {"id": 1462, "x": 2, "y": 0, "z": 0, "c": "#c6beb1"}, {"id": 1463, "x": 2, "y": 0, "z": 1, "c": "#c6beb1"}, {"id": 1464, "x": 2, "y": 0, "z": 2, "c": "#c6beb1"}, {"id": 1465, "x": 2, "y": 0, "z": 3, "c": "#9ca2a6"}, {"id": 1466, "x": 2, "y": 0, "z": 4, "c": "#9ca2a6"}, {"id": 1467, "x": 3, "y": 0, "z": -4, "c": "#9ca2a6"}, {"id": 1468, "x": 3, "y": 0, "z": -3, "c": "#9ca2a6"}, {"id": 1469, "x": 3, "y": 0, "z": -2, "c": "#9ca2a6"}, {"id": 1470, "x": 3, "y": 0, "z": -1, "c": "#9ca2a6"}, {"id": 1471, "x": 3, "y": 0, "z": 0, "c": "#9ca2a6"}, {"id": 1472, "x": 3, "y": 0, "z": 1, "c": "#9ca2a6"}, {"id": 1473, "x": 3, "y": 0, "z": 2, "c": "#9ca2a6"}, {"id": 1474, "x": 3, "y": 0, "z": 3, "c": "#9ca2a6"}, {"id": 1475, "x": 3, "y": 0, "z": 4, "c": "#9ca2a6"}, {"id": 1476, "x": 4, "y": 0, "z": -4, "c": "#9ca2a6"}, {"id": 1477, "x": 4, "y": 0, "z": -3, "c": "#9ca2a6"}, {"id": 1478, "x": 4, "y": 0, "z": -2, "c": "#9ca2a6"}, {"id": 1479, "x": 4, "y": 0, "z": -1, "c": "#9ca2a6"}, {"id": 1480, "x": 4, "y": 0, "z": 0, "c": "#9ca2a6"}, {"id": 1481, "x": 4, "y": 0, "z": 1, "c": "#9ca2a6"}, {"id": 1482, "x": 4, "y": 0, "z": 2, "c": "#9ca2a6"}, {"id": 1483, "x": 4, "y": 0, "z": 3, "c": "#9ca2a6"}, {"id": 1484, "x": 4, "y": 0, "z": 4, "c": "#9ca2a6"}, {"id": 1485, "x": -1, "y": 2, "z": -1, "c": "#23272c"}, {"id": 1486, "x": -1, "y": 2, "z": 0, "c": "#23272c"}, {"id": 1487, "x": -1, "y": 2, "z": 1, "c": "#23272c"}, {"id": 1488, "x": -1, "y": 2, "z": 2, "c": "#23272c"}, {"id": 1489, "x": -1, "y": 2, "z": 3, "c": "#23272c"}, {"id": 1490, "x": 0, "y": 2, "z": -1, "c": "#23272c"}, {"id": 1491, "x": 0, "y": 2, "z": 0, "c": "#23272c"}, {"id": 1492, "x": 0, "y": 2, "z": 1, "c": "#23272c"}, {"id": 1493, "x": 0, "y": 2, "z": 2, "c": "#23272c"}, {"id": 1494, "x": 0, "y": 2, "z": 3, "c": "#23272c"}, {"id": 1495, "x": 1, "y": 2, "z": -1, "c": "#23272c"}, {"id": 1496, "x": 1, "y": 2, "z": 0, "c": "#23272c"}, {"id": 1497, "x": 1, "y": 2, "z": 1, "c": "#23272c"}, {"id": 1498, "x": 1, "y": 2, "z": 2, "c": "#23272c"}, {"id": 1499, "x": 1, "y": 2, "z": 3, "c": "#23272c"}, {"id": 1500, "x": 0, "y": 2, "z": 4, "c": "#23272c"}, {"id": 1501, "x": 0, "y": 3, "z": 4, "c": "#505860"}, {"id": 1502, "x": -3, "y": 3, "z": 1, "c": "#505860"}, {"id": 1503, "x": -2, "y": 3, "z": 1, "c": "#505860"}, {"id": 1504, "x": -1, "y": 3, "z": 1, "c": "#505860"}, {"id": 1505, "x": 0, "y": 3, "z": 1, "c": "#505860"}, {"id": 1506, "x": 1, "y": 3, "z": 1, "c": "#505860"}, {"id": 1507, "x": 2, "y": 3, "z": 1, "c": "#505860"}, {"id": 1508, "x": 3, "y": 3, "z": 1, "c": "#505860"}, {"id": 1509, "x": 0, "y": 3, "z": -2, "c": "#505860"}, {"id": 1510, "x": 0, "y": 3, "z": -1, "c": "#505860"}, {"id": 1511, "x": 0, "y": 3, "z": 0, "c": "#505860"}, {"id": 1512, "x": 0, "y": 3, "z": 2, "c": "#505860"}, {"id": 1513, "x": 0, "y": 3, "z": 3, "c": "#505860"}, {"id": 1514, "x": 7, "y": 0, "z": -5, "c": "#23272c"}, {"id": 1515, "x": 7, "y": 1, "z": -5, "c": "#23272c"}, {"id": 1516, "x": 7, "y": 2, "z": -5, "c": "#23272c"}, {"id": 1517, "x": 7, "y": 3, "z": -5, "c": "#23272c"}, {"id": 1518, "x": 7, "y": 4, "z": -5, "c": "#23272c"}, {"id": 1519, "x": 7, "y": 5, "z": -5, "c": "#23272c"}, {"id": 1520, "x": 7, "y": 6, "z": -5, "c": "#23272c"}, {"id": 1521, "x": 7, "y": 7, "z": -5, "c": "#a24b44"}, {"id": 1522, "x": -10, "y": -11, "z": 3, "c": "#23272c"}, {"id": 1523, "x": -10, "y": -10, "z": 3, "c": "#23272c"}, {"id": 1524, "x": -10, "y": -9, "z": 3, "c": "#23272c"}, {"id": 1525, "x": -10, "y": -11, "z": 4, "c": "#23272c"}, {"id": 1526, "x": -10, "y": -10, "z": 4, "c": "#b0a89c"}, {"id": 1527, "x": -10, "y": -9, "z": 4, "c": "#60737e"}, {"id": 1528, "x": -10, "y": -11, "z": 5, "c": "#23272c"}, {"id": 1529, "x": -10, "y": -10, "z": 5, "c": "#23272c"}, {"id": 1530, "x": -10, "y": -9, "z": 5, "c": "#23272c"}, {"id": 1531, "x": -10, "y": -11, "z": 6, "c": "#23272c"}, {"id": 1532, "x": -10, "y": -10, "z": 6, "c": "#b0a89c"}, {"id": 1533, "x": -10, "y": -9, "z": 6, "c": "#60737e"}, {"id": 1534, "x": -10, "y": -11, "z": 7, "c": "#23272c"}, {"id": 1535, "x": -10, "y": -10, "z": 7, "c": "#23272c"}, {"id": 1536, "x": -10, "y": -9, "z": 7, "c": "#23272c"}, {"id": 1537, "x": -9, "y": -11, "z": 3, "c": "#23272c"}, {"id": 1538, "x": -9, "y": -10, "z": 3, "c": "#23272c"}, {"id": 1539, "x": -9, "y": -9, "z": 3, "c": "#23272c"}, {"id": 1540, "x": -9, "y": -11, "z": 4, "c": "#23272c"}, {"id": 1541, "x": -9, "y": -10, "z": 4, "c": "#b0a89c"}, {"id": 1542, "x": -9, "y": -9, "z": 4, "c": "#60737e"}, {"id": 1543, "x": -9, "y": -11, "z": 5, "c": "#23272c"}, {"id": 1544, "x": -9, "y": -10, "z": 5, "c": "#23272c"}, {"id": 1545, "x": -9, "y": -9, "z": 5, "c": "#23272c"}, {"id": 1546, "x": -9, "y": -11, "z": 6, "c": "#23272c"}, {"id": 1547, "x": -9, "y": -10, "z": 6, "c": "#b0a89c"}, {"id": 1548, "x": -9, "y": -9, "z": 6, "c": "#60737e"}, {"id": 1549, "x": -9, "y": -11, "z": 7, "c": "#23272c"}, {"id": 1550, "x": -9, "y": -10, "z": 7, "c": "#23272c"}, {"id": 1551, "x": -9, "y": -9, "z": 7, "c": "#23272c"}, {"id": 1552, "x": -8, "y": -11, "z": 7, "c": "#23272c"}, {"id": 1553, "x": -8, "y": -10, "z": 7, "c": "#23272c"}, {"id": 1554, "x": -8, "y": -9, "z": 7, "c": "#23272c"}, {"id": 1555, "x": -9, "y": -8, "z": 5, "c": "#4f7a74"}, {"id": 1556, "x": -9, "y": -8, "z": 6, "c": "#a24b44"}]}