{"voxels": [{"id": 0, "x": -10, "y": -12, "z": -8, "c": "#6f7378"}, {"id": 1, "x": -10, "y": -12, "z": -7, "c": "#6f7378"}, {"id": 2, "x": -10, "y": -12, "z": -6, "c": "#6f7378"}, {"id": 3, "x": -10, "y": -12, "z": -5, "c": "#6f7378"}, {"id": 4, "x": -10, "y": -12, "z": -4, "c": "#6f7378"}, {"id": 5, "x": -10, "y": -12, "z": -3, "c": "#6f7378"}, {"id": 6, "x": -10, "y": -12, "z": -2, "c": "#6f7378"}, {"id": 7, "x": -10, "y": -12, "z": -1, "c": "#6f7378"}, {"id": 8, "x": -10, "y": -12, "z": 0, "c": "#6f7378"}, {"id": 9, "x": -10, "y": -12, "z": 1, "c": "#6f7378"}, {"id": 10, "x": -10, "y": -12, "z": 2, "c": "#6f7378"}, {"id": 11, "x": -10, "y": -12, "z": 3, "c": "#6f7378"}, {"id": 12, "x": -10, "y": -12, "z": 4, "c": "#6f7378"}, {"id": 13, "x": -10, "y": -12, "z": 5, "c": "#6f7378"}, {"id": 14, "x": -10, "y": -12, "z": 6, "c": "#6f7378"}, {"id": 15, "x": -10, "y": -12, "z": 7, "c": "#6f7378"}, {"id": 16, "x": -10, "y": -12, "z": 8, "c": "#6f7378"}, {"id": 17, "x": -10, "y": -12, "z": 9, "c": "#6f7378"}, {"id": 18, "x": -10, "y": -12, "z": 10, "c": "#6f7378"}, {"id": 19, "x": -9, "y": -12, "z": -8, "c": "#6f7378"}, {"id": 20, "x": -9, "y": -12, "z": -7, "c": "#6f7378"}, {"id": 21, "x": -9, "y": -12, "z": -6, "c": "#6f7378"}, {"id": 22, "x": -9, "y": -12, "z": -5, "c": "#6f7378"}, {"id": 23, "x": -9, "y": -12, "z": -4, "c": "#6f7378"}, {"id": 24, "x": -9, "y": -12, "z": -3, "c": "#6f7378"}, {"id": 25, "x": -9, "y": -12, "z": -2, "c": "#6f7378"}, {"id": 26, "x": -9, "y": -12, "z": -1, "c": "#6f7378"}, {"id": 27, "x": -9, "y": -12, "z": 0, "c": "#6f7378"}, {"id": 28, "x": -9, "y": -12, "z": 1, "c": "#6f7378"}, {"id": 29, "x": -9, "y": -12, "z": 2, "c": "#6f7378"}, {"id": 30, "x": -9, "y": -12, "z": 3, "c": "#6f7378"}, {"id": 31, "x": -9, "y": -12, "z": 4, "c": "#6f7378"}, {"id": 32, "x": -9, "y": -12, "z": 5, "c": "#6f7378"}, {"id": 33, "x": -9, "y": -12, "z": 6, "c": "#6f7378"}, {"id": 34, "x": -9, "y": -12, "z": 7, "c": "#6f7378"}, {"id": 35, "x": -9, "y": -12, "z": 8, "c": "#6f7378"}, {"id": 36, "x": -9, "y": -12, "z": 9, "c": "#6f7378"}, {"id": 37, "x": -9, "y": -12, "z": 10, "c": "#6f7378"}, {"id": 38, "x": -8, "y": -12, "z": -8, "c": "#6f7378"}, {"id": 39, "x": -8, "y": -12, "z": -7, "c": "#6f7378"}, {"id": 40, "x": -8, "y": -12, "z": -6, "c": "#6f7378"}, {"id": 41, "x": -8, "y": -12, "z": -5, "c": "#6f7378"}, {"id": 42, "x": -8, "y": -12, "z": -4, "c": "#6f7378"}, {"id": 43, "x": -8, "y": -12, "z": -3, "c": "#6f7378"}, {"id": 44, "x": -8, "y": -12, "z": -2, "c": "#6f7378"}, {"id": 45, "x": -8, "y": -12, "z": -1, "c": "#6f7378"}, {"id": 46, "x": -8, "y": -12, "z": 0, "c": "#6f7378"}, {"id": 47, "x": -8, "y": -12, "z": 1, "c": "#6f7378"}, {"id": 48, "x": -8, "y": -12, "z": 2, "c": "#6f7378"}, {"id": 49, "x": -8, "y": -12, "z": 3, "c": "#6f7378"}, {"id": 50, "x": -8, "y": -12, "z": 4, "c": "#6f7378"}, {"id": 51, "x": -8, "y": -12, "z": 5, "c": "#6f7378"}, {"id": 52, "x": -8, "y": -12, "z": 6, "c": "#6f7378"}, {"id": 53, "x": -8, "y": -12, "z": 7, "c": "#6f7378"}, {"id": 54, "x": -8, "y": -12, "z": 8, "c": "#6f7378"}, {"id": 55, "x": -8, "y": -12, "z": 9, "c": "#6f7378"}, {"id": 56, "x": -8, "y": -12, "z": 10, "c": "#6f7378"}, {"id": 57, "x": -7, "y": -12, "z": -8, "c": "#6f7378"}, {"id": 58, "x": -7, "y": -12, "z": -7, "c": "#6f7378"}, {"id": 59, "x": -7, "y": -12, "z": -6, "c": "#6f7378"}, {"id": 60, "x": -7, "y": -12, "z": -5, "c": "#6f7378"}, {"id": 61, "x": -7, "y": -12, "z": -4, "c": "#6f7378"}, {"id": 62, "x": -7, "y": -12, "z": -3, "c": "#6f7378"}, {"id": 63, "x": -7, "y": -12, "z": -2, "c": "#6f7378"}, {"id": 64, "x": -7, "y": -12, "z": -1, "c": "#6f7378"}, {"id": 65, "x": -7, "y": -12, "z": 0, "c": "#6f7378"}, {"id": 66, "x": -7, "y": -12, "z": 1, "c": "#6f7378"}, {"id": 67, "x": -7, "y": -12, "z": 2, "c": "#6f7378"}, {"id": 68, "x": -7, "y": -12, "z": 3, "c": "#6f7378"}, {"id": 69, "x": -7, "y": -12, "z": 4, "c": "#6f7378"}, {"id": 70, "x": -7, "y": -12, "z": 5, "c": "#6f7378"}, {"id": 71, "x": -7, "y": -12, "z": 6, "c": "#6f7378"}, {"id": 72, "x": -7, "y": -12, "z": 7, "c": "#6f7378"}, {"id": 73, "x": -7, "y": -12, "z": 8, "c": "#6f7378"}, {"id": 74, "x": -7, "y": -12, "z": 9, "c": "#6f7378"}, {"id": 75, "x": -7, "y": -12, "z": 10, "c": "#6f7378"}, {"id": 76, "x": -6, "y": -12, "z": -8, "c": "#6f7378"}, {"id": 77, "x": -6, "y": -12, "z": -7, "c": "#6f7378"}, {"id": 78, "x": -6, "y": -12, "z": -6, "c": "#6f7378"}, {"id": 79, "x": -6, "y": -12, "z": -5, "c": "#6f7378"}, {"id": 80, "x": -6, "y": -12, "z": -4, "c": "#6f7378"}, {"id": 81, "x": -6, "y": -12, "z": -3, "c": "#6f7378"}, {"id": 82, "x": -6, "y": -12, "z": -2, "c": "#6f7378"}, {"id": 83, "x": -6, "y": -12, "z": -1, "c": "#6f7378"}, {"id": 84, "x": -6, "y": -12, "z": 0, "c": "#6f7378"}, {"id": 85, "x": -6, "y": -12, "z": 1, "c": "#6f7378"}, {"id": 86, "x": -6, "y": -12, "z": 2, "c": "#6f7378"}, {"id": 87, "x": -6, "y": -12, "z": 3, "c": "#6f7378"}, {"id": 88, "x": -6, "y": -12, "z": 4, "c": "#6f7378"}, {"id": 89, "x": -6, "y": -12, "z": 5, "c": "#6f7378"}, {"id": 90, "x": -6, "y": -12, "z": 6, "c": "#6f7378"}, {"id": 91, "x": -6, "y": -12, "z": 7, "c": "#23272c"}, {"id": 92, "x": -6, "y": -12, "z": 8, "c": "#23272c"}, {"id": 93, "x": -6, "y": -12, "z": 9, "c": "#23272c"}, {"id": 94, "x": -6, "y": -12, "z": 10, "c": "#23272c"}, {"id": 95, "x": -5, "y": -12, "z": -8, "c": "#6f7378"}, {"id": 96, "x": -5, "y": -12, "z": -7, "c": "#6f7378"}, {"id": 97, "x": -5, "y": -12, "z": -6, "c": "#6f7378"}, {"id": 98, "x": -5, "y": -12, "z": -5, "c": "#6f7378"}, {"id": 99, "x": -5, "y": -12, "z": -4, "c": "#6f7378"}, {"id": 100, "x": -5, "y": -12, "z": -3, "c": "#6f7378"}, {"id": 101, "x": -5, "y": -12, "z": -2, "c": "#6f7378"}, {"id": 102, "x": -5, "y": -12, "z": -1, "c": "#6f7378"}, {"id": 103, "x": -5, "y": -12, "z": 0, "c": "#6f7378"}, {"id": 104, "x": -5, "y": -12, "z": 1, "c": "#6f7378"}, {"id": 105, "x": -5, "y": -12, "z": 2, "c": "#6f7378"}, {"id": 106, "x": -5, "y": -12, "z": 3, "c": "#6f7378"}, {"id": 107, "x": -5, "y": -12, "z": 4, "c": "#6f7378"}, {"id": 108, "x": -5, "y": -12, "z": 5, "c": "#6f7378"}, {"id": 109, "x": -5, "y": -12, "z": 6, "c": "#6f7378"}, {"id": 110, "x": -5, "y": -12, "z": 7, "c": "#23272c"}, {"id": 111, "x": -5, "y": -12, "z": 8, "c": "#23272c"}, {"id": 112, "x": -5, "y": -12, "z": 9, "c": "#23272c"}, {"id": 113, "x": -5, "y": -12, "z": 10, "c": "#23272c"}, {"id": 114, "x": -4, "y": -12, "z": -8, "c": "#6f7378"}, {"id": 115, "x": -4, "y": -12, "z": -7, "c": "#6f7378"}, {"id": 116, "x": -4, "y": -12, "z": -6, "c": "#6f7378"}, {"id": 117, "x": -4, "y": -12, "z": -5, "c": "#6f7378"}, {"id": 118, "x": -4, "y": -12, "z": -4, "c": "#6f7378"}, {"id": 119, "x": -4, "y": -12, "z": -3, "c": "#6f7378"}, {"id": 120, "x": -4, "y": -12, "z": -2, "c": "#6f7378"}, {"id": 121, "x": -4, "y": -12, "z": -1, "c": "#6f7378"}, {"id": 122, "x": -4, "y": -12, "z": 0, "c": "#6f7378"}, {"id": 123, "x": -4, "y": -12, "z": 1, "c": "#6f7378"}, {"id": 124, "x": -4, "y": -12, "z": 2, "c": "#6f7378"}, {"id": 125, "x": -4, "y": -12, "z": 3, "c": "#6f7378"}, {"id": 126, "x": -4, "y": -12, "z": 4, "c": "#6f7378"}, {"id": 127, "x": -4, "y": -12, "z": 5, "c": "#6f7378"}, {"id": 128, "x": -4, "y": -12, "z": 6, "c": "#6f7378"}, {"id": 129, "x": -4, "y": -12, "z": 7, "c": "#23272c"}, {"id": 130, "x": -4, "y": -12, "z": 8, "c": "#23272c"}, {"id": 131, "x": -4, "y": -12, "z": 9, "c": "#23272c"}, {"id": 132, "x": -4, "y": -12, "z": 10, "c": "#23272c"}, {"id": 133, "x": -3, "y": -12, "z": -8, "c": "#6f7378"}, {"id": 134, "x": -3, "y": -12, "z": -7, "c": "#6f7378"}, {"id": 135, "x": -3, "y": -12, "z": -6, "c": "#6f7378"}, {"id": 136, "x": -3, "y": -12, "z": -5, "c": "#6f7378"}, {"id": 137, "x": -3, "y": -12, "z": -4, "c": "#6f7378"}, {"id": 138, "x": -3, "y": -12, "z": -3, "c": "#6f7378"}, {"id": 139, "x": -3, "y": -12, "z": -2, "c": "#6f7378"}, {"id": 140, "x": -3, "y": -12, "z": -1, "c": "#6f7378"}, {"id": 141, "x": -3, "y": -12, "z": 0, "c": "#6f7378"}, {"id": 142, "x": -3, "y": -12, "z": 1, "c": "#6f7378"}, {"id": 143, "x": -3, "y": -12, "z": 2, "c": "#6f7378"}, {"id": 144, "x": -3, "y": -12, "z": 3, "c": "#6f7378"}, {"id": 145, "x": -3, "y": -12, "z": 4, "c": "#6f7378"}, {"id": 146, "x": -3, "y": -12, "z": 5, "c": "#6f7378"}, {"id": 147, "x": -3, "y": -12, "z": 6, "c": "#6f7378"}, {"id": 148, "x": -3, "y": -12, "z": 7, "c": "#23272c"}, {"id": 149, "x": -3, "y": -12, "z": 8, "c": "#23272c"}, {"id": 150, "x": -3, "y": -12, "z": 9, "c": "#23272c"}, {"id": 151, "x": -3, "y": -12, "z": 10, "c": "#23272c"}, {"id": 152, "x": -2, "y": -12, "z": -8, "c": "#6f7378"}, {"id": 153, "x": -2, "y": -12, "z": -7, "c": "#6f7378"}, {"id": 154, "x": -2, "y": -12, "z": -6, "c": "#6f7378"}, {"id": 155, "x": -2, "y": -12, "z": -5, "c": "#6f7378"}, {"id": 156, "x": -2, "y": -12, "z": -4, "c": "#6f7378"}, {"id": 157, "x": -2, "y": -12, "z": -3, "c": "#6f7378"}, {"id": 158, "x": -2, "y": -12, "z": -2, "c": "#6f7378"}, {"id": 159, "x": -2, "y": -12, "z": -1, "c": "#6f7378"}, {"id": 160, "x": -2, "y": -12, "z": 0, "c": "#6f7378"}, {"id": 161, "x": -2, "y": -12, "z": 1, "c": "#6f7378"}, {"id": 162, "x": -2, "y": -12, "z": 2, "c": "#6f7378"}, {"id": 163, "x": -2, "y": -12, "z": 3, "c": "#6f7378"}, {"id": 164, "x": -2, "y": -12, "z": 4, "c": "#6f7378"}, {"id": 165, "x": -2, "y": -12, "z": 5, "c": "#6f7378"}, {"id": 166, "x": -2, "y": -12, "z": 6, "c": "#6f7378"}, {"id": 167, "x": -2, "y": -12, "z": 7, "c": "#23272c"}, {"id": 168, "x": -2, "y": -12, "z": 8, "c": "#23272c"}, {"id": 169, "x": -2, "y": -12, "z": 9, "c": "#23272c"}, {"id": 170, "x": -2, "y": -12, "z": 10, "c": "#23272c"}, {"id": 171, "x": -1, "y": -12, "z": -8, "c": "#6f7378"}, {"id": 172, "x": -1, "y": -12, "z": -7, "c": "#6f7378"}, {"id": 173, "x": -1, "y": -12, "z": -6, "c": "#6f7378"}, {"id": 174, "x": -1, "y": -12, "z": -5, "c": "#6f7378"}, {"id": 175, "x": -1, "y": -12, "z": -4, "c": "#6f7378"}, {"id": 176, "x": -1, "y": -12, "z": -3, "c": "#6f7378"}, {"id": 177, "x": -1, "y": -12, "z": -2, "c": "#6f7378"}, {"id": 178, "x": -1, "y": -12, "z": -1, "c": "#6f7378"}, {"id": 179, "x": -1, "y": -12, "z": 0, "c": "#d6bb71"}, {"id": 180, "x": -1, "y": -12, "z": 1, "c": "#6f7378"}, {"id": 181, "x": -1, "y": -12, "z": 2, "c": "#6f7378"}, {"id": 182, "x": -1, "y": -12, "z": 3, "c": "#6f7378"}, {"id": 183, "x": -1, "y": -12, "z": 4, "c": "#6f7378"}, {"id": 184, "x": -1, "y": -12, "z": 5, "c": "#6f7378"}, {"id": 185, "x": -1, "y": -12, "z": 6, "c": "#6f7378"}, {"id": 186, "x": -1, "y": -12, "z": 7, "c": "#23272c"}, {"id": 187, "x": -1, "y": -12, "z": 8, "c": "#23272c"}, {"id": 188, "x": -1, "y": -12, "z": 9, "c": "#23272c"}, {"id": 189, "x": -1, "y": -12, "z": 10, "c": "#23272c"}, {"id": 190, "x": 0, "y": -12, "z": -8, "c": "#6f7378"}, {"id": 191, "x": 0, "y": -12, "z": -7, "c": "#6f7378"}, {"id": 192, "x": 0, "y": -12, "z": -6, "c": "#6f7378"}, {"id": 193, "x": 0, "y": -12, "z": -5, "c": "#6f7378"}, {"id": 194, "x": 0, "y": -12, "z": -4, "c": "#6f7378"}, {"id": 195, "x": 0, "y": -12, "z": -3, "c": "#6f7378"}, {"id": 196, "x": 0, "y": -12, "z": -2, "c": "#6f7378"}, {"id": 197, "x": 0, "y": -12, "z": -1, "c": "#6f7378"}, {"id": 198, "x": 0, "y": -12, "z": 0, "c": "#d6bb71"}, {"id": 199, "x": 0, "y": -12, "z": 1, "c": "#6f7378"}, {"id": 200, "x": 0, "y": -12, "z": 2, "c": "#6f7378"}, {"id": 201, "x": 0, "y": -12, "z": 3, "c": "#6f7378"}, {"id": 202, "x": 0, "y": -12, "z": 4, "c": "#6f7378"}, {"id": 203, "x": 0, "y": -12, "z": 5, "c": "#6f7378"}, {"id": 204, "x": 0, "y": -12, "z": 6, "c": "#6f7378"}, {"id": 205, "x": 0, "y": -12, "z": 7, "c": "#b18b57"}, {"id": 206, "x": 0, "y": -12, "z": 8, "c": "#b18b57"}, {"id": 207, "x": 0, "y": -12, "z": 9, "c": "#b18b57"}, {"id": 208, "x": 0, "y": -12, "z": 10, "c": "#b18b57"}, {"id": 209, "x": 1, "y": -12, "z": -8, "c": "#6f7378"}, {"id": 210, "x": 1, "y": -12, "z": -7, "c": "#6f7378"}, {"id": 211, "x": 1, "y": -12, "z": -6, "c": "#6f7378"}, {"id": 212, "x": 1, "y": -12, "z": -5, "c": "#6f7378"}, {"id": 213, "x": 1, "y": -12, "z": -4, "c": "#6f7378"}, {"id": 214, "x": 1, "y": -12, "z": -3, "c": "#6f7378"}, {"id": 215, "x": 1, "y": -12, "z": -2, "c": "#6f7378"}, {"id": 216, "x": 1, "y": -12, "z": -1, "c": "#6f7378"}, {"id": 217, "x": 1, "y": -12, "z": 0, "c": "#d6bb71"}, {"id": 218, "x": 1, "y": -12, "z": 1, "c": "#6f7378"}, {"id": 219, "x": 1, "y": -12, "z": 2, "c": "#6f7378"}, {"id": 220, "x": 1, "y": -12, "z": 3, "c": "#6f7378"}, {"id": 221, "x": 1, "y": -12, "z": 4, "c": "#6f7378"}, {"id": 222, "x": 1, "y": -12, "z": 5, "c": "#6f7378"}, {"id": 223, "x": 1, "y": -12, "z": 6, "c": "#6f7378"}, {"id": 224, "x": 1, "y": -12, "z": 7, "c": "#23272c"}, {"id": 225, "x": 1, "y": -12, "z": 8, "c": "#23272c"}, {"id": 226, "x": 1, "y": -12, "z": 9, "c": "#23272c"}, {"id": 227, "x": 1, "y": -12, "z": 10, "c": "#23272c"}, {"id": 228, "x": 2, "y": -12, "z": -8, "c": "#6f7378"}, {"id": 229, "x": 2, "y": -12, "z": -7, "c": "#6f7378"}, {"id": 230, "x": 2, "y": -12, "z": -6, "c": "#6f7378"}, {"id": 231, "x": 2, "y": -12, "z": -5, "c": "#6f7378"}, {"id": 232, "x": 2, "y": -12, "z": -4, "c": "#6f7378"}, {"id": 233, "x": 2, "y": -12, "z": -3, "c": "#6f7378"}, {"id": 234, "x": 2, "y": -12, "z": -2, "c": "#6f7378"}, {"id": 235, "x": 2, "y": -12, "z": -1, "c": "#6f7378"}, {"id": 236, "x": 2, "y": -12, "z": 0, "c": "#6f7378"}, {"id": 237, "x": 2, "y": -12, "z": 1, "c": "#6f7378"}, {"id": 238, "x": 2, "y": -12, "z": 2, "c": "#6f7378"}, {"id": 239, "x": 2, "y": -12, "z": 3, "c": "#6f7378"}, {"id": 240, "x": 2, "y": -12, "z": 4, "c": "#6f7378"}, {"id": 241, "x": 2, "y": -12, "z": 5, "c": "#6f7378"}, {"id": 242, "x": 2, "y": -12, "z": 6, "c": "#6f7378"}, {"id": 243, "x": 2, "y": -12, "z": 7, "c": "#23272c"}, {"id": 244, "x": 2, "y": -12, "z": 8, "c": "#23272c"}, {"id": 245, "x": 2, "y": -12, "z": 9, "c": "#23272c"}, {"id": 246, "x": 2, "y": -12, "z": 10, "c": "#23272c"}, {"id": 247, "x": 3, "y": -12, "z": -8, "c": "#6f7378"}, {"id": 248, "x": 3, "y": -12, "z": -7, "c": "#6f7378"}, {"id": 249, "x": 3, "y": -12, "z": -6, "c": "#6f7378"}, {"id": 250, "x": 3, "y": -12, "z": -5, "c": "#6f7378"}, {"id": 251, "x": 3, "y": -12, "z": -4, "c": "#6f7378"}, {"id": 252, "x": 3, "y": -12, "z": -3, "c": "#6f7378"}, {"id": 253, "x": 3, "y": -12, "z": -2, "c": "#6f7378"}, {"id": 254, "x": 3, "y": -12, "z": -1, "c": "#6f7378"}, {"id": 255, "x": 3, "y": -12, "z": 0, "c": "#6f7378"}, {"id": 256, "x": 3, "y": -12, "z": 1, "c": "#6f7378"}, {"id": 257, "x": 3, "y": -12, "z": 2, "c": "#6f7378"}, {"id": 258, "x": 3, "y": -12, "z": 3, "c": "#6f7378"}, {"id": 259, "x": 3, "y": -12, "z": 4, "c": "#6f7378"}, {"id": 260, "x": 3, "y": -12, "z": 5, "c": "#6f7378"}, {"id": 261, "x": 3, "y": -12, "z": 6, "c": "#6f7378"}, {"id": 262, "x": 3, "y": -12, "z": 7, "c": "#23272c"}, {"id": 263, "x": 3, "y": -12, "z": 8, "c": "#23272c"}, {"id": 264, "x": 3, "y": -12, "z": 9, "c": "#23272c"}, {"id": 265, "x": 3, "y": -12, "z": 10, "c": "#23272c"}, {"id": 266, "x": 4, "y": -12, "z": -8, "c": "#6f7378"}, {"id": 267, "x": 4, "y": -12, "z": -7, "c": "#6f7378"}, {"id": 268, "x": 4, "y": -12, "z": -6, "c": "#6f7378"}, {"id": 269, "x": 4, "y": -12, "z": -5, "c": "#6f7378"}, {"id": 270, "x": 4, "y": -12, "z": -4, "c": "#6f7378"}, {"id": 271, "x": 4, "y": -12, "z": -3, "c": "#6f7378"}, {"id": 272, "x": 4, "y": -12, "z": -2, "c": "#6f7378"}, {"id": 273, "x": 4, "y": -12, "z": -1, "c": "#6f7378"}, {"id": 274, "x": 4, "y": -12, "z": 0, "c": "#6f7378"}, {"id": 275, "x": 4, "y": -12, "z": 1, "c": "#6f7378"}, {"id": 276, "x": 4, "y": -12, "z": 2, "c": "#6f7378"}, {"id": 277, "x": 4, "y": -12, "z": 3, "c": "#6f7378"}, {"id": 278, "x": 4, "y": -12, "z": 4, "c": "#6f7378"}, {"id": 279, "x": 4, "y": -12, "z": 5, "c": "#6f7378"}, {"id": 280, "x": 4, "y": -12, "z": 6, "c": "#6f7378"}, {"id": 281, "x": 4, "y": -12, "z": 7, "c": "#23272c"}, {"id": 282, "x": 4, "y": -12, "z": 8, "c": "#23272c"}, {"id": 283, "x": 4, "y": -12, "z": 9, "c": "#23272c"}, {"id": 284, "x": 4, "y": -12, "z": 10, "c": "#23272c"}, {"id": 285, "x": 5, "y": -12, "z": -8, "c": "#6f7378"}, {"id": 286, "x": 5, "y": -12, "z": -7, "c": "#6f7378"}, {"id": 287, "x": 5, "y": -12, "z": -6, "c": "#6f7378"}, {"id": 288, "x": 5, "y": -12, "z": -5, "c": "#6f7378"}, {"id": 289, "x": 5, "y": -12, "z": -4, "c": "#6f7378"}, {"id": 290, "x": 5, "y": -12, "z": -3, "c": "#6f7378"}, {"id": 291, "x": 5, "y": -12, "z": -2, "c": "#6f7378"}, {"id": 292, "x": 5, "y": -12, "z": -1, "c": "#6f7378"}, {"id": 293, "x": 5, "y": -12, "z": 0, "c": "#6f7378"}, {"id": 294, "x": 5, "y": -12, "z": 1, "c": "#6f7378"}, {"id": 295, "x": 5, "y": -12, "z": 2, "c": "#6f7378"}, {"id": 296, "x": 5, "y": -12, "z": 3, "c": "#6f7378"}, {"id": 297, "x": 5, "y": -12, "z": 4, "c": "#6f7378"}, {"id": 298, "x": 5, "y": -12, "z": 5, "c": "#6f7378"}, {"id": 299, "x": 5, "y": -12, "z": 6, "c": "#6f7378"}, {"id": 300, "x": 5, "y": -12, "z": 7, "c": "#23272c"}, {"id": 301, "x": 5, "y": -12, "z": 8, "c": "#23272c"}, {"id": 302, "x": 5, "y": -12, "z": 9, "c": "#23272c"}, {"id": 303, "x": 5, "y": -12, "z": 10, "c": "#23272c"}, {"id": 304, "x": 6, "y": -12, "z": -8, "c": "#6f7378"}, {"id": 305, "x": 6, "y": -12, "z": -7, "c": "#6f7378"}, {"id": 306, "x": 6, "y": -12, "z": -6, "c": "#6f7378"}, {"id": 307, "x": 6, "y": -12, "z": -5, "c": "#6f7378"}, {"id": 308, "x": 6, "y": -12, "z": -4, "c": "#6f7378"}, {"id": 309, "x": 6, "y": -12, "z": -3, "c": "#6f7378"}, {"id": 310, "x": 6, "y": -12, "z": -2, "c": "#6f7378"}, {"id": 311, "x": 6, "y": -12, "z": -1, "c": "#6f7378"}, {"id": 312, "x": 6, "y": -12, "z": 0, "c": "#6f7378"}, {"id": 313, "x": 6, "y": -12, "z": 1, "c": "#6f7378"}, {"id": 314, "x": 6, "y": -12, "z": 2, "c": "#6f7378"}, {"id": 315, "x": 6, "y": -12, "z": 3, "c": "#6f7378"}, {"id": 316, "x": 6, "y": -12, "z": 4, "c": "#6f7378"}, {"id": 317, "x": 6, "y": -12, "z": 5, "c": "#6f7378"}, {"id": 318, "x": 6, "y": -12, "z": 6, "c": "#6f7378"}, {"id": 319, "x": 6, "y": -12, "z": 7, "c": "#23272c"}, {"id": 320, "x": 6, "y": -12, "z": 8, "c": "#23272c"}, {"id": 321, "x": 6, "y": -12, "z": 9, "c": "#23272c"}, {"id": 322, "x": 6, "y": -12, "z": 10, "c": "#23272c"}, {"id": 323, "x": 7, "y": -12, "z": -8, "c": "#6f7378"}, {"id": 324, "x": 7, "y": -12, "z": -7, "c": "#6f7378"}, {"id": 325, "x": 7, "y": -12, "z": -6, "c": "#6f7378"}, {"id": 326, "x": 7, "y": -12, "z": -5, "c": "#6f7378"}, {"id": 327, "x": 7, "y": -12, "z": -4, "c": "#6f7378"}, {"id": 328, "x": 7, "y": -12, "z": -3, "c": "#6f7378"}, {"id": 329, "x": 7, "y": -12, "z": -2, "c": "#6f7378"}, {"id": 330, "x": 7, "y": -12, "z": -1, "c": "#6f7378"}, {"id": 331, "x": 7, "y": -12, "z": 0, "c": "#6f7378"}, {"id": 332, "x": 7, "y": -12, "z": 1, "c": "#6f7378"}, {"id": 333, "x": 7, "y": -12, "z": 2, "c": "#6f7378"}, {"id": 334, "x": 7, "y": -12, "z": 3, "c": "#6f7378"}, {"id": 335, "x": 7, "y": -12, "z": 4, "c": "#6f7378"}, {"id": 336, "x": 7, "y": -12, "z": 5, "c": "#6f7378"}, {"id": 337, "x": 7, "y": -12, "z": 6, "c": "#6f7378"}, {"id": 338, "x": 7, "y": -12, "z": 7, "c": "#6f7378"}, {"id": 339, "x": 7, "y": -12, "z": 8, "c": "#6f7378"}, {"id": 340, "x": 7, "y": -12, "z": 9, "c": "#6f7378"}, {"id": 341, "x": 7, "y": -12, "z": 10, "c": "#6f7378"}, {"id": 342, "x": 8, "y": -12, "z": -8, "c": "#6f7378"}, {"id": 343, "x": 8, "y": -12, "z": -7, "c": "#6f7378"}, {"id": 344, "x": 8, "y": -12, "z": -6, "c": "#6f7378"}, {"id": 345, "x": 8, "y": -12, "z": -5, "c": "#6f7378"}, {"id": 346, "x": 8, "y": -12, "z": -4, "c": "#6f7378"}, {"id": 347, "x": 8, "y": -12, "z": -3, "c": "#6f7378"}, {"id": 348, "x": 8, "y": -12, "z": -2, "c": "#6f7378"}, {"id": 349, "x": 8, "y": -12, "z": -1, "c": "#6f7378"}, {"id": 350, "x": 8, "y": -12, "z": 0, "c": "#6f7378"}, {"id": 351, "x": 8, "y": -12, "z": 1, "c": "#6f7378"}, {"id": 352, "x": 8, "y": -12, "z": 2, "c": "#6f7378"}, {"id": 353, "x": 8, "y": -12, "z": 3, "c": "#6f7378"}, {"id": 354, "x": 8, "y": -12, "z": 4, "c": "#6f7378"}, {"id": 355, "x": 8, "y": -12, "z": 5, "c": "#6f7378"}, {"id": 356, "x": 8, "y": -12, "z": 6, "c": "#6f7378"}, {"id": 357, "x": 8, "y": -12, "z": 7, "c": "#6f7378"}, {"id": 358, "x": 8, "y": -12, "z": 8, "c": "#6f7378"}, {"id": 359, "x": 8, "y": -12, "z": 9, "c": "#6f7378"}, {"id": 360, "x": 8, "y": -12, "z": 10, "c": "#6f7378"}, {"id": 361, "x": 9, "y": -12, "z": -8, "c": "#6f7378"}, {"id": 362, "x": 9, "y": -12, "z": -7, "c": "#6f7378"}, {"id": 363, "x": 9, "y": -12, "z": -6, "c": "#6f7378"}, {"id": 364, "x": 9, "y": -12, "z": -5, "c": "#6f7378"}, {"id": 365, "x": 9, "y": -12, "z": -4, "c": "#6f7378"}, {"id": 366, "x": 9, "y": -12, "z": -3, "c": "#6f7378"}, {"id": 367, "x": 9, "y": -12, "z": -2, "c": "#6f7378"}, {"id": 368, "x": 9, "y": -12, "z": -1, "c": "#6f7378"}, {"id": 369, "x": 9, "y": -12, "z": 0, "c": "#6f7378"}, {"id": 370, "x": 9, "y": -12, "z": 1, "c": "#6f7378"}, {"id": 371, "x": 9, "y": -12, "z": 2, "c": "#6f7378"}, {"id": 372, "x": 9, "y": -12, "z": 3, "c": "#6f7378"}, {"id": 373, "x": 9, "y": -12, "z": 4, "c": "#6f7378"}, {"id": 374, "x": 9, "y": -12, "z": 5, "c": "#6f7378"}, {"id": 375, "x": 9, "y": -12, "z": 6, "c": "#6f7378"}, {"id": 376, "x": 9, "y": -12, "z": 7, "c": "#6f7378"}, {"id": 377, "x": 9, "y": -12, "z": 8, "c": "#6f7378"}, {"id": 378, "x": 9, "y": -12, "z": 9, "c": "#6f7378"}, {"id": 379, "x": 9, "y": -12, "z": 10, "c": "#6f7378"}, {"id": 380, "x": 10, "y": -12, "z": -8, "c": "#6f7378"}, {"id": 381, "x": 10, "y": -12, "z": -7, "c": "#6f7378"}, {"id": 382, "x": 10, "y": -12, "z": -6, "c": "#6f7378"}, {"id": 383, "x": 10, "y": -12, "z": -5, "c": "#6f7378"}, {"id": 384, "x": 10, "y": -12, "z": -4, "c": "#6f7378"}, {"id": 385, "x": 10, "y": -12, "z": -3, "c": "#6f7378"}, {"id": 386, "x": 10, "y": -12, "z": -2, "c": "#6f7378"}, {"id": 387, "x": 10, "y": -12, "z": -1, "c": "#6f7378"}, {"id": 388, "x": 10, "y": -12, "z": 0, "c": "#6f7378"}, {"id": 389, "x": 10, "y": -12, "z": 1, "c": "#6f7378"}, {"id": 390, "x": 10, "y": -12, "z": 2, "c": "#6f7378"}, {"id": 391, "x": 10, "y": -12, "z": 3, "c": "#6f7378"}, {"id": 392, "x": 10, "y": -12, "z": 4, "c": "#6f7378"}, {"id": 393, "x": 10, "y": -12, "z": 5, "c": "#6f7378"}, {"id": 394, "x": 10, "y": -12, "z": 6, "c": "#6f7378"}, {"id": 395, "x": 10, "y": -12, "z": 7, "c": "#6f7378"}, {"id": 396, "x": 10, "y": -12, "z": 8, "c": "#6f7378"}, {"id": 397, "x": 10, "y": -12, "z": 9, "c": "#6f7378"}, {"id": 398, "x": 10, "y": -12, "z": 10, "c": "#6f7378"}, {"id": 399, "x": -8, "y": -11, "z": -6, "c": "#5a4231"}, {"id": 400, "x": -8, "y": -11, "z": -5, "c": "#5a4231"}, {"id": 401, "x": -8, "y": -11, "z": -4, "c": "#5a4231"}, {"id": 402, "x": -8, "y": -11, "z": -3, "c": "#5a4231"}, {"id": 403, "x": -8, "y": -11, "z": -2, "c": "#5a4231"}, {"id": 404, "x": -8, "y": -11, "z": -1, "c": "#5a4231"}, {"id": 405, "x": -8, "y": -11, "z": 0, "c": "#5a4231"}, {"id": 406, "x": -8, "y": -11, "z": 1, "c": "#5a4231"}, {"id": 407, "x": -8, "y": -11, "z": 2, "c": "#5a4231"}, {"id": 408, "x": -8, "y": -11, "z": 3, "c": "#5a4231"}, {"id": 409, "x": -8, "y": -11, "z": 4, "c": "#5a4231"}, {"id": 410, "x": -8, "y": -11, "z": 5, "c": "#5a4231"}, {"id": 411, "x": -8, "y": -11, "z": 6, "c": "#5a4231"}, {"id": 412, "x": -7, "y": -11, "z": -6, "c": "#5a4231"}, {"id": 413, "x": -7, "y": -11, "z": 6, "c": "#5a4231"}, {"id": 414, "x": -6, "y": -11, "z": -6, "c": "#5a4231"}, {"id": 415, "x": -6, "y": -11, "z": 6, "c": "#c6beb1"}, {"id": 416, "x": -5, "y": -11, "z": -6, "c": "#5a4231"}, {"id": 417, "x": -5, "y": -11, "z": 6, "c": "#c6beb1"}, {"id": 418, "x": -4, "y": -11, "z": -6, "c": "#5a4231"}, {"id": 419, "x": -4, "y": -11, "z": 6, "c": "#c6beb1"}, {"id": 420, "x": -3, "y": -11, "z": -6, "c": "#5a4231"}, {"id": 421, "x": -3, "y": -11, "z": 6, "c": "#c6beb1"}, {"id": 422, "x": -2, "y": -11, "z": -6, "c": "#5a4231"}, {"id": 423, "x": -2, "y": -11, "z": 6, "c": "#c6beb1"}, {"id": 424, "x": -1, "y": -11, "z": -6, "c": "#5a4231"}, {"id": 425, "x": -1, "y": -11, "z": 6, "c": "#c6beb1"}, {"id": 426, "x": 0, "y": -11, "z": -6, "c": "#5a4231"}, {"id": 427, "x": 0, "y": -11, "z": 6, "c": "#5a4231"}, {"id": 428, "x": 1, "y": -11, "z": -6, "c": "#5a4231"}, {"id": 429, "x": 1, "y": -11, "z": 6, "c": "#c6beb1"}, {"id": 430, "x": 2, "y": -11, "z": -6, "c": "#5a4231"}, {"id": 431, "x": 2, "y": -11, "z": 6, "c": "#c6beb1"}, {"id": 432, "x": 3, "y": -11, "z": -6, "c": "#5a4231"}, {"id": 433, "x": 3, "y": -11, "z": 6, "c": "#c6beb1"}, {"id": 434, "x": 4, "y": -11, "z": -6, "c": "#5a4231"}, {"id": 435, "x": 4, "y": -11, "z": 6, "c": "#c6beb1"}, {"id": 436, "x": 5, "y": -11, "z": -6, "c": "#5a4231"}, {"id": 437, "x": 5, "y": -11, "z": 6, "c": "#c6beb1"}, {"id": 438, "x": 6, "y": -11, "z": -6, "c": "#5a4231"}, {"id": 439, "x": 6, "y": -11, "z": 6, "c": "#c6beb1"}, {"id": 440, "x": 7, "y": -11, "z": -6, "c": "#5a4231"}, {"id": 441, "x": 7, "y": -11, "z": 6, "c": "#5a4231"}, {"id": 442, "x": 8, "y": -11, "z": -6, "c": "#5a4231"}, {"id": 443, "x": 8, "y": -11, "z": -5, "c": "#5a4231"}, {"id": 444, "x": 8, "y": -11, "z": -4, "c": "#5a4231"}, {"id": 445, "x": 8, "y": -11, "z": -3, "c": "#5a4231"}, {"id": 446, "x": 8, "y": -11, "z": -2, "c": "#5a4231"}, {"id": 447, "x": 8, "y": -11, "z": -1, "c": "#5a4231"}, {"id": 448, "x": 8, "y": -11, "z": 0, "c": "#5a4231"}, {"id": 449, "x": 8, "y": -11, "z": 1, "c": "#5a4231"}, {"id": 450, "x": 8, "y": -11, "z": 2, "c": "#5a4231"}, {"id": 451, "x": 8, "y": -11, "z": 3, "c": "#5a4231"}, {"id": 452, "x": 8, "y": -11, "z": 4, "c": "#5a4231"}, {"id": 453, "x": 8, "y": -11, "z": 5, "c": "#5a4231"}, {"id": 454, "x": 8, "y": -11, "z": 6, "c": "#5a4231"}, {"id": 455, "x": -8, "y": -10, "z": -6, "c": "#5a4231"}, {"id": 456, "x": -8, "y": -10, "z": -5, "c": "#5a4231"}, {"id": 457, "x": -8, "y": -10, "z": -4, "c": "#5a4231"}, {"id": 458, "x": -8, "y": -10, "z": -3, "c": "#5a4231"}, {"id": 459, "x": -8, "y": -10, "z": -2, "c": "#5a4231"}, {"id": 460, "x": -8, "y": -10, "z": -1, "c": "#5a4231"}, {"id": 461, "x": -8, "y": -10, "z": 0, "c": "#5a4231"}, {"id": 462, "x": -8, "y": -10, "z": 1, "c": "#5a4231"}, {"id": 463, "x": -8, "y": -10, "z": 2, "c": "#5a4231"}, {"id": 464, "x": -8, "y": -10, "z": 3, "c": "#5a4231"}, {"id": 465, "x": -8, "y": -10, "z": 4, "c": "#5a4231"}, {"id": 466, "x": -8, "y": -10, "z": 5, "c": "#5a4231"}, {"id": 467, "x": -8, "y": -10, "z": 6, "c": "#5a4231"}, {"id": 468, "x": -7, "y": -10, "z": -6, "c": "#5a4231"}, {"id": 469, "x": -7, "y": -10, "z": 6, "c": "#5a4231"}, {"id": 470, "x": -6, "y": -10, "z": -6, "c": "#5a4231"}, {"id": 471, "x": -6, "y": -10, "z": 6, "c": "#60737e"}, {"id": 472, "x": -5, "y": -10, "z": -6, "c": "#5a4231"}, {"id": 473, "x": -5, "y": -10, "z": 6, "c": "#60737e"}, {"id": 474, "x": -4, "y": -10, "z": -6, "c": "#5a4231"}, {"id": 475, "x": -4, "y": -10, "z": 6, "c": "#60737e"}, {"id": 476, "x": -3, "y": -10, "z": -6, "c": "#5a4231"}, {"id": 477, "x": -3, "y": -10, "z": 6, "c": "#60737e"}, {"id": 478, "x": -2, "y": -10, "z": -6, "c": "#5a4231"}, {"id": 479, "x": -2, "y": -10, "z": 6, "c": "#60737e"}, {"id": 480, "x": -1, "y": -10, "z": -6, "c": "#5a4231"}, {"id": 481, "x": -1, "y": -10, "z": 6, "c": "#60737e"}, {"id": 482, "x": 0, "y": -10, "z": -6, "c": "#5a4231"}, {"id": 483, "x": 0, "y": -10, "z": 6, "c": "#5a4231"}, {"id": 484, "x": 1, "y": -10, "z": -6, "c": "#5a4231"}, {"id": 485, "x": 1, "y": -10, "z": 6, "c": "#60737e"}, {"id": 486, "x": 2, "y": -10, "z": -6, "c": "#5a4231"}, {"id": 487, "x": 2, "y": -10, "z": 6, "c": "#60737e"}, {"id": 488, "x": 3, "y": -10, "z": -6, "c": "#5a4231"}, {"id": 489, "x": 3, "y": -10, "z": 6, "c": "#60737e"}, {"id": 490, "x": 4, "y": -10, "z": -6, "c": "#5a4231"}, {"id": 491, "x": 4, "y": -10, "z": 6, "c": "#60737e"}, {"id": 492, "x": 5, "y": -10, "z": -6, "c": "#5a4231"}, {"id": 493, "x": 5, "y": -10, "z": 6, "c": "#60737e"}, {"id": 494, "x": 6, "y": -10, "z": -6, "c": "#5a4231"}, {"id": 495, "x": 6, "y": -10, "z": 6, "c": "#60737e"}, {"id": 496, "x": 7, "y": -10, "z": -6, "c": "#5a4231"}, {"id": 497, "x": 7, "y": -10, "z": 6, "c": "#5a4231"}, {"id": 498, "x": 8, "y": -10, "z": -6, "c": "#5a4231"}, {"id": 499, "x": 8, "y": -10, "z": -5, "c": "#5a4231"}, {"id": 500, "x": 8, "y": -10, "z": -4, "c": "#5a4231"}, {"id": 501, "x": 8, "y": -10, "z": -3, "c": "#5a4231"}, {"id": 502, "x": 8, "y": -10, "z": -2, "c": "#5a4231"}, {"id": 503, "x": 8, "y": -10, "z": -1, "c": "#5a4231"}, {"id": 504, "x": 8, "y": -10, "z": 0, "c": "#5a4231"}, {"id": 505, "x": 8, "y": -10, "z": 1, "c": "#5a4231"}, {"id": 506, "x": 8, "y": -10, "z": 2, "c": "#5a4231"}, {"id": 507, "x": 8, "y": -10, "z": 3, "c": "#5a4231"}, {"id": 508, "x": 8, "y": -10, "z": 4, "c": "#5a4231"}, {"id": 509, "x": 8, "y": -10, "z": 5, "c": "#5a4231"}, {"id": 510, "x": 8, "y": -10, "z": 6, "c": "#5a4231"}, {"id": 511, "x": -8, "y": -9, "z": -6, "c": "#7a5749"}, {"id": 512, "x": -8, "y": -9, "z": -5, "c": "#7a5749"}, {"id": 513, "x": -8, "y": -9, "z": -4, "c": "#7a5749"}, {"id": 514, "x": -8, "y": -9, "z": -3, "c": "#7a5749"}, {"id": 515, "x": -8, "y": -9, "z": -2, "c": "#7a5749"}, {"id": 516, "x": -8, "y": -9, "z": -1, "c": "#7a5749"}, {"id": 517, "x": -8, "y": -9, "z": 0, "c": "#7a5749"}, {"id": 518, "x": -8, "y": -9, "z": 1, "c": "#7a5749"}, {"id": 519, "x": -8, "y": -9, "z": 2, "c": "#7a5749"}, {"id": 520, "x": -8, "y": -9, "z": 3, "c": "#7a5749"}, {"id": 521, "x": -8, "y": -9, "z": 4, "c": "#7a5749"}, {"id": 522, "x": -8, "y": -9, "z": 5, "c": "#7a5749"}, {"id": 523, "x": -8, "y": -9, "z": 6, "c": "#7a5749"}, {"id": 524, "x": -7, "y": -9, "z": -6, "c": "#7a5749"}, {"id": 525, "x": -7, "y": -9, "z": 6, "c": "#7a5749"}, {"id": 526, "x": -6, "y": -9, "z": -6, "c": "#7a5749"}, {"id": 527, "x": -6, "y": -9, "z": 6, "c": "#c6beb1"}, {"id": 528, "x": -5, "y": -9, "z": -6, "c": "#7a5749"}, {"id": 529, "x": -5, "y": -9, "z": 6, "c": "#c6beb1"}, {"id": 530, "x": -4, "y": -9, "z": -6, "c": "#7a5749"}, {"id": 531, "x": -4, "y": -9, "z": 6, "c": "#c6beb1"}, {"id": 532, "x": -3, "y": -9, "z": -6, "c": "#7a5749"}, {"id": 533, "x": -3, "y": -9, "z": 6, "c": "#c6beb1"}, {"id": 534, "x": -2, "y": -9, "z": -6, "c": "#7a5749"}, {"id": 535, "x": -2, "y": -9, "z": 6, "c": "#c6beb1"}, {"id": 536, "x": -1, "y": -9, "z": -6, "c": "#7a5749"}, {"id": 537, "x": -1, "y": -9, "z": 6, "c": "#c6beb1"}, {"id": 538, "x": 0, "y": -9, "z": -6, "c": "#7a5749"}, {"id": 539, "x": 0, "y": -9, "z": 6, "c": "#7a5749"}, {"id": 540, "x": 1, "y": -9, "z": -6, "c": "#7a5749"}, {"id": 541, "x": 1, "y": -9, "z": 6, "c": "#c6beb1"}, {"id": 542, "x": 2, "y": -9, "z": -6, "c": "#7a5749"}, {"id": 543, "x": 2, "y": -9, "z": 6, "c": "#c6beb1"}, {"id": 544, "x": 3, "y": -9, "z": -6, "c": "#7a5749"}, {"id": 545, "x": 3, "y": -9, "z": 6, "c": "#c6beb1"}, {"id": 546, "x": 4, "y": -9, "z": -6, "c": "#7a5749"}, {"id": 547, "x": 4, "y": -9, "z": 6, "c": "#c6beb1"}, {"id": 548, "x": 5, "y": -9, "z": -6, "c": "#7a5749"}, {"id": 549, "x": 5, "y": -9, "z": 6, "c": "#c6beb1"}, {"id": 550, "x": 6, "y": -9, "z": -6, "c": "#7a5749"}, {"id": 551, "x": 6, "y": -9, "z": 6, "c": "#c6beb1"}, {"id": 552, "x": 7, "y": -9, "z": -6, "c": "#7a5749"}, {"id": 553, "x": 7, "y": -9, "z": 6, "c": "#7a5749"}, {"id": 554, "x": 8, "y": -9, "z": -6, "c": "#7a5749"}, {"id": 555, "x": 8, "y": -9, "z": -5, "c": "#7a5749"}, {"id": 556, "x": 8, "y": -9, "z": -4, "c": "#7a5749"}, {"id": 557, "x": 8, "y": -9, "z": -3, "c": "#7a5749"}, {"id": 558, "x": 8, "y": -9, "z": -2, "c": "#7a5749"}, {"id": 559, "x": 8, "y": -9, "z": -1, "c": "#7a5749"}, {"id": 560, "x": 8, "y": -9, "z": 0, "c": "#7a5749"}, {"id": 561, "x": 8, "y": -9, "z": 1, "c": "#7a5749"}, {"id": 562, "x": 8, "y": -9, "z": 2, "c": "#7a5749"}, {"id": 563, "x": 8, "y": -9, "z": 3, "c": "#7a5749"}, {"id": 564, "x": 8, "y": -9, "z": 4, "c": "#7a5749"}, {"id": 565, "x": 8, "y": -9, "z": 5, "c": "#7a5749"}, {"id": 566, "x": 8, "y": -9, "z": 6, "c": "#7a5749"}, {"id": 567, "x": -8, "y": -8, "z": -6, "c": "#7a5749"}, {"id": 568, "x": -8, "y": -8, "z": -5, "c": "#7a5749"}, {"id": 569, "x": -8, "y": -8, "z": -4, "c": "#7a5749"}, {"id": 570, "x": -8, "y": -8, "z": -3, "c": "#7a5749"}, {"id": 571, "x": -8, "y": -8, "z": -2, "c": "#7a5749"}, {"id": 572, "x": -8, "y": -8, "z": -1, "c": "#7a5749"}, {"id": 573, "x": -8, "y": -8, "z": 0, "c": "#7a5749"}, {"id": 574, "x": -8, "y": -8, "z": 1, "c": "#7a5749"}, {"id": 575, "x": -8, "y": -8, "z": 2, "c": "#7a5749"}, {"id": 576, "x": -8, "y": -8, "z": 3, "c": "#7a5749"}, {"id": 577, "x": -8, "y": -8, "z": 4, "c": "#7a5749"}, {"id": 578, "x": -8, "y": -8, "z": 5, "c": "#7a5749"}, {"id": 579, "x": -8, "y": -8, "z": 6, "c": "#7a5749"}, {"id": 580, "x": -7, "y": -8, "z": -6, "c": "#7a5749"}, {"id": 581, "x": -7, "y": -8, "z": 6, "c": "#7a5749"}, {"id": 582, "x": -6, "y": -8, "z": -6, "c": "#7a5749"}, {"id": 583, "x": -6, "y": -8, "z": 6, "c": "#60737e"}, {"id": 584, "x": -5, "y": -8, "z": -6, "c": "#7a5749"}, {"id": 585, "x": -5, "y": -8, "z": 6, "c": "#60737e"}, {"id": 586, "x": -4, "y": -8, "z": -6, "c": "#7a5749"}, {"id": 587, "x": -4, "y": -8, "z": 6, "c": "#60737e"}, {"id": 588, "x": -3, "y": -8, "z": -6, "c": "#7a5749"}, {"id": 589, "x": -3, "y": -8, "z": 6, "c": "#60737e"}, {"id": 590, "x": -2, "y": -8, "z": -6, "c": "#7a5749"}, {"id": 591, "x": -2, "y": -8, "z": 6, "c": "#60737e"}, {"id": 592, "x": -1, "y": -8, "z": -6, "c": "#7a5749"}, {"id": 593, "x": -1, "y": -8, "z": 6, "c": "#60737e"}, {"id": 594, "x": 0, "y": -8, "z": -6, "c": "#7a5749"}, {"id": 595, "x": 0, "y": -8, "z": 6, "c": "#7a5749"}, {"id": 596, "x": 1, "y": -8, "z": -6, "c": "#7a5749"}, {"id": 597, "x": 1, "y": -8, "z": 6, "c": "#60737e"}, {"id": 598, "x": 2, "y": -8, "z": -6, "c": "#7a5749"}, {"id": 599, "x": 2, "y": -8, "z": 6, "c": "#60737e"}, {"id": 600, "x": 3, "y": -8, "z": -6, "c": "#7a5749"}, {"id": 601, "x": 3, "y": -8, "z": 6, "c": "#60737e"}, {"id": 602, "x": 4, "y": -8, "z": -6, "c": "#7a5749"}, {"id": 603, "x": 4, "y": -8, "z": 6, "c": "#60737e"}, {"id": 604, "x": 5, "y": -8, "z": -6, "c": "#7a5749"}, {"id": 605, "x": 5, "y": -8, "z": 6, "c": "#60737e"}, {"id": 606, "x": 6, "y": -8, "z": -6, "c": "#7a5749"}, {"id": 607, "x": 6, "y": -8, "z": 6, "c": "#60737e"}, {"id": 608, "x": 7, "y": -8, "z": -6, "c": "#7a5749"}, {"id": 609, "x": 7, "y": -8, "z": 6, "c": "#7a5749"}, {"id": 610, "x": 8, "y": -8, "z": -6, "c": "#7a5749"}, {"id": 611, "x": 8, "y": -8, "z": -5, "c": "#7a5749"}, {"id": 612, "x": 8, "y": -8, "z": -4, "c": "#7a5749"}, {"id": 613, "x": 8, "y": -8, "z": -3, "c": "#7a5749"}, {"id": 614, "x": 8, "y": -8, "z": -2, "c": "#7a5749"}, {"id": 615, "x": 8, "y": -8, "z": -1, "c": "#7a5749"}, {"id": 616, "x": 8, "y": -8, "z": 0, "c": "#7a5749"}, {"id": 617, "x": 8, "y": -8, "z": 1, "c": "#7a5749"}, {"id": 618, "x": 8, "y": -8, "z": 2, "c": "#7a5749"}, {"id": 619, "x": 8, "y": -8, "z": 3, "c": "#7a5749"}, {"id": 620, "x": 8, "y": -8, "z": 4, "c": "#7a5749"}, {"id": 621, "x": 8, "y": -8, "z": 5, "c": "#7a5749"}, {"id": 622, "x": 8, "y": -8, "z": 6, "c": "#7a5749"}, {"id": 623, "x": -8, "y": -7, "z": -6, "c": "#60737e"}, {"id": 624, "x": -8, "y": -7, "z": -5, "c": "#7a5749"}, {"id": 625, "x": -8, "y": -7, "z": -4, "c": "#7a5749"}, {"id": 626, "x": -8, "y": -7, "z": -3, "c": "#60737e"}, {"id": 627, "x": -8, "y": -7, "z": -2, "c": "#7a5749"}, {"id": 628, "x": -8, "y": -7, "z": -1, "c": "#7a5749"}, {"id": 629, "x": -8, "y": -7, "z": 0, "c": "#60737e"}, {"id": 630, "x": -8, "y": -7, "z": 1, "c": "#7a5749"}, {"id": 631, "x": -8, "y": -7, "z": 2, "c": "#7a5749"}, {"id": 632, "x": -8, "y": -7, "z": 3, "c": "#60737e"}, {"id": 633, "x": -8, "y": -7, "z": 4, "c": "#7a5749"}, {"id": 634, "x": -8, "y": -7, "z": 5, "c": "#7a5749"}, {"id": 635, "x": -8, "y": -7, "z": 6, "c": "#60737e"}, {"id": 636, "x": -7, "y": -7, "z": -6, "c": "#7a5749"}, {"id": 637, "x": -7, "y": -7, "z": 6, "c": "#7a5749"}, {"id": 638, "x": -6, "y": -7, "z": -6, "c": "#7a5749"}, {"id": 639, "x": -6, "y": -7, "z": 6, "c": "#c6beb1"}, {"id": 640, "x": -5, "y": -7, "z": -6, "c": "#60737e"}, {"id": 641, "x": -5, "y": -7, "z": 6, "c": "#c6beb1"}, {"id": 642, "x": -4, "y": -7, "z": -6, "c": "#7a5749"}, {"id": 643, "x": -4, "y": -7, "z": 6, "c": "#c6beb1"}, {"id": 644, "x": -3, "y": -7, "z": -6, "c": "#7a5749"}, {"id": 645, "x": -3, "y": -7, "z": 6, "c": "#c6beb1"}, {"id": 646, "x": -2, "y": -7, "z": -6, "c": "#60737e"}, {"id": 647, "x": -2, "y": -7, "z": 6, "c": "#c6beb1"}, {"id": 648, "x": -1, "y": -7, "z": -6, "c": "#7a5749"}, {"id": 649, "x": -1, "y": -7, "z": 6, "c": "#c6beb1"}, {"id": 650, "x": 0, "y": -7, "z": -6, "c": "#7a5749"}, {"id": 651, "x": 0, "y": -7, "z": 6, "c": "#7a5749"}, {"id": 652, "x": 1, "y": -7, "z": -6, "c": "#60737e"}, {"id": 653, "x": 1, "y": -7, "z": 6, "c": "#c6beb1"}, {"id": 654, "x": 2, "y": -7, "z": -6, "c": "#7a5749"}, {"id": 655, "x": 2, "y": -7, "z": 6, "c": "#c6beb1"}, {"id": 656, "x": 3, "y": -7, "z": -6, "c": "#7a5749"}, {"id": 657, "x": 3, "y": -7, "z": 6, "c": "#c6beb1"}, {"id": 658, "x": 4, "y": -7, "z": -6, "c": "#60737e"}, {"id": 659, "x": 4, "y": -7, "z": 6, "c": "#c6beb1"}, {"id": 660, "x": 5, "y": -7, "z": -6, "c": "#7a5749"}, {"id": 661, "x": 5, "y": -7, "z": 6, "c": "#c6beb1"}, {"id": 662, "x": 6, "y": -7, "z": -6, "c": "#7a5749"}, {"id": 663, "x": 6, "y": -7, "z": 6, "c": "#c6beb1"}, {"id": 664, "x": 7, "y": -7, "z": -6, "c": "#60737e"}, {"id": 665, "x": 7, "y": -7, "z": 6, "c": "#60737e"}, {"id": 666, "x": 8, "y": -7, "z": -6, "c": "#7a5749"}, {"id": 667, "x": 8, "y": -7, "z": -5, "c": "#7a5749"}, {"id": 668, "x": 8, "y": -7, "z": -4, "c": "#60737e"}, {"id": 669, "x": 8, "y": -7, "z": -3, "c": "#7a5749"}, {"id": 670, "x": 8, "y": -7, "z": -2, "c": "#7a5749"}, {"id": 671, "x": 8, "y": -7, "z": -1, "c": "#60737e"}, {"id": 672, "x": 8, "y": -7, "z": 0, "c": "#7a5749"}, {"id": 673, "x": 8, "y": -7, "z": 1, "c": "#7a5749"}, {"id": 674, "x": 8, "y": -7, "z": 2, "c": "#60737e"}, {"id": 675, "x": 8, "y": -7, "z": 3, "c": "#7a5749"}, {"id": 676, "x": 8, "y": -7, "z": 4, "c": "#7a5749"}, {"id": 677, "x": 8, "y": -7, "z": 5, "c": "#60737e"}, {"id": 678, "x": 8, "y": -7, "z": 6, "c": "#7a5749"}, {"id": 679, "x": -8, "y": -6, "z": -6, "c": "#c6beb1"}, {"id": 680, "x": -8, "y": -6, "z": -5, "c": "#c6beb1"}, {"id": 681, "x": -8, "y": -6, "z": -4, "c": "#c6beb1"}, {"id": 682, "x": -8, "y": -6, "z": -3, "c": "#c6beb1"}, {"id": 683, "x": -8, "y": -6, "z": -2, "c": "#c6beb1"}, {"id": 684, "x": -8, "y": -6, "z": -1, "c": "#c6beb1"}, {"id": 685, "x": -8, "y": -6, "z": 0, "c": "#c6beb1"}, {"id": 686, "x": -8, "y": -6, "z": 1, "c": "#c6beb1"}, {"id": 687, "x": -8, "y": -6, "z": 2, "c": "#c6beb1"}, {"id": 688, "x": -8, "y": -6, "z": 3, "c": "#c6beb1"}, {"id": 689, "x": -8, "y": -6, "z": 4, "c": "#c6beb1"}, {"id": 690, "x": -8, "y": -6, "z": 5, "c": "#c6beb1"}, {"id": 691, "x": -8, "y": -6, "z": 6, "c": "#c6beb1"}, {"id": 692, "x": -7, "y": -6, "z": -6, "c": "#c6beb1"}, {"id": 693, "x": -7, "y": -6, "z": 6, "c": "#c6beb1"}, {"id": 694, "x": -6, "y": -6, "z": -6, "c": "#c6beb1"}, {"id": 695, "x": -6, "y": -6, "z": 6, "c": "#60737e"}, {"id": 696, "x": -5, "y": -6, "z": -6, "c": "#c6beb1"}, {"id": 697, "x": -5, "y": -6, "z": 6, "c": "#60737e"}, {"id": 698, "x": -4, "y": -6, "z": -6, "c": "#c6beb1"}, {"id": 699, "x": -4, "y": -6, "z": 6, "c": "#60737e"}, {"id": 700, "x": -3, "y": -6, "z": -6, "c": "#c6beb1"}, {"id": 701, "x": -3, "y": -6, "z": 6, "c": "#60737e"}, {"id": 702, "x": -2, "y": -6, "z": -6, "c": "#c6beb1"}, {"id": 703, "x": -2, "y": -6, "z": 6, "c": "#60737e"}, {"id": 704, "x": -1, "y": -6, "z": -6, "c": "#c6beb1"}, {"id": 705, "x": -1, "y": -6, "z": 6, "c": "#60737e"}, {"id": 706, "x": 0, "y": -6, "z": -6, "c": "#c6beb1"}, {"id": 707, "x": 0, "y": -6, "z": 6, "c": "#c6beb1"}, {"id": 708, "x": 1, "y": -6, "z": -6, "c": "#c6beb1"}, {"id": 709, "x": 1, "y": -6, "z": 6, "c": "#60737e"}, {"id": 710, "x": 2, "y": -6, "z": -6, "c": "#c6beb1"}, {"id": 711, "x": 2, "y": -6, "z": 6, "c": "#60737e"}, {"id": 712, "x": 3, "y": -6, "z": -6, "c": "#c6beb1"}, {"id": 713, "x": 3, "y": -6, "z": 6, "c": "#60737e"}, {"id": 714, "x": 4, "y": -6, "z": -6, "c": "#c6beb1"}, {"id": 715, "x": 4, "y": -6, "z": 6, "c": "#60737e"}, {"id": 716, "x": 5, "y": -6, "z": -6, "c": "#c6beb1"}, {"id": 717, "x": 5, "y": -6, "z": 6, "c": "#60737e"}, {"id": 718, "x": 6, "y": -6, "z": -6, "c": "#c6beb1"}, {"id": 719, "x": 6, "y": -6, "z": 6, "c": "#60737e"}, {"id": 720, "x": 7, "y": -6, "z": -6, "c": "#c6beb1"}, {"id": 721, "x": 7, "y": -6, "z": 6, "c": "#c6beb1"}, {"id": 722, "x": 8, "y": -6, "z": -6, "c": "#c6beb1"}, {"id": 723, "x": 8, "y": -6, "z": -5, "c": "#c6beb1"}, {"id": 724, "x": 8, "y": -6, "z": -4, "c": "#c6beb1"}, {"id": 725, "x": 8, "y": -6, "z": -3, "c": "#c6beb1"}, {"id": 726, "x": 8, "y": -6, "z": -2, "c": "#c6beb1"}, {"id": 727, "x": 8, "y": -6, "z": -1, "c": "#c6beb1"}, {"id": 728, "x": 8, "y": -6, "z": 0, "c": "#c6beb1"}, {"id": 729, "x": 8, "y": -6, "z": 1, "c": "#c6beb1"}, {"id": 730, "x": 8, "y": -6, "z": 2, "c": "#c6beb1"}, {"id": 731, "x": 8, "y": -6, "z": 3, "c": "#c6beb1"}, {"id": 732, "x": 8, "y": -6, "z": 4, "c": "#c6beb1"}, {"id": 733, "x": 8, "y": -6, "z": 5, "c": "#c6beb1"}, {"id": 734, "x": 8, "y": -6, "z": 6, "c": "#c6beb1"}, {"id": 735, "x": -8, "y": -5, "z": -6, "c": "#60737e"}, {"id": 736, "x": -8, "y": -5, "z": -5, "c": "#7a5749"}, {"id": 737, "x": -8, "y": -5, "z": -4, "c": "#7a5749"}, {"id": 738, "x": -8, "y": -5, "z": -3, "c": "#60737e"}, {"id": 739, "x": -8, "y": -5, "z": -2, "c": "#7a5749"}, {"id": 740, "x": -8, "y": -5, "z": -1, "c": "#7a5749"}, {"id": 741, "x": -8, "y": -5, "z": 0, "c": "#60737e"}, {"id": 742, "x": -8, "y": -5, "z": 1, "c": "#7a5749"}, {"id": 743, "x": -8, "y": -5, "z": 2, "c": "#7a5749"}, {"id": 744, "x": -8, "y": -5, "z": 3, "c": "#60737e"}, {"id": 745, "x": -8, "y": -5, "z": 4, "c": "#7a5749"}, {"id": 746, "x": -8, "y": -5, "z": 5, "c": "#7a5749"}, {"id": 747, "x": -8, "y": -5, "z": 6, "c": "#60737e"}, {"id": 748, "x": -7, "y": -5, "z": -6, "c": "#7a5749"}, {"id": 749, "x": -7, "y": -5, "z": 6, "c": "#7a5749"}, {"id": 750, "x": -6, "y": -5, "z": -6, "c": "#7a5749"}, {"id": 751, "x": -6, "y": -5, "z": 6, "c": "#7a5749"}, {"id": 752, "x": -5, "y": -5, "z": -6, "c": "#60737e"}, {"id": 753, "x": -5, "y": -5, "z": 6, "c": "#60737e"}, {"id": 754, "x": -4, "y": -5, "z": -6, "c": "#7a5749"}, {"id": 755, "x": -4, "y": -5, "z": 6, "c": "#7a5749"}, {"id": 756, "x": -3, "y": -5, "z": -6, "c": "#7a5749"}, {"id": 757, "x": -3, "y": -5, "z": 6, "c": "#7a5749"}, {"id": 758, "x": -2, "y": -5, "z": -6, "c": "#60737e"}, {"id": 759, "x": -2, "y": -5, "z": 6, "c": "#60737e"}, {"id": 760, "x": -1, "y": -5, "z": -6, "c": "#7a5749"}, {"id": 761, "x": -1, "y": -5, "z": 6, "c": "#7a5749"}, {"id": 762, "x": 0, "y": -5, "z": -6, "c": "#7a5749"}, {"id": 763, "x": 0, "y": -5, "z": 6, "c": "#7a5749"}, {"id": 764, "x": 1, "y": -5, "z": -6, "c": "#60737e"}, {"id": 765, "x": 1, "y": -5, "z": 6, "c": "#60737e"}, {"id": 766, "x": 2, "y": -5, "z": -6, "c": "#7a5749"}, {"id": 767, "x": 2, "y": -5, "z": 6, "c": "#7a5749"}, {"id": 768, "x": 3, "y": -5, "z": -6, "c": "#7a5749"}, {"id": 769, "x": 3, "y": -5, "z": 6, "c": "#7a5749"}, {"id": 770, "x": 4, "y": -5, "z": -6, "c": "#60737e"}, {"id": 771, "x": 4, "y": -5, "z": 6, "c": "#60737e"}, {"id": 772, "x": 5, "y": -5, "z": -6, "c": "#7a5749"}, {"id": 773, "x": 5, "y": -5, "z": 6, "c": "#7a5749"}, {"id": 774, "x": 6, "y": -5, "z": -6, "c": "#7a5749"}, {"id": 775, "x": 6, "y": -5, "z": 6, "c": "#7a5749"}, {"id": 776, "x": 7, "y": -5, "z": -6, "c": "#60737e"}, {"id": 777, "x": 7, "y": -5, "z": 6, "c": "#60737e"}, {"id": 778, "x": 8, "y": -5, "z": -6, "c": "#7a5749"}, {"id": 779, "x": 8, "y": -5, "z": -5, "c": "#7a5749"}, {"id": 780, "x": 8, "y": -5, "z": -4, "c": "#60737e"}, {"id": 781, "x": 8, "y": -5, "z": -3, "c": "#7a5749"}, {"id": 782, "x": 8, "y": -5, "z": -2, "c": "#7a5749"}, {"id": 783, "x": 8, "y": -5, "z": -1, "c": "#60737e"}, {"id": 784, "x": 8, "y": -5, "z": 0, "c": "#7a5749"}, {"id": 785, "x": 8, "y": -5, "z": 1, "c": "#7a5749"}, {"id": 786, "x": 8, "y": -5, "z": 2, "c": "#60737e"}, {"id": 787, "x": 8, "y": -5, "z": 3, "c": "#7a5749"}, {"id": 788, "x": 8, "y": -5, "z": 4, "c": "#7a5749"}, {"id": 789, "x": 8, "y": -5, "z": 5, "c": "#60737e"}, {"id": 790, "x": 8, "y": -5, "z": 6, "c": "#7a5749"}, {"id": 791, "x": -8, "y": -4, "z": -6, "c": "#60737e"}, {"id": 792, "x": -8, "y": -4, "z": -5, "c": "#7a5749"}, {"id": 793, "x": -8, "y": -4, "z": -4, "c": "#7a5749"}, {"id": 794, "x": -8, "y": -4, "z": -3, "c": "#60737e"}, {"id": 795, "x": -8, "y": -4, "z": -2, "c": "#7a5749"}, {"id": 796, "x": -8, "y": -4, "z": -1, "c": "#7a5749"}, {"id": 797, "x": -8, "y": -4, "z": 0, "c": "#60737e"}, {"id": 798, "x": -8, "y": -4, "z": 1, "c": "#7a5749"}, {"id": 799, "x": -8, "y": -4, "z": 2, "c": "#7a5749"}, {"id": 800, "x": -8, "y": -4, "z": 3, "c": "#60737e"}, {"id": 801, "x": -8, "y": -4, "z": 4, "c": "#7a5749"}, {"id": 802, "x": -8, "y": -4, "z": 5, "c": "#7a5749"}, {"id": 803, "x": -8, "y": -4, "z": 6, "c": "#60737e"}, {"id": 804, "x": -7, "y": -4, "z": -6, "c": "#7a5749"}, {"id": 805, "x": -7, "y": -4, "z": 6, "c": "#7a5749"}, {"id": 806, "x": -6, "y": -4, "z": -6, "c": "#7a5749"}, {"id": 807, "x": -6, "y": -4, "z": 6, "c": "#7a5749"}, {"id": 808, "x": -5, "y": -4, "z": -6, "c": "#60737e"}, {"id": 809, "x": -5, "y": -4, "z": 6, "c": "#60737e"}, {"id": 810, "x": -4, "y": -4, "z": -6, "c": "#7a5749"}, {"id": 811, "x": -4, "y": -4, "z": 6, "c": "#7a5749"}, {"id": 812, "x": -3, "y": -4, "z": -6, "c": "#7a5749"}, {"id": 813, "x": -3, "y": -4, "z": 6, "c": "#7a5749"}, {"id": 814, "x": -2, "y": -4, "z": -6, "c": "#60737e"}, {"id": 815, "x": -2, "y": -4, "z": 6, "c": "#60737e"}, {"id": 816, "x": -1, "y": -4, "z": -6, "c": "#7a5749"}, {"id": 817, "x": -1, "y": -4, "z": 6, "c": "#7a5749"}, {"id": 818, "x": 0, "y": -4, "z": -6, "c": "#7a5749"}, {"id": 819, "x": 0, "y": -4, "z": 6, "c": "#7a5749"}, {"id": 820, "x": 1, "y": -4, "z": -6, "c": "#60737e"}, {"id": 821, "x": 1, "y": -4, "z": 6, "c": "#60737e"}, {"id": 822, "x": 2, "y": -4, "z": -6, "c": "#7a5749"}, {"id": 823, "x": 2, "y": -4, "z": 6, "c": "#7a5749"}, {"id": 824, "x": 3, "y": -4, "z": -6, "c": "#7a5749"}, {"id": 825, "x": 3, "y": -4, "z": 6, "c": "#7a5749"}, {"id": 826, "x": 4, "y": -4, "z": -6, "c": "#60737e"}, {"id": 827, "x": 4, "y": -4, "z": 6, "c": "#60737e"}, {"id": 828, "x": 5, "y": -4, "z": -6, "c": "#7a5749"}, {"id": 829, "x": 5, "y": -4, "z": 6, "c": "#7a5749"}, {"id": 830, "x": 6, "y": -4, "z": -6, "c": "#7a5749"}, {"id": 831, "x": 6, "y": -4, "z": 6, "c": "#7a5749"}, {"id": 832, "x": 7, "y": -4, "z": -6, "c": "#60737e"}, {"id": 833, "x": 7, "y": -4, "z": 6, "c": "#60737e"}, {"id": 834, "x": 8, "y": -4, "z": -6, "c": "#7a5749"}, {"id": 835, "x": 8, "y": -4, "z": -5, "c": "#7a5749"}, {"id": 836, "x": 8, "y": -4, "z": -4, "c": "#60737e"}, {"id": 837, "x": 8, "y": -4, "z": -3, "c": "#7a5749"}, {"id": 838, "x": 8, "y": -4, "z": -2, "c": "#7a5749"}, {"id": 839, "x": 8, "y": -4, "z": -1, "c": "#60737e"}, {"id": 840, "x": 8, "y": -4, "z": 0, "c": "#7a5749"}, {"id": 841, "x": 8, "y": -4, "z": 1, "c": "#7a5749"}, {"id": 842, "x": 8, "y": -4, "z": 2, "c": "#60737e"}, {"id": 843, "x": 8, "y": -4, "z": 3, "c": "#7a5749"}, {"id": 844, "x": 8, "y": -4, "z": 4, "c": "#7a5749"}, {"id": 845, "x": 8, "y": -4, "z": 5, "c": "#60737e"}, {"id": 846, "x": 8, "y": -4, "z": 6, "c": "#7a5749"}, {"id": 847, "x": -8, "y": -3, "z": -6, "c": "#30363d"}, {"id": 848, "x": -8, "y": -3, "z": -5, "c": "#30363d"}, {"id": 849, "x": -8, "y": -3, "z": -4, "c": "#30363d"}, {"id": 850, "x": -8, "y": -3, "z": -3, "c": "#30363d"}, {"id": 851, "x": -8, "y": -3, "z": -2, "c": "#30363d"}, {"id": 852, "x": -7, "y": -3, "z": -6, "c": "#30363d"}, {"id": 853, "x": -7, "y": -3, "z": -2, "c": "#30363d"}, {"id": 854, "x": -6, "y": -3, "z": -6, "c": "#30363d"}, {"id": 855, "x": -6, "y": -3, "z": -2, "c": "#30363d"}, {"id": 856, "x": -5, "y": -3, "z": -6, "c": "#30363d"}, {"id": 857, "x": -5, "y": -3, "z": -2, "c": "#30363d"}, {"id": 858, "x": -4, "y": -3, "z": -6, "c": "#30363d"}, {"id": 859, "x": -4, "y": -3, "z": -5, "c": "#30363d"}, {"id": 860, "x": -4, "y": -3, "z": -4, "c": "#30363d"}, {"id": 861, "x": -4, "y": -3, "z": -3, "c": "#30363d"}, {"id": 862, "x": -4, "y": -3, "z": -2, "c": "#30363d"}, {"id": 863, "x": -8, "y": -2, "z": -6, "c": "#60737e"}, {"id": 864, "x": -8, "y": -2, "z": -5, "c": "#86483f"}, {"id": 865, "x": -8, "y": -2, "z": -4, "c": "#86483f"}, {"id": 866, "x": -8, "y": -2, "z": -3, "c": "#60737e"}, {"id": 867, "x": -8, "y": -2, "z": -2, "c": "#86483f"}, {"id": 868, "x": -7, "y": -2, "z": -6, "c": "#86483f"}, {"id": 869, "x": -7, "y": -2, "z": -2, "c": "#86483f"}, {"id": 870, "x": -6, "y": -2, "z": -6, "c": "#86483f"}, {"id": 871, "x": -6, "y": -2, "z": -2, "c": "#60737e"}, {"id": 872, "x": -5, "y": -2, "z": -6, "c": "#60737e"}, {"id": 873, "x": -5, "y": -2, "z": -2, "c": "#86483f"}, {"id": 874, "x": -4, "y": -2, "z": -6, "c": "#86483f"}, {"id": 875, "x": -4, "y": -2, "z": -5, "c": "#86483f"}, {"id": 876, "x": -4, "y": -2, "z": -4, "c": "#60737e"}, {"id": 877, "x": -4, "y": -2, "z": -3, "c": "#86483f"}, {"id": 878, "x": -4, "y": -2, "z": -2, "c": "#86483f"}, {"id": 879, "x": -8, "y": -1, "z": -6, "c": "#60737e"}, {"id": 880, "x": -8, "y": -1, "z": -5, "c": "#86483f"}, {"id": 881, "x": -8, "y": -1, "z": -4, "c": "#86483f"}, {"id": 882, "x": -8, "y": -1, "z": -3, "c": "#60737e"}, {"id": 883, "x": -8, "y": -1, "z": -2, "c": "#86483f"}, {"id": 884, "x": -7, "y": -1, "z": -6, "c": "#86483f"}, {"id": 885, "x": -7, "y": -1, "z": -2, "c": "#86483f"}, {"id": 886, "x": -6, "y": -1, "z": -6, "c": "#86483f"}, {"id": 887, "x": -6, "y": -1, "z": -2, "c": "#60737e"}, {"id": 888, "x": -5, "y": -1, "z": -6, "c": "#60737e"}, {"id": 889, "x": -5, "y": -1, "z": -2, "c": "#86483f"}, {"id": 890, "x": -4, "y": -1, "z": -6, "c": "#86483f"}, {"id": 891, "x": -4, "y": -1, "z": -5, "c": "#86483f"}, {"id": 892, "x": -4, "y": -1, "z": -4, "c": "#60737e"}, {"id": 893, "x": -4, "y": -1, "z": -3, "c": "#86483f"}, {"id": 894, "x": -4, "y": -1, "z": -2, "c": "#86483f"}, {"id": 895, "x": -8, "y": 0, "z": -6, "c": "#60737e"}, {"id": 896, "x": -8, "y": 0, "z": -5, "c": "#86483f"}, {"id": 897, "x": -8, "y": 0, "z": -4, "c": "#86483f"}, {"id": 898, "x": -8, "y": 0, "z": -3, "c": "#60737e"}, {"id": 899, "x": -8, "y": 0, "z": -2, "c": "#86483f"}, {"id": 900, "x": -7, "y": 0, "z": -6, "c": "#86483f"}, {"id": 901, "x": -7, "y": 0, "z": -2, "c": "#86483f"}, {"id": 902, "x": -6, "y": 0, "z": -6, "c": "#86483f"}, {"id": 903, "x": -6, "y": 0, "z": -2, "c": "#60737e"}, {"id": 904, "x": -5, "y": 0, "z": -6, "c": "#60737e"}, {"id": 905, "x": -5, "y": 0, "z": -2, "c": "#86483f"}, {"id": 906, "x": -4, "y": 0, "z": -6, "c": "#86483f"}, {"id": 907, "x": -4, "y": 0, "z": -5, "c": "#86483f"}, {"id": 908, "x": -4, "y": 0, "z": -4, "c": "#60737e"}, {"id": 909, "x": -4, "y": 0, "z": -3, "c": "#86483f"}, {"id": 910, "x": -4, "y": 0, "z": -2, "c": "#86483f"}, {"id": 911, "x": -8, "y": 1, "z": -6, "c": "#60737e"}, {"id": 912, "x": -8, "y": 1, "z": -5, "c": "#86483f"}, {"id": 913, "x": -8, "y": 1, "z": -4, "c": "#86483f"}, {"id": 914, "x": -8, "y": 1, "z": -3, "c": "#60737e"}, {"id": 915, "x": -8, "y": 1, "z": -2, "c": "#86483f"}, {"id": 916, "x": -7, "y": 1, "z": -6, "c": "#86483f"}, {"id": 917, "x": -7, "y": 1, "z": -2, "c": "#86483f"}, {"id": 918, "x": -6, "y": 1, "z": -6, "c": "#86483f"}, {"id": 919, "x": -6, "y": 1, "z": -2, "c": "#60737e"}, {"id": 920, "x": -5, "y": 1, "z": -6, "c": "#60737e"}, {"id": 921, "x": -5, "y": 1, "z": -2, "c": "#86483f"}, {"id": 922, "x": -4, "y": 1, "z": -6, "c": "#86483f"}, {"id": 923, "x": -4, "y": 1, "z": -5, "c": "#86483f"}, {"id": 924, "x": -4, "y": 1, "z": -4, "c": "#60737e"}, {"id": 925, "x": -4, "y": 1, "z": -3, "c": "#86483f"}, {"id": 926, "x": -4, "y": 1, "z": -2, "c": "#86483f"}, {"id": 927, "x": -8, "y": 2, "z": -6, "c": "#86483f"}, {"id": 928, "x": -8, "y": 2, "z": -5, "c": "#86483f"}, {"id": 929, "x": -8, "y": 2, "z": -4, "c": "#86483f"}, {"id": 930, "x": -8, "y": 2, "z": -3, "c": "#86483f"}, {"id": 931, "x": -8, "y": 2, "z": -2, "c": "#86483f"}, {"id": 932, "x": -7, "y": 2, "z": -6, "c": "#86483f"}, {"id": 933, "x": -7, "y": 2, "z": -2, "c": "#86483f"}, {"id": 934, "x": -6, "y": 2, "z": -6, "c": "#86483f"}, {"id": 935, "x": -6, "y": 2, "z": -2, "c": "#86483f"}, {"id": 936, "x": -5, "y": 2, "z": -6, "c": "#86483f"}, {"id": 937, "x": -5, "y": 2, "z": -2, "c": "#86483f"}, {"id": 938, "x": -4, "y": 2, "z": -6, "c": "#86483f"}, {"id": 939, "x": -4, "y": 2, "z": -5, "c": "#86483f"}, {"id": 940, "x": -4, "y": 2, "z": -4, "c": "#86483f"}, {"id": 941, "x": -4, "y": 2, "z": -3, "c": "#86483f"}, {"id": 942, "x": -4, "y": 2, "z": -2, "c": "#86483f"}, {"id": 943, "x": -8, "y": 3, "z": -6, "c": "#86483f"}, {"id": 944, "x": -8, "y": 3, "z": -5, "c": "#86483f"}, {"id": 945, "x": -8, "y": 3, "z": -4, "c": "#86483f"}, {"id": 946, "x": -8, "y": 3, "z": -3, "c": "#86483f"}, {"id": 947, "x": -8, "y": 3, "z": -2, "c": "#86483f"}, {"id": 948, "x": -7, "y": 3, "z": -6, "c": "#86483f"}, {"id": 949, "x": -7, "y": 3, "z": -2, "c": "#86483f"}, {"id": 950, "x": -6, "y": 3, "z": -6, "c": "#86483f"}, {"id": 951, "x": -6, "y": 3, "z": -2, "c": "#86483f"}, {"id": 952, "x": -5, "y": 3, "z": -6, "c": "#86483f"}, {"id": 953, "x": -5, "y": 3, "z": -2, "c": "#86483f"}, {"id": 954, "x": -4, "y": 3, "z": -6, "c": "#86483f"}, {"id": 955, "x": -4, "y": 3, "z": -5, "c": "#86483f"}, {"id": 956, "x": -4, "y": 3, "z": -4, "c": "#86483f"}, {"id": 957, "x": -4, "y": 3, "z": -3, "c": "#86483f"}, {"id": 958, "x": -4, "y": 3, "z": -2, "c": "#86483f"}, {"id": 959, "x": -8, "y": 4, "z": -6, "c": "#7a5749"}, {"id": 960, "x": -8, "y": 4, "z": -5, "c": "#7a5749"}, {"id": 961, "x": -8, "y": 4, "z": -4, "c": "#7a5749"}, {"id": 962, "x": -8, "y": 4, "z": -3, "c": "#7a5749"}, {"id": 963, "x": -8, "y": 4, "z": -2, "c": "#7a5749"}, {"id": 964, "x": -7, "y": 4, "z": -6, "c": "#7a5749"}, {"id": 965, "x": -7, "y": 4, "z": -2, "c": "#7a5749"}, {"id": 966, "x": -6, "y": 4, "z": -6, "c": "#7a5749"}, {"id": 967, "x": -6, "y": 4, "z": -2, "c": "#7a5749"}, {"id": 968, "x": -5, "y": 4, "z": -6, "c": "#7a5749"}, {"id": 969, "x": -5, "y": 4, "z": -2, "c": "#7a5749"}, {"id": 970, "x": -4, "y": 4, "z": -6, "c": "#7a5749"}, {"id": 971, "x": -4, "y": 4, "z": -5, "c": "#7a5749"}, {"id": 972, "x": -4, "y": 4, "z": -4, "c": "#7a5749"}, {"id": 973, "x": -4, "y": 4, "z": -3, "c": "#7a5749"}, {"id": 974, "x": -4, "y": 4, "z": -2, "c": "#7a5749"}, {"id": 975, "x": -8, "y": 5, "z": -6, "c": "#c6beb1"}, {"id": 976, "x": -8, "y": 5, "z": -5, "c": "#c6beb1"}, {"id": 977, "x": -8, "y": 5, "z": -4, "c": "#c6beb1"}, {"id": 978, "x": -8, "y": 5, "z": -3, "c": "#c6beb1"}, {"id": 979, "x": -8, "y": 5, "z": -2, "c": "#c6beb1"}, {"id": 980, "x": -7, "y": 5, "z": -6, "c": "#c6beb1"}, {"id": 981, "x": -7, "y": 5, "z": -2, "c": "#c6beb1"}, {"id": 982, "x": -6, "y": 5, "z": -6, "c": "#c6beb1"}, {"id": 983, "x": -6, "y": 5, "z": -2, "c": "#c6beb1"}, {"id": 984, "x": -5, "y": 5, "z": -6, "c": "#c6beb1"}, {"id": 985, "x": -5, "y": 5, "z": -2, "c": "#c6beb1"}, {"id": 986, "x": -4, "y": 5, "z": -6, "c": "#c6beb1"}, {"id": 987, "x": -4, "y": 5, "z": -5, "c": "#c6beb1"}, {"id": 988, "x": -4, "y": 5, "z": -4, "c": "#c6beb1"}, {"id": 989, "x": -4, "y": 5, "z": -3, "c": "#c6beb1"}, {"id": 990, "x": -4, "y": 5, "z": -2, "c": "#c6beb1"}, {"id": 991, "x": -8, "y": 6, "z": -6, "c": "#7a5749"}, {"id": 992, "x": -8, "y": 6, "z": -5, "c": "#7a5749"}, {"id": 993, "x": -8, "y": 6, "z": -4, "c": "#7a5749"}, {"id": 994, "x": -8, "y": 6, "z": -3, "c": "#7a5749"}, {"id": 995, "x": -8, "y": 6, "z": -2, "c": "#7a5749"}, {"id": 996, "x": -7, "y": 6, "z": -6, "c": "#7a5749"}, {"id": 997, "x": -7, "y": 6, "z": -2, "c": "#7a5749"}, {"id": 998, "x": -6, "y": 6, "z": -6, "c": "#7a5749"}, {"id": 999, "x": -6, "y": 6, "z": -2, "c": "#7a5749"}, {"id": 1000, "x": -5, "y": 6, "z": -6, "c": "#7a5749"}, {"id": 1001, "x": -5, "y": 6, "z": -2, "c": "#7a5749"}, {"id": 1002, "x": -4, "y": 6, "z": -6, "c": "#7a5749"}, {"id": 1003, "x": -4, "y": 6, "z": -5, "c": "#7a5749"}, {"id": 1004, "x": -4, "y": 6, "z": -4, "c": "#7a5749"}, {"id": 1005, "x": -4, "y": 6, "z": -3, "c": "#7a5749"}, {"id": 1006, "x": -4, "y": 6, "z": -2, "c": "#7a5749"}, {"id": 1007, "x": -9, "y": -3, "z": -7, "c": "#30363d"}, {"id": 1008, "x": -9, "y": -3, "z": -6, "c": "#30363d"}, {"id": 1009, "x": -9, "y": -3, "z": -5, "c": "#30363d"}, {"id": 1010, "x": -9, "y": -3, "z": -4, "c": "#30363d"}, {"id": 1011, "x": -9, "y": -3, "z": -3, "c": "#30363d"}, {"id": 1012, "x": -9, "y": -3, "z": -2, "c": "#30363d"}, {"id": 1013, "x": -9, "y": -3, "z": -1, "c": "#30363d"}, {"id": 1014, "x": -9, "y": -3, "z": 0, "c": "#30363d"}, {"id": 1015, "x": -9, "y": -3, "z": 1, "c": "#30363d"}, {"id": 1016, "x": -9, "y": -3, "z": 2, "c": "#30363d"}, {"id": 1017, "x": -9, "y": -3, "z": 3, "c": "#30363d"}, {"id": 1018, "x": -9, "y": -3, "z": 4, "c": "#30363d"}, {"id": 1019, "x": -9, "y": -3, "z": 5, "c": "#30363d"}, {"id": 1020, "x": -9, "y": -3, "z": 6, "c": "#30363d"}, {"id": 1021, "x": -9, "y": -3, "z": 7, "c": "#30363d"}, {"id": 1022, "x": -8, "y": -3, "z": -7, "c": "#30363d"}, {"id": 1023, "x": -8, "y": -3, "z": -1, "c": "#30363d"}, {"id": 1024, "x": -8, "y": -3, "z": 0, "c": "#30363d"}, {"id": 1025, "x": -8, "y": -3, "z": 1, "c": "#30363d"}, {"id": 1026, "x": -8, "y": -3, "z": 2, "c": "#30363d"}, {"id": 1027, "x": -8, "y": -3, "z": 3, "c": "#30363d"}, {"id": 1028, "x": -8, "y": -3, "z": 4, "c": "#30363d"}, {"id": 1029, "x": -8, "y": -3, "z": 5, "c": "#30363d"}, {"id": 1030, "x": -8, "y": -3, "z": 6, "c": "#30363d"}, {"id": 1031, "x": -8, "y": -3, "z": 7, "c": "#30363d"}, {"id": 1032, "x": -7, "y": -3, "z": -7, "c": "#30363d"}, {"id": 1033, "x": -7, "y": -3, "z": -5, "c": "#30363d"}, {"id": 1034, "x": -7, "y": -3, "z": -4, "c": "#30363d"}, {"id": 1035, "x": -7, "y": -3, "z": -3, "c": "#30363d"}, {"id": 1036, "x": -7, "y": -3, "z": -1, "c": "#30363d"}, {"id": 1037, "x": -7, "y": -3, "z": 0, "c": "#30363d"}, {"id": 1038, "x": -7, "y": -3, "z": 1, "c": "#30363d"}, {"id": 1039, "x": -7, "y": -3, "z": 2, "c": "#30363d"}, {"id": 1040, "x": -7, "y": -3, "z": 3, "c": "#30363d"}, {"id": 1041, "x": -7, "y": -3, "z": 4, "c": "#30363d"}, {"id": 1042, "x": -7, "y": -3, "z": 5, "c": "#30363d"}, {"id": 1043, "x": -7, "y": -3, "z": 6, "c": "#30363d"}, {"id": 1044, "x": -7, "y": -3, "z": 7, "c": "#30363d"}, {"id": 1045, "x": -6, "y": -3, "z": -7, "c": "#30363d"}, {"id": 1046, "x": -6, "y": -3, "z": -5, "c": "#30363d"}, {"id": 1047, "x": -6, "y": -3, "z": -4, "c": "#30363d"}, {"id": 1048, "x": -6, "y": -3, "z": -3, "c": "#30363d"}, {"id": 1049, "x": -6, "y": -3, "z": -1, "c": "#30363d"}, {"id": 1050, "x": -6, "y": -3, "z": 0, "c": "#30363d"}, {"id": 1051, "x": -6, "y": -3, "z": 1, "c": "#30363d"}, {"id": 1052, "x": -6, "y": -3, "z": 2, "c": "#30363d"}, {"id": 1053, "x": -6, "y": -3, "z": 3, "c": "#30363d"}, {"id": 1054, "x": -6, "y": -3, "z": 4, "c": "#30363d"}, {"id": 1055, "x": -6, "y": -3, "z": 5, "c": "#30363d"}, {"id": 1056, "x": -6, "y": -3, "z": 6, "c": "#30363d"}, {"id": 1057, "x": -6, "y": -3, "z": 7, "c": "#30363d"}, {"id": 1058, "x": -5, "y": -3, "z": -7, "c": "#30363d"}, {"id": 1059, "x": -5, "y": -3, "z": -5, "c": "#30363d"}, {"id": 1060, "x": -5, "y": -3, "z": -4, "c": "#30363d"}, {"id": 1061, "x": -5, "y": -3, "z": -3, "c": "#30363d"}, {"id": 1062, "x": -5, "y": -3, "z": -1, "c": "#30363d"}, {"id": 1063, "x": -5, "y": -3, "z": 0, "c": "#30363d"}, {"id": 1064, "x": -5, "y": -3, "z": 1, "c": "#30363d"}, {"id": 1065, "x": -5, "y": -3, "z": 2, "c": "#30363d"}, {"id": 1066, "x": -5, "y": -3, "z": 3, "c": "#30363d"}, {"id": 1067, "x": -5, "y": -3, "z": 4, "c": "#30363d"}, {"id": 1068, "x": -5, "y": -3, "z": 5, "c": "#30363d"}, {"id": 1069, "x": -5, "y": -3, "z": 6, "c": "#30363d"}, {"id": 1070, "x": -5, "y": -3, "z": 7, "c": "#30363d"}, {"id": 1071, "x": -4, "y": -3, "z": -7, "c": "#30363d"}, {"id": 1072, "x": -4, "y": -3, "z": -1, "c": "#30363d"}, {"id": 1073, "x": -4, "y": -3, "z": 0, "c": "#30363d"}, {"id": 1074, "x": -4, "y": -3, "z": 1, "c": "#30363d"}, {"id": 1075, "x": -4, "y": -3, "z": 2, "c": "#30363d"}, {"id": 1076, "x": -4, "y": -3, "z": 3, "c": "#30363d"}, {"id": 1077, "x": -4, "y": -3, "z": 4, "c": "#30363d"}, {"id": 1078, "x": -4, "y": -3, "z": 5, "c": "#30363d"}, {"id": 1079, "x": -4, "y": -3, "z": 6, "c": "#30363d"}, {"id": 1080, "x": -4, "y": -3, "z": 7, "c": "#30363d"}, {"id": 1081, "x": -3, "y": -3, "z": -7, "c": "#30363d"}, {"id": 1082, "x": -3, "y": -3, "z": -6, "c": "#30363d"}, {"id": 1083, "x": -3, "y": -3, "z": -5, "c": "#30363d"}, {"id": 1084, "x": -3, "y": -3, "z": -4, "c": "#30363d"}, {"id": 1085, "x": -3, "y": -3, "z": -3, "c": "#30363d"}, {"id": 1086, "x": -3, "y": -3, "z": -2, "c": "#30363d"}, {"id": 1087, "x": -3, "y": -3, "z": -1, "c": "#30363d"}, {"id": 1088, "x": -3, "y": -3, "z": 0, "c": "#30363d"}, {"id": 1089, "x": -3, "y": -3, "z": 1, "c": "#30363d"}, {"id": 1090, "x": -3, "y": -3, "z": 2, "c": "#30363d"}, {"id": 1091, "x": -3, "y": -3, "z": 3, "c": "#30363d"}, {"id": 1092, "x": -3, "y": -3, "z": 4, "c": "#30363d"}, {"id": 1093, "x": -3, "y": -3, "z": 5, "c": "#30363d"}, {"id": 1094, "x": -3, "y": -3, "z": 6, "c": "#30363d"}, {"id": 1095, "x": -3, "y": -3, "z": 7, "c": "#30363d"}, {"id": 1096, "x": -2, "y": -3, "z": -7, "c": "#30363d"}, {"id": 1097, "x": -2, "y": -3, "z": -6, "c": "#30363d"}, {"id": 1098, "x": -2, "y": -3, "z": -5, "c": "#30363d"}, {"id": 1099, "x": -2, "y": -3, "z": -4, "c": "#30363d"}, {"id": 1100, "x": -2, "y": -3, "z": -3, "c": "#30363d"}, {"id": 1101, "x": -2, "y": -3, "z": -2, "c": "#30363d"}, {"id": 1102, "x": -2, "y": -3, "z": -1, "c": "#30363d"}, {"id": 1103, "x": -2, "y": -3, "z": 0, "c": "#30363d"}, {"id": 1104, "x": -2, "y": -3, "z": 1, "c": "#30363d"}, {"id": 1105, "x": -2, "y": -3, "z": 2, "c": "#30363d"}, {"id": 1106, "x": -2, "y": -3, "z": 3, "c": "#30363d"}, {"id": 1107, "x": -2, "y": -3, "z": 4, "c": "#30363d"}, {"id": 1108, "x": -2, "y": -3, "z": 5, "c": "#30363d"}, {"id": 1109, "x": -2, "y": -3, "z": 6, "c": "#30363d"}, {"id": 1110, "x": -2, "y": -3, "z": 7, "c": "#30363d"}, {"id": 1111, "x": -1, "y": -3, "z": -7, "c": "#30363d"}, {"id": 1112, "x": -1, "y": -3, "z": -6, "c": "#30363d"}, {"id": 1113, "x": -1, "y": -3, "z": -5, "c": "#30363d"}, {"id": 1114, "x": -1, "y": -3, "z": -4, "c": "#30363d"}, {"id": 1115, "x": -1, "y": -3, "z": -3, "c": "#30363d"}, {"id": 1116, "x": -1, "y": -3, "z": -2, "c": "#30363d"}, {"id": 1117, "x": -1, "y": -3, "z": -1, "c": "#30363d"}, {"id": 1118, "x": -1, "y": -3, "z": 0, "c": "#30363d"}, {"id": 1119, "x": -1, "y": -3, "z": 1, "c": "#30363d"}, {"id": 1120, "x": -1, "y": -3, "z": 2, "c": "#30363d"}, {"id": 1121, "x": -1, "y": -3, "z": 3, "c": "#30363d"}, {"id": 1122, "x": -1, "y": -3, "z": 4, "c": "#30363d"}, {"id": 1123, "x": -1, "y": -3, "z": 5, "c": "#30363d"}, {"id": 1124, "x": -1, "y": -3, "z": 6, "c": "#30363d"}, {"id": 1125, "x": -1, "y": -3, "z": 7, "c": "#30363d"}, {"id": 1126, "x": 0, "y": -3, "z": -7, "c": "#30363d"}, {"id": 1127, "x": 0, "y": -3, "z": -6, "c": "#30363d"}, {"id": 1128, "x": 0, "y": -3, "z": -5, "c": "#30363d"}, {"id": 1129, "x": 0, "y": -3, "z": -4, "c": "#30363d"}, {"id": 1130, "x": 0, "y": -3, "z": -3, "c": "#30363d"}, {"id": 1131, "x": 0, "y": -3, "z": -2, "c": "#30363d"}, {"id": 1132, "x": 0, "y": -3, "z": -1, "c": "#30363d"}, {"id": 1133, "x": 0, "y": -3, "z": 0, "c": "#30363d"}, {"id": 1134, "x": 0, "y": -3, "z": 1, "c": "#30363d"}, {"id": 1135, "x": 0, "y": -3, "z": 2, "c": "#30363d"}, {"id": 1136, "x": 0, "y": -3, "z": 3, "c": "#30363d"}, {"id": 1137, "x": 0, "y": -3, "z": 4, "c": "#30363d"}, {"id": 1138, "x": 0, "y": -3, "z": 5, "c": "#30363d"}, {"id": 1139, "x": 0, "y": -3, "z": 6, "c": "#30363d"}, {"id": 1140, "x": 0, "y": -3, "z": 7, "c": "#30363d"}, {"id": 1141, "x": 1, "y": -3, "z": -7, "c": "#30363d"}, {"id": 1142, "x": 1, "y": -3, "z": -6, "c": "#30363d"}, {"id": 1143, "x": 1, "y": -3, "z": -5, "c": "#30363d"}, {"id": 1144, "x": 1, "y": -3, "z": -4, "c": "#30363d"}, {"id": 1145, "x": 1, "y": -3, "z": -3, "c": "#30363d"}, {"id": 1146, "x": 1, "y": -3, "z": -2, "c": "#30363d"}, {"id": 1147, "x": 1, "y": -3, "z": -1, "c": "#30363d"}, {"id": 1148, "x": 1, "y": -3, "z": 0, "c": "#30363d"}, {"id": 1149, "x": 1, "y": -3, "z": 1, "c": "#30363d"}, {"id": 1150, "x": 1, "y": -3, "z": 2, "c": "#30363d"}, {"id": 1151, "x": 1, "y": -3, "z": 3, "c": "#30363d"}, {"id": 1152, "x": 1, "y": -3, "z": 4, "c": "#30363d"}, {"id": 1153, "x": 1, "y": -3, "z": 5, "c": "#30363d"}, {"id": 1154, "x": 1, "y": -3, "z": 6, "c": "#30363d"}, {"id": 1155, "x": 1, "y": -3, "z": 7, "c": "#30363d"}, {"id": 1156, "x": 2, "y": -3, "z": -7, "c": "#30363d"}, {"id": 1157, "x": 2, "y": -3, "z": -6, "c": "#30363d"}, {"id": 1158, "x": 2, "y": -3, "z": -5, "c": "#30363d"}, {"id": 1159, "x": 2, "y": -3, "z": -4, "c": "#30363d"}, {"id": 1160, "x": 2, "y": -3, "z": -3, "c": "#30363d"}, {"id": 1161, "x": 2, "y": -3, "z": -2, "c": "#30363d"}, {"id": 1162, "x": 2, "y": -3, "z": -1, "c": "#30363d"}, {"id": 1163, "x": 2, "y": -3, "z": 0, "c": "#30363d"}, {"id": 1164, "x": 2, "y": -3, "z": 1, "c": "#30363d"}, {"id": 1165, "x": 2, "y": -3, "z": 2, "c": "#30363d"}, {"id": 1166, "x": 2, "y": -3, "z": 3, "c": "#30363d"}, {"id": 1167, "x": 2, "y": -3, "z": 4, "c": "#30363d"}, {"id": 1168, "x": 2, "y": -3, "z": 5, "c": "#30363d"}, {"id": 1169, "x": 2, "y": -3, "z": 6, "c": "#30363d"}, {"id": 1170, "x": 2, "y": -3, "z": 7, "c": "#30363d"}, {"id": 1171, "x": 3, "y": -3, "z": -7, "c": "#30363d"}, {"id": 1172, "x": 3, "y": -3, "z": -6, "c": "#30363d"}, {"id": 1173, "x": 3, "y": -3, "z": -5, "c": "#30363d"}, {"id": 1174, "x": 3, "y": -3, "z": -4, "c": "#30363d"}, {"id": 1175, "x": 3, "y": -3, "z": -3, "c": "#30363d"}, {"id": 1176, "x": 3, "y": -3, "z": -2, "c": "#30363d"}, {"id": 1177, "x": 3, "y": -3, "z": -1, "c": "#30363d"}, {"id": 1178, "x": 3, "y": -3, "z": 0, "c": "#30363d"}, {"id": 1179, "x": 3, "y": -3, "z": 1, "c": "#30363d"}, {"id": 1180, "x": 3, "y": -3, "z": 2, "c": "#30363d"}, {"id": 1181, "x": 3, "y": -3, "z": 3, "c": "#30363d"}, {"id": 1182, "x": 3, "y": -3, "z": 4, "c": "#30363d"}, {"id": 1183, "x": 3, "y": -3, "z": 5, "c": "#30363d"}, {"id": 1184, "x": 3, "y": -3, "z": 6, "c": "#30363d"}, {"id": 1185, "x": 3, "y": -3, "z": 7, "c": "#30363d"}, {"id": 1186, "x": 4, "y": -3, "z": -7, "c": "#30363d"}, {"id": 1187, "x": 4, "y": -3, "z": -6, "c": "#30363d"}, {"id": 1188, "x": 4, "y": -3, "z": -5, "c": "#30363d"}, {"id": 1189, "x": 4, "y": -3, "z": -4, "c": "#30363d"}, {"id": 1190, "x": 4, "y": -3, "z": -3, "c": "#30363d"}, {"id": 1191, "x": 4, "y": -3, "z": -2, "c": "#30363d"}, {"id": 1192, "x": 4, "y": -3, "z": -1, "c": "#30363d"}, {"id": 1193, "x": 4, "y": -3, "z": 0, "c": "#30363d"}, {"id": 1194, "x": 4, "y": -3, "z": 1, "c": "#30363d"}, {"id": 1195, "x": 4, "y": -3, "z": 2, "c": "#30363d"}, {"id": 1196, "x": 4, "y": -3, "z": 3, "c": "#30363d"}, {"id": 1197, "x": 4, "y": -3, "z": 4, "c": "#30363d"}, {"id": 1198, "x": 4, "y": -3, "z": 5, "c": "#30363d"}, {"id": 1199, "x": 4, "y": -3, "z": 6, "c": "#30363d"}, {"id": 1200, "x": 4, "y": -3, "z": 7, "c": "#30363d"}, {"id": 1201, "x": 5, "y": -3, "z": -7, "c": "#30363d"}, {"id": 1202, "x": 5, "y": -3, "z": -6, "c": "#30363d"}, {"id": 1203, "x": 5, "y": -3, "z": -5, "c": "#30363d"}, {"id": 1204, "x": 5, "y": -3, "z": -4, "c": "#30363d"}, {"id": 1205, "x": 5, "y": -3, "z": -3, "c": "#30363d"}, {"id": 1206, "x": 5, "y": -3, "z": -2, "c": "#30363d"}, {"id": 1207, "x": 5, "y": -3, "z": -1, "c": "#30363d"}, {"id": 1208, "x": 5, "y": -3, "z": 0, "c": "#30363d"}, {"id": 1209, "x": 5, "y": -3, "z": 1, "c": "#30363d"}, {"id": 1210, "x": 5, "y": -3, "z": 2, "c": "#30363d"}, {"id": 1211, "x": 5, "y": -3, "z": 3, "c": "#30363d"}, {"id": 1212, "x": 5, "y": -3, "z": 4, "c": "#30363d"}, {"id": 1213, "x": 5, "y": -3, "z": 5, "c": "#30363d"}, {"id": 1214, "x": 5, "y": -3, "z": 6, "c": "#30363d"}, {"id": 1215, "x": 5, "y": -3, "z": 7, "c": "#30363d"}, {"id": 1216, "x": 6, "y": -3, "z": -7, "c": "#30363d"}, {"id": 1217, "x": 6, "y": -3, "z": -6, "c": "#30363d"}, {"id": 1218, "x": 6, "y": -3, "z": -5, "c": "#30363d"}, {"id": 1219, "x": 6, "y": -3, "z": -4, "c": "#30363d"}, {"id": 1220, "x": 6, "y": -3, "z": -3, "c": "#30363d"}, {"id": 1221, "x": 6, "y": -3, "z": -2, "c": "#30363d"}, {"id": 1222, "x": 6, "y": -3, "z": -1, "c": "#30363d"}, {"id": 1223, "x": 6, "y": -3, "z": 0, "c": "#30363d"}, {"id": 1224, "x": 6, "y": -3, "z": 1, "c": "#30363d"}, {"id": 1225, "x": 6, "y": -3, "z": 2, "c": "#30363d"}, {"id": 1226, "x": 6, "y": -3, "z": 3, "c": "#30363d"}, {"id": 1227, "x": 6, "y": -3, "z": 4, "c": "#30363d"}, {"id": 1228, "x": 6, "y": -3, "z": 5, "c": "#30363d"}, {"id": 1229, "x": 6, "y": -3, "z": 6, "c": "#30363d"}, {"id": 1230, "x": 6, "y": -3, "z": 7, "c": "#30363d"}, {"id": 1231, "x": 7, "y": -3, "z": -7, "c": "#30363d"}, {"id": 1232, "x": 7, "y": -3, "z": -6, "c": "#30363d"}, {"id": 1233, "x": 7, "y": -3, "z": -5, "c": "#30363d"}, {"id": 1234, "x": 7, "y": -3, "z": -4, "c": "#30363d"}, {"id": 1235, "x": 7, "y": -3, "z": -3, "c": "#30363d"}, {"id": 1236, "x": 7, "y": -3, "z": -2, "c": "#30363d"}, {"id": 1237, "x": 7, "y": -3, "z": -1, "c": "#30363d"}, {"id": 1238, "x": 7, "y": -3, "z": 0, "c": "#30363d"}, {"id": 1239, "x": 7, "y": -3, "z": 1, "c": "#30363d"}, {"id": 1240, "x": 7, "y": -3, "z": 2, "c": "#30363d"}, {"id": 1241, "x": 7, "y": -3, "z": 3, "c": "#30363d"}, {"id": 1242, "x": 7, "y": -3, "z": 4, "c": "#30363d"}, {"id": 1243, "x": 7, "y": -3, "z": 5, "c": "#30363d"}, {"id": 1244, "x": 7, "y": -3, "z": 6, "c": "#30363d"}, {"id": 1245, "x": 7, "y": -3, "z": 7, "c": "#30363d"}, {"id": 1246, "x": 8, "y": -3, "z": -7, "c": "#30363d"}, {"id": 1247, "x": 8, "y": -3, "z": -6, "c": "#30363d"}, {"id": 1248, "x": 8, "y": -3, "z": -5, "c": "#30363d"}, {"id": 1249, "x": 8, "y": -3, "z": -4, "c": "#30363d"}, {"id": 1250, "x": 8, "y": -3, "z": -3, "c": "#30363d"}, {"id": 1251, "x": 8, "y": -3, "z": -2, "c": "#30363d"}, {"id": 1252, "x": 8, "y": -3, "z": -1, "c": "#30363d"}, {"id": 1253, "x": 8, "y": -3, "z": 0, "c": "#30363d"}, {"id": 1254, "x": 8, "y": -3, "z": 1, "c": "#30363d"}, {"id": 1255, "x": 8, "y": -3, "z": 2, "c": "#30363d"}, {"id": 1256, "x": 8, "y": -3, "z": 3, "c": "#30363d"}, {"id": 1257, "x": 8, "y": -3, "z": 4, "c": "#30363d"}, {"id": 1258, "x": 8, "y": -3, "z": 5, "c": "#30363d"}, {"id": 1259, "x": 8, "y": -3, "z": 6, "c": "#30363d"}, {"id": 1260, "x": 8, "y": -3, "z": 7, "c": "#30363d"}, {"id": 1261, "x": 9, "y": -3, "z": -7, "c": "#30363d"}, {"id": 1262, "x": 9, "y": -3, "z": -6, "c": "#30363d"}, {"id": 1263, "x": 9, "y": -3, "z": -5, "c": "#30363d"}, {"id": 1264, "x": 9, "y": -3, "z": -4, "c": "#30363d"}, {"id": 1265, "x": 9, "y": -3, "z": -3, "c": "#30363d"}, {"id": 1266, "x": 9, "y": -3, "z": -2, "c": "#30363d"}, {"id": 1267, "x": 9, "y": -3, "z": -1, "c": "#30363d"}, {"id": 1268, "x": 9, "y": -3, "z": 0, "c": "#30363d"}, {"id": 1269, "x": 9, "y": -3, "z": 1, "c": "#30363d"}, {"id": 1270, "x": 9, "y": -3, "z": 2, "c": "#30363d"}, {"id": 1271, "x": 9, "y": -3, "z": 3, "c": "#30363d"}, {"id": 1272, "x": 9, "y": -3, "z": 4, "c": "#30363d"}, {"id": 1273, "x": 9, "y": -3, "z": 5, "c": "#30363d"}, {"id": 1274, "x": 9, "y": -3, "z": 6, "c": "#30363d"}, {"id": 1275, "x": 9, "y": -3, "z": 7, "c": "#30363d"}, {"id": 1276, "x": -9, "y": 7, "z": -7, "c": "#30363d"}, {"id": 1277, "x": -9, "y": 7, "z": -6, "c": "#30363d"}, {"id": 1278, "x": -9, "y": 7, "z": -5, "c": "#30363d"}, {"id": 1279, "x": -9, "y": 7, "z": -4, "c": "#30363d"}, {"id": 1280, "x": -9, "y": 7, "z": -3, "c": "#30363d"}, {"id": 1281, "x": -9, "y": 7, "z": -2, "c": "#30363d"}, {"id": 1282, "x": -9, "y": 7, "z": -1, "c": "#30363d"}, {"id": 1283, "x": -8, "y": 7, "z": -7, "c": "#30363d"}, {"id": 1284, "x": -8, "y": 7, "z": -6, "c": "#30363d"}, {"id": 1285, "x": -8, "y": 7, "z": -5, "c": "#30363d"}, {"id": 1286, "x": -8, "y": 7, "z": -4, "c": "#30363d"}, {"id": 1287, "x": -8, "y": 7, "z": -3, "c": "#30363d"}, {"id": 1288, "x": -8, "y": 7, "z": -2, "c": "#30363d"}, {"id": 1289, "x": -8, "y": 7, "z": -1, "c": "#30363d"}, {"id": 1290, "x": -7, "y": 7, "z": -7, "c": "#30363d"}, {"id": 1291, "x": -7, "y": 7, "z": -6, "c": "#30363d"}, {"id": 1292, "x": -7, "y": 7, "z": -5, "c": "#30363d"}, {"id": 1293, "x": -7, "y": 7, "z": -4, "c": "#30363d"}, {"id": 1294, "x": -7, "y": 7, "z": -3, "c": "#30363d"}, {"id": 1295, "x": -7, "y": 7, "z": -2, "c": "#30363d"}, {"id": 1296, "x": -7, "y": 7, "z": -1, "c": "#30363d"}, {"id": 1297, "x": -6, "y": 7, "z": -7, "c": "#30363d"}, {"id": 1298, "x": -6, "y": 7, "z": -6, "c": "#30363d"}, {"id": 1299, "x": -6, "y": 7, "z": -5, "c": "#30363d"}, {"id": 1300, "x": -6, "y": 7, "z": -4, "c": "#30363d"}, {"id": 1301, "x": -6, "y": 7, "z": -3, "c": "#30363d"}, {"id": 1302, "x": -6, "y": 7, "z": -2, "c": "#30363d"}, {"id": 1303, "x": -6, "y": 7, "z": -1, "c": "#30363d"}, {"id": 1304, "x": -5, "y": 7, "z": -7, "c": "#30363d"}, {"id": 1305, "x": -5, "y": 7, "z": -6, "c": "#30363d"}, {"id": 1306, "x": -5, "y": 7, "z": -5, "c": "#30363d"}, {"id": 1307, "x": -5, "y": 7, "z": -4, "c": "#30363d"}, {"id": 1308, "x": -5, "y": 7, "z": -3, "c": "#30363d"}, {"id": 1309, "x": -5, "y": 7, "z": -2, "c": "#30363d"}, {"id": 1310, "x": -5, "y": 7, "z": -1, "c": "#30363d"}, {"id": 1311, "x": -4, "y": 7, "z": -7, "c": "#30363d"}, {"id": 1312, "x": -4, "y": 7, "z": -6, "c": "#30363d"}, {"id": 1313, "x": -4, "y": 7, "z": -5, "c": "#30363d"}, {"id": 1314, "x": -4, "y": 7, "z": -4, "c": "#30363d"}, {"id": 1315, "x": -4, "y": 7, "z": -3, "c": "#30363d"}, {"id": 1316, "x": -4, "y": 7, "z": -2, "c": "#30363d"}, {"id": 1317, "x": -4, "y": 7, "z": -1, "c": "#30363d"}, {"id": 1318, "x": -3, "y": 7, "z": -7, "c": "#30363d"}, {"id": 1319, "x": -3, "y": 7, "z": -6, "c": "#30363d"}, {"id": 1320, "x": -3, "y": 7, "z": -5, "c": "#30363d"}, {"id": 1321, "x": -3, "y": 7, "z": -4, "c": "#30363d"}, {"id": 1322, "x": -3, "y": 7, "z": -3, "c": "#30363d"}, {"id": 1323, "x": -3, "y": 7, "z": -2, "c": "#30363d"}, {"id": 1324, "x": -3, "y": 7, "z": -1, "c": "#30363d"}, {"id": 1325, "x": -6, "y": 8, "z": -4, "c": "#b18b57"}, {"id": 1326, "x": 2, "y": -11, "z": 7, "c": "#23272c"}, {"id": 1327, "x": 2, "y": -10, "z": 7, "c": "#5a4231"}, {"id": 1328, "x": 2, "y": -9, "z": 7, "c": "#7a5749"}, {"id": 1329, "x": 2, "y": -8, "z": 7, "c": "#7a5749"}, {"id": 1330, "x": 2, "y": -11, "z": 8, "c": "#23272c"}, {"id": 1331, "x": 2, "y": -10, "z": 8, "c": "#c6beb1"}, {"id": 1332, "x": 2, "y": -9, "z": 8, "c": "#7a5749"}, {"id": 1333, "x": 2, "y": -8, "z": 8, "c": "#7a5749"}, {"id": 1334, "x": 2, "y": -11, "z": 9, "c": "#23272c"}, {"id": 1335, "x": 2, "y": -10, "z": 9, "c": "#5a4231"}, {"id": 1336, "x": 2, "y": -9, "z": 9, "c": "#7a5749"}, {"id": 1337, "x": 2, "y": -8, "z": 9, "c": "#7a5749"}, {"id": 1338, "x": 2, "y": -11, "z": 10, "c": "#23272c"}, {"id": 1339, "x": 2, "y": -10, "z": 10, "c": "#5a4231"}, {"id": 1340, "x": 2, "y": -9, "z": 10, "c": "#60737e"}, {"id": 1341, "x": 2, "y": -8, "z": 10, "c": "#7a5749"}, {"id": 1342, "x": 3, "y": -11, "z": 7, "c": "#23272c"}, {"id": 1343, "x": 3, "y": -10, "z": 7, "c": "#5a4231"}, {"id": 1344, "x": 3, "y": -9, "z": 7, "c": "#7a5749"}, {"id": 1345, "x": 3, "y": -8, "z": 7, "c": "#7a5749"}, {"id": 1346, "x": 3, "y": -11, "z": 8, "c": "#23272c"}, {"id": 1347, "x": 3, "y": -10, "z": 8, "c": "#5a4231"}, {"id": 1348, "x": 3, "y": -9, "z": 8, "c": "#7a5749"}, {"id": 1349, "x": 3, "y": -8, "z": 8, "c": "#7a5749"}, {"id": 1350, "x": 3, "y": -11, "z": 9, "c": "#23272c"}, {"id": 1351, "x": 3, "y": -10, "z": 9, "c": "#5a4231"}, {"id": 1352, "x": 3, "y": -9, "z": 9, "c": "#7a5749"}, {"id": 1353, "x": 3, "y": -8, "z": 9, "c": "#7a5749"}, {"id": 1354, "x": 3, "y": -11, "z": 10, "c": "#23272c"}, {"id": 1355, "x": 3, "y": -10, "z": 10, "c": "#5a4231"}, {"id": 1356, "x": 3, "y": -9, "z": 10, "c": "#60737e"}, {"id": 1357, "x": 3, "y": -8, "z": 10, "c": "#7a5749"}, {"id": 1358, "x": 4, "y": -11, "z": 7, "c": "#23272c"}, {"id": 1359, "x": 4, "y": -10, "z": 7, "c": "#5a4231"}, {"id": 1360, "x": 4, "y": -9, "z": 7, "c": "#7a5749"}, {"id": 1361, "x": 4, "y": -8, "z": 7, "c": "#7a5749"}, {"id": 1362, "x": 4, "y": -11, "z": 8, "c": "#23272c"}, {"id": 1363, "x": 4, "y": -10, "z": 8, "c": "#5a4231"}, {"id": 1364, "x": 4, "y": -9, "z": 8, "c": "#7a5749"}, {"id": 1365, "x": 4, "y": -8, "z": 8, "c": "#7a5749"}, {"id": 1366, "x": 4, "y": -11, "z": 9, "c": "#23272c"}, {"id": 1367, "x": 4, "y": -10, "z": 9, "c": "#5a4231"}, {"id": 1368, "x": 4, "y": -9, "z": 9, "c": "#7a5749"}, {"id": 1369, "x": 4, "y": -8, "z": 9, "c": "#7a5749"}, {"id": 1370, "x": 4, "y": -11, "z": 10, "c": "#23272c"}, {"id": 1371, "x": 4, "y": -10, "z": 10, "c": "#5a4231"}, {"id": 1372, "x": 4, "y": -9, "z": 10, "c": "#60737e"}, {"id": 1373, "x": 4, "y": -8, "z": 10, "c": "#7a5749"}, {"id": 1374, "x": 5, "y": -11, "z": 7, "c": "#23272c"}, {"id": 1375, "x": 5, "y": -10, "z": 7, "c": "#5a4231"}, {"id": 1376, "x": 5, "y": -9, "z": 7, "c": "#7a5749"}, {"id": 1377, "x": 5, "y": -8, "z": 7, "c": "#7a5749"}, {"id": 1378, "x": 5, "y": -11, "z": 8, "c": "#23272c"}, {"id": 1379, "x": 5, "y": -10, "z": 8, "c": "#5a4231"}, {"id": 1380, "x": 5, "y": -9, "z": 8, "c": "#7a5749"}, {"id": 1381, "x": 5, "y": -8, "z": 8, "c": "#7a5749"}, {"id": 1382, "x": 5, "y": -11, "z": 9, "c": "#23272c"}, {"id": 1383, "x": 5, "y": -10, "z": 9, "c": "#5a4231"}, {"id": 1384, "x": 5, "y": -9, "z": 9, "c": "#7a5749"}, {"id": 1385, "x": 5, "y": -8, "z": 9, "c": "#7a5749"}, {"id": 1386, "x": 5, "y": -11, "z": 10, "c": "#23272c"}, {"id": 1387, "x": 5, "y": -10, "z": 10, "c": "#5a4231"}, {"id": 1388, "x": 5, "y": -9, "z": 10, "c": "#60737e"}, {"id": 1389, "x": 5, "y": -8, "z": 10, "c": "#7a5749"}, {"id": 1390, "x": 3, "y": -7, "z": 8, "c": "#4f6274"}, {"id": 1391, "x": 4, "y": -7, "z": 8, "c": "#c6beb1"}, {"id": 1392, "x": -5, "y": -11, "z": 1, "c": "#23272c"}, {"id": 1393, "x": -5, "y": -10, "z": 1, "c": "#5a4231"}, {"id": 1394, "x": -5, "y": -9, "z": 1, "c": "#7a5749"}, {"id": 1395, "x": -5, "y": -8, "z": 1, "c": "#7a5749"}, {"id": 1396, "x": -5, "y": -11, "z": 2, "c": "#23272c"}, {"id": 1397, "x": -5, "y": -10, "z": 2, "c": "#5a4231"}, {"id": 1398, "x": -5, "y": -9, "z": 2, "c": "#7a5749"}, {"id": 1399, "x": -5, "y": -8, "z": 2, "c": "#7a5749"}, {"id": 1400, "x": -5, "y": -11, "z": 3, "c": "#23272c"}, {"id": 1401, "x": -5, "y": -10, "z": 3, "c": "#5a4231"}, {"id": 1402, "x": -5, "y": -9, "z": 3, "c": "#7a5749"}, {"id": 1403, "x": -5, "y": -8, "z": 3, "c": "#7a5749"}, {"id": 1404, "x": -5, "y": -11, "z": 4, "c": "#23272c"}, {"id": 1405, "x": -5, "y": -10, "z": 4, "c": "#5a4231"}, {"id": 1406, "x": -5, "y": -9, "z": 4, "c": "#7a5749"}, {"id": 1407, "x": -5, "y": -8, "z": 4, "c": "#7a5749"}, {"id": 1408, "x": -5, "y": -11, "z": 5, "c": "#23272c"}, {"id": 1409, "x": -5, "y": -10, "z": 5, "c": "#5a4231"}, {"id": 1410, "x": -5, "y": -9, "z": 5, "c": "#60737e"}, {"id": 1411, "x": -5, "y": -8, "z": 5, "c": "#7a5749"}, {"id": 1412, "x": -4, "y": -11, "z": 1, "c": "#23272c"}, {"id": 1413, "x": -4, "y": -10, "z": 1, "c": "#5a4231"}, {"id": 1414, "x": -4, "y": -9, "z": 1, "c": "#7a5749"}, {"id": 1415, "x": -4, "y": -8, "z": 1, "c": "#7a5749"}, {"id": 1416, "x": -4, "y": -11, "z": 2, "c": "#23272c"}, {"id": 1417, "x": -4, "y": -10, "z": 2, "c": "#5a4231"}, {"id": 1418, "x": -4, "y": -9, "z": 2, "c": "#7a5749"}, {"id": 1419, "x": -4, "y": -8, "z": 2, "c": "#7a5749"}, {"id": 1420, "x": -4, "y": -11, "z": 3, "c": "#23272c"}, {"id": 1421, "x": -4, "y": -10, "z": 3, "c": "#5a4231"}, {"id": 1422, "x": -4, "y": -9, "z": 3, "c": "#7a5749"}, {"id": 1423, "x": -4, "y": -8, "z": 3, "c": "#7a5749"}, {"id": 1424, "x": -4, "y": -11, "z": 4, "c": "#23272c"}, {"id": 1425, "x": -4, "y": -10, "z": 4, "c": "#5a4231"}, {"id": 1426, "x": -4, "y": -9, "z": 4, "c": "#7a5749"}, {"id": 1427, "x": -4, "y": -8, "z": 4, "c": "#7a5749"}, {"id": 1428, "x": -4, "y": -11, "z": 5, "c": "#23272c"}, {"id": 1429, "x": -4, "y": -10, "z": 5, "c": "#5a4231"}, {"id": 1430, "x": -4, "y": -9, "z": 5, "c": "#60737e"}, {"id": 1431, "x": -4, "y": -8, "z": 5, "c": "#7a5749"}, {"id": 1432, "x": -3, "y": -11, "z": 1, "c": "#23272c"}, {"id": 1433, "x": -3, "y": -10, "z": 1, "c": "#5a4231"}, {"id": 1434, "x": -3, "y": -9, "z": 1, "c": "#7a5749"}, {"id": 1435, "x": -3, "y": -8, "z": 1, "c": "#7a5749"}, {"id": 1436, "x": -3, "y": -11, "z": 2, "c": "#23272c"}, {"id": 1437, "x": -3, "y": -10, "z": 2, "c": "#5a4231"}, {"id": 1438, "x": -3, "y": -9, "z": 2, "c": "#7a5749"}, {"id": 1439, "x": -3, "y": -8, "z": 2, "c": "#7a5749"}, {"id": 1440, "x": -3, "y": -11, "z": 3, "c": "#23272c"}, {"id": 1441, "x": -3, "y": -10, "z": 3, "c": "#5a4231"}, {"id": 1442, "x": -3, "y": -9, "z": 3, "c": "#7a5749"}, {"id": 1443, "x": -3, "y": -8, "z": 3, "c": "#7a5749"}, {"id": 1444, "x": -3, "y": -11, "z": 4, "c": "#23272c"}, {"id": 1445, "x": -3, "y": -10, "z": 4, "c": "#5a4231"}, {"id": 1446, "x": -3, "y": -9, "z": 4, "c": "#7a5749"}, {"id": 1447, "x": -3, "y": -8, "z": 4, "c": "#7a5749"}, {"id": 1448, "x": -3, "y": -11, "z": 5, "c": "#23272c"}, {"id": 1449, "x": -3, "y": -10, "z": 5, "c": "#5a4231"}, {"id": 1450, "x": -3, "y": -9, "z": 5, "c": "#60737e"}, {"id": 1451, "x": -3, "y": -8, "z": 5, "c": "#7a5749"}, {"id": 1452, "x": -2, "y": -11, "z": 1, "c": "#23272c"}, {"id": 1453, "x": -2, "y": -10, "z": 1, "c": "#5a4231"}, {"id": 1454, "x": -2, "y": -9, "z": 1, "c": "#7a5749"}, {"id": 1455, "x": -2, "y": -8, "z": 1, "c": "#7a5749"}, {"id": 1456, "x": -2, "y": -11, "z": 2, "c": "#23272c"}, {"id": 1457, "x": -2, "y": -10, "z": 2, "c": "#5a4231"}, {"id": 1458, "x": -2, "y": -9, "z": 2, "c": "#7a5749"}, {"id": 1459, "x": -2, "y": -8, "z": 2, "c": "#7a5749"}, {"id": 1460, "x": -2, "y": -11, "z": 3, "c": "#23272c"}, {"id": 1461, "x": -2, "y": -10, "z": 3, "c": "#5a4231"}, {"id": 1462, "x": -2, "y": -9, "z": 3, "c": "#7a5749"}, {"id": 1463, "x": -2, "y": -8, "z": 3, "c": "#7a5749"}, {"id": 1464, "x": -2, "y": -11, "z": 4, "c": "#23272c"}, {"id": 1465, "x": -2, "y": -10, "z": 4, "c": "#5a4231"}, {"id": 1466, "x": -2, "y": -9, "z": 4, "c": "#7a5749"}, {"id": 1467, "x": -2, "y": -8, "z": 4, "c": "#7a5749"}, {"id": 1468, "x": -2, "y": -11, "z": 5, "c": "#23272c"}, {"id": 1469, "x": -2, "y": -10, "z": 5, "c": "#5a4231"}, {"id": 1470, "x": -2, "y": -9, "z": 5, "c": "#60737e"}, {"id": 1471, "x": -2, "y": -8, "z": 5, "c": "#7a5749"}, {"id": 1472, "x": -4, "y": -7, "z": 3, "c": "#4f6274"}, {"id": 1473, "x": -7, "y": -11, "z": 7, "c": "#c6beb1"}, {"id": 1474, "x": -7, "y": -10, "z": 7, "c": "#23272c"}, {"id": 1475, "x": -3, "y": -11, "z": -9, "c": "#c6beb1"}, {"id": 1476, "x": -3, "y": -10, "z": -9, "c": "#c6beb1"}, {"id": 1477, "x": -3, "y": -9, "z": -9, "c": "#c6beb1"}, {"id": 1478, "x": 3, "y": -11, "z": -9, "c": "#c6beb1"}, {"id": 1479, "x": 3, "y": -10, "z": -9, "c": "#c6beb1"}, {"id": 1480, "x": 3, "y": -9, "z": -9, "c": "#c6beb1"}]}